Workbook

Sheet 統合マスタ値
C3: 棚卸 | N3: マスタ | AD3: 合計 | AE3: 8723165 | AF3: 7615000.5 | AG3: 1108164.5
B4: no | C4: 名称 | D4: 2025年度卸 | E4: 包装形態 | F4: 容量 | G4: メーカー | H4: 新単位薬価 | I4: 2025年度薬価 | J4: 単位数量 | K4: 薬価単位 | L4: 2025年納入価格 | M4: 単位納入価 | N4: コード(区分値) | O4: コード | P4: 名称 | Q4: ホストコード | R4: 採用区分（区分値）(区分値) | S4: 採用区分（区分値） | T4: 薬価 | U4: カナ名称 | V4: 剤形(区分値) | W4: 剤形 | X4: 毒劇薬（区分値）(区分値) | Y4: 毒劇薬（区分値） | Z4: 場所番号 | AA4: 非採用/処置薬 | AB4: Excelシート | AC4: ソートキー | AD4: 数量合計 | AE4: 薬価×数量 | AF4: 納入価×数量 | AG4: 差益
A5: 640 | B5: 751 | C5: レキサルティＯＤ錠２ｍｇ | D5: スズケン | E5: ＰＴＰ | F5: １００Ｔ | G5: 大塚製薬 | H5: 461.9 | I5: 46190 | J5: 100 | K5: 錠 | L5: 40555 | M5: 405.55 | N5: ﾚｷｻ002 | O5: ﾚｷｻ002 | P5: レキサルティＯＤ錠２ｍｇ | Q5: ﾚｷｻﾙ2 | R5: 1 | T5: 461.9 | U5: ﾚｷｻﾙﾃｨODｼﾞｮｳ2mg | V5: 1 | W5: 錠剤 | X5: 2 | Z5: 26 | AB5: 錠剤 | AC5: 200751 | AD5: 1097 | AE5: 506704.3 | AF5: 444888.35 | AG5: =AE5-AF5 -> 61815.95
A6: 583 | B6: 671 | C6: ラゲブリオカプセル２００ｍｇ | D6: スズケン | E6: バラ | F6: ４０ｃａｐ | G6: MSD | H6: 2164.9 | I6: 86596 | J6: 40 | K6: cap | L6: 77149 | M6: 1928.725 | N6: ﾗｹﾌ001 | O6: ﾗｹﾌ001 | P6: ラゲブリオカプセル２００ｍｇ | Q6: ﾗｹﾞﾌﾞ | R6: 1 | T6: 2164.9 | U6: ﾗｹﾞﾌﾞﾘｵｶﾌﾟｾﾙ200mg | V6: 2 | W6: カプセル | X6: 2 | Z6: 6 | AB6: 錠剤 | AC6: 200671 | AD6: 156 | AE6: 337724.4 | AF6: 300881.1 | AG6: =AE6-AF6 -> 36843.3
A7: 591 | B7: 681 | C7: ラツーダ錠４０ｍｇ | D7: メディセオ | E7: ＰＴＰ | F7: １００Ｔ | G7: 住友ファーマ | H7: 295.8 | I7: 29580 | J7: 100 | K7: 錠 | L7: 25400 | M7: 254 | N7: ﾗﾂﾀ002 | O7: ﾗﾂﾀ002 | P7: ラツーダ錠４０ｍｇ | Q7: ﾗﾂｰ | R7: 1 | T7: 295.8 | U7: ﾗﾂｰﾀﾞｼﾞｮｳ40mg | V7: 1 | W7: 錠剤 | X7: 2 | Z7: 26 | AB7: 錠剤 | AC7: 200681 | AD7: 1084 | AE7: 320647.2 | AF7: 275336 | AG7: =AE7-AF7 -> 45311.2
A8: 252 | B8: 315 | C8: ゾフルーザ錠２０ｍｇ | E8: ＰＴＰ | F8: １０Ｔ | G8: 塩野義製薬 | H8: 2438.8 | I8: 24388 | J8: 10 | K8: 錠 | L8: 21709 | M8: 2170.9 | N8: ｿﾌﾙ001 | O8: ｿﾌﾙ001 | P8: ゾフルーザ錠２０ｍｇ | Q8: ｿﾞﾌﾙ | R8: 1 | T8: 2438.8 | U8: ｿﾞﾌﾙｰｻﾞｼﾞｮｳ20mg | V8: 1 | W8: 錠剤 | X8: 0 | Z8: 1 | AB8: 錠剤 | AC8: 315 | AD8: 122 | AE8: 297533.6 | AF8: 264849.8 | AG8: =AE8-AF8 -> 32683.8
A9: 66 | B9: 114 | C9: インヴェガ錠６ｍｇ | D9: メディセオ | E9: ＰＴＰ | F9: １００Ｔ | G9: ヤンセン | H9: 419.7 | I9: 41970 | J9: 100 | K9: 錠 | L9: 35200 | M9: 352 | N9: ｲﾝｳ002 | O9: ｲﾝｳ002 | P9: インヴェガ錠６ｍｇ | Q9: ｲﾝｳﾞｪ6 | R9: 1 | T9: 419.7 | U9: ｲﾝｳﾞｪｶﾞｼﾞｮｳ6mg | V9: 1 | W9: 錠剤 | X9: 2 | Z9: 26 | AB9: 錠剤 | AC9: 200114 | AD9: 602 | AE9: 252659.4 | AF9: 211904 | AG9: =AE9-AF9 -> 40755.4
A10: 639 | B10: 749 | C10: レキサルティＯＤ錠１ｍｇ | D10: スズケン | E10: ＰＴＰ | F10: １００Ｔ | G10: 大塚製薬 | H10: 241.8 | I10: 24180 | J10: 100 | K10: 錠 | L10: 21230 | M10: 212.3 | N10: ﾚｷｻ001 | O10: ﾚｷｻ001 | P10: レキサルティＯＤ錠１ｍｇ | Q10: ﾚｷｻﾙ1 | R10: 1 | T10: 241.8 | U10: ﾚｷｻﾙﾃｨODｼﾞｮｳ1mg | V10: 1 | W10: 錠剤 | X10: 2 | Z10: 26 | AB10: 錠剤 | AC10: 200749 | AD10: 817 | AE10: 197550.6 | AF10: 173449.1 | AG10: =AE10-AF10 -> 24101.5
A11: 506 | B11: 585 | C11: ベクルリー点滴静注用１００ｍｇ | D11: スズケン | F11: １Ｖ | G11: ギリアド | H11: 46498 | I11: 46498 | J11: 1 | K11: 瓶 | L11: 41108 | M11: 41108 | N11: ﾍｸﾙ001 | O11: ﾍｸﾙ001 | P11: ベクルリー点滴静注用１００ｍｇ | Q11: ﾍﾞｸﾙ | R11: 1 | T11: 46498 | U11: ﾍﾞｸﾙﾘｰﾃﾝﾃｷｼﾞｮｳﾁｭｳﾖｳ100mg | V11: 25 | W11: 注射剤 | X11: 0 | Z11: 6 | AB11: 注射 | AC11: 585 | AD11: 4 | AE11: 185992 | AF11: 164432 | AG11: =AE11-AF11 -> 21560
A12: 590 | B12: 679 | C12: ラツーダ錠２０ｍｇ | D12: メディセオ | E12: ＰＴＰ | F12: １００Ｔ | G12: 住友ファーマ | H12: 159.1 | I12: 15910 | J12: 100 | K12: 錠 | L12: 13691 | M12: 136.91 | N12: ﾗﾂﾀ001 | O12: ﾗﾂﾀ001 | P12: ラツーダ錠２０ｍｇ | Q12: ﾗﾂｰ2 | R12: 1 | T12: 159.1 | U12: ﾗﾂｰﾀﾞｼﾞｮｳ20mg | V12: 1 | W12: 錠剤 | X12: 2 | Z12: 26 | AB12: 錠剤 | AC12: 200679 | AD12: 972 | AE12: 154645.2 | AF12: 133076.52 | AG12: =AE12-AF12 -> 21568.68
A13: 515 | B13: 593 | C13: ヘパリン類似物質外用スプレー０．３％「サトウ」 | D13: アルフレッサ | F13: １００ｇｘ１０ | G13: 佐藤製薬 | H13: 7.4 | I13: 7400 | J13: 1000 | K13: ｇ | L13: 6592 | M13: 6.592 | N13: ﾍﾊﾘ004 | O13: ﾍﾊﾘ004 | P13: ヘパリン類似物質外用スプレー０．３％「サトウ」 | Q13: ﾍﾊﾟﾘ1 | R13: 1 | T13: 7.4 | U13: ﾍﾊﾟﾘﾝﾙｲｼﾞﾌﾞｯｼﾂｶﾞｲﾖｳｽﾌﾟﾚｰ0.3%｢ｻﾄｳ｣ | V13: 18 | W13: 噴霧剤 | X13: 0 | Z13: 5 | AB13: 外用 | AC13: 593 | AD13: 16600 | AE13: 122840 | AF13: 109427.2 | AG13: =AE13-AF13 -> 13412.8
A14: 459 | B14: 538 | C14: フォシーガ錠５ｍｇ | D14: アルフレッサ | E14: ＰＴＰ | F14: １００Ｔ | G14: 小野薬品 | H14: 149.3 | I14: 14930 | J14: 100 | K14: 錠 | L14: 12765 | M14: 127.65 | N14: ﾌｵｼ001 | O14: ﾌｵｼ001 | P14: フォシーガ錠５ｍｇ | Q14: ﾌｫｼ | R14: 1 | T14: 149.3 | U14: ﾌｫｼｰｶﾞｼﾞｮｳ5mg | V14: 1 | W14: 錠剤 | X14: 0 | Z14: 25 | AB14: 錠剤 | AC14: 538 | AD14: 841 | AE14: 125561.3 | AF14: 107353.65 | AG14: =AE14-AF14 -> 18207.65
A15: 659 | B15: 773 | C15: レボレード錠１２．５ｍｇ | E15: ＰＴＰ | F15: ７０Ｔ | G15: ノバルティス | H15: 2377.3 | I15: 166411 | J15: 70 | K15: 錠 | L15: 148189 | M15: 2116.9857 | N15: ﾚﾎﾚ001 | O15: ﾚﾎﾚ001 | P15: レボレード錠１２．５ｍｇ | Q15: ﾚﾎﾞﾚ | R15: 2 | T15: 2377.3 | U15: ﾚﾎﾞﾚｰﾄﾞｼﾞｮｳ12.5mg | V15: 1 | W15: 錠剤 | X15: 2 | Z15: 15 | AB15: 臨時 | AC15: 200773 | AD15: 47 | AE15: 111733.1 | AF15: 99498.329 | AG15: =AE15-AF15 -> 12234.771
A16: 641 | B16: 747 | C16: レキサルティＯＤ錠０．５ｍｇ | D16: スズケン | E16: ＰＴＰ | F16: １００Ｔ | G16: 大塚製薬 | H16: 128.7 | I16: 12870 | J16: 100 | K16: 錠 | L16: 11300 | M16: 113 | N16: ﾚｷｻ003 | O16: ﾚｷｻ003 | P16: レキサルティＯＤ錠０．５ｍｇ | R16: 1 | T16: 128.7 | U16: ﾚｷｻﾙﾃｲODｼﾞﾖｳ0.5MG | V16: 1 | W16: 錠剤 | X16: 2 | Z16: 26 | AB16: 錠剤 | AC16: 200747 | AD16: 800 | AE16: 102960 | AF16: 90400 | AG16: =AE16-AF16 -> 12560
A17: 687 | B17: 814 | C17: 生食注シリンジ「ＮＰ」中口１０ｍｌ | D17: スズケン | F17: １０ｍｌｘ１０ | G17: ニプロ | H17: 100 | I17: 1000 | J17: 10 | K17: 10ｍｌ | L17: 900 | M17: 90 | N17: ｾｲｼ004 | O17: ｾｲｼ004 | P17: 生食注シリンジ「オーツカ」１０ｍＬ | Q17: ｾｲｼｮｸ8 | R17: 0 | T17: 100 | U17: ｾｲｼｮｸﾁｭｳｼﾘﾝｼﾞ｢ｵｰﾂｶ｣10mL | V17: 25 | W17: 注射剤 | X17: 0 | Z17: 9 | AB17: 注射 | AC17: 814 | AD17: 920 | AE17: 92000 | AF17: 82800 | AG17: =AE17-AF17 -> 9200
A18: 136 | B18: 188 | C18: グーフィス錠５ｍｇ | D18: スズケン | E18: ＰＴＰ | F18: ５００Ｔ | G18: 持田製薬 | H18: 80.2 | I18: 40100 | J18: 500 | K18: 錠 | L18: 34309 | M18: 68.618 | N18: ｸﾌｲ001 | O18: ｸﾌｲ001 | P18: グーフィス錠５ｍｇ | Q18: ｸﾞｰﾌｨ | R18: 1 | T18: 80.2 | U18: ｸﾞｰﾌｨｽｼﾞｮｳ5mg | V18: 1 | W18: 錠剤 | X18: 0 | Z18: 25 | AB18: 錠剤 | AC18: 188 | AD18: 1194 | AE18: 95758.8 | AF18: 81929.892 | AG18: =AE18-AF18 -> 13828.908
A19: 571 | B19: 659 | C19: メロペネム点滴静注用０．５ｇ「サワイ」 | D19: 東邦 | F19: ５００ｍｇｘ１０Ｖ | G19: 沢井製薬 | H19: 656 | I19: 6560 | J19: 10 | K19: V | L19: 5921 | M19: 592.1 | N19: ﾒﾛﾍ003 | O19: ﾒﾛﾍ003 | P19: メロペネム点滴静注用０．５ｇ「サワイ」 | R19: 1 | T19: 656 | U19: ﾒﾛﾍﾟﾈﾑﾃﾝﾃｷｼﾞﾖｳﾁﾕｳﾖｳ0.5Gｻﾜｲ | V19: 25 | W19: 注射剤 | X19: 0 | Z19: 8 | AB19: 注射 | AC19: 659 | AD19: 131 | AE19: 85936 | AF19: 77565.1 | AG19: =AE19-AF19 -> 8370.9
A20: 599 | B20: 696 | C20: リクシアナＯＤ錠３０ｍｇ | D20: メディセオ | E20: バラ | F20: １００Ｔ | G20: 第一三共 | H20: 411.3 | I20: 41130 | J20: 100 | K20: 錠 | L20: 35730 | M20: 357.3 | N20: ﾘｸｼ001 | O20: ﾘｸｼ001 | P20: リクシアナＯＤ錠３０ｍｇ | Q20: ﾘｸｼ1 | R20: 1 | T20: 411.3 | U20: ﾘｸｼｱﾅODｼﾞｮｳ30mg | V20: 1 | W20: 錠剤 | X20: 0 | Z20: 25 | AB20: 錠剤 | AC20: 696 | AD20: 214 | AE20: 88018.2 | AF20: 76462.2 | AG20: =AE20-AF20 -> 11556
A21: 674 | B21: 793 | C21: ロナセンテープ４０ｍｇ | D21: メディセオ | F21: ７０枚 | G21: 住友ファーマ | H21: 429.1 | I21: 30037 | J21: 70 | K21: 枚 | L21: 25980 | M21: 371.14286 | N21: ﾛﾅｾ002 | O21: ﾛﾅｾ002 | P21: ロナセンテープ４０ｍｇ | Q21: ﾛﾅｾ5 | R21: 1 | T21: 429.1 | U21: ﾛﾅｾﾝﾃｰﾌﾟ40mg | V21: 19 | W21: 貼付剤 | X21: 2 | Z21: 3 | AB21: 外用 | AC21: 200793 | AD21: 203 | AE21: 87107.3 | AF21: 75342 | AG21: =AE21-AF21 -> 11765.3
A22: 86 | B22: 140 | C22: エビリファイ持続性水懸筋注用４００ｍｇ シリンジ | D22: メディセオ | F22: １キット | G22: 大塚製薬 | H22: 41300 | I22: 41300 | J22: 1 | K22: kit | L22: 35700 | M22: 35700 | N22: ｴﾋﾘ007 | O22: ｴﾋﾘ007 | P22: エビリファイ持続性水懸筋注用４００ｍｇシリンジ外来用 | Q22: ｴﾋﾞﾘ10 | R22: 1 | T22: 41300 | U22: ｴﾋﾞﾘﾌｧｲ持続ｾｲｽｲ懸ｷﾝﾁｭｳﾖｳ400mgｼﾘﾝｼﾞ | V22: 25 | W22: 注射剤 | X22: 2 | Z22: 9 | AB22: 注射 | AC22: 200140 | AD22: 2 | AE22: 82600 | AF22: 71400 | AG22: =AE22-AF22 -> 11200
A23: 356 | B23: 417 | C23: トリンテリックス錠１０ｍｇ | D23: メディセオ | E23: ＰＴＰ | F23: １００Ｔ | G23: 武田薬品工業 | H23: 161.7 | I23: 16170 | J23: 100 | K23: 錠 | L23: 14387 | M23: 143.87 | N23: ﾄﾘﾝ001 | O23: ﾄﾘﾝ001 | P23: トリンテリックス錠１０ｍｇ | Q23: ﾄﾘﾝ | R23: 1 | T23: 161.7 | U23: ﾄﾘﾝﾃﾘｯｸｽｼﾞｮｳ10mg | V23: 1 | W23: 錠剤 | X23: 2 | Z23: 26 | AB23: 錠剤 | AC23: 200417 | AD23: 480 | AE23: 77616 | AF23: 69057.6 | AG23: =AE23-AF23 -> 8558.4
A24: 400 | B24: 457 | C24: ハベカシン注射液７５ｍｇ | D24: アルフレッサ | F24: １．５ｍｌｘ１０Ａ | G24: meijiseika | H24: 4691 | I24: 46910 | J24: 10 | K24: Ａ | L24: 42420 | M24: 4242 | N24: ﾊﾍｶ001 | O24: ﾊﾍｶ001 | P24: ハベカシン注射液７５ｍｇ | Q24: ﾊﾍﾞｶｼﾝ | R24: 1 | T24: 4691 | U24: ﾊﾍﾞｶｼﾝﾁｭｳｼｬｴｷ75mg | V24: 25 | W24: 注射剤 | X24: 2 | Z24: 8 | AB24: 注射 | AC24: 200457 | AD24: 16 | AE24: 75056 | AF24: 67872 | AG24: =AE24-AF24 -> 7184
A25: 683 | B25: 802 | C25: ワンパル２号輸液（１） | D25: スズケン | F25: ８００ｍｌｘ１０袋 | G25: 陽進堂 | H25: 1399 | I25: 13990 | J25: 10 | K25: 袋 | L25: 12717 | M25: 1271.7 | N25: ﾜﾝﾊ002 | O25: ﾜﾝﾊ002 | P25: ワンパル２号輸液 | Q25: ﾜﾝﾊﾟ2 | R25: 1 | T25: 1399 | U25: ﾜﾝﾊﾟﾙ2ｺﾞｳﾕｴｷ | V25: 25 | W25: 注射剤 | X25: 0 | Z25: 10 | AB25: 注射 | AC25: 802 | AD25: 53 | AE25: 74147 | AF25: 67400.1 | AG25: =AE25-AF25 -> 6746.9
A26: 60 | B26: 107 | C26: イフェクサーＳＲカプセル３７．５ｍｇ | D26: アルフレッサ | E26: ＰＴＰ | F26: １００Ｔ | G26: ヴィアトリス | H26: 101.9 | I26: 10190 | J26: 100 | K26: 錠 | L26: 8763 | M26: 87.63 | N26: ｲﾌｴ001 | O26: ｲﾌｴ001 | P26: イフェクサーＳＲカプセル３７．５ｍｇ | Q26: ｲﾌｪｸ | R26: 1 | T26: 101.9 | U26: ｲﾌｪｸｻｰSRｶﾌﾟｾﾙ37.5mg | V26: 2 | W26: カプセル | X26: 2 | Z26: 6 | AB26: 錠剤 | AC26: 200107 | AD26: 727 | AE26: 74081.3 | AF26: 63707.01 | AG26: =AE26-AF26 -> 10374.29
A27: 非採用特別 | B27: 63 | C27: アトモキセチンカプセル１０ｍｇ 「ＶＴＲＳ」 | D27: メディセオ | E27: ＰＴＰ | F27: １４０Ｐ | G27: ヴィアトリス製薬 | H27: 50.3 | I27: 7042 | J27: 140 | K27: cap | L27: 6273 | M27: 44.807143 | N27: #VALUE! | O27: #VALUE! | P27: #VALUE! | Q27: #VALUE! | R27: 0 | S27: #VALUE! | T27: #VALUE! | U27: #VALUE! | V27: #VALUE! | W27: #VALUE! | X27: #VALUE! | Y27: #VALUE! | Z27: #VALUE! | AB27: 非採用特別 | AC27: #VALUE! | AD27: 1400 | AE27: 70420 | AF27: 62730 | AG27: =AE27-AF27 -> 7690
A28: 247 | B28: 309 | C28: ゾシン静注用４．５ | D28: メディセオ | F28: １０Ｖ | G28: 大鵬薬品 | H28: 1144 | I28: 11440 | J28: 10 | K28: V | L28: 10191 | M28: 1019.1 | N28: ｿｼﾝ001 | O28: ｿｼﾝ001 | P28: ゾシン静注用４．５ | Q28: ｿﾞｼﾝ | R28: 1 | T28: 1144 | U28: ｿﾞｼﾝｼﾞｮｳﾁｭｳﾖｳ4.5 | V28: 25 | W28: 注射剤 | X28: 0 | Z28: 8 | AB28: 注射 | AC28: 309 | AD28: 60 | AE28: 68640 | AF28: 61146 | AG28: =AE28-AF28 -> 7494
A29: 37 | B29: 75 | C29: アミティーザカプセル２４μｇ | D29: アルフレッサ | E29: ＰＴＰ | F29: ５００Ｐ | G29: ヴィアトリス | H29: 96.9 | I29: 48450 | J29: 500 | K29: cap | L29: 41183 | M29: 82.366 | N29: ｱﾐﾃ001 | O29: ｱﾐﾃ001 | P29: アミティーザカプセル２４μｇ | Q29: ｱﾐﾃ | R29: 1 | T29: 96.9 | U29: ｱﾐﾃｨｰｻﾞｶﾌﾟｾﾙ24μg | V29: 2 | W29: カプセル | X29: 0 | Z29: 5 | AB29: 錠剤 | AC29: 75 | AD29: 706 | AE29: 68411.4 | AF29: 58150.396 | AG29: =AE29-AF29 -> 10261.004
A30: 505 | B30: 584 | C30: ベオーパ錠５０ｍｇ | D30: スズケン | E30: ＰＴＰ | F30: １００Ｔ | G30: 杏林製薬 | H30: 146.1 | I30: 14610 | J30: 100 | L30: 12478 | M30: 124.78 | N30: ﾍｵﾊ001 | O30: ﾍｵﾊ001 | P30: ベオーバ錠５０ｍｇ | R30: 1 | T30: 146.1 | U30: ﾍﾞｵ-ﾊﾞｼﾞﾖｳ50MG | V30: 1 | W30: 錠剤 | X30: 0 | Z30: 25 | AB30: 錠剤 | AC30: 584 | AD30: 435 | AE30: 63553.5 | AF30: 54279.3 | AG30: =AE30-AF30 -> 9274.2
A31: 67 | B31: 115 | C31: インチュニブ錠１ｍｇ | D31: メディセオ | E31: ＰＴＰ | F31: １００Ｔ | G31: 武田薬品工業 | H31: 398.8 | I31: 39880 | J31: 100 | K31: 錠 | L31: 35500 | M31: 355 | N31: ｲﾝﾁ001 | O31: ｲﾝﾁ001 | P31: インチュニブ錠１ｍｇ | Q31: ｲﾝﾁｭ | R31: 2 | T31: 398.8 | U31: ｲﾝﾁｭﾆﾌﾞｼﾞｮｳ1mg | V31: 1 | W31: 錠剤 | X31: 2 | Z31: 3 | AB31: 臨時 | AC31: 200115 | AD31: 142 | AE31: 56629.6 | AF31: 50410 | AG31: =AE31-AF31 -> 6219.6
A32: 224 | B32: 816 | C32: 生理食塩液「ＶＴＲＳ」１００ｍｌ | D32: メディセオ | F32: １００ｍｌｘ１０Ｖ | G32: ヴィアトリス | H32: 147 | I32: 1470 | J32: 10 | K32: 瓶 | L32: 1300 | M32: 130 | N32: ｾｲﾘ001 | O32: ｾｲﾘ001 | P32: 生理食塩液「ＶＴＲＳ」 | Q32: ｾｲｼｮｸ9 | R32: 1 | T32: 147 | U32: ｾｲﾘｼｮｸｴﾝｴｷ｢VTRS｣ | V32: 25 | W32: 注射剤 | X32: 0 | Z32: 9 | AB32: 注射 | AC32: 816 | AD32: 368 | AE32: 54096 | AF32: 47840 | AG32: =AE32-AF32 -> 6256
A33: 42 | B33: 81 | C33: アリドネパッチ５５ｍｇ | D33: スズケン | F33: ２８枚 | G33: 興和 | H33: 437.6 | I33: 12252.8 | J33: 28 | K33: 枚 | L33: 10608 | M33: 378.85714 | N33: ｱﾘﾄ002 | O33: ｱﾘﾄ002 | P33: アリドネパッチ５５ｍｇ | R33: 1 | T33: 437.6 | U33: ｱﾘﾄﾞﾈﾊﾟﾂﾁ55MG | V33: 19 | W33: 貼付剤 | X33: 2 | Z33: 3 | AB33: 外用 | AC33: 200081 | AD33: 123 | AE33: 53824.8 | AF33: 46599.429 | AG33: =AE33-AF33 -> 7225.3714
A34: 61 | B34: 108 | C34: イフェクサーＳＲカプセル７５ｍｇ | D34: アルフレッサ | E34: ＰＴＰ | F34: １００Ｔ | G34: ヴィアトリス | H34: 167.6 | I34: 16760 | J34: 100 | K34: 錠 | L34: 14414 | M34: 144.14 | N34: ｲﾌｴ002 | O34: ｲﾌｴ002 | P34: イフェクサーＳＲカプセル７５ｍｇ | Q34: ｲﾌｪｸ1 | R34: 1 | T34: 167.6 | U34: ｲﾌｪｸｻｰSRｶﾌﾟｾﾙ75mg | V34: 2 | W34: カプセル | X34: 2 | Z34: 6 | AB34: 錠剤 | AC34: 200108 | AD34: 318 | AE34: 53296.8 | AF34: 45836.52 | AG34: =AE34-AF34 -> 7460.28
A35: 531 | B35: 613 | C35: ホスホマイシンナトリウム静注用２ｇ「日医工」 | F35: ２ｇ×１０Ｖ | G35: 日医工 | H35: 863 | I35: 8630 | J35: 10 | K35: V | L35: 7845 | M35: 784.5 | N35: ﾎｽﾎ001 | O35: ﾎｽﾎ001 | P35: ホスホマイシンナトリウム静注用２ｇ「日医工」 | Q35: ﾎｽﾎﾏｲｼ | R35: 1 | T35: 863 | U35: ﾎｽﾎﾏｲｼﾝﾅﾄﾘｳﾑｼﾞｮｳﾁｭｳﾖｳ2g｢ﾆﾁｲｺｳ｣ | V35: 25 | W35: 注射剤 | X35: 0 | Z35: 8 | AB35: 注射 | AC35: 613 | AD35: 57 | AE35: 49191 | AF35: 44716.5 | AG35: =AE35-AF35 -> 4474.5
A36: 62 | B36: 109 | C36: イベニティ皮下注１０５ｍｇシリンジ | D36: アルフレッサ | F36: ２筒 | G36: アステラス製薬 | H36: 25061 | I36: 50122 | J36: 2 | K36: 本 | L36: 43706 | M36: 21853 | N36: ｲﾍﾆ001 | O36: ｲﾍﾆ001 | P36: イベニティ皮下注１０５ｍｇシリンジ | Q36: ｲﾍﾞﾆ | R36: 1 | T36: 25061 | U36: ｲﾍﾞﾆﾃｨﾋｶﾁｭｳ105mgｼﾘﾝｼﾞ | V36: 25 | W36: 注射剤 | X36: 0 | Z36: 11 | AB36: 注射 | AC36: 109 | AD36: 2 | AE36: 50122 | AF36: 43706 | AG36: =AE36-AF36 -> 6416
A37: 非採用 | B37: 448 | C37: ノウリアスト錠２０ｍｇ | D37: メディセオ | E37: ＰＴＰ | F37: １００Ｔ | G37: 協和キリン | H37: 770.6 | I37: 77060 | J37: 100 | K37: 錠 | L37: 68652 | M37: 686.52 | N37: #VALUE! | O37: #VALUE! | P37: #VALUE! | Q37: #VALUE! | R37: 0 | S37: #VALUE! | T37: #VALUE! | U37: #VALUE! | V37: #VALUE! | W37: #VALUE! | X37: #VALUE! | Y37: #VALUE! | Z37: #VALUE! | AA37: 非採用 | AB37: 無し | AC37: #VALUE! | AD37: 62 | AE37: 47777.2 | AF37: 42564.24 | AG37: =AE37-AF37 -> 5212.96
A38: 212 | B38: 272 | C38: ストロメクトール錠３ｍｇ | D38: アルフレッサ | E38: ＰＴＰ | F38: １０Ｔ | G38: マルホ | H38: 574.8 | I38: 5748 | J38: 10 | K38: 錠 | L38: 5058 | M38: 505.8 | N38: ｽﾄﾛ001 | O38: ｽﾄﾛ001 | P38: ストロメクトール錠３ｍｇ | Q38: ｽﾄﾛﾒｸﾄ | R38: 2 | T38: 574.8 | U38: ｽﾄﾛﾒｸﾄｰﾙｼﾞｮｳ3mg | V38: 1 | W38: 錠剤 | X38: 2 | Z38: 3 | AB38: 臨時 | AC38: 200272 | AD38: 83 | AE38: 47708.4 | AF38: 41981.4 | AG38: =AE38-AF38 -> 5727
A39: 651 | B39: 767 | C39: レベチラセタム点滴静注５００ｍｇ「明治」 | D39: アルフレッサ | F39: ５ｍｌｘ１０Ａ | G39: meijiseika | H39: 669 | I39: 6690 | J39: 10 | K39: A | L39: 5887 | M39: 588.7 | N39: ﾚﾍﾁ003 | O39: ﾚﾍﾁ003 | P39: レベチラセタム点滴静注５００ｍｇ「明治」 | Q39: ﾚﾍﾞﾁﾁ | R39: 1 | T39: 669 | U39: ﾚﾍﾞﾁﾗｾﾀﾑﾃﾝﾃｷｼﾞｮｳﾁｭｳ500mg｢ﾒｲｼﾞ｣ | V39: 25 | W39: 注射剤 | X39: 0 | Z39: 9 | AB39: 注射 | AC39: 767 | AD39: 68 | AE39: 45492 | AF39: 40031.6 | AG39: =AE39-AF39 -> 5460.4
A40: 302 | B40: 9 | C40: ０５４ ツムラ ヨクカンサン | D40: メディセオ | E40: 粉 | F40: ２．５ｇＸ１８９ | G40: ツムラ | H40: 16.1 | I40: 7607.25 | J40: 472.5 | K40: g | L40: 6849 | M40: 14.495238 | N40: ﾂﾑﾗ054 | O40: ﾂﾑﾗ054 | P40: ツムラ抑肝散エキス顆粒（医療用） | Q40: ﾖｸｶ | R40: 1 | T40: 16.1 | U40: ﾂﾑﾗﾖｸｶﾝｻﾝｴｷｽｶﾘｭｳ(ｲﾘｮｳﾖｳ) | V40: 3 | W40: 散 | X40: 0 | Z40: 4 | AB40: 散剤 | AC40: 9 | AD40: 2752.5 | AE40: 44315.25 | AF40: 39898.143 | AG40: =AE40-AF40 -> 4417.1071
A41: 264 | B41: 332 | C41: タケキャブＯＤ錠２０ｍｇ | D41: メディセオ | E41: ＰＴＰ | F41: １００Ｔ | G41: 武田薬品工業 | H41: 141 | I41: 14100 | J41: 100 | K41: 錠 | L41: 12490 | M41: 124.9 | N41: ﾀｹｷ004 | O41: ﾀｹｷ004 | P41: タケキャブＯＤ錠２０ｍｇ | R41: 1 | T41: 141 | U41: ﾀｹｷﾔﾌﾞODｼﾞﾖｳ20MG | V41: 1 | W41: 錠剤 | X41: 0 | Z41: 25 | AB41: 錠剤 | AC41: 332 | AD41: 306 | AE41: 43146 | AF41: 38219.4 | AG41: =AE41-AF41 -> 4926.6
A42: 263 | B42: 330 | C42: タケキャブＯＤ錠１０ｍｇ | D42: メディセオ | E42: ＰＴＰ | F42: １００Ｔ | G42: 武田薬品工業 | H42: 94.3 | I42: 9430 | J42: 100 | K42: 錠 | L42: 8355 | M42: 83.55 | N42: ﾀｹｷ003 | O42: ﾀｹｷ003 | P42: タケキャブＯＤ錠１０ｍｇ | R42: 1 | T42: 94.3 | U42: ﾀｹｷﾔﾌﾞODｼﾞﾖｳ10MG | V42: 1 | W42: 錠剤 | X42: 0 | Z42: 25 | AB42: 錠剤 | AC42: 330 | AD42: 449 | AE42: 42340.7 | AF42: 37513.95 | AG42: =AE42-AF42 -> 4826.75
...

Sheet 統合マスタ
C3: 棚卸 | N3: マスタ | AD3: 合計 | AE3: =_xlfn.AGGREGATE(9,7,AE5:AE843) -> 8723165 | AF3: =_xlfn.AGGREGATE(9,7,AF5:AF843) -> 7615000.5 | AG3: =AE3-AF3 -> 1108164.5
B4: no | C4: 名称 | D4: 2025年度卸 | E4: 包装形態 | F4: 容量 | G4: メーカー | H4: 新単位薬価 | I4: 2025年度薬価 | J4: 単位数量 | K4: 薬価単位 | L4: 2025年納入価格 | M4: 単位納入価 | N4: コード(区分値) | O4: コード | P4: 名称 | Q4: ホストコード | R4: 採用区分（区分値）(区分値) | S4: 採用区分（区分値） | T4: 薬価 | U4: カナ名称 | V4: 剤形(区分値) | W4: 剤形 | X4: 毒劇薬（区分値）(区分値) | Y4: 毒劇薬（区分値） | Z4: 場所番号 | AA4: 非採用/処置薬 | AB4: Excelシート | AC4: ソートキー | AD4: 数量合計 | AE4: 薬価×数量 | AF4: 納入価×数量
A5: =元データ!P2 -> 295 | B5: 1 | C5: =DBCS(元データ!A2) -> ００７ ツムラ ハチミジオウガン | D5: =元データ!B2 -> メディセオ | E5: =DBCS(元データ!C2) -> 粉 | F5: =DBCS(元データ!D2) -> ２．５ｇｘ１８９ | G5: =元データ!E2 -> ツムラ | H5: =元データ!F2 -> 9.8 | I5: =元データ!G2 -> 4630.5 | J5: =元データ!H2 -> 472.5 | K5: =元データ!I2 -> ｇ | L5: =元データ!J2 -> 4093 | M5: =元データ!K2 -> 8.6624339 | N5: =IF(OFFSET(マスタ非採用削除!A$4,統合マスタ!$A5,0)="","",OFFSET(マスタ非採用削除!A$4,統合マスタ!$A5,0)) -> ﾂﾑﾗ007 | O5: =IF(OFFSET(マスタ非採用削除!B$4,統合マスタ!$A5,0)="","",OFFSET(マスタ非採用削除!B$4,統合マスタ!$A5,0)) -> ﾂﾑﾗ007 | P5: =IF(OFFSET(マスタ非採用削除!C$4,統合マスタ!$A5,0)="","",OFFSET(マスタ非採用削除!C$4,統合マスタ!$A5,0)) -> ツムラ八味地黄丸エキス顆粒（医療用） | Q5: =IF(OFFSET(マスタ非採用削除!D$4,統合マスタ!$A5,0)="","",OFFSET(マスタ非採用削除!D$4,統合マスタ!$A5,0)) -> ﾊﾁﾐ | R5: =IF(OR(A5="非採用",A5="処置薬",A5="非採用特別"),0,IF(OFFSET(マスタ非採用削除!E$4,統合マスタ!$A5,0)="","",OFFSET(マスタ非採用削除!E$4,統合マスタ!$A5,0))) -> 2 | S5: =IF(OFFSET(マスタ非採用削除!F$4,統合マスタ!$A5,0)="","",OFFSET(マスタ非採用削除!F$4,統合マスタ!$A5,0)) | T5: =IF(OFFSET(マスタ非採用削除!G$4,統合マスタ!$A5,0)="","",OFFSET(マスタ非採用削除!G$4,統合マスタ!$A5,0)) -> 9.8 | U5: =IF(OFFSET(マスタ非採用削除!H$4,統合マスタ!$A5,0)="","",OFFSET(マスタ非採用削除!H$4,統合マスタ!$A5,0)) -> ﾂﾑﾗﾊﾁﾐｼﾞｵｳｶﾞﾝｴｷｽｶﾘｭｳ(ｲﾘｮｳﾖｳ) | V5: =IF(OFFSET(マスタ非採用削除!I$4,統合マスタ!$A5,0)="","",OFFSET(マスタ非採用削除!I$4,統合マスタ!$A5,0)) -> 3 | W5: =IF(OFFSET(マスタ非採用削除!J$4,統合マスタ!$A5,0)="","",OFFSET(マスタ非採用削除!J$4,統合マスタ!$A5,0)) -> 散 | X5: =IF(OFFSET(マスタ非採用削除!K$4,統合マスタ!$A5,0)="","",OFFSET(マスタ非採用削除!K$4,統合マスタ!$A5,0)) -> 0 | Y5: =IF(OFFSET(マスタ非採用削除!L$4,統合マスタ!$A5,0)="","",OFFSET(マスタ非採用削除!L$4,統合マスタ!$A5,0)) | Z5: =IF(OFFSET(マスタ非採用削除!M$4,統合マスタ!$A5,0)="","",OFFSET(マスタ非採用削除!M$4,統合マスタ!$A5,0)) -> 4 | AA5: =IF(A5="非採用","非採用",IF(A5="処置薬","処置薬","")) | AB5: =IF(A5="非採用特別","非採用特別",IF(R5=2,"臨時", IF(COUNTIF(分類!$H$8:$H$25, 統合マスタ!V5)>0, 分類!$G$7, IF(COUNTIF(分類!$K$8:$K$25, 統合マスタ!V5)>0, 分類!$J$7, IF(COUNTIF(分類!$N$8:$N$25, 統合マスタ!V5)>0, 分類!$M$7, IF(COUNTIF(分類!$Q$8:$Q$25, 統合マスタ!V5)>0, 分類!$P$7, IF(COUNTIF(分類!$T$8:$T$25, 統合マスタ!V5)>0, 分類!$S$7, "無し"))))))) -> 臨時 | AC5: =X5*100000+B5 -> 1 | AD5: {=IF(A5="非採用","非採用",OFFSET( INDIRECT("'" & AB5 & "'!A4"), MATCH(B5, INDIRECT("'" & AB5 & "'!C5:C1000"), 0), MATCH("合計", INDIRECT("'" & AB5 & "'!4:4"), 0) - 1 ))} -> 395 | AE5: =H5*AD5 -> 3871 | AF5: =M5*AD5 -> 3421.6614
A6: =元データ!P3 -> 295 | B6: =B5+1 -> 2 | C6: =DBCS(元データ!A3) -> ００７ ツムラ ハチミジオウガン | D6: =元データ!B3 | E6: =DBCS(元データ!C3) -> 粉 | F6: =DBCS(元データ!D3) -> ２．５ｇｘ４２ | G6: =元データ!E3 -> ツムラ | H6: =元データ!F3 -> 9.8 | I6: =元データ!G3 -> 1029 | J6: =元データ!H3 -> 105 | K6: =元データ!I3 -> ｇ | L6: =元データ!J3 -> 935 | M6: =元データ!K3 -> 8.9047619 | N6: =IF(OFFSET(マスタ非採用削除!A$4,統合マスタ!$A6,0)="","",OFFSET(マスタ非採用削除!A$4,統合マスタ!$A6,0)) -> ﾂﾑﾗ007 | O6: =IF(OFFSET(マスタ非採用削除!B$4,統合マスタ!$A6,0)="","",OFFSET(マスタ非採用削除!B$4,統合マスタ!$A6,0)) -> ﾂﾑﾗ007 | P6: =IF(OFFSET(マスタ非採用削除!C$4,統合マスタ!$A6,0)="","",OFFSET(マスタ非採用削除!C$4,統合マスタ!$A6,0)) -> ツムラ八味地黄丸エキス顆粒（医療用） | Q6: =IF(OFFSET(マスタ非採用削除!D$4,統合マスタ!$A6,0)="","",OFFSET(マスタ非採用削除!D$4,統合マスタ!$A6,0)) -> ﾊﾁﾐ | R6: =IF(OR(A6="非採用",A6="処置薬",A6="非採用特別"),0,IF(OFFSET(マスタ非採用削除!E$4,統合マスタ!$A6,0)="","",OFFSET(マスタ非採用削除!E$4,統合マスタ!$A6,0))) -> 2 | S6: =IF(OFFSET(マスタ非採用削除!F$4,統合マスタ!$A6,0)="","",OFFSET(マスタ非採用削除!F$4,統合マスタ!$A6,0)) | T6: =IF(OFFSET(マスタ非採用削除!G$4,統合マスタ!$A6,0)="","",OFFSET(マスタ非採用削除!G$4,統合マスタ!$A6,0)) -> 9.8 | U6: =IF(OFFSET(マスタ非採用削除!H$4,統合マスタ!$A6,0)="","",OFFSET(マスタ非採用削除!H$4,統合マスタ!$A6,0)) -> ﾂﾑﾗﾊﾁﾐｼﾞｵｳｶﾞﾝｴｷｽｶﾘｭｳ(ｲﾘｮｳﾖｳ) | V6: =IF(OFFSET(マスタ非採用削除!I$4,統合マスタ!$A6,0)="","",OFFSET(マスタ非採用削除!I$4,統合マスタ!$A6,0)) -> 3 | W6: =IF(OFFSET(マスタ非採用削除!J$4,統合マスタ!$A6,0)="","",OFFSET(マスタ非採用削除!J$4,統合マスタ!$A6,0)) -> 散 | X6: =IF(OFFSET(マスタ非採用削除!K$4,統合マスタ!$A6,0)="","",OFFSET(マスタ非採用削除!K$4,統合マスタ!$A6,0)) -> 0 | Y6: =IF(OFFSET(マスタ非採用削除!L$4,統合マスタ!$A6,0)="","",OFFSET(マスタ非採用削除!L$4,統合マスタ!$A6,0)) | Z6: =IF(OFFSET(マスタ非採用削除!M$4,統合マスタ!$A6,0)="","",OFFSET(マスタ非採用削除!M$4,統合マスタ!$A6,0)) -> 4 | AA6: =IF(A6="非採用","非採用",IF(A6="処置薬","処置薬","")) | AB6: =IF(A6="非採用特別","非採用特別",IF(R6=2,"臨時", IF(COUNTIF(分類!$H$8:$H$25, 統合マスタ!V6)>0, 分類!$G$7, IF(COUNTIF(分類!$K$8:$K$25, 統合マスタ!V6)>0, 分類!$J$7, IF(COUNTIF(分類!$N$8:$N$25, 統合マスタ!V6)>0, 分類!$M$7, IF(COUNTIF(分類!$Q$8:$Q$25, 統合マスタ!V6)>0, 分類!$P$7, IF(COUNTIF(分類!$T$8:$T$25, 統合マスタ!V6)>0, 分類!$S$7, "無し"))))))) -> 臨時 | AC6: =X6*100000+B6 -> 2 | AD6: {=IF(A6="非採用","非採用",OFFSET( INDIRECT("'" & AB6 & "'!A4"), MATCH(B6, INDIRECT("'" & AB6 & "'!C5:C1000"), 0), MATCH("合計", INDIRECT("'" & AB6 & "'!4:4"), 0) - 1 ))} -> 0 | AE6: =H6*AD6 -> 0 | AF6: =M6*AD6 -> 0
A7: =元データ!P4 -> 296 | B7: =B6+1 -> 3 | C7: =DBCS(元データ!A4) -> ０１２ ツムラ サイコカリュウコツボレイトウ | D7: =元データ!B4 -> メディセオ | E7: =DBCS(元データ!C4) -> 粉 | F7: =DBCS(元データ!D4) -> ２．５ｇｘ１８９ | G7: =元データ!E4 -> ツムラ | H7: =元データ!F4 -> 20.3 | I7: =元データ!G4 -> 9591.75 | J7: =元データ!H4 -> 472.5 | K7: =元データ!I4 -> g | L7: =元データ!J4 -> 8544 | M7: =元データ!K4 -> 18.08254 | N7: =IF(OFFSET(マスタ非採用削除!A$4,統合マスタ!$A7,0)="","",OFFSET(マスタ非採用削除!A$4,統合マスタ!$A7,0)) -> ﾂﾑﾗ012 | O7: =IF(OFFSET(マスタ非採用削除!B$4,統合マスタ!$A7,0)="","",OFFSET(マスタ非採用削除!B$4,統合マスタ!$A7,0)) -> ﾂﾑﾗ012 | P7: =IF(OFFSET(マスタ非採用削除!C$4,統合マスタ!$A7,0)="","",OFFSET(マスタ非採用削除!C$4,統合マスタ!$A7,0)) -> ツムラ柴胡加竜骨牡蛎湯エキス顆粒（医療用） | Q7: =IF(OFFSET(マスタ非採用削除!D$4,統合マスタ!$A7,0)="","",OFFSET(マスタ非採用削除!D$4,統合マスタ!$A7,0)) -> ｻｲｺ | R7: =IF(OR(A7="非採用",A7="処置薬",A7="非採用特別"),0,IF(OFFSET(マスタ非採用削除!E$4,統合マスタ!$A7,0)="","",OFFSET(マスタ非採用削除!E$4,統合マスタ!$A7,0))) -> 2 | S7: =IF(OFFSET(マスタ非採用削除!F$4,統合マスタ!$A7,0)="","",OFFSET(マスタ非採用削除!F$4,統合マスタ!$A7,0)) | T7: =IF(OFFSET(マスタ非採用削除!G$4,統合マスタ!$A7,0)="","",OFFSET(マスタ非採用削除!G$4,統合マスタ!$A7,0)) -> 20.3 | U7: =IF(OFFSET(マスタ非採用削除!H$4,統合マスタ!$A7,0)="","",OFFSET(マスタ非採用削除!H$4,統合マスタ!$A7,0)) -> ﾂﾑﾗｻｲｺｶﾘｭｳｺﾂﾎﾞﾚｲﾄｳｴｷｽｶﾘｭｳ(ｲﾘｮｳﾖｳ) | V7: =IF(OFFSET(マスタ非採用削除!I$4,統合マスタ!$A7,0)="","",OFFSET(マスタ非採用削除!I$4,統合マスタ!$A7,0)) -> 3 | W7: =IF(OFFSET(マスタ非採用削除!J$4,統合マスタ!$A7,0)="","",OFFSET(マスタ非採用削除!J$4,統合マスタ!$A7,0)) -> 散 | X7: =IF(OFFSET(マスタ非採用削除!K$4,統合マスタ!$A7,0)="","",OFFSET(マスタ非採用削除!K$4,統合マスタ!$A7,0)) -> 0 | Y7: =IF(OFFSET(マスタ非採用削除!L$4,統合マスタ!$A7,0)="","",OFFSET(マスタ非採用削除!L$4,統合マスタ!$A7,0)) | Z7: =IF(OFFSET(マスタ非採用削除!M$4,統合マスタ!$A7,0)="","",OFFSET(マスタ非採用削除!M$4,統合マスタ!$A7,0)) -> 4 | AA7: =IF(A7="非採用","非採用",IF(A7="処置薬","処置薬","")) | AB7: =IF(A7="非採用特別","非採用特別",IF(R7=2,"臨時", IF(COUNTIF(分類!$H$8:$H$25, 統合マスタ!V7)>0, 分類!$G$7, IF(COUNTIF(分類!$K$8:$K$25, 統合マスタ!V7)>0, 分類!$J$7, IF(COUNTIF(分類!$N$8:$N$25, 統合マスタ!V7)>0, 分類!$M$7, IF(COUNTIF(分類!$Q$8:$Q$25, 統合マスタ!V7)>0, 分類!$P$7, IF(COUNTIF(分類!$T$8:$T$25, 統合マスタ!V7)>0, 分類!$S$7, "無し"))))))) -> 臨時 | AC7: =X7*100000+B7 -> 3 | AD7: {=IF(A7="非採用","非採用",OFFSET( INDIRECT("'" & AB7 & "'!A4"), MATCH(B7, INDIRECT("'" & AB7 & "'!C5:C1000"), 0), MATCH("合計", INDIRECT("'" & AB7 & "'!4:4"), 0) - 1 ))} -> 247.5 | AE7: =H7*AD7 -> 5024.25 | AF7: =M7*AD7 -> 4475.4286
A8: =元データ!P5 -> 297 | B8: =B7+1 -> 4 | C8: =DBCS(元データ!A5) -> ０１６ ツムラ ハンゲコウボクトウ | D8: =元データ!B5 -> メディセオ | E8: =DBCS(元データ!C5) -> 粉 | F8: =DBCS(元データ!D5) -> ２．５ｇｘ１８９ | G8: =元データ!E5 -> ツムラ | H8: =元データ!F5 -> 14.6 | I8: =元データ!G5 -> 6898.5 | J8: =元データ!H5 -> 472.5 | K8: =元データ!I5 -> ｇ | L8: =元データ!J5 -> 6211 | M8: =元データ!K5 -> 13.144974 | N8: =IF(OFFSET(マスタ非採用削除!A$4,統合マスタ!$A8,0)="","",OFFSET(マスタ非採用削除!A$4,統合マスタ!$A8,0)) -> ﾂﾑﾗ016 | O8: =IF(OFFSET(マスタ非採用削除!B$4,統合マスタ!$A8,0)="","",OFFSET(マスタ非採用削除!B$4,統合マスタ!$A8,0)) -> ﾂﾑﾗ016 | P8: =IF(OFFSET(マスタ非採用削除!C$4,統合マスタ!$A8,0)="","",OFFSET(マスタ非採用削除!C$4,統合マスタ!$A8,0)) -> ツムラ半夏厚朴湯エキス顆粒（医療用） | Q8: =IF(OFFSET(マスタ非採用削除!D$4,統合マスタ!$A8,0)="","",OFFSET(マスタ非採用削除!D$4,統合マスタ!$A8,0)) -> ﾊﾝｹﾞｺ | R8: =IF(OR(A8="非採用",A8="処置薬",A8="非採用特別"),0,IF(OFFSET(マスタ非採用削除!E$4,統合マスタ!$A8,0)="","",OFFSET(マスタ非採用削除!E$4,統合マスタ!$A8,0))) -> 2 | S8: =IF(OFFSET(マスタ非採用削除!F$4,統合マスタ!$A8,0)="","",OFFSET(マスタ非採用削除!F$4,統合マスタ!$A8,0)) | T8: =IF(OFFSET(マスタ非採用削除!G$4,統合マスタ!$A8,0)="","",OFFSET(マスタ非採用削除!G$4,統合マスタ!$A8,0)) -> 14.6 | U8: =IF(OFFSET(マスタ非採用削除!H$4,統合マスタ!$A8,0)="","",OFFSET(マスタ非採用削除!H$4,統合マスタ!$A8,0)) -> ﾂﾑﾗﾊﾝｹﾞｺｳﾎﾞｸﾄｳｴｷｽｶﾘｭｳ(ｲﾘｮｳﾖｳ) | V8: =IF(OFFSET(マスタ非採用削除!I$4,統合マスタ!$A8,0)="","",OFFSET(マスタ非採用削除!I$4,統合マスタ!$A8,0)) -> 3 | W8: =IF(OFFSET(マスタ非採用削除!J$4,統合マスタ!$A8,0)="","",OFFSET(マスタ非採用削除!J$4,統合マスタ!$A8,0)) -> 散 | X8: =IF(OFFSET(マスタ非採用削除!K$4,統合マスタ!$A8,0)="","",OFFSET(マスタ非採用削除!K$4,統合マスタ!$A8,0)) -> 0 | Y8: =IF(OFFSET(マスタ非採用削除!L$4,統合マスタ!$A8,0)="","",OFFSET(マスタ非採用削除!L$4,統合マスタ!$A8,0)) | Z8: =IF(OFFSET(マスタ非採用削除!M$4,統合マスタ!$A8,0)="","",OFFSET(マスタ非採用削除!M$4,統合マスタ!$A8,0)) -> 4 | AA8: =IF(A8="非採用","非採用",IF(A8="処置薬","処置薬","")) | AB8: =IF(A8="非採用特別","非採用特別",IF(R8=2,"臨時", IF(COUNTIF(分類!$H$8:$H$25, 統合マスタ!V8)>0, 分類!$G$7, IF(COUNTIF(分類!$K$8:$K$25, 統合マスタ!V8)>0, 分類!$J$7, IF(COUNTIF(分類!$N$8:$N$25, 統合マスタ!V8)>0, 分類!$M$7, IF(COUNTIF(分類!$Q$8:$Q$25, 統合マスタ!V8)>0, 分類!$P$7, IF(COUNTIF(分類!$T$8:$T$25, 統合マスタ!V8)>0, 分類!$S$7, "無し"))))))) -> 臨時 | AC8: =X8*100000+B8 -> 4 | AD8: {=IF(A8="非採用","非採用",OFFSET( INDIRECT("'" & AB8 & "'!A4"), MATCH(B8, INDIRECT("'" & AB8 & "'!C5:C1000"), 0), MATCH("合計", INDIRECT("'" & AB8 & "'!4:4"), 0) - 1 ))} -> 372.5 | AE8: =H8*AD8 -> 5438.5 | AF8: =M8*AD8 -> 4896.5026
A9: =元データ!P6 -> 298 | B9: =B8+1 -> 5 | C9: =DBCS(元データ!A6) -> ０１７ ツムラ ゴレイサン | D9: =元データ!B6 -> メディセオ | E9: =DBCS(元データ!C6) -> 粉 | F9: =DBCS(元データ!D6) -> ２．５ｇｘ１８９ | G9: =元データ!E6 -> ツムラ | H9: =元データ!F6 -> 13.6 | I9: =元データ!G6 -> 6426 | J9: =元データ!H6 -> 472.5 | K9: =元データ!I6 -> g | L9: =元データ!J6 -> 5728 | M9: =元データ!K6 -> 12.122751 | N9: =IF(OFFSET(マスタ非採用削除!A$4,統合マスタ!$A9,0)="","",OFFSET(マスタ非採用削除!A$4,統合マスタ!$A9,0)) -> ﾂﾑﾗ017 | O9: =IF(OFFSET(マスタ非採用削除!B$4,統合マスタ!$A9,0)="","",OFFSET(マスタ非採用削除!B$4,統合マスタ!$A9,0)) -> ﾂﾑﾗ017 | P9: =IF(OFFSET(マスタ非採用削除!C$4,統合マスタ!$A9,0)="","",OFFSET(マスタ非採用削除!C$4,統合マスタ!$A9,0)) -> ツムラ五苓散エキス顆粒（医療用） | Q9: =IF(OFFSET(マスタ非採用削除!D$4,統合マスタ!$A9,0)="","",OFFSET(マスタ非採用削除!D$4,統合マスタ!$A9,0)) -> ｺﾞﾚｲ | R9: =IF(OR(A9="非採用",A9="処置薬",A9="非採用特別"),0,IF(OFFSET(マスタ非採用削除!E$4,統合マスタ!$A9,0)="","",OFFSET(マスタ非採用削除!E$4,統合マスタ!$A9,0))) -> 1 | S9: =IF(OFFSET(マスタ非採用削除!F$4,統合マスタ!$A9,0)="","",OFFSET(マスタ非採用削除!F$4,統合マスタ!$A9,0)) | T9: =IF(OFFSET(マスタ非採用削除!G$4,統合マスタ!$A9,0)="","",OFFSET(マスタ非採用削除!G$4,統合マスタ!$A9,0)) -> 13.6 | U9: =IF(OFFSET(マスタ非採用削除!H$4,統合マスタ!$A9,0)="","",OFFSET(マスタ非採用削除!H$4,統合マスタ!$A9,0)) -> ﾂﾑﾗｺﾞﾚｲｻﾝｴｷｽｶﾘｭｳ(ｲﾘｮｳﾖｳ) | V9: =IF(OFFSET(マスタ非採用削除!I$4,統合マスタ!$A9,0)="","",OFFSET(マスタ非採用削除!I$4,統合マスタ!$A9,0)) -> 3 | W9: =IF(OFFSET(マスタ非採用削除!J$4,統合マスタ!$A9,0)="","",OFFSET(マスタ非採用削除!J$4,統合マスタ!$A9,0)) -> 散 | X9: =IF(OFFSET(マスタ非採用削除!K$4,統合マスタ!$A9,0)="","",OFFSET(マスタ非採用削除!K$4,統合マスタ!$A9,0)) -> 0 | Y9: =IF(OFFSET(マスタ非採用削除!L$4,統合マスタ!$A9,0)="","",OFFSET(マスタ非採用削除!L$4,統合マスタ!$A9,0)) | Z9: =IF(OFFSET(マスタ非採用削除!M$4,統合マスタ!$A9,0)="","",OFFSET(マスタ非採用削除!M$4,統合マスタ!$A9,0)) -> 4 | AA9: =IF(A9="非採用","非採用",IF(A9="処置薬","処置薬","")) | AB9: =IF(A9="非採用特別","非採用特別",IF(R9=2,"臨時", IF(COUNTIF(分類!$H$8:$H$25, 統合マスタ!V9)>0, 分類!$G$7, IF(COUNTIF(分類!$K$8:$K$25, 統合マスタ!V9)>0, 分類!$J$7, IF(COUNTIF(分類!$N$8:$N$25, 統合マスタ!V9)>0, 分類!$M$7, IF(COUNTIF(分類!$Q$8:$Q$25, 統合マスタ!V9)>0, 分類!$P$7, IF(COUNTIF(分類!$T$8:$T$25, 統合マスタ!V9)>0, 分類!$S$7, "無し"))))))) -> 散剤 | AC9: =X9*100000+B9 -> 5 | AD9: {=IF(A9="非採用","非採用",OFFSET( INDIRECT("'" & AB9 & "'!A4"), MATCH(B9, INDIRECT("'" & AB9 & "'!C5:C1000"), 0), MATCH("合計", INDIRECT("'" & AB9 & "'!4:4"), 0) - 1 ))} -> 237.5 | AE9: =H9*AD9 -> 3230 | AF9: =M9*AD9 -> 2879.1534
A10: =元データ!P7 -> 299 | B10: =B9+1 -> 6 | C10: =DBCS(元データ!A7) -> ０１９ ツムラ ショウセイリュウトウ | D10: =元データ!B7 -> メディセオ | E10: =DBCS(元データ!C7) -> 粉 | F10: =DBCS(元データ!D7) -> ３ｇＸ４２ | G10: =元データ!E7 -> ツムラ | H10: =元データ!F7 -> 12.8 | I10: =元データ!G7 -> 1612.8 | J10: =元データ!H7 -> 126 | K10: =元データ!I7 -> g | L10: =元データ!J7 -> 1465 | M10: =元データ!K7 -> 11.626984 | N10: =IF(OFFSET(マスタ非採用削除!A$4,統合マスタ!$A10,0)="","",OFFSET(マスタ非採用削除!A$4,統合マスタ!$A10,0)) -> ﾂﾑﾗ019 | O10: =IF(OFFSET(マスタ非採用削除!B$4,統合マスタ!$A10,0)="","",OFFSET(マスタ非採用削除!B$4,統合マスタ!$A10,0)) -> ﾂﾑﾗ019 | P10: =IF(OFFSET(マスタ非採用削除!C$4,統合マスタ!$A10,0)="","",OFFSET(マスタ非採用削除!C$4,統合マスタ!$A10,0)) -> ツムラ小青竜湯エキス顆粒（医療用） | Q10: =IF(OFFSET(マスタ非採用削除!D$4,統合マスタ!$A10,0)="","",OFFSET(マスタ非採用削除!D$4,統合マスタ!$A10,0)) | R10: =IF(OR(A10="非採用",A10="処置薬",A10="非採用特別"),0,IF(OFFSET(マスタ非採用削除!E$4,統合マスタ!$A10,0)="","",OFFSET(マスタ非採用削除!E$4,統合マスタ!$A10,0))) -> 2 | S10: =IF(OFFSET(マスタ非採用削除!F$4,統合マスタ!$A10,0)="","",OFFSET(マスタ非採用削除!F$4,統合マスタ!$A10,0)) | T10: =IF(OFFSET(マスタ非採用削除!G$4,統合マスタ!$A10,0)="","",OFFSET(マスタ非採用削除!G$4,統合マスタ!$A10,0)) -> 12.8 | U10: =IF(OFFSET(マスタ非採用削除!H$4,統合マスタ!$A10,0)="","",OFFSET(マスタ非採用削除!H$4,統合マスタ!$A10,0)) -> ﾂﾑﾗｼﾖｳｾｲﾘﾕｳﾄｳｴｷｽｶﾘﾕｳｲﾘﾖｳﾖｳ | V10: =IF(OFFSET(マスタ非採用削除!I$4,統合マスタ!$A10,0)="","",OFFSET(マスタ非採用削除!I$4,統合マスタ!$A10,0)) -> 5 | W10: =IF(OFFSET(マスタ非採用削除!J$4,統合マスタ!$A10,0)="","",OFFSET(マスタ非採用削除!J$4,統合マスタ!$A10,0)) -> 顆粒 | X10: =IF(OFFSET(マスタ非採用削除!K$4,統合マスタ!$A10,0)="","",OFFSET(マスタ非採用削除!K$4,統合マスタ!$A10,0)) -> 0 | Y10: =IF(OFFSET(マスタ非採用削除!L$4,統合マスタ!$A10,0)="","",OFFSET(マスタ非採用削除!L$4,統合マスタ!$A10,0)) | Z10: =IF(OFFSET(マスタ非採用削除!M$4,統合マスタ!$A10,0)="","",OFFSET(マスタ非採用削除!M$4,統合マスタ!$A10,0)) -> 4 | AA10: =IF(A10="非採用","非採用",IF(A10="処置薬","処置薬","")) | AB10: =IF(A10="非採用特別","非採用特別",IF(R10=2,"臨時", IF(COUNTIF(分類!$H$8:$H$25, 統合マスタ!V10)>0, 分類!$G$7, IF(COUNTIF(分類!$K$8:$K$25, 統合マスタ!V10)>0, 分類!$J$7, IF(COUNTIF(分類!$N$8:$N$25, 統合マスタ!V10)>0, 分類!$M$7, IF(COUNTIF(分類!$Q$8:$Q$25, 統合マスタ!V10)>0, 分類!$P$7, IF(COUNTIF(分類!$T$8:$T$25, 統合マスタ!V10)>0, 分類!$S$7, "無し"))))))) -> 臨時 | AC10: =X10*100000+B10 -> 6 | AD10: {=IF(A10="非採用","非採用",OFFSET( INDIRECT("'" & AB10 & "'!A4"), MATCH(B10, INDIRECT("'" & AB10 & "'!C5:C1000"), 0), MATCH("合計", INDIRECT("'" & AB10 & "'!4:4"), 0) - 1 ))} -> 15 | AE10: =H10*AD10 -> 192 | AF10: =M10*AD10 -> 174.40476
A11: =元データ!P8 -> 301 | B11: =B10+1 -> 7 | C11: =DBCS(元データ!A8) -> ０４３ ツムラ リツクンシトウ | D11: =元データ!B8 -> メディセオ | E11: =DBCS(元データ!C8) -> 粉 | F11: =DBCS(元データ!D8) -> ２．５ｇｘ１８９ | G11: =元データ!E8 -> ツムラ | H11: =元データ!F8 -> 18 | I11: =元データ!G8 -> 8505 | J11: =元データ!H8 -> 472.5 | K11: =元データ!I8 -> g | L11: =元データ!J8 -> 7576 | M11: =元データ!K8 -> 16.033862 | N11: =IF(OFFSET(マスタ非採用削除!A$4,統合マスタ!$A11,0)="","",OFFSET(マスタ非採用削除!A$4,統合マスタ!$A11,0)) -> ﾂﾑﾗ043 | O11: =IF(OFFSET(マスタ非採用削除!B$4,統合マスタ!$A11,0)="","",OFFSET(マスタ非採用削除!B$4,統合マスタ!$A11,0)) -> ﾂﾑﾗ043 | P11: =IF(OFFSET(マスタ非採用削除!C$4,統合マスタ!$A11,0)="","",OFFSET(マスタ非採用削除!C$4,統合マスタ!$A11,0)) -> ツムラ六君子湯エキス顆粒（医療用） | Q11: =IF(OFFSET(マスタ非採用削除!D$4,統合マスタ!$A11,0)="","",OFFSET(マスタ非採用削除!D$4,統合マスタ!$A11,0)) -> ﾘｯｸ | R11: =IF(OR(A11="非採用",A11="処置薬",A11="非採用特別"),0,IF(OFFSET(マスタ非採用削除!E$4,統合マスタ!$A11,0)="","",OFFSET(マスタ非採用削除!E$4,統合マスタ!$A11,0))) -> 2 | S11: =IF(OFFSET(マスタ非採用削除!F$4,統合マスタ!$A11,0)="","",OFFSET(マスタ非採用削除!F$4,統合マスタ!$A11,0)) | T11: =IF(OFFSET(マスタ非採用削除!G$4,統合マスタ!$A11,0)="","",OFFSET(マスタ非採用削除!G$4,統合マスタ!$A11,0)) -> 18 | U11: =IF(OFFSET(マスタ非採用削除!H$4,統合マスタ!$A11,0)="","",OFFSET(マスタ非採用削除!H$4,統合マスタ!$A11,0)) -> ﾂﾑﾗﾘｯｸﾝｼﾄｳｴｷｽｶﾘｭｳ(ｲﾘｮｳﾖｳ) | V11: =IF(OFFSET(マスタ非採用削除!I$4,統合マスタ!$A11,0)="","",OFFSET(マスタ非採用削除!I$4,統合マスタ!$A11,0)) -> 3 | W11: =IF(OFFSET(マスタ非採用削除!J$4,統合マスタ!$A11,0)="","",OFFSET(マスタ非採用削除!J$4,統合マスタ!$A11,0)) -> 散 | X11: =IF(OFFSET(マスタ非採用削除!K$4,統合マスタ!$A11,0)="","",OFFSET(マスタ非採用削除!K$4,統合マスタ!$A11,0)) -> 0 | Y11: =IF(OFFSET(マスタ非採用削除!L$4,統合マスタ!$A11,0)="","",OFFSET(マスタ非採用削除!L$4,統合マスタ!$A11,0)) | Z11: =IF(OFFSET(マスタ非採用削除!M$4,統合マスタ!$A11,0)="","",OFFSET(マスタ非採用削除!M$4,統合マスタ!$A11,0)) -> 4 | AA11: =IF(A11="非採用","非採用",IF(A11="処置薬","処置薬","")) | AB11: =IF(A11="非採用特別","非採用特別",IF(R11=2,"臨時", IF(COUNTIF(分類!$H$8:$H$25, 統合マスタ!V11)>0, 分類!$G$7, IF(COUNTIF(分類!$K$8:$K$25, 統合マスタ!V11)>0, 分類!$J$7, IF(COUNTIF(分類!$N$8:$N$25, 統合マスタ!V11)>0, 分類!$M$7, IF(COUNTIF(分類!$Q$8:$Q$25, 統合マスタ!V11)>0, 分類!$P$7, IF(COUNTIF(分類!$T$8:$T$25, 統合マスタ!V11)>0, 分類!$S$7, "無し"))))))) -> 臨時 | AC11: =X11*100000+B11 -> 7 | AD11: {=IF(A11="非採用","非採用",OFFSET( INDIRECT("'" & AB11 & "'!A4"), MATCH(B11, INDIRECT("'" & AB11 & "'!C5:C1000"), 0), MATCH("合計", INDIRECT("'" & AB11 & "'!4:4"), 0) - 1 ))} -> 495 | AE11: =H11*AD11 -> 8910 | AF11: =M11*AD11 -> 7936.7619
A12: =元データ!P9 -> 非採用 | B12: =B11+1 -> 8 | C12: =DBCS(元データ!A9) -> ０４８ ツムラ ジュウゼンタイホトウ | D12: =元データ!B9 | E12: =DBCS(元データ!C9) -> 粉 | F12: =DBCS(元データ!D9) -> ２．５ｇｘ１８９包 | G12: =元データ!E9 -> ツムラ | H12: =元データ!F9 -> 18.4 | I12: =元データ!G9 -> 8694 | J12: =元データ!H9 -> 472.5 | K12: =元データ!I9 -> g | L12: =元データ!J9 -> 7750 | M12: =元データ!K9 -> 16.402116 | N12: =IF(OFFSET(マスタ非採用削除!A$4,統合マスタ!$A12,0)="","",OFFSET(マスタ非採用削除!A$4,統合マスタ!$A12,0)) -> #VALUE! | O12: =IF(OFFSET(マスタ非採用削除!B$4,統合マスタ!$A12,0)="","",OFFSET(マスタ非採用削除!B$4,統合マスタ!$A12,0)) -> #VALUE! | P12: =IF(OFFSET(マスタ非採用削除!C$4,統合マスタ!$A12,0)="","",OFFSET(マスタ非採用削除!C$4,統合マスタ!$A12,0)) -> #VALUE! | Q12: =IF(OFFSET(マスタ非採用削除!D$4,統合マスタ!$A12,0)="","",OFFSET(マスタ非採用削除!D$4,統合マスタ!$A12,0)) -> #VALUE! | R12: =IF(OR(A12="非採用",A12="処置薬",A12="非採用特別"),0,IF(OFFSET(マスタ非採用削除!E$4,統合マスタ!$A12,0)="","",OFFSET(マスタ非採用削除!E$4,統合マスタ!$A12,0))) -> 0 | S12: =IF(OFFSET(マスタ非採用削除!F$4,統合マスタ!$A12,0)="","",OFFSET(マスタ非採用削除!F$4,統合マスタ!$A12,0)) -> #VALUE! | T12: =IF(OFFSET(マスタ非採用削除!G$4,統合マスタ!$A12,0)="","",OFFSET(マスタ非採用削除!G$4,統合マスタ!$A12,0)) -> #VALUE! | U12: =IF(OFFSET(マスタ非採用削除!H$4,統合マスタ!$A12,0)="","",OFFSET(マスタ非採用削除!H$4,統合マスタ!$A12,0)) -> #VALUE! | V12: =IF(OFFSET(マスタ非採用削除!I$4,統合マスタ!$A12,0)="","",OFFSET(マスタ非採用削除!I$4,統合マスタ!$A12,0)) -> #VALUE! | W12: =IF(OFFSET(マスタ非採用削除!J$4,統合マスタ!$A12,0)="","",OFFSET(マスタ非採用削除!J$4,統合マスタ!$A12,0)) -> #VALUE! | X12: =IF(OFFSET(マスタ非採用削除!K$4,統合マスタ!$A12,0)="","",OFFSET(マスタ非採用削除!K$4,統合マスタ!$A12,0)) -> #VALUE! | Y12: =IF(OFFSET(マスタ非採用削除!L$4,統合マスタ!$A12,0)="","",OFFSET(マスタ非採用削除!L$4,統合マスタ!$A12,0)) -> #VALUE! | Z12: =IF(OFFSET(マスタ非採用削除!M$4,統合マスタ!$A12,0)="","",OFFSET(マスタ非採用削除!M$4,統合マスタ!$A12,0)) -> #VALUE! | AA12: =IF(A12="非採用","非採用",IF(A12="処置薬","処置薬","")) -> 非採用 | AB12: =IF(A12="非採用特別","非採用特別",IF(R12=2,"臨時", IF(COUNTIF(分類!$H$8:$H$25, 統合マスタ!V12)>0, 分類!$G$7, IF(COUNTIF(分類!$K$8:$K$25, 統合マスタ!V12)>0, 分類!$J$7, IF(COUNTIF(分類!$N$8:$N$25, 統合マスタ!V12)>0, 分類!$M$7, IF(COUNTIF(分類!$Q$8:$Q$25, 統合マスタ!V12)>0, 分類!$P$7, IF(COUNTIF(分類!$T$8:$T$25, 統合マスタ!V12)>0, 分類!$S$7, "無し"))))))) -> 無し | AC12: =X12*100000+B12 -> #VALUE! | AD12: {=IF(A12="非採用","非採用",OFFSET( INDIRECT("'" & AB12 & "'!A4"), MATCH(B12, INDIRECT("'" & AB12 & "'!C5:C1000"), 0), MATCH("合計", INDIRECT("'" & AB12 & "'!4:4"), 0) - 1 ))} -> 非採用 | AE12: =H12*AD12 -> #VALUE! | AF12: =M12*AD12 -> #VALUE!
A13: =元データ!P10 -> 302 | B13: =B12+1 -> 9 | C13: =DBCS(元データ!A10) -> ０５４ ツムラ ヨクカンサン | D13: =元データ!B10 -> メディセオ | E13: =DBCS(元データ!C10) -> 粉 | F13: =DBCS(元データ!D10) -> ２．５ｇＸ１８９ | G13: =元データ!E10 -> ツムラ | H13: =元データ!F10 -> 16.1 | I13: =元データ!G10 -> 7607.25 | J13: =元データ!H10 -> 472.5 | K13: =元データ!I10 -> g | L13: =元データ!J10 -> 6849 | M13: =元データ!K10 -> 14.495238 | N13: =IF(OFFSET(マスタ非採用削除!A$4,統合マスタ!$A13,0)="","",OFFSET(マスタ非採用削除!A$4,統合マスタ!$A13,0)) -> ﾂﾑﾗ054 | O13: =IF(OFFSET(マスタ非採用削除!B$4,統合マスタ!$A13,0)="","",OFFSET(マスタ非採用削除!B$4,統合マスタ!$A13,0)) -> ﾂﾑﾗ054 | P13: =IF(OFFSET(マスタ非採用削除!C$4,統合マスタ!$A13,0)="","",OFFSET(マスタ非採用削除!C$4,統合マスタ!$A13,0)) -> ツムラ抑肝散エキス顆粒（医療用） | Q13: =IF(OFFSET(マスタ非採用削除!D$4,統合マスタ!$A13,0)="","",OFFSET(マスタ非採用削除!D$4,統合マスタ!$A13,0)) -> ﾖｸｶ | R13: =IF(OR(A13="非採用",A13="処置薬",A13="非採用特別"),0,IF(OFFSET(マスタ非採用削除!E$4,統合マスタ!$A13,0)="","",OFFSET(マスタ非採用削除!E$4,統合マスタ!$A13,0))) -> 1 | S13: =IF(OFFSET(マスタ非採用削除!F$4,統合マスタ!$A13,0)="","",OFFSET(マスタ非採用削除!F$4,統合マスタ!$A13,0)) | T13: =IF(OFFSET(マスタ非採用削除!G$4,統合マスタ!$A13,0)="","",OFFSET(マスタ非採用削除!G$4,統合マスタ!$A13,0)) -> 16.1 | U13: =IF(OFFSET(マスタ非採用削除!H$4,統合マスタ!$A13,0)="","",OFFSET(マスタ非採用削除!H$4,統合マスタ!$A13,0)) -> ﾂﾑﾗﾖｸｶﾝｻﾝｴｷｽｶﾘｭｳ(ｲﾘｮｳﾖｳ) | V13: =IF(OFFSET(マスタ非採用削除!I$4,統合マスタ!$A13,0)="","",OFFSET(マスタ非採用削除!I$4,統合マスタ!$A13,0)) -> 3 | W13: =IF(OFFSET(マスタ非採用削除!J$4,統合マスタ!$A13,0)="","",OFFSET(マスタ非採用削除!J$4,統合マスタ!$A13,0)) -> 散 | X13: =IF(OFFSET(マスタ非採用削除!K$4,統合マスタ!$A13,0)="","",OFFSET(マスタ非採用削除!K$4,統合マスタ!$A13,0)) -> 0 | Y13: =IF(OFFSET(マスタ非採用削除!L$4,統合マスタ!$A13,0)="","",OFFSET(マスタ非採用削除!L$4,統合マスタ!$A13,0)) | Z13: =IF(OFFSET(マスタ非採用削除!M$4,統合マスタ!$A13,0)="","",OFFSET(マスタ非採用削除!M$4,統合マスタ!$A13,0)) -> 4 | AA13: =IF(A13="非採用","非採用",IF(A13="処置薬","処置薬","")) | AB13: =IF(A13="非採用特別","非採用特別",IF(R13=2,"臨時", IF(COUNTIF(分類!$H$8:$H$25, 統合マスタ!V13)>0, 分類!$G$7, IF(COUNTIF(分類!$K$8:$K$25, 統合マスタ!V13)>0, 分類!$J$7, IF(COUNTIF(分類!$N$8:$N$25, 統合マスタ!V13)>0, 分類!$M$7, IF(COUNTIF(分類!$Q$8:$Q$25, 統合マスタ!V13)>0, 分類!$P$7, IF(COUNTIF(分類!$T$8:$T$25, 統合マスタ!V13)>0, 分類!$S$7, "無し"))))))) -> 散剤 | AC13: =X13*100000+B13 -> 9 | AD13: {=IF(A13="非採用","非採用",OFFSET( INDIRECT("'" & AB13 & "'!A4"), MATCH(B13, INDIRECT("'" & AB13 & "'!C5:C1000"), 0), MATCH("合計", INDIRECT("'" & AB13 & "'!4:4"), 0) - 1 ))} -> 2752.5 | AE13: =H13*AD13 -> 44315.25 | AF13: =M13*AD13 -> 39898.143
A14: =元データ!P11 -> 303 | B14: =B13+1 -> 10 | C14: =DBCS(元データ!A11) -> ０６２ ツムラ ボウフウツウシヨウサン | D14: =元データ!B11 -> メディセオ | E14: =DBCS(元データ!C11) -> 粉 | F14: =DBCS(元データ!D11) -> ２．５ｇｘ１８９ | G14: =元データ!E11 -> ツムラ | H14: =元データ!F11 -> 13.8 | I14: =元データ!G11 -> 6520.5 | J14: =元データ!H11 -> 472.5 | K14: =元データ!I11 -> g | L14: =元データ!J11 -> 5871 | M14: =元データ!K11 -> 12.425397 | N14: =IF(OFFSET(マスタ非採用削除!A$4,統合マスタ!$A14,0)="","",OFFSET(マスタ非採用削除!A$4,統合マスタ!$A14,0)) -> ﾂﾑﾗ062 | O14: =IF(OFFSET(マスタ非採用削除!B$4,統合マスタ!$A14,0)="","",OFFSET(マスタ非採用削除!B$4,統合マスタ!$A14,0)) -> ﾂﾑﾗ062 | P14: =IF(OFFSET(マスタ非採用削除!C$4,統合マスタ!$A14,0)="","",OFFSET(マスタ非採用削除!C$4,統合マスタ!$A14,0)) -> ツムラ防風通聖散エキス顆粒（医療用） | Q14: =IF(OFFSET(マスタ非採用削除!D$4,統合マスタ!$A14,0)="","",OFFSET(マスタ非採用削除!D$4,統合マスタ!$A14,0)) -> ﾎﾞｳﾌｳ | R14: =IF(OR(A14="非採用",A14="処置薬",A14="非採用特別"),0,IF(OFFSET(マスタ非採用削除!E$4,統合マスタ!$A14,0)="","",OFFSET(マスタ非採用削除!E$4,統合マスタ!$A14,0))) -> 1 | S14: =IF(OFFSET(マスタ非採用削除!F$4,統合マスタ!$A14,0)="","",OFFSET(マスタ非採用削除!F$4,統合マスタ!$A14,0)) | T14: =IF(OFFSET(マスタ非採用削除!G$4,統合マスタ!$A14,0)="","",OFFSET(マスタ非採用削除!G$4,統合マスタ!$A14,0)) -> 13.8 | U14: =IF(OFFSET(マスタ非採用削除!H$4,統合マスタ!$A14,0)="","",OFFSET(マスタ非採用削除!H$4,統合マスタ!$A14,0)) -> ﾂﾑﾗﾎﾞｳﾌｳﾂｳｼｮｳｻﾝｴｷｽｶﾘｭｳ(ｲﾘｮｳﾖｳ) | V14: =IF(OFFSET(マスタ非採用削除!I$4,統合マスタ!$A14,0)="","",OFFSET(マスタ非採用削除!I$4,統合マスタ!$A14,0)) -> 3 | W14: =IF(OFFSET(マスタ非採用削除!J$4,統合マスタ!$A14,0)="","",OFFSET(マスタ非採用削除!J$4,統合マスタ!$A14,0)) -> 散 | X14: =IF(OFFSET(マスタ非採用削除!K$4,統合マスタ!$A14,0)="","",OFFSET(マスタ非採用削除!K$4,統合マスタ!$A14,0)) -> 0 | Y14: =IF(OFFSET(マスタ非採用削除!L$4,統合マスタ!$A14,0)="","",OFFSET(マスタ非採用削除!L$4,統合マスタ!$A14,0)) | Z14: =IF(OFFSET(マスタ非採用削除!M$4,統合マスタ!$A14,0)="","",OFFSET(マスタ非採用削除!M$4,統合マスタ!$A14,0)) -> 4 | AA14: =IF(A14="非採用","非採用",IF(A14="処置薬","処置薬","")) | AB14: =IF(A14="非採用特別","非採用特別",IF(R14=2,"臨時", IF(COUNTIF(分類!$H$8:$H$25, 統合マスタ!V14)>0, 分類!$G$7, IF(COUNTIF(分類!$K$8:$K$25, 統合マスタ!V14)>0, 分類!$J$7, IF(COUNTIF(分類!$N$8:$N$25, 統合マスタ!V14)>0, 分類!$M$7, IF(COUNTIF(分類!$Q$8:$Q$25, 統合マスタ!V14)>0, 分類!$P$7, IF(COUNTIF(分類!$T$8:$T$25, 統合マスタ!V14)>0, 分類!$S$7, "無し"))))))) -> 散剤 | AC14: =X14*100000+B14 -> 10 | AD14: {=IF(A14="非採用","非採用",OFFSET( INDIRECT("'" & AB14 & "'!A4"), MATCH(B14, INDIRECT("'" & AB14 & "'!C5:C1000"), 0), MATCH("合計", INDIRECT("'" & AB14 & "'!4:4"), 0) - 1 ))} -> 427.5 | AE14: =H14*AD14 -> 5899.5 | AF14: =M14*AD14 -> 5311.8571
A15: =元データ!P12 -> 304 | B15: =B14+1 -> 11 | C15: =DBCS(元データ!A12) -> ０６８ ツムラ シャクヤクカンゾウトウ | D15: =元データ!B12 -> メディセオ | E15: =DBCS(元データ!C12) -> 粉 | F15: =DBCS(元データ!D12) -> ２．５ｇｘ４２ | G15: =元データ!E12 -> ツムラ | H15: =元データ!F12 -> 10.4 | I15: =元データ!G12 -> 1092 | J15: =元データ!H12 -> 105 | K15: =元データ!I12 -> g | L15: =元データ!J12 -> 992 | M15: =元データ!K12 -> 9.447619 | N15: =IF(OFFSET(マスタ非採用削除!A$4,統合マスタ!$A15,0)="","",OFFSET(マスタ非採用削除!A$4,統合マスタ!$A15,0)) -> ﾂﾑﾗ068 | O15: =IF(OFFSET(マスタ非採用削除!B$4,統合マスタ!$A15,0)="","",OFFSET(マスタ非採用削除!B$4,統合マスタ!$A15,0)) -> ﾂﾑﾗ068 | P15: =IF(OFFSET(マスタ非採用削除!C$4,統合マスタ!$A15,0)="","",OFFSET(マスタ非採用削除!C$4,統合マスタ!$A15,0)) -> ツムラ芍薬甘草湯エキス顆粒（医療用） | Q15: =IF(OFFSET(マスタ非採用削除!D$4,統合マスタ!$A15,0)="","",OFFSET(マスタ非採用削除!D$4,統合マスタ!$A15,0)) -> ｼｬｸ | R15: =IF(OR(A15="非採用",A15="処置薬",A15="非採用特別"),0,IF(OFFSET(マスタ非採用削除!E$4,統合マスタ!$A15,0)="","",OFFSET(マスタ非採用削除!E$4,統合マスタ!$A15,0))) -> 1 | S15: =IF(OFFSET(マスタ非採用削除!F$4,統合マスタ!$A15,0)="","",OFFSET(マスタ非採用削除!F$4,統合マスタ!$A15,0)) | T15: =IF(OFFSET(マスタ非採用削除!G$4,統合マスタ!$A15,0)="","",OFFSET(マスタ非採用削除!G$4,統合マスタ!$A15,0)) -> 10.4 | U15: =IF(OFFSET(マスタ非採用削除!H$4,統合マスタ!$A15,0)="","",OFFSET(マスタ非採用削除!H$4,統合マスタ!$A15,0)) -> ﾂﾑﾗｼｬｸﾔｸｶﾝｿﾞｳﾄｳｴｷｽｶﾘｭｳ(ｲﾘｮｳﾖｳ) | V15: =IF(OFFSET(マスタ非採用削除!I$4,統合マスタ!$A15,0)="","",OFFSET(マスタ非採用削除!I$4,統合マスタ!$A15,0)) -> 3 | W15: =IF(OFFSET(マスタ非採用削除!J$4,統合マスタ!$A15,0)="","",OFFSET(マスタ非採用削除!J$4,統合マスタ!$A15,0)) -> 散 | X15: =IF(OFFSET(マスタ非採用削除!K$4,統合マスタ!$A15,0)="","",OFFSET(マスタ非採用削除!K$4,統合マスタ!$A15,0)) -> 0 | Y15: =IF(OFFSET(マスタ非採用削除!L$4,統合マスタ!$A15,0)="","",OFFSET(マスタ非採用削除!L$4,統合マスタ!$A15,0)) | Z15: =IF(OFFSET(マスタ非採用削除!M$4,統合マスタ!$A15,0)="","",OFFSET(マスタ非採用削除!M$4,統合マスタ!$A15,0)) -> 4 | AA15: =IF(A15="非採用","非採用",IF(A15="処置薬","処置薬","")) | AB15: =IF(A15="非採用特別","非採用特別",IF(R15=2,"臨時", IF(COUNTIF(分類!$H$8:$H$25, 統合マスタ!V15)>0, 分類!$G$7, IF(COUNTIF(分類!$K$8:$K$25, 統合マスタ!V15)>0, 分類!$J$7, IF(COUNTIF(分類!$N$8:$N$25, 統合マスタ!V15)>0, 分類!$M$7, IF(COUNTIF(分類!$Q$8:$Q$25, 統合マスタ!V15)>0, 分類!$P$7, IF(COUNTIF(分類!$T$8:$T$25, 統合マスタ!V15)>0, 分類!$S$7, "無し"))))))) -> 散剤 | AC15: =X15*100000+B15 -> 11 | AD15: {=IF(A15="非採用","非採用",OFFSET( INDIRECT("'" & AB15 & "'!A4"), MATCH(B15, INDIRECT("'" & AB15 & "'!C5:C1000"), 0), MATCH("合計", INDIRECT("'" & AB15 & "'!4:4"), 0) - 1 ))} -> 5 | AE15: =H15*AD15 -> 52 | AF15: =M15*AD15 -> 47.238095
A16: =元データ!P13 -> 305 | B16: =B15+1 -> 12 | C16: =DBCS(元データ!A13) -> ０８３ ツムラ ヨクカンサンカチンピハンゲ | D16: =元データ!B13 -> メディセオ | E16: =DBCS(元データ!C13) -> 粉 | F16: =DBCS(元データ!D13) -> ２．５ｇｘ１８９ | G16: =元データ!E13 -> ツムラ | H16: =元データ!F13 -> 14.4 | I16: =元データ!G13 -> 6804 | J16: =元データ!H13 -> 472.5 | K16: =元データ!I13 -> g | L16: =元データ!J13 -> 6065 | M16: =元データ!K13 -> 12.835979 | N16: =IF(OFFSET(マスタ非採用削除!A$4,統合マスタ!$A16,0)="","",OFFSET(マスタ非採用削除!A$4,統合マスタ!$A16,0)) -> ﾂﾑﾗ083 | O16: =IF(OFFSET(マスタ非採用削除!B$4,統合マスタ!$A16,0)="","",OFFSET(マスタ非採用削除!B$4,統合マスタ!$A16,0)) -> ﾂﾑﾗ083 | P16: =IF(OFFSET(マスタ非採用削除!C$4,統合マスタ!$A16,0)="","",OFFSET(マスタ非採用削除!C$4,統合マスタ!$A16,0)) -> ツムラ抑肝散加陳皮半夏エキス顆粒（医療用） | Q16: =IF(OFFSET(マスタ非採用削除!D$4,統合マスタ!$A16,0)="","",OFFSET(マスタ非採用削除!D$4,統合マスタ!$A16,0)) -> ﾖｸｶﾁﾝ | R16: =IF(OR(A16="非採用",A16="処置薬",A16="非採用特別"),0,IF(OFFSET(マスタ非採用削除!E$4,統合マスタ!$A16,0)="","",OFFSET(マスタ非採用削除!E$4,統合マスタ!$A16,0))) -> 1 | S16: =IF(OFFSET(マスタ非採用削除!F$4,統合マスタ!$A16,0)="","",OFFSET(マスタ非採用削除!F$4,統合マスタ!$A16,0)) | T16: =IF(OFFSET(マスタ非採用削除!G$4,統合マスタ!$A16,0)="","",OFFSET(マスタ非採用削除!G$4,統合マスタ!$A16,0)) -> 14.4 | U16: =IF(OFFSET(マスタ非採用削除!H$4,統合マスタ!$A16,0)="","",OFFSET(マスタ非採用削除!H$4,統合マスタ!$A16,0)) -> ﾂﾑﾗﾖｸｶﾝｻﾝｶﾁﾝﾋﾟﾊﾝｹﾞｴｷｽｶﾘｭｳ(ｲﾘｮｳﾖｳ) | V16: =IF(OFFSET(マスタ非採用削除!I$4,統合マスタ!$A16,0)="","",OFFSET(マスタ非採用削除!I$4,統合マスタ!$A16,0)) -> 3 | W16: =IF(OFFSET(マスタ非採用削除!J$4,統合マスタ!$A16,0)="","",OFFSET(マスタ非採用削除!J$4,統合マスタ!$A16,0)) -> 散 | X16: =IF(OFFSET(マスタ非採用削除!K$4,統合マスタ!$A16,0)="","",OFFSET(マスタ非採用削除!K$4,統合マスタ!$A16,0)) -> 0 | Y16: =IF(OFFSET(マスタ非採用削除!L$4,統合マスタ!$A16,0)="","",OFFSET(マスタ非採用削除!L$4,統合マスタ!$A16,0)) | Z16: =IF(OFFSET(マスタ非採用削除!M$4,統合マスタ!$A16,0)="","",OFFSET(マスタ非採用削除!M$4,統合マスタ!$A16,0)) -> 4 | AA16: =IF(A16="非採用","非採用",IF(A16="処置薬","処置薬","")) | AB16: =IF(A16="非採用特別","非採用特別",IF(R16=2,"臨時", IF(COUNTIF(分類!$H$8:$H$25, 統合マスタ!V16)>0, 分類!$G$7, IF(COUNTIF(分類!$K$8:$K$25, 統合マスタ!V16)>0, 分類!$J$7, IF(COUNTIF(分類!$N$8:$N$25, 統合マスタ!V16)>0, 分類!$M$7, IF(COUNTIF(分類!$Q$8:$Q$25, 統合マスタ!V16)>0, 分類!$P$7, IF(COUNTIF(分類!$T$8:$T$25, 統合マスタ!V16)>0, 分類!$S$7, "無し"))))))) -> 散剤 | AC16: =X16*100000+B16 -> 12 | AD16: {=IF(A16="非採用","非採用",OFFSET( INDIRECT("'" & AB16 & "'!A4"), MATCH(B16, INDIRECT("'" & AB16 & "'!C5:C1000"), 0), MATCH("合計", INDIRECT("'" & AB16 & "'!4:4"), 0) - 1 ))} -> 582.5 | AE16: =H16*AD16 -> 8388 | AF16: =M16*AD16 -> 7476.9577
A17: =元データ!P14 -> 306 | B17: =B16+1 -> 13 | C17: =DBCS(元データ!A14) -> １００ ツムラ ダイケンチユウトウ | D17: =元データ!B14 -> メディセオ | E17: =DBCS(元データ!C14) -> 粉 | F17: =DBCS(元データ!D14) -> ２．５ｇＸ１８９ | G17: =元データ!E14 -> ツムラ | H17: =元データ!F14 -> 13.7 | I17: =元データ!G14 -> 6473.25 | J17: =元データ!H14 -> 472.5 | K17: =元データ!I14 -> g | L17: =元データ!J14 -> 5828 | M17: =元データ!K14 -> 12.334392 | N17: =IF(OFFSET(マスタ非採用削除!A$4,統合マスタ!$A17,0)="","",OFFSET(マスタ非採用削除!A$4,統合マスタ!$A17,0)) -> ﾂﾑﾗ100 | O17: =IF(OFFSET(マスタ非採用削除!B$4,統合マスタ!$A17,0)="","",OFFSET(マスタ非採用削除!B$4,統合マスタ!$A17,0)) -> ﾂﾑﾗ100 | P17: =IF(OFFSET(マスタ非採用削除!C$4,統合マスタ!$A17,0)="","",OFFSET(マスタ非採用削除!C$4,統合マスタ!$A17,0)) -> ツムラ大建中湯エキス顆粒（医療用） | Q17: =IF(OFFSET(マスタ非採用削除!D$4,統合マスタ!$A17,0)="","",OFFSET(マスタ非採用削除!D$4,統合マスタ!$A17,0)) -> ﾀﾞｲｹﾝﾁ | R17: =IF(OR(A17="非採用",A17="処置薬",A17="非採用特別"),0,IF(OFFSET(マスタ非採用削除!E$4,統合マスタ!$A17,0)="","",OFFSET(マスタ非採用削除!E$4,統合マスタ!$A17,0))) -> 1 | S17: =IF(OFFSET(マスタ非採用削除!F$4,統合マスタ!$A17,0)="","",OFFSET(マスタ非採用削除!F$4,統合マスタ!$A17,0)) | T17: =IF(OFFSET(マスタ非採用削除!G$4,統合マスタ!$A17,0)="","",OFFSET(マスタ非採用削除!G$4,統合マスタ!$A17,0)) -> 13.7 | U17: =IF(OFFSET(マスタ非採用削除!H$4,統合マスタ!$A17,0)="","",OFFSET(マスタ非採用削除!H$4,統合マスタ!$A17,0)) -> ﾂﾑﾗﾀﾞｲｹﾝﾁｭｳﾄｳｴｷｽｶﾘｭｳ(ｲﾘｮｳﾖｳ) | V17: =IF(OFFSET(マスタ非採用削除!I$4,統合マスタ!$A17,0)="","",OFFSET(マスタ非採用削除!I$4,統合マスタ!$A17,0)) -> 3 | W17: =IF(OFFSET(マスタ非採用削除!J$4,統合マスタ!$A17,0)="","",OFFSET(マスタ非採用削除!J$4,統合マスタ!$A17,0)) -> 散 | X17: =IF(OFFSET(マスタ非採用削除!K$4,統合マスタ!$A17,0)="","",OFFSET(マスタ非採用削除!K$4,統合マスタ!$A17,0)) -> 0 | Y17: =IF(OFFSET(マスタ非採用削除!L$4,統合マスタ!$A17,0)="","",OFFSET(マスタ非採用削除!L$4,統合マスタ!$A17,0)) | Z17: =IF(OFFSET(マスタ非採用削除!M$4,統合マスタ!$A17,0)="","",OFFSET(マスタ非採用削除!M$4,統合マスタ!$A17,0)) -> 4 | AA17: =IF(A17="非採用","非採用",IF(A17="処置薬","処置薬","")) | AB17: =IF(A17="非採用特別","非採用特別",IF(R17=2,"臨時", IF(COUNTIF(分類!$H$8:$H$25, 統合マスタ!V17)>0, 分類!$G$7, IF(COUNTIF(分類!$K$8:$K$25, 統合マスタ!V17)>0, 分類!$J$7, IF(COUNTIF(分類!$N$8:$N$25, 統合マスタ!V17)>0, 分類!$M$7, IF(COUNTIF(分類!$Q$8:$Q$25, 統合マスタ!V17)>0, 分類!$P$7, IF(COUNTIF(分類!$T$8:$T$25, 統合マスタ!V17)>0, 分類!$S$7, "無し"))))))) -> 散剤 | AC17: =X17*100000+B17 -> 13 | AD17: {=IF(A17="非採用","非採用",OFFSET( INDIRECT("'" & AB17 & "'!A4"), MATCH(B17, INDIRECT("'" & AB17 & "'!C5:C1000"), 0), MATCH("合計", INDIRECT("'" & AB17 & "'!4:4"), 0) - 1 ))} -> 1400 | AE17: =H17*AD17 -> 19180 | AF17: =M17*AD17 -> 17268.148
... A37: =元データ!P34 -> 4 | B37: =B36+1 -> 33 | C37: =DBCS(元データ!A34) -> アクチット輸液 | D37: =元データ!B34 -> メディセオ | E37: =DBCS(元データ!C34) | F37: =DBCS(元データ!D34) -> ５００ｍｌｘ２０袋 | G37: =元データ!E34 -> 扶桑薬品 | H37: =元データ!F34 -> 341 | I37: =元データ!G34 -> 6820 | J37: =元データ!H34 -> 20 | K37: =元データ!I34 -> 袋 | L37: =元データ!J34 -> 6075 | M37: =元データ!K34 -> 303.75 | N37: =IF(OFFSET(マスタ非採用削除!A$4,統合マスタ!$A37,0)="","",OFFSET(マスタ非採用削除!A$4,統合マスタ!$A37,0)) -> ｱｸﾁ002 | O37: =IF(OFFSET(マスタ非採用削除!B$4,統合マスタ!$A37,0)="","",OFFSET(マスタ非採用削除!B$4,統合マスタ!$A37,0)) -> ｱｸﾁ002 | P37: =IF(OFFSET(マスタ非採用削除!C$4,統合マスタ!$A37,0)="","",OFFSET(マスタ非採用削除!C$4,統合マスタ!$A37,0)) -> アクチット輸液 | Q37: =IF(OFFSET(マスタ非採用削除!D$4,統合マスタ!$A37,0)="","",OFFSET(マスタ非採用削除!D$4,統合マスタ!$A37,0)) | R37: =IF(OR(A37="非採用",A37="処置薬",A37="非採用特別"),0,IF(OFFSET(マスタ非採用削除!E$4,統合マスタ!$A37,0)="","",OFFSET(マスタ非採用削除!E$4,統合マスタ!$A37,0))) -> 1 | S37: =IF(OFFSET(マスタ非採用削除!F$4,統合マスタ!$A37,0)="","",OFFSET(マスタ非採用削除!F$4,統合マスタ!$A37,0)) | T37: =IF(OFFSET(マスタ非採用削除!G$4,統合マスタ!$A37,0)="","",OFFSET(マスタ非採用削除!G$4,統合マスタ!$A37,0)) -> 341 | U37: =IF(OFFSET(マスタ非採用削除!H$4,統合マスタ!$A37,0)="","",OFFSET(マスタ非採用削除!H$4,統合マスタ!$A37,0)) -> ｱｸﾁﾂﾄﾕｴｷ | V37: =IF(OFFSET(マスタ非採用削除!I$4,統合マスタ!$A37,0)="","",OFFSET(マスタ非採用削除!I$4,統合マスタ!$A37,0)) -> 25 | W37: =IF(OFFSET(マスタ非採用削除!J$4,統合マスタ!$A37,0)="","",OFFSET(マスタ非採用削除!J$4,統合マスタ!$A37,0)) -> 注射剤 | X37: =IF(OFFSET(マスタ非採用削除!K$4,統合マスタ!$A37,0)="","",OFFSET(マスタ非採用削除!K$4,統合マスタ!$A37,0)) -> 0 | Y37: =IF(OFFSET(マスタ非採用削除!L$4,統合マスタ!$A37,0)="","",OFFSET(マスタ非採用削除!L$4,統合マスタ!$A37,0)) | Z37: =IF(OFFSET(マスタ非採用削除!M$4,統合マスタ!$A37,0)="","",OFFSET(マスタ非採用削除!M$4,統合マスタ!$A37,0)) -> 10 | AA37: =IF(A37="非採用","非採用",IF(A37="処置薬","処置薬","")) | AB37: =IF(A37="非採用特別","非採用特別",IF(R37=2,"臨時", IF(COUNTIF(分類!$H$8:$H$25, 統合マスタ!V37)>0, 分類!$G$7, IF(COUNTIF(分類!$K$8:$K$25, 統合マスタ!V37)>0, 分類!$J$7, IF(COUNTIF(分類!$N$8:$N$25, 統合マスタ!V37)>0, 分類!$M$7, IF(COUNTIF(分類!$Q$8:$Q$25, 統合マスタ!V37)>0, 分類!$P$7, IF(COUNTIF(分類!$T$8:$T$25, 統合マスタ!V37)>0, 分類!$S$7, "無し"))))))) -> 注射 | AC37: =X37*100000+B37 -> 33 | AD37: {=IF(A37="非採用","非採用",OFFSET( INDIRECT("'" & AB37 & "'!A4"), MATCH(B37, INDIRECT("'" & AB37 & "'!C5:C1000"), 0), MATCH("合計", INDIRECT("'" & AB37 & "'!4:4"), 0) - 1 ))} -> 7 | AE37: =H37*AD37 -> 2387 | AF37: =M37*AD37 -> 2126.25
A38: =元データ!P35 -> 5 | B38: =B37+1 -> 34 | C38: =DBCS(元データ!A35) -> アクトシン軟膏３％ | D38: =元データ!B35 -> アルフレッサ | E38: =DBCS(元データ!C35) | F38: =DBCS(元データ!D35) -> ３０ｇ | G38: =元データ!E35 -> マルホ | H38: =元データ!F35 -> 50 | I38: =元データ!G35 -> 1500 | J38: =元データ!H35 -> 30 | K38: =元データ!I35 -> g | L38: =元データ!J35 -> 1251 | M38: =元データ!K35 -> 41.7 | N38: =IF(OFFSET(マスタ非採用削除!A$4,統合マスタ!$A38,0)="","",OFFSET(マスタ非採用削除!A$4,統合マスタ!$A38,0)) -> ｱｸﾄ001 | O38: =IF(OFFSET(マスタ非採用削除!B$4,統合マスタ!$A38,0)="","",OFFSET(マスタ非採用削除!B$4,統合マスタ!$A38,0)) -> ｱｸﾄ001 | P38: =IF(OFFSET(マスタ非採用削除!C$4,統合マスタ!$A38,0)="","",OFFSET(マスタ非採用削除!C$4,統合マスタ!$A38,0)) -> アクトシン軟膏３％ | Q38: =IF(OFFSET(マスタ非採用削除!D$4,統合マスタ!$A38,0)="","",OFFSET(マスタ非採用削除!D$4,統合マスタ!$A38,0)) -> ｱｸﾄｼﾝ | R38: =IF(OR(A38="非採用",A38="処置薬",A38="非採用特別"),0,IF(OFFSET(マスタ非採用削除!E$4,統合マスタ!$A38,0)="","",OFFSET(マスタ非採用削除!E$4,統合マスタ!$A38,0))) -> 1 | S38: =IF(OFFSET(マスタ非採用削除!F$4,統合マスタ!$A38,0)="","",OFFSET(マスタ非採用削除!F$4,統合マスタ!$A38,0)) | T38: =IF(OFFSET(マスタ非採用削除!G$4,統合マスタ!$A38,0)="","",OFFSET(マスタ非採用削除!G$4,統合マスタ!$A38,0)) -> 50 | U38: =IF(OFFSET(マスタ非採用削除!H$4,統合マスタ!$A38,0)="","",OFFSET(マスタ非採用削除!H$4,統合マスタ!$A38,0)) -> ｱｸﾄｼﾝﾅﾝｺｳ3% | V38: =IF(OFFSET(マスタ非採用削除!I$4,統合マスタ!$A38,0)="","",OFFSET(マスタ非採用削除!I$4,統合マスタ!$A38,0)) -> 14 | W38: =IF(OFFSET(マスタ非採用削除!J$4,統合マスタ!$A38,0)="","",OFFSET(マスタ非採用削除!J$4,統合マスタ!$A38,0)) -> 軟膏 | X38: =IF(OFFSET(マスタ非採用削除!K$4,統合マスタ!$A38,0)="","",OFFSET(マスタ非採用削除!K$4,統合マスタ!$A38,0)) -> 0 | Y38: =IF(OFFSET(マスタ非採用削除!L$4,統合マスタ!$A38,0)="","",OFFSET(マスタ非採用削除!L$4,統合マスタ!$A38,0)) | Z38: =IF(OFFSET(マスタ非採用削除!M$4,統合マスタ!$A38,0)="","",OFFSET(マスタ非採用削除!M$4,統合マスタ!$A38,0)) -> 15 | AA38: =IF(A38="非採用","非採用",IF(A38="処置薬","処置薬","")) | AB38: =IF(A38="非採用特別","非採用特別",IF(R38=2,"臨時", IF(COUNTIF(分類!$H$8:$H$25, 統合マスタ!V38)>0, 分類!$G$7, IF(COUNTIF(分類!$K$8:$K$25, 統合マスタ!V38)>0, 分類!$J$7, IF(COUNTIF(分類!$N$8:$N$25, 統合マスタ!V38)>0, 分類!$M$7, IF(COUNTIF(分類!$Q$8:$Q$25, 統合マスタ!V38)>0, 分類!$P$7, IF(COUNTIF(分類!$T$8:$T$25, 統合マスタ!V38)>0, 分類!$S$7, "無し"))))))) -> 外用 | AC38: =X38*100000+B38 -> 34 | AD38: 91 | AE38: =H38*AD38 -> 4550 | AF38: =M38*AD38 -> 3794.7
A39: =元データ!P36 -> 6 | B39: =B38+1 -> 35 | C39: =DBCS(元データ!A36) -> アザルフィジンＥＮ錠５００ｍｇ | D39: =元データ!B36 -> KSK | E39: =DBCS(元データ!C36) -> ＰＴＰ | F39: =DBCS(元データ!D36) -> １００Ｔ | G39: =元データ!E36 -> ファイザー | H39: =元データ!F36 -> 25.9 | I39: =元データ!G36 -> 2590 | J39: =元データ!H36 -> 100 | K39: =元データ!I36 -> 錠 | L39: =元データ!J36 -> 2308 | M39: =元データ!K36 -> 23.08 | N39: =IF(OFFSET(マスタ非採用削除!A$4,統合マスタ!$A39,0)="","",OFFSET(マスタ非採用削除!A$4,統合マスタ!$A39,0)) -> ｱｻﾙ001 | O39: =IF(OFFSET(マスタ非採用削除!B$4,統合マスタ!$A39,0)="","",OFFSET(マスタ非採用削除!B$4,統合マスタ!$A39,0)) -> ｱｻﾙ001 | P39: =IF(OFFSET(マスタ非採用削除!C$4,統合マスタ!$A39,0)="","",OFFSET(マスタ非採用削除!C$4,統合マスタ!$A39,0)) -> アザルフィジンＥＮ錠５００ｍｇ | Q39: =IF(OFFSET(マスタ非採用削除!D$4,統合マスタ!$A39,0)="","",OFFSET(マスタ非採用削除!D$4,統合マスタ!$A39,0)) -> ｱｻﾞﾙ1 | R39: =IF(OR(A39="非採用",A39="処置薬",A39="非採用特別"),0,IF(OFFSET(マスタ非採用削除!E$4,統合マスタ!$A39,0)="","",OFFSET(マスタ非採用削除!E$4,統合マスタ!$A39,0))) -> 2 | S39: =IF(OFFSET(マスタ非採用削除!F$4,統合マスタ!$A39,0)="","",OFFSET(マスタ非採用削除!F$4,統合マスタ!$A39,0)) | T39: =IF(OFFSET(マスタ非採用削除!G$4,統合マスタ!$A39,0)="","",OFFSET(マスタ非採用削除!G$4,統合マスタ!$A39,0)) -> 25.9 | U39: =IF(OFFSET(マスタ非採用削除!H$4,統合マスタ!$A39,0)="","",OFFSET(マスタ非採用削除!H$4,統合マスタ!$A39,0)) -> ｱｻﾞﾙﾌｨｼﾞﾝENｼﾞｮｳ500mg | V39: =IF(OFFSET(マスタ非採用削除!I$4,統合マスタ!$A39,0)="","",OFFSET(マスタ非採用削除!I$4,統合マスタ!$A39,0)) -> 1 | W39: =IF(OFFSET(マスタ非採用削除!J$4,統合マスタ!$A39,0)="","",OFFSET(マスタ非採用削除!J$4,統合マスタ!$A39,0)) -> 錠剤 | X39: =IF(OFFSET(マスタ非採用削除!K$4,統合マスタ!$A39,0)="","",OFFSET(マスタ非採用削除!K$4,統合マスタ!$A39,0)) -> 0 | Y39: =IF(OFFSET(マスタ非採用削除!L$4,統合マスタ!$A39,0)="","",OFFSET(マスタ非採用削除!L$4,統合マスタ!$A39,0)) | Z39: =IF(OFFSET(マスタ非採用削除!M$4,統合マスタ!$A39,0)="","",OFFSET(マスタ非採用削除!M$4,統合マスタ!$A39,0)) -> 3 | AA39: =IF(A39="非採用","非採用",IF(A39="処置薬","処置薬","")) | AB39: =IF(A39="非採用特別","非採用特別",IF(R39=2,"臨時", IF(COUNTIF(分類!$H$8:$H$25, 統合マスタ!V39)>0, 分類!$G$7, IF(COUNTIF(分類!$K$8:$K$25, 統合マスタ!V39)>0, 分類!$J$7, IF(COUNTIF(分類!$N$8:$N$25, 統合マスタ!V39)>0, 分類!$M$7, IF(COUNTIF(分類!$Q$8:$Q$25, 統合マスタ!V39)>0, 分類!$P$7, IF(COUNTIF(分類!$T$8:$T$25, 統合マスタ!V39)>0, 分類!$S$7, "無し"))))))) -> 臨時 | AC39: =X39*100000+B39 -> 35 | AD39: {=IF(A39="非採用","非採用",OFFSET( INDIRECT("'" & AB39 & "'!A4"), MATCH(B39, INDIRECT("'" & AB39 & "'!C5:C1000"), 0), MATCH("合計", INDIRECT("'" & AB39 & "'!4:4"), 0) - 1 ))} -> 34 | AE39: =H39*AD39 -> 880.6 | AF39: =M39*AD39 -> 784.72
A40: =元データ!P37 -> 7 | B40: =B39+1 -> 36 | C40: =DBCS(元データ!A37) -> アシクロビル点滴静注用２５０ｍｇ「サワイ」 | D40: =元データ!B37 | E40: =DBCS(元データ!C37) | F40: =DBCS(元データ!D37) -> １０Ｖ | G40: =元データ!E37 -> 沢井製薬 | H40: =元データ!F37 -> 368 | I40: =元データ!G37 -> 3680 | J40: =元データ!H37 -> 10 | K40: =元データ!I37 -> V | L40: =元データ!J37 -> 3238 | M40: =元データ!K37 -> 323.8 | N40: =IF(OFFSET(マスタ非採用削除!A$4,統合マスタ!$A40,0)="","",OFFSET(マスタ非採用削除!A$4,統合マスタ!$A40,0)) -> ｱｼｸ001 | O40: =IF(OFFSET(マスタ非採用削除!B$4,統合マスタ!$A40,0)="","",OFFSET(マスタ非採用削除!B$4,統合マスタ!$A40,0)) -> ｱｼｸ001 | P40: =IF(OFFSET(マスタ非採用削除!C$4,統合マスタ!$A40,0)="","",OFFSET(マスタ非採用削除!C$4,統合マスタ!$A40,0)) -> アシクロビル点滴静注用２５０ｍｇ「サワイ」 | Q40: =IF(OFFSET(マスタ非採用削除!D$4,統合マスタ!$A40,0)="","",OFFSET(マスタ非採用削除!D$4,統合マスタ!$A40,0)) -> ｱｼｸﾛ | R40: =IF(OR(A40="非採用",A40="処置薬",A40="非採用特別"),0,IF(OFFSET(マスタ非採用削除!E$4,統合マスタ!$A40,0)="","",OFFSET(マスタ非採用削除!E$4,統合マスタ!$A40,0))) -> 2 | S40: =IF(OFFSET(マスタ非採用削除!F$4,統合マスタ!$A40,0)="","",OFFSET(マスタ非採用削除!F$4,統合マスタ!$A40,0)) | T40: =IF(OFFSET(マスタ非採用削除!G$4,統合マスタ!$A40,0)="","",OFFSET(マスタ非採用削除!G$4,統合マスタ!$A40,0)) -> 368 | U40: =IF(OFFSET(マスタ非採用削除!H$4,統合マスタ!$A40,0)="","",OFFSET(マスタ非採用削除!H$4,統合マスタ!$A40,0)) -> ｱｼｸﾛﾋﾞﾙﾃﾝﾃｷｼﾞｮｳﾁｭｳﾖｳ250mg｢ｻﾜｲ｣ | V40: =IF(OFFSET(マスタ非採用削除!I$4,統合マスタ!$A40,0)="","",OFFSET(マスタ非採用削除!I$4,統合マスタ!$A40,0)) -> 25 | W40: =IF(OFFSET(マスタ非採用削除!J$4,統合マスタ!$A40,0)="","",OFFSET(マスタ非採用削除!J$4,統合マスタ!$A40,0)) -> 注射剤 | X40: =IF(OFFSET(マスタ非採用削除!K$4,統合マスタ!$A40,0)="","",OFFSET(マスタ非採用削除!K$4,統合マスタ!$A40,0)) -> 0 | Y40: =IF(OFFSET(マスタ非採用削除!L$4,統合マスタ!$A40,0)="","",OFFSET(マスタ非採用削除!L$4,統合マスタ!$A40,0)) | Z40: =IF(OFFSET(マスタ非採用削除!M$4,統合マスタ!$A40,0)="","",OFFSET(マスタ非採用削除!M$4,統合マスタ!$A40,0)) -> 9 | AA40: =IF(A40="非採用","非採用",IF(A40="処置薬","処置薬","")) | AB40: =IF(A40="非採用特別","非採用特別",IF(R40=2,"臨時", IF(COUNTIF(分類!$H$8:$H$25, 統合マスタ!V40)>0, 分類!$G$7, IF(COUNTIF(分類!$K$8:$K$25, 統合マスタ!V40)>0, 分類!$J$7, IF(COUNTIF(分類!$N$8:$N$25, 統合マスタ!V40)>0, 分類!$M$7, IF(COUNTIF(分類!$Q$8:$Q$25, 統合マスタ!V40)>0, 分類!$P$7, IF(COUNTIF(分類!$T$8:$T$25, 統合マスタ!V40)>0, 分類!$S$7, "無し"))))))) -> 臨時 | AC40: =X40*100000+B40 -> 36 | AD40: {=IF(A40="非採用","非採用",OFFSET( INDIRECT("'" & AB40 & "'!A4"), MATCH(B40, INDIRECT("'" & AB40 & "'!C5:C1000"), 0), MATCH("合計", INDIRECT("'" & AB40 & "'!4:4"), 0) - 1 ))} -> 56 | AE40: =H40*AD40 -> 20608 | AF40: =M40*AD40 -> 18132.8
A41: =元データ!P38 -> 8 | B41: =B40+1 -> 37 | C41: =DBCS(元データ!A38) -> アジスロマイシン錠２５０ｍｇ「トーワ」 | D41: =元データ!B38 | E41: =DBCS(元データ!C38) -> ＰＴＰ | F41: =DBCS(元データ!D38) -> ６０Ｔ | G41: =元データ!E38 -> 東和薬品 | H41: =元データ!F38 -> 60.7 | I41: =元データ!G38 -> 3642 | J41: =元データ!H38 -> 60 | K41: =元データ!I38 -> 錠 | L41: =元データ!J38 -> 2952 | M41: =元データ!K38 -> 49.2 | N41: =IF(OFFSET(マスタ非採用削除!A$4,統合マスタ!$A41,0)="","",OFFSET(マスタ非採用削除!A$4,統合マスタ!$A41,0)) -> ｱｼｽ001 | O41: =IF(OFFSET(マスタ非採用削除!B$4,統合マスタ!$A41,0)="","",OFFSET(マスタ非採用削除!B$4,統合マスタ!$A41,0)) -> ｱｼｽ001 | P41: =IF(OFFSET(マスタ非採用削除!C$4,統合マスタ!$A41,0)="","",OFFSET(マスタ非採用削除!C$4,統合マスタ!$A41,0)) -> アジスロマイシン錠２５０ｍｇ「トーワ」 | Q41: =IF(OFFSET(マスタ非採用削除!D$4,統合マスタ!$A41,0)="","",OFFSET(マスタ非採用削除!D$4,統合マスタ!$A41,0)) -> ｱｼﾞｽ | R41: =IF(OR(A41="非採用",A41="処置薬",A41="非採用特別"),0,IF(OFFSET(マスタ非採用削除!E$4,統合マスタ!$A41,0)="","",OFFSET(マスタ非採用削除!E$4,統合マスタ!$A41,0))) -> 1 | S41: =IF(OFFSET(マスタ非採用削除!F$4,統合マスタ!$A41,0)="","",OFFSET(マスタ非採用削除!F$4,統合マスタ!$A41,0)) | T41: =IF(OFFSET(マスタ非採用削除!G$4,統合マスタ!$A41,0)="","",OFFSET(マスタ非採用削除!G$4,統合マスタ!$A41,0)) -> 60.7 | U41: =IF(OFFSET(マスタ非採用削除!H$4,統合マスタ!$A41,0)="","",OFFSET(マスタ非採用削除!H$4,統合マスタ!$A41,0)) -> ｱｼﾞｽﾛﾏｲｼﾝｼﾞｮｳ250mg｢ﾄｰﾜ｣ | V41: =IF(OFFSET(マスタ非採用削除!I$4,統合マスタ!$A41,0)="","",OFFSET(マスタ非採用削除!I$4,統合マスタ!$A41,0)) -> 1 | W41: =IF(OFFSET(マスタ非採用削除!J$4,統合マスタ!$A41,0)="","",OFFSET(マスタ非採用削除!J$4,統合マスタ!$A41,0)) -> 錠剤 | X41: =IF(OFFSET(マスタ非採用削除!K$4,統合マスタ!$A41,0)="","",OFFSET(マスタ非採用削除!K$4,統合マスタ!$A41,0)) -> 0 | Y41: =IF(OFFSET(マスタ非採用削除!L$4,統合マスタ!$A41,0)="","",OFFSET(マスタ非採用削除!L$4,統合マスタ!$A41,0)) | Z41: =IF(OFFSET(マスタ非採用削除!M$4,統合マスタ!$A41,0)="","",OFFSET(マスタ非採用削除!M$4,統合マスタ!$A41,0)) -> 1 | AA41: =IF(A41="非採用","非採用",IF(A41="処置薬","処置薬","")) | AB41: =IF(A41="非採用特別","非採用特別",IF(R41=2,"臨時", IF(COUNTIF(分類!$H$8:$H$25, 統合マスタ!V41)>0, 分類!$G$7, IF(COUNTIF(分類!$K$8:$K$25, 統合マスタ!V41)>0, 分類!$J$7, IF(COUNTIF(分類!$N$8:$N$25, 統合マスタ!V41)>0, 分類!$M$7, IF(COUNTIF(分類!$Q$8:$Q$25, 統合マスタ!V41)>0, 分類!$P$7, IF(COUNTIF(分類!$T$8:$T$25, 統合マスタ!V41)>0, 分類!$S$7, "無し"))))))) -> 錠剤 | AC41: =X41*100000+B41 -> 37 | AD41: {=IF(A41="非採用","非採用",OFFSET( INDIRECT("'" & AB41 & "'!A4"), MATCH(B41, INDIRECT("'" & AB41 & "'!C5:C1000"), 0), MATCH("合計", INDIRECT("'" & AB41 & "'!4:4"), 0) - 1 ))} -> 147 | AE41: =H41*AD41 -> 8922.9 | AF41: =M41*AD41 -> 7232.4
A42: =元データ!P39 -> 9 | B42: =B41+1 -> 38 | C42: =DBCS(元データ!A39) -> アジルサルタンＯＤ錠２０ｍｇ「サワイ」 | D42: =元データ!B39 -> アルフレッサ | E42: =DBCS(元データ!C39) -> ＰＴＰ | F42: =DBCS(元データ!D39) -> １００Ｔ | G42: =元データ!E39 -> 沢井製薬 | H42: =元データ!F39 -> 27.4 | I42: =元データ!G39 -> 2740 | J42: =元データ!H39 -> 100 | K42: =元データ!I39 -> 錠 | L42: =元データ!J39 -> 2082 | M42: =元データ!K39 -> 20.82 | N42: =IF(OFFSET(マスタ非採用削除!A$4,統合マスタ!$A42,0)="","",OFFSET(マスタ非採用削除!A$4,統合マスタ!$A42,0)) -> ｱｼﾙ003 | O42: =IF(OFFSET(マスタ非採用削除!B$4,統合マスタ!$A42,0)="","",OFFSET(マスタ非採用削除!B$4,統合マスタ!$A42,0)) -> ｱｼﾙ003 | P42: =IF(OFFSET(マスタ非採用削除!C$4,統合マスタ!$A42,0)="","",OFFSET(マスタ非採用削除!C$4,統合マスタ!$A42,0)) -> アジルサルタンＯＤ錠２０ｍｇ「サワイ」 | Q42: =IF(OFFSET(マスタ非採用削除!D$4,統合マスタ!$A42,0)="","",OFFSET(マスタ非採用削除!D$4,統合マスタ!$A42,0)) | R42: =IF(OR(A42="非採用",A42="処置薬",A42="非採用特別"),0,IF(OFFSET(マスタ非採用削除!E$4,統合マスタ!$A42,0)="","",OFFSET(マスタ非採用削除!E$4,統合マスタ!$A42,0))) -> 1 | S42: =IF(OFFSET(マスタ非採用削除!F$4,統合マスタ!$A42,0)="","",OFFSET(マスタ非採用削除!F$4,統合マスタ!$A42,0)) | T42: =IF(OFFSET(マスタ非採用削除!G$4,統合マスタ!$A42,0)="","",OFFSET(マスタ非採用削除!G$4,統合マスタ!$A42,0)) -> 27.4 | U42: =IF(OFFSET(マスタ非採用削除!H$4,統合マスタ!$A42,0)="","",OFFSET(マスタ非採用削除!H$4,統合マスタ!$A42,0)) -> ｱｼﾞﾙｻﾙﾀﾝODｼﾞﾖｳ20MGｻﾜｲ | V42: =IF(OFFSET(マスタ非採用削除!I$4,統合マスタ!$A42,0)="","",OFFSET(マスタ非採用削除!I$4,統合マスタ!$A42,0)) -> 1 | W42: =IF(OFFSET(マスタ非採用削除!J$4,統合マスタ!$A42,0)="","",OFFSET(マスタ非採用削除!J$4,統合マスタ!$A42,0)) -> 錠剤 | X42: =IF(OFFSET(マスタ非採用削除!K$4,統合マスタ!$A42,0)="","",OFFSET(マスタ非採用削除!K$4,統合マスタ!$A42,0)) -> 0 | Y42: =IF(OFFSET(マスタ非採用削除!L$4,統合マスタ!$A42,0)="","",OFFSET(マスタ非採用削除!L$4,統合マスタ!$A42,0)) | Z42: =IF(OFFSET(マスタ非採用削除!M$4,統合マスタ!$A42,0)="","",OFFSET(マスタ非採用削除!M$4,統合マスタ!$A42,0)) -> 25 | AA42: =IF(A42="非採用","非採用",IF(A42="処置薬","処置薬","")) | AB42: =IF(A42="非採用特別","非採用特別",IF(R42=2,"臨時", IF(COUNTIF(分類!$H$8:$H$25, 統合マスタ!V42)>0, 分類!$G$7, IF(COUNTIF(分類!$K$8:$K$25, 統合マスタ!V42)>0, 分類!$J$7, IF(COUNTIF(分類!$N$8:$N$25, 統合マスタ!V42)>0, 分類!$M$7, IF(COUNTIF(分類!$Q$8:$Q$25, 統合マスタ!V42)>0, 分類!$P$7, IF(COUNTIF(分類!$T$8:$T$25, 統合マスタ!V42)>0, 分類!$S$7, "無し"))))))) -> 錠剤 | AC42: =X42*100000+B42 -> 38 | AD42: {=IF(A42="非採用","非採用",OFFSET( INDIRECT("'" & AB42 & "'!A4"), MATCH(B42, INDIRECT("'" & AB42 & "'!C5:C1000"), 0), MATCH("合計", INDIRECT("'" & AB42 & "'!4:4"), 0) - 1 ))} -> 264 | AE42: =H42*AD42 -> 7233.6 | AF42: =M42*AD42 -> 5496.48
