Workbook

Sheet マスタ
A1: 薬品マスタ | B1: 46056
A2: PK | B2: TZMYAKUHINMEISHO | C2: TZMYAKUHIN | D2: TZMYAKUHINBETSUKIHONJOHOKUBUN | E2: TZMYAKUHINMEISHO | F2: TZMYAKUHIN | H2: TZMYAKUHINBETSUKIHONJOHOKUBUN
A3: YAKUHIN_CODE | B3: YAKUHIN_NM | C3: HOST_CODE | D3: SAIYO_DIV | E3: YAKUHIN_NM_KANA | F3: ZAIKEI_CODE | H3: DOKUGEKIYAKU_DIV
A4: コード | B4: 名称 | C4: ホストコード | D4: 採用区分（区分値） | E4: カナ名称 | F4: 剤形(区分値) | G4: 剤形 | H4: 毒劇薬（区分値）
A5: ｱｲﾌ001 | B5: アイファガン点眼液０．１％ | C5: ｱｲﾌｧ | D5: 0 | E5: ｱｲﾌｧｶﾞﾝﾃﾝｶﾞﾝｴｷ0.1% | F5: 21 | G5: 点眼剤 | H5: 0
A6: ｱｳｲ001 | B6: アウィクリ注 フレックスタッチ 総量３００単位 | D6: 2 | E6: ｱｳｲｸﾘﾁﾕｳﾌﾚﾂｸｽﾀﾂﾁｿｳﾘﾖｳ300ﾀﾝｲ | F6: 25 | G6: 注射剤 | H6: 2
A7: ｱｴﾝ001 | B7: 亜鉛華軟膏「ニッコー」 | C7: ｱｴﾝｶﾅﾝ | D7: 1 | E7: ｱｴﾝｶﾅﾝｺｳ｢ﾆｯｺｰ｣ | F7: 14 | G7: 軟膏 | H7: 0
A8: ｱｷﾈ001 | B8: アキネトン細粒１％ | C8: ｱｷﾈﾄﾝｻ | D8: 0 | E8: ｱｷﾈﾄﾝｻｲﾘｭｳ1% | F8: 3 | G8: 散 | H8: 0
A9: ｱｷﾈ002 | B9: アキネトン注射液５ｍｇ | C9: ｱｷﾈﾄﾝﾁ | D9: 1 | E9: ｱｷﾈﾄﾝﾁｭｳｼｬｴｷ5mg | F9: 25 | G9: 注射剤 | H9: 2
A10: ｱｸｱ001 | B10: アクアチムクリーム１％ | C10: ｱｸｱﾁﾑ | D10: 1 | E10: ｱｸｱﾁﾑｸﾘｰﾑ1% | F10: 15 | G10: クリーム | H10: 0
A11: ｱｸﾁ002 | B11: アクチット輸液 | D11: 1 | E11: ｱｸﾁﾂﾄﾕｴｷ | F11: 25 | G11: 注射剤 | H11: 0
A12: ｱｸﾄ001 | B12: アクトシン軟膏３％ | C12: ｱｸﾄｼﾝ | D12: 1 | E12: ｱｸﾄｼﾝﾅﾝｺｳ3% | F12: 14 | G12: 軟膏 | H12: 0
A13: ｱｻﾙ001 | B13: アザルフィジンＥＮ錠５００ｍｇ | C13: ｱｻﾞﾙ1 | D13: 2 | E13: ｱｻﾞﾙﾌｨｼﾞﾝENｼﾞｮｳ500mg | F13: 1 | G13: 錠剤 | H13: 0
A14: ｱｼｸ001 | B14: アシクロビル点滴静注用２５０ｍｇ「サワイ」 | C14: ｱｼｸﾛ | D14: 2 | E14: ｱｼｸﾛﾋﾞﾙﾃﾝﾃｷｼﾞｮｳﾁｭｳﾖｳ250mg｢ｻﾜｲ｣ | F14: 25 | G14: 注射剤 | H14: 0
A15: ｱｼｽ001 | B15: アジスロマイシン錠２５０ｍｇ「トーワ」 | C15: ｱｼﾞｽ | D15: 1 | E15: ｱｼﾞｽﾛﾏｲｼﾝｼﾞｮｳ250mg｢ﾄｰﾜ｣ | F15: 1 | G15: 錠剤 | H15: 0
A16: ｱｼﾙ001 | B16: アジルバ錠１０ｍｇ | C16: ｱｼﾞﾙ1 | D16: 0 | E16: ｱｼﾞﾙﾊﾞｼﾞｮｳ10mg | F16: 1 | G16: 錠剤 | H16: 0
A17: ｱｼﾙ002 | B17: アジルバ錠２０ｍｇ | C17: ｱｼﾞﾙ | D17: 0 | E17: ｱｼﾞﾙﾊﾞｼﾞｮｳ20mg | F17: 1 | G17: 錠剤 | H17: 0
A18: ｱｼﾙ003 | B18: アジルサルタンＯＤ錠２０ｍｇ「サワイ」 | D18: 1 | E18: ｱｼﾞﾙｻﾙﾀﾝODｼﾞﾖｳ20MGｻﾜｲ | F18: 1 | G18: 錠剤 | H18: 0
A19: ｱｽｺ001 | B19: アスコルビン酸注射液５００ｍｇ「日医工」 | C19: ｱｽｺ | D19: 0 | E19: ｱｽｺﾙﾋﾞﾝｻﾝﾁｭｳｼｬｴｷ500mg｢ﾆﾁｲｺｳ｣ | F19: 25 | G19: 注射剤 | H19: 0
A20: ｱｽｺ002 | B20: アスコルビン酸注射液５００ｍｇ「トーワ」 | D20: 0 | E20: ｱｽｺﾙﾋﾞﾝｻﾝﾁﾕｳｼﾔｴｷ500MGﾄ-ﾜ | F20: 25 | G20: 注射剤 | H20: 0
A21: ｱｽｺ003 | B21: アスコルビン酸注５００ｍｇ「イセイ」 | D21: 1 | E21: ｱｽｺﾙﾋﾞﾝｻﾝﾁﾕｳ500MGｲｾｲ | F21: 25 | G21: 注射剤 | H21: 0
A22: ｱｽﾉ001 | B22: アズノールＳＴ錠口腔用５ｍｇ | C22: ｱｽﾞﾉ1 | D22: 0 | E22: ｱｽﾞﾉｰﾙSTｼﾞｮｳｺｳｸｳﾖｳ5mg | F22: 8 | G22: トローチ | H22: 0
A23: ｱｽﾉ002 | B23: アズノール軟膏０．０３３％ | C23: ｱｽﾞﾉ3 | D23: 1 | E23: ｱｽﾞﾉｰﾙﾅﾝｺｳ0.033% | F23: 14 | G23: 軟膏 | H23: 0
A24: ｱｽﾉ003 | B24: アズノール錠２ｍｇ | D24: 0 | E24: ｱｽﾞﾉ-ﾙｼﾞﾖｳ2MG | F24: 1 | G24: 錠剤 | H24: 0
A25: ｱｽﾊ001 | B25: アスパラ－ＣＡ錠２００ | C25: ｱｽﾊﾟ | D25: 1 | E25: ｱｽﾊﾟﾗ-CAｼﾞｮｳ200 | F25: 1 | G25: 錠剤 | H25: 0
A26: ｱｽﾊ002 | B26: アスパラカリウム錠３００ｍｇ | C26: ｱｽﾊﾟﾗ | D26: 1 | E26: ｱｽﾊﾟﾗｶﾘｳﾑｼﾞｮｳ300mg | F26: 1 | G26: 錠剤 | H26: 0
A27: ｱｽﾊ003 | B27: アスパラカリウム散５０％ | C27: ｱｽﾊﾟ1 | D27: 1 | E27: ｱｽﾊﾟﾗｶﾘｳﾑｻﾝ50% | F27: 3 | G27: 散 | H27: 0
A28: ｱｽﾊ004 | B28: アスパラギン酸カリウム注１０ｍＥｑキット「テルモ」 | C28: ｱｽﾊﾟ2 | D28: 1 | E28: ｱｽﾊﾟﾗｷﾞﾝｻﾝｶﾘｳﾑﾁｭｳ10mEqｷｯﾄ｢ﾃﾙﾓ｣ | F28: 25 | G28: 注射剤 | H28: 0
A29: ｱｽﾚ001 | B29: アズレン点眼液０．０２％「ニットー」 | C29: ｱｽﾞﾚ | D29: 1 | E29: ｱｽﾞﾚﾝﾃﾝｶﾞﾝｴｷ0.02%｢ﾆｯﾄｰ｣ | F29: 21 | G29: 点眼剤 | H29: 0
A30: ｱｽﾚ002 | B30: アズレン点眼液わかもと | D30: 0 | E30: ｱｽﾞﾚﾝﾃﾝｶﾞﾝｴｷﾜｶﾓﾄ | F30: 21 | G30: 点眼剤 | H30: 0
A31: ｱｾﾘ001 | B31: アセリオ静注液１０００ｍｇバッグ | C31: ｱｾﾘ | D31: 2 | E31: ｱｾﾘｵｼﾞｮｳﾁｭｳｴｷ1000mgﾊﾞｯｸﾞ | F31: 25 | G31: 注射剤 | H31: 2
A32: ｱｾﾚ001 | B32: アセレンド注１００μｇ | C32: ｱｾﾚ | D32: 2 | E32: ｱｾﾚﾝﾄﾞﾁｭｳ100μg | F32: 25 | G32: 注射剤 | H32: 2
A33: ｱｿｾ001 | B33: アゾセミド錠３０ｍｇ「ＪＧ」 | C33: ｱｿﾞｾ1 | D33: 0 | E33: ｱｿﾞｾﾐﾄﾞｼﾞｮｳ30mg｢JG｣ | F33: 1 | G33: 錠剤 | H33: 0
A34: ｱｿｾ002 | B34: アゾセミド錠３０ｍｇ「ＤＳＥＰ」 | C34: ｱｿﾞｾ2 | D34: 2 | E34: ｱｿﾞｾﾐﾄﾞｼﾞｮｳ30mg｢DSEP｣ | F34: 1 | G34: 錠剤 | H34: 0
A35: ｱｿｾ003 | B35: アゾセミド錠６０ｍｇ「ＤＳＥＰ」 | C35: ｱｿﾞｾ | D35: 0 | E35: ｱｿﾞｾﾐﾄﾞｼﾞｮｳ60mg｢DSEP｣ | F35: 1 | G35: 錠剤 | H35: 0
A36: ｱﾀﾗ001 | B36: アタラックス錠２５ｍｇ | C36: ｱﾀﾗｯ2 | D36: 1 | E36: ｱﾀﾗｯｸｽｼﾞｮｳ25mg | F36: 1 | G36: 錠剤 | H36: 0
A37: ｱﾀﾗ002 | B37: アダラートＣＲ錠２０ｍｇ | C37: ｱﾀﾞﾗ | D37: 1 | E37: ｱﾀﾞﾗｰﾄCRｼﾞｮｳ20mg | F37: 1 | G37: 錠剤 | H37: 2
A38: ｱﾁｽ001 | B38: アーチスト錠１．２５ｍｇ | C38: ｱｰﾁ | D38: 1 | E38: ｱｰﾁｽﾄｼﾞｮｳ1.25mg | F38: 1 | G38: 錠剤 | H38: 0
A39: ｱﾄｴ001 | B39: アドエア５００ディスカス６０吸入用 | C39: ｱﾄﾞｴ | D39: 2 | E39: ｱﾄﾞｴｱ500ﾃﾞｨｽｶｽ60ｷｭｳﾆｭｳﾖｳ | F39: 10 | G39: 吸入剤 | H39: 0
A40: ｱﾄﾅ001 | B40: アドナ錠３０ｍｇ | C40: ｱﾄﾞﾅ | D40: 1 | E40: ｱﾄﾞﾅｼﾞｮｳ30mg | F40: 1 | G40: 錠剤 | H40: 0
...

Sheet 臨時
B2: {=RIGHT(CELL("filename",A1),LEN(CELL("filename",A1))-FIND("]",CELL("filename",A1)))} -> 臨時
B4: No | C4: 薬品名 | D4: 毒劇区分
B5: 1 | C5: {=_xlfn._xlws.SORT(_xlfn.CHOOSECOLS(_xlfn._xlws.FILTER(マスタ!A5:H2000,マスタ!D5:D2000=2),2,8),2,1)} -> アザルフィジンＥＮ錠５００ｍｇ | D5: 0
B6: =B5+1 -> 2 | C6: アシクロビル点滴静注用２５０ｍｇ「サワイ」 | D6: 0
B7: =B6+1 -> 3 | C7: アゾセミド錠３０ｍｇ「ＤＳＥＰ」 | D7: 0
B8: =B7+1 -> 4 | C8: アドエア５００ディスカス６０吸入用 | D8: 0
B9: =B8+1 -> 5 | C9: アミノレバン点滴静注（用時購入） | D9: 0
B10: =B9+1 -> 6 | C10: イノソリッド配合経腸用半固形剤 | D10: 0
B11: =B10+1 -> 7 | C11: イントラリポス輸液２０％ | D11: 0
B12: =B11+1 -> 8 | C12: エイゾプト懸濁性点眼液１％ | D12: 0
B13: =B12+1 -> 9 | C13: エゼチミブＯＤ錠１０ｍｇ「トーワ」 | D13: 0
B14: =B13+1 -> 10 | C14: エフィエント錠２．５ｍｇ | D14: 0
B15: =B14+1 -> 11 | C15: エフィナコナゾール爪外用液１０％「サワイ」 | D15: 0
B16: =B15+1 -> 12 | C16: エリキュース錠２．５ｍｇ | D16: 0
B17: =B16+1 -> 13 | C17: エリスロシン錠２００ｍｇ | D17: 0
... B165: =B164+1 -> 161 | C165: レルパックス錠２０ｍｇ | D165: 2
B166: =B165+1 -> 162
B167: =B166+1 -> 163
B168: =B167+1 -> 164
B169: =B168+1 -> 165
B170: =B169+1 -> 166
B171: =B170+1 -> 167
B172: =B171+1 -> 168
B173: =B172+1 -> 169
B174: =B173+1 -> 170
B175: =B174+1 -> 171
B176: =B175+1 -> 172
B177: =B176+1 -> 173
... B304: =B303+1 -> 300

Sheet 外用
B2: {=RIGHT(CELL("filename",A1),LEN(CELL("filename",A1))-FIND("]",CELL("filename",A1)))} -> 外用
B4: No | C4: 薬品名 | D4: 毒劇区分
B5: 1 | C5: {=_xlfn._xlws.SORT(_xlfn.CHOOSECOLS(_xlfn._xlws.FILTER(マスタ!A2:H10000,(マスタ!D2:D10000=1)*ISNUMBER(MATCH(マスタ!F2:F10000,分類!H8:H15,0))),2,8),2,1)} -> 亜鉛華軟膏「ニッコー」 | D5: 0
B6: =B5+1 -> 2 | C6: アクアチムクリーム１％ | D6: 0
B7: =B6+1 -> 3 | C7: アクトシン軟膏３％ | D7: 0
B8: =B7+1 -> 4 | C8: アズノール軟膏０．０３３％ | D8: 0
B9: =B8+1 -> 5 | C9: アズレン点眼液０．０２％「ニットー」 | D9: 0
B10: =B9+1 -> 6 | C10: アドフィードパップ４０ｍｇ | D10: 0
B11: =B10+1 -> 7 | C11: インテバン外用液１％ | D11: 0
B12: =B11+1 -> 8 | C12: インテバンクリーム１％ | D12: 0
B13: =B12+1 -> 9 | C13: ＳＰトローチ０．２５ｍｇ「明治」 | D13: 0
B14: =B13+1 -> 10 | C14: オイラックスクリーム１０％ | D14: 0
B15: =B14+1 -> 11 | C15: オフロキサシン点眼液０．３％「ＪＧ」 | D15: 0
B16: =B15+1 -> 12 | C16: キュバール１００エアゾール | D16: 0
B17: =B16+1 -> 13 | C17: クロモグリク酸Ｎａ点眼液２％「ニットー」 | D17: 0
... B69: =B68+1 -> 65 | C69: ロナセンテープ４０ｍｇ | D69: 2
B70: =B69+1 -> 66
B71: =B70+1 -> 67
B72: =B71+1 -> 68
B73: =B72+1 -> 69
B74: =B73+1 -> 70
B75: =B74+1 -> 71
B76: =B75+1 -> 72
B77: =B76+1 -> 73
B78: =B77+1 -> 74
B79: =B78+1 -> 75
B80: =B79+1 -> 76
B81: =B80+1 -> 77
... B304: =B303+1 -> 300

Sheet 散剤
B2: {=RIGHT(CELL("filename",A1),LEN(CELL("filename",A1))-FIND("]",CELL("filename",A1)))} -> 散剤
B4: No | C4: 薬品名 | D4: 毒劇区分
B5: 1 | C5: {=_xlfn._xlws.SORT(_xlfn.CHOOSECOLS(_xlfn._xlws.FILTER(マスタ!A2:H10000,(マスタ!D2:D10000=1)*ISNUMBER(MATCH(マスタ!F2:F10000,分類!K8:K15,0))),2,8),2,1)} -> アスパラカリウム散５０％ | D5: 0
B6: =B5+1 -> 2 | C6: アドナ散１０％ | D6: 0
B7: =B6+1 -> 3 | C7: アミノレバンＥＮ配合散 | D7: 0
B8: =B7+1 -> 4 | C8: 胃散(院内製剤) | D8: 0
B9: =B8+1 -> 5 | C9: エチゾラム細粒１％「ＪＧ」 | D9: 0
B10: =B9+1 -> 6 | C10: 塩化カリウム | D10: 0
B11: =B10+1 -> 7 | C11: 塩化ナトリウム | D11: 0
B12: =B11+1 -> 8 | C12: カルバマゼピン細粒５０％「アメル」 | D12: 0
B13: =B12+1 -> 9 | C13: クラシエ葛根湯エキス細粒 | D13: 0
B14: =B13+1 -> 10 | C14: クラシエ加味逍遙散料エキス細粒 | D14: 0
B15: =B14+1 -> 11 | C15: クラシエ補中益気湯エキス細粒 | D15: 0
B16: =B15+1 -> 12 | C16: グラマリール細粒１０％ | D16: 0
B17: =B16+1 -> 13 | C17: クレメジン細粒分包２ｇ | D17: 0
... B56: =B55+1 -> 52 | C56: ロドピン細粒５０％ | D56: 2
B57: =B56+1 -> 53
B58: =B57+1 -> 54
B59: =B58+1 -> 55
B60: =B59+1 -> 56
B61: =B60+1 -> 57
B62: =B61+1 -> 58
B63: =B62+1 -> 59
B64: =B63+1 -> 60
B65: =B64+1 -> 61
B66: =B65+1 -> 62
B67: =B66+1 -> 63
B68: =B67+1 -> 64
... B304: =B303+1 -> 300

Sheet 錠剤
B2: {=RIGHT(CELL("filename",A1),LEN(CELL("filename",A1))-FIND("]",CELL("filename",A1)))} -> 錠剤
B4: No | C4: 薬品名 | D4: 毒劇区分
B5: 1 | C5: {=_xlfn._xlws.SORT(_xlfn.CHOOSECOLS(_xlfn._xlws.FILTER(マスタ!A2:H10000,(マスタ!D2:D10000=1)*ISNUMBER(MATCH(マスタ!F2:F10000,分類!N8:N15,0))),2,8),2,1)} -> アジスロマイシン錠２５０ｍｇ「トーワ」 | D5: 0
B6: =B5+1 -> 2 | C6: アジルサルタンＯＤ錠２０ｍｇ「サワイ」 | D6: 0
B7: =B6+1 -> 3 | C7: アスパラ－ＣＡ錠２００ | D7: 0
B8: =B7+1 -> 4 | C8: アスパラカリウム錠３００ｍｇ | D8: 0
B9: =B8+1 -> 5 | C9: アタラックス錠２５ｍｇ | D9: 0
B10: =B9+1 -> 6 | C10: アーチスト錠１．２５ｍｇ | D10: 0
B11: =B10+1 -> 7 | C11: アドナ錠３０ｍｇ | D11: 0
B12: =B11+1 -> 8 | C12: アトルバスタチンＯＤ錠１０ｍｇ「トーワ」 | D12: 0
B13: =B12+1 -> 9 | C13: アマンタジン塩酸塩錠５０ｍｇ「杏林」 | D13: 0
B14: =B13+1 -> 10 | C14: ２５ｍｇアリナミンＦ糖衣錠 | D14: 0
B15: =B14+1 -> 11 | C15: アルダクトンＡ錠２５ｍｇ | D15: 0
B16: =B15+1 -> 12 | C16: アロプリノール錠１００ｍｇ「サワイ」 | D16: 0
B17: =B16+1 -> 13 | C17: イルベサルタン錠５０ｍｇ「サワイ」 | D17: 0
... B257: =B256+1 -> 253 | C257: ロドピン錠５０ｍｇ | D257: 2
B258: =B257+1 -> 254
B259: =B258+1 -> 255
B260: =B259+1 -> 256
B261: =B260+1 -> 257
B262: =B261+1 -> 258
B263: =B262+1 -> 259
B264: =B263+1 -> 260
B265: =B264+1 -> 261
B266: =B265+1 -> 262
B267: =B266+1 -> 263
B268: =B267+1 -> 264
B269: =B268+1 -> 265
... B304: =B303+1 -> 300

Sheet 注射
B2: {=RIGHT(CELL("filename",A1),LEN(CELL("filename",A1))-FIND("]",CELL("filename",A1)))} -> 注射
B4: No | C4: 薬品名 | D4: 毒劇区分
B5: 1 | C5: {=_xlfn._xlws.SORT(_xlfn.CHOOSECOLS(_xlfn._xlws.FILTER(マスタ!A2:H10000,(マスタ!D2:D10000=1)*ISNUMBER(MATCH(マスタ!F2:F10000,分類!Q8:Q15,0))),2,8),2,1)} -> アクチット輸液 | D5: 0
B6: =B5+1 -> 2 | C6: アスコルビン酸注５００ｍｇ「イセイ」 | D6: 0
B7: =B6+1 -> 3 | C7: アスパラギン酸カリウム注１０ｍＥｑキット「テルモ」 | D7: 0
B8: =B7+1 -> 4 | C8: アドナ注（静脈用）５０ｍｇ | D8: 0
B9: =B8+1 -> 5 | C9: アルブミナー２５％静注１２．５ｇ／５０ｍＬ | D9: 0
B10: =B9+1 -> 6 | C10: イベニティ皮下注１０５ｍｇシリンジ | D10: 0
B11: =B10+1 -> 7 | C11: １０％塩化ナトリウム注射液 | D11: 0
B12: =B11+1 -> 8 | C12: グリセオール注 | D12: 0
B13: =B12+1 -> 9 | C13: クリンダマイシンリン酸エステル６００ｍｇ注射液 | D13: 0
B14: =B13+1 -> 10 | C14: ケイツーＮ静注１０ｍｇ | D14: 0
B15: =B14+1 -> 11 | C15: ジアゼパム注射液５ｍｇ「ＮＩＧ」 | D15: 0
B16: =B15+1 -> 12 | C16: 照射赤血球液－ＬＲ「日赤」 | D16: 0
B17: =B16+1 -> 13 | C17: 水溶性ハイドロコートン注射液 | D17: 0
... B103: =B102+1 -> 99 | C103: ワソラン静注５ｍｇ | D103: 2
B104: =B103+1 -> 100
B105: =B104+1 -> 101
B106: =B105+1 -> 102
B107: =B106+1 -> 103
B108: =B107+1 -> 104
B109: =B108+1 -> 105
B110: =B109+1 -> 106
B111: =B110+1 -> 107
B112: =B111+1 -> 108
B113: =B112+1 -> 109
B114: =B113+1 -> 110
B115: =B114+1 -> 111
... B304: =B303+1 -> 300

Sheet 分類
A2: No | B2: 分類
A3: 1 | B3: 錠剤 | F3: 採用０（非採用）はいらない
A4: 2 | B4: カプセル | F4: 採用２（臨時採用薬）で1グループ
A5: 3 | B5: 散 | F5: 採用１（採用薬）
A6: 4 | B6: 細粒
A7: 5 | B7: 顆粒 | G7: 外用剤 | J7: 散剤 | M7: 錠剤 | P7: 注射
A8: 6 | B8: シロップ | G8: クリーム | H8: 15 | J8: 散剤 | K8: 3 | M8: 錠剤 | N8: 1 | P8: 注射 | Q8: 25
A9: 7 | B9: 液（内用） | G9: 軟膏 | H9: 14
A10: 8 | B10: トローチ | G10: トローチ | H10: 8
A11: 9 | B11: 含漱剤 | G11: 点眼 | H11: 21
A12: 10 | B12: 吸入剤 | G12: 点鼻 | H12: 23
A13: 11 | B13: 膣錠 | G13: 外用剤 | H13: 17
A14: 12 | B14: 坐剤 | G14: 吸入 | H14: 10
A15: 13 | B15: 浣腸 | G15: 貼付薬 | H15: 19
A16: 14 | B16: 軟膏
A17: 15 | B17: クリーム
A18: 16 | B18: ゼリー（ゲル）
A19: 17 | B19: 外用液剤
A20: 18 | B20: 噴霧剤
A21: 19 | B21: 貼付剤
A22: 21 | B22: 点眼剤
A23: 22 | B23: 点耳薬
A24: 23 | B24: 点鼻薬
A25: 24 | B25: その他
A26: 25 | B26: 注射剤
