Workbook

Sheet 統合マスタ
C3: 棚卸 | N3: マスタ
B4: no | C4: 名称 | D4: 2025年度卸 | E4: 包装形態 | F4: 容量 | G4: メーカー | H4: 新単位薬価 | I4: 2025年度薬価 | J4: 単位数量 | K4: 薬価単位 | L4: 2025年納入価格 | M4: 単位納入価 | N4: コード(区分値) | O4: コード | P4: 名称 | Q4: ホストコード | R4: 採用区分（区分値）(区分値) | S4: 採用区分（区分値） | T4: 薬価 | U4: カナ名称 | V4: 剤形(区分値) | W4: 剤形 | X4: 毒劇薬（区分値）(区分値) | Y4: 毒劇薬（区分値） | Z4: 棚 | AA4: 非採用
A5: =元データ!P2 -> 295 | B5: 1 | C5: =DBCS(元データ!A2) -> ００７ ツムラ ハチミジオウガン | D5: =元データ!B2 -> メディセオ | E5: =DBCS(元データ!C2) -> 粉 | F5: =DBCS(元データ!D2) -> ２．５ｇｘ１８９ | G5: =元データ!E2 -> ツムラ | H5: =元データ!F2 -> 9.8 | I5: =元データ!G2 -> 4630.5 | J5: =元データ!H2 -> 472.5 | K5: =元データ!I2 -> ｇ | L5: =元データ!J2 -> 4093 | M5: =元データ!K2 -> 8.6624339 | N5: =IF(OFFSET(マスタ非採用削除!A$4,統合マスタ!$A5,0)="","",OFFSET(マスタ非採用削除!A$4,統合マスタ!$A5,0)) -> ﾂﾑﾗ007 | O5: =IF(OFFSET(マスタ非採用削除!B$4,統合マスタ!$A5,0)="","",OFFSET(マスタ非採用削除!B$4,統合マスタ!$A5,0)) -> ﾂﾑﾗ007 | P5: =IF(OFFSET(マスタ非採用削除!C$4,統合マスタ!$A5,0)="","",OFFSET(マスタ非採用削除!C$4,統合マスタ!$A5,0)) -> ツムラ八味地黄丸エキス顆粒（医療用） | Q5: =IF(OFFSET(マスタ非採用削除!D$4,統合マスタ!$A5,0)="","",OFFSET(マスタ非採用削除!D$4,統合マスタ!$A5,0)) -> ﾊﾁﾐ | R5: =IF(OFFSET(マスタ非採用削除!E$4,統合マスタ!$A5,0)="","",OFFSET(マスタ非採用削除!E$4,統合マスタ!$A5,0)) -> 2 | S5: =IF(OFFSET(マスタ非採用削除!F$4,統合マスタ!$A5,0)="","",OFFSET(マスタ非採用削除!F$4,統合マスタ!$A5,0)) | T5: =IF(OFFSET(マスタ非採用削除!G$4,統合マスタ!$A5,0)="","",OFFSET(マスタ非採用削除!G$4,統合マスタ!$A5,0)) -> 9.8 | U5: =IF(OFFSET(マスタ非採用削除!H$4,統合マスタ!$A5,0)="","",OFFSET(マスタ非採用削除!H$4,統合マスタ!$A5,0)) -> ﾂﾑﾗﾊﾁﾐｼﾞｵｳｶﾞﾝｴｷｽｶﾘｭｳ(ｲﾘｮｳﾖｳ) | ... Z5: =IF(OFFSET(マスタ非採用削除!M$4,統合マスタ!$A5,0)="","",OFFSET(マスタ非採用削除!M$4,統合マスタ!$A5,0)) -> 4
A6: =元データ!P3 -> 295 | B6: =B5+1 -> 2 | C6: =DBCS(元データ!A3) -> ００７ ツムラ ハチミジオウガン | D6: =元データ!B3 | E6: =DBCS(元データ!C3) -> 粉 | F6: =DBCS(元データ!D3) -> ２．５ｇｘ４２ | G6: =元データ!E3 -> ツムラ | H6: =元データ!F3 -> 9.8 | I6: =元データ!G3 -> 1029 | J6: =元データ!H3 -> 105 | K6: =元データ!I3 -> ｇ | L6: =元データ!J3 -> 935 | M6: =元データ!K3 -> 8.9047619 | N6: =IF(OFFSET(マスタ非採用削除!A$4,統合マスタ!$A6,0)="","",OFFSET(マスタ非採用削除!A$4,統合マスタ!$A6,0)) -> ﾂﾑﾗ007 | O6: =IF(OFFSET(マスタ非採用削除!B$4,統合マスタ!$A6,0)="","",OFFSET(マスタ非採用削除!B$4,統合マスタ!$A6,0)) -> ﾂﾑﾗ007 | P6: =IF(OFFSET(マスタ非採用削除!C$4,統合マスタ!$A6,0)="","",OFFSET(マスタ非採用削除!C$4,統合マスタ!$A6,0)) -> ツムラ八味地黄丸エキス顆粒（医療用） | Q6: =IF(OFFSET(マスタ非採用削除!D$4,統合マスタ!$A6,0)="","",OFFSET(マスタ非採用削除!D$4,統合マスタ!$A6,0)) -> ﾊﾁﾐ | R6: =IF(OFFSET(マスタ非採用削除!E$4,統合マスタ!$A6,0)="","",OFFSET(マスタ非採用削除!E$4,統合マスタ!$A6,0)) -> 2 | S6: =IF(OFFSET(マスタ非採用削除!F$4,統合マスタ!$A6,0)="","",OFFSET(マスタ非採用削除!F$4,統合マスタ!$A6,0)) | T6: =IF(OFFSET(マスタ非採用削除!G$4,統合マスタ!$A6,0)="","",OFFSET(マスタ非採用削除!G$4,統合マスタ!$A6,0)) -> 9.8 | U6: =IF(OFFSET(マスタ非採用削除!H$4,統合マスタ!$A6,0)="","",OFFSET(マスタ非採用削除!H$4,統合マスタ!$A6,0)) -> ﾂﾑﾗﾊﾁﾐｼﾞｵｳｶﾞﾝｴｷｽｶﾘｭｳ(ｲﾘｮｳﾖｳ) | ... Z6: =IF(OFFSET(マスタ非採用削除!M$4,統合マスタ!$A6,0)="","",OFFSET(マスタ非採用削除!M$4,統合マスタ!$A6,0)) -> 4
A7: =元データ!P4 -> 296 | B7: =B6+1 -> 3 | C7: =DBCS(元データ!A4) -> ０１２ ツムラ サイコカリュウコツボレイトウ | D7: =元データ!B4 -> メディセオ | E7: =DBCS(元データ!C4) -> 粉 | F7: =DBCS(元データ!D4) -> ２．５ｇｘ１８９ | G7: =元データ!E4 -> ツムラ | H7: =元データ!F4 -> 20.3 | I7: =元データ!G4 -> 9591.75 | J7: =元データ!H4 -> 472.5 | K7: =元データ!I4 -> g | L7: =元データ!J4 -> 8544 | M7: =元データ!K4 -> 18.08254 | N7: =IF(OFFSET(マスタ非採用削除!A$4,統合マスタ!$A7,0)="","",OFFSET(マスタ非採用削除!A$4,統合マスタ!$A7,0)) -> ﾂﾑﾗ012 | O7: =IF(OFFSET(マスタ非採用削除!B$4,統合マスタ!$A7,0)="","",OFFSET(マスタ非採用削除!B$4,統合マスタ!$A7,0)) -> ﾂﾑﾗ012 | P7: =IF(OFFSET(マスタ非採用削除!C$4,統合マスタ!$A7,0)="","",OFFSET(マスタ非採用削除!C$4,統合マスタ!$A7,0)) -> ツムラ柴胡加竜骨牡蛎湯エキス顆粒（医療用） | Q7: =IF(OFFSET(マスタ非採用削除!D$4,統合マスタ!$A7,0)="","",OFFSET(マスタ非採用削除!D$4,統合マスタ!$A7,0)) -> ｻｲｺ | R7: =IF(OFFSET(マスタ非採用削除!E$4,統合マスタ!$A7,0)="","",OFFSET(マスタ非採用削除!E$4,統合マスタ!$A7,0)) -> 2 | S7: =IF(OFFSET(マスタ非採用削除!F$4,統合マスタ!$A7,0)="","",OFFSET(マスタ非採用削除!F$4,統合マスタ!$A7,0)) | T7: =IF(OFFSET(マスタ非採用削除!G$4,統合マスタ!$A7,0)="","",OFFSET(マスタ非採用削除!G$4,統合マスタ!$A7,0)) -> 20.3 | U7: =IF(OFFSET(マスタ非採用削除!H$4,統合マスタ!$A7,0)="","",OFFSET(マスタ非採用削除!H$4,統合マスタ!$A7,0)) -> ﾂﾑﾗｻｲｺｶﾘｭｳｺﾂﾎﾞﾚｲﾄｳｴｷｽｶﾘｭｳ(ｲﾘｮｳﾖｳ) | ... Z7: =IF(OFFSET(マスタ非採用削除!M$4,統合マスタ!$A7,0)="","",OFFSET(マスタ非採用削除!M$4,統合マスタ!$A7,0)) -> 4
A8: =元データ!P5 -> 297 | B8: =B7+1 -> 4 | C8: =DBCS(元データ!A5) -> ０１６ ツムラ ハンゲコウボクトウ | D8: =元データ!B5 -> メディセオ | E8: =DBCS(元データ!C5) -> 粉 | F8: =DBCS(元データ!D5) -> ２．５ｇｘ１８９ | G8: =元データ!E5 -> ツムラ | H8: =元データ!F5 -> 14.6 | I8: =元データ!G5 -> 6898.5 | J8: =元データ!H5 -> 472.5 | K8: =元データ!I5 -> ｇ | L8: =元データ!J5 -> 6211 | M8: =元データ!K5 -> 13.144974 | N8: =IF(OFFSET(マスタ非採用削除!A$4,統合マスタ!$A8,0)="","",OFFSET(マスタ非採用削除!A$4,統合マスタ!$A8,0)) -> ﾂﾑﾗ016 | O8: =IF(OFFSET(マスタ非採用削除!B$4,統合マスタ!$A8,0)="","",OFFSET(マスタ非採用削除!B$4,統合マスタ!$A8,0)) -> ﾂﾑﾗ016 | P8: =IF(OFFSET(マスタ非採用削除!C$4,統合マスタ!$A8,0)="","",OFFSET(マスタ非採用削除!C$4,統合マスタ!$A8,0)) -> ツムラ半夏厚朴湯エキス顆粒（医療用） | Q8: =IF(OFFSET(マスタ非採用削除!D$4,統合マスタ!$A8,0)="","",OFFSET(マスタ非採用削除!D$4,統合マスタ!$A8,0)) -> ﾊﾝｹﾞｺ | R8: =IF(OFFSET(マスタ非採用削除!E$4,統合マスタ!$A8,0)="","",OFFSET(マスタ非採用削除!E$4,統合マスタ!$A8,0)) -> 2 | S8: =IF(OFFSET(マスタ非採用削除!F$4,統合マスタ!$A8,0)="","",OFFSET(マスタ非採用削除!F$4,統合マスタ!$A8,0)) | T8: =IF(OFFSET(マスタ非採用削除!G$4,統合マスタ!$A8,0)="","",OFFSET(マスタ非採用削除!G$4,統合マスタ!$A8,0)) -> 14.6 | U8: =IF(OFFSET(マスタ非採用削除!H$4,統合マスタ!$A8,0)="","",OFFSET(マスタ非採用削除!H$4,統合マスタ!$A8,0)) -> ﾂﾑﾗﾊﾝｹﾞｺｳﾎﾞｸﾄｳｴｷｽｶﾘｭｳ(ｲﾘｮｳﾖｳ) | ... Z8: =IF(OFFSET(マスタ非採用削除!M$4,統合マスタ!$A8,0)="","",OFFSET(マスタ非採用削除!M$4,統合マスタ!$A8,0)) -> 4
A9: =元データ!P6 -> 298 | B9: =B8+1 -> 5 | C9: =DBCS(元データ!A6) -> ０１７ ツムラ ゴレイサン | D9: =元データ!B6 -> メディセオ | E9: =DBCS(元データ!C6) -> 粉 | F9: =DBCS(元データ!D6) -> ２．５ｇｘ１８９ | G9: =元データ!E6 -> ツムラ | H9: =元データ!F6 -> 13.6 | I9: =元データ!G6 -> 6426 | J9: =元データ!H6 -> 472.5 | K9: =元データ!I6 -> g | L9: =元データ!J6 -> 5728 | M9: =元データ!K6 -> 12.122751 | N9: =IF(OFFSET(マスタ非採用削除!A$4,統合マスタ!$A9,0)="","",OFFSET(マスタ非採用削除!A$4,統合マスタ!$A9,0)) -> ﾂﾑﾗ017 | O9: =IF(OFFSET(マスタ非採用削除!B$4,統合マスタ!$A9,0)="","",OFFSET(マスタ非採用削除!B$4,統合マスタ!$A9,0)) -> ﾂﾑﾗ017 | P9: =IF(OFFSET(マスタ非採用削除!C$4,統合マスタ!$A9,0)="","",OFFSET(マスタ非採用削除!C$4,統合マスタ!$A9,0)) -> ツムラ五苓散エキス顆粒（医療用） | Q9: =IF(OFFSET(マスタ非採用削除!D$4,統合マスタ!$A9,0)="","",OFFSET(マスタ非採用削除!D$4,統合マスタ!$A9,0)) -> ｺﾞﾚｲ | R9: =IF(OFFSET(マスタ非採用削除!E$4,統合マスタ!$A9,0)="","",OFFSET(マスタ非採用削除!E$4,統合マスタ!$A9,0)) -> 1 | S9: =IF(OFFSET(マスタ非採用削除!F$4,統合マスタ!$A9,0)="","",OFFSET(マスタ非採用削除!F$4,統合マスタ!$A9,0)) | T9: =IF(OFFSET(マスタ非採用削除!G$4,統合マスタ!$A9,0)="","",OFFSET(マスタ非採用削除!G$4,統合マスタ!$A9,0)) -> 13.6 | U9: =IF(OFFSET(マスタ非採用削除!H$4,統合マスタ!$A9,0)="","",OFFSET(マスタ非採用削除!H$4,統合マスタ!$A9,0)) -> ﾂﾑﾗｺﾞﾚｲｻﾝｴｷｽｶﾘｭｳ(ｲﾘｮｳﾖｳ) | ... Z9: =IF(OFFSET(マスタ非採用削除!M$4,統合マスタ!$A9,0)="","",OFFSET(マスタ非採用削除!M$4,統合マスタ!$A9,0)) -> 4
A10: =元データ!P7 -> 299 | B10: =B9+1 -> 6 | C10: =DBCS(元データ!A7) -> ０１９ ツムラ ショウセイリュウトウ | D10: =元データ!B7 -> メディセオ | E10: =DBCS(元データ!C7) -> 粉 | F10: =DBCS(元データ!D7) -> ３ｇＸ４２ | G10: =元データ!E7 -> ツムラ | H10: =元データ!F7 -> 12.8 | I10: =元データ!G7 -> 1612.8 | J10: =元データ!H7 -> 126 | K10: =元データ!I7 -> g | L10: =元データ!J7 -> 1465 | M10: =元データ!K7 -> 11.626984 | N10: =IF(OFFSET(マスタ非採用削除!A$4,統合マスタ!$A10,0)="","",OFFSET(マスタ非採用削除!A$4,統合マスタ!$A10,0)) -> ﾂﾑﾗ019 | O10: =IF(OFFSET(マスタ非採用削除!B$4,統合マスタ!$A10,0)="","",OFFSET(マスタ非採用削除!B$4,統合マスタ!$A10,0)) -> ﾂﾑﾗ019 | P10: =IF(OFFSET(マスタ非採用削除!C$4,統合マスタ!$A10,0)="","",OFFSET(マスタ非採用削除!C$4,統合マスタ!$A10,0)) -> ツムラ小青竜湯エキス顆粒（医療用） | Q10: =IF(OFFSET(マスタ非採用削除!D$4,統合マスタ!$A10,0)="","",OFFSET(マスタ非採用削除!D$4,統合マスタ!$A10,0)) | R10: =IF(OFFSET(マスタ非採用削除!E$4,統合マスタ!$A10,0)="","",OFFSET(マスタ非採用削除!E$4,統合マスタ!$A10,0)) -> 2 | S10: =IF(OFFSET(マスタ非採用削除!F$4,統合マスタ!$A10,0)="","",OFFSET(マスタ非採用削除!F$4,統合マスタ!$A10,0)) | T10: =IF(OFFSET(マスタ非採用削除!G$4,統合マスタ!$A10,0)="","",OFFSET(マスタ非採用削除!G$4,統合マスタ!$A10,0)) -> 12.8 | U10: =IF(OFFSET(マスタ非採用削除!H$4,統合マスタ!$A10,0)="","",OFFSET(マスタ非採用削除!H$4,統合マスタ!$A10,0)) -> ﾂﾑﾗｼﾖｳｾｲﾘﾕｳﾄｳｴｷｽｶﾘﾕｳｲﾘﾖｳﾖｳ | ... Z10: =IF(OFFSET(マスタ非採用削除!M$4,統合マスタ!$A10,0)="","",OFFSET(マスタ非採用削除!M$4,統合マスタ!$A10,0)) -> 4
A11: =元データ!P8 -> 301 | B11: =B10+1 -> 7 | C11: =DBCS(元データ!A8) -> ０４３ ツムラ リツクンシトウ | D11: =元データ!B8 -> メディセオ | E11: =DBCS(元データ!C8) -> 粉 | F11: =DBCS(元データ!D8) -> ２．５ｇｘ１８９ | G11: =元データ!E8 -> ツムラ | H11: =元データ!F8 -> 18 | I11: =元データ!G8 -> 8505 | J11: =元データ!H8 -> 472.5 | K11: =元データ!I8 -> g | L11: =元データ!J8 -> 7576 | M11: =元データ!K8 -> 16.033862 | N11: =IF(OFFSET(マスタ非採用削除!A$4,統合マスタ!$A11,0)="","",OFFSET(マスタ非採用削除!A$4,統合マスタ!$A11,0)) -> ﾂﾑﾗ043 | O11: =IF(OFFSET(マスタ非採用削除!B$4,統合マスタ!$A11,0)="","",OFFSET(マスタ非採用削除!B$4,統合マスタ!$A11,0)) -> ﾂﾑﾗ043 | P11: =IF(OFFSET(マスタ非採用削除!C$4,統合マスタ!$A11,0)="","",OFFSET(マスタ非採用削除!C$4,統合マスタ!$A11,0)) -> ツムラ六君子湯エキス顆粒（医療用） | Q11: =IF(OFFSET(マスタ非採用削除!D$4,統合マスタ!$A11,0)="","",OFFSET(マスタ非採用削除!D$4,統合マスタ!$A11,0)) -> ﾘｯｸ | R11: =IF(OFFSET(マスタ非採用削除!E$4,統合マスタ!$A11,0)="","",OFFSET(マスタ非採用削除!E$4,統合マスタ!$A11,0)) -> 2 | S11: =IF(OFFSET(マスタ非採用削除!F$4,統合マスタ!$A11,0)="","",OFFSET(マスタ非採用削除!F$4,統合マスタ!$A11,0)) | T11: =IF(OFFSET(マスタ非採用削除!G$4,統合マスタ!$A11,0)="","",OFFSET(マスタ非採用削除!G$4,統合マスタ!$A11,0)) -> 18 | U11: =IF(OFFSET(マスタ非採用削除!H$4,統合マスタ!$A11,0)="","",OFFSET(マスタ非採用削除!H$4,統合マスタ!$A11,0)) -> ﾂﾑﾗﾘｯｸﾝｼﾄｳｴｷｽｶﾘｭｳ(ｲﾘｮｳﾖｳ) | ... Z11: =IF(OFFSET(マスタ非採用削除!M$4,統合マスタ!$A11,0)="","",OFFSET(マスタ非採用削除!M$4,統合マスタ!$A11,0)) -> 4
A12: =元データ!P9 -> 非採用 | B12: =B11+1 -> 8 | C12: =DBCS(元データ!A9) -> ０４８ ツムラ ジュウゼンタイホトウ | D12: =元データ!B9 | E12: =DBCS(元データ!C9) -> 粉 | F12: =DBCS(元データ!D9) -> ２．５ｇｘ１８９包 | G12: =元データ!E9 -> ツムラ | H12: =元データ!F9 -> 18.4 | I12: =元データ!G9 -> 8694 | J12: =元データ!H9 -> 472.5 | K12: =元データ!I9 -> g | L12: =元データ!J9 -> 7750 | M12: =元データ!K9 -> 16.402116 | N12: =IF(OFFSET(マスタ非採用削除!A$4,統合マスタ!$A12,0)="","",OFFSET(マスタ非採用削除!A$4,統合マスタ!$A12,0)) -> #VALUE! | O12: =IF(OFFSET(マスタ非採用削除!B$4,統合マスタ!$A12,0)="","",OFFSET(マスタ非採用削除!B$4,統合マスタ!$A12,0)) -> #VALUE! | P12: =IF(OFFSET(マスタ非採用削除!C$4,統合マスタ!$A12,0)="","",OFFSET(マスタ非採用削除!C$4,統合マスタ!$A12,0)) -> #VALUE! | Q12: =IF(OFFSET(マスタ非採用削除!D$4,統合マスタ!$A12,0)="","",OFFSET(マスタ非採用削除!D$4,統合マスタ!$A12,0)) -> #VALUE! | R12: =IF(OFFSET(マスタ非採用削除!E$4,統合マスタ!$A12,0)="","",OFFSET(マスタ非採用削除!E$4,統合マスタ!$A12,0)) -> #VALUE! | S12: =IF(OFFSET(マスタ非採用削除!F$4,統合マスタ!$A12,0)="","",OFFSET(マスタ非採用削除!F$4,統合マスタ!$A12,0)) -> #VALUE! | T12: =IF(OFFSET(マスタ非採用削除!G$4,統合マスタ!$A12,0)="","",OFFSET(マスタ非採用削除!G$4,統合マスタ!$A12,0)) -> #VALUE! | U12: =IF(OFFSET(マスタ非採用削除!H$4,統合マスタ!$A12,0)="","",OFFSET(マスタ非採用削除!H$4,統合マスタ!$A12,0)) -> #VALUE! | ... Z12: =IF(OFFSET(マスタ非採用削除!M$4,統合マスタ!$A12,0)="","",OFFSET(マスタ非採用削除!M$4,統合マスタ!$A12,0)) -> #VALUE! | AA12: 非採用
A13: =元データ!P10 -> 302 | B13: =B12+1 -> 9 | C13: =DBCS(元データ!A10) -> ０５４ ツムラ ヨクカンサン | D13: =元データ!B10 -> メディセオ | E13: =DBCS(元データ!C10) -> 粉 | F13: =DBCS(元データ!D10) -> ２．５ｇＸ１８９ | G13: =元データ!E10 -> ツムラ | H13: =元データ!F10 -> 16.1 | I13: =元データ!G10 -> 7607.25 | J13: =元データ!H10 -> 472.5 | K13: =元データ!I10 -> g | L13: =元データ!J10 -> 6849 | M13: =元データ!K10 -> 14.495238 | N13: =IF(OFFSET(マスタ非採用削除!A$4,統合マスタ!$A13,0)="","",OFFSET(マスタ非採用削除!A$4,統合マスタ!$A13,0)) -> ﾂﾑﾗ054 | O13: =IF(OFFSET(マスタ非採用削除!B$4,統合マスタ!$A13,0)="","",OFFSET(マスタ非採用削除!B$4,統合マスタ!$A13,0)) -> ﾂﾑﾗ054 | P13: =IF(OFFSET(マスタ非採用削除!C$4,統合マスタ!$A13,0)="","",OFFSET(マスタ非採用削除!C$4,統合マスタ!$A13,0)) -> ツムラ抑肝散エキス顆粒（医療用） | Q13: =IF(OFFSET(マスタ非採用削除!D$4,統合マスタ!$A13,0)="","",OFFSET(マスタ非採用削除!D$4,統合マスタ!$A13,0)) -> ﾖｸｶ | R13: =IF(OFFSET(マスタ非採用削除!E$4,統合マスタ!$A13,0)="","",OFFSET(マスタ非採用削除!E$4,統合マスタ!$A13,0)) -> 1 | S13: =IF(OFFSET(マスタ非採用削除!F$4,統合マスタ!$A13,0)="","",OFFSET(マスタ非採用削除!F$4,統合マスタ!$A13,0)) | T13: =IF(OFFSET(マスタ非採用削除!G$4,統合マスタ!$A13,0)="","",OFFSET(マスタ非採用削除!G$4,統合マスタ!$A13,0)) -> 16.1 | U13: =IF(OFFSET(マスタ非採用削除!H$4,統合マスタ!$A13,0)="","",OFFSET(マスタ非採用削除!H$4,統合マスタ!$A13,0)) -> ﾂﾑﾗﾖｸｶﾝｻﾝｴｷｽｶﾘｭｳ(ｲﾘｮｳﾖｳ) | ... Z13: =IF(OFFSET(マスタ非採用削除!M$4,統合マスタ!$A13,0)="","",OFFSET(マスタ非採用削除!M$4,統合マスタ!$A13,0)) -> 4
A14: =元データ!P11 -> 303 | B14: =B13+1 -> 10 | C14: =DBCS(元データ!A11) -> ０６２ ツムラ ボウフウツウシヨウサン | D14: =元データ!B11 -> メディセオ | E14: =DBCS(元データ!C11) -> 粉 | F14: =DBCS(元データ!D11) -> ２．５ｇｘ１８９ | G14: =元データ!E11 -> ツムラ | H14: =元データ!F11 -> 13.8 | I14: =元データ!G11 -> 6520.5 | J14: =元データ!H11 -> 472.5 | K14: =元データ!I11 -> g | L14: =元データ!J11 -> 5871 | M14: =元データ!K11 -> 12.425397 | N14: =IF(OFFSET(マスタ非採用削除!A$4,統合マスタ!$A14,0)="","",OFFSET(マスタ非採用削除!A$4,統合マスタ!$A14,0)) -> ﾂﾑﾗ062 | O14: =IF(OFFSET(マスタ非採用削除!B$4,統合マスタ!$A14,0)="","",OFFSET(マスタ非採用削除!B$4,統合マスタ!$A14,0)) -> ﾂﾑﾗ062 | P14: =IF(OFFSET(マスタ非採用削除!C$4,統合マスタ!$A14,0)="","",OFFSET(マスタ非採用削除!C$4,統合マスタ!$A14,0)) -> ツムラ防風通聖散エキス顆粒（医療用） | Q14: =IF(OFFSET(マスタ非採用削除!D$4,統合マスタ!$A14,0)="","",OFFSET(マスタ非採用削除!D$4,統合マスタ!$A14,0)) -> ﾎﾞｳﾌｳ | R14: =IF(OFFSET(マスタ非採用削除!E$4,統合マスタ!$A14,0)="","",OFFSET(マスタ非採用削除!E$4,統合マスタ!$A14,0)) -> 1 | S14: =IF(OFFSET(マスタ非採用削除!F$4,統合マスタ!$A14,0)="","",OFFSET(マスタ非採用削除!F$4,統合マスタ!$A14,0)) | T14: =IF(OFFSET(マスタ非採用削除!G$4,統合マスタ!$A14,0)="","",OFFSET(マスタ非採用削除!G$4,統合マスタ!$A14,0)) -> 13.8 | U14: =IF(OFFSET(マスタ非採用削除!H$4,統合マスタ!$A14,0)="","",OFFSET(マスタ非採用削除!H$4,統合マスタ!$A14,0)) -> ﾂﾑﾗﾎﾞｳﾌｳﾂｳｼｮｳｻﾝｴｷｽｶﾘｭｳ(ｲﾘｮｳﾖｳ) | ... Z14: =IF(OFFSET(マスタ非採用削除!M$4,統合マスタ!$A14,0)="","",OFFSET(マスタ非採用削除!M$4,統合マスタ!$A14,0)) -> 4
A15: =元データ!P12 -> 304 | B15: =B14+1 -> 11 | C15: =DBCS(元データ!A12) -> ０６８ ツムラ シャクヤクカンゾウトウ | D15: =元データ!B12 -> メディセオ | E15: =DBCS(元データ!C12) -> 粉 | F15: =DBCS(元データ!D12) -> ２．５ｇｘ４２ | G15: =元データ!E12 -> ツムラ | H15: =元データ!F12 -> 10.4 | I15: =元データ!G12 -> 1092 | J15: =元データ!H12 -> 105 | K15: =元データ!I12 -> g | L15: =元データ!J12 -> 992 | M15: =元データ!K12 -> 9.447619 | N15: =IF(OFFSET(マスタ非採用削除!A$4,統合マスタ!$A15,0)="","",OFFSET(マスタ非採用削除!A$4,統合マスタ!$A15,0)) -> ﾂﾑﾗ068 | O15: =IF(OFFSET(マスタ非採用削除!B$4,統合マスタ!$A15,0)="","",OFFSET(マスタ非採用削除!B$4,統合マスタ!$A15,0)) -> ﾂﾑﾗ068 | P15: =IF(OFFSET(マスタ非採用削除!C$4,統合マスタ!$A15,0)="","",OFFSET(マスタ非採用削除!C$4,統合マスタ!$A15,0)) -> ツムラ芍薬甘草湯エキス顆粒（医療用） | Q15: =IF(OFFSET(マスタ非採用削除!D$4,統合マスタ!$A15,0)="","",OFFSET(マスタ非採用削除!D$4,統合マスタ!$A15,0)) -> ｼｬｸ | R15: =IF(OFFSET(マスタ非採用削除!E$4,統合マスタ!$A15,0)="","",OFFSET(マスタ非採用削除!E$4,統合マスタ!$A15,0)) -> 1 | S15: =IF(OFFSET(マスタ非採用削除!F$4,統合マスタ!$A15,0)="","",OFFSET(マスタ非採用削除!F$4,統合マスタ!$A15,0)) | T15: =IF(OFFSET(マスタ非採用削除!G$4,統合マスタ!$A15,0)="","",OFFSET(マスタ非採用削除!G$4,統合マスタ!$A15,0)) -> 10.4 | U15: =IF(OFFSET(マスタ非採用削除!H$4,統合マスタ!$A15,0)="","",OFFSET(マスタ非採用削除!H$4,統合マスタ!$A15,0)) -> ﾂﾑﾗｼｬｸﾔｸｶﾝｿﾞｳﾄｳｴｷｽｶﾘｭｳ(ｲﾘｮｳﾖｳ) | ... Z15: =IF(OFFSET(マスタ非採用削除!M$4,統合マスタ!$A15,0)="","",OFFSET(マスタ非採用削除!M$4,統合マスタ!$A15,0)) -> 4
A16: =元データ!P13 -> 305 | B16: =B15+1 -> 12 | C16: =DBCS(元データ!A13) -> ０８３ ツムラ ヨクカンサンカチンピハンゲ | D16: =元データ!B13 -> メディセオ | E16: =DBCS(元データ!C13) -> 粉 | F16: =DBCS(元データ!D13) -> ２．５ｇｘ１８９ | G16: =元データ!E13 -> ツムラ | H16: =元データ!F13 -> 14.4 | I16: =元データ!G13 -> 6804 | J16: =元データ!H13 -> 472.5 | K16: =元データ!I13 -> g | L16: =元データ!J13 -> 6065 | M16: =元データ!K13 -> 12.835979 | N16: =IF(OFFSET(マスタ非採用削除!A$4,統合マスタ!$A16,0)="","",OFFSET(マスタ非採用削除!A$4,統合マスタ!$A16,0)) -> ﾂﾑﾗ083 | O16: =IF(OFFSET(マスタ非採用削除!B$4,統合マスタ!$A16,0)="","",OFFSET(マスタ非採用削除!B$4,統合マスタ!$A16,0)) -> ﾂﾑﾗ083 | P16: =IF(OFFSET(マスタ非採用削除!C$4,統合マスタ!$A16,0)="","",OFFSET(マスタ非採用削除!C$4,統合マスタ!$A16,0)) -> ツムラ抑肝散加陳皮半夏エキス顆粒（医療用） | Q16: =IF(OFFSET(マスタ非採用削除!D$4,統合マスタ!$A16,0)="","",OFFSET(マスタ非採用削除!D$4,統合マスタ!$A16,0)) -> ﾖｸｶﾁﾝ | R16: =IF(OFFSET(マスタ非採用削除!E$4,統合マスタ!$A16,0)="","",OFFSET(マスタ非採用削除!E$4,統合マスタ!$A16,0)) -> 1 | S16: =IF(OFFSET(マスタ非採用削除!F$4,統合マスタ!$A16,0)="","",OFFSET(マスタ非採用削除!F$4,統合マスタ!$A16,0)) | T16: =IF(OFFSET(マスタ非採用削除!G$4,統合マスタ!$A16,0)="","",OFFSET(マスタ非採用削除!G$4,統合マスタ!$A16,0)) -> 14.4 | U16: =IF(OFFSET(マスタ非採用削除!H$4,統合マスタ!$A16,0)="","",OFFSET(マスタ非採用削除!H$4,統合マスタ!$A16,0)) -> ﾂﾑﾗﾖｸｶﾝｻﾝｶﾁﾝﾋﾟﾊﾝｹﾞｴｷｽｶﾘｭｳ(ｲﾘｮｳﾖｳ) | ... Z16: =IF(OFFSET(マスタ非採用削除!M$4,統合マスタ!$A16,0)="","",OFFSET(マスタ非採用削除!M$4,統合マスタ!$A16,0)) -> 4
A17: =元データ!P14 -> 306 | B17: =B16+1 -> 13 | C17: =DBCS(元データ!A14) -> １００ ツムラ ダイケンチユウトウ | D17: =元データ!B14 -> メディセオ | E17: =DBCS(元データ!C14) -> 粉 | F17: =DBCS(元データ!D14) -> ２．５ｇＸ１８９ | G17: =元データ!E14 -> ツムラ | H17: =元データ!F14 -> 13.7 | I17: =元データ!G14 -> 6473.25 | J17: =元データ!H14 -> 472.5 | K17: =元データ!I14 -> g | L17: =元データ!J14 -> 5828 | M17: =元データ!K14 -> 12.334392 | N17: =IF(OFFSET(マスタ非採用削除!A$4,統合マスタ!$A17,0)="","",OFFSET(マスタ非採用削除!A$4,統合マスタ!$A17,0)) -> ﾂﾑﾗ100 | O17: =IF(OFFSET(マスタ非採用削除!B$4,統合マスタ!$A17,0)="","",OFFSET(マスタ非採用削除!B$4,統合マスタ!$A17,0)) -> ﾂﾑﾗ100 | P17: =IF(OFFSET(マスタ非採用削除!C$4,統合マスタ!$A17,0)="","",OFFSET(マスタ非採用削除!C$4,統合マスタ!$A17,0)) -> ツムラ大建中湯エキス顆粒（医療用） | Q17: =IF(OFFSET(マスタ非採用削除!D$4,統合マスタ!$A17,0)="","",OFFSET(マスタ非採用削除!D$4,統合マスタ!$A17,0)) -> ﾀﾞｲｹﾝﾁ | R17: =IF(OFFSET(マスタ非採用削除!E$4,統合マスタ!$A17,0)="","",OFFSET(マスタ非採用削除!E$4,統合マスタ!$A17,0)) -> 1 | S17: =IF(OFFSET(マスタ非採用削除!F$4,統合マスタ!$A17,0)="","",OFFSET(マスタ非採用削除!F$4,統合マスタ!$A17,0)) | T17: =IF(OFFSET(マスタ非採用削除!G$4,統合マスタ!$A17,0)="","",OFFSET(マスタ非採用削除!G$4,統合マスタ!$A17,0)) -> 13.7 | U17: =IF(OFFSET(マスタ非採用削除!H$4,統合マスタ!$A17,0)="","",OFFSET(マスタ非採用削除!H$4,統合マスタ!$A17,0)) -> ﾂﾑﾗﾀﾞｲｹﾝﾁｭｳﾄｳｴｷｽｶﾘｭｳ(ｲﾘｮｳﾖｳ) | ... Z17: =IF(OFFSET(マスタ非採用削除!M$4,統合マスタ!$A17,0)="","",OFFSET(マスタ非採用削除!M$4,統合マスタ!$A17,0)) -> 4
A18: =元データ!P15 -> 307 | B18: =B17+1 -> 14 | C18: =DBCS(元データ!A15) -> １０８ ツムラ ニンジンヨウエイトウ | D18: =元データ!B15 -> メディセオ | E18: =DBCS(元データ!C15) -> 粉 | F18: =DBCS(元データ!D15) -> ３ｇｘ４２包 | G18: =元データ!E15 -> ツムラ | H18: =元データ!F15 -> 20.1 | I18: =元データ!G15 -> 2532.6 | J18: =元データ!H15 -> 126 | K18: =元データ!I15 -> ｇ | L18: =元データ!J15 -> 2301 | M18: =元データ!K15 -> 18.261905 | N18: =IF(OFFSET(マスタ非採用削除!A$4,統合マスタ!$A18,0)="","",OFFSET(マスタ非採用削除!A$4,統合マスタ!$A18,0)) -> ﾂﾑﾗ108 | O18: =IF(OFFSET(マスタ非採用削除!B$4,統合マスタ!$A18,0)="","",OFFSET(マスタ非採用削除!B$4,統合マスタ!$A18,0)) -> ﾂﾑﾗ108 | P18: =IF(OFFSET(マスタ非採用削除!C$4,統合マスタ!$A18,0)="","",OFFSET(マスタ非採用削除!C$4,統合マスタ!$A18,0)) -> ツムラ人参養栄湯エキス顆粒（医療用） | Q18: =IF(OFFSET(マスタ非採用削除!D$4,統合マスタ!$A18,0)="","",OFFSET(マスタ非採用削除!D$4,統合マスタ!$A18,0)) -> ﾆﾝｼﾞﾝﾖ | R18: =IF(OFFSET(マスタ非採用削除!E$4,統合マスタ!$A18,0)="","",OFFSET(マスタ非採用削除!E$4,統合マスタ!$A18,0)) -> 2 | S18: =IF(OFFSET(マスタ非採用削除!F$4,統合マスタ!$A18,0)="","",OFFSET(マスタ非採用削除!F$4,統合マスタ!$A18,0)) | T18: =IF(OFFSET(マスタ非採用削除!G$4,統合マスタ!$A18,0)="","",OFFSET(マスタ非採用削除!G$4,統合マスタ!$A18,0)) -> 20.1 | U18: =IF(OFFSET(マスタ非採用削除!H$4,統合マスタ!$A18,0)="","",OFFSET(マスタ非採用削除!H$4,統合マスタ!$A18,0)) -> ﾂﾑﾗﾆﾝｼﾞﾝﾖｳｴｲﾄｳｴｷｽｶﾘｭｳ(ｲﾘｮｳﾖｳ) | ... Z18: =IF(OFFSET(マスタ非採用削除!M$4,統合マスタ!$A18,0)="","",OFFSET(マスタ非採用削除!M$4,統合マスタ!$A18,0)) -> 4
A19: =元データ!P16 -> 308 | B19: =B18+1 -> 15 | C19: =DBCS(元データ!A16) -> １１２ ツムラ チョレイトウゴウシモットウ | D19: =元データ!B16 | E19: =DBCS(元データ!C16) -> 粉 | F19: =DBCS(元データ!D16) -> ２．５ｇｘ４２ | G19: =元データ!E16 -> ツムラ | H19: =元データ!F16 -> 22.9 | I19: =元データ!G16 -> 2404.5 | J19: =元データ!H16 -> 105 | K19: =元データ!I16 -> g | L19: =元データ!J16 -> 2185 | M19: =元データ!K16 -> 20.809524 | N19: =IF(OFFSET(マスタ非採用削除!A$4,統合マスタ!$A19,0)="","",OFFSET(マスタ非採用削除!A$4,統合マスタ!$A19,0)) -> ﾂﾑﾗ112 | O19: =IF(OFFSET(マスタ非採用削除!B$4,統合マスタ!$A19,0)="","",OFFSET(マスタ非採用削除!B$4,統合マスタ!$A19,0)) -> ﾂﾑﾗ112 | P19: =IF(OFFSET(マスタ非採用削除!C$4,統合マスタ!$A19,0)="","",OFFSET(マスタ非採用削除!C$4,統合マスタ!$A19,0)) -> ツムラ猪苓湯合四物湯エキス顆粒（医療用） | Q19: =IF(OFFSET(マスタ非採用削除!D$4,統合マスタ!$A19,0)="","",OFFSET(マスタ非採用削除!D$4,統合マスタ!$A19,0)) | R19: =IF(OFFSET(マスタ非採用削除!E$4,統合マスタ!$A19,0)="","",OFFSET(マスタ非採用削除!E$4,統合マスタ!$A19,0)) -> 2 | S19: =IF(OFFSET(マスタ非採用削除!F$4,統合マスタ!$A19,0)="","",OFFSET(マスタ非採用削除!F$4,統合マスタ!$A19,0)) | T19: =IF(OFFSET(マスタ非採用削除!G$4,統合マスタ!$A19,0)="","",OFFSET(マスタ非採用削除!G$4,統合マスタ!$A19,0)) -> 22.9 | U19: =IF(OFFSET(マスタ非採用削除!H$4,統合マスタ!$A19,0)="","",OFFSET(マスタ非採用削除!H$4,統合マスタ!$A19,0)) -> ﾂﾑﾗﾁﾖﾚｲﾄｳｺﾞｳｼﾓﾂﾄｳｴｷｽｶﾘﾕｳｲﾘﾖｳﾖｳ | ... Z19: =IF(OFFSET(マスタ非採用削除!M$4,統合マスタ!$A19,0)="","",OFFSET(マスタ非採用削除!M$4,統合マスタ!$A19,0)) -> 4
A20: =元データ!P17 -> 43 | B20: =B19+1 -> 16 | C20: =DBCS(元データ!A17) -> ２５ｍｇアリナミン Ｆ糖衣錠 | D20: =元データ!B17 -> メディセオ | E20: =DBCS(元データ!C17) -> ＰＴＰ | F20: =DBCS(元データ!D17) -> １００Ｔ | G20: =元データ!E17 -> 武田薬品工業 | H20: =元データ!F17 -> 6.1 | I20: =元データ!G17 -> 610 | J20: =元データ!H17 -> 100 | K20: =元データ!I17 -> 錠 | L20: =元データ!J17 -> 544 | M20: =元データ!K17 -> 5.44 | N20: =IF(OFFSET(マスタ非採用削除!A$4,統合マスタ!$A20,0)="","",OFFSET(マスタ非採用削除!A$4,統合マスタ!$A20,0)) -> ｱﾘﾅ001 | O20: =IF(OFFSET(マスタ非採用削除!B$4,統合マスタ!$A20,0)="","",OFFSET(マスタ非採用削除!B$4,統合マスタ!$A20,0)) -> ｱﾘﾅ001 | P20: =IF(OFFSET(マスタ非採用削除!C$4,統合マスタ!$A20,0)="","",OFFSET(マスタ非採用削除!C$4,統合マスタ!$A20,0)) -> ２５ｍｇアリナミンＦ糖衣錠 | Q20: =IF(OFFSET(マスタ非採用削除!D$4,統合マスタ!$A20,0)="","",OFFSET(マスタ非採用削除!D$4,統合マスタ!$A20,0)) -> ｱﾘF** | R20: =IF(OFFSET(マスタ非採用削除!E$4,統合マスタ!$A20,0)="","",OFFSET(マスタ非採用削除!E$4,統合マスタ!$A20,0)) -> 1 | S20: =IF(OFFSET(マスタ非採用削除!F$4,統合マスタ!$A20,0)="","",OFFSET(マスタ非採用削除!F$4,統合マスタ!$A20,0)) | T20: =IF(OFFSET(マスタ非採用削除!G$4,統合マスタ!$A20,0)="","",OFFSET(マスタ非採用削除!G$4,統合マスタ!$A20,0)) -> 6.1 | U20: =IF(OFFSET(マスタ非採用削除!H$4,統合マスタ!$A20,0)="","",OFFSET(マスタ非採用削除!H$4,統合マスタ!$A20,0)) -> 25mgｱﾘﾅﾐﾝFﾄｳｲｼﾞｮｳ | ... Z20: =IF(OFFSET(マスタ非採用削除!M$4,統合マスタ!$A20,0)="","",OFFSET(マスタ非採用削除!M$4,統合マスタ!$A20,0)) -> 5
A21: =元データ!P18 -> 139 | B21: =B20+1 -> 17 | C21: =DBCS(元データ!A18) -> ＥＫ１ 葛根湯エキス細粒 | D21: =元データ!B18 -> メディセオ | E21: =DBCS(元データ!C18) -> 粉 | F21: =DBCS(元データ!D18) -> ２．５ｇ×２９４ | G21: =元データ!E18 -> クラシエ | H21: =元データ!F18 -> 10.2 | I21: =元データ!G18 -> 7497 | J21: =元データ!H18 -> 735 | K21: =元データ!I18 -> g | L21: =元データ!J18 -> 6679 | M21: =元データ!K18 -> 9.0870748 | N21: =IF(OFFSET(マスタ非採用削除!A$4,統合マスタ!$A21,0)="","",OFFSET(マスタ非採用削除!A$4,統合マスタ!$A21,0)) -> ｸﾗｼ001 | O21: =IF(OFFSET(マスタ非採用削除!B$4,統合マスタ!$A21,0)="","",OFFSET(マスタ非採用削除!B$4,統合マスタ!$A21,0)) -> ｸﾗｼ001 | P21: =IF(OFFSET(マスタ非採用削除!C$4,統合マスタ!$A21,0)="","",OFFSET(マスタ非採用削除!C$4,統合マスタ!$A21,0)) -> クラシエ葛根湯エキス細粒 | Q21: =IF(OFFSET(マスタ非採用削除!D$4,統合マスタ!$A21,0)="","",OFFSET(マスタ非採用削除!D$4,統合マスタ!$A21,0)) -> ｶｯｺﾝ | R21: =IF(OFFSET(マスタ非採用削除!E$4,統合マスタ!$A21,0)="","",OFFSET(マスタ非採用削除!E$4,統合マスタ!$A21,0)) -> 1 | S21: =IF(OFFSET(マスタ非採用削除!F$4,統合マスタ!$A21,0)="","",OFFSET(マスタ非採用削除!F$4,統合マスタ!$A21,0)) | T21: =IF(OFFSET(マスタ非採用削除!G$4,統合マスタ!$A21,0)="","",OFFSET(マスタ非採用削除!G$4,統合マスタ!$A21,0)) -> 10.2 | U21: =IF(OFFSET(マスタ非採用削除!H$4,統合マスタ!$A21,0)="","",OFFSET(マスタ非採用削除!H$4,統合マスタ!$A21,0)) -> ｸﾗｼｴｶｯｺﾝﾄｳｴｷｽｻｲﾘｭｳ | ... Z21: =IF(OFFSET(マスタ非採用削除!M$4,統合マスタ!$A21,0)="","",OFFSET(マスタ非採用削除!M$4,統合マスタ!$A21,0)) -> 4
A22: =元データ!P19 -> 144 | B22: =B21+1 -> 18 | C22: =DBCS(元データ!A19) -> ＥＫ１１４ 柴苓湯 | D22: =元データ!B19 -> メディセオ | E22: =DBCS(元データ!C19) -> 粉 | F22: =DBCS(元データ!D19) -> ２．７ｇ×２９４ | G22: =元データ!E19 -> クラシエ | H22: =元データ!F19 -> 46.8 | I22: =元データ!G19 -> 37149.84 | J22: =元データ!H19 -> 793.8 | K22: =元データ!I19 -> g | L22: =元データ!J19 -> 33097 | M22: =元データ!K19 -> 41.694381 | N22: =IF(OFFSET(マスタ非採用削除!A$4,統合マスタ!$A22,0)="","",OFFSET(マスタ非採用削除!A$4,統合マスタ!$A22,0)) -> ｸﾗｼ114 | O22: =IF(OFFSET(マスタ非採用削除!B$4,統合マスタ!$A22,0)="","",OFFSET(マスタ非採用削除!B$4,統合マスタ!$A22,0)) -> ｸﾗｼ114 | P22: =IF(OFFSET(マスタ非採用削除!C$4,統合マスタ!$A22,0)="","",OFFSET(マスタ非採用削除!C$4,統合マスタ!$A22,0)) -> クラシエ柴苓湯エキス細粒 | Q22: =IF(OFFSET(マスタ非採用削除!D$4,統合マスタ!$A22,0)="","",OFFSET(マスタ非採用削除!D$4,統合マスタ!$A22,0)) -> ｻｲﾚ | R22: =IF(OFFSET(マスタ非採用削除!E$4,統合マスタ!$A22,0)="","",OFFSET(マスタ非採用削除!E$4,統合マスタ!$A22,0)) -> 2 | S22: =IF(OFFSET(マスタ非採用削除!F$4,統合マスタ!$A22,0)="","",OFFSET(マスタ非採用削除!F$4,統合マスタ!$A22,0)) | T22: =IF(OFFSET(マスタ非採用削除!G$4,統合マスタ!$A22,0)="","",OFFSET(マスタ非採用削除!G$4,統合マスタ!$A22,0)) -> 46.8 | U22: =IF(OFFSET(マスタ非採用削除!H$4,統合マスタ!$A22,0)="","",OFFSET(マスタ非採用削除!H$4,統合マスタ!$A22,0)) -> ｸﾗｼｴｻｲﾚｲﾄｳｴｷｽｻｲﾘｭｳ | ... Z22: =IF(OFFSET(マスタ非採用削除!M$4,統合マスタ!$A22,0)="","",OFFSET(マスタ非採用削除!M$4,統合マスタ!$A22,0)) -> 4
A23: =元データ!P20 -> 140 | B23: =B22+1 -> 19 | C23: =DBCS(元データ!A20) -> ＥＫ１５ 黄連解毒湯エキス細粒 | D23: =元データ!B20 -> メディセオ | E23: =DBCS(元データ!C20) -> 粉 | F23: =DBCS(元データ!D20) -> ２ｇｘ４２包 | G23: =元データ!E20 -> クラシエ | H23: =元データ!F20 -> 13.3 | I23: =元データ!G20 -> 1117.2 | J23: =元データ!H20 -> 84 | K23: =元データ!I20 -> g | L23: =元データ!J20 -> 1015 | M23: =元データ!K20 -> 12.083333 | N23: =IF(OFFSET(マスタ非採用削除!A$4,統合マスタ!$A23,0)="","",OFFSET(マスタ非採用削除!A$4,統合マスタ!$A23,0)) -> ｸﾗｼ015 | O23: =IF(OFFSET(マスタ非採用削除!B$4,統合マスタ!$A23,0)="","",OFFSET(マスタ非採用削除!B$4,統合マスタ!$A23,0)) -> ｸﾗｼ015 | P23: =IF(OFFSET(マスタ非採用削除!C$4,統合マスタ!$A23,0)="","",OFFSET(マスタ非採用削除!C$4,統合マスタ!$A23,0)) -> クラシエ黄連解毒湯エキス細粒 | Q23: =IF(OFFSET(マスタ非採用削除!D$4,統合マスタ!$A23,0)="","",OFFSET(マスタ非採用削除!D$4,統合マスタ!$A23,0)) -> ｵｳ | R23: =IF(OFFSET(マスタ非採用削除!E$4,統合マスタ!$A23,0)="","",OFFSET(マスタ非採用削除!E$4,統合マスタ!$A23,0)) -> 2 | S23: =IF(OFFSET(マスタ非採用削除!F$4,統合マスタ!$A23,0)="","",OFFSET(マスタ非採用削除!F$4,統合マスタ!$A23,0)) | T23: =IF(OFFSET(マスタ非採用削除!G$4,統合マスタ!$A23,0)="","",OFFSET(マスタ非採用削除!G$4,統合マスタ!$A23,0)) -> 13.3 | U23: =IF(OFFSET(マスタ非採用削除!H$4,統合マスタ!$A23,0)="","",OFFSET(マスタ非採用削除!H$4,統合マスタ!$A23,0)) -> ｸﾗｼｴｵｳﾚﾝｹﾞﾄﾞｸﾄｳｴｷｽｻｲﾘｭｳ | ... Z23: =IF(OFFSET(マスタ非採用削除!M$4,統合マスタ!$A23,0)="","",OFFSET(マスタ非採用削除!M$4,統合マスタ!$A23,0)) -> 4
A24: =元データ!P21 -> 非採用 | B24: =B23+1 -> 20 | C24: =DBCS(元データ!A21) -> ＥＫ１９ 小青竜湯エキス細粒 | D24: =元データ!B21 -> アルフレッサ | E24: =DBCS(元データ!C21) | F24: =DBCS(元データ!D21) -> ２ｇｘ４２包 | G24: =元データ!E21 -> クラシエ | H24: =元データ!F21 -> 24.1 | I24: =元データ!G21 -> 2024.4 | J24: =元データ!H21 -> 84 | K24: =元データ!I21 -> g | L24: =元データ!J21 -> 1840 | M24: =元データ!K21 -> 21.904762 | N24: =IF(OFFSET(マスタ非採用削除!A$4,統合マスタ!$A24,0)="","",OFFSET(マスタ非採用削除!A$4,統合マスタ!$A24,0)) -> #VALUE! | O24: =IF(OFFSET(マスタ非採用削除!B$4,統合マスタ!$A24,0)="","",OFFSET(マスタ非採用削除!B$4,統合マスタ!$A24,0)) -> #VALUE! | P24: =IF(OFFSET(マスタ非採用削除!C$4,統合マスタ!$A24,0)="","",OFFSET(マスタ非採用削除!C$4,統合マスタ!$A24,0)) -> #VALUE! | Q24: =IF(OFFSET(マスタ非採用削除!D$4,統合マスタ!$A24,0)="","",OFFSET(マスタ非採用削除!D$4,統合マスタ!$A24,0)) -> #VALUE! | R24: =IF(OFFSET(マスタ非採用削除!E$4,統合マスタ!$A24,0)="","",OFFSET(マスタ非採用削除!E$4,統合マスタ!$A24,0)) -> #VALUE! | S24: =IF(OFFSET(マスタ非採用削除!F$4,統合マスタ!$A24,0)="","",OFFSET(マスタ非採用削除!F$4,統合マスタ!$A24,0)) -> #VALUE! | T24: =IF(OFFSET(マスタ非採用削除!G$4,統合マスタ!$A24,0)="","",OFFSET(マスタ非採用削除!G$4,統合マスタ!$A24,0)) -> #VALUE! | U24: =IF(OFFSET(マスタ非採用削除!H$4,統合マスタ!$A24,0)="","",OFFSET(マスタ非採用削除!H$4,統合マスタ!$A24,0)) -> #VALUE! | ... Z24: =IF(OFFSET(マスタ非採用削除!M$4,統合マスタ!$A24,0)="","",OFFSET(マスタ非採用削除!M$4,統合マスタ!$A24,0)) -> #VALUE! | AA24: 非採用
A25: =元データ!P22 -> 141 | B25: =B24+1 -> 21 | C25: =DBCS(元データ!A22) -> ＥＫ２４ 加味逍遥散料エキス細粒 | D25: =元データ!B22 -> メディセオ | E25: =DBCS(元データ!C22) -> 粉 | F25: =DBCS(元データ!D22) -> ２ｇｘ４２包 | G25: =元データ!E22 -> クラシエ | H25: =元データ!F22 -> 18.3 | I25: =元データ!G22 -> 1537.2 | J25: =元データ!H22 -> 84 | K25: =元データ!I22 -> g | L25: =元データ!J22 -> 1397 | M25: =元データ!K22 -> 16.630952 | N25: =IF(OFFSET(マスタ非採用削除!A$4,統合マスタ!$A25,0)="","",OFFSET(マスタ非採用削除!A$4,統合マスタ!$A25,0)) -> ｸﾗｼ024 | O25: =IF(OFFSET(マスタ非採用削除!B$4,統合マスタ!$A25,0)="","",OFFSET(マスタ非採用削除!B$4,統合マスタ!$A25,0)) -> ｸﾗｼ024 | P25: =IF(OFFSET(マスタ非採用削除!C$4,統合マスタ!$A25,0)="","",OFFSET(マスタ非採用削除!C$4,統合マスタ!$A25,0)) -> クラシエ加味逍遙散料エキス細粒 | Q25: =IF(OFFSET(マスタ非採用削除!D$4,統合マスタ!$A25,0)="","",OFFSET(マスタ非採用削除!D$4,統合マスタ!$A25,0)) -> ｶﾐｼｮ1 | R25: =IF(OFFSET(マスタ非採用削除!E$4,統合マスタ!$A25,0)="","",OFFSET(マスタ非採用削除!E$4,統合マスタ!$A25,0)) -> 1 | S25: =IF(OFFSET(マスタ非採用削除!F$4,統合マスタ!$A25,0)="","",OFFSET(マスタ非採用削除!F$4,統合マスタ!$A25,0)) | T25: =IF(OFFSET(マスタ非採用削除!G$4,統合マスタ!$A25,0)="","",OFFSET(マスタ非採用削除!G$4,統合マスタ!$A25,0)) -> 18.3 | U25: =IF(OFFSET(マスタ非採用削除!H$4,統合マスタ!$A25,0)="","",OFFSET(マスタ非採用削除!H$4,統合マスタ!$A25,0)) -> ｸﾗｼｴｶﾐｼｮｳﾖｳｻﾝﾘｮｳｴｷｽｻｲﾘｭｳ | ... Z25: =IF(OFFSET(マスタ非採用削除!M$4,統合マスタ!$A25,0)="","",OFFSET(マスタ非採用削除!M$4,統合マスタ!$A25,0)) -> 4
A26: =元データ!P23 -> 142 | B26: =B25+1 -> 22 | C26: =DBCS(元データ!A23) -> ＥＫ４０ 猪苓湯エキス細粒 | D26: =元データ!B23 -> メディセオ | E26: =DBCS(元データ!C23) -> 粉 | F26: =DBCS(元データ!D23) -> ２ｇｘ４２包 | G26: =元データ!E23 -> クラシエ | H26: =元データ!F23 -> 14.8 | I26: =元データ!G23 -> 1243.2 | J26: =元データ!H23 -> 84 | K26: =元データ!I23 -> g | L26: =元データ!J23 -> 1130 | M26: =元データ!K23 -> 13.452381 | N26: =IF(OFFSET(マスタ非採用削除!A$4,統合マスタ!$A26,0)="","",OFFSET(マスタ非採用削除!A$4,統合マスタ!$A26,0)) -> ｸﾗｼ040 | O26: =IF(OFFSET(マスタ非採用削除!B$4,統合マスタ!$A26,0)="","",OFFSET(マスタ非採用削除!B$4,統合マスタ!$A26,0)) -> ｸﾗｼ040 | P26: =IF(OFFSET(マスタ非採用削除!C$4,統合マスタ!$A26,0)="","",OFFSET(マスタ非採用削除!C$4,統合マスタ!$A26,0)) -> クラシエ猪苓湯エキス細粒 | Q26: =IF(OFFSET(マスタ非採用削除!D$4,統合マスタ!$A26,0)="","",OFFSET(マスタ非採用削除!D$4,統合マスタ!$A26,0)) -> ﾁｮﾚ | R26: =IF(OFFSET(マスタ非採用削除!E$4,統合マスタ!$A26,0)="","",OFFSET(マスタ非採用削除!E$4,統合マスタ!$A26,0)) -> 2 | S26: =IF(OFFSET(マスタ非採用削除!F$4,統合マスタ!$A26,0)="","",OFFSET(マスタ非採用削除!F$4,統合マスタ!$A26,0)) | T26: =IF(OFFSET(マスタ非採用削除!G$4,統合マスタ!$A26,0)="","",OFFSET(マスタ非採用削除!G$4,統合マスタ!$A26,0)) -> 14.8 | U26: =IF(OFFSET(マスタ非採用削除!H$4,統合マスタ!$A26,0)="","",OFFSET(マスタ非採用削除!H$4,統合マスタ!$A26,0)) -> ｸﾗｼｴﾁｮﾚｲﾄｳｴｷｽｻｲﾘｭｳ | ... Z26: =IF(OFFSET(マスタ非採用削除!M$4,統合マスタ!$A26,0)="","",OFFSET(マスタ非採用削除!M$4,統合マスタ!$A26,0)) -> 4
A27: =元データ!P24 -> 143 | B27: =B26+1 -> 23 | C27: =DBCS(元データ!A24) -> ＥＫ４１ 補中益気湯エキス細粒 | D27: =元データ!B24 -> メディセオ | E27: =DBCS(元データ!C24) -> 粉 | F27: =DBCS(元データ!D24) -> ２．５ｇｘ２９４ | G27: =元データ!E24 -> クラシエ | H27: =元データ!F24 -> 20.4 | I27: =元データ!G24 -> 14994 | J27: =元データ!H24 -> 735 | K27: =元データ!I24 -> g | L27: =元データ!J24 -> 13358 | M27: =元データ!K24 -> 18.17415 | N27: =IF(OFFSET(マスタ非採用削除!A$4,統合マスタ!$A27,0)="","",OFFSET(マスタ非採用削除!A$4,統合マスタ!$A27,0)) -> ｸﾗｼ041 | O27: =IF(OFFSET(マスタ非採用削除!B$4,統合マスタ!$A27,0)="","",OFFSET(マスタ非採用削除!B$4,統合マスタ!$A27,0)) -> ｸﾗｼ041 | P27: =IF(OFFSET(マスタ非採用削除!C$4,統合マスタ!$A27,0)="","",OFFSET(マスタ非採用削除!C$4,統合マスタ!$A27,0)) -> クラシエ補中益気湯エキス細粒 | Q27: =IF(OFFSET(マスタ非採用削除!D$4,統合マスタ!$A27,0)="","",OFFSET(マスタ非採用削除!D$4,統合マスタ!$A27,0)) -> ﾎﾁｭｳ | R27: =IF(OFFSET(マスタ非採用削除!E$4,統合マスタ!$A27,0)="","",OFFSET(マスタ非採用削除!E$4,統合マスタ!$A27,0)) -> 1 | S27: =IF(OFFSET(マスタ非採用削除!F$4,統合マスタ!$A27,0)="","",OFFSET(マスタ非採用削除!F$4,統合マスタ!$A27,0)) | T27: =IF(OFFSET(マスタ非採用削除!G$4,統合マスタ!$A27,0)="","",OFFSET(マスタ非採用削除!G$4,統合マスタ!$A27,0)) -> 20.4 | U27: =IF(OFFSET(マスタ非採用削除!H$4,統合マスタ!$A27,0)="","",OFFSET(マスタ非採用削除!H$4,統合マスタ!$A27,0)) -> ｸﾗｼｴﾎﾁｭｳｴｯｷﾄｳｴｷｽｻｲﾘｭｳ | ... Z27: =IF(OFFSET(マスタ非採用削除!M$4,統合マスタ!$A27,0)="","",OFFSET(マスタ非採用削除!M$4,統合マスタ!$A27,0)) -> 4
A28: =元データ!P25 -> 59 | B28: =B27+1 -> 24 | C28: =DBCS(元データ!A25) -> ＥＰＬカプセル２５０ｍｇ 販売中止 | D28: =元データ!B25 -> アルフレッサ | E28: =DBCS(元データ!C25) -> ＰＴＰ | F28: =DBCS(元データ!D25) -> ４００Ｐ | G28: =元データ!E25 -> アルフレッサファーマ | H28: =元データ!F25 -> 6.1 | I28: =元データ!G25 -> 2440 | J28: =元データ!H25 -> 400 | K28: =元データ!I25 -> cap | L28: =元データ!J25 -> 2218 | M28: =元データ!K25 -> 5.545 | N28: =IF(OFFSET(マスタ非採用削除!A$4,統合マスタ!$A28,0)="","",OFFSET(マスタ非採用削除!A$4,統合マスタ!$A28,0)) -> ｲﾋｴ001 | O28: =IF(OFFSET(マスタ非採用削除!B$4,統合マスタ!$A28,0)="","",OFFSET(マスタ非採用削除!B$4,統合マスタ!$A28,0)) -> ｲﾋｴ001 | P28: =IF(OFFSET(マスタ非採用削除!C$4,統合マスタ!$A28,0)="","",OFFSET(マスタ非採用削除!C$4,統合マスタ!$A28,0)) -> ＥＰＬカプセル２５０ｍｇ | Q28: =IF(OFFSET(マスタ非採用削除!D$4,統合マスタ!$A28,0)="","",OFFSET(マスタ非採用削除!D$4,統合マスタ!$A28,0)) -> EPL** | R28: =IF(OFFSET(マスタ非採用削除!E$4,統合マスタ!$A28,0)="","",OFFSET(マスタ非採用削除!E$4,統合マスタ!$A28,0)) -> 1 | S28: =IF(OFFSET(マスタ非採用削除!F$4,統合マスタ!$A28,0)="","",OFFSET(マスタ非採用削除!F$4,統合マスタ!$A28,0)) | T28: =IF(OFFSET(マスタ非採用削除!G$4,統合マスタ!$A28,0)="","",OFFSET(マスタ非採用削除!G$4,統合マスタ!$A28,0)) -> 6.1 | U28: =IF(OFFSET(マスタ非採用削除!H$4,統合マスタ!$A28,0)="","",OFFSET(マスタ非採用削除!H$4,統合マスタ!$A28,0)) -> EPLｶﾌﾟｾﾙ250mg | ... Z28: =IF(OFFSET(マスタ非採用削除!M$4,統合マスタ!$A28,0)="","",OFFSET(マスタ非採用削除!M$4,統合マスタ!$A28,0)) -> 5
A29: =元データ!P26 -> 76 | B29: =B28+1 -> 25 | C29: =DBCS(元データ!A26) -> ＳＰトローチ０．２５ｍｇ「明治」 | D29: =元データ!B26 -> メディセオ | E29: =DBCS(元データ!C26) -> ＰＴＰ | F29: =DBCS(元データ!D26) -> １２００Ｔ | G29: =元データ!E26 -> meijiseika | H29: =元データ!F26 -> 5.9 | I29: =元データ!G26 -> 7080 | J29: =元データ!H26 -> 1200 | K29: =元データ!I26 -> 錠 | L29: =元データ!J26 -> 6435 | M29: =元データ!K26 -> 5.3625 | N29: =IF(OFFSET(マスタ非採用削除!A$4,統合マスタ!$A29,0)="","",OFFSET(マスタ非採用削除!A$4,統合マスタ!$A29,0)) -> ｴｽﾋ001 | O29: =IF(OFFSET(マスタ非採用削除!B$4,統合マスタ!$A29,0)="","",OFFSET(マスタ非採用削除!B$4,統合マスタ!$A29,0)) -> ｴｽﾋ001 | P29: =IF(OFFSET(マスタ非採用削除!C$4,統合マスタ!$A29,0)="","",OFFSET(マスタ非採用削除!C$4,統合マスタ!$A29,0)) -> ＳＰトローチ０．２５ｍｇ「明治」 | Q29: =IF(OFFSET(マスタ非採用削除!D$4,統合マスタ!$A29,0)="","",OFFSET(マスタ非採用削除!D$4,統合マスタ!$A29,0)) -> SPﾄ | R29: =IF(OFFSET(マスタ非採用削除!E$4,統合マスタ!$A29,0)="","",OFFSET(マスタ非採用削除!E$4,統合マスタ!$A29,0)) -> 1 | S29: =IF(OFFSET(マスタ非採用削除!F$4,統合マスタ!$A29,0)="","",OFFSET(マスタ非採用削除!F$4,統合マスタ!$A29,0)) | T29: =IF(OFFSET(マスタ非採用削除!G$4,統合マスタ!$A29,0)="","",OFFSET(マスタ非採用削除!G$4,統合マスタ!$A29,0)) -> 5.9 | U29: =IF(OFFSET(マスタ非採用削除!H$4,統合マスタ!$A29,0)="","",OFFSET(マスタ非採用削除!H$4,統合マスタ!$A29,0)) -> SPﾄﾛｰﾁ0.25mg｢ﾒｲｼﾞ｣ | ... Z29: =IF(OFFSET(マスタ非採用削除!M$4,統合マスタ!$A29,0)="","",OFFSET(マスタ非採用削除!M$4,統合マスタ!$A29,0)) -> 3
A30: =元データ!P27 -> 581 | B30: =B29+1 -> 26 | C30: =DBCS(元データ!A27) -> Ｔ７２ ヨクイニンエキス錠「コタロー」 | D30: =元データ!B27 -> メディセオ | E30: =DBCS(元データ!C27) -> バラ | F30: =DBCS(元データ!D27) -> １２６Ｔｘ１０ | G30: =元データ!E27 -> 小太郎漢方 | H30: =元データ!F27 -> 6.5 | I30: =元データ!G27 -> 8190 | J30: =元データ!H27 -> 1260 | K30: =元データ!I27 -> 錠 | L30: =元データ!J27 -> 7445 | M30: =元データ!K27 -> 5.9087302 | N30: =IF(OFFSET(マスタ非採用削除!A$4,統合マスタ!$A30,0)="","",OFFSET(マスタ非採用削除!A$4,統合マスタ!$A30,0)) -> ﾖｸｲ001 | O30: =IF(OFFSET(マスタ非採用削除!B$4,統合マスタ!$A30,0)="","",OFFSET(マスタ非採用削除!B$4,統合マスタ!$A30,0)) -> ﾖｸｲ001 | P30: =IF(OFFSET(マスタ非採用削除!C$4,統合マスタ!$A30,0)="","",OFFSET(マスタ非採用削除!C$4,統合マスタ!$A30,0)) -> ヨクイニンエキス錠「コタロー」 | Q30: =IF(OFFSET(マスタ非採用削除!D$4,統合マスタ!$A30,0)="","",OFFSET(マスタ非採用削除!D$4,統合マスタ!$A30,0)) | R30: =IF(OFFSET(マスタ非採用削除!E$4,統合マスタ!$A30,0)="","",OFFSET(マスタ非採用削除!E$4,統合マスタ!$A30,0)) -> 2 | S30: =IF(OFFSET(マスタ非採用削除!F$4,統合マスタ!$A30,0)="","",OFFSET(マスタ非採用削除!F$4,統合マスタ!$A30,0)) | T30: =IF(OFFSET(マスタ非採用削除!G$4,統合マスタ!$A30,0)="","",OFFSET(マスタ非採用削除!G$4,統合マスタ!$A30,0)) -> 6.5 | U30: =IF(OFFSET(マスタ非採用削除!H$4,統合マスタ!$A30,0)="","",OFFSET(マスタ非採用削除!H$4,統合マスタ!$A30,0)) -> ﾖｸｲﾆﾝｴｷｽｼﾞﾖｳｺﾀﾛ- | ... Z30: =IF(OFFSET(マスタ非採用削除!M$4,統合マスタ!$A30,0)="","",OFFSET(マスタ非採用削除!M$4,統合マスタ!$A30,0)) -> 15
A31: =元データ!P28 -> 22 | B31: =B30+1 -> 27 | C31: =DBCS(元データ!A28) -> アーチスト錠１．２５ｍｇ | D31: =元データ!B28 -> メディセオ | E31: =DBCS(元データ!C28) -> ＰＴＰ | F31: =DBCS(元データ!D28) -> １００Ｔ | G31: =元データ!E28 -> 第一三共 | H31: =元データ!F28 -> 10.4 | I31: =元データ!G28 -> 1040 | J31: =元データ!H28 -> 100 | K31: =元データ!I28 -> 錠 | L31: =元データ!J28 -> 926 | M31: =元データ!K28 -> 9.26 | N31: =IF(OFFSET(マスタ非採用削除!A$4,統合マスタ!$A31,0)="","",OFFSET(マスタ非採用削除!A$4,統合マスタ!$A31,0)) -> ｱﾁｽ001 | O31: =IF(OFFSET(マスタ非採用削除!B$4,統合マスタ!$A31,0)="","",OFFSET(マスタ非採用削除!B$4,統合マスタ!$A31,0)) -> ｱﾁｽ001 | P31: =IF(OFFSET(マスタ非採用削除!C$4,統合マスタ!$A31,0)="","",OFFSET(マスタ非採用削除!C$4,統合マスタ!$A31,0)) -> アーチスト錠１．２５ｍｇ | Q31: =IF(OFFSET(マスタ非採用削除!D$4,統合マスタ!$A31,0)="","",OFFSET(マスタ非採用削除!D$4,統合マスタ!$A31,0)) -> ｱｰﾁ | R31: =IF(OFFSET(マスタ非採用削除!E$4,統合マスタ!$A31,0)="","",OFFSET(マスタ非採用削除!E$4,統合マスタ!$A31,0)) -> 1 | S31: =IF(OFFSET(マスタ非採用削除!F$4,統合マスタ!$A31,0)="","",OFFSET(マスタ非採用削除!F$4,統合マスタ!$A31,0)) | T31: =IF(OFFSET(マスタ非採用削除!G$4,統合マスタ!$A31,0)="","",OFFSET(マスタ非採用削除!G$4,統合マスタ!$A31,0)) -> 10.4 | U31: =IF(OFFSET(マスタ非採用削除!H$4,統合マスタ!$A31,0)="","",OFFSET(マスタ非採用削除!H$4,統合マスタ!$A31,0)) -> ｱｰﾁｽﾄｼﾞｮｳ1.25mg | ... Z31: =IF(OFFSET(マスタ非採用削除!M$4,統合マスタ!$A31,0)="","",OFFSET(マスタ非採用削除!M$4,統合マスタ!$A31,0)) -> 5
A32: =元データ!P29 -> 非採用 | B32: =B31+1 -> 28 | C32: =DBCS(元データ!A29) -> アイファガン点眼液０．１％ | D32: =元データ!B29 | E32: =DBCS(元データ!C29) | F32: =DBCS(元データ!D29) -> ５ｍｌｘ５ | G32: =元データ!E29 -> 武田薬品工業 | H32: =元データ!F29 -> 268.9 | I32: =元データ!G29 -> 6722.5 | J32: =元データ!H29 -> 25 | K32: =元データ!I29 -> ｍｌ | L32: =元データ!J29 -> 5858 | M32: =元データ!K29 -> 234.32 | N32: =IF(OFFSET(マスタ非採用削除!A$4,統合マスタ!$A32,0)="","",OFFSET(マスタ非採用削除!A$4,統合マスタ!$A32,0)) -> #VALUE! | O32: =IF(OFFSET(マスタ非採用削除!B$4,統合マスタ!$A32,0)="","",OFFSET(マスタ非採用削除!B$4,統合マスタ!$A32,0)) -> #VALUE! | P32: =IF(OFFSET(マスタ非採用削除!C$4,統合マスタ!$A32,0)="","",OFFSET(マスタ非採用削除!C$4,統合マスタ!$A32,0)) -> #VALUE! | Q32: =IF(OFFSET(マスタ非採用削除!D$4,統合マスタ!$A32,0)="","",OFFSET(マスタ非採用削除!D$4,統合マスタ!$A32,0)) -> #VALUE! | R32: =IF(OFFSET(マスタ非採用削除!E$4,統合マスタ!$A32,0)="","",OFFSET(マスタ非採用削除!E$4,統合マスタ!$A32,0)) -> #VALUE! | S32: =IF(OFFSET(マスタ非採用削除!F$4,統合マスタ!$A32,0)="","",OFFSET(マスタ非採用削除!F$4,統合マスタ!$A32,0)) -> #VALUE! | T32: =IF(OFFSET(マスタ非採用削除!G$4,統合マスタ!$A32,0)="","",OFFSET(マスタ非採用削除!G$4,統合マスタ!$A32,0)) -> #VALUE! | U32: =IF(OFFSET(マスタ非採用削除!H$4,統合マスタ!$A32,0)="","",OFFSET(マスタ非採用削除!H$4,統合マスタ!$A32,0)) -> #VALUE! | ... Z32: =IF(OFFSET(マスタ非採用削除!M$4,統合マスタ!$A32,0)="","",OFFSET(マスタ非採用削除!M$4,統合マスタ!$A32,0)) -> #VALUE! | AA32: 非採用
A33: =元データ!P30 -> 非採用 | B33: =B32+1 -> 29 | C33: =DBCS(元データ!A30) -> アウィクリ注 フレックスタッチ 総量３００単位 | D33: =元データ!B30 -> アルフレッサ | E33: =DBCS(元データ!C30) | F33: =DBCS(元データ!D30) -> ０．４３ｍｌｘ２ｋｉｔ | G33: =元データ!E30 -> ノボノルディスク | H33: =元データ!F30 -> 2081 | I33: =元データ!G30 -> 4162 | J33: =元データ!H30 -> 2 | K33: =元データ!I30 -> kit | L33: =元データ!J30 -> 3689 | M33: =元データ!K30 -> 1844.5 | N33: =IF(OFFSET(マスタ非採用削除!A$4,統合マスタ!$A33,0)="","",OFFSET(マスタ非採用削除!A$4,統合マスタ!$A33,0)) -> #VALUE! | O33: =IF(OFFSET(マスタ非採用削除!B$4,統合マスタ!$A33,0)="","",OFFSET(マスタ非採用削除!B$4,統合マスタ!$A33,0)) -> #VALUE! | P33: =IF(OFFSET(マスタ非採用削除!C$4,統合マスタ!$A33,0)="","",OFFSET(マスタ非採用削除!C$4,統合マスタ!$A33,0)) -> #VALUE! | Q33: =IF(OFFSET(マスタ非採用削除!D$4,統合マスタ!$A33,0)="","",OFFSET(マスタ非採用削除!D$4,統合マスタ!$A33,0)) -> #VALUE! | R33: =IF(OFFSET(マスタ非採用削除!E$4,統合マスタ!$A33,0)="","",OFFSET(マスタ非採用削除!E$4,統合マスタ!$A33,0)) -> #VALUE! | S33: =IF(OFFSET(マスタ非採用削除!F$4,統合マスタ!$A33,0)="","",OFFSET(マスタ非採用削除!F$4,統合マスタ!$A33,0)) -> #VALUE! | T33: =IF(OFFSET(マスタ非採用削除!G$4,統合マスタ!$A33,0)="","",OFFSET(マスタ非採用削除!G$4,統合マスタ!$A33,0)) -> #VALUE! | U33: =IF(OFFSET(マスタ非採用削除!H$4,統合マスタ!$A33,0)="","",OFFSET(マスタ非採用削除!H$4,統合マスタ!$A33,0)) -> #VALUE! | ... Z33: =IF(OFFSET(マスタ非採用削除!M$4,統合マスタ!$A33,0)="","",OFFSET(マスタ非採用削除!M$4,統合マスタ!$A33,0)) -> #VALUE! | AA33: 非採用
A34: =元データ!P31 -> 非採用 | B34: =B33+1 -> 30 | C34: =DBCS(元データ!A31) -> アキネトン細粒１％ | D34: =元データ!B31 | E34: =DBCS(元データ!C31) -> 粉 | F34: =DBCS(元データ!D31) -> １００ｇ | G34: =元データ!E31 -> 住友ファーマ | H34: =元データ!F31 -> 21.4 | I34: =元データ!G31 -> 2140 | J34: =元データ!H31 -> 100 | K34: =元データ!I31 -> ｇ | L34: =元データ!J31 -> 1907 | M34: =元データ!K31 -> 19.07 | N34: =IF(OFFSET(マスタ非採用削除!A$4,統合マスタ!$A34,0)="","",OFFSET(マスタ非採用削除!A$4,統合マスタ!$A34,0)) -> #VALUE! | O34: =IF(OFFSET(マスタ非採用削除!B$4,統合マスタ!$A34,0)="","",OFFSET(マスタ非採用削除!B$4,統合マスタ!$A34,0)) -> #VALUE! | P34: =IF(OFFSET(マスタ非採用削除!C$4,統合マスタ!$A34,0)="","",OFFSET(マスタ非採用削除!C$4,統合マスタ!$A34,0)) -> #VALUE! | Q34: =IF(OFFSET(マスタ非採用削除!D$4,統合マスタ!$A34,0)="","",OFFSET(マスタ非採用削除!D$4,統合マスタ!$A34,0)) -> #VALUE! | R34: =IF(OFFSET(マスタ非採用削除!E$4,統合マスタ!$A34,0)="","",OFFSET(マスタ非採用削除!E$4,統合マスタ!$A34,0)) -> #VALUE! | S34: =IF(OFFSET(マスタ非採用削除!F$4,統合マスタ!$A34,0)="","",OFFSET(マスタ非採用削除!F$4,統合マスタ!$A34,0)) -> #VALUE! | T34: =IF(OFFSET(マスタ非採用削除!G$4,統合マスタ!$A34,0)="","",OFFSET(マスタ非採用削除!G$4,統合マスタ!$A34,0)) -> #VALUE! | U34: =IF(OFFSET(マスタ非採用削除!H$4,統合マスタ!$A34,0)="","",OFFSET(マスタ非採用削除!H$4,統合マスタ!$A34,0)) -> #VALUE! | ... Z34: =IF(OFFSET(マスタ非採用削除!M$4,統合マスタ!$A34,0)="","",OFFSET(マスタ非採用削除!M$4,統合マスタ!$A34,0)) -> #VALUE! | AA34: 非採用
A35: =元データ!P32 -> 2 | B35: =B34+1 -> 31 | C35: =DBCS(元データ!A32) -> アキネトン注射液５ｍｇ | D35: =元データ!B32 | E35: =DBCS(元データ!C32) | F35: =DBCS(元データ!D32) -> １ｍＬ×５０Ａ | G35: =元データ!E32 -> 住友ファーマ | H35: =元データ!F32 -> 61 | I35: =元データ!G32 -> 3050 | J35: =元データ!H32 -> 50 | K35: =元データ!I32 -> A | L35: =元データ!J32 -> 2718 | M35: =元データ!K32 -> 54.36 | N35: =IF(OFFSET(マスタ非採用削除!A$4,統合マスタ!$A35,0)="","",OFFSET(マスタ非採用削除!A$4,統合マスタ!$A35,0)) -> ｱｷﾈ002 | O35: =IF(OFFSET(マスタ非採用削除!B$4,統合マスタ!$A35,0)="","",OFFSET(マスタ非採用削除!B$4,統合マスタ!$A35,0)) -> ｱｷﾈ002 | P35: =IF(OFFSET(マスタ非採用削除!C$4,統合マスタ!$A35,0)="","",OFFSET(マスタ非採用削除!C$4,統合マスタ!$A35,0)) -> アキネトン注射液５ｍｇ | Q35: =IF(OFFSET(マスタ非採用削除!D$4,統合マスタ!$A35,0)="","",OFFSET(マスタ非採用削除!D$4,統合マスタ!$A35,0)) -> ｱｷﾈﾄﾝﾁ | R35: =IF(OFFSET(マスタ非採用削除!E$4,統合マスタ!$A35,0)="","",OFFSET(マスタ非採用削除!E$4,統合マスタ!$A35,0)) -> 1 | S35: =IF(OFFSET(マスタ非採用削除!F$4,統合マスタ!$A35,0)="","",OFFSET(マスタ非採用削除!F$4,統合マスタ!$A35,0)) | T35: =IF(OFFSET(マスタ非採用削除!G$4,統合マスタ!$A35,0)="","",OFFSET(マスタ非採用削除!G$4,統合マスタ!$A35,0)) -> 61 | U35: =IF(OFFSET(マスタ非採用削除!H$4,統合マスタ!$A35,0)="","",OFFSET(マスタ非採用削除!H$4,統合マスタ!$A35,0)) -> ｱｷﾈﾄﾝﾁｭｳｼｬｴｷ5mg | ... Z35: =IF(OFFSET(マスタ非採用削除!M$4,統合マスタ!$A35,0)="","",OFFSET(マスタ非採用削除!M$4,統合マスタ!$A35,0)) -> 9
A36: =元データ!P33 -> 3 | B36: =B35+1 -> 32 | C36: =DBCS(元データ!A33) -> アクアチムクリーム１％ | D36: =元データ!B33 -> スズケン | E36: =DBCS(元データ!C33) | F36: =DBCS(元データ!D33) -> １０ｇＸ１０ | G36: =元データ!E33 -> 大塚製薬 | H36: =元データ!F33 -> 20.7 | I36: =元データ!G33 -> 2070 | J36: =元データ!H33 -> 100 | K36: =元データ!I33 -> ｇ | L36: =元データ!J33 -> 1841 | M36: =元データ!K33 -> 18.41 | N36: =IF(OFFSET(マスタ非採用削除!A$4,統合マスタ!$A36,0)="","",OFFSET(マスタ非採用削除!A$4,統合マスタ!$A36,0)) -> ｱｸｱ001 | O36: =IF(OFFSET(マスタ非採用削除!B$4,統合マスタ!$A36,0)="","",OFFSET(マスタ非採用削除!B$4,統合マスタ!$A36,0)) -> ｱｸｱ001 | P36: =IF(OFFSET(マスタ非採用削除!C$4,統合マスタ!$A36,0)="","",OFFSET(マスタ非採用削除!C$4,統合マスタ!$A36,0)) -> アクアチムクリーム１％ | Q36: =IF(OFFSET(マスタ非採用削除!D$4,統合マスタ!$A36,0)="","",OFFSET(マスタ非採用削除!D$4,統合マスタ!$A36,0)) -> ｱｸｱﾁﾑ | R36: =IF(OFFSET(マスタ非採用削除!E$4,統合マスタ!$A36,0)="","",OFFSET(マスタ非採用削除!E$4,統合マスタ!$A36,0)) -> 1 | S36: =IF(OFFSET(マスタ非採用削除!F$4,統合マスタ!$A36,0)="","",OFFSET(マスタ非採用削除!F$4,統合マスタ!$A36,0)) | T36: =IF(OFFSET(マスタ非採用削除!G$4,統合マスタ!$A36,0)="","",OFFSET(マスタ非採用削除!G$4,統合マスタ!$A36,0)) -> 20.7 | U36: =IF(OFFSET(マスタ非採用削除!H$4,統合マスタ!$A36,0)="","",OFFSET(マスタ非採用削除!H$4,統合マスタ!$A36,0)) -> ｱｸｱﾁﾑｸﾘｰﾑ1% | ... Z36: =IF(OFFSET(マスタ非採用削除!M$4,統合マスタ!$A36,0)="","",OFFSET(マスタ非採用削除!M$4,統合マスタ!$A36,0)) -> 3
A37: =元データ!P34 -> 4 | B37: =B36+1 -> 33 | C37: =DBCS(元データ!A34) -> アクチット輸液 | D37: =元データ!B34 -> メディセオ | E37: =DBCS(元データ!C34) | F37: =DBCS(元データ!D34) -> ５００ｍｌｘ２０袋 | G37: =元データ!E34 -> 扶桑薬品 | H37: =元データ!F34 -> 341 | I37: =元データ!G34 -> 6820 | J37: =元データ!H34 -> 20 | K37: =元データ!I34 -> 袋 | L37: =元データ!J34 -> 6075 | M37: =元データ!K34 -> 303.75 | N37: =IF(OFFSET(マスタ非採用削除!A$4,統合マスタ!$A37,0)="","",OFFSET(マスタ非採用削除!A$4,統合マスタ!$A37,0)) -> ｱｸﾁ002 | O37: =IF(OFFSET(マスタ非採用削除!B$4,統合マスタ!$A37,0)="","",OFFSET(マスタ非採用削除!B$4,統合マスタ!$A37,0)) -> ｱｸﾁ002 | P37: =IF(OFFSET(マスタ非採用削除!C$4,統合マスタ!$A37,0)="","",OFFSET(マスタ非採用削除!C$4,統合マスタ!$A37,0)) -> アクチット輸液 | Q37: =IF(OFFSET(マスタ非採用削除!D$4,統合マスタ!$A37,0)="","",OFFSET(マスタ非採用削除!D$4,統合マスタ!$A37,0)) | R37: =IF(OFFSET(マスタ非採用削除!E$4,統合マスタ!$A37,0)="","",OFFSET(マスタ非採用削除!E$4,統合マスタ!$A37,0)) -> 1 | S37: =IF(OFFSET(マスタ非採用削除!F$4,統合マスタ!$A37,0)="","",OFFSET(マスタ非採用削除!F$4,統合マスタ!$A37,0)) | T37: =IF(OFFSET(マスタ非採用削除!G$4,統合マスタ!$A37,0)="","",OFFSET(マスタ非採用削除!G$4,統合マスタ!$A37,0)) -> 341 | U37: =IF(OFFSET(マスタ非採用削除!H$4,統合マスタ!$A37,0)="","",OFFSET(マスタ非採用削除!H$4,統合マスタ!$A37,0)) -> ｱｸﾁﾂﾄﾕｴｷ | ... Z37: =IF(OFFSET(マスタ非採用削除!M$4,統合マスタ!$A37,0)="","",OFFSET(マスタ非採用削除!M$4,統合マスタ!$A37,0)) -> 10
A38: =元データ!P35 -> 5 | B38: =B37+1 -> 34 | C38: =DBCS(元データ!A35) -> アクトシン軟膏３％ | D38: =元データ!B35 -> アルフレッサ | E38: =DBCS(元データ!C35) | F38: =DBCS(元データ!D35) -> ３０ｇ | G38: =元データ!E35 -> マルホ | H38: =元データ!F35 -> 50 | I38: =元データ!G35 -> 1500 | J38: =元データ!H35 -> 30 | K38: =元データ!I35 -> g | L38: =元データ!J35 -> 1251 | M38: =元データ!K35 -> 41.7 | N38: =IF(OFFSET(マスタ非採用削除!A$4,統合マスタ!$A38,0)="","",OFFSET(マスタ非採用削除!A$4,統合マスタ!$A38,0)) -> ｱｸﾄ001 | O38: =IF(OFFSET(マスタ非採用削除!B$4,統合マスタ!$A38,0)="","",OFFSET(マスタ非採用削除!B$4,統合マスタ!$A38,0)) -> ｱｸﾄ001 | P38: =IF(OFFSET(マスタ非採用削除!C$4,統合マスタ!$A38,0)="","",OFFSET(マスタ非採用削除!C$4,統合マスタ!$A38,0)) -> アクトシン軟膏３％ | Q38: =IF(OFFSET(マスタ非採用削除!D$4,統合マスタ!$A38,0)="","",OFFSET(マスタ非採用削除!D$4,統合マスタ!$A38,0)) -> ｱｸﾄｼﾝ | R38: =IF(OFFSET(マスタ非採用削除!E$4,統合マスタ!$A38,0)="","",OFFSET(マスタ非採用削除!E$4,統合マスタ!$A38,0)) -> 1 | S38: =IF(OFFSET(マスタ非採用削除!F$4,統合マスタ!$A38,0)="","",OFFSET(マスタ非採用削除!F$4,統合マスタ!$A38,0)) | T38: =IF(OFFSET(マスタ非採用削除!G$4,統合マスタ!$A38,0)="","",OFFSET(マスタ非採用削除!G$4,統合マスタ!$A38,0)) -> 50 | U38: =IF(OFFSET(マスタ非採用削除!H$4,統合マスタ!$A38,0)="","",OFFSET(マスタ非採用削除!H$4,統合マスタ!$A38,0)) -> ｱｸﾄｼﾝﾅﾝｺｳ3% | ... Z38: =IF(OFFSET(マスタ非採用削除!M$4,統合マスタ!$A38,0)="","",OFFSET(マスタ非採用削除!M$4,統合マスタ!$A38,0)) -> 15
A39: =元データ!P36 -> 6 | B39: =B38+1 -> 35 | C39: =DBCS(元データ!A36) -> アザルフィジンＥＮ錠５００ｍｇ | D39: =元データ!B36 -> KSK | E39: =DBCS(元データ!C36) -> ＰＴＰ | F39: =DBCS(元データ!D36) -> １００Ｔ | G39: =元データ!E36 -> ファイザー | H39: =元データ!F36 -> 25.9 | I39: =元データ!G36 -> 2590 | J39: =元データ!H36 -> 100 | K39: =元データ!I36 -> 錠 | L39: =元データ!J36 -> 2308 | M39: =元データ!K36 -> 23.08 | N39: =IF(OFFSET(マスタ非採用削除!A$4,統合マスタ!$A39,0)="","",OFFSET(マスタ非採用削除!A$4,統合マスタ!$A39,0)) -> ｱｻﾙ001 | O39: =IF(OFFSET(マスタ非採用削除!B$4,統合マスタ!$A39,0)="","",OFFSET(マスタ非採用削除!B$4,統合マスタ!$A39,0)) -> ｱｻﾙ001 | P39: =IF(OFFSET(マスタ非採用削除!C$4,統合マスタ!$A39,0)="","",OFFSET(マスタ非採用削除!C$4,統合マスタ!$A39,0)) -> アザルフィジンＥＮ錠５００ｍｇ | Q39: =IF(OFFSET(マスタ非採用削除!D$4,統合マスタ!$A39,0)="","",OFFSET(マスタ非採用削除!D$4,統合マスタ!$A39,0)) -> ｱｻﾞﾙ1 | R39: =IF(OFFSET(マスタ非採用削除!E$4,統合マスタ!$A39,0)="","",OFFSET(マスタ非採用削除!E$4,統合マスタ!$A39,0)) -> 2 | S39: =IF(OFFSET(マスタ非採用削除!F$4,統合マスタ!$A39,0)="","",OFFSET(マスタ非採用削除!F$4,統合マスタ!$A39,0)) | T39: =IF(OFFSET(マスタ非採用削除!G$4,統合マスタ!$A39,0)="","",OFFSET(マスタ非採用削除!G$4,統合マスタ!$A39,0)) -> 25.9 | U39: =IF(OFFSET(マスタ非採用削除!H$4,統合マスタ!$A39,0)="","",OFFSET(マスタ非採用削除!H$4,統合マスタ!$A39,0)) -> ｱｻﾞﾙﾌｨｼﾞﾝENｼﾞｮｳ500mg | ... Z39: =IF(OFFSET(マスタ非採用削除!M$4,統合マスタ!$A39,0)="","",OFFSET(マスタ非採用削除!M$4,統合マスタ!$A39,0)) -> 3
A40: =元データ!P37 -> 7 | B40: =B39+1 -> 36 | C40: =DBCS(元データ!A37) -> アシクロビル点滴静注用２５０ｍｇ「サワイ」 | D40: =元データ!B37 | E40: =DBCS(元データ!C37) | F40: =DBCS(元データ!D37) -> １０Ｖ | G40: =元データ!E37 -> 沢井製薬 | H40: =元データ!F37 -> 368 | I40: =元データ!G37 -> 3680 | J40: =元データ!H37 -> 10 | K40: =元データ!I37 -> V | L40: =元データ!J37 -> 3238 | M40: =元データ!K37 -> 323.8 | N40: =IF(OFFSET(マスタ非採用削除!A$4,統合マスタ!$A40,0)="","",OFFSET(マスタ非採用削除!A$4,統合マスタ!$A40,0)) -> ｱｼｸ001 | O40: =IF(OFFSET(マスタ非採用削除!B$4,統合マスタ!$A40,0)="","",OFFSET(マスタ非採用削除!B$4,統合マスタ!$A40,0)) -> ｱｼｸ001 | P40: =IF(OFFSET(マスタ非採用削除!C$4,統合マスタ!$A40,0)="","",OFFSET(マスタ非採用削除!C$4,統合マスタ!$A40,0)) -> アシクロビル点滴静注用２５０ｍｇ「サワイ」 | Q40: =IF(OFFSET(マスタ非採用削除!D$4,統合マスタ!$A40,0)="","",OFFSET(マスタ非採用削除!D$4,統合マスタ!$A40,0)) -> ｱｼｸﾛ | R40: =IF(OFFSET(マスタ非採用削除!E$4,統合マスタ!$A40,0)="","",OFFSET(マスタ非採用削除!E$4,統合マスタ!$A40,0)) -> 2 | S40: =IF(OFFSET(マスタ非採用削除!F$4,統合マスタ!$A40,0)="","",OFFSET(マスタ非採用削除!F$4,統合マスタ!$A40,0)) | T40: =IF(OFFSET(マスタ非採用削除!G$4,統合マスタ!$A40,0)="","",OFFSET(マスタ非採用削除!G$4,統合マスタ!$A40,0)) -> 368 | U40: =IF(OFFSET(マスタ非採用削除!H$4,統合マスタ!$A40,0)="","",OFFSET(マスタ非採用削除!H$4,統合マスタ!$A40,0)) -> ｱｼｸﾛﾋﾞﾙﾃﾝﾃｷｼﾞｮｳﾁｭｳﾖｳ250mg｢ｻﾜｲ｣ | ... Z40: =IF(OFFSET(マスタ非採用削除!M$4,統合マスタ!$A40,0)="","",OFFSET(マスタ非採用削除!M$4,統合マスタ!$A40,0)) -> 9
A41: =元データ!P38 -> 8 | B41: =B40+1 -> 37 | C41: =DBCS(元データ!A38) -> アジスロマイシン錠２５０ｍｇ「トーワ」 | D41: =元データ!B38 | E41: =DBCS(元データ!C38) -> ＰＴＰ | F41: =DBCS(元データ!D38) -> ６０Ｔ | G41: =元データ!E38 -> 東和薬品 | H41: =元データ!F38 -> 60.7 | I41: =元データ!G38 -> 3642 | J41: =元データ!H38 -> 60 | K41: =元データ!I38 -> 錠 | L41: =元データ!J38 -> 2952 | M41: =元データ!K38 -> 49.2 | N41: =IF(OFFSET(マスタ非採用削除!A$4,統合マスタ!$A41,0)="","",OFFSET(マスタ非採用削除!A$4,統合マスタ!$A41,0)) -> ｱｼｽ001 | O41: =IF(OFFSET(マスタ非採用削除!B$4,統合マスタ!$A41,0)="","",OFFSET(マスタ非採用削除!B$4,統合マスタ!$A41,0)) -> ｱｼｽ001 | P41: =IF(OFFSET(マスタ非採用削除!C$4,統合マスタ!$A41,0)="","",OFFSET(マスタ非採用削除!C$4,統合マスタ!$A41,0)) -> アジスロマイシン錠２５０ｍｇ「トーワ」 | Q41: =IF(OFFSET(マスタ非採用削除!D$4,統合マスタ!$A41,0)="","",OFFSET(マスタ非採用削除!D$4,統合マスタ!$A41,0)) -> ｱｼﾞｽ | R41: =IF(OFFSET(マスタ非採用削除!E$4,統合マスタ!$A41,0)="","",OFFSET(マスタ非採用削除!E$4,統合マスタ!$A41,0)) -> 1 | S41: =IF(OFFSET(マスタ非採用削除!F$4,統合マスタ!$A41,0)="","",OFFSET(マスタ非採用削除!F$4,統合マスタ!$A41,0)) | T41: =IF(OFFSET(マスタ非採用削除!G$4,統合マスタ!$A41,0)="","",OFFSET(マスタ非採用削除!G$4,統合マスタ!$A41,0)) -> 60.7 | U41: =IF(OFFSET(マスタ非採用削除!H$4,統合マスタ!$A41,0)="","",OFFSET(マスタ非採用削除!H$4,統合マスタ!$A41,0)) -> ｱｼﾞｽﾛﾏｲｼﾝｼﾞｮｳ250mg｢ﾄｰﾜ｣ | ... Z41: =IF(OFFSET(マスタ非採用削除!M$4,統合マスタ!$A41,0)="","",OFFSET(マスタ非採用削除!M$4,統合マスタ!$A41,0)) -> 1
A42: =元データ!P39 -> 9 | B42: =B41+1 -> 38 | C42: =DBCS(元データ!A39) -> アジルサルタンＯＤ錠２０ｍｇ「サワイ」 | D42: =元データ!B39 -> アルフレッサ | E42: =DBCS(元データ!C39) -> ＰＴＰ | F42: =DBCS(元データ!D39) -> １００Ｔ | G42: =元データ!E39 -> 沢井製薬 | H42: =元データ!F39 -> 27.4 | I42: =元データ!G39 -> 2740 | J42: =元データ!H39 -> 100 | K42: =元データ!I39 -> 錠 | L42: =元データ!J39 -> 2082 | M42: =元データ!K39 -> 20.82 | N42: =IF(OFFSET(マスタ非採用削除!A$4,統合マスタ!$A42,0)="","",OFFSET(マスタ非採用削除!A$4,統合マスタ!$A42,0)) -> ｱｼﾙ003 | O42: =IF(OFFSET(マスタ非採用削除!B$4,統合マスタ!$A42,0)="","",OFFSET(マスタ非採用削除!B$4,統合マスタ!$A42,0)) -> ｱｼﾙ003 | P42: =IF(OFFSET(マスタ非採用削除!C$4,統合マスタ!$A42,0)="","",OFFSET(マスタ非採用削除!C$4,統合マスタ!$A42,0)) -> アジルサルタンＯＤ錠２０ｍｇ「サワイ」 | Q42: =IF(OFFSET(マスタ非採用削除!D$4,統合マスタ!$A42,0)="","",OFFSET(マスタ非採用削除!D$4,統合マスタ!$A42,0)) | R42: =IF(OFFSET(マスタ非採用削除!E$4,統合マスタ!$A42,0)="","",OFFSET(マスタ非採用削除!E$4,統合マスタ!$A42,0)) -> 1 | S42: =IF(OFFSET(マスタ非採用削除!F$4,統合マスタ!$A42,0)="","",OFFSET(マスタ非採用削除!F$4,統合マスタ!$A42,0)) | T42: =IF(OFFSET(マスタ非採用削除!G$4,統合マスタ!$A42,0)="","",OFFSET(マスタ非採用削除!G$4,統合マスタ!$A42,0)) -> 27.4 | U42: =IF(OFFSET(マスタ非採用削除!H$4,統合マスタ!$A42,0)="","",OFFSET(マスタ非採用削除!H$4,統合マスタ!$A42,0)) -> ｱｼﾞﾙｻﾙﾀﾝODｼﾞﾖｳ20MGｻﾜｲ | ... Z42: =IF(OFFSET(マスタ非採用削除!M$4,統合マスタ!$A42,0)="","",OFFSET(マスタ非採用削除!M$4,統合マスタ!$A42,0)) -> 5
...

Sheet 臨時
B2: {=RIGHT(CELL("filename",A1),LEN(CELL("filename",A1))-FIND("]",CELL("filename",A1)))} -> 臨時
B4: No | C4: 薬品名 | D4: 毒劇区分 | E4: 棚 | F4: 包装形態 | G4: 容量 | H4: 棚場所
B5: 1 | C5: {=_xlfn._xlws.SORT(_xlfn.CHOOSECOLS(_xlfn._xlws.FILTER(IFERROR(統合マスタ!B5:Z1491,""),IFERROR(統合マスタ!R5:R1491=2,FALSE)),2,23,25,4,5),2,1)} -> ００７ ツムラ ハチミジオウガン | D5: 0 | E5: 4 | F5: 粉 | G5: ２．５ｇｘ１８９ | H5: =IF(E5="","",OFFSET(分類!$B$29,臨時!E5,0)) -> 漢方薬
B6: =B5+1 -> 2 | C6: ００７ ツムラ ハチミジオウガン | D6: 0 | E6: 4 | F6: 粉 | G6: ２．５ｇｘ４２ | H6: =IF(E6="","",OFFSET(分類!$B$29,臨時!E6,0)) -> 漢方薬
B7: =B6+1 -> 3 | C7: ０１２ ツムラ サイコカリュウコツボレイトウ | D7: 0 | E7: 4 | F7: 粉 | G7: ２．５ｇｘ１８９ | H7: =IF(E7="","",OFFSET(分類!$B$29,臨時!E7,0)) -> 漢方薬
B8: =B7+1 -> 4 | C8: ０１６ ツムラ ハンゲコウボクトウ | D8: 0 | E8: 4 | F8: 粉 | G8: ２．５ｇｘ１８９ | H8: =IF(E8="","",OFFSET(分類!$B$29,臨時!E8,0)) -> 漢方薬
B9: =B8+1 -> 5 | C9: ０１９ ツムラ ショウセイリュウトウ | D9: 0 | E9: 4 | F9: 粉 | G9: ３ｇＸ４２ | H9: =IF(E9="","",OFFSET(分類!$B$29,臨時!E9,0)) -> 漢方薬
B10: =B9+1 -> 6 | C10: ０４３ ツムラ リツクンシトウ | D10: 0 | E10: 4 | F10: 粉 | G10: ２．５ｇｘ１８９ | H10: =IF(E10="","",OFFSET(分類!$B$29,臨時!E10,0)) -> 漢方薬
B11: =B10+1 -> 7 | C11: １０８ ツムラ ニンジンヨウエイトウ | D11: 0 | E11: 4 | F11: 粉 | G11: ３ｇｘ４２包 | H11: =IF(E11="","",OFFSET(分類!$B$29,臨時!E11,0)) -> 漢方薬
B12: =B11+1 -> 8 | C12: １１２ ツムラ チョレイトウゴウシモットウ | D12: 0 | E12: 4 | F12: 粉 | G12: ２．５ｇｘ４２ | H12: =IF(E12="","",OFFSET(分類!$B$29,臨時!E12,0)) -> 漢方薬
B13: =B12+1 -> 9 | C13: ＥＫ１１４ 柴苓湯 | D13: 0 | E13: 4 | F13: 粉 | G13: ２．７ｇ×２９４ | H13: =IF(E13="","",OFFSET(分類!$B$29,臨時!E13,0)) -> 漢方薬
B14: =B13+1 -> 10 | C14: ＥＫ１５ 黄連解毒湯エキス細粒 | D14: 0 | E14: 4 | F14: 粉 | G14: ２ｇｘ４２包 | H14: =IF(E14="","",OFFSET(分類!$B$29,臨時!E14,0)) -> 漢方薬
B15: =B14+1 -> 11 | C15: ＥＫ４０ 猪苓湯エキス細粒 | D15: 0 | E15: 4 | F15: 粉 | G15: ２ｇｘ４２包 | H15: =IF(E15="","",OFFSET(分類!$B$29,臨時!E15,0)) -> 漢方薬
B16: =B15+1 -> 12 | C16: Ｔ７２ ヨクイニンエキス錠「コタロー」 | D16: 0 | E16: 15 | F16: バラ | G16: １２６Ｔｘ１０ | H16: =IF(E16="","",OFFSET(分類!$B$29,臨時!E16,0)) -> 不良在庫
B17: =B16+1 -> 13 | C17: アザルフィジンＥＮ錠５００ｍｇ | D17: 0 | E17: 3 | F17: ＰＴＰ | G17: １００Ｔ | H17: =IF(E17="","",OFFSET(分類!$B$29,臨時!E17,0)) -> 外用.臨時.散薬ヒート
B18: =B17+1 -> 14 | C18: アシクロビル点滴静注用２５０ｍｇ「サワイ」 | D18: 0 | E18: 9 | G18: １０Ｖ | H18: =IF(E18="","",OFFSET(分類!$B$29,臨時!E18,0)) -> 注射
B19: =B18+1 -> 15 | C19: アゾセミド錠３０ｍｇ「ＤＳＥＰ」 | D19: 0 | E19: 3 | F19: ＰＴＰ | G19: １００Ｔ | H19: =IF(E19="","",OFFSET(分類!$B$29,臨時!E19,0)) -> 外用.臨時.散薬ヒート
B20: =B19+1 -> 16 | C20: アドエア５００ディスカス ６０吸入用 | D20: 0 | E20: 3 | G20: ６０ブリスターｘ１ | H20: =IF(E20="","",OFFSET(分類!$B$29,臨時!E20,0)) -> 外用.臨時.散薬ヒート
B21: =B20+1 -> 17 | C21: アミノレバン点滴静注 | D21: 0 | E21: 15 | G21: ５００ｍｌｘ２０ | H21: =IF(E21="","",OFFSET(分類!$B$29,臨時!E21,0)) -> 不良在庫
B22: =B21+1 -> 18 | C22: イノソリッド配合経腸用半固形剤 | D22: 0 | E22: 7 | G22: ３００ｇｘ１８バッグ | H22: =IF(E22="","",OFFSET(分類!$B$29,臨時!E22,0)) -> 軟膏
B23: =B22+1 -> 19 | C23: イントラリポス輸液２０％ ソフトバッグ １００ｍｌ | D23: 0 | E23: 8 | G23: １００ｍｌｘ１０ | H23: =IF(E23="","",OFFSET(分類!$B$29,臨時!E23,0)) -> 抗生剤.小輸液
B24: =B23+1 -> 20 | C24: エイゾプト懸濁性点眼液１％ | D24: 0 | E24: 15 | G24: ５ｍｌｘ１０ | H24: =IF(E24="","",OFFSET(分類!$B$29,臨時!E24,0)) -> 不良在庫
B25: =B24+1 -> 21 | C25: エゼチミブＯＤ錠１０ｍｇ「トーワ」 | D25: 0 | E25: 3 | F25: ＰＴＰ | G25: １００Ｔ | H25: =IF(E25="","",OFFSET(分類!$B$29,臨時!E25,0)) -> 外用.臨時.散薬ヒート
B26: =B25+1 -> 22 | C26: エフィエント錠２．５ｍｇ | D26: 0 | E26: 15 | F26: ＰＴＰ | G26: １００Ｔ | H26: =IF(E26="","",OFFSET(分類!$B$29,臨時!E26,0)) -> 不良在庫
B27: =B26+1 -> 23 | C27: エフィナコナゾール爪外用液１０％「サワイ」 ３．５６ｇ | D27: 0 | E27: 3 | G27: ４．１ｍｌｘ５ | H27: =IF(E27="","",OFFSET(分類!$B$29,臨時!E27,0)) -> 外用.臨時.散薬ヒート
B28: =B27+1 -> 24 | C28: エリキュース錠２．５ｍｇ | D28: 0 | E28: 3 | F28: ＰＴＰ | G28: １００Ｔ | H28: =IF(E28="","",OFFSET(分類!$B$29,臨時!E28,0)) -> 外用.臨時.散薬ヒート
B29: =B28+1 -> 25 | C29: エリスロシン錠２００ｍｇ | D29: 0 | E29: 15 | F29: ＰＴＰ | G29: １００Ｔ | H29: =IF(E29="","",OFFSET(分類!$B$29,臨時!E29,0)) -> 不良在庫
B30: =B29+1 -> 26 | C30: エンレスト錠１００ｍｇ | D30: 0 | E30: 3 | F30: ＰＴＰ | G30: １００Ｔ | H30: =IF(E30="","",OFFSET(分類!$B$29,臨時!E30,0)) -> 外用.臨時.散薬ヒート
B31: =B30+1 -> 27 | C31: オーグメンチン配合錠２５０ＲＳ（３７５ｍｇ） | D31: 0 | E31: 15 | F31: ＰＴＰ | G31: ３０Ｔ | H31: =IF(E31="","",OFFSET(分類!$B$29,臨時!E31,0)) -> 不良在庫
B32: =B31+1 -> 28 | C32: オルメテックＯＤ錠１０ｍｇ | D32: 0 | E32: 3 | F32: ＰＴＰ | G32: １００Ｔ | H32: =IF(E32="","",OFFSET(分類!$B$29,臨時!E32,0)) -> 外用.臨時.散薬ヒート
B33: =B32+1 -> 29 | C33: カリメートドライシロップ９２．５９％ | D33: 0 | E33: 15 | G33: ５．４ｇｘ１２６包 | H33: =IF(E33="","",OFFSET(分類!$B$29,臨時!E33,0)) -> 不良在庫
B34: =B33+1 -> 30 | C34: グラアルファ配合点眼液 | D34: 0 | E34: 3 | G34: ５ｍｌｘ５ | H34: =IF(E34="","",OFFSET(分類!$B$29,臨時!E34,0)) -> 外用.臨時.散薬ヒート
B35: =B34+1 -> 31 | C35: クロピドグレル錠２５ｍｇ「ＪＧ」 | D35: 0 | E35: 3 | F35: ＰＴＰ | G35: １００Ｔ | H35: =IF(E35="","",OFFSET(分類!$B$29,臨時!E35,0)) -> 外用.臨時.散薬ヒート
B36: =B35+1 -> 32 | C36: クロフェクトン錠２５ｍｇ | D36: 0 | E36: 3 | F36: ＰＴＰ | G36: １００Ｔ | H36: =IF(E36="","",OFFSET(分類!$B$29,臨時!E36,0)) -> 外用.臨時.散薬ヒート
B37: =B36+1 -> 33 | C37: コソプト配合点眼液 | D37: 0 | E37: 3 | G37: ５ｍｌｘ１０ | H37: =IF(E37="","",OFFSET(分類!$B$29,臨時!E37,0)) -> 外用.臨時.散薬ヒート
B38: =B37+1 -> 34 | C38: ジクアス点眼液３％ | D38: 0 | E38: 3 | G38: ５ｍｌｘ１０ | H38: =IF(E38="","",OFFSET(分類!$B$29,臨時!E38,0)) -> 外用.臨時.散薬ヒート
B39: =B38+1 -> 35 | C39: スミスリンローション５％ | D39: 0 | E39: 3 | G39: ３０ｇｘ２ | H39: =IF(E39="","",OFFSET(分類!$B$29,臨時!E39,0)) -> 外用.臨時.散薬ヒート
B40: =B39+1 -> 36 | C40: セララ錠５０ｍｇ | D40: 0 | E40: 3 | F40: ＰＴＰ | G40: １００Ｔ | H40: =IF(E40="","",OFFSET(分類!$B$29,臨時!E40,0)) -> 外用.臨時.散薬ヒート
B41: =B40+1 -> 37 | C41: ソタロール塩酸塩錠８０ｍｇ「ＴＥ」 | D41: 0 | E41: 15 | F41: ＰＴＰ | G41: １４０Ｔ | H41: =IF(E41="","",OFFSET(分類!$B$29,臨時!E41,0)) -> 不良在庫
B42: =B41+1 -> 38 | C42: ダイフェン配合錠 | D42: 0 | E42: 15 | F42: ＰＴＰ | G42: １００Ｔ | H42: =IF(E42="","",OFFSET(分類!$B$29,臨時!E42,0)) -> 不良在庫
...

Sheet 外用
B2: {=RIGHT(CELL("filename",A1),LEN(CELL("filename",A1))-FIND("]",CELL("filename",A1)))} -> 外用
B4: No | C4: 薬品名 | D4: 毒劇区分 | E4: 棚 | F4: 包装形態 | G4: 容量 | H4: 棚場所
B5: 1 | C5: {=_xlfn._xlws.SORT(_xlfn.CHOOSECOLS(_xlfn._xlws.FILTER(IFERROR(統合マスタ!B2:Z1491,""),IFERROR(統合マスタ!R2:R1491=1,FALSE)*IFERROR(ISNUMBER(MATCH(統合マスタ!V2:V1491,分類!H8:H15,0)),FALSE)),2,23,25,4,5),2,1)} -> ＳＰトローチ０．２５ｍｇ「明治」 | D5: 0 | E5: 3 | F5: ＰＴＰ | G5: １２００Ｔ | H5: =IF(E5="","",OFFSET(分類!$B$29,E5,0)) -> 外用.臨時.散薬ヒート
B6: =B5+1 -> 2 | C6: アクアチムクリーム１％ | D6: 0 | E6: 3 | G6: １０ｇＸ１０ | H6: =IF(E6="","",OFFSET(分類!$B$29,E6,0)) -> 外用.臨時.散薬ヒート
B7: =B6+1 -> 3 | C7: アクトシン軟膏３％ | D7: 0 | E7: 15 | G7: ３０ｇ | H7: =IF(E7="","",OFFSET(分類!$B$29,E7,0)) -> 不良在庫
B8: =B7+1 -> 4 | C8: アズレン点眼液０．０２％「ニットー」 | D8: 0 | E8: 3 | G8: ５ｍｌｘ１０ | H8: =IF(E8="","",OFFSET(分類!$B$29,E8,0)) -> 外用.臨時.散薬ヒート
B9: =B8+1 -> 5 | C9: アドフィードパップ４０ｍｇ | D9: 0 | E9: 12 | G9: ７枚ｘ５０ | H9: =IF(E9="","",OFFSET(分類!$B$29,E9,0)) -> 湿布
B10: =B9+1 -> 6 | C10: インテバンクリーム１％ | D10: 0 | E10: 1 | G10: ２５ｇｌｘ１０ | H10: =IF(E10="","",OFFSET(分類!$B$29,E10,0)) -> 調剤棚
B11: =B10+1 -> 7 | C11: インテバン外用液１％ | D11: 0 | E11: 3 | G11: ５０ｍｌｘ１０ | H11: =IF(E11="","",OFFSET(分類!$B$29,E11,0)) -> 外用.臨時.散薬ヒート
B12: =B11+1 -> 8 | C12: オイラックスクリーム１０％ | D12: 0 | E12: 3 | G12: １０ｇＸ１０ | H12: =IF(E12="","",OFFSET(分類!$B$29,E12,0)) -> 外用.臨時.散薬ヒート
B13: =B12+1 -> 9 | C13: オフロキサシン点眼液０．３％「ＪＧ」 | D13: 0 | E13: 3 | G13: ５ｍｌｘ１０ | H13: =IF(E13="","",OFFSET(分類!$B$29,E13,0)) -> 外用.臨時.散薬ヒート
B14: =B13+1 -> 10 | C14: キュバール１００エアゾール１５ｍｇ | D14: 0 | E14: 3 | G14: ８．７ｇｘ１ | H14: =IF(E14="","",OFFSET(分類!$B$29,E14,0)) -> 外用.臨時.散薬ヒート
B15: =B14+1 -> 11 | C15: クロモグリク酸Ｎａ点眼液２％「ニットー」 | D15: 0 | E15: 3 | G15: ５ＭＬＸ５Ｖ | H15: =IF(E15="","",OFFSET(分類!$B$29,E15,0)) -> 外用.臨時.散薬ヒート
B16: =B15+1 -> 12 | C16: クロモグリク酸Ｎａ点眼液２％「ニットー」 | D16: 0 | E16: 3 | G16: ５ＭＬＸ１０Ｖ | H16: =IF(E16="","",OFFSET(分類!$B$29,E16,0)) -> 外用.臨時.散薬ヒート
B17: =B16+1 -> 13 | C17: ゲーベンクリーム１％ | D17: 0 | E17: 7 | G17: １００ｇ | H17: =IF(E17="","",OFFSET(分類!$B$29,E17,0)) -> 軟膏
... B67: =B66+1 -> 63 | C67: ロナセンテープ４０ｍｇ | D67: 2 | E67: 3 | G67: ７０枚 | H67: =IF(E67="","",OFFSET(分類!$B$29,E67,0)) -> 外用.臨時.散薬ヒート
B68: =B67+1 -> 64 | H68: =IF(E68="","",OFFSET(分類!$B$29,E68,0))
B69: =B68+1 -> 65 | H69: =IF(E69="","",OFFSET(分類!$B$29,E69,0))
B70: =B69+1 -> 66 | H70: =IF(E70="","",OFFSET(分類!$B$29,E70,0))
B71: =B70+1 -> 67 | H71: =IF(E71="","",OFFSET(分類!$B$29,E71,0))
B72: =B71+1 -> 68 | H72: =IF(E72="","",OFFSET(分類!$B$29,E72,0))
B73: =B72+1 -> 69 | H73: =IF(E73="","",OFFSET(分類!$B$29,E73,0))
B74: =B73+1 -> 70 | H74: =IF(E74="","",OFFSET(分類!$B$29,E74,0))
B75: =B74+1 -> 71 | H75: =IF(E75="","",OFFSET(分類!$B$29,E75,0))
B76: =B75+1 -> 72 | H76: =IF(E76="","",OFFSET(分類!$B$29,E76,0))
B77: =B76+1 -> 73 | H77: =IF(E77="","",OFFSET(分類!$B$29,E77,0))
B78: =B77+1 -> 74 | H78: =IF(E78="","",OFFSET(分類!$B$29,E78,0))
B79: =B78+1 -> 75 | H79: =IF(E79="","",OFFSET(分類!$B$29,E79,0))
... B304: =B303+1 -> 300 | H304: =IF(E304="","",OFFSET(分類!$B$29,E304,0))

Sheet 散剤
B2: {=RIGHT(CELL("filename",A1),LEN(CELL("filename",A1))-FIND("]",CELL("filename",A1)))} -> 散剤
B4: No | C4: 薬品名 | D4: 毒劇区分 | E4: 棚 | F4: 包装形態 | G4: 容量 | H4: 棚場所
B5: 1 | C5: {=_xlfn._xlws.SORT(_xlfn.CHOOSECOLS(_xlfn._xlws.FILTER(IFERROR(統合マスタ!B2:Z1491,""),IFERROR(統合マスタ!R2:R1491=1,FALSE)*IFERROR(ISNUMBER(MATCH(統合マスタ!V2:V1491,分類!K8:K15,0)),FALSE)),2,23,25,4,5),2,1)} -> ０１７ ツムラ ゴレイサン | D5: 0 | E5: 4 | F5: 粉 | G5: ２．５ｇｘ１８９ | H5: =IF(E5="","",OFFSET(分類!$B$29,E5,0)) -> 漢方薬
B6: =B5+1 -> 2 | C6: ０５４ ツムラ ヨクカンサン | D6: 0 | E6: 4 | F6: 粉 | G6: ２．５ｇＸ１８９ | H6: =IF(E6="","",OFFSET(分類!$B$29,E6,0)) -> 漢方薬
B7: =B6+1 -> 3 | C7: ０６２ ツムラ ボウフウツウシヨウサン | D7: 0 | E7: 4 | F7: 粉 | G7: ２．５ｇｘ１８９ | H7: =IF(E7="","",OFFSET(分類!$B$29,E7,0)) -> 漢方薬
B8: =B7+1 -> 4 | C8: ０６８ ツムラ シャクヤクカンゾウトウ | D8: 0 | E8: 4 | F8: 粉 | G8: ２．５ｇｘ４２ | H8: =IF(E8="","",OFFSET(分類!$B$29,E8,0)) -> 漢方薬
B9: =B8+1 -> 5 | C9: ０８３ ツムラ ヨクカンサンカチンピハンゲ | D9: 0 | E9: 4 | F9: 粉 | G9: ２．５ｇｘ１８９ | H9: =IF(E9="","",OFFSET(分類!$B$29,E9,0)) -> 漢方薬
B10: =B9+1 -> 6 | C10: １００ ツムラ ダイケンチユウトウ | D10: 0 | E10: 4 | F10: 粉 | G10: ２．５ｇＸ１８９ | H10: =IF(E10="","",OFFSET(分類!$B$29,E10,0)) -> 漢方薬
B11: =B10+1 -> 7 | C11: ＥＫ１ 葛根湯エキス細粒 | D11: 0 | E11: 4 | F11: 粉 | G11: ２．５ｇ×２９４ | H11: =IF(E11="","",OFFSET(分類!$B$29,E11,0)) -> 漢方薬
B12: =B11+1 -> 8 | C12: ＥＫ２４ 加味逍遥散料エキス細粒 | D12: 0 | E12: 4 | F12: 粉 | G12: ２ｇｘ４２包 | H12: =IF(E12="","",OFFSET(分類!$B$29,E12,0)) -> 漢方薬
B13: =B12+1 -> 9 | C13: ＥＫ４１ 補中益気湯エキス細粒 | D13: 0 | E13: 4 | F13: 粉 | G13: ２．５ｇｘ２９４ | H13: =IF(E13="","",OFFSET(分類!$B$29,E13,0)) -> 漢方薬
B14: =B13+1 -> 10 | C14: アスパラカリウム散５０％ | D14: 0 | E14: 2 | F14: 粉 | G14: ５００ｇ | H14: =IF(E14="","",OFFSET(分類!$B$29,E14,0)) -> 散薬調剤台
B15: =B14+1 -> 11 | C15: アドナ散１０％ | D15: 0 | E15: 2 | F15: 粉 | G15: １００ｇ | H15: =IF(E15="","",OFFSET(分類!$B$29,E15,0)) -> 散薬調剤台
B16: =B15+1 -> 12 | C16: アミノレバンＥＮ配合散 コーヒー味 | D16: 0 | E16: 15 | F16: 粉 | G16: ５０ｇＸ２１包 | H16: =IF(E16="","",OFFSET(分類!$B$29,E16,0)) -> 不良在庫
B17: =B16+1 -> 13 | C17: カルバマゼピン細粒５０％「アメル」 | D17: 0 | E17: 2 | F17: 粉 | G17: ５００ｇ | H17: =IF(E17="","",OFFSET(分類!$B$29,E17,0)) -> 散薬調剤台
B18: =B17+1 -> 14 | C18: グラマリール細粒１０％ | D18: 0 | E18: 2 | F18: 粉 | G18: １００ｇ | H18: =IF(E18="","",OFFSET(分類!$B$29,E18,0)) -> 散薬調剤台
B19: =B18+1 -> 15 | C19: クレメジン細粒分包２ｇ | D19: 0 | E19: 3 | G19: ２ｇｘ８４包 | H19: =IF(E19="","",OFFSET(分類!$B$29,E19,0)) -> 外用.臨時.散薬ヒート
B20: =B19+1 -> 16 | C20: シーピー配合顆粒 | D20: 0 | E20: 3 | F20: 粉 | G20: １ｇｘ１０５０包 | H20: =IF(E20="","",OFFSET(分類!$B$29,E20,0)) -> 外用.臨時.散薬ヒート
B21: =B20+1 -> 17 | C21: センブリ・重曹散 | D21: 0 | E21: 2 | F21: 粉 | G21: ５００ｇ | H21: =IF(E21="","",OFFSET(分類!$B$29,E21,0)) -> 散薬調剤台
B22: =B21+1 -> 18 | C22: タンニン酸アルブミン「ＶＴＲＳ」原末 | D22: 0 | E22: 2 | F22: 粉 | G22: ５００ｇ | H22: =IF(E22="","",OFFSET(分類!$B$29,E22,0)) -> 散薬調剤台
B23: =B22+1 -> 19 | C23: テプレノン細粒１０％「ＹＤ」 | D23: 0 | E23: 2 | F23: 粉 | G23: １００ｇ | H23: =IF(E23="","",OFFSET(分類!$B$29,E23,0)) -> 散薬調剤台
B24: =B23+1 -> 20 | C24: パントシン散２０％ | D24: 0 | E24: 2 | F24: 粉 | G24: １００ｇ | H24: =IF(E24="","",OFFSET(分類!$B$29,E24,0)) -> 散薬調剤台
B25: =B24+1 -> 21 | C25: ビオフェルミン配合散 | D25: 0 | E25: 3 | F25: 粉 | G25: １ｇｘ１２０ | H25: =IF(E25="","",OFFSET(分類!$B$29,E25,0)) -> 外用.臨時.散薬ヒート
B26: =B25+1 -> 22 | C26: ビオフェルミン配合散 | D26: 0 | E26: 3 | F26: 粉 | G26: １ｇｘ６００ | H26: =IF(E26="","",OFFSET(分類!$B$29,E26,0)) -> 外用.臨時.散薬ヒート
B27: =B26+1 -> 23 | C27: ビオフェルミン配合散 | D27: 0 | E27: 3 | F27: 粉 | G27: １ｋｇ | H27: =IF(E27="","",OFFSET(分類!$B$29,E27,0)) -> 外用.臨時.散薬ヒート
B28: =B27+1 -> 24 | C28: フロセミド細粒４％「ＥＭＥＣ」 | D28: 0 | E28: 2 | F28: 粉 | G28: １００ｇ | H28: =IF(E28="","",OFFSET(分類!$B$29,E28,0)) -> 散薬調剤台
B29: =B28+1 -> 25 | C29: マーズレンＳ配合顆粒 | D29: 0 | E29: 3 | F29: 粉 | G29: ４００ｇ（０．６７ｆｘ６００） | H29: =IF(E29="","",OFFSET(分類!$B$29,E29,0)) -> 外用.臨時.散薬ヒート
B30: =B29+1 -> 26 | C30: マーズレンＳ配合顆粒 | D30: 0 | E30: 3 | F30: 粉 | G30: １０００ｇ | H30: =IF(E30="","",OFFSET(分類!$B$29,E30,0)) -> 外用.臨時.散薬ヒート
B31: =B30+1 -> 27 | C31: モサプリドクエン酸塩散１％「日医工」 | D31: 0 | E31: 2 | F31: 粉 | G31: １００ｇ | H31: =IF(E31="","",OFFSET(分類!$B$29,E31,0)) -> 散薬調剤台
... B45: =B44+1 -> 41 | C45: リスパダール細粒１％ | D45: 2 | E45: 1 | F45: 粉 | G45: １００ｇ | H45: =IF(E45="","",OFFSET(分類!$B$29,E45,0)) -> 調剤棚
B46: =B45+1 -> 42 | C46: ロドピン細粒５０％ | D46: 2 | E46: 2 | G46: １００ｇ | H46: =IF(E46="","",OFFSET(分類!$B$29,E46,0)) -> 散薬調剤台
B47: =B46+1 -> 43 | H47: =IF(E47="","",OFFSET(分類!$B$29,E47,0))
B48: =B47+1 -> 44 | H48: =IF(E48="","",OFFSET(分類!$B$29,E48,0))
B49: =B48+1 -> 45 | H49: =IF(E49="","",OFFSET(分類!$B$29,E49,0))
B50: =B49+1 -> 46 | H50: =IF(E50="","",OFFSET(分類!$B$29,E50,0))
B51: =B50+1 -> 47 | H51: =IF(E51="","",OFFSET(分類!$B$29,E51,0))
B52: =B51+1 -> 48 | H52: =IF(E52="","",OFFSET(分類!$B$29,E52,0))
B53: =B52+1 -> 49 | H53: =IF(E53="","",OFFSET(分類!$B$29,E53,0))
B54: =B53+1 -> 50 | H54: =IF(E54="","",OFFSET(分類!$B$29,E54,0))
B55: =B54+1 -> 51 | H55: =IF(E55="","",OFFSET(分類!$B$29,E55,0))
...

Sheet 錠剤
B2: {=RIGHT(CELL("filename",A1),LEN(CELL("filename",A1))-FIND("]",CELL("filename",A1)))} -> 錠剤
B4: No | C4: 薬品名 | D4: 毒劇区分 | E4: 棚 | F4: 包装形態 | G4: 容量 | H4: 棚場所
B5: 1 | C5: {=_xlfn._xlws.SORT(_xlfn.CHOOSECOLS(_xlfn._xlws.FILTER(IFERROR(統合マスタ!B2:Z1491,""),IFERROR(統合マスタ!R2:R1491=1,FALSE)*IFERROR(ISNUMBER(MATCH(統合マスタ!V2:V1491,分類!N8:N15,0)),FALSE)),2,23,25,4,5),2,1)} -> ２５ｍｇアリナミン Ｆ糖衣錠 | D5: 0 | E5: 5 | F5: ＰＴＰ | G5: １００Ｔ | H5: =IF(E5="","",OFFSET(分類!$B$29,E5,0)) -> 普通薬バラ
