Workbook

Sheet 統合マスタ
C3: 棚卸 | N3: マスタ
B4: no | C4: 名称 | D4: 2025年度卸 | E4: 包装形態 | F4: 容量 | G4: メーカー | H4: 新単位薬価 | I4: 2025年度薬価 | J4: 単位数量 | K4: 薬価単位 | L4: 2025年納入価格 | M4: 単位納入価 | N4: コード(区分値) | O4: コード | P4: 名称 | Q4: ホストコード | R4: 採用区分（区分値）(区分値) | S4: 採用区分（区分値） | T4: 薬価 | U4: カナ名称 | V4: 剤形(区分値) | W4: 剤形 | X4: 毒劇薬（区分値）(区分値) | Y4: 毒劇薬（区分値） | Z4: 場所番号 | AA4: 非採用/処置薬 | AB4: Excelシート | AC4: ソートキー | AD4: 数量合計
A5: =元データ!P2 -> 295 | B5: 1 | C5: =DBCS(元データ!A2) -> ００７ ツムラ ハチミジオウガン | D5: =元データ!B2 -> メディセオ | E5: =DBCS(元データ!C2) -> 粉 | F5: =DBCS(元データ!D2) -> ２．５ｇｘ１８９ | G5: =元データ!E2 -> ツムラ | H5: =元データ!F2 -> 9.8 | I5: =元データ!G2 -> 4630.5 | J5: =元データ!H2 -> 472.5 | K5: =元データ!I2 -> ｇ | L5: =元データ!J2 -> 4093 | M5: =元データ!K2 -> 8.6624339 | N5: =IF(OFFSET(マスタ非採用削除!A$4,統合マスタ!$A5,0)="","",OFFSET(マスタ非採用削除!A$4,統合マスタ!$A5,0)) -> ﾂﾑﾗ007 | O5: =IF(OFFSET(マスタ非採用削除!B$4,統合マスタ!$A5,0)="","",OFFSET(マスタ非採用削除!B$4,統合マスタ!$A5,0)) -> ﾂﾑﾗ007 | P5: =IF(OFFSET(マスタ非採用削除!C$4,統合マスタ!$A5,0)="","",OFFSET(マスタ非採用削除!C$4,統合マスタ!$A5,0)) -> ツムラ八味地黄丸エキス顆粒（医療用） | Q5: =IF(OFFSET(マスタ非採用削除!D$4,統合マスタ!$A5,0)="","",OFFSET(マスタ非採用削除!D$4,統合マスタ!$A5,0)) -> ﾊﾁﾐ | R5: =IF(OR(A5="非採用",A5="処置薬",A5="非採用特別"),0,IF(OFFSET(マスタ非採用削除!E$4,統合マスタ!$A5,0)="","",OFFSET(マスタ非採用削除!E$4,統合マスタ!$A5,0))) -> 2 | S5: =IF(OFFSET(マスタ非採用削除!F$4,統合マスタ!$A5,0)="","",OFFSET(マスタ非採用削除!F$4,統合マスタ!$A5,0)) | T5: =IF(OFFSET(マスタ非採用削除!G$4,統合マスタ!$A5,0)="","",OFFSET(マスタ非採用削除!G$4,統合マスタ!$A5,0)) -> 9.8 | U5: =IF(OFFSET(マスタ非採用削除!H$4,統合マスタ!$A5,0)="","",OFFSET(マスタ非採用削除!H$4,統合マスタ!$A5,0)) -> ﾂﾑﾗﾊﾁﾐｼﾞｵｳｶﾞﾝｴｷｽｶﾘｭｳ(ｲﾘｮｳﾖｳ) | V5: =IF(OFFSET(マスタ非採用削除!I$4,統合マスタ!$A5,0)="","",OFFSET(マスタ非採用削除!I$4,統合マスタ!$A5,0)) -> 3 | W5: =IF(OFFSET(マスタ非採用削除!J$4,統合マスタ!$A5,0)="","",OFFSET(マスタ非採用削除!J$4,統合マスタ!$A5,0)) -> 散 | X5: =IF(OFFSET(マスタ非採用削除!K$4,統合マスタ!$A5,0)="","",OFFSET(マスタ非採用削除!K$4,統合マスタ!$A5,0)) -> 0 | Y5: =IF(OFFSET(マスタ非採用削除!L$4,統合マスタ!$A5,0)="","",OFFSET(マスタ非採用削除!L$4,統合マスタ!$A5,0)) | Z5: =IF(OFFSET(マスタ非採用削除!M$4,統合マスタ!$A5,0)="","",OFFSET(マスタ非採用削除!M$4,統合マスタ!$A5,0)) -> 4 | AA5: =IF(A5="非採用","非採用",IF(A5="処置薬","処置薬","")) | AB5: =IF(A5="非採用特別","非採用特別",IF(R5=2,"臨時", IF(COUNTIF(分類!$H$8:$H$19, 統合マスタ!V5)>0, 分類!$G$7, IF(COUNTIF(分類!$K$8:$K$19, 統合マスタ!V5)>0, 分類!$J$7, IF(COUNTIF(分類!$N$8:$N$19, 統合マスタ!V5)>0, 分類!$M$7, IF(COUNTIF(分類!$Q$8:$Q$19, 統合マスタ!V5)>0, 分類!$P$7, IF(COUNTIF(分類!$T$8:$T$19, 統合マスタ!V5)>0, 分類!$S$7, "無し"))))))) -> 臨時 | AC5: =X5*100000+B5 -> 1 | AD5: {=IF(A5="非採用","非採用",OFFSET( INDIRECT("'" & AB5 & "'!A4"), MATCH(B5, INDIRECT("'" & AB5 & "'!C5:C1000"), 0), MATCH("合計", INDIRECT("'" & AB5 & "'!4:4"), 0) - 1 ))} -> 0
A6: =元データ!P3 -> 295 | B6: =B5+1 -> 2 | C6: =DBCS(元データ!A3) -> ００７ ツムラ ハチミジオウガン | D6: =元データ!B3 | E6: =DBCS(元データ!C3) -> 粉 | F6: =DBCS(元データ!D3) -> ２．５ｇｘ４２ | G6: =元データ!E3 -> ツムラ | H6: =元データ!F3 -> 9.8 | I6: =元データ!G3 -> 1029 | J6: =元データ!H3 -> 105 | K6: =元データ!I3 -> ｇ | L6: =元データ!J3 -> 935 | M6: =元データ!K3 -> 8.9047619 | N6: =IF(OFFSET(マスタ非採用削除!A$4,統合マスタ!$A6,0)="","",OFFSET(マスタ非採用削除!A$4,統合マスタ!$A6,0)) -> ﾂﾑﾗ007 | O6: =IF(OFFSET(マスタ非採用削除!B$4,統合マスタ!$A6,0)="","",OFFSET(マスタ非採用削除!B$4,統合マスタ!$A6,0)) -> ﾂﾑﾗ007 | P6: =IF(OFFSET(マスタ非採用削除!C$4,統合マスタ!$A6,0)="","",OFFSET(マスタ非採用削除!C$4,統合マスタ!$A6,0)) -> ツムラ八味地黄丸エキス顆粒（医療用） | Q6: =IF(OFFSET(マスタ非採用削除!D$4,統合マスタ!$A6,0)="","",OFFSET(マスタ非採用削除!D$4,統合マスタ!$A6,0)) -> ﾊﾁﾐ | R6: =IF(OR(A6="非採用",A6="処置薬",A6="非採用特別"),0,IF(OFFSET(マスタ非採用削除!E$4,統合マスタ!$A6,0)="","",OFFSET(マスタ非採用削除!E$4,統合マスタ!$A6,0))) -> 2 | S6: =IF(OFFSET(マスタ非採用削除!F$4,統合マスタ!$A6,0)="","",OFFSET(マスタ非採用削除!F$4,統合マスタ!$A6,0)) | T6: =IF(OFFSET(マスタ非採用削除!G$4,統合マスタ!$A6,0)="","",OFFSET(マスタ非採用削除!G$4,統合マスタ!$A6,0)) -> 9.8 | U6: =IF(OFFSET(マスタ非採用削除!H$4,統合マスタ!$A6,0)="","",OFFSET(マスタ非採用削除!H$4,統合マスタ!$A6,0)) -> ﾂﾑﾗﾊﾁﾐｼﾞｵｳｶﾞﾝｴｷｽｶﾘｭｳ(ｲﾘｮｳﾖｳ) | V6: =IF(OFFSET(マスタ非採用削除!I$4,統合マスタ!$A6,0)="","",OFFSET(マスタ非採用削除!I$4,統合マスタ!$A6,0)) -> 3 | W6: =IF(OFFSET(マスタ非採用削除!J$4,統合マスタ!$A6,0)="","",OFFSET(マスタ非採用削除!J$4,統合マスタ!$A6,0)) -> 散 | X6: =IF(OFFSET(マスタ非採用削除!K$4,統合マスタ!$A6,0)="","",OFFSET(マスタ非採用削除!K$4,統合マスタ!$A6,0)) -> 0 | Y6: =IF(OFFSET(マスタ非採用削除!L$4,統合マスタ!$A6,0)="","",OFFSET(マスタ非採用削除!L$4,統合マスタ!$A6,0)) | Z6: =IF(OFFSET(マスタ非採用削除!M$4,統合マスタ!$A6,0)="","",OFFSET(マスタ非採用削除!M$4,統合マスタ!$A6,0)) -> 4 | AA6: =IF(A6="非採用","非採用",IF(A6="処置薬","処置薬","")) | AB6: =IF(A6="非採用特別","非採用特別",IF(R6=2,"臨時", IF(COUNTIF(分類!$H$8:$H$19, 統合マスタ!V6)>0, 分類!$G$7, IF(COUNTIF(分類!$K$8:$K$19, 統合マスタ!V6)>0, 分類!$J$7, IF(COUNTIF(分類!$N$8:$N$19, 統合マスタ!V6)>0, 分類!$M$7, IF(COUNTIF(分類!$Q$8:$Q$19, 統合マスタ!V6)>0, 分類!$P$7, IF(COUNTIF(分類!$T$8:$T$19, 統合マスタ!V6)>0, 分類!$S$7, "無し"))))))) -> 臨時 | AC6: =X6*100000+B6 -> 2 | AD6: {=IF(A6="非採用","非採用",OFFSET( INDIRECT("'" & AB6 & "'!A4"), MATCH(B6, INDIRECT("'" & AB6 & "'!C5:C1000"), 0), MATCH("合計", INDIRECT("'" & AB6 & "'!4:4"), 0) - 1 ))} -> 0
A7: =元データ!P4 -> 296 | B7: =B6+1 -> 3 | C7: =DBCS(元データ!A4) -> ０１２ ツムラ サイコカリュウコツボレイトウ | D7: =元データ!B4 -> メディセオ | E7: =DBCS(元データ!C4) -> 粉 | F7: =DBCS(元データ!D4) -> ２．５ｇｘ１８９ | G7: =元データ!E4 -> ツムラ | H7: =元データ!F4 -> 20.3 | I7: =元データ!G4 -> 9591.75 | J7: =元データ!H4 -> 472.5 | K7: =元データ!I4 -> g | L7: =元データ!J4 -> 8544 | M7: =元データ!K4 -> 18.08254 | N7: =IF(OFFSET(マスタ非採用削除!A$4,統合マスタ!$A7,0)="","",OFFSET(マスタ非採用削除!A$4,統合マスタ!$A7,0)) -> ﾂﾑﾗ012 | O7: =IF(OFFSET(マスタ非採用削除!B$4,統合マスタ!$A7,0)="","",OFFSET(マスタ非採用削除!B$4,統合マスタ!$A7,0)) -> ﾂﾑﾗ012 | P7: =IF(OFFSET(マスタ非採用削除!C$4,統合マスタ!$A7,0)="","",OFFSET(マスタ非採用削除!C$4,統合マスタ!$A7,0)) -> ツムラ柴胡加竜骨牡蛎湯エキス顆粒（医療用） | Q7: =IF(OFFSET(マスタ非採用削除!D$4,統合マスタ!$A7,0)="","",OFFSET(マスタ非採用削除!D$4,統合マスタ!$A7,0)) -> ｻｲｺ | R7: =IF(OR(A7="非採用",A7="処置薬",A7="非採用特別"),0,IF(OFFSET(マスタ非採用削除!E$4,統合マスタ!$A7,0)="","",OFFSET(マスタ非採用削除!E$4,統合マスタ!$A7,0))) -> 2 | S7: =IF(OFFSET(マスタ非採用削除!F$4,統合マスタ!$A7,0)="","",OFFSET(マスタ非採用削除!F$4,統合マスタ!$A7,0)) | T7: =IF(OFFSET(マスタ非採用削除!G$4,統合マスタ!$A7,0)="","",OFFSET(マスタ非採用削除!G$4,統合マスタ!$A7,0)) -> 20.3 | U7: =IF(OFFSET(マスタ非採用削除!H$4,統合マスタ!$A7,0)="","",OFFSET(マスタ非採用削除!H$4,統合マスタ!$A7,0)) -> ﾂﾑﾗｻｲｺｶﾘｭｳｺﾂﾎﾞﾚｲﾄｳｴｷｽｶﾘｭｳ(ｲﾘｮｳﾖｳ) | V7: =IF(OFFSET(マスタ非採用削除!I$4,統合マスタ!$A7,0)="","",OFFSET(マスタ非採用削除!I$4,統合マスタ!$A7,0)) -> 3 | W7: =IF(OFFSET(マスタ非採用削除!J$4,統合マスタ!$A7,0)="","",OFFSET(マスタ非採用削除!J$4,統合マスタ!$A7,0)) -> 散 | X7: =IF(OFFSET(マスタ非採用削除!K$4,統合マスタ!$A7,0)="","",OFFSET(マスタ非採用削除!K$4,統合マスタ!$A7,0)) -> 0 | Y7: =IF(OFFSET(マスタ非採用削除!L$4,統合マスタ!$A7,0)="","",OFFSET(マスタ非採用削除!L$4,統合マスタ!$A7,0)) | Z7: =IF(OFFSET(マスタ非採用削除!M$4,統合マスタ!$A7,0)="","",OFFSET(マスタ非採用削除!M$4,統合マスタ!$A7,0)) -> 4 | AA7: =IF(A7="非採用","非採用",IF(A7="処置薬","処置薬","")) | AB7: =IF(A7="非採用特別","非採用特別",IF(R7=2,"臨時", IF(COUNTIF(分類!$H$8:$H$19, 統合マスタ!V7)>0, 分類!$G$7, IF(COUNTIF(分類!$K$8:$K$19, 統合マスタ!V7)>0, 分類!$J$7, IF(COUNTIF(分類!$N$8:$N$19, 統合マスタ!V7)>0, 分類!$M$7, IF(COUNTIF(分類!$Q$8:$Q$19, 統合マスタ!V7)>0, 分類!$P$7, IF(COUNTIF(分類!$T$8:$T$19, 統合マスタ!V7)>0, 分類!$S$7, "無し"))))))) -> 臨時 | AC7: =X7*100000+B7 -> 3 | AD7: {=IF(A7="非採用","非採用",OFFSET( INDIRECT("'" & AB7 & "'!A4"), MATCH(B7, INDIRECT("'" & AB7 & "'!C5:C1000"), 0), MATCH("合計", INDIRECT("'" & AB7 & "'!4:4"), 0) - 1 ))} -> 0
A8: =元データ!P5 -> 297 | B8: =B7+1 -> 4 | C8: =DBCS(元データ!A5) -> ０１６ ツムラ ハンゲコウボクトウ | D8: =元データ!B5 -> メディセオ | E8: =DBCS(元データ!C5) -> 粉 | F8: =DBCS(元データ!D5) -> ２．５ｇｘ１８９ | G8: =元データ!E5 -> ツムラ | H8: =元データ!F5 -> 14.6 | I8: =元データ!G5 -> 6898.5 | J8: =元データ!H5 -> 472.5 | K8: =元データ!I5 -> ｇ | L8: =元データ!J5 -> 6211 | M8: =元データ!K5 -> 13.144974 | N8: =IF(OFFSET(マスタ非採用削除!A$4,統合マスタ!$A8,0)="","",OFFSET(マスタ非採用削除!A$4,統合マスタ!$A8,0)) -> ﾂﾑﾗ016 | O8: =IF(OFFSET(マスタ非採用削除!B$4,統合マスタ!$A8,0)="","",OFFSET(マスタ非採用削除!B$4,統合マスタ!$A8,0)) -> ﾂﾑﾗ016 | P8: =IF(OFFSET(マスタ非採用削除!C$4,統合マスタ!$A8,0)="","",OFFSET(マスタ非採用削除!C$4,統合マスタ!$A8,0)) -> ツムラ半夏厚朴湯エキス顆粒（医療用） | Q8: =IF(OFFSET(マスタ非採用削除!D$4,統合マスタ!$A8,0)="","",OFFSET(マスタ非採用削除!D$4,統合マスタ!$A8,0)) -> ﾊﾝｹﾞｺ | R8: =IF(OR(A8="非採用",A8="処置薬",A8="非採用特別"),0,IF(OFFSET(マスタ非採用削除!E$4,統合マスタ!$A8,0)="","",OFFSET(マスタ非採用削除!E$4,統合マスタ!$A8,0))) -> 2 | S8: =IF(OFFSET(マスタ非採用削除!F$4,統合マスタ!$A8,0)="","",OFFSET(マスタ非採用削除!F$4,統合マスタ!$A8,0)) | T8: =IF(OFFSET(マスタ非採用削除!G$4,統合マスタ!$A8,0)="","",OFFSET(マスタ非採用削除!G$4,統合マスタ!$A8,0)) -> 14.6 | U8: =IF(OFFSET(マスタ非採用削除!H$4,統合マスタ!$A8,0)="","",OFFSET(マスタ非採用削除!H$4,統合マスタ!$A8,0)) -> ﾂﾑﾗﾊﾝｹﾞｺｳﾎﾞｸﾄｳｴｷｽｶﾘｭｳ(ｲﾘｮｳﾖｳ) | V8: =IF(OFFSET(マスタ非採用削除!I$4,統合マスタ!$A8,0)="","",OFFSET(マスタ非採用削除!I$4,統合マスタ!$A8,0)) -> 3 | W8: =IF(OFFSET(マスタ非採用削除!J$4,統合マスタ!$A8,0)="","",OFFSET(マスタ非採用削除!J$4,統合マスタ!$A8,0)) -> 散 | X8: =IF(OFFSET(マスタ非採用削除!K$4,統合マスタ!$A8,0)="","",OFFSET(マスタ非採用削除!K$4,統合マスタ!$A8,0)) -> 0 | Y8: =IF(OFFSET(マスタ非採用削除!L$4,統合マスタ!$A8,0)="","",OFFSET(マスタ非採用削除!L$4,統合マスタ!$A8,0)) | Z8: =IF(OFFSET(マスタ非採用削除!M$4,統合マスタ!$A8,0)="","",OFFSET(マスタ非採用削除!M$4,統合マスタ!$A8,0)) -> 4 | AA8: =IF(A8="非採用","非採用",IF(A8="処置薬","処置薬","")) | AB8: =IF(A8="非採用特別","非採用特別",IF(R8=2,"臨時", IF(COUNTIF(分類!$H$8:$H$19, 統合マスタ!V8)>0, 分類!$G$7, IF(COUNTIF(分類!$K$8:$K$19, 統合マスタ!V8)>0, 分類!$J$7, IF(COUNTIF(分類!$N$8:$N$19, 統合マスタ!V8)>0, 分類!$M$7, IF(COUNTIF(分類!$Q$8:$Q$19, 統合マスタ!V8)>0, 分類!$P$7, IF(COUNTIF(分類!$T$8:$T$19, 統合マスタ!V8)>0, 分類!$S$7, "無し"))))))) -> 臨時 | AC8: =X8*100000+B8 -> 4 | AD8: {=IF(A8="非採用","非採用",OFFSET( INDIRECT("'" & AB8 & "'!A4"), MATCH(B8, INDIRECT("'" & AB8 & "'!C5:C1000"), 0), MATCH("合計", INDIRECT("'" & AB8 & "'!4:4"), 0) - 1 ))} -> 0
A9: =元データ!P6 -> 298 | B9: =B8+1 -> 5 | C9: =DBCS(元データ!A6) -> ０１７ ツムラ ゴレイサン | D9: =元データ!B6 -> メディセオ | E9: =DBCS(元データ!C6) -> 粉 | F9: =DBCS(元データ!D6) -> ２．５ｇｘ１８９ | G9: =元データ!E6 -> ツムラ | H9: =元データ!F6 -> 13.6 | I9: =元データ!G6 -> 6426 | J9: =元データ!H6 -> 472.5 | K9: =元データ!I6 -> g | L9: =元データ!J6 -> 5728 | M9: =元データ!K6 -> 12.122751 | N9: =IF(OFFSET(マスタ非採用削除!A$4,統合マスタ!$A9,0)="","",OFFSET(マスタ非採用削除!A$4,統合マスタ!$A9,0)) -> ﾂﾑﾗ017 | O9: =IF(OFFSET(マスタ非採用削除!B$4,統合マスタ!$A9,0)="","",OFFSET(マスタ非採用削除!B$4,統合マスタ!$A9,0)) -> ﾂﾑﾗ017 | P9: =IF(OFFSET(マスタ非採用削除!C$4,統合マスタ!$A9,0)="","",OFFSET(マスタ非採用削除!C$4,統合マスタ!$A9,0)) -> ツムラ五苓散エキス顆粒（医療用） | Q9: =IF(OFFSET(マスタ非採用削除!D$4,統合マスタ!$A9,0)="","",OFFSET(マスタ非採用削除!D$4,統合マスタ!$A9,0)) -> ｺﾞﾚｲ | R9: =IF(OR(A9="非採用",A9="処置薬",A9="非採用特別"),0,IF(OFFSET(マスタ非採用削除!E$4,統合マスタ!$A9,0)="","",OFFSET(マスタ非採用削除!E$4,統合マスタ!$A9,0))) -> 1 | S9: =IF(OFFSET(マスタ非採用削除!F$4,統合マスタ!$A9,0)="","",OFFSET(マスタ非採用削除!F$4,統合マスタ!$A9,0)) | T9: =IF(OFFSET(マスタ非採用削除!G$4,統合マスタ!$A9,0)="","",OFFSET(マスタ非採用削除!G$4,統合マスタ!$A9,0)) -> 13.6 | U9: =IF(OFFSET(マスタ非採用削除!H$4,統合マスタ!$A9,0)="","",OFFSET(マスタ非採用削除!H$4,統合マスタ!$A9,0)) -> ﾂﾑﾗｺﾞﾚｲｻﾝｴｷｽｶﾘｭｳ(ｲﾘｮｳﾖｳ) | V9: =IF(OFFSET(マスタ非採用削除!I$4,統合マスタ!$A9,0)="","",OFFSET(マスタ非採用削除!I$4,統合マスタ!$A9,0)) -> 3 | W9: =IF(OFFSET(マスタ非採用削除!J$4,統合マスタ!$A9,0)="","",OFFSET(マスタ非採用削除!J$4,統合マスタ!$A9,0)) -> 散 | X9: =IF(OFFSET(マスタ非採用削除!K$4,統合マスタ!$A9,0)="","",OFFSET(マスタ非採用削除!K$4,統合マスタ!$A9,0)) -> 0 | Y9: =IF(OFFSET(マスタ非採用削除!L$4,統合マスタ!$A9,0)="","",OFFSET(マスタ非採用削除!L$4,統合マスタ!$A9,0)) | Z9: =IF(OFFSET(マスタ非採用削除!M$4,統合マスタ!$A9,0)="","",OFFSET(マスタ非採用削除!M$4,統合マスタ!$A9,0)) -> 4 | AA9: =IF(A9="非採用","非採用",IF(A9="処置薬","処置薬","")) | AB9: =IF(A9="非採用特別","非採用特別",IF(R9=2,"臨時", IF(COUNTIF(分類!$H$8:$H$19, 統合マスタ!V9)>0, 分類!$G$7, IF(COUNTIF(分類!$K$8:$K$19, 統合マスタ!V9)>0, 分類!$J$7, IF(COUNTIF(分類!$N$8:$N$19, 統合マスタ!V9)>0, 分類!$M$7, IF(COUNTIF(分類!$Q$8:$Q$19, 統合マスタ!V9)>0, 分類!$P$7, IF(COUNTIF(分類!$T$8:$T$19, 統合マスタ!V9)>0, 分類!$S$7, "無し"))))))) -> 散剤 | AC9: =X9*100000+B9 -> 5 | AD9: {=IF(A9="非採用","非採用",OFFSET( INDIRECT("'" & AB9 & "'!A4"), MATCH(B9, INDIRECT("'" & AB9 & "'!C5:C1000"), 0), MATCH("合計", INDIRECT("'" & AB9 & "'!4:4"), 0) - 1 ))} -> 0
A10: =元データ!P7 -> 299 | B10: =B9+1 -> 6 | C10: =DBCS(元データ!A7) -> ０１９ ツムラ ショウセイリュウトウ | D10: =元データ!B7 -> メディセオ | E10: =DBCS(元データ!C7) -> 粉 | F10: =DBCS(元データ!D7) -> ３ｇＸ４２ | G10: =元データ!E7 -> ツムラ | H10: =元データ!F7 -> 12.8 | I10: =元データ!G7 -> 1612.8 | J10: =元データ!H7 -> 126 | K10: =元データ!I7 -> g | L10: =元データ!J7 -> 1465 | M10: =元データ!K7 -> 11.626984 | N10: =IF(OFFSET(マスタ非採用削除!A$4,統合マスタ!$A10,0)="","",OFFSET(マスタ非採用削除!A$4,統合マスタ!$A10,0)) -> ﾂﾑﾗ019 | O10: =IF(OFFSET(マスタ非採用削除!B$4,統合マスタ!$A10,0)="","",OFFSET(マスタ非採用削除!B$4,統合マスタ!$A10,0)) -> ﾂﾑﾗ019 | P10: =IF(OFFSET(マスタ非採用削除!C$4,統合マスタ!$A10,0)="","",OFFSET(マスタ非採用削除!C$4,統合マスタ!$A10,0)) -> ツムラ小青竜湯エキス顆粒（医療用） | Q10: =IF(OFFSET(マスタ非採用削除!D$4,統合マスタ!$A10,0)="","",OFFSET(マスタ非採用削除!D$4,統合マスタ!$A10,0)) | R10: =IF(OR(A10="非採用",A10="処置薬",A10="非採用特別"),0,IF(OFFSET(マスタ非採用削除!E$4,統合マスタ!$A10,0)="","",OFFSET(マスタ非採用削除!E$4,統合マスタ!$A10,0))) -> 2 | S10: =IF(OFFSET(マスタ非採用削除!F$4,統合マスタ!$A10,0)="","",OFFSET(マスタ非採用削除!F$4,統合マスタ!$A10,0)) | T10: =IF(OFFSET(マスタ非採用削除!G$4,統合マスタ!$A10,0)="","",OFFSET(マスタ非採用削除!G$4,統合マスタ!$A10,0)) -> 12.8 | U10: =IF(OFFSET(マスタ非採用削除!H$4,統合マスタ!$A10,0)="","",OFFSET(マスタ非採用削除!H$4,統合マスタ!$A10,0)) -> ﾂﾑﾗｼﾖｳｾｲﾘﾕｳﾄｳｴｷｽｶﾘﾕｳｲﾘﾖｳﾖｳ | V10: =IF(OFFSET(マスタ非採用削除!I$4,統合マスタ!$A10,0)="","",OFFSET(マスタ非採用削除!I$4,統合マスタ!$A10,0)) -> 5 | W10: =IF(OFFSET(マスタ非採用削除!J$4,統合マスタ!$A10,0)="","",OFFSET(マスタ非採用削除!J$4,統合マスタ!$A10,0)) -> 顆粒 | X10: =IF(OFFSET(マスタ非採用削除!K$4,統合マスタ!$A10,0)="","",OFFSET(マスタ非採用削除!K$4,統合マスタ!$A10,0)) -> 0 | Y10: =IF(OFFSET(マスタ非採用削除!L$4,統合マスタ!$A10,0)="","",OFFSET(マスタ非採用削除!L$4,統合マスタ!$A10,0)) | Z10: =IF(OFFSET(マスタ非採用削除!M$4,統合マスタ!$A10,0)="","",OFFSET(マスタ非採用削除!M$4,統合マスタ!$A10,0)) -> 4 | AA10: =IF(A10="非採用","非採用",IF(A10="処置薬","処置薬","")) | AB10: =IF(A10="非採用特別","非採用特別",IF(R10=2,"臨時", IF(COUNTIF(分類!$H$8:$H$19, 統合マスタ!V10)>0, 分類!$G$7, IF(COUNTIF(分類!$K$8:$K$19, 統合マスタ!V10)>0, 分類!$J$7, IF(COUNTIF(分類!$N$8:$N$19, 統合マスタ!V10)>0, 分類!$M$7, IF(COUNTIF(分類!$Q$8:$Q$19, 統合マスタ!V10)>0, 分類!$P$7, IF(COUNTIF(分類!$T$8:$T$19, 統合マスタ!V10)>0, 分類!$S$7, "無し"))))))) -> 臨時 | AC10: =X10*100000+B10 -> 6 | AD10: {=IF(A10="非採用","非採用",OFFSET( INDIRECT("'" & AB10 & "'!A4"), MATCH(B10, INDIRECT("'" & AB10 & "'!C5:C1000"), 0), MATCH("合計", INDIRECT("'" & AB10 & "'!4:4"), 0) - 1 ))} -> 0
A11: =元データ!P8 -> 301 | B11: =B10+1 -> 7 | C11: =DBCS(元データ!A8) -> ０４３ ツムラ リツクンシトウ | D11: =元データ!B8 -> メディセオ | E11: =DBCS(元データ!C8) -> 粉 | F11: =DBCS(元データ!D8) -> ２．５ｇｘ１８９ | G11: =元データ!E8 -> ツムラ | H11: =元データ!F8 -> 18 | I11: =元データ!G8 -> 8505 | J11: =元データ!H8 -> 472.5 | K11: =元データ!I8 -> g | L11: =元データ!J8 -> 7576 | M11: =元データ!K8 -> 16.033862 | N11: =IF(OFFSET(マスタ非採用削除!A$4,統合マスタ!$A11,0)="","",OFFSET(マスタ非採用削除!A$4,統合マスタ!$A11,0)) -> ﾂﾑﾗ043 | O11: =IF(OFFSET(マスタ非採用削除!B$4,統合マスタ!$A11,0)="","",OFFSET(マスタ非採用削除!B$4,統合マスタ!$A11,0)) -> ﾂﾑﾗ043 | P11: =IF(OFFSET(マスタ非採用削除!C$4,統合マスタ!$A11,0)="","",OFFSET(マスタ非採用削除!C$4,統合マスタ!$A11,0)) -> ツムラ六君子湯エキス顆粒（医療用） | Q11: =IF(OFFSET(マスタ非採用削除!D$4,統合マスタ!$A11,0)="","",OFFSET(マスタ非採用削除!D$4,統合マスタ!$A11,0)) -> ﾘｯｸ | R11: =IF(OR(A11="非採用",A11="処置薬",A11="非採用特別"),0,IF(OFFSET(マスタ非採用削除!E$4,統合マスタ!$A11,0)="","",OFFSET(マスタ非採用削除!E$4,統合マスタ!$A11,0))) -> 2 | S11: =IF(OFFSET(マスタ非採用削除!F$4,統合マスタ!$A11,0)="","",OFFSET(マスタ非採用削除!F$4,統合マスタ!$A11,0)) | T11: =IF(OFFSET(マスタ非採用削除!G$4,統合マスタ!$A11,0)="","",OFFSET(マスタ非採用削除!G$4,統合マスタ!$A11,0)) -> 18 | U11: =IF(OFFSET(マスタ非採用削除!H$4,統合マスタ!$A11,0)="","",OFFSET(マスタ非採用削除!H$4,統合マスタ!$A11,0)) -> ﾂﾑﾗﾘｯｸﾝｼﾄｳｴｷｽｶﾘｭｳ(ｲﾘｮｳﾖｳ) | V11: =IF(OFFSET(マスタ非採用削除!I$4,統合マスタ!$A11,0)="","",OFFSET(マスタ非採用削除!I$4,統合マスタ!$A11,0)) -> 3 | W11: =IF(OFFSET(マスタ非採用削除!J$4,統合マスタ!$A11,0)="","",OFFSET(マスタ非採用削除!J$4,統合マスタ!$A11,0)) -> 散 | X11: =IF(OFFSET(マスタ非採用削除!K$4,統合マスタ!$A11,0)="","",OFFSET(マスタ非採用削除!K$4,統合マスタ!$A11,0)) -> 0 | Y11: =IF(OFFSET(マスタ非採用削除!L$4,統合マスタ!$A11,0)="","",OFFSET(マスタ非採用削除!L$4,統合マスタ!$A11,0)) | Z11: =IF(OFFSET(マスタ非採用削除!M$4,統合マスタ!$A11,0)="","",OFFSET(マスタ非採用削除!M$4,統合マスタ!$A11,0)) -> 4 | AA11: =IF(A11="非採用","非採用",IF(A11="処置薬","処置薬","")) | AB11: =IF(A11="非採用特別","非採用特別",IF(R11=2,"臨時", IF(COUNTIF(分類!$H$8:$H$19, 統合マスタ!V11)>0, 分類!$G$7, IF(COUNTIF(分類!$K$8:$K$19, 統合マスタ!V11)>0, 分類!$J$7, IF(COUNTIF(分類!$N$8:$N$19, 統合マスタ!V11)>0, 分類!$M$7, IF(COUNTIF(分類!$Q$8:$Q$19, 統合マスタ!V11)>0, 分類!$P$7, IF(COUNTIF(分類!$T$8:$T$19, 統合マスタ!V11)>0, 分類!$S$7, "無し"))))))) -> 臨時 | AC11: =X11*100000+B11 -> 7 | AD11: {=IF(A11="非採用","非採用",OFFSET( INDIRECT("'" & AB11 & "'!A4"), MATCH(B11, INDIRECT("'" & AB11 & "'!C5:C1000"), 0), MATCH("合計", INDIRECT("'" & AB11 & "'!4:4"), 0) - 1 ))} -> 0
A12: =元データ!P9 -> 非採用 | B12: =B11+1 -> 8 | C12: =DBCS(元データ!A9) -> ０４８ ツムラ ジュウゼンタイホトウ | D12: =元データ!B9 | E12: =DBCS(元データ!C9) -> 粉 | F12: =DBCS(元データ!D9) -> ２．５ｇｘ１８９包 | G12: =元データ!E9 -> ツムラ | H12: =元データ!F9 -> 18.4 | I12: =元データ!G9 -> 8694 | J12: =元データ!H9 -> 472.5 | K12: =元データ!I9 -> g | L12: =元データ!J9 -> 7750 | M12: =元データ!K9 -> 16.402116 | N12: =IF(OFFSET(マスタ非採用削除!A$4,統合マスタ!$A12,0)="","",OFFSET(マスタ非採用削除!A$4,統合マスタ!$A12,0)) -> #VALUE! | O12: =IF(OFFSET(マスタ非採用削除!B$4,統合マスタ!$A12,0)="","",OFFSET(マスタ非採用削除!B$4,統合マスタ!$A12,0)) -> #VALUE! | P12: =IF(OFFSET(マスタ非採用削除!C$4,統合マスタ!$A12,0)="","",OFFSET(マスタ非採用削除!C$4,統合マスタ!$A12,0)) -> #VALUE! | Q12: =IF(OFFSET(マスタ非採用削除!D$4,統合マスタ!$A12,0)="","",OFFSET(マスタ非採用削除!D$4,統合マスタ!$A12,0)) -> #VALUE! | R12: =IF(OR(A12="非採用",A12="処置薬",A12="非採用特別"),0,IF(OFFSET(マスタ非採用削除!E$4,統合マスタ!$A12,0)="","",OFFSET(マスタ非採用削除!E$4,統合マスタ!$A12,0))) -> 0 | S12: =IF(OFFSET(マスタ非採用削除!F$4,統合マスタ!$A12,0)="","",OFFSET(マスタ非採用削除!F$4,統合マスタ!$A12,0)) -> #VALUE! | T12: =IF(OFFSET(マスタ非採用削除!G$4,統合マスタ!$A12,0)="","",OFFSET(マスタ非採用削除!G$4,統合マスタ!$A12,0)) -> #VALUE! | U12: =IF(OFFSET(マスタ非採用削除!H$4,統合マスタ!$A12,0)="","",OFFSET(マスタ非採用削除!H$4,統合マスタ!$A12,0)) -> #VALUE! | V12: =IF(OFFSET(マスタ非採用削除!I$4,統合マスタ!$A12,0)="","",OFFSET(マスタ非採用削除!I$4,統合マスタ!$A12,0)) -> #VALUE! | W12: =IF(OFFSET(マスタ非採用削除!J$4,統合マスタ!$A12,0)="","",OFFSET(マスタ非採用削除!J$4,統合マスタ!$A12,0)) -> #VALUE! | X12: =IF(OFFSET(マスタ非採用削除!K$4,統合マスタ!$A12,0)="","",OFFSET(マスタ非採用削除!K$4,統合マスタ!$A12,0)) -> #VALUE! | Y12: =IF(OFFSET(マスタ非採用削除!L$4,統合マスタ!$A12,0)="","",OFFSET(マスタ非採用削除!L$4,統合マスタ!$A12,0)) -> #VALUE! | Z12: =IF(OFFSET(マスタ非採用削除!M$4,統合マスタ!$A12,0)="","",OFFSET(マスタ非採用削除!M$4,統合マスタ!$A12,0)) -> #VALUE! | AA12: =IF(A12="非採用","非採用",IF(A12="処置薬","処置薬","")) -> 非採用 | AB12: =IF(A12="非採用特別","非採用特別",IF(R12=2,"臨時", IF(COUNTIF(分類!$H$8:$H$19, 統合マスタ!V12)>0, 分類!$G$7, IF(COUNTIF(分類!$K$8:$K$19, 統合マスタ!V12)>0, 分類!$J$7, IF(COUNTIF(分類!$N$8:$N$19, 統合マスタ!V12)>0, 分類!$M$7, IF(COUNTIF(分類!$Q$8:$Q$19, 統合マスタ!V12)>0, 分類!$P$7, IF(COUNTIF(分類!$T$8:$T$19, 統合マスタ!V12)>0, 分類!$S$7, "無し"))))))) -> 無し | AC12: =X12*100000+B12 -> #VALUE! | AD12: {=IF(A12="非採用","非採用",OFFSET( INDIRECT("'" & AB12 & "'!A4"), MATCH(B12, INDIRECT("'" & AB12 & "'!C5:C1000"), 0), MATCH("合計", INDIRECT("'" & AB12 & "'!4:4"), 0) - 1 ))} -> 非採用
A13: =元データ!P10 -> 302 | B13: =B12+1 -> 9 | C13: =DBCS(元データ!A10) -> ０５４ ツムラ ヨクカンサン | D13: =元データ!B10 -> メディセオ | E13: =DBCS(元データ!C10) -> 粉 | F13: =DBCS(元データ!D10) -> ２．５ｇＸ１８９ | G13: =元データ!E10 -> ツムラ | H13: =元データ!F10 -> 16.1 | I13: =元データ!G10 -> 7607.25 | J13: =元データ!H10 -> 472.5 | K13: =元データ!I10 -> g | L13: =元データ!J10 -> 6849 | M13: =元データ!K10 -> 14.495238 | N13: =IF(OFFSET(マスタ非採用削除!A$4,統合マスタ!$A13,0)="","",OFFSET(マスタ非採用削除!A$4,統合マスタ!$A13,0)) -> ﾂﾑﾗ054 | O13: =IF(OFFSET(マスタ非採用削除!B$4,統合マスタ!$A13,0)="","",OFFSET(マスタ非採用削除!B$4,統合マスタ!$A13,0)) -> ﾂﾑﾗ054 | P13: =IF(OFFSET(マスタ非採用削除!C$4,統合マスタ!$A13,0)="","",OFFSET(マスタ非採用削除!C$4,統合マスタ!$A13,0)) -> ツムラ抑肝散エキス顆粒（医療用） | Q13: =IF(OFFSET(マスタ非採用削除!D$4,統合マスタ!$A13,0)="","",OFFSET(マスタ非採用削除!D$4,統合マスタ!$A13,0)) -> ﾖｸｶ | R13: =IF(OR(A13="非採用",A13="処置薬",A13="非採用特別"),0,IF(OFFSET(マスタ非採用削除!E$4,統合マスタ!$A13,0)="","",OFFSET(マスタ非採用削除!E$4,統合マスタ!$A13,0))) -> 1 | S13: =IF(OFFSET(マスタ非採用削除!F$4,統合マスタ!$A13,0)="","",OFFSET(マスタ非採用削除!F$4,統合マスタ!$A13,0)) | T13: =IF(OFFSET(マスタ非採用削除!G$4,統合マスタ!$A13,0)="","",OFFSET(マスタ非採用削除!G$4,統合マスタ!$A13,0)) -> 16.1 | U13: =IF(OFFSET(マスタ非採用削除!H$4,統合マスタ!$A13,0)="","",OFFSET(マスタ非採用削除!H$4,統合マスタ!$A13,0)) -> ﾂﾑﾗﾖｸｶﾝｻﾝｴｷｽｶﾘｭｳ(ｲﾘｮｳﾖｳ) | V13: =IF(OFFSET(マスタ非採用削除!I$4,統合マスタ!$A13,0)="","",OFFSET(マスタ非採用削除!I$4,統合マスタ!$A13,0)) -> 3 | W13: =IF(OFFSET(マスタ非採用削除!J$4,統合マスタ!$A13,0)="","",OFFSET(マスタ非採用削除!J$4,統合マスタ!$A13,0)) -> 散 | X13: =IF(OFFSET(マスタ非採用削除!K$4,統合マスタ!$A13,0)="","",OFFSET(マスタ非採用削除!K$4,統合マスタ!$A13,0)) -> 0 | Y13: =IF(OFFSET(マスタ非採用削除!L$4,統合マスタ!$A13,0)="","",OFFSET(マスタ非採用削除!L$4,統合マスタ!$A13,0)) | Z13: =IF(OFFSET(マスタ非採用削除!M$4,統合マスタ!$A13,0)="","",OFFSET(マスタ非採用削除!M$4,統合マスタ!$A13,0)) -> 4 | AA13: =IF(A13="非採用","非採用",IF(A13="処置薬","処置薬","")) | AB13: =IF(A13="非採用特別","非採用特別",IF(R13=2,"臨時", IF(COUNTIF(分類!$H$8:$H$19, 統合マスタ!V13)>0, 分類!$G$7, IF(COUNTIF(分類!$K$8:$K$19, 統合マスタ!V13)>0, 分類!$J$7, IF(COUNTIF(分類!$N$8:$N$19, 統合マスタ!V13)>0, 分類!$M$7, IF(COUNTIF(分類!$Q$8:$Q$19, 統合マスタ!V13)>0, 分類!$P$7, IF(COUNTIF(分類!$T$8:$T$19, 統合マスタ!V13)>0, 分類!$S$7, "無し"))))))) -> 散剤 | AC13: =X13*100000+B13 -> 9 | AD13: {=IF(A13="非採用","非採用",OFFSET( INDIRECT("'" & AB13 & "'!A4"), MATCH(B13, INDIRECT("'" & AB13 & "'!C5:C1000"), 0), MATCH("合計", INDIRECT("'" & AB13 & "'!4:4"), 0) - 1 ))} -> 0
A14: =元データ!P11 -> 303 | B14: =B13+1 -> 10 | C14: =DBCS(元データ!A11) -> ０６２ ツムラ ボウフウツウシヨウサン | D14: =元データ!B11 -> メディセオ | E14: =DBCS(元データ!C11) -> 粉 | F14: =DBCS(元データ!D11) -> ２．５ｇｘ１８９ | G14: =元データ!E11 -> ツムラ | H14: =元データ!F11 -> 13.8 | I14: =元データ!G11 -> 6520.5 | J14: =元データ!H11 -> 472.5 | K14: =元データ!I11 -> g | L14: =元データ!J11 -> 5871 | M14: =元データ!K11 -> 12.425397 | N14: =IF(OFFSET(マスタ非採用削除!A$4,統合マスタ!$A14,0)="","",OFFSET(マスタ非採用削除!A$4,統合マスタ!$A14,0)) -> ﾂﾑﾗ062 | O14: =IF(OFFSET(マスタ非採用削除!B$4,統合マスタ!$A14,0)="","",OFFSET(マスタ非採用削除!B$4,統合マスタ!$A14,0)) -> ﾂﾑﾗ062 | P14: =IF(OFFSET(マスタ非採用削除!C$4,統合マスタ!$A14,0)="","",OFFSET(マスタ非採用削除!C$4,統合マスタ!$A14,0)) -> ツムラ防風通聖散エキス顆粒（医療用） | Q14: =IF(OFFSET(マスタ非採用削除!D$4,統合マスタ!$A14,0)="","",OFFSET(マスタ非採用削除!D$4,統合マスタ!$A14,0)) -> ﾎﾞｳﾌｳ | R14: =IF(OR(A14="非採用",A14="処置薬",A14="非採用特別"),0,IF(OFFSET(マスタ非採用削除!E$4,統合マスタ!$A14,0)="","",OFFSET(マスタ非採用削除!E$4,統合マスタ!$A14,0))) -> 1 | S14: =IF(OFFSET(マスタ非採用削除!F$4,統合マスタ!$A14,0)="","",OFFSET(マスタ非採用削除!F$4,統合マスタ!$A14,0)) | T14: =IF(OFFSET(マスタ非採用削除!G$4,統合マスタ!$A14,0)="","",OFFSET(マスタ非採用削除!G$4,統合マスタ!$A14,0)) -> 13.8 | U14: =IF(OFFSET(マスタ非採用削除!H$4,統合マスタ!$A14,0)="","",OFFSET(マスタ非採用削除!H$4,統合マスタ!$A14,0)) -> ﾂﾑﾗﾎﾞｳﾌｳﾂｳｼｮｳｻﾝｴｷｽｶﾘｭｳ(ｲﾘｮｳﾖｳ) | V14: =IF(OFFSET(マスタ非採用削除!I$4,統合マスタ!$A14,0)="","",OFFSET(マスタ非採用削除!I$4,統合マスタ!$A14,0)) -> 3 | W14: =IF(OFFSET(マスタ非採用削除!J$4,統合マスタ!$A14,0)="","",OFFSET(マスタ非採用削除!J$4,統合マスタ!$A14,0)) -> 散 | X14: =IF(OFFSET(マスタ非採用削除!K$4,統合マスタ!$A14,0)="","",OFFSET(マスタ非採用削除!K$4,統合マスタ!$A14,0)) -> 0 | Y14: =IF(OFFSET(マスタ非採用削除!L$4,統合マスタ!$A14,0)="","",OFFSET(マスタ非採用削除!L$4,統合マスタ!$A14,0)) | Z14: =IF(OFFSET(マスタ非採用削除!M$4,統合マスタ!$A14,0)="","",OFFSET(マスタ非採用削除!M$4,統合マスタ!$A14,0)) -> 4 | AA14: =IF(A14="非採用","非採用",IF(A14="処置薬","処置薬","")) | AB14: =IF(A14="非採用特別","非採用特別",IF(R14=2,"臨時", IF(COUNTIF(分類!$H$8:$H$19, 統合マスタ!V14)>0, 分類!$G$7, IF(COUNTIF(分類!$K$8:$K$19, 統合マスタ!V14)>0, 分類!$J$7, IF(COUNTIF(分類!$N$8:$N$19, 統合マスタ!V14)>0, 分類!$M$7, IF(COUNTIF(分類!$Q$8:$Q$19, 統合マスタ!V14)>0, 分類!$P$7, IF(COUNTIF(分類!$T$8:$T$19, 統合マスタ!V14)>0, 分類!$S$7, "無し"))))))) -> 散剤 | AC14: =X14*100000+B14 -> 10 | AD14: {=IF(A14="非採用","非採用",OFFSET( INDIRECT("'" & AB14 & "'!A4"), MATCH(B14, INDIRECT("'" & AB14 & "'!C5:C1000"), 0), MATCH("合計", INDIRECT("'" & AB14 & "'!4:4"), 0) - 1 ))} -> 0
A15: =元データ!P12 -> 304 | B15: =B14+1 -> 11 | C15: =DBCS(元データ!A12) -> ０６８ ツムラ シャクヤクカンゾウトウ | D15: =元データ!B12 -> メディセオ | E15: =DBCS(元データ!C12) -> 粉 | F15: =DBCS(元データ!D12) -> ２．５ｇｘ４２ | G15: =元データ!E12 -> ツムラ | H15: =元データ!F12 -> 10.4 | I15: =元データ!G12 -> 1092 | J15: =元データ!H12 -> 105 | K15: =元データ!I12 -> g | L15: =元データ!J12 -> 992 | M15: =元データ!K12 -> 9.447619 | N15: =IF(OFFSET(マスタ非採用削除!A$4,統合マスタ!$A15,0)="","",OFFSET(マスタ非採用削除!A$4,統合マスタ!$A15,0)) -> ﾂﾑﾗ068 | O15: =IF(OFFSET(マスタ非採用削除!B$4,統合マスタ!$A15,0)="","",OFFSET(マスタ非採用削除!B$4,統合マスタ!$A15,0)) -> ﾂﾑﾗ068 | P15: =IF(OFFSET(マスタ非採用削除!C$4,統合マスタ!$A15,0)="","",OFFSET(マスタ非採用削除!C$4,統合マスタ!$A15,0)) -> ツムラ芍薬甘草湯エキス顆粒（医療用） | Q15: =IF(OFFSET(マスタ非採用削除!D$4,統合マスタ!$A15,0)="","",OFFSET(マスタ非採用削除!D$4,統合マスタ!$A15,0)) -> ｼｬｸ | R15: =IF(OR(A15="非採用",A15="処置薬",A15="非採用特別"),0,IF(OFFSET(マスタ非採用削除!E$4,統合マスタ!$A15,0)="","",OFFSET(マスタ非採用削除!E$4,統合マスタ!$A15,0))) -> 1 | S15: =IF(OFFSET(マスタ非採用削除!F$4,統合マスタ!$A15,0)="","",OFFSET(マスタ非採用削除!F$4,統合マスタ!$A15,0)) | T15: =IF(OFFSET(マスタ非採用削除!G$4,統合マスタ!$A15,0)="","",OFFSET(マスタ非採用削除!G$4,統合マスタ!$A15,0)) -> 10.4 | U15: =IF(OFFSET(マスタ非採用削除!H$4,統合マスタ!$A15,0)="","",OFFSET(マスタ非採用削除!H$4,統合マスタ!$A15,0)) -> ﾂﾑﾗｼｬｸﾔｸｶﾝｿﾞｳﾄｳｴｷｽｶﾘｭｳ(ｲﾘｮｳﾖｳ) | V15: =IF(OFFSET(マスタ非採用削除!I$4,統合マスタ!$A15,0)="","",OFFSET(マスタ非採用削除!I$4,統合マスタ!$A15,0)) -> 3 | W15: =IF(OFFSET(マスタ非採用削除!J$4,統合マスタ!$A15,0)="","",OFFSET(マスタ非採用削除!J$4,統合マスタ!$A15,0)) -> 散 | X15: =IF(OFFSET(マスタ非採用削除!K$4,統合マスタ!$A15,0)="","",OFFSET(マスタ非採用削除!K$4,統合マスタ!$A15,0)) -> 0 | Y15: =IF(OFFSET(マスタ非採用削除!L$4,統合マスタ!$A15,0)="","",OFFSET(マスタ非採用削除!L$4,統合マスタ!$A15,0)) | Z15: =IF(OFFSET(マスタ非採用削除!M$4,統合マスタ!$A15,0)="","",OFFSET(マスタ非採用削除!M$4,統合マスタ!$A15,0)) -> 4 | AA15: =IF(A15="非採用","非採用",IF(A15="処置薬","処置薬","")) | AB15: =IF(A15="非採用特別","非採用特別",IF(R15=2,"臨時", IF(COUNTIF(分類!$H$8:$H$19, 統合マスタ!V15)>0, 分類!$G$7, IF(COUNTIF(分類!$K$8:$K$19, 統合マスタ!V15)>0, 分類!$J$7, IF(COUNTIF(分類!$N$8:$N$19, 統合マスタ!V15)>0, 分類!$M$7, IF(COUNTIF(分類!$Q$8:$Q$19, 統合マスタ!V15)>0, 分類!$P$7, IF(COUNTIF(分類!$T$8:$T$19, 統合マスタ!V15)>0, 分類!$S$7, "無し"))))))) -> 散剤 | AC15: =X15*100000+B15 -> 11 | AD15: {=IF(A15="非採用","非採用",OFFSET( INDIRECT("'" & AB15 & "'!A4"), MATCH(B15, INDIRECT("'" & AB15 & "'!C5:C1000"), 0), MATCH("合計", INDIRECT("'" & AB15 & "'!4:4"), 0) - 1 ))} -> 0
A16: =元データ!P13 -> 305 | B16: =B15+1 -> 12 | C16: =DBCS(元データ!A13) -> ０８３ ツムラ ヨクカンサンカチンピハンゲ | D16: =元データ!B13 -> メディセオ | E16: =DBCS(元データ!C13) -> 粉 | F16: =DBCS(元データ!D13) -> ２．５ｇｘ１８９ | G16: =元データ!E13 -> ツムラ | H16: =元データ!F13 -> 14.4 | I16: =元データ!G13 -> 6804 | J16: =元データ!H13 -> 472.5 | K16: =元データ!I13 -> g | L16: =元データ!J13 -> 6065 | M16: =元データ!K13 -> 12.835979 | N16: =IF(OFFSET(マスタ非採用削除!A$4,統合マスタ!$A16,0)="","",OFFSET(マスタ非採用削除!A$4,統合マスタ!$A16,0)) -> ﾂﾑﾗ083 | O16: =IF(OFFSET(マスタ非採用削除!B$4,統合マスタ!$A16,0)="","",OFFSET(マスタ非採用削除!B$4,統合マスタ!$A16,0)) -> ﾂﾑﾗ083 | P16: =IF(OFFSET(マスタ非採用削除!C$4,統合マスタ!$A16,0)="","",OFFSET(マスタ非採用削除!C$4,統合マスタ!$A16,0)) -> ツムラ抑肝散加陳皮半夏エキス顆粒（医療用） | Q16: =IF(OFFSET(マスタ非採用削除!D$4,統合マスタ!$A16,0)="","",OFFSET(マスタ非採用削除!D$4,統合マスタ!$A16,0)) -> ﾖｸｶﾁﾝ | R16: =IF(OR(A16="非採用",A16="処置薬",A16="非採用特別"),0,IF(OFFSET(マスタ非採用削除!E$4,統合マスタ!$A16,0)="","",OFFSET(マスタ非採用削除!E$4,統合マスタ!$A16,0))) -> 1 | S16: =IF(OFFSET(マスタ非採用削除!F$4,統合マスタ!$A16,0)="","",OFFSET(マスタ非採用削除!F$4,統合マスタ!$A16,0)) | T16: =IF(OFFSET(マスタ非採用削除!G$4,統合マスタ!$A16,0)="","",OFFSET(マスタ非採用削除!G$4,統合マスタ!$A16,0)) -> 14.4 | U16: =IF(OFFSET(マスタ非採用削除!H$4,統合マスタ!$A16,0)="","",OFFSET(マスタ非採用削除!H$4,統合マスタ!$A16,0)) -> ﾂﾑﾗﾖｸｶﾝｻﾝｶﾁﾝﾋﾟﾊﾝｹﾞｴｷｽｶﾘｭｳ(ｲﾘｮｳﾖｳ) | V16: =IF(OFFSET(マスタ非採用削除!I$4,統合マスタ!$A16,0)="","",OFFSET(マスタ非採用削除!I$4,統合マスタ!$A16,0)) -> 3 | W16: =IF(OFFSET(マスタ非採用削除!J$4,統合マスタ!$A16,0)="","",OFFSET(マスタ非採用削除!J$4,統合マスタ!$A16,0)) -> 散 | X16: =IF(OFFSET(マスタ非採用削除!K$4,統合マスタ!$A16,0)="","",OFFSET(マスタ非採用削除!K$4,統合マスタ!$A16,0)) -> 0 | Y16: =IF(OFFSET(マスタ非採用削除!L$4,統合マスタ!$A16,0)="","",OFFSET(マスタ非採用削除!L$4,統合マスタ!$A16,0)) | Z16: =IF(OFFSET(マスタ非採用削除!M$4,統合マスタ!$A16,0)="","",OFFSET(マスタ非採用削除!M$4,統合マスタ!$A16,0)) -> 4 | AA16: =IF(A16="非採用","非採用",IF(A16="処置薬","処置薬","")) | AB16: =IF(A16="非採用特別","非採用特別",IF(R16=2,"臨時", IF(COUNTIF(分類!$H$8:$H$19, 統合マスタ!V16)>0, 分類!$G$7, IF(COUNTIF(分類!$K$8:$K$19, 統合マスタ!V16)>0, 分類!$J$7, IF(COUNTIF(分類!$N$8:$N$19, 統合マスタ!V16)>0, 分類!$M$7, IF(COUNTIF(分類!$Q$8:$Q$19, 統合マスタ!V16)>0, 分類!$P$7, IF(COUNTIF(分類!$T$8:$T$19, 統合マスタ!V16)>0, 分類!$S$7, "無し"))))))) -> 散剤 | AC16: =X16*100000+B16 -> 12 | AD16: {=IF(A16="非採用","非採用",OFFSET( INDIRECT("'" & AB16 & "'!A4"), MATCH(B16, INDIRECT("'" & AB16 & "'!C5:C1000"), 0), MATCH("合計", INDIRECT("'" & AB16 & "'!4:4"), 0) - 1 ))} -> 0
A17: =元データ!P14 -> 306 | B17: =B16+1 -> 13 | C17: =DBCS(元データ!A14) -> １００ ツムラ ダイケンチユウトウ | D17: =元データ!B14 -> メディセオ | E17: =DBCS(元データ!C14) -> 粉 | F17: =DBCS(元データ!D14) -> ２．５ｇＸ１８９ | G17: =元データ!E14 -> ツムラ | H17: =元データ!F14 -> 13.7 | I17: =元データ!G14 -> 6473.25 | J17: =元データ!H14 -> 472.5 | K17: =元データ!I14 -> g | L17: =元データ!J14 -> 5828 | M17: =元データ!K14 -> 12.334392 | N17: =IF(OFFSET(マスタ非採用削除!A$4,統合マスタ!$A17,0)="","",OFFSET(マスタ非採用削除!A$4,統合マスタ!$A17,0)) -> ﾂﾑﾗ100 | O17: =IF(OFFSET(マスタ非採用削除!B$4,統合マスタ!$A17,0)="","",OFFSET(マスタ非採用削除!B$4,統合マスタ!$A17,0)) -> ﾂﾑﾗ100 | P17: =IF(OFFSET(マスタ非採用削除!C$4,統合マスタ!$A17,0)="","",OFFSET(マスタ非採用削除!C$4,統合マスタ!$A17,0)) -> ツムラ大建中湯エキス顆粒（医療用） | Q17: =IF(OFFSET(マスタ非採用削除!D$4,統合マスタ!$A17,0)="","",OFFSET(マスタ非採用削除!D$4,統合マスタ!$A17,0)) -> ﾀﾞｲｹﾝﾁ | R17: =IF(OR(A17="非採用",A17="処置薬",A17="非採用特別"),0,IF(OFFSET(マスタ非採用削除!E$4,統合マスタ!$A17,0)="","",OFFSET(マスタ非採用削除!E$4,統合マスタ!$A17,0))) -> 1 | S17: =IF(OFFSET(マスタ非採用削除!F$4,統合マスタ!$A17,0)="","",OFFSET(マスタ非採用削除!F$4,統合マスタ!$A17,0)) | T17: =IF(OFFSET(マスタ非採用削除!G$4,統合マスタ!$A17,0)="","",OFFSET(マスタ非採用削除!G$4,統合マスタ!$A17,0)) -> 13.7 | U17: =IF(OFFSET(マスタ非採用削除!H$4,統合マスタ!$A17,0)="","",OFFSET(マスタ非採用削除!H$4,統合マスタ!$A17,0)) -> ﾂﾑﾗﾀﾞｲｹﾝﾁｭｳﾄｳｴｷｽｶﾘｭｳ(ｲﾘｮｳﾖｳ) | V17: =IF(OFFSET(マスタ非採用削除!I$4,統合マスタ!$A17,0)="","",OFFSET(マスタ非採用削除!I$4,統合マスタ!$A17,0)) -> 3 | W17: =IF(OFFSET(マスタ非採用削除!J$4,統合マスタ!$A17,0)="","",OFFSET(マスタ非採用削除!J$4,統合マスタ!$A17,0)) -> 散 | X17: =IF(OFFSET(マスタ非採用削除!K$4,統合マスタ!$A17,0)="","",OFFSET(マスタ非採用削除!K$4,統合マスタ!$A17,0)) -> 0 | Y17: =IF(OFFSET(マスタ非採用削除!L$4,統合マスタ!$A17,0)="","",OFFSET(マスタ非採用削除!L$4,統合マスタ!$A17,0)) | Z17: =IF(OFFSET(マスタ非採用削除!M$4,統合マスタ!$A17,0)="","",OFFSET(マスタ非採用削除!M$4,統合マスタ!$A17,0)) -> 4 | AA17: =IF(A17="非採用","非採用",IF(A17="処置薬","処置薬","")) | AB17: =IF(A17="非採用特別","非採用特別",IF(R17=2,"臨時", IF(COUNTIF(分類!$H$8:$H$19, 統合マスタ!V17)>0, 分類!$G$7, IF(COUNTIF(分類!$K$8:$K$19, 統合マスタ!V17)>0, 分類!$J$7, IF(COUNTIF(分類!$N$8:$N$19, 統合マスタ!V17)>0, 分類!$M$7, IF(COUNTIF(分類!$Q$8:$Q$19, 統合マスタ!V17)>0, 分類!$P$7, IF(COUNTIF(分類!$T$8:$T$19, 統合マスタ!V17)>0, 分類!$S$7, "無し"))))))) -> 散剤 | AC17: =X17*100000+B17 -> 13 | AD17: {=IF(A17="非採用","非採用",OFFSET( INDIRECT("'" & AB17 & "'!A4"), MATCH(B17, INDIRECT("'" & AB17 & "'!C5:C1000"), 0), MATCH("合計", INDIRECT("'" & AB17 & "'!4:4"), 0) - 1 ))} -> 0
... A837: =元データ!P834 -> 685 | B837: =B836+1 -> 833 | C837: =DBCS(元データ!A834) -> 白色ワセリン「ケンエー」 | D837: =元データ!B834 -> アルフレッサ | E837: =DBCS(元データ!C834) | F837: =DBCS(元データ!D834) -> ５００ｇ | G837: =元データ!E834 -> ケンエー | H837: =元データ!F834 -> 24.3 | I837: =元データ!G834 -> 1215 | J837: =元データ!H834 -> 50 | K837: =元データ!I834 -> 10ｇ | L837: =元データ!J834 -> 1082 | M837: =元データ!K834 -> 21.64 | N837: =IF(OFFSET(マスタ非採用削除!A$4,統合マスタ!$A837,0)="","",OFFSET(マスタ非採用削除!A$4,統合マスタ!$A837,0)) -> ﾊｸｼ001 | O837: =IF(OFFSET(マスタ非採用削除!B$4,統合マスタ!$A837,0)="","",OFFSET(マスタ非採用削除!B$4,統合マスタ!$A837,0)) -> ﾊｸｼ001 | P837: =IF(OFFSET(マスタ非採用削除!C$4,統合マスタ!$A837,0)="","",OFFSET(マスタ非採用削除!C$4,統合マスタ!$A837,0)) -> 白色ワセリン | Q837: =IF(OFFSET(マスタ非採用削除!D$4,統合マスタ!$A837,0)="","",OFFSET(マスタ非採用削除!D$4,統合マスタ!$A837,0)) -> ﾜｾﾘﾝ | R837: =IF(OR(A837="非採用",A837="処置薬",A837="非採用特別"),0,IF(OFFSET(マスタ非採用削除!E$4,統合マスタ!$A837,0)="","",OFFSET(マスタ非採用削除!E$4,統合マスタ!$A837,0))) -> 1 | S837: =IF(OFFSET(マスタ非採用削除!F$4,統合マスタ!$A837,0)="","",OFFSET(マスタ非採用削除!F$4,統合マスタ!$A837,0)) | T837: =IF(OFFSET(マスタ非採用削除!G$4,統合マスタ!$A837,0)="","",OFFSET(マスタ非採用削除!G$4,統合マスタ!$A837,0)) -> 2.09 | U837: =IF(OFFSET(マスタ非採用削除!H$4,統合マスタ!$A837,0)="","",OFFSET(マスタ非採用削除!H$4,統合マスタ!$A837,0)) -> ﾊｸｼｮｸﾜｾﾘﾝ | V837: =IF(OFFSET(マスタ非採用削除!I$4,統合マスタ!$A837,0)="","",OFFSET(マスタ非採用削除!I$4,統合マスタ!$A837,0)) -> 15 | W837: =IF(OFFSET(マスタ非採用削除!J$4,統合マスタ!$A837,0)="","",OFFSET(マスタ非採用削除!J$4,統合マスタ!$A837,0)) -> その他 | X837: =IF(OFFSET(マスタ非採用削除!K$4,統合マスタ!$A837,0)="","",OFFSET(マスタ非採用削除!K$4,統合マスタ!$A837,0)) -> 0 | Y837: =IF(OFFSET(マスタ非採用削除!L$4,統合マスタ!$A837,0)="","",OFFSET(マスタ非採用削除!L$4,統合マスタ!$A837,0)) | Z837: =IF(OFFSET(マスタ非採用削除!M$4,統合マスタ!$A837,0)="","",OFFSET(マスタ非採用削除!M$4,統合マスタ!$A837,0)) -> 7 | AA837: =IF(A837="非採用","非採用",IF(A837="処置薬","処置薬","")) | AB837: =IF(A837="非採用特別","非採用特別",IF(R837=2,"臨時", IF(COUNTIF(分類!$H$8:$H$19, 統合マスタ!V837)>0, 分類!$G$7, IF(COUNTIF(分類!$K$8:$K$19, 統合マスタ!V837)>0, 分類!$J$7, IF(COUNTIF(分類!$N$8:$N$19, 統合マスタ!V837)>0, 分類!$M$7, IF(COUNTIF(分類!$Q$8:$Q$19, 統合マスタ!V837)>0, 分類!$P$7, IF(COUNTIF(分類!$T$8:$T$19, 統合マスタ!V837)>0, 分類!$S$7, "無し"))))))) -> 外用 | AC837: =X837*100000+B837 -> 833 | AD837: {=IF(A837="非採用","非採用",OFFSET( INDIRECT("'" & AB837 & "'!A4"), MATCH(B837, INDIRECT("'" & AB837 & "'!C5:C1000"), 0), MATCH("合計", INDIRECT("'" & AB837 & "'!4:4"), 0) - 1 ))} -> 0

Sheet 臨時
B2: {=RIGHT(CELL("filename",A1),LEN(CELL("filename",A1))-FIND("]",CELL("filename",A1)))} -> 臨時
A4: ソートキー | B4: No | C4: マスタNo | D4: 薬品名 | E4: 毒劇区分 | F4: 棚番 | G4: 包装形態 | H4: 容量 | I4: 場所 | J4: 数量 | K4: 数える単位 | L4: 係数 | M4: 合計 | N4: 薬価単位
A5: {=IFERROR(SMALL(IF(統合マスタ!$R$5:$R$1500=2,統合マスタ!$AC$5:$AC$1500),ROW(A1)),"")} -> 1 | B5: 1 | C5: =IF($A5="","",OFFSET(統合マスタ!$B$4,MATCH($A5,統合マスタ!$AC$5:$AC$1500,0),0)) -> 1 | D5: =IF($A5="","",OFFSET(統合マスタ!$C$4,MATCH($A5,統合マスタ!$AC$5:$AC$1500,0),0)) -> ００７ ツムラ ハチミジオウガン | E5: =IF($A5="","",OFFSET(統合マスタ!$X$4,MATCH($A5,統合マスタ!$AC$5:$AC$1500,0),0)) -> 0 | F5: =IF($A5="","",OFFSET(統合マスタ!$Z$4,MATCH($A5,統合マスタ!$AC$5:$AC$1500,0),0)) -> 4 | G5: =IF($A5="","",OFFSET(統合マスタ!$E$4,MATCH($A5,統合マスタ!$AC$5:$AC$1500,0),0)) -> 粉 | H5: =IF($A5="","",OFFSET(統合マスタ!$F$4,MATCH($A5,統合マスタ!$AC$5:$AC$1500,0),0)) -> ２．５ｇｘ１８９ | I5: =IF(F5="","",OFFSET(分類!$B$29,MATCH(F5,分類!$A$30:$A$46,0),0)) -> 漢方薬 | L5: =IF(G5="粉",VALUE(SUBSTITUTE(SUBSTITUTE(LEFT(H5, FIND("ｇ", H5) - 1), "．", "."), " ", "")),"") -> 2.5 | M5: =IF(L5="",J5,J5*L5) -> 0 | N5: =IF($A5="","",OFFSET(統合マスタ!$K$4,MATCH($A5,統合マスタ!$AC$5:$AC$1500,0),0)) -> ｇ
A6: {=IFERROR(SMALL(IF(統合マスタ!$R$5:$R$1500=2,統合マスタ!$AC$5:$AC$1500),ROW(A2)),"")} -> 2 | B6: =B5+1 -> 2 | C6: =IF(A6="","",OFFSET(統合マスタ!$B$4,MATCH(A6,統合マスタ!$AC$5:$AC$1500,0),0)) -> 2 | D6: =IF($A6="","",OFFSET(統合マスタ!$C$4,MATCH($A6,統合マスタ!$AC$5:$AC$1500,0),0)) -> ００７ ツムラ ハチミジオウガン | E6: =IF($A6="","",OFFSET(統合マスタ!$X$4,MATCH($A6,統合マスタ!$AC$5:$AC$1500,0),0)) -> 0 | F6: =IF($A6="","",OFFSET(統合マスタ!$Z$4,MATCH($A6,統合マスタ!$AC$5:$AC$1500,0),0)) -> 4 | G6: =IF($A6="","",OFFSET(統合マスタ!$E$4,MATCH($A6,統合マスタ!$AC$5:$AC$1500,0),0)) -> 粉 | H6: =IF($A6="","",OFFSET(統合マスタ!$F$4,MATCH($A6,統合マスタ!$AC$5:$AC$1500,0),0)) -> ２．５ｇｘ４２ | I6: =IF(F6="","",OFFSET(分類!$B$29,MATCH(F6,分類!$A$30:$A$46,0),0)) -> 漢方薬 | L6: =IF(G6="粉",VALUE(SUBSTITUTE(SUBSTITUTE(LEFT(H6, FIND("ｇ", H6) - 1), "．", "."), " ", "")),"") -> 2.5 | M6: =IF(L6="",J6,J6*L6) -> 0 | N6: =IF($A6="","",OFFSET(統合マスタ!$K$4,MATCH($A6,統合マスタ!$AC$5:$AC$1500,0),0)) -> ｇ
A7: {=IFERROR(SMALL(IF(統合マスタ!$R$5:$R$1500=2,統合マスタ!$AC$5:$AC$1500),ROW(A3)),"")} -> 3 | B7: =B6+1 -> 3 | C7: =IF(A7="","",OFFSET(統合マスタ!$B$4,MATCH(A7,統合マスタ!$AC$5:$AC$1500,0),0)) -> 3 | D7: =IF($A7="","",OFFSET(統合マスタ!$C$4,MATCH($A7,統合マスタ!$AC$5:$AC$1500,0),0)) -> ０１２ ツムラ サイコカリュウコツボレイトウ | E7: =IF($A7="","",OFFSET(統合マスタ!$X$4,MATCH($A7,統合マスタ!$AC$5:$AC$1500,0),0)) -> 0 | F7: =IF($A7="","",OFFSET(統合マスタ!$Z$4,MATCH($A7,統合マスタ!$AC$5:$AC$1500,0),0)) -> 4 | G7: =IF($A7="","",OFFSET(統合マスタ!$E$4,MATCH($A7,統合マスタ!$AC$5:$AC$1500,0),0)) -> 粉 | H7: =IF($A7="","",OFFSET(統合マスタ!$F$4,MATCH($A7,統合マスタ!$AC$5:$AC$1500,0),0)) -> ２．５ｇｘ１８９ | I7: =IF(F7="","",OFFSET(分類!$B$29,MATCH(F7,分類!$A$30:$A$46,0),0)) -> 漢方薬 | L7: =IF(G7="粉",VALUE(SUBSTITUTE(SUBSTITUTE(LEFT(H7, FIND("ｇ", H7) - 1), "．", "."), " ", "")),"") -> 2.5 | M7: =IF(L7="",J7,J7*L7) -> 0 | N7: =IF($A7="","",OFFSET(統合マスタ!$K$4,MATCH($A7,統合マスタ!$AC$5:$AC$1500,0),0)) -> g
A8: {=IFERROR(SMALL(IF(統合マスタ!$R$5:$R$1500=2,統合マスタ!$AC$5:$AC$1500),ROW(A4)),"")} -> 4 | B8: =B7+1 -> 4 | C8: =IF(A8="","",OFFSET(統合マスタ!$B$4,MATCH(A8,統合マスタ!$AC$5:$AC$1500,0),0)) -> 4 | D8: =IF($A8="","",OFFSET(統合マスタ!$C$4,MATCH($A8,統合マスタ!$AC$5:$AC$1500,0),0)) -> ０１６ ツムラ ハンゲコウボクトウ | E8: =IF($A8="","",OFFSET(統合マスタ!$X$4,MATCH($A8,統合マスタ!$AC$5:$AC$1500,0),0)) -> 0 | F8: =IF($A8="","",OFFSET(統合マスタ!$Z$4,MATCH($A8,統合マスタ!$AC$5:$AC$1500,0),0)) -> 4 | G8: =IF($A8="","",OFFSET(統合マスタ!$E$4,MATCH($A8,統合マスタ!$AC$5:$AC$1500,0),0)) -> 粉 | H8: =IF($A8="","",OFFSET(統合マスタ!$F$4,MATCH($A8,統合マスタ!$AC$5:$AC$1500,0),0)) -> ２．５ｇｘ１８９ | I8: =IF(F8="","",OFFSET(分類!$B$29,MATCH(F8,分類!$A$30:$A$46,0),0)) -> 漢方薬 | L8: =IF(G8="粉",VALUE(SUBSTITUTE(SUBSTITUTE(LEFT(H8, FIND("ｇ", H8) - 1), "．", "."), " ", "")),"") -> 2.5 | M8: =IF(L8="",J8,J8*L8) -> 0 | N8: =IF($A8="","",OFFSET(統合マスタ!$K$4,MATCH($A8,統合マスタ!$AC$5:$AC$1500,0),0)) -> ｇ
A9: {=IFERROR(SMALL(IF(統合マスタ!$R$5:$R$1500=2,統合マスタ!$AC$5:$AC$1500),ROW(A5)),"")} -> 6 | B9: =B8+1 -> 5 | C9: =IF(A9="","",OFFSET(統合マスタ!$B$4,MATCH(A9,統合マスタ!$AC$5:$AC$1500,0),0)) -> 6 | D9: =IF($A9="","",OFFSET(統合マスタ!$C$4,MATCH($A9,統合マスタ!$AC$5:$AC$1500,0),0)) -> ０１９ ツムラ ショウセイリュウトウ | E9: =IF($A9="","",OFFSET(統合マスタ!$X$4,MATCH($A9,統合マスタ!$AC$5:$AC$1500,0),0)) -> 0 | F9: =IF($A9="","",OFFSET(統合マスタ!$Z$4,MATCH($A9,統合マスタ!$AC$5:$AC$1500,0),0)) -> 4 | G9: =IF($A9="","",OFFSET(統合マスタ!$E$4,MATCH($A9,統合マスタ!$AC$5:$AC$1500,0),0)) -> 粉 | H9: =IF($A9="","",OFFSET(統合マスタ!$F$4,MATCH($A9,統合マスタ!$AC$5:$AC$1500,0),0)) -> ３ｇＸ４２ | I9: =IF(F9="","",OFFSET(分類!$B$29,MATCH(F9,分類!$A$30:$A$46,0),0)) -> 漢方薬 | L9: =IF(G9="粉",VALUE(SUBSTITUTE(SUBSTITUTE(LEFT(H9, FIND("ｇ", H9) - 1), "．", "."), " ", "")),"") -> 3 | M9: =IF(L9="",J9,J9*L9) -> 0 | N9: =IF($A9="","",OFFSET(統合マスタ!$K$4,MATCH($A9,統合マスタ!$AC$5:$AC$1500,0),0)) -> g
A10: {=IFERROR(SMALL(IF(統合マスタ!$R$5:$R$1500=2,統合マスタ!$AC$5:$AC$1500),ROW(A6)),"")} -> 7 | B10: =B9+1 -> 6 | C10: =IF(A10="","",OFFSET(統合マスタ!$B$4,MATCH(A10,統合マスタ!$AC$5:$AC$1500,0),0)) -> 7 | D10: =IF($A10="","",OFFSET(統合マスタ!$C$4,MATCH($A10,統合マスタ!$AC$5:$AC$1500,0),0)) -> ０４３ ツムラ リツクンシトウ | E10: =IF($A10="","",OFFSET(統合マスタ!$X$4,MATCH($A10,統合マスタ!$AC$5:$AC$1500,0),0)) -> 0 | F10: =IF($A10="","",OFFSET(統合マスタ!$Z$4,MATCH($A10,統合マスタ!$AC$5:$AC$1500,0),0)) -> 4 | G10: =IF($A10="","",OFFSET(統合マスタ!$E$4,MATCH($A10,統合マスタ!$AC$5:$AC$1500,0),0)) -> 粉 | H10: =IF($A10="","",OFFSET(統合マスタ!$F$4,MATCH($A10,統合マスタ!$AC$5:$AC$1500,0),0)) -> ２．５ｇｘ１８９ | I10: =IF(F10="","",OFFSET(分類!$B$29,MATCH(F10,分類!$A$30:$A$46,0),0)) -> 漢方薬 | L10: =IF(G10="粉",VALUE(SUBSTITUTE(SUBSTITUTE(LEFT(H10, FIND("ｇ", H10) - 1), "．", "."), " ", "")),"") -> 2.5 | M10: =IF(L10="",J10,J10*L10) -> 0 | N10: =IF($A10="","",OFFSET(統合マスタ!$K$4,MATCH($A10,統合マスタ!$AC$5:$AC$1500,0),0)) -> g
A11: {=IFERROR(SMALL(IF(統合マスタ!$R$5:$R$1500=2,統合マスタ!$AC$5:$AC$1500),ROW(A7)),"")} -> 14 | B11: =B10+1 -> 7 | C11: =IF(A11="","",OFFSET(統合マスタ!$B$4,MATCH(A11,統合マスタ!$AC$5:$AC$1500,0),0)) -> 14 | D11: =IF($A11="","",OFFSET(統合マスタ!$C$4,MATCH($A11,統合マスタ!$AC$5:$AC$1500,0),0)) -> １０８ ツムラ ニンジンヨウエイトウ | E11: =IF($A11="","",OFFSET(統合マスタ!$X$4,MATCH($A11,統合マスタ!$AC$5:$AC$1500,0),0)) -> 0 | F11: =IF($A11="","",OFFSET(統合マスタ!$Z$4,MATCH($A11,統合マスタ!$AC$5:$AC$1500,0),0)) -> 4 | G11: =IF($A11="","",OFFSET(統合マスタ!$E$4,MATCH($A11,統合マスタ!$AC$5:$AC$1500,0),0)) -> 粉 | H11: =IF($A11="","",OFFSET(統合マスタ!$F$4,MATCH($A11,統合マスタ!$AC$5:$AC$1500,0),0)) -> ３ｇｘ４２包 | I11: =IF(F11="","",OFFSET(分類!$B$29,MATCH(F11,分類!$A$30:$A$46,0),0)) -> 漢方薬 | L11: =IF(G11="粉",VALUE(SUBSTITUTE(SUBSTITUTE(LEFT(H11, FIND("ｇ", H11) - 1), "．", "."), " ", "")),"") -> 3 | M11: =IF(L11="",J11,J11*L11) -> 0 | N11: =IF($A11="","",OFFSET(統合マスタ!$K$4,MATCH($A11,統合マスタ!$AC$5:$AC$1500,0),0)) -> ｇ
A12: {=IFERROR(SMALL(IF(統合マスタ!$R$5:$R$1500=2,統合マスタ!$AC$5:$AC$1500),ROW(A8)),"")} -> 15 | B12: =B11+1 -> 8 | C12: =IF(A12="","",OFFSET(統合マスタ!$B$4,MATCH(A12,統合マスタ!$AC$5:$AC$1500,0),0)) -> 15 | D12: =IF($A12="","",OFFSET(統合マスタ!$C$4,MATCH($A12,統合マスタ!$AC$5:$AC$1500,0),0)) -> １１２ ツムラ チョレイトウゴウシモットウ | E12: =IF($A12="","",OFFSET(統合マスタ!$X$4,MATCH($A12,統合マスタ!$AC$5:$AC$1500,0),0)) -> 0 | F12: =IF($A12="","",OFFSET(統合マスタ!$Z$4,MATCH($A12,統合マスタ!$AC$5:$AC$1500,0),0)) -> 4 | G12: =IF($A12="","",OFFSET(統合マスタ!$E$4,MATCH($A12,統合マスタ!$AC$5:$AC$1500,0),0)) -> 粉 | H12: =IF($A12="","",OFFSET(統合マスタ!$F$4,MATCH($A12,統合マスタ!$AC$5:$AC$1500,0),0)) -> ２．５ｇｘ４２ | I12: =IF(F12="","",OFFSET(分類!$B$29,MATCH(F12,分類!$A$30:$A$46,0),0)) -> 漢方薬 | L12: =IF(G12="粉",VALUE(SUBSTITUTE(SUBSTITUTE(LEFT(H12, FIND("ｇ", H12) - 1), "．", "."), " ", "")),"") -> 2.5 | M12: =IF(L12="",J12,J12*L12) -> 0 | N12: =IF($A12="","",OFFSET(統合マスタ!$K$4,MATCH($A12,統合マスタ!$AC$5:$AC$1500,0),0)) -> g
A13: {=IFERROR(SMALL(IF(統合マスタ!$R$5:$R$1500=2,統合マスタ!$AC$5:$AC$1500),ROW(A9)),"")} -> 18 | B13: =B12+1 -> 9 | C13: =IF(A13="","",OFFSET(統合マスタ!$B$4,MATCH(A13,統合マスタ!$AC$5:$AC$1500,0),0)) -> 18 | D13: =IF($A13="","",OFFSET(統合マスタ!$C$4,MATCH($A13,統合マスタ!$AC$5:$AC$1500,0),0)) -> ＥＫ１１４ 柴苓湯 | E13: =IF($A13="","",OFFSET(統合マスタ!$X$4,MATCH($A13,統合マスタ!$AC$5:$AC$1500,0),0)) -> 0 | F13: =IF($A13="","",OFFSET(統合マスタ!$Z$4,MATCH($A13,統合マスタ!$AC$5:$AC$1500,0),0)) -> 4 | G13: =IF($A13="","",OFFSET(統合マスタ!$E$4,MATCH($A13,統合マスタ!$AC$5:$AC$1500,0),0)) -> 粉 | H13: =IF($A13="","",OFFSET(統合マスタ!$F$4,MATCH($A13,統合マスタ!$AC$5:$AC$1500,0),0)) -> ２．７ｇ×２９４ | I13: =IF(F13="","",OFFSET(分類!$B$29,MATCH(F13,分類!$A$30:$A$46,0),0)) -> 漢方薬 | L13: =IF(G13="粉",VALUE(SUBSTITUTE(SUBSTITUTE(LEFT(H13, FIND("ｇ", H13) - 1), "．", "."), " ", "")),"") -> 2.7 | M13: =IF(L13="",J13,J13*L13) -> 0 | N13: =IF($A13="","",OFFSET(統合マスタ!$K$4,MATCH($A13,統合マスタ!$AC$5:$AC$1500,0),0)) -> g
A14: {=IFERROR(SMALL(IF(統合マスタ!$R$5:$R$1500=2,統合マスタ!$AC$5:$AC$1500),ROW(A10)),"")} -> 19 | B14: =B13+1 -> 10 | C14: =IF(A14="","",OFFSET(統合マスタ!$B$4,MATCH(A14,統合マスタ!$AC$5:$AC$1500,0),0)) -> 19 | D14: =IF($A14="","",OFFSET(統合マスタ!$C$4,MATCH($A14,統合マスタ!$AC$5:$AC$1500,0),0)) -> ＥＫ１５ 黄連解毒湯エキス細粒 | E14: =IF($A14="","",OFFSET(統合マスタ!$X$4,MATCH($A14,統合マスタ!$AC$5:$AC$1500,0),0)) -> 0 | F14: =IF($A14="","",OFFSET(統合マスタ!$Z$4,MATCH($A14,統合マスタ!$AC$5:$AC$1500,0),0)) -> 4 | G14: =IF($A14="","",OFFSET(統合マスタ!$E$4,MATCH($A14,統合マスタ!$AC$5:$AC$1500,0),0)) -> 粉 | H14: =IF($A14="","",OFFSET(統合マスタ!$F$4,MATCH($A14,統合マスタ!$AC$5:$AC$1500,0),0)) -> ２ｇｘ４２包 | I14: =IF(F14="","",OFFSET(分類!$B$29,MATCH(F14,分類!$A$30:$A$46,0),0)) -> 漢方薬 | L14: =IF(G14="粉",VALUE(SUBSTITUTE(SUBSTITUTE(LEFT(H14, FIND("ｇ", H14) - 1), "．", "."), " ", "")),"") -> 2 | M14: =IF(L14="",J14,J14*L14) -> 0 | N14: =IF($A14="","",OFFSET(統合マスタ!$K$4,MATCH($A14,統合マスタ!$AC$5:$AC$1500,0),0)) -> g
A15: {=IFERROR(SMALL(IF(統合マスタ!$R$5:$R$1500=2,統合マスタ!$AC$5:$AC$1500),ROW(A11)),"")} -> 22 | B15: =B14+1 -> 11 | C15: =IF(A15="","",OFFSET(統合マスタ!$B$4,MATCH(A15,統合マスタ!$AC$5:$AC$1500,0),0)) -> 22 | D15: =IF($A15="","",OFFSET(統合マスタ!$C$4,MATCH($A15,統合マスタ!$AC$5:$AC$1500,0),0)) -> ＥＫ４０ 猪苓湯エキス細粒 | E15: =IF($A15="","",OFFSET(統合マスタ!$X$4,MATCH($A15,統合マスタ!$AC$5:$AC$1500,0),0)) -> 0 | F15: =IF($A15="","",OFFSET(統合マスタ!$Z$4,MATCH($A15,統合マスタ!$AC$5:$AC$1500,0),0)) -> 4 | G15: =IF($A15="","",OFFSET(統合マスタ!$E$4,MATCH($A15,統合マスタ!$AC$5:$AC$1500,0),0)) -> 粉 | H15: =IF($A15="","",OFFSET(統合マスタ!$F$4,MATCH($A15,統合マスタ!$AC$5:$AC$1500,0),0)) -> ２ｇｘ４２包 | I15: =IF(F15="","",OFFSET(分類!$B$29,MATCH(F15,分類!$A$30:$A$46,0),0)) -> 漢方薬 | L15: =IF(G15="粉",VALUE(SUBSTITUTE(SUBSTITUTE(LEFT(H15, FIND("ｇ", H15) - 1), "．", "."), " ", "")),"") -> 2 | M15: =IF(L15="",J15,J15*L15) -> 0 | N15: =IF($A15="","",OFFSET(統合マスタ!$K$4,MATCH($A15,統合マスタ!$AC$5:$AC$1500,0),0)) -> g
A16: {=IFERROR(SMALL(IF(統合マスタ!$R$5:$R$1500=2,統合マスタ!$AC$5:$AC$1500),ROW(A12)),"")} -> 26 | B16: =B15+1 -> 12 | C16: =IF(A16="","",OFFSET(統合マスタ!$B$4,MATCH(A16,統合マスタ!$AC$5:$AC$1500,0),0)) -> 26 | D16: =IF($A16="","",OFFSET(統合マスタ!$C$4,MATCH($A16,統合マスタ!$AC$5:$AC$1500,0),0)) -> Ｔ７２ ヨクイニンエキス錠「コタロー」 | E16: =IF($A16="","",OFFSET(統合マスタ!$X$4,MATCH($A16,統合マスタ!$AC$5:$AC$1500,0),0)) -> 0 | F16: =IF($A16="","",OFFSET(統合マスタ!$Z$4,MATCH($A16,統合マスタ!$AC$5:$AC$1500,0),0)) -> 15 | G16: =IF($A16="","",OFFSET(統合マスタ!$E$4,MATCH($A16,統合マスタ!$AC$5:$AC$1500,0),0)) -> バラ | H16: =IF($A16="","",OFFSET(統合マスタ!$F$4,MATCH($A16,統合マスタ!$AC$5:$AC$1500,0),0)) -> １２６Ｔｘ１０ | I16: =IF(F16="","",OFFSET(分類!$B$29,MATCH(F16,分類!$A$30:$A$46,0),0)) -> 不良在庫 | L16: =IF(G16="粉",VALUE(SUBSTITUTE(SUBSTITUTE(LEFT(H16, FIND("ｇ", H16) - 1), "．", "."), " ", "")),"") | M16: =IF(L16="",J16,J16*L16) -> 0 | N16: =IF($A16="","",OFFSET(統合マスタ!$K$4,MATCH($A16,統合マスタ!$AC$5:$AC$1500,0),0)) -> 錠
A17: {=IFERROR(SMALL(IF(統合マスタ!$R$5:$R$1500=2,統合マスタ!$AC$5:$AC$1500),ROW(A13)),"")} -> 35 | B17: =B16+1 -> 13 | C17: =IF(A17="","",OFFSET(統合マスタ!$B$4,MATCH(A17,統合マスタ!$AC$5:$AC$1500,0),0)) -> 35 | D17: =IF($A17="","",OFFSET(統合マスタ!$C$4,MATCH($A17,統合マスタ!$AC$5:$AC$1500,0),0)) -> アザルフィジンＥＮ錠５００ｍｇ | E17: =IF($A17="","",OFFSET(統合マスタ!$X$4,MATCH($A17,統合マスタ!$AC$5:$AC$1500,0),0)) -> 0 | F17: =IF($A17="","",OFFSET(統合マスタ!$Z$4,MATCH($A17,統合マスタ!$AC$5:$AC$1500,0),0)) -> 3 | G17: =IF($A17="","",OFFSET(統合マスタ!$E$4,MATCH($A17,統合マスタ!$AC$5:$AC$1500,0),0)) -> ＰＴＰ | H17: =IF($A17="","",OFFSET(統合マスタ!$F$4,MATCH($A17,統合マスタ!$AC$5:$AC$1500,0),0)) -> １００Ｔ | I17: =IF(F17="","",OFFSET(分類!$B$29,MATCH(F17,分類!$A$30:$A$46,0),0)) -> 外用.臨時.散薬ヒート | L17: =IF(G17="粉",VALUE(SUBSTITUTE(SUBSTITUTE(LEFT(H17, FIND("ｇ", H17) - 1), "．", "."), " ", "")),"") | M17: =IF(L17="",J17,J17*L17) -> 0 | N17: =IF($A17="","",OFFSET(統合マスタ!$K$4,MATCH($A17,統合マスタ!$AC$5:$AC$1500,0),0)) -> 錠
... A304: {=IFERROR(SMALL(IF(統合マスタ!$R$5:$R$1500=2,統合マスタ!$AC$5:$AC$1500),ROW(A300)),"")} | B304: =B303+1 -> 300 | C304: =IF(A304="","",OFFSET(統合マスタ!$B$4,MATCH(A304,統合マスタ!$AC$5:$AC$1500,0),0)) | D304: =IF($A304="","",OFFSET(統合マスタ!$C$4,MATCH($A304,統合マスタ!$AC$5:$AC$1500,0),0)) | E304: =IF($A304="","",OFFSET(統合マスタ!$X$4,MATCH($A304,統合マスタ!$AC$5:$AC$1500,0),0)) | F304: =IF($A304="","",OFFSET(統合マスタ!$Z$4,MATCH($A304,統合マスタ!$AC$5:$AC$1500,0),0)) | G304: =IF($A304="","",OFFSET(統合マスタ!$E$4,MATCH($A304,統合マスタ!$AC$5:$AC$1500,0),0)) | H304: =IF($A304="","",OFFSET(統合マスタ!$F$4,MATCH($A304,統合マスタ!$AC$5:$AC$1500,0),0)) | I304: =IF(F304="","",OFFSET(分類!$B$29,MATCH(F304,分類!$A$30:$A$46,0),0)) | L304: =IF(G304="粉",VALUE(SUBSTITUTE(SUBSTITUTE(LEFT(H304, FIND("ｇ", H304) - 1), "．", "."), " ", "")),"") | M304: =IF(L304="",J304,J304*L304) -> 0 | N304: =IF($A304="","",OFFSET(統合マスタ!$K$4,MATCH($A304,統合マスタ!$AC$5:$AC$1500,0),0))

Sheet 外用
B2: {=RIGHT(CELL("filename",A1),LEN(CELL("filename",A1))-FIND("]",CELL("filename",A1)))} -> 外用
A4: ソートキー | B4: No | C4: マスタNo | D4: 薬品名 | E4: 毒劇区分 | F4: 棚番 | G4: 包装形態 | H4: 容量 | I4: 薬価単位 | J4: 場所 | K4: 数量 | L4: 数える単位 | M4: 係数 | N4: 合計 | O4: 薬価単位
A5: {=IFERROR( SMALL( IF((統合マスタ!$R$5:$R$1500=1)* (ISNUMBER(MATCH(統合マスタ!$V$5:$V$1500, 分類!$H$8:$H$16, 0))), 統合マスタ!$AC$5:$AC$1500), ROW(A1) ), "")} -> 25 | B5: 1 | C5: =IF($A5="","",OFFSET(統合マスタ!$B$4,MATCH($A5,統合マスタ!$AC$5:$AC$1500,0),0)) -> 25 | D5: =IF($A5="","",OFFSET(統合マスタ!$C$4,MATCH($A5,統合マスタ!$AC$5:$AC$1500,0),0)) -> ＳＰトローチ０．２５ｍｇ「明治」 | E5: =IF($A5="","",OFFSET(統合マスタ!$X$4,MATCH($A5,統合マスタ!$AC$5:$AC$1500,0),0)) -> 0 | F5: =IF($A5="","",OFFSET(統合マスタ!$Z$4,MATCH($A5,統合マスタ!$AC$5:$AC$1500,0),0)) -> 3 | G5: =IF($A5="","",OFFSET(統合マスタ!$E$4,MATCH($A5,統合マスタ!$AC$5:$AC$1500,0),0)) -> ＰＴＰ | H5: =IF($A5="","",OFFSET(統合マスタ!$F$4,MATCH($A5,統合マスタ!$AC$5:$AC$1500,0),0)) -> １２００Ｔ | I5: =IF($A5="","",OFFSET(統合マスタ!$K$4,MATCH($A5,統合マスタ!$AC$5:$AC$1500,0),0)) -> 錠 | J5: =IF(F5="","",OFFSET(分類!$B$29,MATCH(F5,分類!$A$30:$A$46,0),0)) -> 外用.臨時.散薬ヒート | L5: 錠 | N5: =IF(M5="",K5,K5*M5) -> 0 | O5: =I5 -> 錠
A6: {=IFERROR( SMALL( IF((統合マスタ!$R$5:$R$1500=1)* (ISNUMBER(MATCH(統合マスタ!$V$5:$V$1500, 分類!$H$8:$H$16, 0))), 統合マスタ!$AC$5:$AC$1500), ROW(A2) ), "")} -> 32 | B6: =B5+1 -> 2 | C6: =IF($A6="","",OFFSET(統合マスタ!$B$4,MATCH($A6,統合マスタ!$AC$5:$AC$1500,0),0)) -> 32 | D6: =IF($A6="","",OFFSET(統合マスタ!$C$4,MATCH($A6,統合マスタ!$AC$5:$AC$1500,0),0)) -> アクアチムクリーム１％ | E6: =IF($A6="","",OFFSET(統合マスタ!$X$4,MATCH($A6,統合マスタ!$AC$5:$AC$1500,0),0)) -> 0 | F6: =IF($A6="","",OFFSET(統合マスタ!$Z$4,MATCH($A6,統合マスタ!$AC$5:$AC$1500,0),0)) -> 3 | G6: =IF($A6="","",OFFSET(統合マスタ!$E$4,MATCH($A6,統合マスタ!$AC$5:$AC$1500,0),0)) | H6: =IF($A6="","",OFFSET(統合マスタ!$F$4,MATCH($A6,統合マスタ!$AC$5:$AC$1500,0),0)) -> １０ｇＸ１０ | I6: =IF($A6="","",OFFSET(統合マスタ!$K$4,MATCH($A6,統合マスタ!$AC$5:$AC$1500,0),0)) -> ｇ | J6: =IF(F6="","",OFFSET(分類!$B$29,MATCH(F6,分類!$A$30:$A$46,0),0)) -> 外用.臨時.散薬ヒート | L6: 本 | M6: 10 | N6: =IF(M6="",K6,K6*M6) -> 0 | O6: =I6 -> ｇ
A7: {=IFERROR( SMALL( IF((統合マスタ!$R$5:$R$1500=1)* (ISNUMBER(MATCH(統合マスタ!$V$5:$V$1500, 分類!$H$8:$H$16, 0))), 統合マスタ!$AC$5:$AC$1500), ROW(A3) ), "")} -> 34 | B7: =B6+1 -> 3 | C7: =IF($A7="","",OFFSET(統合マスタ!$B$4,MATCH($A7,統合マスタ!$AC$5:$AC$1500,0),0)) -> 34 | D7: =IF($A7="","",OFFSET(統合マスタ!$C$4,MATCH($A7,統合マスタ!$AC$5:$AC$1500,0),0)) -> アクトシン軟膏３％ | E7: =IF($A7="","",OFFSET(統合マスタ!$X$4,MATCH($A7,統合マスタ!$AC$5:$AC$1500,0),0)) -> 0 | F7: =IF($A7="","",OFFSET(統合マスタ!$Z$4,MATCH($A7,統合マスタ!$AC$5:$AC$1500,0),0)) -> 15 | G7: =IF($A7="","",OFFSET(統合マスタ!$E$4,MATCH($A7,統合マスタ!$AC$5:$AC$1500,0),0)) | H7: =IF($A7="","",OFFSET(統合マスタ!$F$4,MATCH($A7,統合マスタ!$AC$5:$AC$1500,0),0)) -> ３０ｇ | I7: =IF($A7="","",OFFSET(統合マスタ!$K$4,MATCH($A7,統合マスタ!$AC$5:$AC$1500,0),0)) -> g | J7: =IF(F7="","",OFFSET(分類!$B$29,MATCH(F7,分類!$A$30:$A$46,0),0)) -> 不良在庫 | L7: 本 | M7: 30 | N7: =IF(M7="",K7,K7*M7) -> 0 | O7: =I7 -> g
A8: {=IFERROR( SMALL( IF((統合マスタ!$R$5:$R$1500=1)* (ISNUMBER(MATCH(統合マスタ!$V$5:$V$1500, 分類!$H$8:$H$16, 0))), 統合マスタ!$AC$5:$AC$1500), ROW(A4) ), "")} -> 49 | B8: =B7+1 -> 4 | C8: =IF($A8="","",OFFSET(統合マスタ!$B$4,MATCH($A8,統合マスタ!$AC$5:$AC$1500,0),0)) -> 49 | D8: =IF($A8="","",OFFSET(統合マスタ!$C$4,MATCH($A8,統合マスタ!$AC$5:$AC$1500,0),0)) -> アズレン点眼液０．０２％「ニットー」 | E8: =IF($A8="","",OFFSET(統合マスタ!$X$4,MATCH($A8,統合マスタ!$AC$5:$AC$1500,0),0)) -> 0 | F8: =IF($A8="","",OFFSET(統合マスタ!$Z$4,MATCH($A8,統合マスタ!$AC$5:$AC$1500,0),0)) -> 3 | G8: =IF($A8="","",OFFSET(統合マスタ!$E$4,MATCH($A8,統合マスタ!$AC$5:$AC$1500,0),0)) | H8: =IF($A8="","",OFFSET(統合マスタ!$F$4,MATCH($A8,統合マスタ!$AC$5:$AC$1500,0),0)) -> ５ｍｌｘ１０ | I8: =IF($A8="","",OFFSET(統合マスタ!$K$4,MATCH($A8,統合マスタ!$AC$5:$AC$1500,0),0)) -> 瓶 | J8: =IF(F8="","",OFFSET(分類!$B$29,MATCH(F8,分類!$A$30:$A$46,0),0)) -> 外用.臨時.散薬ヒート | L8: 瓶 | N8: =IF(M8="",K8,K8*M8) -> 0 | O8: =I8 -> 瓶
A9: {=IFERROR( SMALL( IF((統合マスタ!$R$5:$R$1500=1)* (ISNUMBER(MATCH(統合マスタ!$V$5:$V$1500, 分類!$H$8:$H$16, 0))), 統合マスタ!$AC$5:$AC$1500), ROW(A5) ), "")} -> 62 | B9: =B8+1 -> 5 | C9: =IF($A9="","",OFFSET(統合マスタ!$B$4,MATCH($A9,統合マスタ!$AC$5:$AC$1500,0),0)) -> 62 | D9: =IF($A9="","",OFFSET(統合マスタ!$C$4,MATCH($A9,統合マスタ!$AC$5:$AC$1500,0),0)) -> アドフィードパップ４０ｍｇ | E9: =IF($A9="","",OFFSET(統合マスタ!$X$4,MATCH($A9,統合マスタ!$AC$5:$AC$1500,0),0)) -> 0 | F9: =IF($A9="","",OFFSET(統合マスタ!$Z$4,MATCH($A9,統合マスタ!$AC$5:$AC$1500,0),0)) -> 12 | G9: =IF($A9="","",OFFSET(統合マスタ!$E$4,MATCH($A9,統合マスタ!$AC$5:$AC$1500,0),0)) | H9: =IF($A9="","",OFFSET(統合マスタ!$F$4,MATCH($A9,統合マスタ!$AC$5:$AC$1500,0),0)) -> ７枚ｘ５０ | I9: =IF($A9="","",OFFSET(統合マスタ!$K$4,MATCH($A9,統合マスタ!$AC$5:$AC$1500,0),0)) -> 枚 | J9: =IF(F9="","",OFFSET(分類!$B$29,MATCH(F9,分類!$A$30:$A$46,0),0)) -> 湿布 | L9: 袋 | M9: 7 | N9: =IF(M9="",K9,K9*M9) -> 0 | O9: =I9 -> 枚
A10: {=IFERROR( SMALL( IF((統合マスタ!$R$5:$R$1500=1)* (ISNUMBER(MATCH(統合マスタ!$V$5:$V$1500, 分類!$H$8:$H$16, 0))), 統合マスタ!$AC$5:$AC$1500), ROW(A6) ), "")} -> 116 | B10: =B9+1 -> 6 | C10: =IF($A10="","",OFFSET(統合マスタ!$B$4,MATCH($A10,統合マスタ!$AC$5:$AC$1500,0),0)) -> 116 | D10: =IF($A10="","",OFFSET(統合マスタ!$C$4,MATCH($A10,統合マスタ!$AC$5:$AC$1500,0),0)) -> インテバンクリーム１％ | E10: =IF($A10="","",OFFSET(統合マスタ!$X$4,MATCH($A10,統合マスタ!$AC$5:$AC$1500,0),0)) -> 0 | F10: =IF($A10="","",OFFSET(統合マスタ!$Z$4,MATCH($A10,統合マスタ!$AC$5:$AC$1500,0),0)) -> 1 | G10: =IF($A10="","",OFFSET(統合マスタ!$E$4,MATCH($A10,統合マスタ!$AC$5:$AC$1500,0),0)) | H10: =IF($A10="","",OFFSET(統合マスタ!$F$4,MATCH($A10,統合マスタ!$AC$5:$AC$1500,0),0)) -> ２５ｇｌｘ１０ | I10: =IF($A10="","",OFFSET(統合マスタ!$K$4,MATCH($A10,統合マスタ!$AC$5:$AC$1500,0),0)) -> ｇ | J10: =IF(F10="","",OFFSET(分類!$B$29,MATCH(F10,分類!$A$30:$A$46,0),0)) -> 調剤棚 | L10: 本 | M10: 25 | N10: =IF(M10="",K10,K10*M10) -> 0 | O10: =I10 -> ｇ
A11: {=IFERROR( SMALL( IF((統合マスタ!$R$5:$R$1500=1)* (ISNUMBER(MATCH(統合マスタ!$V$5:$V$1500, 分類!$H$8:$H$16, 0))), 統合マスタ!$AC$5:$AC$1500), ROW(A7) ), "")} -> 117 | B11: =B10+1 -> 7 | C11: =IF($A11="","",OFFSET(統合マスタ!$B$4,MATCH($A11,統合マスタ!$AC$5:$AC$1500,0),0)) -> 117 | D11: =IF($A11="","",OFFSET(統合マスタ!$C$4,MATCH($A11,統合マスタ!$AC$5:$AC$1500,0),0)) -> インテバン外用液１％ | E11: =IF($A11="","",OFFSET(統合マスタ!$X$4,MATCH($A11,統合マスタ!$AC$5:$AC$1500,0),0)) -> 0 | F11: =IF($A11="","",OFFSET(統合マスタ!$Z$4,MATCH($A11,統合マスタ!$AC$5:$AC$1500,0),0)) -> 3 | G11: =IF($A11="","",OFFSET(統合マスタ!$E$4,MATCH($A11,統合マスタ!$AC$5:$AC$1500,0),0)) | H11: =IF($A11="","",OFFSET(統合マスタ!$F$4,MATCH($A11,統合マスタ!$AC$5:$AC$1500,0),0)) -> ５０ｍｌｘ１０ | I11: =IF($A11="","",OFFSET(統合マスタ!$K$4,MATCH($A11,統合マスタ!$AC$5:$AC$1500,0),0)) -> ｍｌ | J11: =IF(F11="","",OFFSET(分類!$B$29,MATCH(F11,分類!$A$30:$A$46,0),0)) -> 外用.臨時.散薬ヒート | L11: 本 | M11: 50 | N11: =IF(M11="",K11,K11*M11) -> 0 | O11: =I11 -> ｍｌ
A12: {=IFERROR( SMALL( IF((統合マスタ!$R$5:$R$1500=1)* (ISNUMBER(MATCH(統合マスタ!$V$5:$V$1500, 分類!$H$8:$H$16, 0))), 統合マスタ!$AC$5:$AC$1500), ROW(A8) ), "")} -> 152 | B12: =B11+1 -> 8 | C12: =IF($A12="","",OFFSET(統合マスタ!$B$4,MATCH($A12,統合マスタ!$AC$5:$AC$1500,0),0)) -> 152 | D12: =IF($A12="","",OFFSET(統合マスタ!$C$4,MATCH($A12,統合マスタ!$AC$5:$AC$1500,0),0)) -> オイラックスクリーム１０％ | E12: =IF($A12="","",OFFSET(統合マスタ!$X$4,MATCH($A12,統合マスタ!$AC$5:$AC$1500,0),0)) -> 0 | F12: =IF($A12="","",OFFSET(統合マスタ!$Z$4,MATCH($A12,統合マスタ!$AC$5:$AC$1500,0),0)) -> 3 | G12: =IF($A12="","",OFFSET(統合マスタ!$E$4,MATCH($A12,統合マスタ!$AC$5:$AC$1500,0),0)) | H12: =IF($A12="","",OFFSET(統合マスタ!$F$4,MATCH($A12,統合マスタ!$AC$5:$AC$1500,0),0)) -> １０ｇＸ１０ | I12: =IF($A12="","",OFFSET(統合マスタ!$K$4,MATCH($A12,統合マスタ!$AC$5:$AC$1500,0),0)) -> 10ｇ | J12: =IF(F12="","",OFFSET(分類!$B$29,MATCH(F12,分類!$A$30:$A$46,0),0)) -> 外用.臨時.散薬ヒート | L12: 本 | M12: 10 | N12: =IF(M12="",K12,K12*M12) -> 0 | O12: =I12 -> 10ｇ
A13: {=IFERROR( SMALL( IF((統合マスタ!$R$5:$R$1500=1)* (ISNUMBER(MATCH(統合マスタ!$V$5:$V$1500, 分類!$H$8:$H$16, 0))), 統合マスタ!$AC$5:$AC$1500), ROW(A9) ), "")} -> 156 | B13: =B12+1 -> 9 | C13: =IF($A13="","",OFFSET(統合マスタ!$B$4,MATCH($A13,統合マスタ!$AC$5:$AC$1500,0),0)) -> 156 | D13: =IF($A13="","",OFFSET(統合マスタ!$C$4,MATCH($A13,統合マスタ!$AC$5:$AC$1500,0),0)) -> オフロキサシン点眼液０．３％「ＪＧ」 | E13: =IF($A13="","",OFFSET(統合マスタ!$X$4,MATCH($A13,統合マスタ!$AC$5:$AC$1500,0),0)) -> 0 | F13: =IF($A13="","",OFFSET(統合マスタ!$Z$4,MATCH($A13,統合マスタ!$AC$5:$AC$1500,0),0)) -> 3 | G13: =IF($A13="","",OFFSET(統合マスタ!$E$4,MATCH($A13,統合マスタ!$AC$5:$AC$1500,0),0)) | H13: =IF($A13="","",OFFSET(統合マスタ!$F$4,MATCH($A13,統合マスタ!$AC$5:$AC$1500,0),0)) -> ５ｍｌｘ１０ | I13: =IF($A13="","",OFFSET(統合マスタ!$K$4,MATCH($A13,統合マスタ!$AC$5:$AC$1500,0),0)) -> ｍｌ | J13: =IF(F13="","",OFFSET(分類!$B$29,MATCH(F13,分類!$A$30:$A$46,0),0)) -> 外用.臨時.散薬ヒート | L13: 本 | M13: 5 | N13: =IF(M13="",K13,K13*M13) -> 0 | O13: =I13 -> ｍｌ
A14: {=IFERROR( SMALL( IF((統合マスタ!$R$5:$R$1500=1)* (ISNUMBER(MATCH(統合マスタ!$V$5:$V$1500, 分類!$H$8:$H$16, 0))), 統合マスタ!$AC$5:$AC$1500), ROW(A10) ), "")} -> 183 | B14: =B13+1 -> 10 | C14: =IF($A14="","",OFFSET(統合マスタ!$B$4,MATCH($A14,統合マスタ!$AC$5:$AC$1500,0),0)) -> 183 | D14: =IF($A14="","",OFFSET(統合マスタ!$C$4,MATCH($A14,統合マスタ!$AC$5:$AC$1500,0),0)) -> キュバール１００エアゾール１５ｍｇ | E14: =IF($A14="","",OFFSET(統合マスタ!$X$4,MATCH($A14,統合マスタ!$AC$5:$AC$1500,0),0)) -> 0 | F14: =IF($A14="","",OFFSET(統合マスタ!$Z$4,MATCH($A14,統合マスタ!$AC$5:$AC$1500,0),0)) -> 3 | G14: =IF($A14="","",OFFSET(統合マスタ!$E$4,MATCH($A14,統合マスタ!$AC$5:$AC$1500,0),0)) | H14: =IF($A14="","",OFFSET(統合マスタ!$F$4,MATCH($A14,統合マスタ!$AC$5:$AC$1500,0),0)) -> ８．７ｇｘ１ | I14: =IF($A14="","",OFFSET(統合マスタ!$K$4,MATCH($A14,統合マスタ!$AC$5:$AC$1500,0),0)) -> 本 | J14: =IF(F14="","",OFFSET(分類!$B$29,MATCH(F14,分類!$A$30:$A$46,0),0)) -> 外用.臨時.散薬ヒート | L14: 本 | N14: =IF(M14="",K14,K14*M14) -> 0 | O14: =I14 -> 本
A15: {=IFERROR( SMALL( IF((統合マスタ!$R$5:$R$1500=1)* (ISNUMBER(MATCH(統合マスタ!$V$5:$V$1500, 分類!$H$8:$H$16, 0))), 統合マスタ!$AC$5:$AC$1500), ROW(A11) ), "")} -> 208 | B15: =B14+1 -> 11 | C15: =IF($A15="","",OFFSET(統合マスタ!$B$4,MATCH($A15,統合マスタ!$AC$5:$AC$1500,0),0)) -> 208 | D15: =IF($A15="","",OFFSET(統合マスタ!$C$4,MATCH($A15,統合マスタ!$AC$5:$AC$1500,0),0)) -> グリセリン浣腸液５０％「ムネ」 ６０ｍｌ | E15: =IF($A15="","",OFFSET(統合マスタ!$X$4,MATCH($A15,統合マスタ!$AC$5:$AC$1500,0),0)) -> 0 | F15: =IF($A15="","",OFFSET(統合マスタ!$Z$4,MATCH($A15,統合マスタ!$AC$5:$AC$1500,0),0)) -> 14 | G15: =IF($A15="","",OFFSET(統合マスタ!$E$4,MATCH($A15,統合マスタ!$AC$5:$AC$1500,0),0)) | H15: =IF($A15="","",OFFSET(統合マスタ!$F$4,MATCH($A15,統合マスタ!$AC$5:$AC$1500,0),0)) -> ６０ｍｌｘ１０ | I15: =IF($A15="","",OFFSET(統合マスタ!$K$4,MATCH($A15,統合マスタ!$AC$5:$AC$1500,0),0)) -> 本 | J15: =IF(F15="","",OFFSET(分類!$B$29,MATCH(F15,分類!$A$30:$A$46,0),0)) -> グリセリン浣腸 | L15: 本 | N15: =IF(M15="",K15,K15*M15) -> 0 | O15: =I15 -> 本
A16: {=IFERROR( SMALL( IF((統合マスタ!$R$5:$R$1500=1)* (ISNUMBER(MATCH(統合マスタ!$V$5:$V$1500, 分類!$H$8:$H$16, 0))), 統合マスタ!$AC$5:$AC$1500), ROW(A12) ), "")} -> 219 | B16: =B15+1 -> 12 | C16: =IF($A16="","",OFFSET(統合マスタ!$B$4,MATCH($A16,統合マスタ!$AC$5:$AC$1500,0),0)) -> 219 | D16: =IF($A16="","",OFFSET(統合マスタ!$C$4,MATCH($A16,統合マスタ!$AC$5:$AC$1500,0),0)) -> クロモグリク酸Ｎａ点眼液２％「ニットー」 | E16: =IF($A16="","",OFFSET(統合マスタ!$X$4,MATCH($A16,統合マスタ!$AC$5:$AC$1500,0),0)) -> 0 | F16: =IF($A16="","",OFFSET(統合マスタ!$Z$4,MATCH($A16,統合マスタ!$AC$5:$AC$1500,0),0)) -> 3 | G16: =IF($A16="","",OFFSET(統合マスタ!$E$4,MATCH($A16,統合マスタ!$AC$5:$AC$1500,0),0)) | H16: =IF($A16="","",OFFSET(統合マスタ!$F$4,MATCH($A16,統合マスタ!$AC$5:$AC$1500,0),0)) -> ５ＭＬＸ５Ｖ | I16: =IF($A16="","",OFFSET(統合マスタ!$K$4,MATCH($A16,統合マスタ!$AC$5:$AC$1500,0),0)) -> 瓶 | J16: =IF(F16="","",OFFSET(分類!$B$29,MATCH(F16,分類!$A$30:$A$46,0),0)) -> 外用.臨時.散薬ヒート | L16: 瓶 | N16: =IF(M16="",K16,K16*M16) -> 0 | O16: =I16 -> 瓶
A17: {=IFERROR( SMALL( IF((統合マスタ!$R$5:$R$1500=1)* (ISNUMBER(MATCH(統合マスタ!$V$5:$V$1500, 分類!$H$8:$H$16, 0))), 統合マスタ!$AC$5:$AC$1500), ROW(A13) ), "")} -> 220 | B17: =B16+1 -> 13 | C17: =IF($A17="","",OFFSET(統合マスタ!$B$4,MATCH($A17,統合マスタ!$AC$5:$AC$1500,0),0)) -> 220 | D17: =IF($A17="","",OFFSET(統合マスタ!$C$4,MATCH($A17,統合マスタ!$AC$5:$AC$1500,0),0)) -> クロモグリク酸Ｎａ点眼液２％「ニットー」 | E17: =IF($A17="","",OFFSET(統合マスタ!$X$4,MATCH($A17,統合マスタ!$AC$5:$AC$1500,0),0)) -> 0 | F17: =IF($A17="","",OFFSET(統合マスタ!$Z$4,MATCH($A17,統合マスタ!$AC$5:$AC$1500,0),0)) -> 3 | G17: =IF($A17="","",OFFSET(統合マスタ!$E$4,MATCH($A17,統合マスタ!$AC$5:$AC$1500,0),0)) | H17: =IF($A17="","",OFFSET(統合マスタ!$F$4,MATCH($A17,統合マスタ!$AC$5:$AC$1500,0),0)) -> ５ＭＬＸ１０Ｖ | I17: =IF($A17="","",OFFSET(統合マスタ!$K$4,MATCH($A17,統合マスタ!$AC$5:$AC$1500,0),0)) -> 瓶 | J17: =IF(F17="","",OFFSET(分類!$B$29,MATCH(F17,分類!$A$30:$A$46,0),0)) -> 外用.臨時.散薬ヒート | L17: 瓶 | N17: =IF(M17="",K17,K17*M17) -> 0 | O17: =I17 -> 瓶
A18: {=IFERROR( SMALL( IF((統合マスタ!$R$5:$R$1500=1)* (ISNUMBER(MATCH(統合マスタ!$V$5:$V$1500, 分類!$H$8:$H$16, 0))), 統合マスタ!$AC$5:$AC$1500), ROW(A14) ), "")} -> 222 | B18: =B17+1 -> 14 | C18: =IF($A18="","",OFFSET(統合マスタ!$B$4,MATCH($A18,統合マスタ!$AC$5:$AC$1500,0),0)) -> 222 | D18: =IF($A18="","",OFFSET(統合マスタ!$C$4,MATCH($A18,統合マスタ!$AC$5:$AC$1500,0),0)) -> ゲーベンクリーム１％ | E18: =IF($A18="","",OFFSET(統合マスタ!$X$4,MATCH($A18,統合マスタ!$AC$5:$AC$1500,0),0)) -> 0 | F18: =IF($A18="","",OFFSET(統合マスタ!$Z$4,MATCH($A18,統合マスタ!$AC$5:$AC$1500,0),0)) -> 7 | G18: =IF($A18="","",OFFSET(統合マスタ!$E$4,MATCH($A18,統合マスタ!$AC$5:$AC$1500,0),0)) | H18: =IF($A18="","",OFFSET(統合マスタ!$F$4,MATCH($A18,統合マスタ!$AC$5:$AC$1500,0),0)) -> １００ｇ | I18: =IF($A18="","",OFFSET(統合マスタ!$K$4,MATCH($A18,統合マスタ!$AC$5:$AC$1500,0),0)) -> ｇ | J18: =IF(F18="","",OFFSET(分類!$B$29,MATCH(F18,分類!$A$30:$A$46,0),0)) -> 軟膏 | L18: ｇ | N18: =IF(M18="",K18,K18*M18) -> 0 | O18: =I18 -> ｇ
A19: {=IFERROR( SMALL( IF((統合マスタ!$R$5:$R$1500=1)* (ISNUMBER(MATCH(統合マスタ!$V$5:$V$1500, 分類!$H$8:$H$16, 0))), 統合マスタ!$AC$5:$AC$1500), ROW(A15) ), "")} -> 223 | B19: =B18+1 -> 15 | C19: =IF($A19="","",OFFSET(統合マスタ!$B$4,MATCH($A19,統合マスタ!$AC$5:$AC$1500,0),0)) -> 223 | D19: =IF($A19="","",OFFSET(統合マスタ!$C$4,MATCH($A19,統合マスタ!$AC$5:$AC$1500,0),0)) -> ケトチフェン点鼻液０．０５％「サワイ」 | E19: =IF($A19="","",OFFSET(統合マスタ!$X$4,MATCH($A19,統合マスタ!$AC$5:$AC$1500,0),0)) -> 0 | F19: =IF($A19="","",OFFSET(統合マスタ!$Z$4,MATCH($A19,統合マスタ!$AC$5:$AC$1500,0),0)) -> 3 | G19: =IF($A19="","",OFFSET(統合マスタ!$E$4,MATCH($A19,統合マスタ!$AC$5:$AC$1500,0),0)) | H19: =IF($A19="","",OFFSET(統合マスタ!$F$4,MATCH($A19,統合マスタ!$AC$5:$AC$1500,0),0)) -> ６．０４８／８ｍｌｘ１０ | I19: =IF($A19="","",OFFSET(統合マスタ!$K$4,MATCH($A19,統合マスタ!$AC$5:$AC$1500,0),0)) -> 瓶 | J19: =IF(F19="","",OFFSET(分類!$B$29,MATCH(F19,分類!$A$30:$A$46,0),0)) -> 外用.臨時.散薬ヒート | L19: 瓶 | N19: =IF(M19="",K19,K19*M19) -> 0 | O19: =I19 -> 瓶
A20: {=IFERROR( SMALL( IF((統合マスタ!$R$5:$R$1500=1)* (ISNUMBER(MATCH(統合マスタ!$V$5:$V$1500, 分類!$H$8:$H$16, 0))), 統合マスタ!$AC$5:$AC$1500), ROW(A16) ), "")} -> 224 | B20: =B19+1 -> 16 | C20: =IF($A20="","",OFFSET(統合マスタ!$B$4,MATCH($A20,統合マスタ!$AC$5:$AC$1500,0),0)) -> 224 | D20: =IF($A20="","",OFFSET(統合マスタ!$C$4,MATCH($A20,統合マスタ!$AC$5:$AC$1500,0),0)) -> ケトプロフェンパップ３０ｍｇ 「三和」 １０ｘ１４ｃｍ | E20: =IF($A20="","",OFFSET(統合マスタ!$X$4,MATCH($A20,統合マスタ!$AC$5:$AC$1500,0),0)) -> 0 | F20: =IF($A20="","",OFFSET(統合マスタ!$Z$4,MATCH($A20,統合マスタ!$AC$5:$AC$1500,0),0)) -> 12 | G20: =IF($A20="","",OFFSET(統合マスタ!$E$4,MATCH($A20,統合マスタ!$AC$5:$AC$1500,0),0)) | H20: =IF($A20="","",OFFSET(統合マスタ!$F$4,MATCH($A20,統合マスタ!$AC$5:$AC$1500,0),0)) -> ７枚ｘ１００ | I20: =IF($A20="","",OFFSET(統合マスタ!$K$4,MATCH($A20,統合マスタ!$AC$5:$AC$1500,0),0)) -> 枚 | J20: =IF(F20="","",OFFSET(分類!$B$29,MATCH(F20,分類!$A$30:$A$46,0),0)) -> 湿布 | L20: 袋 | M20: 7 | N20: =IF(M20="",K20,K20*M20) -> 0 | O20: =I20 -> 枚
A21: {=IFERROR( SMALL( IF((統合マスタ!$R$5:$R$1500=1)* (ISNUMBER(MATCH(統合マスタ!$V$5:$V$1500, 分類!$H$8:$H$16, 0))), 統合マスタ!$AC$5:$AC$1500), ROW(A17) ), "")} -> 228 | B21: =B20+1 -> 17 | C21: =IF($A21="","",OFFSET(統合マスタ!$B$4,MATCH($A21,統合マスタ!$AC$5:$AC$1500,0),0)) -> 228 | D21: =IF($A21="","",OFFSET(統合マスタ!$C$4,MATCH($A21,統合マスタ!$AC$5:$AC$1500,0),0)) -> ゲンタマイシン硫酸塩軟膏０．１％「イワキ」 | E21: =IF($A21="","",OFFSET(統合マスタ!$X$4,MATCH($A21,統合マスタ!$AC$5:$AC$1500,0),0)) -> 0 | F21: =IF($A21="","",OFFSET(統合マスタ!$Z$4,MATCH($A21,統合マスタ!$AC$5:$AC$1500,0),0)) -> 3 | G21: =IF($A21="","",OFFSET(統合マスタ!$E$4,MATCH($A21,統合マスタ!$AC$5:$AC$1500,0),0)) | H21: =IF($A21="","",OFFSET(統合マスタ!$F$4,MATCH($A21,統合マスタ!$AC$5:$AC$1500,0),0)) -> １０ｇＸ１０ | I21: =IF($A21="","",OFFSET(統合マスタ!$K$4,MATCH($A21,統合マスタ!$AC$5:$AC$1500,0),0)) -> ｇ | J21: =IF(F21="","",OFFSET(分類!$B$29,MATCH(F21,分類!$A$30:$A$46,0),0)) -> 外用.臨時.散薬ヒート | L21: 本 | M21: 10 | N21: =IF(M21="",K21,K21*M21) -> 0 | O21: =I21 -> ｇ
