Workbook

Sheet 統合マスタ
C3: 棚卸 | N3: マスタ
B4: no | C4: 名称 | D4: 2025年度卸 | E4: 包装形態 | F4: 容量 | G4: メーカー | H4: 新単位薬価 | I4: 2025年度薬価 | J4: 単位数量 | K4: 薬価単位 | L4: 2025年納入価格 | M4: 単位納入価 | N4: コード(区分値) | O4: コード | P4: 名称 | Q4: ホストコード | R4: 採用区分（区分値）(区分値) | S4: 採用区分（区分値） | T4: 薬価 | U4: カナ名称 | V4: 剤形(区分値) | W4: 剤形 | X4: 毒劇薬（区分値）(区分値) | Y4: 毒劇薬（区分値） | Z4: 棚 | AA4: 非採用
A5: =元データ!P2 -> 295 | B5: 1 | C5: =DBCS(元データ!A2) -> ００７ ツムラ ハチミジオウガン | D5: =元データ!B2 -> メディセオ | E5: =元データ!C2 -> 粉 | F5: =元データ!D2 -> 2.5ｇｘ189 | G5: =元データ!E2 -> ツムラ | H5: =元データ!F2 -> 9.8 | I5: =元データ!G2 -> 4630.5 | J5: =元データ!H2 -> 472.5 | K5: =元データ!I2 -> ｇ | ... M5: =元データ!K2 -> 8.6624339 | N5: =IF(OFFSET(マスタ非採用削除!A$4,統合マスタ!$A5,0)="","",OFFSET(マスタ非採用削除!A$4,統合マスタ!$A5,0)) -> ﾂﾑﾗ007 | O5: =IF(OFFSET(マスタ非採用削除!B$4,統合マスタ!$A5,0)="","",OFFSET(マスタ非採用削除!B$4,統合マスタ!$A5,0)) -> ﾂﾑﾗ007 | P5: =IF(OFFSET(マスタ非採用削除!C$4,統合マスタ!$A5,0)="","",OFFSET(マスタ非採用削除!C$4,統合マスタ!$A5,0)) -> ツムラ八味地黄丸エキス顆粒（医療用） | Q5: =IF(OFFSET(マスタ非採用削除!D$4,統合マスタ!$A5,0)="","",OFFSET(マスタ非採用削除!D$4,統合マスタ!$A5,0)) -> ﾊﾁﾐ | R5: =IF(OFFSET(マスタ非採用削除!E$4,統合マスタ!$A5,0)="","",OFFSET(マスタ非採用削除!E$4,統合マスタ!$A5,0)) -> 2 | S5: =IF(OFFSET(マスタ非採用削除!F$4,統合マスタ!$A5,0)="","",OFFSET(マスタ非採用削除!F$4,統合マスタ!$A5,0)) | T5: =IF(OFFSET(マスタ非採用削除!G$4,統合マスタ!$A5,0)="","",OFFSET(マスタ非採用削除!G$4,統合マスタ!$A5,0)) -> 9.8 | U5: =IF(OFFSET(マスタ非採用削除!H$4,統合マスタ!$A5,0)="","",OFFSET(マスタ非採用削除!H$4,統合マスタ!$A5,0)) -> ﾂﾑﾗﾊﾁﾐｼﾞｵｳｶﾞﾝｴｷｽｶﾘｭｳ(ｲﾘｮｳﾖｳ) | ... Z5: =IF(OFFSET(マスタ非採用削除!M$4,統合マスタ!$A5,0)="","",OFFSET(マスタ非採用削除!M$4,統合マスタ!$A5,0)) -> 4
A6: =元データ!P3 -> 295 | B6: =B5+1 -> 2 | C6: =DBCS(元データ!A3) -> ００７ ツムラ ハチミジオウガン | D6: =元データ!B3 | E6: =元データ!C3 -> 粉 | F6: =元データ!D3 -> 2.5ｇｘ42 | G6: =元データ!E3 -> ツムラ | H6: =元データ!F3 -> 9.8 | I6: =元データ!G3 -> 1029 | J6: =元データ!H3 -> 105 | K6: =元データ!I3 -> ｇ | ... M6: =元データ!K3 -> 8.9047619 | N6: =IF(OFFSET(マスタ非採用削除!A$4,統合マスタ!$A6,0)="","",OFFSET(マスタ非採用削除!A$4,統合マスタ!$A6,0)) -> ﾂﾑﾗ007 | O6: =IF(OFFSET(マスタ非採用削除!B$4,統合マスタ!$A6,0)="","",OFFSET(マスタ非採用削除!B$4,統合マスタ!$A6,0)) -> ﾂﾑﾗ007 | P6: =IF(OFFSET(マスタ非採用削除!C$4,統合マスタ!$A6,0)="","",OFFSET(マスタ非採用削除!C$4,統合マスタ!$A6,0)) -> ツムラ八味地黄丸エキス顆粒（医療用） | Q6: =IF(OFFSET(マスタ非採用削除!D$4,統合マスタ!$A6,0)="","",OFFSET(マスタ非採用削除!D$4,統合マスタ!$A6,0)) -> ﾊﾁﾐ | R6: =IF(OFFSET(マスタ非採用削除!E$4,統合マスタ!$A6,0)="","",OFFSET(マスタ非採用削除!E$4,統合マスタ!$A6,0)) -> 2 | S6: =IF(OFFSET(マスタ非採用削除!F$4,統合マスタ!$A6,0)="","",OFFSET(マスタ非採用削除!F$4,統合マスタ!$A6,0)) | T6: =IF(OFFSET(マスタ非採用削除!G$4,統合マスタ!$A6,0)="","",OFFSET(マスタ非採用削除!G$4,統合マスタ!$A6,0)) -> 9.8 | U6: =IF(OFFSET(マスタ非採用削除!H$4,統合マスタ!$A6,0)="","",OFFSET(マスタ非採用削除!H$4,統合マスタ!$A6,0)) -> ﾂﾑﾗﾊﾁﾐｼﾞｵｳｶﾞﾝｴｷｽｶﾘｭｳ(ｲﾘｮｳﾖｳ) | ... Z6: =IF(OFFSET(マスタ非採用削除!M$4,統合マスタ!$A6,0)="","",OFFSET(マスタ非採用削除!M$4,統合マスタ!$A6,0)) -> 4
A7: =元データ!P4 -> 296 | B7: =B6+1 -> 3 | C7: =DBCS(元データ!A4) -> ０１２ ツムラ サイコカリュウコツボレイトウ | D7: =元データ!B4 -> メディセオ | E7: =元データ!C4 -> 粉 | F7: =元データ!D4 -> 2.5ｇｘ189 | G7: =元データ!E4 -> ツムラ | H7: =元データ!F4 -> 20.3 | I7: =元データ!G4 -> 9591.75 | J7: =元データ!H4 -> 472.5 | K7: =元データ!I4 -> g | ... M7: =元データ!K4 -> 18.08254 | N7: =IF(OFFSET(マスタ非採用削除!A$4,統合マスタ!$A7,0)="","",OFFSET(マスタ非採用削除!A$4,統合マスタ!$A7,0)) -> ﾂﾑﾗ012 | O7: =IF(OFFSET(マスタ非採用削除!B$4,統合マスタ!$A7,0)="","",OFFSET(マスタ非採用削除!B$4,統合マスタ!$A7,0)) -> ﾂﾑﾗ012 | P7: =IF(OFFSET(マスタ非採用削除!C$4,統合マスタ!$A7,0)="","",OFFSET(マスタ非採用削除!C$4,統合マスタ!$A7,0)) -> ツムラ柴胡加竜骨牡蛎湯エキス顆粒（医療用） | Q7: =IF(OFFSET(マスタ非採用削除!D$4,統合マスタ!$A7,0)="","",OFFSET(マスタ非採用削除!D$4,統合マスタ!$A7,0)) -> ｻｲｺ | R7: =IF(OFFSET(マスタ非採用削除!E$4,統合マスタ!$A7,0)="","",OFFSET(マスタ非採用削除!E$4,統合マスタ!$A7,0)) -> 2 | S7: =IF(OFFSET(マスタ非採用削除!F$4,統合マスタ!$A7,0)="","",OFFSET(マスタ非採用削除!F$4,統合マスタ!$A7,0)) | T7: =IF(OFFSET(マスタ非採用削除!G$4,統合マスタ!$A7,0)="","",OFFSET(マスタ非採用削除!G$4,統合マスタ!$A7,0)) -> 20.3 | U7: =IF(OFFSET(マスタ非採用削除!H$4,統合マスタ!$A7,0)="","",OFFSET(マスタ非採用削除!H$4,統合マスタ!$A7,0)) -> ﾂﾑﾗｻｲｺｶﾘｭｳｺﾂﾎﾞﾚｲﾄｳｴｷｽｶﾘｭｳ(ｲﾘｮｳﾖｳ) | ... Z7: =IF(OFFSET(マスタ非採用削除!M$4,統合マスタ!$A7,0)="","",OFFSET(マスタ非採用削除!M$4,統合マスタ!$A7,0)) -> 4
A8: =元データ!P5 -> 297 | B8: =B7+1 -> 4 | C8: =DBCS(元データ!A5) -> ０１６ ツムラ ハンゲコウボクトウ | D8: =元データ!B5 -> メディセオ | E8: =元データ!C5 -> 粉 | F8: =元データ!D5 -> 2.5ｇｘ189 | G8: =元データ!E5 -> ツムラ | H8: =元データ!F5 -> 14.6 | I8: =元データ!G5 -> 6898.5 | J8: =元データ!H5 -> 472.5 | K8: =元データ!I5 -> ｇ | ... M8: =元データ!K5 -> 13.144974 | N8: =IF(OFFSET(マスタ非採用削除!A$4,統合マスタ!$A8,0)="","",OFFSET(マスタ非採用削除!A$4,統合マスタ!$A8,0)) -> ﾂﾑﾗ016 | O8: =IF(OFFSET(マスタ非採用削除!B$4,統合マスタ!$A8,0)="","",OFFSET(マスタ非採用削除!B$4,統合マスタ!$A8,0)) -> ﾂﾑﾗ016 | P8: =IF(OFFSET(マスタ非採用削除!C$4,統合マスタ!$A8,0)="","",OFFSET(マスタ非採用削除!C$4,統合マスタ!$A8,0)) -> ツムラ半夏厚朴湯エキス顆粒（医療用） | Q8: =IF(OFFSET(マスタ非採用削除!D$4,統合マスタ!$A8,0)="","",OFFSET(マスタ非採用削除!D$4,統合マスタ!$A8,0)) -> ﾊﾝｹﾞｺ | R8: =IF(OFFSET(マスタ非採用削除!E$4,統合マスタ!$A8,0)="","",OFFSET(マスタ非採用削除!E$4,統合マスタ!$A8,0)) -> 2 | S8: =IF(OFFSET(マスタ非採用削除!F$4,統合マスタ!$A8,0)="","",OFFSET(マスタ非採用削除!F$4,統合マスタ!$A8,0)) | T8: =IF(OFFSET(マスタ非採用削除!G$4,統合マスタ!$A8,0)="","",OFFSET(マスタ非採用削除!G$4,統合マスタ!$A8,0)) -> 14.6 | U8: =IF(OFFSET(マスタ非採用削除!H$4,統合マスタ!$A8,0)="","",OFFSET(マスタ非採用削除!H$4,統合マスタ!$A8,0)) -> ﾂﾑﾗﾊﾝｹﾞｺｳﾎﾞｸﾄｳｴｷｽｶﾘｭｳ(ｲﾘｮｳﾖｳ) | ... Z8: =IF(OFFSET(マスタ非採用削除!M$4,統合マスタ!$A8,0)="","",OFFSET(マスタ非採用削除!M$4,統合マスタ!$A8,0)) -> 4
A9: =元データ!P6 -> 298 | B9: =B8+1 -> 5 | C9: =DBCS(元データ!A6) -> ０１７ ツムラ ゴレイサン | D9: =元データ!B6 -> メディセオ | E9: =元データ!C6 -> 粉 | F9: =元データ!D6 -> 2.5ｇｘ189 | G9: =元データ!E6 -> ツムラ | H9: =元データ!F6 -> 13.6 | I9: =元データ!G6 -> 6426 | J9: =元データ!H6 -> 472.5 | K9: =元データ!I6 -> g | ... M9: =元データ!K6 -> 12.122751 | N9: =IF(OFFSET(マスタ非採用削除!A$4,統合マスタ!$A9,0)="","",OFFSET(マスタ非採用削除!A$4,統合マスタ!$A9,0)) -> ﾂﾑﾗ017 | O9: =IF(OFFSET(マスタ非採用削除!B$4,統合マスタ!$A9,0)="","",OFFSET(マスタ非採用削除!B$4,統合マスタ!$A9,0)) -> ﾂﾑﾗ017 | P9: =IF(OFFSET(マスタ非採用削除!C$4,統合マスタ!$A9,0)="","",OFFSET(マスタ非採用削除!C$4,統合マスタ!$A9,0)) -> ツムラ五苓散エキス顆粒（医療用） | Q9: =IF(OFFSET(マスタ非採用削除!D$4,統合マスタ!$A9,0)="","",OFFSET(マスタ非採用削除!D$4,統合マスタ!$A9,0)) -> ｺﾞﾚｲ | R9: =IF(OFFSET(マスタ非採用削除!E$4,統合マスタ!$A9,0)="","",OFFSET(マスタ非採用削除!E$4,統合マスタ!$A9,0)) -> 1 | S9: =IF(OFFSET(マスタ非採用削除!F$4,統合マスタ!$A9,0)="","",OFFSET(マスタ非採用削除!F$4,統合マスタ!$A9,0)) | T9: =IF(OFFSET(マスタ非採用削除!G$4,統合マスタ!$A9,0)="","",OFFSET(マスタ非採用削除!G$4,統合マスタ!$A9,0)) -> 13.6 | U9: =IF(OFFSET(マスタ非採用削除!H$4,統合マスタ!$A9,0)="","",OFFSET(マスタ非採用削除!H$4,統合マスタ!$A9,0)) -> ﾂﾑﾗｺﾞﾚｲｻﾝｴｷｽｶﾘｭｳ(ｲﾘｮｳﾖｳ) | ... Z9: =IF(OFFSET(マスタ非採用削除!M$4,統合マスタ!$A9,0)="","",OFFSET(マスタ非採用削除!M$4,統合マスタ!$A9,0)) -> 4
A10: =元データ!P7 -> 299 | B10: =B9+1 -> 6 | C10: =DBCS(元データ!A7) -> ０１９ ツムラ ショウセイリュウトウ | D10: =元データ!B7 -> メディセオ | E10: =元データ!C7 -> 粉 | F10: =元データ!D7 -> 3ｇX42 | G10: =元データ!E7 -> ツムラ | H10: =元データ!F7 -> 12.8 | I10: =元データ!G7 -> 1612.8 | J10: =元データ!H7 -> 126 | K10: =元データ!I7 -> g | ... M10: =元データ!K7 -> 11.626984 | N10: =IF(OFFSET(マスタ非採用削除!A$4,統合マスタ!$A10,0)="","",OFFSET(マスタ非採用削除!A$4,統合マスタ!$A10,0)) -> ﾂﾑﾗ019 | O10: =IF(OFFSET(マスタ非採用削除!B$4,統合マスタ!$A10,0)="","",OFFSET(マスタ非採用削除!B$4,統合マスタ!$A10,0)) -> ﾂﾑﾗ019 | P10: =IF(OFFSET(マスタ非採用削除!C$4,統合マスタ!$A10,0)="","",OFFSET(マスタ非採用削除!C$4,統合マスタ!$A10,0)) -> ツムラ小青竜湯エキス顆粒（医療用） | Q10: =IF(OFFSET(マスタ非採用削除!D$4,統合マスタ!$A10,0)="","",OFFSET(マスタ非採用削除!D$4,統合マスタ!$A10,0)) | R10: =IF(OFFSET(マスタ非採用削除!E$4,統合マスタ!$A10,0)="","",OFFSET(マスタ非採用削除!E$4,統合マスタ!$A10,0)) -> 2 | S10: =IF(OFFSET(マスタ非採用削除!F$4,統合マスタ!$A10,0)="","",OFFSET(マスタ非採用削除!F$4,統合マスタ!$A10,0)) | T10: =IF(OFFSET(マスタ非採用削除!G$4,統合マスタ!$A10,0)="","",OFFSET(マスタ非採用削除!G$4,統合マスタ!$A10,0)) -> 12.8 | U10: =IF(OFFSET(マスタ非採用削除!H$4,統合マスタ!$A10,0)="","",OFFSET(マスタ非採用削除!H$4,統合マスタ!$A10,0)) -> ﾂﾑﾗｼﾖｳｾｲﾘﾕｳﾄｳｴｷｽｶﾘﾕｳｲﾘﾖｳﾖｳ | ... Z10: =IF(OFFSET(マスタ非採用削除!M$4,統合マスタ!$A10,0)="","",OFFSET(マスタ非採用削除!M$4,統合マスタ!$A10,0)) -> 4
A11: =元データ!P8 -> 301 | B11: =B10+1 -> 7 | C11: =DBCS(元データ!A8) -> ０４３ ツムラ リツクンシトウ | D11: =元データ!B8 -> メディセオ | E11: =元データ!C8 -> 粉 | F11: =元データ!D8 -> 2.5ｇｘ189 | G11: =元データ!E8 -> ツムラ | H11: =元データ!F8 -> 18 | I11: =元データ!G8 -> 8505 | J11: =元データ!H8 -> 472.5 | K11: =元データ!I8 -> g | ... M11: =元データ!K8 -> 16.033862 | N11: =IF(OFFSET(マスタ非採用削除!A$4,統合マスタ!$A11,0)="","",OFFSET(マスタ非採用削除!A$4,統合マスタ!$A11,0)) -> ﾂﾑﾗ043 | O11: =IF(OFFSET(マスタ非採用削除!B$4,統合マスタ!$A11,0)="","",OFFSET(マスタ非採用削除!B$4,統合マスタ!$A11,0)) -> ﾂﾑﾗ043 | P11: =IF(OFFSET(マスタ非採用削除!C$4,統合マスタ!$A11,0)="","",OFFSET(マスタ非採用削除!C$4,統合マスタ!$A11,0)) -> ツムラ六君子湯エキス顆粒（医療用） | Q11: =IF(OFFSET(マスタ非採用削除!D$4,統合マスタ!$A11,0)="","",OFFSET(マスタ非採用削除!D$4,統合マスタ!$A11,0)) -> ﾘｯｸ | R11: =IF(OFFSET(マスタ非採用削除!E$4,統合マスタ!$A11,0)="","",OFFSET(マスタ非採用削除!E$4,統合マスタ!$A11,0)) -> 2 | S11: =IF(OFFSET(マスタ非採用削除!F$4,統合マスタ!$A11,0)="","",OFFSET(マスタ非採用削除!F$4,統合マスタ!$A11,0)) | T11: =IF(OFFSET(マスタ非採用削除!G$4,統合マスタ!$A11,0)="","",OFFSET(マスタ非採用削除!G$4,統合マスタ!$A11,0)) -> 18 | U11: =IF(OFFSET(マスタ非採用削除!H$4,統合マスタ!$A11,0)="","",OFFSET(マスタ非採用削除!H$4,統合マスタ!$A11,0)) -> ﾂﾑﾗﾘｯｸﾝｼﾄｳｴｷｽｶﾘｭｳ(ｲﾘｮｳﾖｳ) | ... Z11: =IF(OFFSET(マスタ非採用削除!M$4,統合マスタ!$A11,0)="","",OFFSET(マスタ非採用削除!M$4,統合マスタ!$A11,0)) -> 4
A12: =元データ!P9 -> 0 | B12: =B11+1 -> 8 | C12: =DBCS(元データ!A9) -> ０４８ ツムラ ジュウゼンタイホトウ | D12: =元データ!B9 | E12: =元データ!C9 -> 粉 | F12: =元データ!D9 -> 2.5ｇｘ189包 | G12: =元データ!E9 -> ツムラ | H12: =元データ!F9 -> 18.4 | I12: =元データ!G9 -> 8694 | J12: =元データ!H9 -> 472.5 | K12: =元データ!I9 -> g | ... M12: =元データ!K9 -> 16.402116 | N12: =IF(OFFSET(マスタ非採用削除!A$4,統合マスタ!$A12,0)="","",OFFSET(マスタ非採用削除!A$4,統合マスタ!$A12,0)) -> コード(区分値) | O12: =IF(OFFSET(マスタ非採用削除!B$4,統合マスタ!$A12,0)="","",OFFSET(マスタ非採用削除!B$4,統合マスタ!$A12,0)) -> コード | P12: =IF(OFFSET(マスタ非採用削除!C$4,統合マスタ!$A12,0)="","",OFFSET(マスタ非採用削除!C$4,統合マスタ!$A12,0)) -> 名称 | Q12: =IF(OFFSET(マスタ非採用削除!D$4,統合マスタ!$A12,0)="","",OFFSET(マスタ非採用削除!D$4,統合マスタ!$A12,0)) -> ホストコード | R12: =IF(OFFSET(マスタ非採用削除!E$4,統合マスタ!$A12,0)="","",OFFSET(マスタ非採用削除!E$4,統合マスタ!$A12,0)) -> 採用区分（区分値）(区分値) | S12: =IF(OFFSET(マスタ非採用削除!F$4,統合マスタ!$A12,0)="","",OFFSET(マスタ非採用削除!F$4,統合マスタ!$A12,0)) -> 採用区分（区分値） | T12: =IF(OFFSET(マスタ非採用削除!G$4,統合マスタ!$A12,0)="","",OFFSET(マスタ非採用削除!G$4,統合マスタ!$A12,0)) -> 薬価 | U12: =IF(OFFSET(マスタ非採用削除!H$4,統合マスタ!$A12,0)="","",OFFSET(マスタ非採用削除!H$4,統合マスタ!$A12,0)) -> カナ名称 | ... Z12: =IF(OFFSET(マスタ非採用削除!M$4,統合マスタ!$A12,0)="","",OFFSET(マスタ非採用削除!M$4,統合マスタ!$A12,0)) -> 棚
A13: =元データ!P10 -> 302 | B13: =B12+1 -> 9 | C13: =DBCS(元データ!A10) -> ０５４ ツムラ ヨクカンサン | D13: =元データ!B10 -> メディセオ | E13: =元データ!C10 -> 粉 | F13: =元データ!D10 -> 2.5ｇX189 | G13: =元データ!E10 -> ツムラ | H13: =元データ!F10 -> 16.1 | I13: =元データ!G10 -> 7607.25 | J13: =元データ!H10 -> 472.5 | K13: =元データ!I10 -> g | ... M13: =元データ!K10 -> 14.495238 | N13: =IF(OFFSET(マスタ非採用削除!A$4,統合マスタ!$A13,0)="","",OFFSET(マスタ非採用削除!A$4,統合マスタ!$A13,0)) -> ﾂﾑﾗ054 | O13: =IF(OFFSET(マスタ非採用削除!B$4,統合マスタ!$A13,0)="","",OFFSET(マスタ非採用削除!B$4,統合マスタ!$A13,0)) -> ﾂﾑﾗ054 | P13: =IF(OFFSET(マスタ非採用削除!C$4,統合マスタ!$A13,0)="","",OFFSET(マスタ非採用削除!C$4,統合マスタ!$A13,0)) -> ツムラ抑肝散エキス顆粒（医療用） | Q13: =IF(OFFSET(マスタ非採用削除!D$4,統合マスタ!$A13,0)="","",OFFSET(マスタ非採用削除!D$4,統合マスタ!$A13,0)) -> ﾖｸｶ | R13: =IF(OFFSET(マスタ非採用削除!E$4,統合マスタ!$A13,0)="","",OFFSET(マスタ非採用削除!E$4,統合マスタ!$A13,0)) -> 1 | S13: =IF(OFFSET(マスタ非採用削除!F$4,統合マスタ!$A13,0)="","",OFFSET(マスタ非採用削除!F$4,統合マスタ!$A13,0)) | T13: =IF(OFFSET(マスタ非採用削除!G$4,統合マスタ!$A13,0)="","",OFFSET(マスタ非採用削除!G$4,統合マスタ!$A13,0)) -> 16.1 | U13: =IF(OFFSET(マスタ非採用削除!H$4,統合マスタ!$A13,0)="","",OFFSET(マスタ非採用削除!H$4,統合マスタ!$A13,0)) -> ﾂﾑﾗﾖｸｶﾝｻﾝｴｷｽｶﾘｭｳ(ｲﾘｮｳﾖｳ) | ... Z13: =IF(OFFSET(マスタ非採用削除!M$4,統合マスタ!$A13,0)="","",OFFSET(マスタ非採用削除!M$4,統合マスタ!$A13,0)) -> 4
A14: =元データ!P11 -> 303 | B14: =B13+1 -> 10 | C14: =DBCS(元データ!A11) -> ０６２ ツムラ ボウフウツウシヨウサン | D14: =元データ!B11 -> メディセオ | E14: =元データ!C11 -> 粉 | F14: =元データ!D11 -> 2.5ｇｘ189 | G14: =元データ!E11 -> ツムラ | H14: =元データ!F11 -> 13.8 | I14: =元データ!G11 -> 6520.5 | J14: =元データ!H11 -> 472.5 | K14: =元データ!I11 -> g | ... M14: =元データ!K11 -> 12.425397 | N14: =IF(OFFSET(マスタ非採用削除!A$4,統合マスタ!$A14,0)="","",OFFSET(マスタ非採用削除!A$4,統合マスタ!$A14,0)) -> ﾂﾑﾗ062 | O14: =IF(OFFSET(マスタ非採用削除!B$4,統合マスタ!$A14,0)="","",OFFSET(マスタ非採用削除!B$4,統合マスタ!$A14,0)) -> ﾂﾑﾗ062 | P14: =IF(OFFSET(マスタ非採用削除!C$4,統合マスタ!$A14,0)="","",OFFSET(マスタ非採用削除!C$4,統合マスタ!$A14,0)) -> ツムラ防風通聖散エキス顆粒（医療用） | Q14: =IF(OFFSET(マスタ非採用削除!D$4,統合マスタ!$A14,0)="","",OFFSET(マスタ非採用削除!D$4,統合マスタ!$A14,0)) -> ﾎﾞｳﾌｳ | R14: =IF(OFFSET(マスタ非採用削除!E$4,統合マスタ!$A14,0)="","",OFFSET(マスタ非採用削除!E$4,統合マスタ!$A14,0)) -> 1 | S14: =IF(OFFSET(マスタ非採用削除!F$4,統合マスタ!$A14,0)="","",OFFSET(マスタ非採用削除!F$4,統合マスタ!$A14,0)) | T14: =IF(OFFSET(マスタ非採用削除!G$4,統合マスタ!$A14,0)="","",OFFSET(マスタ非採用削除!G$4,統合マスタ!$A14,0)) -> 13.8 | U14: =IF(OFFSET(マスタ非採用削除!H$4,統合マスタ!$A14,0)="","",OFFSET(マスタ非採用削除!H$4,統合マスタ!$A14,0)) -> ﾂﾑﾗﾎﾞｳﾌｳﾂｳｼｮｳｻﾝｴｷｽｶﾘｭｳ(ｲﾘｮｳﾖｳ) | ... Z14: =IF(OFFSET(マスタ非採用削除!M$4,統合マスタ!$A14,0)="","",OFFSET(マスタ非採用削除!M$4,統合マスタ!$A14,0)) -> 4
A15: =元データ!P12 -> 304 | B15: =B14+1 -> 11 | C15: =DBCS(元データ!A12) -> ０６８ ツムラ シャクヤクカンゾウトウ | D15: =元データ!B12 -> メディセオ | E15: =元データ!C12 -> 粉 | F15: =元データ!D12 -> 2.5ｇｘ42 | G15: =元データ!E12 -> ツムラ | H15: =元データ!F12 -> 10.4 | I15: =元データ!G12 -> 1092 | J15: =元データ!H12 -> 105 | K15: =元データ!I12 -> g | ... M15: =元データ!K12 -> 9.447619 | N15: =IF(OFFSET(マスタ非採用削除!A$4,統合マスタ!$A15,0)="","",OFFSET(マスタ非採用削除!A$4,統合マスタ!$A15,0)) -> ﾂﾑﾗ068 | O15: =IF(OFFSET(マスタ非採用削除!B$4,統合マスタ!$A15,0)="","",OFFSET(マスタ非採用削除!B$4,統合マスタ!$A15,0)) -> ﾂﾑﾗ068 | P15: =IF(OFFSET(マスタ非採用削除!C$4,統合マスタ!$A15,0)="","",OFFSET(マスタ非採用削除!C$4,統合マスタ!$A15,0)) -> ツムラ芍薬甘草湯エキス顆粒（医療用） | Q15: =IF(OFFSET(マスタ非採用削除!D$4,統合マスタ!$A15,0)="","",OFFSET(マスタ非採用削除!D$4,統合マスタ!$A15,0)) -> ｼｬｸ | R15: =IF(OFFSET(マスタ非採用削除!E$4,統合マスタ!$A15,0)="","",OFFSET(マスタ非採用削除!E$4,統合マスタ!$A15,0)) -> 1 | S15: =IF(OFFSET(マスタ非採用削除!F$4,統合マスタ!$A15,0)="","",OFFSET(マスタ非採用削除!F$4,統合マスタ!$A15,0)) | T15: =IF(OFFSET(マスタ非採用削除!G$4,統合マスタ!$A15,0)="","",OFFSET(マスタ非採用削除!G$4,統合マスタ!$A15,0)) -> 10.4 | U15: =IF(OFFSET(マスタ非採用削除!H$4,統合マスタ!$A15,0)="","",OFFSET(マスタ非採用削除!H$4,統合マスタ!$A15,0)) -> ﾂﾑﾗｼｬｸﾔｸｶﾝｿﾞｳﾄｳｴｷｽｶﾘｭｳ(ｲﾘｮｳﾖｳ) | ... Z15: =IF(OFFSET(マスタ非採用削除!M$4,統合マスタ!$A15,0)="","",OFFSET(マスタ非採用削除!M$4,統合マスタ!$A15,0)) -> 4
A16: =元データ!P13 -> 305 | B16: =B15+1 -> 12 | C16: =DBCS(元データ!A13) -> ０８３ ツムラ ヨクカンサンカチンピハンゲ | D16: =元データ!B13 -> メディセオ | E16: =元データ!C13 -> 粉 | F16: =元データ!D13 -> 2.5ｇｘ189 | G16: =元データ!E13 -> ツムラ | H16: =元データ!F13 -> 14.4 | I16: =元データ!G13 -> 6804 | J16: =元データ!H13 -> 472.5 | K16: =元データ!I13 -> g | ... M16: =元データ!K13 -> 12.835979 | N16: =IF(OFFSET(マスタ非採用削除!A$4,統合マスタ!$A16,0)="","",OFFSET(マスタ非採用削除!A$4,統合マスタ!$A16,0)) -> ﾂﾑﾗ083 | O16: =IF(OFFSET(マスタ非採用削除!B$4,統合マスタ!$A16,0)="","",OFFSET(マスタ非採用削除!B$4,統合マスタ!$A16,0)) -> ﾂﾑﾗ083 | P16: =IF(OFFSET(マスタ非採用削除!C$4,統合マスタ!$A16,0)="","",OFFSET(マスタ非採用削除!C$4,統合マスタ!$A16,0)) -> ツムラ抑肝散加陳皮半夏エキス顆粒（医療用） | Q16: =IF(OFFSET(マスタ非採用削除!D$4,統合マスタ!$A16,0)="","",OFFSET(マスタ非採用削除!D$4,統合マスタ!$A16,0)) -> ﾖｸｶﾁﾝ | R16: =IF(OFFSET(マスタ非採用削除!E$4,統合マスタ!$A16,0)="","",OFFSET(マスタ非採用削除!E$4,統合マスタ!$A16,0)) -> 1 | S16: =IF(OFFSET(マスタ非採用削除!F$4,統合マスタ!$A16,0)="","",OFFSET(マスタ非採用削除!F$4,統合マスタ!$A16,0)) | T16: =IF(OFFSET(マスタ非採用削除!G$4,統合マスタ!$A16,0)="","",OFFSET(マスタ非採用削除!G$4,統合マスタ!$A16,0)) -> 14.4 | U16: =IF(OFFSET(マスタ非採用削除!H$4,統合マスタ!$A16,0)="","",OFFSET(マスタ非採用削除!H$4,統合マスタ!$A16,0)) -> ﾂﾑﾗﾖｸｶﾝｻﾝｶﾁﾝﾋﾟﾊﾝｹﾞｴｷｽｶﾘｭｳ(ｲﾘｮｳﾖｳ) | ... Z16: =IF(OFFSET(マスタ非採用削除!M$4,統合マスタ!$A16,0)="","",OFFSET(マスタ非採用削除!M$4,統合マスタ!$A16,0)) -> 4
A17: =元データ!P14 -> 306 | B17: =B16+1 -> 13 | C17: =DBCS(元データ!A14) -> １００ ツムラ ダイケンチユウトウ | D17: =元データ!B14 -> メディセオ | E17: =元データ!C14 -> 粉 | F17: =元データ!D14 -> 2.5ｇX189 | G17: =元データ!E14 -> ツムラ | H17: =元データ!F14 -> 13.7 | I17: =元データ!G14 -> 6473.25 | J17: =元データ!H14 -> 472.5 | K17: =元データ!I14 -> g | ... M17: =元データ!K14 -> 12.334392 | N17: =IF(OFFSET(マスタ非採用削除!A$4,統合マスタ!$A17,0)="","",OFFSET(マスタ非採用削除!A$4,統合マスタ!$A17,0)) -> ﾂﾑﾗ100 | O17: =IF(OFFSET(マスタ非採用削除!B$4,統合マスタ!$A17,0)="","",OFFSET(マスタ非採用削除!B$4,統合マスタ!$A17,0)) -> ﾂﾑﾗ100 | P17: =IF(OFFSET(マスタ非採用削除!C$4,統合マスタ!$A17,0)="","",OFFSET(マスタ非採用削除!C$4,統合マスタ!$A17,0)) -> ツムラ大建中湯エキス顆粒（医療用） | Q17: =IF(OFFSET(マスタ非採用削除!D$4,統合マスタ!$A17,0)="","",OFFSET(マスタ非採用削除!D$4,統合マスタ!$A17,0)) -> ﾀﾞｲｹﾝﾁ | R17: =IF(OFFSET(マスタ非採用削除!E$4,統合マスタ!$A17,0)="","",OFFSET(マスタ非採用削除!E$4,統合マスタ!$A17,0)) -> 1 | S17: =IF(OFFSET(マスタ非採用削除!F$4,統合マスタ!$A17,0)="","",OFFSET(マスタ非採用削除!F$4,統合マスタ!$A17,0)) | T17: =IF(OFFSET(マスタ非採用削除!G$4,統合マスタ!$A17,0)="","",OFFSET(マスタ非採用削除!G$4,統合マスタ!$A17,0)) -> 13.7 | U17: =IF(OFFSET(マスタ非採用削除!H$4,統合マスタ!$A17,0)="","",OFFSET(マスタ非採用削除!H$4,統合マスタ!$A17,0)) -> ﾂﾑﾗﾀﾞｲｹﾝﾁｭｳﾄｳｴｷｽｶﾘｭｳ(ｲﾘｮｳﾖｳ) | ... Z17: =IF(OFFSET(マスタ非採用削除!M$4,統合マスタ!$A17,0)="","",OFFSET(マスタ非採用削除!M$4,統合マスタ!$A17,0)) -> 4
... A23: =元データ!P20 -> 140 | B23: =B22+1 -> 19 | C23: =DBCS(元データ!A20) -> ＥＫ１５ 黄連解毒湯エキス細粒 | D23: =元データ!B20 -> メディセオ | E23: =元データ!C20 -> 粉 | F23: =元データ!D20 -> 2ｇｘ42包 | G23: =元データ!E20 -> クラシエ | H23: =元データ!F20 -> 13.3 | I23: =元データ!G20 -> 1117.2 | J23: =元データ!H20 -> 84 | K23: =元データ!I20 -> g | ... M23: =元データ!K20 -> 12.083333 | N23: =IF(OFFSET(マスタ非採用削除!A$4,統合マスタ!$A23,0)="","",OFFSET(マスタ非採用削除!A$4,統合マスタ!$A23,0)) -> ｸﾗｼ015 | O23: =IF(OFFSET(マスタ非採用削除!B$4,統合マスタ!$A23,0)="","",OFFSET(マスタ非採用削除!B$4,統合マスタ!$A23,0)) -> ｸﾗｼ015 | P23: =IF(OFFSET(マスタ非採用削除!C$4,統合マスタ!$A23,0)="","",OFFSET(マスタ非採用削除!C$4,統合マスタ!$A23,0)) -> クラシエ黄連解毒湯エキス細粒 | Q23: =IF(OFFSET(マスタ非採用削除!D$4,統合マスタ!$A23,0)="","",OFFSET(マスタ非採用削除!D$4,統合マスタ!$A23,0)) -> ｵｳ | R23: =IF(OFFSET(マスタ非採用削除!E$4,統合マスタ!$A23,0)="","",OFFSET(マスタ非採用削除!E$4,統合マスタ!$A23,0)) -> 2 | S23: =IF(OFFSET(マスタ非採用削除!F$4,統合マスタ!$A23,0)="","",OFFSET(マスタ非採用削除!F$4,統合マスタ!$A23,0)) | T23: =IF(OFFSET(マスタ非採用削除!G$4,統合マスタ!$A23,0)="","",OFFSET(マスタ非採用削除!G$4,統合マスタ!$A23,0)) -> 13.3 | U23: =IF(OFFSET(マスタ非採用削除!H$4,統合マスタ!$A23,0)="","",OFFSET(マスタ非採用削除!H$4,統合マスタ!$A23,0)) -> ｸﾗｼｴｵｳﾚﾝｹﾞﾄﾞｸﾄｳｴｷｽｻｲﾘｭｳ | ... Z23: =IF(OFFSET(マスタ非採用削除!M$4,統合マスタ!$A23,0)="","",OFFSET(マスタ非採用削除!M$4,統合マスタ!$A23,0)) -> 4
A24: =元データ!P21 -> 非採用 | B24: =B23+1 -> 20 | C24: =DBCS(元データ!A21) -> ＥＫ１９ 小青竜湯エキス細粒 | D24: =元データ!B21 -> アルフレッサ | E24: =元データ!C21 | F24: =元データ!D21 -> 2ｇｘ42包 | G24: =元データ!E21 -> クラシエ | H24: =元データ!F21 -> 24.1 | I24: =元データ!G21 -> 2024.4 | J24: =元データ!H21 -> 84 | K24: =元データ!I21 -> g | ... M24: =元データ!K21 -> 21.904762 | N24: =IF(OFFSET(マスタ非採用削除!A$4,統合マスタ!$A24,0)="","",OFFSET(マスタ非採用削除!A$4,統合マスタ!$A24,0)) -> #VALUE! | O24: =IF(OFFSET(マスタ非採用削除!B$4,統合マスタ!$A24,0)="","",OFFSET(マスタ非採用削除!B$4,統合マスタ!$A24,0)) -> #VALUE! | P24: =IF(OFFSET(マスタ非採用削除!C$4,統合マスタ!$A24,0)="","",OFFSET(マスタ非採用削除!C$4,統合マスタ!$A24,0)) -> #VALUE! | Q24: =IF(OFFSET(マスタ非採用削除!D$4,統合マスタ!$A24,0)="","",OFFSET(マスタ非採用削除!D$4,統合マスタ!$A24,0)) -> #VALUE! | R24: =IF(OFFSET(マスタ非採用削除!E$4,統合マスタ!$A24,0)="","",OFFSET(マスタ非採用削除!E$4,統合マスタ!$A24,0)) -> #VALUE! | S24: =IF(OFFSET(マスタ非採用削除!F$4,統合マスタ!$A24,0)="","",OFFSET(マスタ非採用削除!F$4,統合マスタ!$A24,0)) -> #VALUE! | T24: =IF(OFFSET(マスタ非採用削除!G$4,統合マスタ!$A24,0)="","",OFFSET(マスタ非採用削除!G$4,統合マスタ!$A24,0)) -> #VALUE! | U24: =IF(OFFSET(マスタ非採用削除!H$4,統合マスタ!$A24,0)="","",OFFSET(マスタ非採用削除!H$4,統合マスタ!$A24,0)) -> #VALUE! | ... Z24: =IF(OFFSET(マスタ非採用削除!M$4,統合マスタ!$A24,0)="","",OFFSET(マスタ非採用削除!M$4,統合マスタ!$A24,0)) -> #VALUE! | AA24: 非採用
A25: =元データ!P22 -> 141 | B25: =B24+1 -> 21 | C25: =DBCS(元データ!A22) -> ＥＫ２４ 加味逍遥散料エキス細粒 | D25: =元データ!B22 -> メディセオ | E25: =元データ!C22 -> 粉 | F25: =元データ!D22 -> 2ｇｘ42包 | G25: =元データ!E22 -> クラシエ | H25: =元データ!F22 -> 18.3 | I25: =元データ!G22 -> 1537.2 | J25: =元データ!H22 -> 84 | K25: =元データ!I22 -> g | ... M25: =元データ!K22 -> 16.630952 | N25: =IF(OFFSET(マスタ非採用削除!A$4,統合マスタ!$A25,0)="","",OFFSET(マスタ非採用削除!A$4,統合マスタ!$A25,0)) -> ｸﾗｼ024 | O25: =IF(OFFSET(マスタ非採用削除!B$4,統合マスタ!$A25,0)="","",OFFSET(マスタ非採用削除!B$4,統合マスタ!$A25,0)) -> ｸﾗｼ024 | P25: =IF(OFFSET(マスタ非採用削除!C$4,統合マスタ!$A25,0)="","",OFFSET(マスタ非採用削除!C$4,統合マスタ!$A25,0)) -> クラシエ加味逍遙散料エキス細粒 | Q25: =IF(OFFSET(マスタ非採用削除!D$4,統合マスタ!$A25,0)="","",OFFSET(マスタ非採用削除!D$4,統合マスタ!$A25,0)) -> ｶﾐｼｮ1 | R25: =IF(OFFSET(マスタ非採用削除!E$4,統合マスタ!$A25,0)="","",OFFSET(マスタ非採用削除!E$4,統合マスタ!$A25,0)) -> 1 | S25: =IF(OFFSET(マスタ非採用削除!F$4,統合マスタ!$A25,0)="","",OFFSET(マスタ非採用削除!F$4,統合マスタ!$A25,0)) | T25: =IF(OFFSET(マスタ非採用削除!G$4,統合マスタ!$A25,0)="","",OFFSET(マスタ非採用削除!G$4,統合マスタ!$A25,0)) -> 18.3 | U25: =IF(OFFSET(マスタ非採用削除!H$4,統合マスタ!$A25,0)="","",OFFSET(マスタ非採用削除!H$4,統合マスタ!$A25,0)) -> ｸﾗｼｴｶﾐｼｮｳﾖｳｻﾝﾘｮｳｴｷｽｻｲﾘｭｳ | ... Z25: =IF(OFFSET(マスタ非採用削除!M$4,統合マスタ!$A25,0)="","",OFFSET(マスタ非採用削除!M$4,統合マスタ!$A25,0)) -> 4
A26: =元データ!P23 -> 142 | B26: =B25+1 -> 22 | C26: =DBCS(元データ!A23) -> ＥＫ４０ 猪苓湯エキス細粒 | D26: =元データ!B23 -> メディセオ | E26: =元データ!C23 -> 粉 | F26: =元データ!D23 -> 2ｇｘ42包 | G26: =元データ!E23 -> クラシエ | H26: =元データ!F23 -> 14.8 | I26: =元データ!G23 -> 1243.2 | J26: =元データ!H23 -> 84 | K26: =元データ!I23 -> g | ... M26: =元データ!K23 -> 13.452381 | N26: =IF(OFFSET(マスタ非採用削除!A$4,統合マスタ!$A26,0)="","",OFFSET(マスタ非採用削除!A$4,統合マスタ!$A26,0)) -> ｸﾗｼ040 | O26: =IF(OFFSET(マスタ非採用削除!B$4,統合マスタ!$A26,0)="","",OFFSET(マスタ非採用削除!B$4,統合マスタ!$A26,0)) -> ｸﾗｼ040 | P26: =IF(OFFSET(マスタ非採用削除!C$4,統合マスタ!$A26,0)="","",OFFSET(マスタ非採用削除!C$4,統合マスタ!$A26,0)) -> クラシエ猪苓湯エキス細粒 | Q26: =IF(OFFSET(マスタ非採用削除!D$4,統合マスタ!$A26,0)="","",OFFSET(マスタ非採用削除!D$4,統合マスタ!$A26,0)) -> ﾁｮﾚ | R26: =IF(OFFSET(マスタ非採用削除!E$4,統合マスタ!$A26,0)="","",OFFSET(マスタ非採用削除!E$4,統合マスタ!$A26,0)) -> 2 | S26: =IF(OFFSET(マスタ非採用削除!F$4,統合マスタ!$A26,0)="","",OFFSET(マスタ非採用削除!F$4,統合マスタ!$A26,0)) | T26: =IF(OFFSET(マスタ非採用削除!G$4,統合マスタ!$A26,0)="","",OFFSET(マスタ非採用削除!G$4,統合マスタ!$A26,0)) -> 14.8 | U26: =IF(OFFSET(マスタ非採用削除!H$4,統合マスタ!$A26,0)="","",OFFSET(マスタ非採用削除!H$4,統合マスタ!$A26,0)) -> ｸﾗｼｴﾁｮﾚｲﾄｳｴｷｽｻｲﾘｭｳ | ... Z26: =IF(OFFSET(マスタ非採用削除!M$4,統合マスタ!$A26,0)="","",OFFSET(マスタ非採用削除!M$4,統合マスタ!$A26,0)) -> 4
A27: =元データ!P24 -> 143 | B27: =B26+1 -> 23 | C27: =DBCS(元データ!A24) -> ＥＫ４１ 補中益気湯エキス細粒 | D27: =元データ!B24 -> メディセオ | E27: =元データ!C24 -> 粉 | F27: =元データ!D24 -> 2.5ｇｘ294 | G27: =元データ!E24 -> クラシエ | H27: =元データ!F24 -> 20.4 | I27: =元データ!G24 -> 14994 | J27: =元データ!H24 -> 735 | K27: =元データ!I24 -> g | ... M27: =元データ!K24 -> 18.17415 | N27: =IF(OFFSET(マスタ非採用削除!A$4,統合マスタ!$A27,0)="","",OFFSET(マスタ非採用削除!A$4,統合マスタ!$A27,0)) -> ｸﾗｼ041 | O27: =IF(OFFSET(マスタ非採用削除!B$4,統合マスタ!$A27,0)="","",OFFSET(マスタ非採用削除!B$4,統合マスタ!$A27,0)) -> ｸﾗｼ041 | P27: =IF(OFFSET(マスタ非採用削除!C$4,統合マスタ!$A27,0)="","",OFFSET(マスタ非採用削除!C$4,統合マスタ!$A27,0)) -> クラシエ補中益気湯エキス細粒 | Q27: =IF(OFFSET(マスタ非採用削除!D$4,統合マスタ!$A27,0)="","",OFFSET(マスタ非採用削除!D$4,統合マスタ!$A27,0)) -> ﾎﾁｭｳ | R27: =IF(OFFSET(マスタ非採用削除!E$4,統合マスタ!$A27,0)="","",OFFSET(マスタ非採用削除!E$4,統合マスタ!$A27,0)) -> 1 | S27: =IF(OFFSET(マスタ非採用削除!F$4,統合マスタ!$A27,0)="","",OFFSET(マスタ非採用削除!F$4,統合マスタ!$A27,0)) | T27: =IF(OFFSET(マスタ非採用削除!G$4,統合マスタ!$A27,0)="","",OFFSET(マスタ非採用削除!G$4,統合マスタ!$A27,0)) -> 20.4 | U27: =IF(OFFSET(マスタ非採用削除!H$4,統合マスタ!$A27,0)="","",OFFSET(マスタ非採用削除!H$4,統合マスタ!$A27,0)) -> ｸﾗｼｴﾎﾁｭｳｴｯｷﾄｳｴｷｽｻｲﾘｭｳ | ... Z27: =IF(OFFSET(マスタ非採用削除!M$4,統合マスタ!$A27,0)="","",OFFSET(マスタ非採用削除!M$4,統合マスタ!$A27,0)) -> 4
A28: =元データ!P25 -> 59 | B28: =B27+1 -> 24 | C28: =DBCS(元データ!A25) -> ＥＰＬカプセル２５０ｍｇ 販売中止 | D28: =元データ!B25 -> アルフレッサ | E28: =元データ!C25 -> ＰＴＰ | F28: =元データ!D25 -> ４００Ｐ | G28: =元データ!E25 -> アルフレッサファーマ | H28: =元データ!F25 -> 6.1 | I28: =元データ!G25 -> 2440 | J28: =元データ!H25 -> 400 | K28: =元データ!I25 -> cap | ... M28: =元データ!K25 -> 5.545 | N28: =IF(OFFSET(マスタ非採用削除!A$4,統合マスタ!$A28,0)="","",OFFSET(マスタ非採用削除!A$4,統合マスタ!$A28,0)) -> ｲﾋｴ001 | O28: =IF(OFFSET(マスタ非採用削除!B$4,統合マスタ!$A28,0)="","",OFFSET(マスタ非採用削除!B$4,統合マスタ!$A28,0)) -> ｲﾋｴ001 | P28: =IF(OFFSET(マスタ非採用削除!C$4,統合マスタ!$A28,0)="","",OFFSET(マスタ非採用削除!C$4,統合マスタ!$A28,0)) -> ＥＰＬカプセル２５０ｍｇ | Q28: =IF(OFFSET(マスタ非採用削除!D$4,統合マスタ!$A28,0)="","",OFFSET(マスタ非採用削除!D$4,統合マスタ!$A28,0)) -> EPL** | R28: =IF(OFFSET(マスタ非採用削除!E$4,統合マスタ!$A28,0)="","",OFFSET(マスタ非採用削除!E$4,統合マスタ!$A28,0)) -> 1 | S28: =IF(OFFSET(マスタ非採用削除!F$4,統合マスタ!$A28,0)="","",OFFSET(マスタ非採用削除!F$4,統合マスタ!$A28,0)) | T28: =IF(OFFSET(マスタ非採用削除!G$4,統合マスタ!$A28,0)="","",OFFSET(マスタ非採用削除!G$4,統合マスタ!$A28,0)) -> 6.1 | U28: =IF(OFFSET(マスタ非採用削除!H$4,統合マスタ!$A28,0)="","",OFFSET(マスタ非採用削除!H$4,統合マスタ!$A28,0)) -> EPLｶﾌﾟｾﾙ250mg | ... Z28: =IF(OFFSET(マスタ非採用削除!M$4,統合マスタ!$A28,0)="","",OFFSET(マスタ非採用削除!M$4,統合マスタ!$A28,0)) -> 5
A29: =元データ!P26 -> 76 | B29: =B28+1 -> 25 | C29: =DBCS(元データ!A26) -> ＳＰトローチ０．２５ｍｇ「明治」 | D29: =元データ!B26 -> メディセオ | E29: =元データ!C26 -> PTP | F29: =元データ!D26 -> 1200T | G29: =元データ!E26 -> meijiseika | H29: =元データ!F26 -> 5.9 | I29: =元データ!G26 -> 7080 | J29: =元データ!H26 -> 1200 | K29: =元データ!I26 -> 錠 | ... M29: =元データ!K26 -> 5.3625 | N29: =IF(OFFSET(マスタ非採用削除!A$4,統合マスタ!$A29,0)="","",OFFSET(マスタ非採用削除!A$4,統合マスタ!$A29,0)) -> ｴｽﾋ001 | O29: =IF(OFFSET(マスタ非採用削除!B$4,統合マスタ!$A29,0)="","",OFFSET(マスタ非採用削除!B$4,統合マスタ!$A29,0)) -> ｴｽﾋ001 | P29: =IF(OFFSET(マスタ非採用削除!C$4,統合マスタ!$A29,0)="","",OFFSET(マスタ非採用削除!C$4,統合マスタ!$A29,0)) -> ＳＰトローチ０．２５ｍｇ「明治」 | Q29: =IF(OFFSET(マスタ非採用削除!D$4,統合マスタ!$A29,0)="","",OFFSET(マスタ非採用削除!D$4,統合マスタ!$A29,0)) -> SPﾄ | R29: =IF(OFFSET(マスタ非採用削除!E$4,統合マスタ!$A29,0)="","",OFFSET(マスタ非採用削除!E$4,統合マスタ!$A29,0)) -> 1 | S29: =IF(OFFSET(マスタ非採用削除!F$4,統合マスタ!$A29,0)="","",OFFSET(マスタ非採用削除!F$4,統合マスタ!$A29,0)) | T29: =IF(OFFSET(マスタ非採用削除!G$4,統合マスタ!$A29,0)="","",OFFSET(マスタ非採用削除!G$4,統合マスタ!$A29,0)) -> 5.9 | U29: =IF(OFFSET(マスタ非採用削除!H$4,統合マスタ!$A29,0)="","",OFFSET(マスタ非採用削除!H$4,統合マスタ!$A29,0)) -> SPﾄﾛｰﾁ0.25mg｢ﾒｲｼﾞ｣ | ... Z29: =IF(OFFSET(マスタ非採用削除!M$4,統合マスタ!$A29,0)="","",OFFSET(マスタ非採用削除!M$4,統合マスタ!$A29,0)) -> 3
A30: =元データ!P27 -> 581 | B30: =B29+1 -> 26 | C30: =DBCS(元データ!A27) -> Ｔ７２ ヨクイニンエキス錠「コタロー」 | D30: =元データ!B27 -> メディセオ | E30: =元データ!C27 -> バラ | F30: =元データ!D27 -> 126Tx10 | G30: =元データ!E27 -> 小太郎漢方 | H30: =元データ!F27 -> 6.5 | I30: =元データ!G27 -> 8190 | J30: =元データ!H27 -> 1260 | K30: =元データ!I27 -> 錠 | ... M30: =元データ!K27 -> 5.9087302 | N30: =IF(OFFSET(マスタ非採用削除!A$4,統合マスタ!$A30,0)="","",OFFSET(マスタ非採用削除!A$4,統合マスタ!$A30,0)) -> ﾖｸｲ001 | O30: =IF(OFFSET(マスタ非採用削除!B$4,統合マスタ!$A30,0)="","",OFFSET(マスタ非採用削除!B$4,統合マスタ!$A30,0)) -> ﾖｸｲ001 | P30: =IF(OFFSET(マスタ非採用削除!C$4,統合マスタ!$A30,0)="","",OFFSET(マスタ非採用削除!C$4,統合マスタ!$A30,0)) -> ヨクイニンエキス錠「コタロー」 | Q30: =IF(OFFSET(マスタ非採用削除!D$4,統合マスタ!$A30,0)="","",OFFSET(マスタ非採用削除!D$4,統合マスタ!$A30,0)) | R30: =IF(OFFSET(マスタ非採用削除!E$4,統合マスタ!$A30,0)="","",OFFSET(マスタ非採用削除!E$4,統合マスタ!$A30,0)) -> 2 | S30: =IF(OFFSET(マスタ非採用削除!F$4,統合マスタ!$A30,0)="","",OFFSET(マスタ非採用削除!F$4,統合マスタ!$A30,0)) | T30: =IF(OFFSET(マスタ非採用削除!G$4,統合マスタ!$A30,0)="","",OFFSET(マスタ非採用削除!G$4,統合マスタ!$A30,0)) -> 6.5 | U30: =IF(OFFSET(マスタ非採用削除!H$4,統合マスタ!$A30,0)="","",OFFSET(マスタ非採用削除!H$4,統合マスタ!$A30,0)) -> ﾖｸｲﾆﾝｴｷｽｼﾞﾖｳｺﾀﾛ- | ... Z30: =IF(OFFSET(マスタ非採用削除!M$4,統合マスタ!$A30,0)="","",OFFSET(マスタ非採用削除!M$4,統合マスタ!$A30,0)) -> 15
A31: =元データ!P28 -> 22 | B31: =B30+1 -> 27 | C31: =DBCS(元データ!A28) -> アーチスト錠１．２５ｍｇ | D31: =元データ!B28 -> メディセオ | E31: =元データ!C28 -> PTP | F31: =元データ!D28 -> 100T | G31: =元データ!E28 -> 第一三共 | H31: =元データ!F28 -> 10.4 | I31: =元データ!G28 -> 1040 | J31: =元データ!H28 -> 100 | K31: =元データ!I28 -> 錠 | ... M31: =元データ!K28 -> 9.26 | N31: =IF(OFFSET(マスタ非採用削除!A$4,統合マスタ!$A31,0)="","",OFFSET(マスタ非採用削除!A$4,統合マスタ!$A31,0)) -> ｱﾁｽ001 | O31: =IF(OFFSET(マスタ非採用削除!B$4,統合マスタ!$A31,0)="","",OFFSET(マスタ非採用削除!B$4,統合マスタ!$A31,0)) -> ｱﾁｽ001 | P31: =IF(OFFSET(マスタ非採用削除!C$4,統合マスタ!$A31,0)="","",OFFSET(マスタ非採用削除!C$4,統合マスタ!$A31,0)) -> アーチスト錠１．２５ｍｇ | Q31: =IF(OFFSET(マスタ非採用削除!D$4,統合マスタ!$A31,0)="","",OFFSET(マスタ非採用削除!D$4,統合マスタ!$A31,0)) -> ｱｰﾁ | R31: =IF(OFFSET(マスタ非採用削除!E$4,統合マスタ!$A31,0)="","",OFFSET(マスタ非採用削除!E$4,統合マスタ!$A31,0)) -> 1 | S31: =IF(OFFSET(マスタ非採用削除!F$4,統合マスタ!$A31,0)="","",OFFSET(マスタ非採用削除!F$4,統合マスタ!$A31,0)) | T31: =IF(OFFSET(マスタ非採用削除!G$4,統合マスタ!$A31,0)="","",OFFSET(マスタ非採用削除!G$4,統合マスタ!$A31,0)) -> 10.4 | U31: =IF(OFFSET(マスタ非採用削除!H$4,統合マスタ!$A31,0)="","",OFFSET(マスタ非採用削除!H$4,統合マスタ!$A31,0)) -> ｱｰﾁｽﾄｼﾞｮｳ1.25mg | ... Z31: =IF(OFFSET(マスタ非採用削除!M$4,統合マスタ!$A31,0)="","",OFFSET(マスタ非採用削除!M$4,統合マスタ!$A31,0)) -> 5
A32: =元データ!P29 -> 非採用 | B32: =B31+1 -> 28 | C32: =DBCS(元データ!A29) -> アイファガン点眼液０．１％ | D32: =元データ!B29 | E32: =元データ!C29 | F32: =元データ!D29 -> 5ｍｌｘ5 | G32: =元データ!E29 -> 武田薬品工業 | H32: =元データ!F29 -> 268.9 | I32: =元データ!G29 -> 6722.5 | J32: =元データ!H29 -> 25 | K32: =元データ!I29 -> ｍｌ | ... M32: =元データ!K29 -> 234.32 | N32: =IF(OFFSET(マスタ非採用削除!A$4,統合マスタ!$A32,0)="","",OFFSET(マスタ非採用削除!A$4,統合マスタ!$A32,0)) -> #VALUE! | O32: =IF(OFFSET(マスタ非採用削除!B$4,統合マスタ!$A32,0)="","",OFFSET(マスタ非採用削除!B$4,統合マスタ!$A32,0)) -> #VALUE! | P32: =IF(OFFSET(マスタ非採用削除!C$4,統合マスタ!$A32,0)="","",OFFSET(マスタ非採用削除!C$4,統合マスタ!$A32,0)) -> #VALUE! | Q32: =IF(OFFSET(マスタ非採用削除!D$4,統合マスタ!$A32,0)="","",OFFSET(マスタ非採用削除!D$4,統合マスタ!$A32,0)) -> #VALUE! | R32: =IF(OFFSET(マスタ非採用削除!E$4,統合マスタ!$A32,0)="","",OFFSET(マスタ非採用削除!E$4,統合マスタ!$A32,0)) -> #VALUE! | S32: =IF(OFFSET(マスタ非採用削除!F$4,統合マスタ!$A32,0)="","",OFFSET(マスタ非採用削除!F$4,統合マスタ!$A32,0)) -> #VALUE! | T32: =IF(OFFSET(マスタ非採用削除!G$4,統合マスタ!$A32,0)="","",OFFSET(マスタ非採用削除!G$4,統合マスタ!$A32,0)) -> #VALUE! | U32: =IF(OFFSET(マスタ非採用削除!H$4,統合マスタ!$A32,0)="","",OFFSET(マスタ非採用削除!H$4,統合マスタ!$A32,0)) -> #VALUE! | ... Z32: =IF(OFFSET(マスタ非採用削除!M$4,統合マスタ!$A32,0)="","",OFFSET(マスタ非採用削除!M$4,統合マスタ!$A32,0)) -> #VALUE! | AA32: 非採用
A33: =元データ!P30 -> 非採用 | B33: =B32+1 -> 29 | C33: =DBCS(元データ!A30) -> アウィクリ注 フレックスタッチ 総量３００単位 | D33: =元データ!B30 -> アルフレッサ | E33: =元データ!C30 | F33: =元データ!D30 -> 0.43ｍｌｘ2kit | G33: =元データ!E30 -> ノボノルディスク | H33: =元データ!F30 -> 2081 | I33: =元データ!G30 -> 4162 | J33: =元データ!H30 -> 2 | K33: =元データ!I30 -> kit | ... M33: =元データ!K30 -> 1844.5 | N33: =IF(OFFSET(マスタ非採用削除!A$4,統合マスタ!$A33,0)="","",OFFSET(マスタ非採用削除!A$4,統合マスタ!$A33,0)) -> #VALUE! | O33: =IF(OFFSET(マスタ非採用削除!B$4,統合マスタ!$A33,0)="","",OFFSET(マスタ非採用削除!B$4,統合マスタ!$A33,0)) -> #VALUE! | P33: =IF(OFFSET(マスタ非採用削除!C$4,統合マスタ!$A33,0)="","",OFFSET(マスタ非採用削除!C$4,統合マスタ!$A33,0)) -> #VALUE! | Q33: =IF(OFFSET(マスタ非採用削除!D$4,統合マスタ!$A33,0)="","",OFFSET(マスタ非採用削除!D$4,統合マスタ!$A33,0)) -> #VALUE! | R33: =IF(OFFSET(マスタ非採用削除!E$4,統合マスタ!$A33,0)="","",OFFSET(マスタ非採用削除!E$4,統合マスタ!$A33,0)) -> #VALUE! | S33: =IF(OFFSET(マスタ非採用削除!F$4,統合マスタ!$A33,0)="","",OFFSET(マスタ非採用削除!F$4,統合マスタ!$A33,0)) -> #VALUE! | T33: =IF(OFFSET(マスタ非採用削除!G$4,統合マスタ!$A33,0)="","",OFFSET(マスタ非採用削除!G$4,統合マスタ!$A33,0)) -> #VALUE! | U33: =IF(OFFSET(マスタ非採用削除!H$4,統合マスタ!$A33,0)="","",OFFSET(マスタ非採用削除!H$4,統合マスタ!$A33,0)) -> #VALUE! | ... Z33: =IF(OFFSET(マスタ非採用削除!M$4,統合マスタ!$A33,0)="","",OFFSET(マスタ非採用削除!M$4,統合マスタ!$A33,0)) -> #VALUE! | AA33: 非採用
A34: =元データ!P31 -> 非採用 | B34: =B33+1 -> 30 | C34: =DBCS(元データ!A31) -> アキネトン細粒１％ | D34: =元データ!B31 | E34: =元データ!C31 -> 粉 | F34: =元データ!D31 -> 100ｇ | G34: =元データ!E31 -> 住友ファーマ | H34: =元データ!F31 -> 21.4 | I34: =元データ!G31 -> 2140 | J34: =元データ!H31 -> 100 | K34: =元データ!I31 -> ｇ | ... M34: =元データ!K31 -> 19.07 | N34: =IF(OFFSET(マスタ非採用削除!A$4,統合マスタ!$A34,0)="","",OFFSET(マスタ非採用削除!A$4,統合マスタ!$A34,0)) -> #VALUE! | O34: =IF(OFFSET(マスタ非採用削除!B$4,統合マスタ!$A34,0)="","",OFFSET(マスタ非採用削除!B$4,統合マスタ!$A34,0)) -> #VALUE! | P34: =IF(OFFSET(マスタ非採用削除!C$4,統合マスタ!$A34,0)="","",OFFSET(マスタ非採用削除!C$4,統合マスタ!$A34,0)) -> #VALUE! | Q34: =IF(OFFSET(マスタ非採用削除!D$4,統合マスタ!$A34,0)="","",OFFSET(マスタ非採用削除!D$4,統合マスタ!$A34,0)) -> #VALUE! | R34: =IF(OFFSET(マスタ非採用削除!E$4,統合マスタ!$A34,0)="","",OFFSET(マスタ非採用削除!E$4,統合マスタ!$A34,0)) -> #VALUE! | S34: =IF(OFFSET(マスタ非採用削除!F$4,統合マスタ!$A34,0)="","",OFFSET(マスタ非採用削除!F$4,統合マスタ!$A34,0)) -> #VALUE! | T34: =IF(OFFSET(マスタ非採用削除!G$4,統合マスタ!$A34,0)="","",OFFSET(マスタ非採用削除!G$4,統合マスタ!$A34,0)) -> #VALUE! | U34: =IF(OFFSET(マスタ非採用削除!H$4,統合マスタ!$A34,0)="","",OFFSET(マスタ非採用削除!H$4,統合マスタ!$A34,0)) -> #VALUE! | ... Z34: =IF(OFFSET(マスタ非採用削除!M$4,統合マスタ!$A34,0)="","",OFFSET(マスタ非採用削除!M$4,統合マスタ!$A34,0)) -> #VALUE! | AA34: 非採用
A35: =元データ!P32 -> 2 | B35: =B34+1 -> 31 | C35: =DBCS(元データ!A32) -> アキネトン注射液５ｍｇ | D35: =元データ!B32 | E35: =元データ!C32 | F35: =元データ!D32 -> １ｍＬ×5０Ａ | G35: =元データ!E32 -> 住友ファーマ | H35: =元データ!F32 -> 61 | I35: =元データ!G32 -> 3050 | J35: =元データ!H32 -> 50 | K35: =元データ!I32 -> A | ... M35: =元データ!K32 -> 54.36 | N35: =IF(OFFSET(マスタ非採用削除!A$4,統合マスタ!$A35,0)="","",OFFSET(マスタ非採用削除!A$4,統合マスタ!$A35,0)) -> ｱｷﾈ002 | O35: =IF(OFFSET(マスタ非採用削除!B$4,統合マスタ!$A35,0)="","",OFFSET(マスタ非採用削除!B$4,統合マスタ!$A35,0)) -> ｱｷﾈ002 | P35: =IF(OFFSET(マスタ非採用削除!C$4,統合マスタ!$A35,0)="","",OFFSET(マスタ非採用削除!C$4,統合マスタ!$A35,0)) -> アキネトン注射液５ｍｇ | Q35: =IF(OFFSET(マスタ非採用削除!D$4,統合マスタ!$A35,0)="","",OFFSET(マスタ非採用削除!D$4,統合マスタ!$A35,0)) -> ｱｷﾈﾄﾝﾁ | R35: =IF(OFFSET(マスタ非採用削除!E$4,統合マスタ!$A35,0)="","",OFFSET(マスタ非採用削除!E$4,統合マスタ!$A35,0)) -> 1 | S35: =IF(OFFSET(マスタ非採用削除!F$4,統合マスタ!$A35,0)="","",OFFSET(マスタ非採用削除!F$4,統合マスタ!$A35,0)) | T35: =IF(OFFSET(マスタ非採用削除!G$4,統合マスタ!$A35,0)="","",OFFSET(マスタ非採用削除!G$4,統合マスタ!$A35,0)) -> 61 | U35: =IF(OFFSET(マスタ非採用削除!H$4,統合マスタ!$A35,0)="","",OFFSET(マスタ非採用削除!H$4,統合マスタ!$A35,0)) -> ｱｷﾈﾄﾝﾁｭｳｼｬｴｷ5mg | ... Z35: =IF(OFFSET(マスタ非採用削除!M$4,統合マスタ!$A35,0)="","",OFFSET(マスタ非採用削除!M$4,統合マスタ!$A35,0)) -> 9
A36: =元データ!P33 -> 3 | B36: =B35+1 -> 32 | C36: =DBCS(元データ!A33) -> アクアチムクリーム１％ | D36: =元データ!B33 -> スズケン | E36: =元データ!C33 | F36: =元データ!D33 -> 10ｇX10 | G36: =元データ!E33 -> 大塚製薬 | H36: =元データ!F33 -> 20.7 | I36: =元データ!G33 -> 2070 | J36: =元データ!H33 -> 100 | K36: =元データ!I33 -> ｇ | ... M36: =元データ!K33 -> 18.41 | N36: =IF(OFFSET(マスタ非採用削除!A$4,統合マスタ!$A36,0)="","",OFFSET(マスタ非採用削除!A$4,統合マスタ!$A36,0)) -> ｱｸｱ001 | O36: =IF(OFFSET(マスタ非採用削除!B$4,統合マスタ!$A36,0)="","",OFFSET(マスタ非採用削除!B$4,統合マスタ!$A36,0)) -> ｱｸｱ001 | P36: =IF(OFFSET(マスタ非採用削除!C$4,統合マスタ!$A36,0)="","",OFFSET(マスタ非採用削除!C$4,統合マスタ!$A36,0)) -> アクアチムクリーム１％ | Q36: =IF(OFFSET(マスタ非採用削除!D$4,統合マスタ!$A36,0)="","",OFFSET(マスタ非採用削除!D$4,統合マスタ!$A36,0)) -> ｱｸｱﾁﾑ | R36: =IF(OFFSET(マスタ非採用削除!E$4,統合マスタ!$A36,0)="","",OFFSET(マスタ非採用削除!E$4,統合マスタ!$A36,0)) -> 1 | S36: =IF(OFFSET(マスタ非採用削除!F$4,統合マスタ!$A36,0)="","",OFFSET(マスタ非採用削除!F$4,統合マスタ!$A36,0)) | T36: =IF(OFFSET(マスタ非採用削除!G$4,統合マスタ!$A36,0)="","",OFFSET(マスタ非採用削除!G$4,統合マスタ!$A36,0)) -> 20.7 | U36: =IF(OFFSET(マスタ非採用削除!H$4,統合マスタ!$A36,0)="","",OFFSET(マスタ非採用削除!H$4,統合マスタ!$A36,0)) -> ｱｸｱﾁﾑｸﾘｰﾑ1% | ... Z36: =IF(OFFSET(マスタ非採用削除!M$4,統合マスタ!$A36,0)="","",OFFSET(マスタ非採用削除!M$4,統合マスタ!$A36,0)) -> 3
A37: =元データ!P34 -> 4 | B37: =B36+1 -> 33 | C37: =DBCS(元データ!A34) -> アクチット輸液 | D37: =元データ!B34 -> メディセオ | E37: =元データ!C34 | F37: =元データ!D34 -> 500ｍｌｘ20袋 | G37: =元データ!E34 -> 扶桑薬品 | H37: =元データ!F34 -> 341 | I37: =元データ!G34 -> 6820 | J37: =元データ!H34 -> 20 | K37: =元データ!I34 -> 袋 | ... M37: =元データ!K34 -> 303.75 | N37: =IF(OFFSET(マスタ非採用削除!A$4,統合マスタ!$A37,0)="","",OFFSET(マスタ非採用削除!A$4,統合マスタ!$A37,0)) -> ｱｸﾁ002 | O37: =IF(OFFSET(マスタ非採用削除!B$4,統合マスタ!$A37,0)="","",OFFSET(マスタ非採用削除!B$4,統合マスタ!$A37,0)) -> ｱｸﾁ002 | P37: =IF(OFFSET(マスタ非採用削除!C$4,統合マスタ!$A37,0)="","",OFFSET(マスタ非採用削除!C$4,統合マスタ!$A37,0)) -> アクチット輸液 | Q37: =IF(OFFSET(マスタ非採用削除!D$4,統合マスタ!$A37,0)="","",OFFSET(マスタ非採用削除!D$4,統合マスタ!$A37,0)) | R37: =IF(OFFSET(マスタ非採用削除!E$4,統合マスタ!$A37,0)="","",OFFSET(マスタ非採用削除!E$4,統合マスタ!$A37,0)) -> 1 | S37: =IF(OFFSET(マスタ非採用削除!F$4,統合マスタ!$A37,0)="","",OFFSET(マスタ非採用削除!F$4,統合マスタ!$A37,0)) | T37: =IF(OFFSET(マスタ非採用削除!G$4,統合マスタ!$A37,0)="","",OFFSET(マスタ非採用削除!G$4,統合マスタ!$A37,0)) -> 341 | U37: =IF(OFFSET(マスタ非採用削除!H$4,統合マスタ!$A37,0)="","",OFFSET(マスタ非採用削除!H$4,統合マスタ!$A37,0)) -> ｱｸﾁﾂﾄﾕｴｷ | ... Z37: =IF(OFFSET(マスタ非採用削除!M$4,統合マスタ!$A37,0)="","",OFFSET(マスタ非採用削除!M$4,統合マスタ!$A37,0)) -> 10
A38: =元データ!P35 -> 5 | B38: =B37+1 -> 34 | C38: =DBCS(元データ!A35) -> アクトシン軟膏３％ | D38: =元データ!B35 -> アルフレッサ | E38: =元データ!C35 | F38: =元データ!D35 -> 30ｇ | G38: =元データ!E35 -> マルホ | H38: =元データ!F35 -> 50 | I38: =元データ!G35 -> 1500 | J38: =元データ!H35 -> 30 | K38: =元データ!I35 -> g | ... M38: =元データ!K35 -> 41.7 | N38: =IF(OFFSET(マスタ非採用削除!A$4,統合マスタ!$A38,0)="","",OFFSET(マスタ非採用削除!A$4,統合マスタ!$A38,0)) -> ｱｸﾄ001 | O38: =IF(OFFSET(マスタ非採用削除!B$4,統合マスタ!$A38,0)="","",OFFSET(マスタ非採用削除!B$4,統合マスタ!$A38,0)) -> ｱｸﾄ001 | P38: =IF(OFFSET(マスタ非採用削除!C$4,統合マスタ!$A38,0)="","",OFFSET(マスタ非採用削除!C$4,統合マスタ!$A38,0)) -> アクトシン軟膏３％ | Q38: =IF(OFFSET(マスタ非採用削除!D$4,統合マスタ!$A38,0)="","",OFFSET(マスタ非採用削除!D$4,統合マスタ!$A38,0)) -> ｱｸﾄｼﾝ | R38: =IF(OFFSET(マスタ非採用削除!E$4,統合マスタ!$A38,0)="","",OFFSET(マスタ非採用削除!E$4,統合マスタ!$A38,0)) -> 1 | S38: =IF(OFFSET(マスタ非採用削除!F$4,統合マスタ!$A38,0)="","",OFFSET(マスタ非採用削除!F$4,統合マスタ!$A38,0)) | T38: =IF(OFFSET(マスタ非採用削除!G$4,統合マスタ!$A38,0)="","",OFFSET(マスタ非採用削除!G$4,統合マスタ!$A38,0)) -> 50 | U38: =IF(OFFSET(マスタ非採用削除!H$4,統合マスタ!$A38,0)="","",OFFSET(マスタ非採用削除!H$4,統合マスタ!$A38,0)) -> ｱｸﾄｼﾝﾅﾝｺｳ3% | ... Z38: =IF(OFFSET(マスタ非採用削除!M$4,統合マスタ!$A38,0)="","",OFFSET(マスタ非採用削除!M$4,統合マスタ!$A38,0)) -> 15
A39: =元データ!P36 -> 6 | B39: =B38+1 -> 35 | C39: =DBCS(元データ!A36) -> アザルフィジンＥＮ錠５００ｍｇ | D39: =元データ!B36 -> KSK | E39: =元データ!C36 -> PTP | F39: =元データ!D36 -> 100Ｔ | G39: =元データ!E36 -> ファイザー | H39: =元データ!F36 -> 25.9 | I39: =元データ!G36 -> 2590 | J39: =元データ!H36 -> 100 | K39: =元データ!I36 -> 錠 | ... M39: =元データ!K36 -> 23.08 | N39: =IF(OFFSET(マスタ非採用削除!A$4,統合マスタ!$A39,0)="","",OFFSET(マスタ非採用削除!A$4,統合マスタ!$A39,0)) -> ｱｻﾙ001 | O39: =IF(OFFSET(マスタ非採用削除!B$4,統合マスタ!$A39,0)="","",OFFSET(マスタ非採用削除!B$4,統合マスタ!$A39,0)) -> ｱｻﾙ001 | P39: =IF(OFFSET(マスタ非採用削除!C$4,統合マスタ!$A39,0)="","",OFFSET(マスタ非採用削除!C$4,統合マスタ!$A39,0)) -> アザルフィジンＥＮ錠５００ｍｇ | Q39: =IF(OFFSET(マスタ非採用削除!D$4,統合マスタ!$A39,0)="","",OFFSET(マスタ非採用削除!D$4,統合マスタ!$A39,0)) -> ｱｻﾞﾙ1 | R39: =IF(OFFSET(マスタ非採用削除!E$4,統合マスタ!$A39,0)="","",OFFSET(マスタ非採用削除!E$4,統合マスタ!$A39,0)) -> 2 | S39: =IF(OFFSET(マスタ非採用削除!F$4,統合マスタ!$A39,0)="","",OFFSET(マスタ非採用削除!F$4,統合マスタ!$A39,0)) | T39: =IF(OFFSET(マスタ非採用削除!G$4,統合マスタ!$A39,0)="","",OFFSET(マスタ非採用削除!G$4,統合マスタ!$A39,0)) -> 25.9 | U39: =IF(OFFSET(マスタ非採用削除!H$4,統合マスタ!$A39,0)="","",OFFSET(マスタ非採用削除!H$4,統合マスタ!$A39,0)) -> ｱｻﾞﾙﾌｨｼﾞﾝENｼﾞｮｳ500mg | ... Z39: =IF(OFFSET(マスタ非採用削除!M$4,統合マスタ!$A39,0)="","",OFFSET(マスタ非採用削除!M$4,統合マスタ!$A39,0)) -> 3
A40: =元データ!P37 -> 7 | B40: =B39+1 -> 36 | C40: =DBCS(元データ!A37) -> アシクロビル点滴静注用２５０ｍｇ「サワイ」 | D40: =元データ!B37 | E40: =元データ!C37 | F40: =元データ!D37 -> 10V | G40: =元データ!E37 -> 沢井製薬 | H40: =元データ!F37 -> 368 | I40: =元データ!G37 -> 3680 | J40: =元データ!H37 -> 10 | K40: =元データ!I37 -> V | ... M40: =元データ!K37 -> 323.8 | N40: =IF(OFFSET(マスタ非採用削除!A$4,統合マスタ!$A40,0)="","",OFFSET(マスタ非採用削除!A$4,統合マスタ!$A40,0)) -> ｱｼｸ001 | O40: =IF(OFFSET(マスタ非採用削除!B$4,統合マスタ!$A40,0)="","",OFFSET(マスタ非採用削除!B$4,統合マスタ!$A40,0)) -> ｱｼｸ001 | P40: =IF(OFFSET(マスタ非採用削除!C$4,統合マスタ!$A40,0)="","",OFFSET(マスタ非採用削除!C$4,統合マスタ!$A40,0)) -> アシクロビル点滴静注用２５０ｍｇ「サワイ」 | Q40: =IF(OFFSET(マスタ非採用削除!D$4,統合マスタ!$A40,0)="","",OFFSET(マスタ非採用削除!D$4,統合マスタ!$A40,0)) -> ｱｼｸﾛ | R40: =IF(OFFSET(マスタ非採用削除!E$4,統合マスタ!$A40,0)="","",OFFSET(マスタ非採用削除!E$4,統合マスタ!$A40,0)) -> 2 | S40: =IF(OFFSET(マスタ非採用削除!F$4,統合マスタ!$A40,0)="","",OFFSET(マスタ非採用削除!F$4,統合マスタ!$A40,0)) | T40: =IF(OFFSET(マスタ非採用削除!G$4,統合マスタ!$A40,0)="","",OFFSET(マスタ非採用削除!G$4,統合マスタ!$A40,0)) -> 368 | U40: =IF(OFFSET(マスタ非採用削除!H$4,統合マスタ!$A40,0)="","",OFFSET(マスタ非採用削除!H$4,統合マスタ!$A40,0)) -> ｱｼｸﾛﾋﾞﾙﾃﾝﾃｷｼﾞｮｳﾁｭｳﾖｳ250mg｢ｻﾜｲ｣ | ... Z40: =IF(OFFSET(マスタ非採用削除!M$4,統合マスタ!$A40,0)="","",OFFSET(マスタ非採用削除!M$4,統合マスタ!$A40,0)) -> 9
A41: =元データ!P38 -> 8 | B41: =B40+1 -> 37 | C41: =DBCS(元データ!A38) -> アジスロマイシン錠２５０ｍｇ「トーワ」 | D41: =元データ!B38 | E41: =元データ!C38 -> ＰＴＰ | F41: =元データ!D38 -> 60T | G41: =元データ!E38 -> 東和薬品 | H41: =元データ!F38 -> 60.7 | I41: =元データ!G38 -> 3642 | J41: =元データ!H38 -> 60 | K41: =元データ!I38 -> 錠 | ... M41: =元データ!K38 -> 49.2 | N41: =IF(OFFSET(マスタ非採用削除!A$4,統合マスタ!$A41,0)="","",OFFSET(マスタ非採用削除!A$4,統合マスタ!$A41,0)) -> ｱｼｽ001 | O41: =IF(OFFSET(マスタ非採用削除!B$4,統合マスタ!$A41,0)="","",OFFSET(マスタ非採用削除!B$4,統合マスタ!$A41,0)) -> ｱｼｽ001 | P41: =IF(OFFSET(マスタ非採用削除!C$4,統合マスタ!$A41,0)="","",OFFSET(マスタ非採用削除!C$4,統合マスタ!$A41,0)) -> アジスロマイシン錠２５０ｍｇ「トーワ」 | Q41: =IF(OFFSET(マスタ非採用削除!D$4,統合マスタ!$A41,0)="","",OFFSET(マスタ非採用削除!D$4,統合マスタ!$A41,0)) -> ｱｼﾞｽ | R41: =IF(OFFSET(マスタ非採用削除!E$4,統合マスタ!$A41,0)="","",OFFSET(マスタ非採用削除!E$4,統合マスタ!$A41,0)) -> 1 | S41: =IF(OFFSET(マスタ非採用削除!F$4,統合マスタ!$A41,0)="","",OFFSET(マスタ非採用削除!F$4,統合マスタ!$A41,0)) | T41: =IF(OFFSET(マスタ非採用削除!G$4,統合マスタ!$A41,0)="","",OFFSET(マスタ非採用削除!G$4,統合マスタ!$A41,0)) -> 60.7 | U41: =IF(OFFSET(マスタ非採用削除!H$4,統合マスタ!$A41,0)="","",OFFSET(マスタ非採用削除!H$4,統合マスタ!$A41,0)) -> ｱｼﾞｽﾛﾏｲｼﾝｼﾞｮｳ250mg｢ﾄｰﾜ｣ | ... Z41: =IF(OFFSET(マスタ非採用削除!M$4,統合マスタ!$A41,0)="","",OFFSET(マスタ非採用削除!M$4,統合マスタ!$A41,0)) -> 1
A42: =元データ!P39 -> 9 | B42: =B41+1 -> 38 | C42: =DBCS(元データ!A39) -> アジルサルタンＯＤ錠２０ｍｇ「サワイ」 | D42: =元データ!B39 -> アルフレッサ | E42: =元データ!C39 -> PTP | F42: =元データ!D39 -> 100T | G42: =元データ!E39 -> 沢井製薬 | H42: =元データ!F39 -> 27.4 | I42: =元データ!G39 -> 2740 | J42: =元データ!H39 -> 100 | K42: =元データ!I39 -> 錠 | ... M42: =元データ!K39 -> 20.82 | N42: =IF(OFFSET(マスタ非採用削除!A$4,統合マスタ!$A42,0)="","",OFFSET(マスタ非採用削除!A$4,統合マスタ!$A42,0)) -> ｱｼﾙ003 | O42: =IF(OFFSET(マスタ非採用削除!B$4,統合マスタ!$A42,0)="","",OFFSET(マスタ非採用削除!B$4,統合マスタ!$A42,0)) -> ｱｼﾙ003 | P42: =IF(OFFSET(マスタ非採用削除!C$4,統合マスタ!$A42,0)="","",OFFSET(マスタ非採用削除!C$4,統合マスタ!$A42,0)) -> アジルサルタンＯＤ錠２０ｍｇ「サワイ」 | Q42: =IF(OFFSET(マスタ非採用削除!D$4,統合マスタ!$A42,0)="","",OFFSET(マスタ非採用削除!D$4,統合マスタ!$A42,0)) | R42: =IF(OFFSET(マスタ非採用削除!E$4,統合マスタ!$A42,0)="","",OFFSET(マスタ非採用削除!E$4,統合マスタ!$A42,0)) -> 1 | S42: =IF(OFFSET(マスタ非採用削除!F$4,統合マスタ!$A42,0)="","",OFFSET(マスタ非採用削除!F$4,統合マスタ!$A42,0)) | T42: =IF(OFFSET(マスタ非採用削除!G$4,統合マスタ!$A42,0)="","",OFFSET(マスタ非採用削除!G$4,統合マスタ!$A42,0)) -> 27.4 | U42: =IF(OFFSET(マスタ非採用削除!H$4,統合マスタ!$A42,0)="","",OFFSET(マスタ非採用削除!H$4,統合マスタ!$A42,0)) -> ｱｼﾞﾙｻﾙﾀﾝODｼﾞﾖｳ20MGｻﾜｲ | ... Z42: =IF(OFFSET(マスタ非採用削除!M$4,統合マスタ!$A42,0)="","",OFFSET(マスタ非採用削除!M$4,統合マスタ!$A42,0)) -> 5
A43: =元データ!P40 -> 9 | B43: =B42+1 -> 39 | C43: =DBCS(元データ!A40) -> アジルサルタンＯＤ錠２０ｍｇ「サワイ」 | D43: =元データ!B40 -> アルフレッサ | E43: =元データ!C40 -> バラ | F43: =元データ!D40 -> 200T | G43: =元データ!E40 -> 沢井製薬 | H43: =元データ!F40 -> 27.4 | I43: =元データ!G40 -> 5480 | J43: =元データ!H40 -> 200 | K43: =元データ!I40 -> 錠 | ... M43: =元データ!K40 -> 20.825 | N43: =IF(OFFSET(マスタ非採用削除!A$4,統合マスタ!$A43,0)="","",OFFSET(マスタ非採用削除!A$4,統合マスタ!$A43,0)) -> ｱｼﾙ003 | O43: =IF(OFFSET(マスタ非採用削除!B$4,統合マスタ!$A43,0)="","",OFFSET(マスタ非採用削除!B$4,統合マスタ!$A43,0)) -> ｱｼﾙ003 | P43: =IF(OFFSET(マスタ非採用削除!C$4,統合マスタ!$A43,0)="","",OFFSET(マスタ非採用削除!C$4,統合マスタ!$A43,0)) -> アジルサルタンＯＤ錠２０ｍｇ「サワイ」 | Q43: =IF(OFFSET(マスタ非採用削除!D$4,統合マスタ!$A43,0)="","",OFFSET(マスタ非採用削除!D$4,統合マスタ!$A43,0)) | R43: =IF(OFFSET(マスタ非採用削除!E$4,統合マスタ!$A43,0)="","",OFFSET(マスタ非採用削除!E$4,統合マスタ!$A43,0)) -> 1 | S43: =IF(OFFSET(マスタ非採用削除!F$4,統合マスタ!$A43,0)="","",OFFSET(マスタ非採用削除!F$4,統合マスタ!$A43,0)) | T43: =IF(OFFSET(マスタ非採用削除!G$4,統合マスタ!$A43,0)="","",OFFSET(マスタ非採用削除!G$4,統合マスタ!$A43,0)) -> 27.4 | U43: =IF(OFFSET(マスタ非採用削除!H$4,統合マスタ!$A43,0)="","",OFFSET(マスタ非採用削除!H$4,統合マスタ!$A43,0)) -> ｱｼﾞﾙｻﾙﾀﾝODｼﾞﾖｳ20MGｻﾜｲ | ... Z43: =IF(OFFSET(マスタ非採用削除!M$4,統合マスタ!$A43,0)="","",OFFSET(マスタ非採用削除!M$4,統合マスタ!$A43,0)) -> 5
A44: =元データ!P41 -> 10 | B44: =B43+1 -> 40 | C44: =DBCS(元データ!A41) -> アスコルビン酸注５００ｍｇ「イセイ」 | D44: =元データ!B41 -> アルフレッサ | E44: =元データ!C41 | F44: =元データ!D41 -> 2ｍｌｘ50Ａ | G44: =元データ!E41 -> 愛知イセイ | H44: =元データ!F41 -> 100 | I44: =元データ!G41 -> 5000 | J44: =元データ!H41 -> 50 | K44: =元データ!I41 -> A | ... M44: =元データ!K41 -> 90.9 | N44: =IF(OFFSET(マスタ非採用削除!A$4,統合マスタ!$A44,0)="","",OFFSET(マスタ非採用削除!A$4,統合マスタ!$A44,0)) -> ｱｽｺ003 | O44: =IF(OFFSET(マスタ非採用削除!B$4,統合マスタ!$A44,0)="","",OFFSET(マスタ非採用削除!B$4,統合マスタ!$A44,0)) -> ｱｽｺ003 | P44: =IF(OFFSET(マスタ非採用削除!C$4,統合マスタ!$A44,0)="","",OFFSET(マスタ非採用削除!C$4,統合マスタ!$A44,0)) -> アスコルビン酸注５００ｍｇ「イセイ」 | Q44: =IF(OFFSET(マスタ非採用削除!D$4,統合マスタ!$A44,0)="","",OFFSET(マスタ非採用削除!D$4,統合マスタ!$A44,0)) | R44: =IF(OFFSET(マスタ非採用削除!E$4,統合マスタ!$A44,0)="","",OFFSET(マスタ非採用削除!E$4,統合マスタ!$A44,0)) -> 1 | S44: =IF(OFFSET(マスタ非採用削除!F$4,統合マスタ!$A44,0)="","",OFFSET(マスタ非採用削除!F$4,統合マスタ!$A44,0)) | T44: =IF(OFFSET(マスタ非採用削除!G$4,統合マスタ!$A44,0)="","",OFFSET(マスタ非採用削除!G$4,統合マスタ!$A44,0)) -> 100 | U44: =IF(OFFSET(マスタ非採用削除!H$4,統合マスタ!$A44,0)="","",OFFSET(マスタ非採用削除!H$4,統合マスタ!$A44,0)) -> ｱｽｺﾙﾋﾞﾝｻﾝﾁﾕｳ500MGｲｾｲ | ... Z44: =IF(OFFSET(マスタ非採用削除!M$4,統合マスタ!$A44,0)="","",OFFSET(マスタ非採用削除!M$4,統合マスタ!$A44,0)) -> 11
A45: =元データ!P42 -> 0 | B45: =B44+1 -> 41 | C45: =DBCS(元データ!A42) -> アスコルビン酸注射液５００ｍｇ「トーワ」 | D45: =元データ!B42 -> 東和薬品 | E45: =元データ!C42 | F45: =元データ!D42 -> 2ｍｌｘ1００Ａ | G45: =元データ!E42 -> 東和薬品 | H45: =元データ!F42 -> 100 | I45: =元データ!G42 -> 10000 | J45: =元データ!H42 -> 100 | K45: =元データ!I42 -> A | ... M45: =元データ!K42 -> 72.2 | N45: =IF(OFFSET(マスタ非採用削除!A$4,統合マスタ!$A45,0)="","",OFFSET(マスタ非採用削除!A$4,統合マスタ!$A45,0)) -> コード(区分値) | O45: =IF(OFFSET(マスタ非採用削除!B$4,統合マスタ!$A45,0)="","",OFFSET(マスタ非採用削除!B$4,統合マスタ!$A45,0)) -> コード | P45: =IF(OFFSET(マスタ非採用削除!C$4,統合マスタ!$A45,0)="","",OFFSET(マスタ非採用削除!C$4,統合マスタ!$A45,0)) -> 名称 | Q45: =IF(OFFSET(マスタ非採用削除!D$4,統合マスタ!$A45,0)="","",OFFSET(マスタ非採用削除!D$4,統合マスタ!$A45,0)) -> ホストコード | R45: =IF(OFFSET(マスタ非採用削除!E$4,統合マスタ!$A45,0)="","",OFFSET(マスタ非採用削除!E$4,統合マスタ!$A45,0)) -> 採用区分（区分値）(区分値) | S45: =IF(OFFSET(マスタ非採用削除!F$4,統合マスタ!$A45,0)="","",OFFSET(マスタ非採用削除!F$4,統合マスタ!$A45,0)) -> 採用区分（区分値） | T45: =IF(OFFSET(マスタ非採用削除!G$4,統合マスタ!$A45,0)="","",OFFSET(マスタ非採用削除!G$4,統合マスタ!$A45,0)) -> 薬価 | U45: =IF(OFFSET(マスタ非採用削除!H$4,統合マスタ!$A45,0)="","",OFFSET(マスタ非採用削除!H$4,統合マスタ!$A45,0)) -> カナ名称 | ... Z45: =IF(OFFSET(マスタ非採用削除!M$4,統合マスタ!$A45,0)="","",OFFSET(マスタ非採用削除!M$4,統合マスタ!$A45,0)) -> 棚
A46: =元データ!P43 -> 非採用 | B46: =B45+1 -> 42 | C46: =DBCS(元データ!A43) -> アズノール軟膏０．０３３％ | D46: =元データ!B43 -> メディセオ | E46: =元データ!C43 | F46: =元データ!D43 -> 20ｇｘ10 | G46: =元データ!E43 -> 日本新薬 | H46: =元データ!F43 -> 80.3 | I46: =元データ!G43 -> 1606 | J46: =元データ!H43 -> 20 | K46: =元データ!I43 -> 10ｇ | ... M46: =元データ!K43 -> 71.55 | N46: =IF(OFFSET(マスタ非採用削除!A$4,統合マスタ!$A46,0)="","",OFFSET(マスタ非採用削除!A$4,統合マスタ!$A46,0)) -> #VALUE! | O46: =IF(OFFSET(マスタ非採用削除!B$4,統合マスタ!$A46,0)="","",OFFSET(マスタ非採用削除!B$4,統合マスタ!$A46,0)) -> #VALUE! | P46: =IF(OFFSET(マスタ非採用削除!C$4,統合マスタ!$A46,0)="","",OFFSET(マスタ非採用削除!C$4,統合マスタ!$A46,0)) -> #VALUE! | Q46: =IF(OFFSET(マスタ非採用削除!D$4,統合マスタ!$A46,0)="","",OFFSET(マスタ非採用削除!D$4,統合マスタ!$A46,0)) -> #VALUE! | R46: =IF(OFFSET(マスタ非採用削除!E$4,統合マスタ!$A46,0)="","",OFFSET(マスタ非採用削除!E$4,統合マスタ!$A46,0)) -> #VALUE! | S46: =IF(OFFSET(マスタ非採用削除!F$4,統合マスタ!$A46,0)="","",OFFSET(マスタ非採用削除!F$4,統合マスタ!$A46,0)) -> #VALUE! | T46: =IF(OFFSET(マスタ非採用削除!G$4,統合マスタ!$A46,0)="","",OFFSET(マスタ非採用削除!G$4,統合マスタ!$A46,0)) -> #VALUE! | U46: =IF(OFFSET(マスタ非採用削除!H$4,統合マスタ!$A46,0)="","",OFFSET(マスタ非採用削除!H$4,統合マスタ!$A46,0)) -> #VALUE! | ... Z46: =IF(OFFSET(マスタ非採用削除!M$4,統合マスタ!$A46,0)="","",OFFSET(マスタ非採用削除!M$4,統合マスタ!$A46,0)) -> #VALUE! | AA46: 非採用
A47: =元データ!P44 -> 12 | B47: =B46+1 -> 43 | C47: =DBCS(元データ!A44) -> アスパラ－ＣＡ錠２００ | D47: =元データ!B44 -> KSK | E47: =元データ!C44 -> PTP | F47: =元データ!D44 -> 100T | G47: =元データ!E44 -> ニプロES | H47: =元データ!F44 -> 5.9 | I47: =元データ!G44 -> 590 | J47: =元データ!H44 -> 100 | K47: =元データ!I44 -> 錠 | ... M47: =元データ!K44 -> 5.25 | N47: =IF(OFFSET(マスタ非採用削除!A$4,統合マスタ!$A47,0)="","",OFFSET(マスタ非採用削除!A$4,統合マスタ!$A47,0)) -> ｱｽﾊ001 | O47: =IF(OFFSET(マスタ非採用削除!B$4,統合マスタ!$A47,0)="","",OFFSET(マスタ非採用削除!B$4,統合マスタ!$A47,0)) -> ｱｽﾊ001 | P47: =IF(OFFSET(マスタ非採用削除!C$4,統合マスタ!$A47,0)="","",OFFSET(マスタ非採用削除!C$4,統合マスタ!$A47,0)) -> アスパラ－ＣＡ錠２００ | Q47: =IF(OFFSET(マスタ非採用削除!D$4,統合マスタ!$A47,0)="","",OFFSET(マスタ非採用削除!D$4,統合マスタ!$A47,0)) -> ｱｽﾊﾟ | R47: =IF(OFFSET(マスタ非採用削除!E$4,統合マスタ!$A47,0)="","",OFFSET(マスタ非採用削除!E$4,統合マスタ!$A47,0)) -> 1 | S47: =IF(OFFSET(マスタ非採用削除!F$4,統合マスタ!$A47,0)="","",OFFSET(マスタ非採用削除!F$4,統合マスタ!$A47,0)) | T47: =IF(OFFSET(マスタ非採用削除!G$4,統合マスタ!$A47,0)="","",OFFSET(マスタ非採用削除!G$4,統合マスタ!$A47,0)) -> 5.9 | U47: =IF(OFFSET(マスタ非採用削除!H$4,統合マスタ!$A47,0)="","",OFFSET(マスタ非採用削除!H$4,統合マスタ!$A47,0)) -> ｱｽﾊﾟﾗ-CAｼﾞｮｳ200 | ... Z47: =IF(OFFSET(マスタ非採用削除!M$4,統合マスタ!$A47,0)="","",OFFSET(マスタ非採用削除!M$4,統合マスタ!$A47,0)) -> 5
...

Sheet match_results_不採用
A1: A行番号 | C1: A薬品名 | D1: 判定 | E1: 候補1_薬品名 | F1: 候補1_行番号
A2: 1 | B2: =MATCH(C2,統合マスタ!$C$5:$C$1000,0) -> #N/A | C2: EK19 小青竜湯エキス細粒 | D2: 薬価一致候補 | E2: クラシエ小青竜湯エキス細粒 | F2: 98
A3: 2 | B3: =MATCH(C3,統合マスタ!$C$5:$C$1000,0) -> #N/A | C3: アイファガン点眼液0.1％ | D3: 薬価一致候補 | E3: アイファガン点眼液０．１％ | F3: 1
A4: 3 | B4: =MATCH(C4,統合マスタ!$C$5:$C$1000,0) -> #N/A | C4: アウィクリ注 フレックスタッチ 総量300単位 | D4: 薬価一致候補 | E4: アウィクリ注 フレックスタッチ 総量３００単位 | F4: 2
A5: 4 | B5: =MATCH(C5,統合マスタ!$C$5:$C$1000,0) -> #N/A | C5: アキネトン細粒1％ | D5: 薬価一致候補 | E5: アキネトン細粒１％ | F5: 3
A6: 5 | B6: =MATCH(C6,統合マスタ!$C$5:$C$1000,0) -> #N/A | C6: アズノール軟膏0.033% | D6: 不一致
A7: 6 | B7: =MATCH(C7,統合マスタ!$C$5:$C$1000,0) -> #N/A | C7: アノーロエリプタ30吸入用 | D7: 薬価一致候補 | E7: アノーロエリプタ３０吸入用 | F7: 19
A8: 7 | B8: =MATCH(C8,統合マスタ!$C$5:$C$1000,0) -> #N/A | C8: アミノレバンEN配合散 コーヒー味 | D8: 不一致
A9: 8 | B9: =MATCH(C9,統合マスタ!$C$5:$C$1000,0) -> 93 | C9: アルメタ軟膏 | D9: 完全一致 | E9: アルメタ軟膏 | F9: 32
A10: 9 | B10: =MATCH(C10,統合マスタ!$C$5:$C$1000,0) -> #N/A | C10: アレギサール点眼液0.1％ 販売中止 | D10: 薬価一致候補 | E10: アレギサール点眼液０．１％ | F10: 33
A11: 10 | B11: =MATCH(C11,統合マスタ!$C$5:$C$1000,0) -> #N/A | C11: アレビアチン錠100ｍｇ | D11: 不一致
A12: 11 | B12: =MATCH(C12,統合マスタ!$C$5:$C$1000,0) -> 104 | C12: イノラス配合経腸用液（コーヒー） | D12: 薬価一致候補 | E12: ルボックス錠２５ | F12: 335
A13: 12 | B13: =MATCH(C13,統合マスタ!$C$5:$C$1000,0) -> #N/A | C13: エピペン注射液0.3ｍｇ | D13: 不一致
A14: 13 | B14: =MATCH(C14,統合マスタ!$C$5:$C$1000,0) -> #N/A | C14: エンテカビルOD錠0.5ｍｇ「サワイ」 | D14: 薬価一致候補 | E14: エンテカビルＯＤ錠０．５ｍｇ「サワイ」 | F14: 68
A15: 14 | B15: =MATCH(C15,統合マスタ!$C$5:$C$1000,0) -> #N/A | C15: オイラックスクリーム10% | D15: 不一致
A16: 15 | B16: =MATCH(C16,統合マスタ!$C$5:$C$1000,0) -> 164 | C16: オリブ油 | D16: 不一致
A17: 16 | B17: =MATCH(C17,統合マスタ!$C$5:$C$1000,0) -> #N/A | C17: グラナテック点眼液0.4％ | D17: 薬価一致候補 | E17: グラナテック点眼液０．４％ | F17: 101
A18: 17 | B18: =MATCH(C18,統合マスタ!$C$5:$C$1000,0) -> #N/A | C18: クレナフィン爪外用液10％3.56ｇ | D18: 薬価一致候補 | E18: クレナフィン爪外用液１０％ | F18: 106
A19: 18 | B19: =MATCH(C19,統合マスタ!$C$5:$C$1000,0) -> 241 | C19: サリベートエアゾール | D19: 完全一致 | E19: サリベートエアゾール | F19: 122
A20: 19 | B20: =MATCH(C20,統合マスタ!$C$5:$C$1000,0) -> #N/A | C20: ジクアス点眼液3％ | D20: 不一致
A21: 20 | B21: =MATCH(C21,統合マスタ!$C$5:$C$1000,0) -> #N/A | C21: ジスバルカプセル40ｍｇ | D21: 薬価一致候補 | E21: ジスバルカプセル４０ｍｇ | F21: 124
A22: 21 | B22: =MATCH(C22,統合マスタ!$C$5:$C$1000,0) -> #N/A | C22: スピリーバ2.5μｇレスピマット60吸入 | D22: 薬価一致候補 | E22: スピリーバ２．５μｇレスピマット６０吸入 | F22: 131
A23: 22 | B23: =MATCH(C23,統合マスタ!$C$5:$C$1000,0) -> #N/A | C23: デカドロン注射液6.6ｍｇ | D23: 不一致
A24: 23 | B24: =MATCH(C24,統合マスタ!$C$5:$C$1000,0) -> #N/A | C24: ドロキシドパカプセル100mg「アメル」 | D24: 薬価一致候補 | E24: ドロキシドパカプセル１００ｍｇ「アメル」 | F24: 209
A25: 24 | B25: =MATCH(C25,統合マスタ!$C$5:$C$1000,0) -> #N/A | C25: ネオメドロールEE軟膏 | D25: 不一致
A26: 25 | B26: =MATCH(C26,統合マスタ!$C$5:$C$1000,0) -> #N/A | C26: ノウリアスト錠20ｍｇ | D26: 薬価一致候補 | E26: ノウリアスト錠２０ｍｇ | F26: 226
A27: 26 | B27: =MATCH(C27,統合マスタ!$C$5:$C$1000,0) -> #N/A | C27: ヒアルロン酸Na点眼液0.1％「ニットー」 | D27: 不一致
A28: 27 | B28: =MATCH(C28,統合マスタ!$C$5:$C$1000,0) -> #N/A | C28: ビムパット錠100ｍｇ | D28: 薬価一致候補 | E28: ビムパット錠１００ｍｇ | F28: 249
A29: 28 | B29: =MATCH(C29,統合マスタ!$C$5:$C$1000,0) -> #N/A | C29: ビムパット錠50ｍｇ 採用中止 | D29: 薬価一致候補 | E29: ビムパット錠５０ｍｇ | F29: 248
A30: 29 | B30: =MATCH(C30,統合マスタ!$C$5:$C$1000,0) -> #N/A | C30: ヒューマリンR注ミリオペン 300単位 | D30: 薬価一致候補 | E30: ヒューマリンＲ注ミリオペン | F30: 251
A31: 30 | B31: =MATCH(C31,統合マスタ!$C$5:$C$1000,0) -> #N/A | C31: ベタニス錠50ｍｇ | D31: 薬価一致候補 | E31: ベタニス錠５０ｍｇ | F31: 284
A32: 31 | B32: =MATCH(C32,統合マスタ!$C$5:$C$1000,0) -> #N/A | C32: ユリス錠1ｍｇ | D32: 薬価一致候補 | E32: ユリス錠１ｍｇ | F32: 309
A33: 32 | B33: =MATCH(C33,統合マスタ!$C$5:$C$1000,0) -> #N/A | C33: ランタスXR注ソロスター450単位 | D33: 薬価一致候補 | E33: ランタスＸＲ注ソロスター | F33: 314
A34: 33 | B34: =MATCH(C34,統合マスタ!$C$5:$C$1000,0) -> #N/A | C34: リスペリドン細粒1％「アメル」 | D34: 薬価一致候補 | E34: リスペリドン細粒１％「アメル」 | F34: 321
A35: 34 | B35: =MATCH(C35,統合マスタ!$C$5:$C$1000,0) -> #N/A | C35: リフキシマ錠200ｍｇ | D35: 薬価一致候補 | E35: リフキシマ錠２００ｍｇ | F35: 329
A36: 35 | B36: =MATCH(C36,統合マスタ!$C$5:$C$1000,0) -> #N/A | C36: ロイコボリン注3ｍｇ | D36: 不一致
A37: 36 | B37: =MATCH(C37,統合マスタ!$C$5:$C$1000,0) -> 809 | C37: 重カマ「ヨシダ」（細粒状） | D37: 不一致
A38: 37 | B38: =MATCH(C38,統合マスタ!$C$5:$C$1000,0) -> 818 | C38: 精製水「ケンエー」 | D38: 不一致
A39: 38 | B39: =MATCH(C39,統合マスタ!$C$5:$C$1000,0) -> 819 | C39: 静注用キシロカイン２％ | D39: 完全一致 | E39: 静注用キシロカイン２％ | F39: 94
A40: 39 | B40: =MATCH(C40,統合マスタ!$C$5:$C$1000,0) -> #N/A | C40: 白色ワセリン「ケンエー」 | D40: 不一致
...

Sheet 臨時
B2: {=RIGHT(CELL("filename",A1),LEN(CELL("filename",A1))-FIND("]",CELL("filename",A1)))} -> 臨時
B4: No | C4: 薬品名 | D4: 毒劇区分 | E4: 棚 | F4: 包装形態 | G4: 容量
B5: 1 | C5: {=_xlfn._xlws.SORT(_xlfn.CHOOSECOLS(_xlfn._xlws.FILTER(IFERROR(統合マスタ!B5:Z1500,""),IFERROR(統合マスタ!R5:R1500=2,FALSE)),2,23,25,4,5),2,1)} -> ００７ ツムラ ハチミジオウガン | D5: 0 | E5: 4 | F5: 粉 | G5: 2.5ｇｘ189
B6: =B5+1 -> 2 | C6: ００７ ツムラ ハチミジオウガン | D6: 0 | E6: 4 | F6: 粉 | G6: 2.5ｇｘ42
B7: =B6+1 -> 3 | C7: ０１２ ツムラ サイコカリュウコツボレイトウ | D7: 0 | E7: 4 | F7: 粉 | G7: 2.5ｇｘ189
B8: =B7+1 -> 4 | C8: ０１６ ツムラ ハンゲコウボクトウ | D8: 0 | E8: 4 | F8: 粉 | G8: 2.5ｇｘ189
B9: =B8+1 -> 5 | C9: ０１９ ツムラ ショウセイリュウトウ | D9: 0 | E9: 4 | F9: 粉 | G9: 3ｇX42
B10: =B9+1 -> 6 | C10: ０４３ ツムラ リツクンシトウ | D10: 0 | E10: 4 | F10: 粉 | G10: 2.5ｇｘ189
B11: =B10+1 -> 7 | C11: １０８ ツムラ ニンジンヨウエイトウ | D11: 0 | E11: 4 | F11: 粉 | G11: 3ｇｘ42包
B12: =B11+1 -> 8 | C12: １１２ ツムラ チョレイトウゴウシモットウ | D12: 0 | E12: 4 | F12: 粉 | G12: 2.5ｇｘ42
B13: =B12+1 -> 9 | C13: ＥＫ１１４ 柴苓湯 | D13: 0 | E13: 4 | F13: 粉 | G13: 2.7ｇ×２９４
B14: =B13+1 -> 10 | C14: ＥＫ１５ 黄連解毒湯エキス細粒 | D14: 0 | E14: 4 | F14: 粉 | G14: 2ｇｘ42包
B15: =B14+1 -> 11 | C15: ＥＫ４０ 猪苓湯エキス細粒 | D15: 0 | E15: 4 | F15: 粉 | G15: 2ｇｘ42包
B16: =B15+1 -> 12 | C16: Ｔ７２ ヨクイニンエキス錠「コタロー」 | D16: 0 | E16: 15 | F16: バラ | G16: 126Tx10
B17: =B16+1 -> 13 | C17: アザルフィジンＥＮ錠５００ｍｇ | D17: 0 | E17: 3 | F17: PTP | G17: 100Ｔ
B18: =B17+1 -> 14 | C18: アシクロビル点滴静注用２５０ｍｇ「サワイ」 | D18: 0 | E18: 9 | G18: 10V
B19: =B18+1 -> 15 | C19: アゾセミド錠３０ｍｇ「ＤＳＥＰ」 | D19: 0 | E19: 3 | F19: PTP | G19: 100T
B20: =B19+1 -> 16 | C20: アドエア５００ディスカス ６０吸入用 | D20: 0 | E20: 3 | G20: 60ﾌﾞﾘｽﾀｰｘ１
B21: =B20+1 -> 17 | C21: アミノレバン点滴静注 | D21: 0 | E21: 15 | G21: 500ｍｌｘ20
B22: =B21+1 -> 18 | C22: イノソリッド配合経腸用半固形剤 | D22: 0 | E22: 7 | G22: 300ｇｘ18バッグ
B23: =B22+1 -> 19 | C23: イントラリポス輸液２０％ ソフトバッグ １００ｍｌ | D23: 0 | E23: 8 | G23: 100ｍｌｘ10
B24: =B23+1 -> 20 | C24: エイゾプト懸濁性点眼液１％ | D24: 0 | E24: 15 | G24: 5ｍｌｘ10
B25: =B24+1 -> 21 | C25: エゼチミブＯＤ錠１０ｍｇ「トーワ」 | D25: 0 | E25: 3 | F25: PTP | G25: 100T
B26: =B25+1 -> 22 | C26: エフィエント錠２．５ｍｇ | D26: 0 | E26: 15 | F26: PTP | G26: 100Ｔ
B27: =B26+1 -> 23 | C27: エフィナコナゾール爪外用液１０％「サワイ」 ３．５６ｇ | D27: 0 | E27: 3 | G27: 4.1ｍｌｘ5
B28: =B27+1 -> 24 | C28: エリキュース錠２．５ｍｇ | D28: 0 | E28: 3 | F28: PTP | G28: 100T
B29: =B28+1 -> 25 | C29: エリスロシン錠２００ｍｇ | D29: 0 | E29: 15 | F29: PTP | G29: 100T
B30: =B29+1 -> 26 | C30: エンレスト錠１００ｍｇ | D30: 0 | E30: 3 | F30: ＰＴＰ | G30: 100Ｔ
B31: =B30+1 -> 27 | C31: オーグメンチン配合錠２５０ＲＳ（３７５ｍｇ） | D31: 0 | E31: 15 | F31: ＰＴＰ | G31: 30Ｔ
B32: =B31+1 -> 28 | C32: オルメテックＯＤ錠１０ｍｇ | D32: 0 | E32: 3 | F32: ＰＴＰ | G32: 100T
B33: =B32+1 -> 29 | C33: カリメートドライシロップ９２．５９％ | D33: 0 | E33: 15 | G33: 5.4ｇｘ126包
B34: =B33+1 -> 30 | C34: グラアルファ配合点眼液 | D34: 0 | E34: 3 | G34: 5ｍｌｘ5
B35: =B34+1 -> 31 | C35: クロピドグレル錠２５ｍｇ「ＪＧ」 | D35: 0 | E35: 3 | F35: PTP | G35: 100Ｔ
B36: =B35+1 -> 32 | C36: クロフェクトン錠２５ｍｇ | D36: 0 | E36: 3 | F36: PTP | G36: 100T
B37: =B36+1 -> 33 | C37: コソプト配合点眼液 | D37: 0 | E37: 3 | G37: 5ｍｌｘ10
B38: =B37+1 -> 34 | C38: ジクアス点眼液３％ | D38: 0 | E38: 3 | G38: 5ｍｌｘ10
B39: =B38+1 -> 35 | C39: スミスリンローション５％ | D39: 0 | E39: 3 | G39: 30ｇｘ2
B40: =B39+1 -> 36 | C40: セララ錠５０ｍｇ | D40: 0 | E40: 3 | F40: PTP | G40: 100T
B41: =B40+1 -> 37 | C41: ソタロール塩酸塩錠８０ｍｇ「ＴＥ」 | D41: 0 | E41: 15 | F41: PTP | G41: 140T
B42: =B41+1 -> 38 | C42: ダイフェン配合錠 | D42: 0 | E42: 15 | F42: PTP | G42: 100T
...

Sheet 外用
B2: {=RIGHT(CELL("filename",A1),LEN(CELL("filename",A1))-FIND("]",CELL("filename",A1)))} -> 外用
B4: No | C4: 薬品名 | D4: 毒劇区分 | E4: 棚 | F4: 包装形態 | G4: 容量
B5: 1 | C5: {=_xlfn._xlws.SORT(_xlfn.CHOOSECOLS(_xlfn._xlws.FILTER(IFERROR(統合マスタ!B2:Z1500,""),IFERROR(統合マスタ!R2:R1500=1,FALSE)*IFERROR(ISNUMBER(MATCH(統合マスタ!V2:V1500,分類!H8:H15,0)),FALSE)),2,23,25,4,5),2,1)} -> ＳＰトローチ０．２５ｍｇ「明治」 | D5: 0 | E5: 3 | F5: PTP | G5: 1200T
B6: =B5+1 -> 2 | C6: アクアチムクリーム１％ | D6: 0 | E6: 3 | G6: 10ｇX10
B7: =B6+1 -> 3 | C7: アクトシン軟膏３％ | D7: 0 | E7: 15 | G7: 30ｇ
B8: =B7+1 -> 4 | C8: アズレン点眼液０．０２％「ニットー」 | D8: 0 | E8: 3 | G8: 5ｍｌｘ10
B9: =B8+1 -> 5 | C9: アドフィードパップ４０ｍｇ | D9: 0 | E9: 12 | G9: ７枚ｘ50
B10: =B9+1 -> 6 | C10: インテバンクリーム１％ | D10: 0 | E10: 1 | G10: 25ｇｌｘ10
B11: =B10+1 -> 7 | C11: インテバン外用液１％ | D11: 0 | E11: 3 | G11: 50ｍｌｘ10
B12: =B11+1 -> 8 | C12: オイラックスクリーム１０％ | D12: 0 | E12: 3 | G12: １０ｇＸ１０
B13: =B12+1 -> 9 | C13: オフロキサシン点眼液０．３％「ＪＧ」 | D13: 0 | E13: 3 | G13: 5ｍｌｘ10
B14: =B13+1 -> 10 | C14: キュバール１００エアゾール１５ｍｇ | D14: 0 | E14: 3 | G14: 8.7ｇｘ1
B15: =B14+1 -> 11 | C15: クロモグリク酸Ｎａ点眼液２％「ニットー」 | D15: 0 | E15: 3 | G15: 5MLX5V
B16: =B15+1 -> 12 | C16: クロモグリク酸Ｎａ点眼液２％「ニットー」 | D16: 0 | E16: 3 | G16: 5MLX10V
B17: =B16+1 -> 13 | C17: ゲーベンクリーム１％ | D17: 0 | E17: 7 | G17: １００ｇ
... B67: =B66+1 -> 63 | C67: ロナセンテープ４０ｍｇ | D67: 2 | E67: 3 | G67: 70枚
B68: =B67+1 -> 64
B69: =B68+1 -> 65
B70: =B69+1 -> 66
B71: =B70+1 -> 67
B72: =B71+1 -> 68
B73: =B72+1 -> 69
B74: =B73+1 -> 70
B75: =B74+1 -> 71
B76: =B75+1 -> 72
B77: =B76+1 -> 73
B78: =B77+1 -> 74
B79: =B78+1 -> 75
... B304: =B303+1 -> 300

Sheet 散剤
B2: {=RIGHT(CELL("filename",A1),LEN(CELL("filename",A1))-FIND("]",CELL("filename",A1)))} -> 散剤
B4: No | C4: 薬品名 | D4: 毒劇区分 | E4: 棚 | F4: 包装形態 | G4: 容量
B5: 1 | C5: {=_xlfn._xlws.SORT(_xlfn.CHOOSECOLS(_xlfn._xlws.FILTER(IFERROR(統合マスタ!B2:Z1500,""),IFERROR(統合マスタ!R2:R1500=1,FALSE)*IFERROR(ISNUMBER(MATCH(統合マスタ!V2:V1500,分類!K8:K15,0)),FALSE)),2,23,25,4,5),2,1)} -> ０１７ ツムラ ゴレイサン | D5: 0 | E5: 4 | F5: 粉 | G5: 2.5ｇｘ189
B6: =B5+1 -> 2 | C6: ０５４ ツムラ ヨクカンサン | D6: 0 | E6: 4 | F6: 粉 | G6: 2.5ｇX189
B7: =B6+1 -> 3 | C7: ０６２ ツムラ ボウフウツウシヨウサン | D7: 0 | E7: 4 | F7: 粉 | G7: 2.5ｇｘ189
B8: =B7+1 -> 4 | C8: ０６８ ツムラ シャクヤクカンゾウトウ | D8: 0 | E8: 4 | F8: 粉 | G8: 2.5ｇｘ42
B9: =B8+1 -> 5 | C9: ０８３ ツムラ ヨクカンサンカチンピハンゲ | D9: 0 | E9: 4 | F9: 粉 | G9: 2.5ｇｘ189
B10: =B9+1 -> 6 | C10: １００ ツムラ ダイケンチユウトウ | D10: 0 | E10: 4 | F10: 粉 | G10: 2.5ｇX189
B11: =B10+1 -> 7 | C11: ＥＫ１ 葛根湯エキス細粒 | D11: 0 | E11: 4 | F11: 粉 | G11: 2.5ｇ×294
B12: =B11+1 -> 8 | C12: ＥＫ２４ 加味逍遥散料エキス細粒 | D12: 0 | E12: 4 | F12: 粉 | G12: 2ｇｘ42包
B13: =B12+1 -> 9 | C13: ＥＫ４１ 補中益気湯エキス細粒 | D13: 0 | E13: 4 | F13: 粉 | G13: 2.5ｇｘ294
B14: =B13+1 -> 10 | C14: アスパラカリウム散５０％ | D14: 0 | E14: 2 | F14: 粉 | G14: 500ｇ
B15: =B14+1 -> 11 | C15: アドナ散１０％ | D15: 0 | E15: 2 | F15: 粉 | G15: 100ｇ
B16: =B15+1 -> 12 | C16: アミノレバンＥＮ配合散 コーヒー味 | D16: 0 | E16: 15 | F16: 粉 | G16: 50ｇX21包
B17: =B16+1 -> 13 | C17: カルバマゼピン細粒５０％「アメル」 | D17: 0 | E17: 2 | F17: 粉 | G17: 500ｇ
B18: =B17+1 -> 14 | C18: グラマリール細粒１０％ | D18: 0 | E18: 2 | F18: 粉 | G18: 100ｇ
B19: =B18+1 -> 15 | C19: クレメジン細粒分包２ｇ | D19: 0 | E19: 3 | G19: 2ｇｘ84包
B20: =B19+1 -> 16 | C20: シーピー配合顆粒 | D20: 0 | E20: 3 | F20: 粉 | G20: 1ｇｘ1050包
B21: =B20+1 -> 17 | C21: センブリ・重曹散 | D21: 0 | E21: 2 | F21: 粉 | G21: 500ｇ
B22: =B21+1 -> 18 | C22: タンニン酸アルブミン「ＶＴＲＳ」原末 | D22: 0 | E22: 2 | F22: 粉 | G22: 500ｇ
B23: =B22+1 -> 19 | C23: テプレノン細粒１０％「ＹＤ」 | D23: 0 | E23: 2 | F23: 粉 | G23: 100ｇ
B24: =B23+1 -> 20 | C24: パントシン散２０％ | D24: 0 | E24: 2 | F24: 粉 | G24: 100ｇ
B25: =B24+1 -> 21 | C25: ビオフェルミン配合散 | D25: 0 | E25: 3 | F25: 粉 | G25: 1ｇｘ120
B26: =B25+1 -> 22 | C26: ビオフェルミン配合散 | D26: 0 | E26: 3 | F26: 粉 | G26: 1ｇｘ600
B27: =B26+1 -> 23 | C27: ビオフェルミン配合散 | D27: 0 | E27: 3 | F27: 粉 | G27: 1ｋｇ
B28: =B27+1 -> 24 | C28: フロセミド細粒４％「ＥＭＥＣ」 | D28: 0 | E28: 2 | F28: 粉 | G28: 100ｇ
B29: =B28+1 -> 25 | C29: マーズレンＳ配合顆粒 | D29: 0 | E29: 3 | F29: 粉 | G29: 400ｇ（0.67ｆｘ600）
B30: =B29+1 -> 26 | C30: マーズレンＳ配合顆粒 | D30: 0 | E30: 3 | F30: 粉 | G30: 1000ｇ
B31: =B30+1 -> 27 | C31: モサプリドクエン酸塩散１％「日医工」 | D31: 0 | E31: 2 | F31: 粉 | G31: 100ｇ
... B44: =B43+1 -> 40 | C44: リスパダール細粒１％ | D44: 2 | E44: 1 | F44: 粉 | G44: 100ｇ
B45: =B44+1 -> 41 | C45: ロドピン細粒５０％ | D45: 2 | E45: 2 | G45: 100ｇ
B46: =B45+1 -> 42
B47: =B46+1 -> 43
B48: =B47+1 -> 44
B49: =B48+1 -> 45
B50: =B49+1 -> 46
B51: =B50+1 -> 47
B52: =B51+1 -> 48
B53: =B52+1 -> 49
B54: =B53+1 -> 50
...

Sheet 錠剤
B2: {=RIGHT(CELL("filename",A1),LEN(CELL("filename",A1))-FIND("]",CELL("filename",A1)))} -> 錠剤
B4: No | C4: 薬品名 | D4: 毒劇区分 | E4: 棚 | F4: 包装形態 | G4: 容量
B5: 1 | C5: {=_xlfn._xlws.SORT(_xlfn.CHOOSECOLS(_xlfn._xlws.FILTER(IFERROR(統合マスタ!B2:Z1500,""),IFERROR(統合マスタ!R2:R1500=1,FALSE)*IFERROR(ISNUMBER(MATCH(統合マスタ!V2:V1500,分類!N8:N15,0)),FALSE)),2,23,25,4,5),2,1)} -> ２５ｍｇアリナミン Ｆ糖衣錠 | D5: 0 | E5: 5 | F5: PTP | G5: 100Ｔ
B6: =B5+1 -> 2 | C6: アーチスト錠１．２５ｍｇ | D6: 0 | E6: 5 | F6: PTP | G6: 100T
B7: =B6+1 -> 3 | C7: アジスロマイシン錠２５０ｍｇ「トーワ」 | D7: 0 | E7: 1 | F7: ＰＴＰ | G7: 60T
B8: =B7+1 -> 4 | C8: アジルサルタンＯＤ錠２０ｍｇ「サワイ」 | D8: 0 | E8: 5 | F8: PTP | G8: 100T
B9: =B8+1 -> 5 | C9: アジルサルタンＯＤ錠２０ｍｇ「サワイ」 | D9: 0 | E9: 5 | F9: バラ | G9: 200T
B10: =B9+1 -> 6 | C10: アスパラ－ＣＡ錠２００ | D10: 0 | E10: 5 | F10: PTP | G10: 100T
B11: =B10+1 -> 7 | C11: アスパラ－ＣＡ錠２００ | D11: 0 | E11: 5 | F11: バラ | G11: 500Ｔ
B12: =B11+1 -> 8 | C12: アスパラカリウム錠３００ｍｇ | D12: 0 | E12: 1 | F12: ＰＴＰ | G12: 1000T
B13: =B12+1 -> 9 | C13: アスパラカリウム錠３００ｍｇ | D13: 0 | E13: 1 | F13: ＰＴＰ | G13: 100T
B14: =B13+1 -> 10 | C14: アタラックス錠２５ｍｇ | D14: 0 | E14: 5 | F14: PTP | G14: 100Ｔ
B15: =B14+1 -> 11 | C15: アドナ錠３０ｍｇ | D15: 0 | E15: 5 | F15: バラ | G15: 500T
B16: =B15+1 -> 12 | C16: アトルバスタチンＯＤ錠１０ｍｇ「トーワ」 | D16: 0 | E16: 5 | F16: ＰＴＰ | G16: 100T
B17: =B16+1 -> 13 | C17: アトルバスタチンＯＤ錠１０ｍｇ「トーワ」 | D17: 0 | E17: 5 | F17: バラ | G17: 300T
... B370: =B369+1 -> 366 | C370: 炭酸リチウム錠２００ｍｇ「大正」 | D370: 2 | E370: 6 | F370: バラ | G370: 1000T
B371: =B370+1 -> 367
B372: =B371+1 -> 368
B373: =B372+1 -> 369
B374: =B373+1 -> 370
B375: =B374+1 -> 371
B376: =B375+1 -> 372
B377: =B376+1 -> 373
B378: =B377+1 -> 374
B379: =B378+1 -> 375
B380: =B379+1 -> 376
B381: =B380+1 -> 377
B382: =B381+1 -> 378
... B504: =B503+1 -> 500

Sheet 注射
B2: {=RIGHT(CELL("filename",A1),LEN(CELL("filename",A1))-FIND("]",CELL("filename",A1)))} -> 注射
B4: No | C4: 薬品名 | D4: 毒劇区分 | E4: 棚 | F4: 包装形態 | G4: 容量
B5: 1 | C5: {=_xlfn._xlws.SORT(_xlfn.CHOOSECOLS(_xlfn._xlws.FILTER(IFERROR(統合マスタ!B2:Z1500,""),IFERROR(統合マスタ!R2:R1500=1,FALSE)*IFERROR(ISNUMBER(MATCH(統合マスタ!V2:V1500,分類!Q8:Q15,0)),FALSE)),2,23,25,4,5),2,1)} -> アクチット輸液 | D5: 0 | E5: 10 | G5: 500ｍｌｘ20袋
B6: =B5+1 -> 2 | C6: アスコルビン酸注５００ｍｇ「イセイ」 | D6: 0 | E6: 11 | G6: 2ｍｌｘ50Ａ
B7: =B6+1 -> 3 | C7: アスパラギン酸カリウム注 １０ＭＥＱキット「テルモ」 | D7: 0 | E7: 9 | G7: 10ｍｌｘ10
B8: =B7+1 -> 4 | C8: アドナ注（静脈用）５０ｍｇ | D8: 0 | E8: 9 | G8: 10ml×10A
B9: =B8+1 -> 5 | C9: アドナ注（静脈用）５０ｍｇ | D9: 0 | E9: 9 | G9: 10ml×50A
B10: =B9+1 -> 6 | C10: アルブミナー２５％静注１２．５ｇ／５０ｍｌ | D10: 0 | E10: 6 | G10: 50ｍｌｘ1V
B11: =B10+1 -> 7 | C11: イベニティ皮下注１０５ｍｇシリンジ | D11: 0 | E11: 11 | G11: 2筒
B12: =B11+1 -> 8 | C12: グリセオール注 | D12: 0 | E12: 9 | G12: 200ｍｌｘ10
B13: =B12+1 -> 9 | C13: ケイツーＮ静注１０ｍｇ | D13: 0 | E13: 9 | G13: 2ｍｌｘ１０管
B14: =B13+1 -> 10 | C14: ジアゼパム注射液５ｍｇ「ＮＩＧ」 | D14: 0 | E14: 9 | G14: 1ｍｌｘ10A
B15: =B14+1 -> 11 | C15: スルバシリン静注用１．５ｇ | D15: 0 | E15: 8 | G15: 10瓶
B16: =B15+1 -> 12 | C16: セフェピム塩酸塩静注用１ｇ「サンド」 | D16: 0 | E16: 8 | G16: 10V
B17: =B16+1 -> 13 | C17: セフタジジム静注用１ｇ「ＶＴＲＳ」 | D17: 0 | E17: 8 | G17: 10V
... B88: =B87+1 -> 84 | C88: ワソラン静注５ｍｇ | D88: 2 | E88: 9 | G88: 2ｍｌｘ10Ａ
B89: =B88+1 -> 85
B90: =B89+1 -> 86
