Workbook

Sheet 統合マスタ
C3: 棚卸 | N3: マスタ
B4: no | C4: 名称 | D4: 2025年度卸 | E4: 包装形態 | F4: 容量 | G4: メーカー | H4: 新単位薬価 | I4: 2025年度薬価 | J4: 単位数量 | K4: 薬価単位 | L4: 2025年納入価格 | M4: 単位納入価 | N4: コード(区分値) | O4: コード | P4: 名称 | Q4: ホストコード | R4: 採用区分（区分値）(区分値) | S4: 採用区分（区分値） | T4: 薬価 | U4: カナ名称 | V4: 剤形(区分値) | W4: 剤形 | X4: 毒劇薬（区分値）(区分値) | Y4: 毒劇薬（区分値） | Z4: 場所番号 | AA4: 非採用 | AB4: Excelシート | AC4: ソートキー | AD4: 数量
A5: =元データ!P2 -> 295 | B5: 1 | C5: =DBCS(元データ!A2) -> ００７ ツムラ ハチミジオウガン | D5: =元データ!B2 -> メディセオ | E5: =DBCS(元データ!C2) -> 粉 | F5: =DBCS(元データ!D2) -> ２．５ｇｘ１８９ | G5: =元データ!E2 -> ツムラ | H5: =元データ!F2 -> 9.8 | I5: =元データ!G2 -> 4630.5 | J5: =元データ!H2 -> 472.5 | K5: =元データ!I2 -> ｇ | L5: =元データ!J2 -> 4093 | M5: =元データ!K2 -> 8.6624339 | N5: =IF(OFFSET(マスタ非採用削除!A$4,統合マスタ!$A5,0)="","",OFFSET(マスタ非採用削除!A$4,統合マスタ!$A5,0)) -> ﾂﾑﾗ007 | O5: =IF(OFFSET(マスタ非採用削除!B$4,統合マスタ!$A5,0)="","",OFFSET(マスタ非採用削除!B$4,統合マスタ!$A5,0)) -> ﾂﾑﾗ007 | P5: =IF(OFFSET(マスタ非採用削除!C$4,統合マスタ!$A5,0)="","",OFFSET(マスタ非採用削除!C$4,統合マスタ!$A5,0)) -> ツムラ八味地黄丸エキス顆粒（医療用） | Q5: =IF(OFFSET(マスタ非採用削除!D$4,統合マスタ!$A5,0)="","",OFFSET(マスタ非採用削除!D$4,統合マスタ!$A5,0)) -> ﾊﾁﾐ | R5: =IF(AA5="非採用",0,IF(OFFSET(マスタ非採用削除!E$4,統合マスタ!$A5,0)="","",OFFSET(マスタ非採用削除!E$4,統合マスタ!$A5,0))) -> 2 | S5: =IF(OFFSET(マスタ非採用削除!F$4,統合マスタ!$A5,0)="","",OFFSET(マスタ非採用削除!F$4,統合マスタ!$A5,0)) | T5: =IF(OFFSET(マスタ非採用削除!G$4,統合マスタ!$A5,0)="","",OFFSET(マスタ非採用削除!G$4,統合マスタ!$A5,0)) -> 9.8 | U5: =IF(OFFSET(マスタ非採用削除!H$4,統合マスタ!$A5,0)="","",OFFSET(マスタ非採用削除!H$4,統合マスタ!$A5,0)) -> ﾂﾑﾗﾊﾁﾐｼﾞｵｳｶﾞﾝｴｷｽｶﾘｭｳ(ｲﾘｮｳﾖｳ) | V5: =IF(OFFSET(マスタ非採用削除!I$4,統合マスタ!$A5,0)="","",OFFSET(マスタ非採用削除!I$4,統合マスタ!$A5,0)) -> 3 | W5: =IF(OFFSET(マスタ非採用削除!J$4,統合マスタ!$A5,0)="","",OFFSET(マスタ非採用削除!J$4,統合マスタ!$A5,0)) -> 散 | X5: =IF(OFFSET(マスタ非採用削除!K$4,統合マスタ!$A5,0)="","",OFFSET(マスタ非採用削除!K$4,統合マスタ!$A5,0)) -> 0 | Y5: =IF(OFFSET(マスタ非採用削除!L$4,統合マスタ!$A5,0)="","",OFFSET(マスタ非採用削除!L$4,統合マスタ!$A5,0)) | Z5: =IF(OFFSET(マスタ非採用削除!M$4,統合マスタ!$A5,0)="","",OFFSET(マスタ非採用削除!M$4,統合マスタ!$A5,0)) -> 4 | AB5: =IF(R5=2,"臨時", IF(COUNTIF(分類!$H$8:$H$15, 統合マスタ!V5)>0, 分類!$G$7, IF(COUNTIF(分類!$K$8:$K$15, 統合マスタ!V5)>0, 分類!$J$7, IF(COUNTIF(分類!$N$8:$N$15, 統合マスタ!V5)>0, 分類!$M$7, IF(COUNTIF(分類!$Q$8:$Q$15, 統合マスタ!V5)>0, 分類!$P$7, "無し"))))) -> 臨時 | AC5: =X5 * 100000 + B5 -> 1 | AD5: {=IF(A5="非採用","非採用",OFFSET( INDIRECT("'" & AB5 & "'!A4"), MATCH(B5, INDIRECT("'" & AB5 & "'!C5:C1000"), 0), MATCH("合計", INDIRECT("'" & AB5 & "'!4:4"), 0) - 1 ))} -> 0
A6: =元データ!P3 -> 295 | B6: =B5+1 -> 2 | C6: =DBCS(元データ!A3) -> ００７ ツムラ ハチミジオウガン | D6: =元データ!B3 | E6: =DBCS(元データ!C3) -> 粉 | F6: =DBCS(元データ!D3) -> ２．５ｇｘ４２ | G6: =元データ!E3 -> ツムラ | H6: =元データ!F3 -> 9.8 | I6: =元データ!G3 -> 1029 | J6: =元データ!H3 -> 105 | K6: =元データ!I3 -> ｇ | L6: =元データ!J3 -> 935 | M6: =元データ!K3 -> 8.9047619 | N6: =IF(OFFSET(マスタ非採用削除!A$4,統合マスタ!$A6,0)="","",OFFSET(マスタ非採用削除!A$4,統合マスタ!$A6,0)) -> ﾂﾑﾗ007 | O6: =IF(OFFSET(マスタ非採用削除!B$4,統合マスタ!$A6,0)="","",OFFSET(マスタ非採用削除!B$4,統合マスタ!$A6,0)) -> ﾂﾑﾗ007 | P6: =IF(OFFSET(マスタ非採用削除!C$4,統合マスタ!$A6,0)="","",OFFSET(マスタ非採用削除!C$4,統合マスタ!$A6,0)) -> ツムラ八味地黄丸エキス顆粒（医療用） | Q6: =IF(OFFSET(マスタ非採用削除!D$4,統合マスタ!$A6,0)="","",OFFSET(マスタ非採用削除!D$4,統合マスタ!$A6,0)) -> ﾊﾁﾐ | R6: =IF(AA6="非採用",0,IF(OFFSET(マスタ非採用削除!E$4,統合マスタ!$A6,0)="","",OFFSET(マスタ非採用削除!E$4,統合マスタ!$A6,0))) -> 2 | S6: =IF(OFFSET(マスタ非採用削除!F$4,統合マスタ!$A6,0)="","",OFFSET(マスタ非採用削除!F$4,統合マスタ!$A6,0)) | T6: =IF(OFFSET(マスタ非採用削除!G$4,統合マスタ!$A6,0)="","",OFFSET(マスタ非採用削除!G$4,統合マスタ!$A6,0)) -> 9.8 | U6: =IF(OFFSET(マスタ非採用削除!H$4,統合マスタ!$A6,0)="","",OFFSET(マスタ非採用削除!H$4,統合マスタ!$A6,0)) -> ﾂﾑﾗﾊﾁﾐｼﾞｵｳｶﾞﾝｴｷｽｶﾘｭｳ(ｲﾘｮｳﾖｳ) | V6: =IF(OFFSET(マスタ非採用削除!I$4,統合マスタ!$A6,0)="","",OFFSET(マスタ非採用削除!I$4,統合マスタ!$A6,0)) -> 3 | W6: =IF(OFFSET(マスタ非採用削除!J$4,統合マスタ!$A6,0)="","",OFFSET(マスタ非採用削除!J$4,統合マスタ!$A6,0)) -> 散 | X6: =IF(OFFSET(マスタ非採用削除!K$4,統合マスタ!$A6,0)="","",OFFSET(マスタ非採用削除!K$4,統合マスタ!$A6,0)) -> 0 | Y6: =IF(OFFSET(マスタ非採用削除!L$4,統合マスタ!$A6,0)="","",OFFSET(マスタ非採用削除!L$4,統合マスタ!$A6,0)) | Z6: =IF(OFFSET(マスタ非採用削除!M$4,統合マスタ!$A6,0)="","",OFFSET(マスタ非採用削除!M$4,統合マスタ!$A6,0)) -> 4 | AB6: =IF(R6=2,"臨時", IF(COUNTIF(分類!$H$8:$H$15, 統合マスタ!V6)>0, 分類!$G$7, IF(COUNTIF(分類!$K$8:$K$15, 統合マスタ!V6)>0, 分類!$J$7, IF(COUNTIF(分類!$N$8:$N$15, 統合マスタ!V6)>0, 分類!$M$7, IF(COUNTIF(分類!$Q$8:$Q$15, 統合マスタ!V6)>0, 分類!$P$7, "無し"))))) -> 臨時 | AC6: =X6 * 100000 + B6 -> 2 | AD6: {=IF(A6="非採用","非採用",OFFSET( INDIRECT("'" & AB6 & "'!A4"), MATCH(B6, INDIRECT("'" & AB6 & "'!C5:C1000"), 0), MATCH("合計", INDIRECT("'" & AB6 & "'!4:4"), 0) - 1 ))} -> 0
A7: =元データ!P4 -> 296 | B7: =B6+1 -> 3 | C7: =DBCS(元データ!A4) -> ０１２ ツムラ サイコカリュウコツボレイトウ | D7: =元データ!B4 -> メディセオ | E7: =DBCS(元データ!C4) -> 粉 | F7: =DBCS(元データ!D4) -> ２．５ｇｘ１８９ | G7: =元データ!E4 -> ツムラ | H7: =元データ!F4 -> 20.3 | I7: =元データ!G4 -> 9591.75 | J7: =元データ!H4 -> 472.5 | K7: =元データ!I4 -> g | L7: =元データ!J4 -> 8544 | M7: =元データ!K4 -> 18.08254 | N7: =IF(OFFSET(マスタ非採用削除!A$4,統合マスタ!$A7,0)="","",OFFSET(マスタ非採用削除!A$4,統合マスタ!$A7,0)) -> ﾂﾑﾗ012 | O7: =IF(OFFSET(マスタ非採用削除!B$4,統合マスタ!$A7,0)="","",OFFSET(マスタ非採用削除!B$4,統合マスタ!$A7,0)) -> ﾂﾑﾗ012 | P7: =IF(OFFSET(マスタ非採用削除!C$4,統合マスタ!$A7,0)="","",OFFSET(マスタ非採用削除!C$4,統合マスタ!$A7,0)) -> ツムラ柴胡加竜骨牡蛎湯エキス顆粒（医療用） | Q7: =IF(OFFSET(マスタ非採用削除!D$4,統合マスタ!$A7,0)="","",OFFSET(マスタ非採用削除!D$4,統合マスタ!$A7,0)) -> ｻｲｺ | R7: =IF(AA7="非採用",0,IF(OFFSET(マスタ非採用削除!E$4,統合マスタ!$A7,0)="","",OFFSET(マスタ非採用削除!E$4,統合マスタ!$A7,0))) -> 2 | S7: =IF(OFFSET(マスタ非採用削除!F$4,統合マスタ!$A7,0)="","",OFFSET(マスタ非採用削除!F$4,統合マスタ!$A7,0)) | T7: =IF(OFFSET(マスタ非採用削除!G$4,統合マスタ!$A7,0)="","",OFFSET(マスタ非採用削除!G$4,統合マスタ!$A7,0)) -> 20.3 | U7: =IF(OFFSET(マスタ非採用削除!H$4,統合マスタ!$A7,0)="","",OFFSET(マスタ非採用削除!H$4,統合マスタ!$A7,0)) -> ﾂﾑﾗｻｲｺｶﾘｭｳｺﾂﾎﾞﾚｲﾄｳｴｷｽｶﾘｭｳ(ｲﾘｮｳﾖｳ) | V7: =IF(OFFSET(マスタ非採用削除!I$4,統合マスタ!$A7,0)="","",OFFSET(マスタ非採用削除!I$4,統合マスタ!$A7,0)) -> 3 | W7: =IF(OFFSET(マスタ非採用削除!J$4,統合マスタ!$A7,0)="","",OFFSET(マスタ非採用削除!J$4,統合マスタ!$A7,0)) -> 散 | X7: =IF(OFFSET(マスタ非採用削除!K$4,統合マスタ!$A7,0)="","",OFFSET(マスタ非採用削除!K$4,統合マスタ!$A7,0)) -> 0 | Y7: =IF(OFFSET(マスタ非採用削除!L$4,統合マスタ!$A7,0)="","",OFFSET(マスタ非採用削除!L$4,統合マスタ!$A7,0)) | Z7: =IF(OFFSET(マスタ非採用削除!M$4,統合マスタ!$A7,0)="","",OFFSET(マスタ非採用削除!M$4,統合マスタ!$A7,0)) -> 4 | AB7: =IF(R7=2,"臨時", IF(COUNTIF(分類!$H$8:$H$15, 統合マスタ!V7)>0, 分類!$G$7, IF(COUNTIF(分類!$K$8:$K$15, 統合マスタ!V7)>0, 分類!$J$7, IF(COUNTIF(分類!$N$8:$N$15, 統合マスタ!V7)>0, 分類!$M$7, IF(COUNTIF(分類!$Q$8:$Q$15, 統合マスタ!V7)>0, 分類!$P$7, "無し"))))) -> 臨時 | AC7: =X7 * 100000 + B7 -> 3 | AD7: {=IF(A7="非採用","非採用",OFFSET( INDIRECT("'" & AB7 & "'!A4"), MATCH(B7, INDIRECT("'" & AB7 & "'!C5:C1000"), 0), MATCH("合計", INDIRECT("'" & AB7 & "'!4:4"), 0) - 1 ))} -> 0
A8: =元データ!P5 -> 297 | B8: =B7+1 -> 4 | C8: =DBCS(元データ!A5) -> ０１６ ツムラ ハンゲコウボクトウ | D8: =元データ!B5 -> メディセオ | E8: =DBCS(元データ!C5) -> 粉 | F8: =DBCS(元データ!D5) -> ２．５ｇｘ１８９ | G8: =元データ!E5 -> ツムラ | H8: =元データ!F5 -> 14.6 | I8: =元データ!G5 -> 6898.5 | J8: =元データ!H5 -> 472.5 | K8: =元データ!I5 -> ｇ | L8: =元データ!J5 -> 6211 | M8: =元データ!K5 -> 13.144974 | N8: =IF(OFFSET(マスタ非採用削除!A$4,統合マスタ!$A8,0)="","",OFFSET(マスタ非採用削除!A$4,統合マスタ!$A8,0)) -> ﾂﾑﾗ016 | O8: =IF(OFFSET(マスタ非採用削除!B$4,統合マスタ!$A8,0)="","",OFFSET(マスタ非採用削除!B$4,統合マスタ!$A8,0)) -> ﾂﾑﾗ016 | P8: =IF(OFFSET(マスタ非採用削除!C$4,統合マスタ!$A8,0)="","",OFFSET(マスタ非採用削除!C$4,統合マスタ!$A8,0)) -> ツムラ半夏厚朴湯エキス顆粒（医療用） | Q8: =IF(OFFSET(マスタ非採用削除!D$4,統合マスタ!$A8,0)="","",OFFSET(マスタ非採用削除!D$4,統合マスタ!$A8,0)) -> ﾊﾝｹﾞｺ | R8: =IF(AA8="非採用",0,IF(OFFSET(マスタ非採用削除!E$4,統合マスタ!$A8,0)="","",OFFSET(マスタ非採用削除!E$4,統合マスタ!$A8,0))) -> 2 | S8: =IF(OFFSET(マスタ非採用削除!F$4,統合マスタ!$A8,0)="","",OFFSET(マスタ非採用削除!F$4,統合マスタ!$A8,0)) | T8: =IF(OFFSET(マスタ非採用削除!G$4,統合マスタ!$A8,0)="","",OFFSET(マスタ非採用削除!G$4,統合マスタ!$A8,0)) -> 14.6 | U8: =IF(OFFSET(マスタ非採用削除!H$4,統合マスタ!$A8,0)="","",OFFSET(マスタ非採用削除!H$4,統合マスタ!$A8,0)) -> ﾂﾑﾗﾊﾝｹﾞｺｳﾎﾞｸﾄｳｴｷｽｶﾘｭｳ(ｲﾘｮｳﾖｳ) | V8: =IF(OFFSET(マスタ非採用削除!I$4,統合マスタ!$A8,0)="","",OFFSET(マスタ非採用削除!I$4,統合マスタ!$A8,0)) -> 3 | W8: =IF(OFFSET(マスタ非採用削除!J$4,統合マスタ!$A8,0)="","",OFFSET(マスタ非採用削除!J$4,統合マスタ!$A8,0)) -> 散 | X8: =IF(OFFSET(マスタ非採用削除!K$4,統合マスタ!$A8,0)="","",OFFSET(マスタ非採用削除!K$4,統合マスタ!$A8,0)) -> 0 | Y8: =IF(OFFSET(マスタ非採用削除!L$4,統合マスタ!$A8,0)="","",OFFSET(マスタ非採用削除!L$4,統合マスタ!$A8,0)) | Z8: =IF(OFFSET(マスタ非採用削除!M$4,統合マスタ!$A8,0)="","",OFFSET(マスタ非採用削除!M$4,統合マスタ!$A8,0)) -> 4 | AB8: =IF(R8=2,"臨時", IF(COUNTIF(分類!$H$8:$H$15, 統合マスタ!V8)>0, 分類!$G$7, IF(COUNTIF(分類!$K$8:$K$15, 統合マスタ!V8)>0, 分類!$J$7, IF(COUNTIF(分類!$N$8:$N$15, 統合マスタ!V8)>0, 分類!$M$7, IF(COUNTIF(分類!$Q$8:$Q$15, 統合マスタ!V8)>0, 分類!$P$7, "無し"))))) -> 臨時 | AC8: =X8 * 100000 + B8 -> 4 | AD8: {=IF(A8="非採用","非採用",OFFSET( INDIRECT("'" & AB8 & "'!A4"), MATCH(B8, INDIRECT("'" & AB8 & "'!C5:C1000"), 0), MATCH("合計", INDIRECT("'" & AB8 & "'!4:4"), 0) - 1 ))} -> 0
A9: =元データ!P6 -> 298 | B9: =B8+1 -> 5 | C9: =DBCS(元データ!A6) -> ０１７ ツムラ ゴレイサン | D9: =元データ!B6 -> メディセオ | E9: =DBCS(元データ!C6) -> 粉 | F9: =DBCS(元データ!D6) -> ２．５ｇｘ１８９ | G9: =元データ!E6 -> ツムラ | H9: =元データ!F6 -> 13.6 | I9: =元データ!G6 -> 6426 | J9: =元データ!H6 -> 472.5 | K9: =元データ!I6 -> g | L9: =元データ!J6 -> 5728 | M9: =元データ!K6 -> 12.122751 | N9: =IF(OFFSET(マスタ非採用削除!A$4,統合マスタ!$A9,0)="","",OFFSET(マスタ非採用削除!A$4,統合マスタ!$A9,0)) -> ﾂﾑﾗ017 | O9: =IF(OFFSET(マスタ非採用削除!B$4,統合マスタ!$A9,0)="","",OFFSET(マスタ非採用削除!B$4,統合マスタ!$A9,0)) -> ﾂﾑﾗ017 | P9: =IF(OFFSET(マスタ非採用削除!C$4,統合マスタ!$A9,0)="","",OFFSET(マスタ非採用削除!C$4,統合マスタ!$A9,0)) -> ツムラ五苓散エキス顆粒（医療用） | Q9: =IF(OFFSET(マスタ非採用削除!D$4,統合マスタ!$A9,0)="","",OFFSET(マスタ非採用削除!D$4,統合マスタ!$A9,0)) -> ｺﾞﾚｲ | R9: =IF(AA9="非採用",0,IF(OFFSET(マスタ非採用削除!E$4,統合マスタ!$A9,0)="","",OFFSET(マスタ非採用削除!E$4,統合マスタ!$A9,0))) -> 1 | S9: =IF(OFFSET(マスタ非採用削除!F$4,統合マスタ!$A9,0)="","",OFFSET(マスタ非採用削除!F$4,統合マスタ!$A9,0)) | T9: =IF(OFFSET(マスタ非採用削除!G$4,統合マスタ!$A9,0)="","",OFFSET(マスタ非採用削除!G$4,統合マスタ!$A9,0)) -> 13.6 | U9: =IF(OFFSET(マスタ非採用削除!H$4,統合マスタ!$A9,0)="","",OFFSET(マスタ非採用削除!H$4,統合マスタ!$A9,0)) -> ﾂﾑﾗｺﾞﾚｲｻﾝｴｷｽｶﾘｭｳ(ｲﾘｮｳﾖｳ) | V9: =IF(OFFSET(マスタ非採用削除!I$4,統合マスタ!$A9,0)="","",OFFSET(マスタ非採用削除!I$4,統合マスタ!$A9,0)) -> 3 | W9: =IF(OFFSET(マスタ非採用削除!J$4,統合マスタ!$A9,0)="","",OFFSET(マスタ非採用削除!J$4,統合マスタ!$A9,0)) -> 散 | X9: =IF(OFFSET(マスタ非採用削除!K$4,統合マスタ!$A9,0)="","",OFFSET(マスタ非採用削除!K$4,統合マスタ!$A9,0)) -> 0 | Y9: =IF(OFFSET(マスタ非採用削除!L$4,統合マスタ!$A9,0)="","",OFFSET(マスタ非採用削除!L$4,統合マスタ!$A9,0)) | Z9: =IF(OFFSET(マスタ非採用削除!M$4,統合マスタ!$A9,0)="","",OFFSET(マスタ非採用削除!M$4,統合マスタ!$A9,0)) -> 4 | AB9: =IF(R9=2,"臨時", IF(COUNTIF(分類!$H$8:$H$15, 統合マスタ!V9)>0, 分類!$G$7, IF(COUNTIF(分類!$K$8:$K$15, 統合マスタ!V9)>0, 分類!$J$7, IF(COUNTIF(分類!$N$8:$N$15, 統合マスタ!V9)>0, 分類!$M$7, IF(COUNTIF(分類!$Q$8:$Q$15, 統合マスタ!V9)>0, 分類!$P$7, "無し"))))) -> 散剤 | AC9: =X9 * 100000 + B9 -> 5 | AD9: {=IF(A9="非採用","非採用",OFFSET( INDIRECT("'" & AB9 & "'!A4"), MATCH(B9, INDIRECT("'" & AB9 & "'!C5:C1000"), 0), MATCH("合計", INDIRECT("'" & AB9 & "'!4:4"), 0) - 1 ))} -> 0
A10: =元データ!P7 -> 299 | B10: =B9+1 -> 6 | C10: =DBCS(元データ!A7) -> ０１９ ツムラ ショウセイリュウトウ | D10: =元データ!B7 -> メディセオ | E10: =DBCS(元データ!C7) -> 粉 | F10: =DBCS(元データ!D7) -> ３ｇＸ４２ | G10: =元データ!E7 -> ツムラ | H10: =元データ!F7 -> 12.8 | I10: =元データ!G7 -> 1612.8 | J10: =元データ!H7 -> 126 | K10: =元データ!I7 -> g | L10: =元データ!J7 -> 1465 | M10: =元データ!K7 -> 11.626984 | N10: =IF(OFFSET(マスタ非採用削除!A$4,統合マスタ!$A10,0)="","",OFFSET(マスタ非採用削除!A$4,統合マスタ!$A10,0)) -> ﾂﾑﾗ019 | O10: =IF(OFFSET(マスタ非採用削除!B$4,統合マスタ!$A10,0)="","",OFFSET(マスタ非採用削除!B$4,統合マスタ!$A10,0)) -> ﾂﾑﾗ019 | P10: =IF(OFFSET(マスタ非採用削除!C$4,統合マスタ!$A10,0)="","",OFFSET(マスタ非採用削除!C$4,統合マスタ!$A10,0)) -> ツムラ小青竜湯エキス顆粒（医療用） | Q10: =IF(OFFSET(マスタ非採用削除!D$4,統合マスタ!$A10,0)="","",OFFSET(マスタ非採用削除!D$4,統合マスタ!$A10,0)) | R10: =IF(AA10="非採用",0,IF(OFFSET(マスタ非採用削除!E$4,統合マスタ!$A10,0)="","",OFFSET(マスタ非採用削除!E$4,統合マスタ!$A10,0))) -> 2 | S10: =IF(OFFSET(マスタ非採用削除!F$4,統合マスタ!$A10,0)="","",OFFSET(マスタ非採用削除!F$4,統合マスタ!$A10,0)) | T10: =IF(OFFSET(マスタ非採用削除!G$4,統合マスタ!$A10,0)="","",OFFSET(マスタ非採用削除!G$4,統合マスタ!$A10,0)) -> 12.8 | U10: =IF(OFFSET(マスタ非採用削除!H$4,統合マスタ!$A10,0)="","",OFFSET(マスタ非採用削除!H$4,統合マスタ!$A10,0)) -> ﾂﾑﾗｼﾖｳｾｲﾘﾕｳﾄｳｴｷｽｶﾘﾕｳｲﾘﾖｳﾖｳ | V10: =IF(OFFSET(マスタ非採用削除!I$4,統合マスタ!$A10,0)="","",OFFSET(マスタ非採用削除!I$4,統合マスタ!$A10,0)) -> 5 | W10: =IF(OFFSET(マスタ非採用削除!J$4,統合マスタ!$A10,0)="","",OFFSET(マスタ非採用削除!J$4,統合マスタ!$A10,0)) -> 顆粒 | X10: =IF(OFFSET(マスタ非採用削除!K$4,統合マスタ!$A10,0)="","",OFFSET(マスタ非採用削除!K$4,統合マスタ!$A10,0)) -> 0 | Y10: =IF(OFFSET(マスタ非採用削除!L$4,統合マスタ!$A10,0)="","",OFFSET(マスタ非採用削除!L$4,統合マスタ!$A10,0)) | Z10: =IF(OFFSET(マスタ非採用削除!M$4,統合マスタ!$A10,0)="","",OFFSET(マスタ非採用削除!M$4,統合マスタ!$A10,0)) -> 4 | AB10: =IF(R10=2,"臨時", IF(COUNTIF(分類!$H$8:$H$15, 統合マスタ!V10)>0, 分類!$G$7, IF(COUNTIF(分類!$K$8:$K$15, 統合マスタ!V10)>0, 分類!$J$7, IF(COUNTIF(分類!$N$8:$N$15, 統合マスタ!V10)>0, 分類!$M$7, IF(COUNTIF(分類!$Q$8:$Q$15, 統合マスタ!V10)>0, 分類!$P$7, "無し"))))) -> 臨時 | AC10: =X10 * 100000 + B10 -> 6 | AD10: {=IF(A10="非採用","非採用",OFFSET( INDIRECT("'" & AB10 & "'!A4"), MATCH(B10, INDIRECT("'" & AB10 & "'!C5:C1000"), 0), MATCH("合計", INDIRECT("'" & AB10 & "'!4:4"), 0) - 1 ))} -> 0
A11: =元データ!P8 -> 301 | B11: =B10+1 -> 7 | C11: =DBCS(元データ!A8) -> ０４３ ツムラ リツクンシトウ | D11: =元データ!B8 -> メディセオ | E11: =DBCS(元データ!C8) -> 粉 | F11: =DBCS(元データ!D8) -> ２．５ｇｘ１８９ | G11: =元データ!E8 -> ツムラ | H11: =元データ!F8 -> 18 | I11: =元データ!G8 -> 8505 | J11: =元データ!H8 -> 472.5 | K11: =元データ!I8 -> g | L11: =元データ!J8 -> 7576 | M11: =元データ!K8 -> 16.033862 | N11: =IF(OFFSET(マスタ非採用削除!A$4,統合マスタ!$A11,0)="","",OFFSET(マスタ非採用削除!A$4,統合マスタ!$A11,0)) -> ﾂﾑﾗ043 | O11: =IF(OFFSET(マスタ非採用削除!B$4,統合マスタ!$A11,0)="","",OFFSET(マスタ非採用削除!B$4,統合マスタ!$A11,0)) -> ﾂﾑﾗ043 | P11: =IF(OFFSET(マスタ非採用削除!C$4,統合マスタ!$A11,0)="","",OFFSET(マスタ非採用削除!C$4,統合マスタ!$A11,0)) -> ツムラ六君子湯エキス顆粒（医療用） | Q11: =IF(OFFSET(マスタ非採用削除!D$4,統合マスタ!$A11,0)="","",OFFSET(マスタ非採用削除!D$4,統合マスタ!$A11,0)) -> ﾘｯｸ | R11: =IF(AA11="非採用",0,IF(OFFSET(マスタ非採用削除!E$4,統合マスタ!$A11,0)="","",OFFSET(マスタ非採用削除!E$4,統合マスタ!$A11,0))) -> 2 | S11: =IF(OFFSET(マスタ非採用削除!F$4,統合マスタ!$A11,0)="","",OFFSET(マスタ非採用削除!F$4,統合マスタ!$A11,0)) | T11: =IF(OFFSET(マスタ非採用削除!G$4,統合マスタ!$A11,0)="","",OFFSET(マスタ非採用削除!G$4,統合マスタ!$A11,0)) -> 18 | U11: =IF(OFFSET(マスタ非採用削除!H$4,統合マスタ!$A11,0)="","",OFFSET(マスタ非採用削除!H$4,統合マスタ!$A11,0)) -> ﾂﾑﾗﾘｯｸﾝｼﾄｳｴｷｽｶﾘｭｳ(ｲﾘｮｳﾖｳ) | V11: =IF(OFFSET(マスタ非採用削除!I$4,統合マスタ!$A11,0)="","",OFFSET(マスタ非採用削除!I$4,統合マスタ!$A11,0)) -> 3 | W11: =IF(OFFSET(マスタ非採用削除!J$4,統合マスタ!$A11,0)="","",OFFSET(マスタ非採用削除!J$4,統合マスタ!$A11,0)) -> 散 | X11: =IF(OFFSET(マスタ非採用削除!K$4,統合マスタ!$A11,0)="","",OFFSET(マスタ非採用削除!K$4,統合マスタ!$A11,0)) -> 0 | Y11: =IF(OFFSET(マスタ非採用削除!L$4,統合マスタ!$A11,0)="","",OFFSET(マスタ非採用削除!L$4,統合マスタ!$A11,0)) | Z11: =IF(OFFSET(マスタ非採用削除!M$4,統合マスタ!$A11,0)="","",OFFSET(マスタ非採用削除!M$4,統合マスタ!$A11,0)) -> 4 | AB11: =IF(R11=2,"臨時", IF(COUNTIF(分類!$H$8:$H$15, 統合マスタ!V11)>0, 分類!$G$7, IF(COUNTIF(分類!$K$8:$K$15, 統合マスタ!V11)>0, 分類!$J$7, IF(COUNTIF(分類!$N$8:$N$15, 統合マスタ!V11)>0, 分類!$M$7, IF(COUNTIF(分類!$Q$8:$Q$15, 統合マスタ!V11)>0, 分類!$P$7, "無し"))))) -> 臨時 | AC11: =X11 * 100000 + B11 -> 7 | AD11: {=IF(A11="非採用","非採用",OFFSET( INDIRECT("'" & AB11 & "'!A4"), MATCH(B11, INDIRECT("'" & AB11 & "'!C5:C1000"), 0), MATCH("合計", INDIRECT("'" & AB11 & "'!4:4"), 0) - 1 ))} -> 0
A12: =元データ!P9 -> 非採用 | B12: =B11+1 -> 8 | C12: =DBCS(元データ!A9) -> ０４８ ツムラ ジュウゼンタイホトウ | D12: =元データ!B9 | E12: =DBCS(元データ!C9) -> 粉 | F12: =DBCS(元データ!D9) -> ２．５ｇｘ１８９包 | G12: =元データ!E9 -> ツムラ | H12: =元データ!F9 -> 18.4 | I12: =元データ!G9 -> 8694 | J12: =元データ!H9 -> 472.5 | K12: =元データ!I9 -> g | L12: =元データ!J9 -> 7750 | M12: =元データ!K9 -> 16.402116 | N12: =IF(OFFSET(マスタ非採用削除!A$4,統合マスタ!$A12,0)="","",OFFSET(マスタ非採用削除!A$4,統合マスタ!$A12,0)) -> #VALUE! | O12: =IF(OFFSET(マスタ非採用削除!B$4,統合マスタ!$A12,0)="","",OFFSET(マスタ非採用削除!B$4,統合マスタ!$A12,0)) -> #VALUE! | P12: =IF(OFFSET(マスタ非採用削除!C$4,統合マスタ!$A12,0)="","",OFFSET(マスタ非採用削除!C$4,統合マスタ!$A12,0)) -> #VALUE! | Q12: =IF(OFFSET(マスタ非採用削除!D$4,統合マスタ!$A12,0)="","",OFFSET(マスタ非採用削除!D$4,統合マスタ!$A12,0)) -> #VALUE! | R12: =IF(AA12="非採用",0,IF(OFFSET(マスタ非採用削除!E$4,統合マスタ!$A12,0)="","",OFFSET(マスタ非採用削除!E$4,統合マスタ!$A12,0))) -> 0 | S12: =IF(OFFSET(マスタ非採用削除!F$4,統合マスタ!$A12,0)="","",OFFSET(マスタ非採用削除!F$4,統合マスタ!$A12,0)) -> #VALUE! | T12: =IF(OFFSET(マスタ非採用削除!G$4,統合マスタ!$A12,0)="","",OFFSET(マスタ非採用削除!G$4,統合マスタ!$A12,0)) -> #VALUE! | U12: =IF(OFFSET(マスタ非採用削除!H$4,統合マスタ!$A12,0)="","",OFFSET(マスタ非採用削除!H$4,統合マスタ!$A12,0)) -> #VALUE! | V12: =IF(OFFSET(マスタ非採用削除!I$4,統合マスタ!$A12,0)="","",OFFSET(マスタ非採用削除!I$4,統合マスタ!$A12,0)) -> #VALUE! | W12: =IF(OFFSET(マスタ非採用削除!J$4,統合マスタ!$A12,0)="","",OFFSET(マスタ非採用削除!J$4,統合マスタ!$A12,0)) -> #VALUE! | X12: =IF(OFFSET(マスタ非採用削除!K$4,統合マスタ!$A12,0)="","",OFFSET(マスタ非採用削除!K$4,統合マスタ!$A12,0)) -> #VALUE! | Y12: =IF(OFFSET(マスタ非採用削除!L$4,統合マスタ!$A12,0)="","",OFFSET(マスタ非採用削除!L$4,統合マスタ!$A12,0)) -> #VALUE! | Z12: =IF(OFFSET(マスタ非採用削除!M$4,統合マスタ!$A12,0)="","",OFFSET(マスタ非採用削除!M$4,統合マスタ!$A12,0)) -> #VALUE! | AA12: 非採用 | AB12: =IF(R12=2,"臨時", IF(COUNTIF(分類!$H$8:$H$15, 統合マスタ!V12)>0, 分類!$G$7, IF(COUNTIF(分類!$K$8:$K$15, 統合マスタ!V12)>0, 分類!$J$7, IF(COUNTIF(分類!$N$8:$N$15, 統合マスタ!V12)>0, 分類!$M$7, IF(COUNTIF(分類!$Q$8:$Q$15, 統合マスタ!V12)>0, 分類!$P$7, "無し"))))) -> 無し | AC12: =X12 * 100000 + B12 -> #VALUE! | AD12: {=IF(A12="非採用","非採用",OFFSET( INDIRECT("'" & AB12 & "'!A4"), MATCH(B12, INDIRECT("'" & AB12 & "'!C5:C1000"), 0), MATCH("合計", INDIRECT("'" & AB12 & "'!4:4"), 0) - 1 ))} -> 非採用
A13: =元データ!P10 -> 302 | B13: =B12+1 -> 9 | C13: =DBCS(元データ!A10) -> ０５４ ツムラ ヨクカンサン | D13: =元データ!B10 -> メディセオ | E13: =DBCS(元データ!C10) -> 粉 | F13: =DBCS(元データ!D10) -> ２．５ｇＸ１８９ | G13: =元データ!E10 -> ツムラ | H13: =元データ!F10 -> 16.1 | I13: =元データ!G10 -> 7607.25 | J13: =元データ!H10 -> 472.5 | K13: =元データ!I10 -> g | L13: =元データ!J10 -> 6849 | M13: =元データ!K10 -> 14.495238 | N13: =IF(OFFSET(マスタ非採用削除!A$4,統合マスタ!$A13,0)="","",OFFSET(マスタ非採用削除!A$4,統合マスタ!$A13,0)) -> ﾂﾑﾗ054 | O13: =IF(OFFSET(マスタ非採用削除!B$4,統合マスタ!$A13,0)="","",OFFSET(マスタ非採用削除!B$4,統合マスタ!$A13,0)) -> ﾂﾑﾗ054 | P13: =IF(OFFSET(マスタ非採用削除!C$4,統合マスタ!$A13,0)="","",OFFSET(マスタ非採用削除!C$4,統合マスタ!$A13,0)) -> ツムラ抑肝散エキス顆粒（医療用） | Q13: =IF(OFFSET(マスタ非採用削除!D$4,統合マスタ!$A13,0)="","",OFFSET(マスタ非採用削除!D$4,統合マスタ!$A13,0)) -> ﾖｸｶ | R13: =IF(AA13="非採用",0,IF(OFFSET(マスタ非採用削除!E$4,統合マスタ!$A13,0)="","",OFFSET(マスタ非採用削除!E$4,統合マスタ!$A13,0))) -> 1 | S13: =IF(OFFSET(マスタ非採用削除!F$4,統合マスタ!$A13,0)="","",OFFSET(マスタ非採用削除!F$4,統合マスタ!$A13,0)) | T13: =IF(OFFSET(マスタ非採用削除!G$4,統合マスタ!$A13,0)="","",OFFSET(マスタ非採用削除!G$4,統合マスタ!$A13,0)) -> 16.1 | U13: =IF(OFFSET(マスタ非採用削除!H$4,統合マスタ!$A13,0)="","",OFFSET(マスタ非採用削除!H$4,統合マスタ!$A13,0)) -> ﾂﾑﾗﾖｸｶﾝｻﾝｴｷｽｶﾘｭｳ(ｲﾘｮｳﾖｳ) | V13: =IF(OFFSET(マスタ非採用削除!I$4,統合マスタ!$A13,0)="","",OFFSET(マスタ非採用削除!I$4,統合マスタ!$A13,0)) -> 3 | W13: =IF(OFFSET(マスタ非採用削除!J$4,統合マスタ!$A13,0)="","",OFFSET(マスタ非採用削除!J$4,統合マスタ!$A13,0)) -> 散 | X13: =IF(OFFSET(マスタ非採用削除!K$4,統合マスタ!$A13,0)="","",OFFSET(マスタ非採用削除!K$4,統合マスタ!$A13,0)) -> 0 | Y13: =IF(OFFSET(マスタ非採用削除!L$4,統合マスタ!$A13,0)="","",OFFSET(マスタ非採用削除!L$4,統合マスタ!$A13,0)) | Z13: =IF(OFFSET(マスタ非採用削除!M$4,統合マスタ!$A13,0)="","",OFFSET(マスタ非採用削除!M$4,統合マスタ!$A13,0)) -> 4 | AB13: =IF(R13=2,"臨時", IF(COUNTIF(分類!$H$8:$H$15, 統合マスタ!V13)>0, 分類!$G$7, IF(COUNTIF(分類!$K$8:$K$15, 統合マスタ!V13)>0, 分類!$J$7, IF(COUNTIF(分類!$N$8:$N$15, 統合マスタ!V13)>0, 分類!$M$7, IF(COUNTIF(分類!$Q$8:$Q$15, 統合マスタ!V13)>0, 分類!$P$7, "無し"))))) -> 散剤 | AC13: =X13 * 100000 + B13 -> 9 | AD13: {=IF(A13="非採用","非採用",OFFSET( INDIRECT("'" & AB13 & "'!A4"), MATCH(B13, INDIRECT("'" & AB13 & "'!C5:C1000"), 0), MATCH("合計", INDIRECT("'" & AB13 & "'!4:4"), 0) - 1 ))} -> 0
A14: =元データ!P11 -> 303 | B14: =B13+1 -> 10 | C14: =DBCS(元データ!A11) -> ０６２ ツムラ ボウフウツウシヨウサン | D14: =元データ!B11 -> メディセオ | E14: =DBCS(元データ!C11) -> 粉 | F14: =DBCS(元データ!D11) -> ２．５ｇｘ１８９ | G14: =元データ!E11 -> ツムラ | H14: =元データ!F11 -> 13.8 | I14: =元データ!G11 -> 6520.5 | J14: =元データ!H11 -> 472.5 | K14: =元データ!I11 -> g | L14: =元データ!J11 -> 5871 | M14: =元データ!K11 -> 12.425397 | N14: =IF(OFFSET(マスタ非採用削除!A$4,統合マスタ!$A14,0)="","",OFFSET(マスタ非採用削除!A$4,統合マスタ!$A14,0)) -> ﾂﾑﾗ062 | O14: =IF(OFFSET(マスタ非採用削除!B$4,統合マスタ!$A14,0)="","",OFFSET(マスタ非採用削除!B$4,統合マスタ!$A14,0)) -> ﾂﾑﾗ062 | P14: =IF(OFFSET(マスタ非採用削除!C$4,統合マスタ!$A14,0)="","",OFFSET(マスタ非採用削除!C$4,統合マスタ!$A14,0)) -> ツムラ防風通聖散エキス顆粒（医療用） | Q14: =IF(OFFSET(マスタ非採用削除!D$4,統合マスタ!$A14,0)="","",OFFSET(マスタ非採用削除!D$4,統合マスタ!$A14,0)) -> ﾎﾞｳﾌｳ | R14: =IF(AA14="非採用",0,IF(OFFSET(マスタ非採用削除!E$4,統合マスタ!$A14,0)="","",OFFSET(マスタ非採用削除!E$4,統合マスタ!$A14,0))) -> 1 | S14: =IF(OFFSET(マスタ非採用削除!F$4,統合マスタ!$A14,0)="","",OFFSET(マスタ非採用削除!F$4,統合マスタ!$A14,0)) | T14: =IF(OFFSET(マスタ非採用削除!G$4,統合マスタ!$A14,0)="","",OFFSET(マスタ非採用削除!G$4,統合マスタ!$A14,0)) -> 13.8 | U14: =IF(OFFSET(マスタ非採用削除!H$4,統合マスタ!$A14,0)="","",OFFSET(マスタ非採用削除!H$4,統合マスタ!$A14,0)) -> ﾂﾑﾗﾎﾞｳﾌｳﾂｳｼｮｳｻﾝｴｷｽｶﾘｭｳ(ｲﾘｮｳﾖｳ) | V14: =IF(OFFSET(マスタ非採用削除!I$4,統合マスタ!$A14,0)="","",OFFSET(マスタ非採用削除!I$4,統合マスタ!$A14,0)) -> 3 | W14: =IF(OFFSET(マスタ非採用削除!J$4,統合マスタ!$A14,0)="","",OFFSET(マスタ非採用削除!J$4,統合マスタ!$A14,0)) -> 散 | X14: =IF(OFFSET(マスタ非採用削除!K$4,統合マスタ!$A14,0)="","",OFFSET(マスタ非採用削除!K$4,統合マスタ!$A14,0)) -> 0 | Y14: =IF(OFFSET(マスタ非採用削除!L$4,統合マスタ!$A14,0)="","",OFFSET(マスタ非採用削除!L$4,統合マスタ!$A14,0)) | Z14: =IF(OFFSET(マスタ非採用削除!M$4,統合マスタ!$A14,0)="","",OFFSET(マスタ非採用削除!M$4,統合マスタ!$A14,0)) -> 4 | AB14: =IF(R14=2,"臨時", IF(COUNTIF(分類!$H$8:$H$15, 統合マスタ!V14)>0, 分類!$G$7, IF(COUNTIF(分類!$K$8:$K$15, 統合マスタ!V14)>0, 分類!$J$7, IF(COUNTIF(分類!$N$8:$N$15, 統合マスタ!V14)>0, 分類!$M$7, IF(COUNTIF(分類!$Q$8:$Q$15, 統合マスタ!V14)>0, 分類!$P$7, "無し"))))) -> 散剤 | AC14: =X14 * 100000 + B14 -> 10 | AD14: {=IF(A14="非採用","非採用",OFFSET( INDIRECT("'" & AB14 & "'!A4"), MATCH(B14, INDIRECT("'" & AB14 & "'!C5:C1000"), 0), MATCH("合計", INDIRECT("'" & AB14 & "'!4:4"), 0) - 1 ))} -> 0
A15: =元データ!P12 -> 304 | B15: =B14+1 -> 11 | C15: =DBCS(元データ!A12) -> ０６８ ツムラ シャクヤクカンゾウトウ | D15: =元データ!B12 -> メディセオ | E15: =DBCS(元データ!C12) -> 粉 | F15: =DBCS(元データ!D12) -> ２．５ｇｘ４２ | G15: =元データ!E12 -> ツムラ | H15: =元データ!F12 -> 10.4 | I15: =元データ!G12 -> 1092 | J15: =元データ!H12 -> 105 | K15: =元データ!I12 -> g | L15: =元データ!J12 -> 992 | M15: =元データ!K12 -> 9.447619 | N15: =IF(OFFSET(マスタ非採用削除!A$4,統合マスタ!$A15,0)="","",OFFSET(マスタ非採用削除!A$4,統合マスタ!$A15,0)) -> ﾂﾑﾗ068 | O15: =IF(OFFSET(マスタ非採用削除!B$4,統合マスタ!$A15,0)="","",OFFSET(マスタ非採用削除!B$4,統合マスタ!$A15,0)) -> ﾂﾑﾗ068 | P15: =IF(OFFSET(マスタ非採用削除!C$4,統合マスタ!$A15,0)="","",OFFSET(マスタ非採用削除!C$4,統合マスタ!$A15,0)) -> ツムラ芍薬甘草湯エキス顆粒（医療用） | Q15: =IF(OFFSET(マスタ非採用削除!D$4,統合マスタ!$A15,0)="","",OFFSET(マスタ非採用削除!D$4,統合マスタ!$A15,0)) -> ｼｬｸ | R15: =IF(AA15="非採用",0,IF(OFFSET(マスタ非採用削除!E$4,統合マスタ!$A15,0)="","",OFFSET(マスタ非採用削除!E$4,統合マスタ!$A15,0))) -> 1 | S15: =IF(OFFSET(マスタ非採用削除!F$4,統合マスタ!$A15,0)="","",OFFSET(マスタ非採用削除!F$4,統合マスタ!$A15,0)) | T15: =IF(OFFSET(マスタ非採用削除!G$4,統合マスタ!$A15,0)="","",OFFSET(マスタ非採用削除!G$4,統合マスタ!$A15,0)) -> 10.4 | U15: =IF(OFFSET(マスタ非採用削除!H$4,統合マスタ!$A15,0)="","",OFFSET(マスタ非採用削除!H$4,統合マスタ!$A15,0)) -> ﾂﾑﾗｼｬｸﾔｸｶﾝｿﾞｳﾄｳｴｷｽｶﾘｭｳ(ｲﾘｮｳﾖｳ) | V15: =IF(OFFSET(マスタ非採用削除!I$4,統合マスタ!$A15,0)="","",OFFSET(マスタ非採用削除!I$4,統合マスタ!$A15,0)) -> 3 | W15: =IF(OFFSET(マスタ非採用削除!J$4,統合マスタ!$A15,0)="","",OFFSET(マスタ非採用削除!J$4,統合マスタ!$A15,0)) -> 散 | X15: =IF(OFFSET(マスタ非採用削除!K$4,統合マスタ!$A15,0)="","",OFFSET(マスタ非採用削除!K$4,統合マスタ!$A15,0)) -> 0 | Y15: =IF(OFFSET(マスタ非採用削除!L$4,統合マスタ!$A15,0)="","",OFFSET(マスタ非採用削除!L$4,統合マスタ!$A15,0)) | Z15: =IF(OFFSET(マスタ非採用削除!M$4,統合マスタ!$A15,0)="","",OFFSET(マスタ非採用削除!M$4,統合マスタ!$A15,0)) -> 4 | AB15: =IF(R15=2,"臨時", IF(COUNTIF(分類!$H$8:$H$15, 統合マスタ!V15)>0, 分類!$G$7, IF(COUNTIF(分類!$K$8:$K$15, 統合マスタ!V15)>0, 分類!$J$7, IF(COUNTIF(分類!$N$8:$N$15, 統合マスタ!V15)>0, 分類!$M$7, IF(COUNTIF(分類!$Q$8:$Q$15, 統合マスタ!V15)>0, 分類!$P$7, "無し"))))) -> 散剤 | AC15: =X15 * 100000 + B15 -> 11 | AD15: {=IF(A15="非採用","非採用",OFFSET( INDIRECT("'" & AB15 & "'!A4"), MATCH(B15, INDIRECT("'" & AB15 & "'!C5:C1000"), 0), MATCH("合計", INDIRECT("'" & AB15 & "'!4:4"), 0) - 1 ))} -> 0
A16: =元データ!P13 -> 305 | B16: =B15+1 -> 12 | C16: =DBCS(元データ!A13) -> ０８３ ツムラ ヨクカンサンカチンピハンゲ | D16: =元データ!B13 -> メディセオ | E16: =DBCS(元データ!C13) -> 粉 | F16: =DBCS(元データ!D13) -> ２．５ｇｘ１８９ | G16: =元データ!E13 -> ツムラ | H16: =元データ!F13 -> 14.4 | I16: =元データ!G13 -> 6804 | J16: =元データ!H13 -> 472.5 | K16: =元データ!I13 -> g | L16: =元データ!J13 -> 6065 | M16: =元データ!K13 -> 12.835979 | N16: =IF(OFFSET(マスタ非採用削除!A$4,統合マスタ!$A16,0)="","",OFFSET(マスタ非採用削除!A$4,統合マスタ!$A16,0)) -> ﾂﾑﾗ083 | O16: =IF(OFFSET(マスタ非採用削除!B$4,統合マスタ!$A16,0)="","",OFFSET(マスタ非採用削除!B$4,統合マスタ!$A16,0)) -> ﾂﾑﾗ083 | P16: =IF(OFFSET(マスタ非採用削除!C$4,統合マスタ!$A16,0)="","",OFFSET(マスタ非採用削除!C$4,統合マスタ!$A16,0)) -> ツムラ抑肝散加陳皮半夏エキス顆粒（医療用） | Q16: =IF(OFFSET(マスタ非採用削除!D$4,統合マスタ!$A16,0)="","",OFFSET(マスタ非採用削除!D$4,統合マスタ!$A16,0)) -> ﾖｸｶﾁﾝ | R16: =IF(AA16="非採用",0,IF(OFFSET(マスタ非採用削除!E$4,統合マスタ!$A16,0)="","",OFFSET(マスタ非採用削除!E$4,統合マスタ!$A16,0))) -> 1 | S16: =IF(OFFSET(マスタ非採用削除!F$4,統合マスタ!$A16,0)="","",OFFSET(マスタ非採用削除!F$4,統合マスタ!$A16,0)) | T16: =IF(OFFSET(マスタ非採用削除!G$4,統合マスタ!$A16,0)="","",OFFSET(マスタ非採用削除!G$4,統合マスタ!$A16,0)) -> 14.4 | U16: =IF(OFFSET(マスタ非採用削除!H$4,統合マスタ!$A16,0)="","",OFFSET(マスタ非採用削除!H$4,統合マスタ!$A16,0)) -> ﾂﾑﾗﾖｸｶﾝｻﾝｶﾁﾝﾋﾟﾊﾝｹﾞｴｷｽｶﾘｭｳ(ｲﾘｮｳﾖｳ) | V16: =IF(OFFSET(マスタ非採用削除!I$4,統合マスタ!$A16,0)="","",OFFSET(マスタ非採用削除!I$4,統合マスタ!$A16,0)) -> 3 | W16: =IF(OFFSET(マスタ非採用削除!J$4,統合マスタ!$A16,0)="","",OFFSET(マスタ非採用削除!J$4,統合マスタ!$A16,0)) -> 散 | X16: =IF(OFFSET(マスタ非採用削除!K$4,統合マスタ!$A16,0)="","",OFFSET(マスタ非採用削除!K$4,統合マスタ!$A16,0)) -> 0 | Y16: =IF(OFFSET(マスタ非採用削除!L$4,統合マスタ!$A16,0)="","",OFFSET(マスタ非採用削除!L$4,統合マスタ!$A16,0)) | Z16: =IF(OFFSET(マスタ非採用削除!M$4,統合マスタ!$A16,0)="","",OFFSET(マスタ非採用削除!M$4,統合マスタ!$A16,0)) -> 4 | AB16: =IF(R16=2,"臨時", IF(COUNTIF(分類!$H$8:$H$15, 統合マスタ!V16)>0, 分類!$G$7, IF(COUNTIF(分類!$K$8:$K$15, 統合マスタ!V16)>0, 分類!$J$7, IF(COUNTIF(分類!$N$8:$N$15, 統合マスタ!V16)>0, 分類!$M$7, IF(COUNTIF(分類!$Q$8:$Q$15, 統合マスタ!V16)>0, 分類!$P$7, "無し"))))) -> 散剤 | AC16: =X16 * 100000 + B16 -> 12 | AD16: {=IF(A16="非採用","非採用",OFFSET( INDIRECT("'" & AB16 & "'!A4"), MATCH(B16, INDIRECT("'" & AB16 & "'!C5:C1000"), 0), MATCH("合計", INDIRECT("'" & AB16 & "'!4:4"), 0) - 1 ))} -> 0
A17: =元データ!P14 -> 306 | B17: =B16+1 -> 13 | C17: =DBCS(元データ!A14) -> １００ ツムラ ダイケンチユウトウ | D17: =元データ!B14 -> メディセオ | E17: =DBCS(元データ!C14) -> 粉 | F17: =DBCS(元データ!D14) -> ２．５ｇＸ１８９ | G17: =元データ!E14 -> ツムラ | H17: =元データ!F14 -> 13.7 | I17: =元データ!G14 -> 6473.25 | J17: =元データ!H14 -> 472.5 | K17: =元データ!I14 -> g | L17: =元データ!J14 -> 5828 | M17: =元データ!K14 -> 12.334392 | N17: =IF(OFFSET(マスタ非採用削除!A$4,統合マスタ!$A17,0)="","",OFFSET(マスタ非採用削除!A$4,統合マスタ!$A17,0)) -> ﾂﾑﾗ100 | O17: =IF(OFFSET(マスタ非採用削除!B$4,統合マスタ!$A17,0)="","",OFFSET(マスタ非採用削除!B$4,統合マスタ!$A17,0)) -> ﾂﾑﾗ100 | P17: =IF(OFFSET(マスタ非採用削除!C$4,統合マスタ!$A17,0)="","",OFFSET(マスタ非採用削除!C$4,統合マスタ!$A17,0)) -> ツムラ大建中湯エキス顆粒（医療用） | Q17: =IF(OFFSET(マスタ非採用削除!D$4,統合マスタ!$A17,0)="","",OFFSET(マスタ非採用削除!D$4,統合マスタ!$A17,0)) -> ﾀﾞｲｹﾝﾁ | R17: =IF(AA17="非採用",0,IF(OFFSET(マスタ非採用削除!E$4,統合マスタ!$A17,0)="","",OFFSET(マスタ非採用削除!E$4,統合マスタ!$A17,0))) -> 1 | S17: =IF(OFFSET(マスタ非採用削除!F$4,統合マスタ!$A17,0)="","",OFFSET(マスタ非採用削除!F$4,統合マスタ!$A17,0)) | T17: =IF(OFFSET(マスタ非採用削除!G$4,統合マスタ!$A17,0)="","",OFFSET(マスタ非採用削除!G$4,統合マスタ!$A17,0)) -> 13.7 | U17: =IF(OFFSET(マスタ非採用削除!H$4,統合マスタ!$A17,0)="","",OFFSET(マスタ非採用削除!H$4,統合マスタ!$A17,0)) -> ﾂﾑﾗﾀﾞｲｹﾝﾁｭｳﾄｳｴｷｽｶﾘｭｳ(ｲﾘｮｳﾖｳ) | V17: =IF(OFFSET(マスタ非採用削除!I$4,統合マスタ!$A17,0)="","",OFFSET(マスタ非採用削除!I$4,統合マスタ!$A17,0)) -> 3 | W17: =IF(OFFSET(マスタ非採用削除!J$4,統合マスタ!$A17,0)="","",OFFSET(マスタ非採用削除!J$4,統合マスタ!$A17,0)) -> 散 | X17: =IF(OFFSET(マスタ非採用削除!K$4,統合マスタ!$A17,0)="","",OFFSET(マスタ非採用削除!K$4,統合マスタ!$A17,0)) -> 0 | Y17: =IF(OFFSET(マスタ非採用削除!L$4,統合マスタ!$A17,0)="","",OFFSET(マスタ非採用削除!L$4,統合マスタ!$A17,0)) | Z17: =IF(OFFSET(マスタ非採用削除!M$4,統合マスタ!$A17,0)="","",OFFSET(マスタ非採用削除!M$4,統合マスタ!$A17,0)) -> 4 | AB17: =IF(R17=2,"臨時", IF(COUNTIF(分類!$H$8:$H$15, 統合マスタ!V17)>0, 分類!$G$7, IF(COUNTIF(分類!$K$8:$K$15, 統合マスタ!V17)>0, 分類!$J$7, IF(COUNTIF(分類!$N$8:$N$15, 統合マスタ!V17)>0, 分類!$M$7, IF(COUNTIF(分類!$Q$8:$Q$15, 統合マスタ!V17)>0, 分類!$P$7, "無し"))))) -> 散剤 | AC17: =X17 * 100000 + B17 -> 13 | AD17: {=IF(A17="非採用","非採用",OFFSET( INDIRECT("'" & AB17 & "'!A4"), MATCH(B17, INDIRECT("'" & AB17 & "'!C5:C1000"), 0), MATCH("合計", INDIRECT("'" & AB17 & "'!4:4"), 0) - 1 ))} -> 0
A18: =元データ!P15 -> 307 | B18: =B17+1 -> 14 | C18: =DBCS(元データ!A15) -> １０８ ツムラ ニンジンヨウエイトウ | D18: =元データ!B15 -> メディセオ | E18: =DBCS(元データ!C15) -> 粉 | F18: =DBCS(元データ!D15) -> ３ｇｘ４２包 | G18: =元データ!E15 -> ツムラ | H18: =元データ!F15 -> 20.1 | I18: =元データ!G15 -> 2532.6 | J18: =元データ!H15 -> 126 | K18: =元データ!I15 -> ｇ | L18: =元データ!J15 -> 2301 | M18: =元データ!K15 -> 18.261905 | N18: =IF(OFFSET(マスタ非採用削除!A$4,統合マスタ!$A18,0)="","",OFFSET(マスタ非採用削除!A$4,統合マスタ!$A18,0)) -> ﾂﾑﾗ108 | O18: =IF(OFFSET(マスタ非採用削除!B$4,統合マスタ!$A18,0)="","",OFFSET(マスタ非採用削除!B$4,統合マスタ!$A18,0)) -> ﾂﾑﾗ108 | P18: =IF(OFFSET(マスタ非採用削除!C$4,統合マスタ!$A18,0)="","",OFFSET(マスタ非採用削除!C$4,統合マスタ!$A18,0)) -> ツムラ人参養栄湯エキス顆粒（医療用） | Q18: =IF(OFFSET(マスタ非採用削除!D$4,統合マスタ!$A18,0)="","",OFFSET(マスタ非採用削除!D$4,統合マスタ!$A18,0)) -> ﾆﾝｼﾞﾝﾖ | R18: =IF(AA18="非採用",0,IF(OFFSET(マスタ非採用削除!E$4,統合マスタ!$A18,0)="","",OFFSET(マスタ非採用削除!E$4,統合マスタ!$A18,0))) -> 2 | S18: =IF(OFFSET(マスタ非採用削除!F$4,統合マスタ!$A18,0)="","",OFFSET(マスタ非採用削除!F$4,統合マスタ!$A18,0)) | T18: =IF(OFFSET(マスタ非採用削除!G$4,統合マスタ!$A18,0)="","",OFFSET(マスタ非採用削除!G$4,統合マスタ!$A18,0)) -> 20.1 | U18: =IF(OFFSET(マスタ非採用削除!H$4,統合マスタ!$A18,0)="","",OFFSET(マスタ非採用削除!H$4,統合マスタ!$A18,0)) -> ﾂﾑﾗﾆﾝｼﾞﾝﾖｳｴｲﾄｳｴｷｽｶﾘｭｳ(ｲﾘｮｳﾖｳ) | V18: =IF(OFFSET(マスタ非採用削除!I$4,統合マスタ!$A18,0)="","",OFFSET(マスタ非採用削除!I$4,統合マスタ!$A18,0)) -> 3 | W18: =IF(OFFSET(マスタ非採用削除!J$4,統合マスタ!$A18,0)="","",OFFSET(マスタ非採用削除!J$4,統合マスタ!$A18,0)) -> 散 | X18: =IF(OFFSET(マスタ非採用削除!K$4,統合マスタ!$A18,0)="","",OFFSET(マスタ非採用削除!K$4,統合マスタ!$A18,0)) -> 0 | Y18: =IF(OFFSET(マスタ非採用削除!L$4,統合マスタ!$A18,0)="","",OFFSET(マスタ非採用削除!L$4,統合マスタ!$A18,0)) | Z18: =IF(OFFSET(マスタ非採用削除!M$4,統合マスタ!$A18,0)="","",OFFSET(マスタ非採用削除!M$4,統合マスタ!$A18,0)) -> 4 | AB18: =IF(R18=2,"臨時", IF(COUNTIF(分類!$H$8:$H$15, 統合マスタ!V18)>0, 分類!$G$7, IF(COUNTIF(分類!$K$8:$K$15, 統合マスタ!V18)>0, 分類!$J$7, IF(COUNTIF(分類!$N$8:$N$15, 統合マスタ!V18)>0, 分類!$M$7, IF(COUNTIF(分類!$Q$8:$Q$15, 統合マスタ!V18)>0, 分類!$P$7, "無し"))))) -> 臨時 | AC18: =X18 * 100000 + B18 -> 14 | AD18: {=IF(A18="非採用","非採用",OFFSET( INDIRECT("'" & AB18 & "'!A4"), MATCH(B18, INDIRECT("'" & AB18 & "'!C5:C1000"), 0), MATCH("合計", INDIRECT("'" & AB18 & "'!4:4"), 0) - 1 ))} -> 0
A19: =元データ!P16 -> 308 | B19: =B18+1 -> 15 | C19: =DBCS(元データ!A16) -> １１２ ツムラ チョレイトウゴウシモットウ | D19: =元データ!B16 | E19: =DBCS(元データ!C16) -> 粉 | F19: =DBCS(元データ!D16) -> ２．５ｇｘ４２ | G19: =元データ!E16 -> ツムラ | H19: =元データ!F16 -> 22.9 | I19: =元データ!G16 -> 2404.5 | J19: =元データ!H16 -> 105 | K19: =元データ!I16 -> g | L19: =元データ!J16 -> 2185 | M19: =元データ!K16 -> 20.809524 | N19: =IF(OFFSET(マスタ非採用削除!A$4,統合マスタ!$A19,0)="","",OFFSET(マスタ非採用削除!A$4,統合マスタ!$A19,0)) -> ﾂﾑﾗ112 | O19: =IF(OFFSET(マスタ非採用削除!B$4,統合マスタ!$A19,0)="","",OFFSET(マスタ非採用削除!B$4,統合マスタ!$A19,0)) -> ﾂﾑﾗ112 | P19: =IF(OFFSET(マスタ非採用削除!C$4,統合マスタ!$A19,0)="","",OFFSET(マスタ非採用削除!C$4,統合マスタ!$A19,0)) -> ツムラ猪苓湯合四物湯エキス顆粒（医療用） | Q19: =IF(OFFSET(マスタ非採用削除!D$4,統合マスタ!$A19,0)="","",OFFSET(マスタ非採用削除!D$4,統合マスタ!$A19,0)) | R19: =IF(AA19="非採用",0,IF(OFFSET(マスタ非採用削除!E$4,統合マスタ!$A19,0)="","",OFFSET(マスタ非採用削除!E$4,統合マスタ!$A19,0))) -> 2 | S19: =IF(OFFSET(マスタ非採用削除!F$4,統合マスタ!$A19,0)="","",OFFSET(マスタ非採用削除!F$4,統合マスタ!$A19,0)) | T19: =IF(OFFSET(マスタ非採用削除!G$4,統合マスタ!$A19,0)="","",OFFSET(マスタ非採用削除!G$4,統合マスタ!$A19,0)) -> 22.9 | U19: =IF(OFFSET(マスタ非採用削除!H$4,統合マスタ!$A19,0)="","",OFFSET(マスタ非採用削除!H$4,統合マスタ!$A19,0)) -> ﾂﾑﾗﾁﾖﾚｲﾄｳｺﾞｳｼﾓﾂﾄｳｴｷｽｶﾘﾕｳｲﾘﾖｳﾖｳ | V19: =IF(OFFSET(マスタ非採用削除!I$4,統合マスタ!$A19,0)="","",OFFSET(マスタ非採用削除!I$4,統合マスタ!$A19,0)) -> 5 | W19: =IF(OFFSET(マスタ非採用削除!J$4,統合マスタ!$A19,0)="","",OFFSET(マスタ非採用削除!J$4,統合マスタ!$A19,0)) -> 顆粒 | X19: =IF(OFFSET(マスタ非採用削除!K$4,統合マスタ!$A19,0)="","",OFFSET(マスタ非採用削除!K$4,統合マスタ!$A19,0)) -> 0 | Y19: =IF(OFFSET(マスタ非採用削除!L$4,統合マスタ!$A19,0)="","",OFFSET(マスタ非採用削除!L$4,統合マスタ!$A19,0)) | Z19: =IF(OFFSET(マスタ非採用削除!M$4,統合マスタ!$A19,0)="","",OFFSET(マスタ非採用削除!M$4,統合マスタ!$A19,0)) -> 4 | AB19: =IF(R19=2,"臨時", IF(COUNTIF(分類!$H$8:$H$15, 統合マスタ!V19)>0, 分類!$G$7, IF(COUNTIF(分類!$K$8:$K$15, 統合マスタ!V19)>0, 分類!$J$7, IF(COUNTIF(分類!$N$8:$N$15, 統合マスタ!V19)>0, 分類!$M$7, IF(COUNTIF(分類!$Q$8:$Q$15, 統合マスタ!V19)>0, 分類!$P$7, "無し"))))) -> 臨時 | AC19: =X19 * 100000 + B19 -> 15 | AD19: {=IF(A19="非採用","非採用",OFFSET( INDIRECT("'" & AB19 & "'!A4"), MATCH(B19, INDIRECT("'" & AB19 & "'!C5:C1000"), 0), MATCH("合計", INDIRECT("'" & AB19 & "'!4:4"), 0) - 1 ))} -> 0
A20: =元データ!P17 -> 43 | B20: =B19+1 -> 16 | C20: =DBCS(元データ!A17) -> ２５ｍｇアリナミン Ｆ糖衣錠 | D20: =元データ!B17 -> メディセオ | E20: =DBCS(元データ!C17) -> ＰＴＰ | F20: =DBCS(元データ!D17) -> １００Ｔ | G20: =元データ!E17 -> 武田薬品工業 | H20: =元データ!F17 -> 6.1 | I20: =元データ!G17 -> 610 | J20: =元データ!H17 -> 100 | K20: =元データ!I17 -> 錠 | L20: =元データ!J17 -> 544 | M20: =元データ!K17 -> 5.44 | N20: =IF(OFFSET(マスタ非採用削除!A$4,統合マスタ!$A20,0)="","",OFFSET(マスタ非採用削除!A$4,統合マスタ!$A20,0)) -> ｱﾘﾅ001 | O20: =IF(OFFSET(マスタ非採用削除!B$4,統合マスタ!$A20,0)="","",OFFSET(マスタ非採用削除!B$4,統合マスタ!$A20,0)) -> ｱﾘﾅ001 | P20: =IF(OFFSET(マスタ非採用削除!C$4,統合マスタ!$A20,0)="","",OFFSET(マスタ非採用削除!C$4,統合マスタ!$A20,0)) -> ２５ｍｇアリナミンＦ糖衣錠 | Q20: =IF(OFFSET(マスタ非採用削除!D$4,統合マスタ!$A20,0)="","",OFFSET(マスタ非採用削除!D$4,統合マスタ!$A20,0)) -> ｱﾘF** | R20: =IF(AA20="非採用",0,IF(OFFSET(マスタ非採用削除!E$4,統合マスタ!$A20,0)="","",OFFSET(マスタ非採用削除!E$4,統合マスタ!$A20,0))) -> 1 | S20: =IF(OFFSET(マスタ非採用削除!F$4,統合マスタ!$A20,0)="","",OFFSET(マスタ非採用削除!F$4,統合マスタ!$A20,0)) | T20: =IF(OFFSET(マスタ非採用削除!G$4,統合マスタ!$A20,0)="","",OFFSET(マスタ非採用削除!G$4,統合マスタ!$A20,0)) -> 6.1 | U20: =IF(OFFSET(マスタ非採用削除!H$4,統合マスタ!$A20,0)="","",OFFSET(マスタ非採用削除!H$4,統合マスタ!$A20,0)) -> 25mgｱﾘﾅﾐﾝFﾄｳｲｼﾞｮｳ | V20: =IF(OFFSET(マスタ非採用削除!I$4,統合マスタ!$A20,0)="","",OFFSET(マスタ非採用削除!I$4,統合マスタ!$A20,0)) -> 1 | W20: =IF(OFFSET(マスタ非採用削除!J$4,統合マスタ!$A20,0)="","",OFFSET(マスタ非採用削除!J$4,統合マスタ!$A20,0)) -> 錠剤 | X20: =IF(OFFSET(マスタ非採用削除!K$4,統合マスタ!$A20,0)="","",OFFSET(マスタ非採用削除!K$4,統合マスタ!$A20,0)) -> 0 | Y20: =IF(OFFSET(マスタ非採用削除!L$4,統合マスタ!$A20,0)="","",OFFSET(マスタ非採用削除!L$4,統合マスタ!$A20,0)) | Z20: =IF(OFFSET(マスタ非採用削除!M$4,統合マスタ!$A20,0)="","",OFFSET(マスタ非採用削除!M$4,統合マスタ!$A20,0)) -> 25 | AB20: =IF(R20=2,"臨時", IF(COUNTIF(分類!$H$8:$H$15, 統合マスタ!V20)>0, 分類!$G$7, IF(COUNTIF(分類!$K$8:$K$15, 統合マスタ!V20)>0, 分類!$J$7, IF(COUNTIF(分類!$N$8:$N$15, 統合マスタ!V20)>0, 分類!$M$7, IF(COUNTIF(分類!$Q$8:$Q$15, 統合マスタ!V20)>0, 分類!$P$7, "無し"))))) -> 錠剤 | AC20: =X20 * 100000 + B20 -> 16 | AD20: {=IF(A20="非採用","非採用",OFFSET( INDIRECT("'" & AB20 & "'!A4"), MATCH(B20, INDIRECT("'" & AB20 & "'!C5:C1000"), 0), MATCH("合計", INDIRECT("'" & AB20 & "'!4:4"), 0) - 1 ))} -> 1
A21: =元データ!P18 -> 139 | B21: =B20+1 -> 17 | C21: =DBCS(元データ!A18) -> ＥＫ１ 葛根湯エキス細粒 | D21: =元データ!B18 -> メディセオ | E21: =DBCS(元データ!C18) -> 粉 | F21: =DBCS(元データ!D18) -> ２．５ｇ×２９４ | G21: =元データ!E18 -> クラシエ | H21: =元データ!F18 -> 10.2 | I21: =元データ!G18 -> 7497 | J21: =元データ!H18 -> 735 | K21: =元データ!I18 -> g | L21: =元データ!J18 -> 6679 | M21: =元データ!K18 -> 9.0870748 | N21: =IF(OFFSET(マスタ非採用削除!A$4,統合マスタ!$A21,0)="","",OFFSET(マスタ非採用削除!A$4,統合マスタ!$A21,0)) -> ｸﾗｼ001 | O21: =IF(OFFSET(マスタ非採用削除!B$4,統合マスタ!$A21,0)="","",OFFSET(マスタ非採用削除!B$4,統合マスタ!$A21,0)) -> ｸﾗｼ001 | P21: =IF(OFFSET(マスタ非採用削除!C$4,統合マスタ!$A21,0)="","",OFFSET(マスタ非採用削除!C$4,統合マスタ!$A21,0)) -> クラシエ葛根湯エキス細粒 | Q21: =IF(OFFSET(マスタ非採用削除!D$4,統合マスタ!$A21,0)="","",OFFSET(マスタ非採用削除!D$4,統合マスタ!$A21,0)) -> ｶｯｺﾝ | R21: =IF(AA21="非採用",0,IF(OFFSET(マスタ非採用削除!E$4,統合マスタ!$A21,0)="","",OFFSET(マスタ非採用削除!E$4,統合マスタ!$A21,0))) -> 1 | S21: =IF(OFFSET(マスタ非採用削除!F$4,統合マスタ!$A21,0)="","",OFFSET(マスタ非採用削除!F$4,統合マスタ!$A21,0)) | T21: =IF(OFFSET(マスタ非採用削除!G$4,統合マスタ!$A21,0)="","",OFFSET(マスタ非採用削除!G$4,統合マスタ!$A21,0)) -> 10.2 | U21: =IF(OFFSET(マスタ非採用削除!H$4,統合マスタ!$A21,0)="","",OFFSET(マスタ非採用削除!H$4,統合マスタ!$A21,0)) -> ｸﾗｼｴｶｯｺﾝﾄｳｴｷｽｻｲﾘｭｳ | V21: =IF(OFFSET(マスタ非採用削除!I$4,統合マスタ!$A21,0)="","",OFFSET(マスタ非採用削除!I$4,統合マスタ!$A21,0)) -> 3 | W21: =IF(OFFSET(マスタ非採用削除!J$4,統合マスタ!$A21,0)="","",OFFSET(マスタ非採用削除!J$4,統合マスタ!$A21,0)) -> 散 | X21: =IF(OFFSET(マスタ非採用削除!K$4,統合マスタ!$A21,0)="","",OFFSET(マスタ非採用削除!K$4,統合マスタ!$A21,0)) -> 0 | Y21: =IF(OFFSET(マスタ非採用削除!L$4,統合マスタ!$A21,0)="","",OFFSET(マスタ非採用削除!L$4,統合マスタ!$A21,0)) | Z21: =IF(OFFSET(マスタ非採用削除!M$4,統合マスタ!$A21,0)="","",OFFSET(マスタ非採用削除!M$4,統合マスタ!$A21,0)) -> 4 | AB21: =IF(R21=2,"臨時", IF(COUNTIF(分類!$H$8:$H$15, 統合マスタ!V21)>0, 分類!$G$7, IF(COUNTIF(分類!$K$8:$K$15, 統合マスタ!V21)>0, 分類!$J$7, IF(COUNTIF(分類!$N$8:$N$15, 統合マスタ!V21)>0, 分類!$M$7, IF(COUNTIF(分類!$Q$8:$Q$15, 統合マスタ!V21)>0, 分類!$P$7, "無し"))))) -> 散剤 | AC21: =X21 * 100000 + B21 -> 17 | AD21: {=IF(A21="非採用","非採用",OFFSET( INDIRECT("'" & AB21 & "'!A4"), MATCH(B21, INDIRECT("'" & AB21 & "'!C5:C1000"), 0), MATCH("合計", INDIRECT("'" & AB21 & "'!4:4"), 0) - 1 ))} -> 0
A22: =元データ!P19 -> 144 | B22: =B21+1 -> 18 | C22: =DBCS(元データ!A19) -> ＥＫ１１４ 柴苓湯 | D22: =元データ!B19 -> メディセオ | E22: =DBCS(元データ!C19) -> 粉 | F22: =DBCS(元データ!D19) -> ２．７ｇ×２９４ | G22: =元データ!E19 -> クラシエ | H22: =元データ!F19 -> 46.8 | I22: =元データ!G19 -> 37149.84 | J22: =元データ!H19 -> 793.8 | K22: =元データ!I19 -> g | L22: =元データ!J19 -> 33097 | M22: =元データ!K19 -> 41.694381 | N22: =IF(OFFSET(マスタ非採用削除!A$4,統合マスタ!$A22,0)="","",OFFSET(マスタ非採用削除!A$4,統合マスタ!$A22,0)) -> ｸﾗｼ114 | O22: =IF(OFFSET(マスタ非採用削除!B$4,統合マスタ!$A22,0)="","",OFFSET(マスタ非採用削除!B$4,統合マスタ!$A22,0)) -> ｸﾗｼ114 | P22: =IF(OFFSET(マスタ非採用削除!C$4,統合マスタ!$A22,0)="","",OFFSET(マスタ非採用削除!C$4,統合マスタ!$A22,0)) -> クラシエ柴苓湯エキス細粒 | Q22: =IF(OFFSET(マスタ非採用削除!D$4,統合マスタ!$A22,0)="","",OFFSET(マスタ非採用削除!D$4,統合マスタ!$A22,0)) -> ｻｲﾚ | R22: =IF(AA22="非採用",0,IF(OFFSET(マスタ非採用削除!E$4,統合マスタ!$A22,0)="","",OFFSET(マスタ非採用削除!E$4,統合マスタ!$A22,0))) -> 2 | S22: =IF(OFFSET(マスタ非採用削除!F$4,統合マスタ!$A22,0)="","",OFFSET(マスタ非採用削除!F$4,統合マスタ!$A22,0)) | T22: =IF(OFFSET(マスタ非採用削除!G$4,統合マスタ!$A22,0)="","",OFFSET(マスタ非採用削除!G$4,統合マスタ!$A22,0)) -> 46.8 | U22: =IF(OFFSET(マスタ非採用削除!H$4,統合マスタ!$A22,0)="","",OFFSET(マスタ非採用削除!H$4,統合マスタ!$A22,0)) -> ｸﾗｼｴｻｲﾚｲﾄｳｴｷｽｻｲﾘｭｳ | V22: =IF(OFFSET(マスタ非採用削除!I$4,統合マスタ!$A22,0)="","",OFFSET(マスタ非採用削除!I$4,統合マスタ!$A22,0)) -> 3 | W22: =IF(OFFSET(マスタ非採用削除!J$4,統合マスタ!$A22,0)="","",OFFSET(マスタ非採用削除!J$4,統合マスタ!$A22,0)) -> 散 | X22: =IF(OFFSET(マスタ非採用削除!K$4,統合マスタ!$A22,0)="","",OFFSET(マスタ非採用削除!K$4,統合マスタ!$A22,0)) -> 0 | Y22: =IF(OFFSET(マスタ非採用削除!L$4,統合マスタ!$A22,0)="","",OFFSET(マスタ非採用削除!L$4,統合マスタ!$A22,0)) | Z22: =IF(OFFSET(マスタ非採用削除!M$4,統合マスタ!$A22,0)="","",OFFSET(マスタ非採用削除!M$4,統合マスタ!$A22,0)) -> 4 | AB22: =IF(R22=2,"臨時", IF(COUNTIF(分類!$H$8:$H$15, 統合マスタ!V22)>0, 分類!$G$7, IF(COUNTIF(分類!$K$8:$K$15, 統合マスタ!V22)>0, 分類!$J$7, IF(COUNTIF(分類!$N$8:$N$15, 統合マスタ!V22)>0, 分類!$M$7, IF(COUNTIF(分類!$Q$8:$Q$15, 統合マスタ!V22)>0, 分類!$P$7, "無し"))))) -> 臨時 | AC22: =X22 * 100000 + B22 -> 18 | AD22: {=IF(A22="非採用","非採用",OFFSET( INDIRECT("'" & AB22 & "'!A4"), MATCH(B22, INDIRECT("'" & AB22 & "'!C5:C1000"), 0), MATCH("合計", INDIRECT("'" & AB22 & "'!4:4"), 0) - 1 ))} -> 0
A23: =元データ!P20 -> 140 | B23: =B22+1 -> 19 | C23: =DBCS(元データ!A20) -> ＥＫ１５ 黄連解毒湯エキス細粒 | D23: =元データ!B20 -> メディセオ | E23: =DBCS(元データ!C20) -> 粉 | F23: =DBCS(元データ!D20) -> ２ｇｘ４２包 | G23: =元データ!E20 -> クラシエ | H23: =元データ!F20 -> 13.3 | I23: =元データ!G20 -> 1117.2 | J23: =元データ!H20 -> 84 | K23: =元データ!I20 -> g | L23: =元データ!J20 -> 1015 | M23: =元データ!K20 -> 12.083333 | N23: =IF(OFFSET(マスタ非採用削除!A$4,統合マスタ!$A23,0)="","",OFFSET(マスタ非採用削除!A$4,統合マスタ!$A23,0)) -> ｸﾗｼ015 | O23: =IF(OFFSET(マスタ非採用削除!B$4,統合マスタ!$A23,0)="","",OFFSET(マスタ非採用削除!B$4,統合マスタ!$A23,0)) -> ｸﾗｼ015 | P23: =IF(OFFSET(マスタ非採用削除!C$4,統合マスタ!$A23,0)="","",OFFSET(マスタ非採用削除!C$4,統合マスタ!$A23,0)) -> クラシエ黄連解毒湯エキス細粒 | Q23: =IF(OFFSET(マスタ非採用削除!D$4,統合マスタ!$A23,0)="","",OFFSET(マスタ非採用削除!D$4,統合マスタ!$A23,0)) -> ｵｳ | R23: =IF(AA23="非採用",0,IF(OFFSET(マスタ非採用削除!E$4,統合マスタ!$A23,0)="","",OFFSET(マスタ非採用削除!E$4,統合マスタ!$A23,0))) -> 2 | S23: =IF(OFFSET(マスタ非採用削除!F$4,統合マスタ!$A23,0)="","",OFFSET(マスタ非採用削除!F$4,統合マスタ!$A23,0)) | T23: =IF(OFFSET(マスタ非採用削除!G$4,統合マスタ!$A23,0)="","",OFFSET(マスタ非採用削除!G$4,統合マスタ!$A23,0)) -> 13.3 | U23: =IF(OFFSET(マスタ非採用削除!H$4,統合マスタ!$A23,0)="","",OFFSET(マスタ非採用削除!H$4,統合マスタ!$A23,0)) -> ｸﾗｼｴｵｳﾚﾝｹﾞﾄﾞｸﾄｳｴｷｽｻｲﾘｭｳ | V23: =IF(OFFSET(マスタ非採用削除!I$4,統合マスタ!$A23,0)="","",OFFSET(マスタ非採用削除!I$4,統合マスタ!$A23,0)) -> 3 | W23: =IF(OFFSET(マスタ非採用削除!J$4,統合マスタ!$A23,0)="","",OFFSET(マスタ非採用削除!J$4,統合マスタ!$A23,0)) -> 散 | X23: =IF(OFFSET(マスタ非採用削除!K$4,統合マスタ!$A23,0)="","",OFFSET(マスタ非採用削除!K$4,統合マスタ!$A23,0)) -> 0 | Y23: =IF(OFFSET(マスタ非採用削除!L$4,統合マスタ!$A23,0)="","",OFFSET(マスタ非採用削除!L$4,統合マスタ!$A23,0)) | Z23: =IF(OFFSET(マスタ非採用削除!M$4,統合マスタ!$A23,0)="","",OFFSET(マスタ非採用削除!M$4,統合マスタ!$A23,0)) -> 4 | AB23: =IF(R23=2,"臨時", IF(COUNTIF(分類!$H$8:$H$15, 統合マスタ!V23)>0, 分類!$G$7, IF(COUNTIF(分類!$K$8:$K$15, 統合マスタ!V23)>0, 分類!$J$7, IF(COUNTIF(分類!$N$8:$N$15, 統合マスタ!V23)>0, 分類!$M$7, IF(COUNTIF(分類!$Q$8:$Q$15, 統合マスタ!V23)>0, 分類!$P$7, "無し"))))) -> 臨時 | AC23: =X23 * 100000 + B23 -> 19 | AD23: {=IF(A23="非採用","非採用",OFFSET( INDIRECT("'" & AB23 & "'!A4"), MATCH(B23, INDIRECT("'" & AB23 & "'!C5:C1000"), 0), MATCH("合計", INDIRECT("'" & AB23 & "'!4:4"), 0) - 1 ))} -> 0
A24: =元データ!P21 -> 非採用 | B24: =B23+1 -> 20 | C24: =DBCS(元データ!A21) -> ＥＫ１９ 小青竜湯エキス細粒 | D24: =元データ!B21 -> アルフレッサ | E24: =DBCS(元データ!C21) | F24: =DBCS(元データ!D21) -> ２ｇｘ４２包 | G24: =元データ!E21 -> クラシエ | H24: =元データ!F21 -> 24.1 | I24: =元データ!G21 -> 2024.4 | J24: =元データ!H21 -> 84 | K24: =元データ!I21 -> g | L24: =元データ!J21 -> 1840 | M24: =元データ!K21 -> 21.904762 | N24: =IF(OFFSET(マスタ非採用削除!A$4,統合マスタ!$A24,0)="","",OFFSET(マスタ非採用削除!A$4,統合マスタ!$A24,0)) -> #VALUE! | O24: =IF(OFFSET(マスタ非採用削除!B$4,統合マスタ!$A24,0)="","",OFFSET(マスタ非採用削除!B$4,統合マスタ!$A24,0)) -> #VALUE! | P24: =IF(OFFSET(マスタ非採用削除!C$4,統合マスタ!$A24,0)="","",OFFSET(マスタ非採用削除!C$4,統合マスタ!$A24,0)) -> #VALUE! | Q24: =IF(OFFSET(マスタ非採用削除!D$4,統合マスタ!$A24,0)="","",OFFSET(マスタ非採用削除!D$4,統合マスタ!$A24,0)) -> #VALUE! | R24: =IF(AA24="非採用",0,IF(OFFSET(マスタ非採用削除!E$4,統合マスタ!$A24,0)="","",OFFSET(マスタ非採用削除!E$4,統合マスタ!$A24,0))) -> 0 | S24: =IF(OFFSET(マスタ非採用削除!F$4,統合マスタ!$A24,0)="","",OFFSET(マスタ非採用削除!F$4,統合マスタ!$A24,0)) -> #VALUE! | T24: =IF(OFFSET(マスタ非採用削除!G$4,統合マスタ!$A24,0)="","",OFFSET(マスタ非採用削除!G$4,統合マスタ!$A24,0)) -> #VALUE! | U24: =IF(OFFSET(マスタ非採用削除!H$4,統合マスタ!$A24,0)="","",OFFSET(マスタ非採用削除!H$4,統合マスタ!$A24,0)) -> #VALUE! | V24: =IF(OFFSET(マスタ非採用削除!I$4,統合マスタ!$A24,0)="","",OFFSET(マスタ非採用削除!I$4,統合マスタ!$A24,0)) -> #VALUE! | W24: =IF(OFFSET(マスタ非採用削除!J$4,統合マスタ!$A24,0)="","",OFFSET(マスタ非採用削除!J$4,統合マスタ!$A24,0)) -> #VALUE! | X24: =IF(OFFSET(マスタ非採用削除!K$4,統合マスタ!$A24,0)="","",OFFSET(マスタ非採用削除!K$4,統合マスタ!$A24,0)) -> #VALUE! | Y24: =IF(OFFSET(マスタ非採用削除!L$4,統合マスタ!$A24,0)="","",OFFSET(マスタ非採用削除!L$4,統合マスタ!$A24,0)) -> #VALUE! | Z24: =IF(OFFSET(マスタ非採用削除!M$4,統合マスタ!$A24,0)="","",OFFSET(マスタ非採用削除!M$4,統合マスタ!$A24,0)) -> #VALUE! | AA24: 非採用 | AB24: =IF(R24=2,"臨時", IF(COUNTIF(分類!$H$8:$H$15, 統合マスタ!V24)>0, 分類!$G$7, IF(COUNTIF(分類!$K$8:$K$15, 統合マスタ!V24)>0, 分類!$J$7, IF(COUNTIF(分類!$N$8:$N$15, 統合マスタ!V24)>0, 分類!$M$7, IF(COUNTIF(分類!$Q$8:$Q$15, 統合マスタ!V24)>0, 分類!$P$7, "無し"))))) -> 無し | AC24: =X24 * 100000 + B24 -> #VALUE! | AD24: {=IF(A24="非採用","非採用",OFFSET( INDIRECT("'" & AB24 & "'!A4"), MATCH(B24, INDIRECT("'" & AB24 & "'!C5:C1000"), 0), MATCH("合計", INDIRECT("'" & AB24 & "'!4:4"), 0) - 1 ))} -> 非採用
A25: =元データ!P22 -> 141 | B25: =B24+1 -> 21 | C25: =DBCS(元データ!A22) -> ＥＫ２４ 加味逍遥散料エキス細粒 | D25: =元データ!B22 -> メディセオ | E25: =DBCS(元データ!C22) -> 粉 | F25: =DBCS(元データ!D22) -> ２ｇｘ４２包 | G25: =元データ!E22 -> クラシエ | H25: =元データ!F22 -> 18.3 | I25: =元データ!G22 -> 1537.2 | J25: =元データ!H22 -> 84 | K25: =元データ!I22 -> g | L25: =元データ!J22 -> 1397 | M25: =元データ!K22 -> 16.630952 | N25: =IF(OFFSET(マスタ非採用削除!A$4,統合マスタ!$A25,0)="","",OFFSET(マスタ非採用削除!A$4,統合マスタ!$A25,0)) -> ｸﾗｼ024 | O25: =IF(OFFSET(マスタ非採用削除!B$4,統合マスタ!$A25,0)="","",OFFSET(マスタ非採用削除!B$4,統合マスタ!$A25,0)) -> ｸﾗｼ024 | P25: =IF(OFFSET(マスタ非採用削除!C$4,統合マスタ!$A25,0)="","",OFFSET(マスタ非採用削除!C$4,統合マスタ!$A25,0)) -> クラシエ加味逍遙散料エキス細粒 | Q25: =IF(OFFSET(マスタ非採用削除!D$4,統合マスタ!$A25,0)="","",OFFSET(マスタ非採用削除!D$4,統合マスタ!$A25,0)) -> ｶﾐｼｮ1 | R25: =IF(AA25="非採用",0,IF(OFFSET(マスタ非採用削除!E$4,統合マスタ!$A25,0)="","",OFFSET(マスタ非採用削除!E$4,統合マスタ!$A25,0))) -> 1 | S25: =IF(OFFSET(マスタ非採用削除!F$4,統合マスタ!$A25,0)="","",OFFSET(マスタ非採用削除!F$4,統合マスタ!$A25,0)) | T25: =IF(OFFSET(マスタ非採用削除!G$4,統合マスタ!$A25,0)="","",OFFSET(マスタ非採用削除!G$4,統合マスタ!$A25,0)) -> 18.3 | U25: =IF(OFFSET(マスタ非採用削除!H$4,統合マスタ!$A25,0)="","",OFFSET(マスタ非採用削除!H$4,統合マスタ!$A25,0)) -> ｸﾗｼｴｶﾐｼｮｳﾖｳｻﾝﾘｮｳｴｷｽｻｲﾘｭｳ | V25: =IF(OFFSET(マスタ非採用削除!I$4,統合マスタ!$A25,0)="","",OFFSET(マスタ非採用削除!I$4,統合マスタ!$A25,0)) -> 3 | W25: =IF(OFFSET(マスタ非採用削除!J$4,統合マスタ!$A25,0)="","",OFFSET(マスタ非採用削除!J$4,統合マスタ!$A25,0)) -> 散 | X25: =IF(OFFSET(マスタ非採用削除!K$4,統合マスタ!$A25,0)="","",OFFSET(マスタ非採用削除!K$4,統合マスタ!$A25,0)) -> 0 | Y25: =IF(OFFSET(マスタ非採用削除!L$4,統合マスタ!$A25,0)="","",OFFSET(マスタ非採用削除!L$4,統合マスタ!$A25,0)) | Z25: =IF(OFFSET(マスタ非採用削除!M$4,統合マスタ!$A25,0)="","",OFFSET(マスタ非採用削除!M$4,統合マスタ!$A25,0)) -> 4 | AB25: =IF(R25=2,"臨時", IF(COUNTIF(分類!$H$8:$H$15, 統合マスタ!V25)>0, 分類!$G$7, IF(COUNTIF(分類!$K$8:$K$15, 統合マスタ!V25)>0, 分類!$J$7, IF(COUNTIF(分類!$N$8:$N$15, 統合マスタ!V25)>0, 分類!$M$7, IF(COUNTIF(分類!$Q$8:$Q$15, 統合マスタ!V25)>0, 分類!$P$7, "無し"))))) -> 散剤 | AC25: =X25 * 100000 + B25 -> 21 | AD25: {=IF(A25="非採用","非採用",OFFSET( INDIRECT("'" & AB25 & "'!A4"), MATCH(B25, INDIRECT("'" & AB25 & "'!C5:C1000"), 0), MATCH("合計", INDIRECT("'" & AB25 & "'!4:4"), 0) - 1 ))} -> 0
A26: =元データ!P23 -> 142 | B26: =B25+1 -> 22 | C26: =DBCS(元データ!A23) -> ＥＫ４０ 猪苓湯エキス細粒 | D26: =元データ!B23 -> メディセオ | E26: =DBCS(元データ!C23) -> 粉 | F26: =DBCS(元データ!D23) -> ２ｇｘ４２包 | G26: =元データ!E23 -> クラシエ | H26: =元データ!F23 -> 14.8 | I26: =元データ!G23 -> 1243.2 | J26: =元データ!H23 -> 84 | K26: =元データ!I23 -> g | L26: =元データ!J23 -> 1130 | M26: =元データ!K23 -> 13.452381 | N26: =IF(OFFSET(マスタ非採用削除!A$4,統合マスタ!$A26,0)="","",OFFSET(マスタ非採用削除!A$4,統合マスタ!$A26,0)) -> ｸﾗｼ040 | O26: =IF(OFFSET(マスタ非採用削除!B$4,統合マスタ!$A26,0)="","",OFFSET(マスタ非採用削除!B$4,統合マスタ!$A26,0)) -> ｸﾗｼ040 | P26: =IF(OFFSET(マスタ非採用削除!C$4,統合マスタ!$A26,0)="","",OFFSET(マスタ非採用削除!C$4,統合マスタ!$A26,0)) -> クラシエ猪苓湯エキス細粒 | Q26: =IF(OFFSET(マスタ非採用削除!D$4,統合マスタ!$A26,0)="","",OFFSET(マスタ非採用削除!D$4,統合マスタ!$A26,0)) -> ﾁｮﾚ | R26: =IF(AA26="非採用",0,IF(OFFSET(マスタ非採用削除!E$4,統合マスタ!$A26,0)="","",OFFSET(マスタ非採用削除!E$4,統合マスタ!$A26,0))) -> 2 | S26: =IF(OFFSET(マスタ非採用削除!F$4,統合マスタ!$A26,0)="","",OFFSET(マスタ非採用削除!F$4,統合マスタ!$A26,0)) | T26: =IF(OFFSET(マスタ非採用削除!G$4,統合マスタ!$A26,0)="","",OFFSET(マスタ非採用削除!G$4,統合マスタ!$A26,0)) -> 14.8 | U26: =IF(OFFSET(マスタ非採用削除!H$4,統合マスタ!$A26,0)="","",OFFSET(マスタ非採用削除!H$4,統合マスタ!$A26,0)) -> ｸﾗｼｴﾁｮﾚｲﾄｳｴｷｽｻｲﾘｭｳ | V26: =IF(OFFSET(マスタ非採用削除!I$4,統合マスタ!$A26,0)="","",OFFSET(マスタ非採用削除!I$4,統合マスタ!$A26,0)) -> 3 | W26: =IF(OFFSET(マスタ非採用削除!J$4,統合マスタ!$A26,0)="","",OFFSET(マスタ非採用削除!J$4,統合マスタ!$A26,0)) -> 散 | X26: =IF(OFFSET(マスタ非採用削除!K$4,統合マスタ!$A26,0)="","",OFFSET(マスタ非採用削除!K$4,統合マスタ!$A26,0)) -> 0 | Y26: =IF(OFFSET(マスタ非採用削除!L$4,統合マスタ!$A26,0)="","",OFFSET(マスタ非採用削除!L$4,統合マスタ!$A26,0)) | Z26: =IF(OFFSET(マスタ非採用削除!M$4,統合マスタ!$A26,0)="","",OFFSET(マスタ非採用削除!M$4,統合マスタ!$A26,0)) -> 4 | AB26: =IF(R26=2,"臨時", IF(COUNTIF(分類!$H$8:$H$15, 統合マスタ!V26)>0, 分類!$G$7, IF(COUNTIF(分類!$K$8:$K$15, 統合マスタ!V26)>0, 分類!$J$7, IF(COUNTIF(分類!$N$8:$N$15, 統合マスタ!V26)>0, 分類!$M$7, IF(COUNTIF(分類!$Q$8:$Q$15, 統合マスタ!V26)>0, 分類!$P$7, "無し"))))) -> 臨時 | AC26: =X26 * 100000 + B26 -> 22 | AD26: {=IF(A26="非採用","非採用",OFFSET( INDIRECT("'" & AB26 & "'!A4"), MATCH(B26, INDIRECT("'" & AB26 & "'!C5:C1000"), 0), MATCH("合計", INDIRECT("'" & AB26 & "'!4:4"), 0) - 1 ))} -> 0
A27: =元データ!P24 -> 143 | B27: =B26+1 -> 23 | C27: =DBCS(元データ!A24) -> ＥＫ４１ 補中益気湯エキス細粒 | D27: =元データ!B24 -> メディセオ | E27: =DBCS(元データ!C24) -> 粉 | F27: =DBCS(元データ!D24) -> ２．５ｇｘ２９４ | G27: =元データ!E24 -> クラシエ | H27: =元データ!F24 -> 20.4 | I27: =元データ!G24 -> 14994 | J27: =元データ!H24 -> 735 | K27: =元データ!I24 -> g | L27: =元データ!J24 -> 13358 | M27: =元データ!K24 -> 18.17415 | N27: =IF(OFFSET(マスタ非採用削除!A$4,統合マスタ!$A27,0)="","",OFFSET(マスタ非採用削除!A$4,統合マスタ!$A27,0)) -> ｸﾗｼ041 | O27: =IF(OFFSET(マスタ非採用削除!B$4,統合マスタ!$A27,0)="","",OFFSET(マスタ非採用削除!B$4,統合マスタ!$A27,0)) -> ｸﾗｼ041 | P27: =IF(OFFSET(マスタ非採用削除!C$4,統合マスタ!$A27,0)="","",OFFSET(マスタ非採用削除!C$4,統合マスタ!$A27,0)) -> クラシエ補中益気湯エキス細粒 | Q27: =IF(OFFSET(マスタ非採用削除!D$4,統合マスタ!$A27,0)="","",OFFSET(マスタ非採用削除!D$4,統合マスタ!$A27,0)) -> ﾎﾁｭｳ | R27: =IF(AA27="非採用",0,IF(OFFSET(マスタ非採用削除!E$4,統合マスタ!$A27,0)="","",OFFSET(マスタ非採用削除!E$4,統合マスタ!$A27,0))) -> 1 | S27: =IF(OFFSET(マスタ非採用削除!F$4,統合マスタ!$A27,0)="","",OFFSET(マスタ非採用削除!F$4,統合マスタ!$A27,0)) | T27: =IF(OFFSET(マスタ非採用削除!G$4,統合マスタ!$A27,0)="","",OFFSET(マスタ非採用削除!G$4,統合マスタ!$A27,0)) -> 20.4 | U27: =IF(OFFSET(マスタ非採用削除!H$4,統合マスタ!$A27,0)="","",OFFSET(マスタ非採用削除!H$4,統合マスタ!$A27,0)) -> ｸﾗｼｴﾎﾁｭｳｴｯｷﾄｳｴｷｽｻｲﾘｭｳ | V27: =IF(OFFSET(マスタ非採用削除!I$4,統合マスタ!$A27,0)="","",OFFSET(マスタ非採用削除!I$4,統合マスタ!$A27,0)) -> 3 | W27: =IF(OFFSET(マスタ非採用削除!J$4,統合マスタ!$A27,0)="","",OFFSET(マスタ非採用削除!J$4,統合マスタ!$A27,0)) -> 散 | X27: =IF(OFFSET(マスタ非採用削除!K$4,統合マスタ!$A27,0)="","",OFFSET(マスタ非採用削除!K$4,統合マスタ!$A27,0)) -> 0 | Y27: =IF(OFFSET(マスタ非採用削除!L$4,統合マスタ!$A27,0)="","",OFFSET(マスタ非採用削除!L$4,統合マスタ!$A27,0)) | Z27: =IF(OFFSET(マスタ非採用削除!M$4,統合マスタ!$A27,0)="","",OFFSET(マスタ非採用削除!M$4,統合マスタ!$A27,0)) -> 4 | AB27: =IF(R27=2,"臨時", IF(COUNTIF(分類!$H$8:$H$15, 統合マスタ!V27)>0, 分類!$G$7, IF(COUNTIF(分類!$K$8:$K$15, 統合マスタ!V27)>0, 分類!$J$7, IF(COUNTIF(分類!$N$8:$N$15, 統合マスタ!V27)>0, 分類!$M$7, IF(COUNTIF(分類!$Q$8:$Q$15, 統合マスタ!V27)>0, 分類!$P$7, "無し"))))) -> 散剤 | AC27: =X27 * 100000 + B27 -> 23 | AD27: {=IF(A27="非採用","非採用",OFFSET( INDIRECT("'" & AB27 & "'!A4"), MATCH(B27, INDIRECT("'" & AB27 & "'!C5:C1000"), 0), MATCH("合計", INDIRECT("'" & AB27 & "'!4:4"), 0) - 1 ))} -> 0
A28: =元データ!P25 -> 59 | B28: =B27+1 -> 24 | C28: =DBCS(元データ!A25) -> ＥＰＬカプセル２５０ｍｇ 販売中止 | D28: =元データ!B25 -> アルフレッサ | E28: =DBCS(元データ!C25) -> ＰＴＰ | F28: =DBCS(元データ!D25) -> ４００Ｐ | G28: =元データ!E25 -> アルフレッサファーマ | H28: =元データ!F25 -> 6.1 | I28: =元データ!G25 -> 2440 | J28: =元データ!H25 -> 400 | K28: =元データ!I25 -> cap | L28: =元データ!J25 -> 2218 | M28: =元データ!K25 -> 5.545 | N28: =IF(OFFSET(マスタ非採用削除!A$4,統合マスタ!$A28,0)="","",OFFSET(マスタ非採用削除!A$4,統合マスタ!$A28,0)) -> ｲﾋｴ001 | O28: =IF(OFFSET(マスタ非採用削除!B$4,統合マスタ!$A28,0)="","",OFFSET(マスタ非採用削除!B$4,統合マスタ!$A28,0)) -> ｲﾋｴ001 | P28: =IF(OFFSET(マスタ非採用削除!C$4,統合マスタ!$A28,0)="","",OFFSET(マスタ非採用削除!C$4,統合マスタ!$A28,0)) -> ＥＰＬカプセル２５０ｍｇ | Q28: =IF(OFFSET(マスタ非採用削除!D$4,統合マスタ!$A28,0)="","",OFFSET(マスタ非採用削除!D$4,統合マスタ!$A28,0)) -> EPL** | R28: =IF(AA28="非採用",0,IF(OFFSET(マスタ非採用削除!E$4,統合マスタ!$A28,0)="","",OFFSET(マスタ非採用削除!E$4,統合マスタ!$A28,0))) -> 1 | S28: =IF(OFFSET(マスタ非採用削除!F$4,統合マスタ!$A28,0)="","",OFFSET(マスタ非採用削除!F$4,統合マスタ!$A28,0)) | T28: =IF(OFFSET(マスタ非採用削除!G$4,統合マスタ!$A28,0)="","",OFFSET(マスタ非採用削除!G$4,統合マスタ!$A28,0)) -> 6.1 | U28: =IF(OFFSET(マスタ非採用削除!H$4,統合マスタ!$A28,0)="","",OFFSET(マスタ非採用削除!H$4,統合マスタ!$A28,0)) -> EPLｶﾌﾟｾﾙ250mg | V28: =IF(OFFSET(マスタ非採用削除!I$4,統合マスタ!$A28,0)="","",OFFSET(マスタ非採用削除!I$4,統合マスタ!$A28,0)) -> 2 | W28: =IF(OFFSET(マスタ非採用削除!J$4,統合マスタ!$A28,0)="","",OFFSET(マスタ非採用削除!J$4,統合マスタ!$A28,0)) -> カプセル | X28: =IF(OFFSET(マスタ非採用削除!K$4,統合マスタ!$A28,0)="","",OFFSET(マスタ非採用削除!K$4,統合マスタ!$A28,0)) -> 0 | Y28: =IF(OFFSET(マスタ非採用削除!L$4,統合マスタ!$A28,0)="","",OFFSET(マスタ非採用削除!L$4,統合マスタ!$A28,0)) | Z28: =IF(OFFSET(マスタ非採用削除!M$4,統合マスタ!$A28,0)="","",OFFSET(マスタ非採用削除!M$4,統合マスタ!$A28,0)) -> 5 | AB28: =IF(R28=2,"臨時", IF(COUNTIF(分類!$H$8:$H$15, 統合マスタ!V28)>0, 分類!$G$7, IF(COUNTIF(分類!$K$8:$K$15, 統合マスタ!V28)>0, 分類!$J$7, IF(COUNTIF(分類!$N$8:$N$15, 統合マスタ!V28)>0, 分類!$M$7, IF(COUNTIF(分類!$Q$8:$Q$15, 統合マスタ!V28)>0, 分類!$P$7, "無し"))))) -> 無し | AC28: =X28 * 100000 + B28 -> 24 | AD28: {=IF(A28="非採用","非採用",OFFSET( INDIRECT("'" & AB28 & "'!A4"), MATCH(B28, INDIRECT("'" & AB28 & "'!C5:C1000"), 0), MATCH("合計", INDIRECT("'" & AB28 & "'!4:4"), 0) - 1 ))} -> #REF!
A29: =元データ!P26 -> 76 | B29: =B28+1 -> 25 | C29: =DBCS(元データ!A26) -> ＳＰトローチ０．２５ｍｇ「明治」 | D29: =元データ!B26 -> メディセオ | E29: =DBCS(元データ!C26) -> ＰＴＰ | F29: =DBCS(元データ!D26) -> １２００Ｔ | G29: =元データ!E26 -> meijiseika | H29: =元データ!F26 -> 5.9 | I29: =元データ!G26 -> 7080 | J29: =元データ!H26 -> 1200 | K29: =元データ!I26 -> 錠 | L29: =元データ!J26 -> 6435 | M29: =元データ!K26 -> 5.3625 | N29: =IF(OFFSET(マスタ非採用削除!A$4,統合マスタ!$A29,0)="","",OFFSET(マスタ非採用削除!A$4,統合マスタ!$A29,0)) -> ｴｽﾋ001 | O29: =IF(OFFSET(マスタ非採用削除!B$4,統合マスタ!$A29,0)="","",OFFSET(マスタ非採用削除!B$4,統合マスタ!$A29,0)) -> ｴｽﾋ001 | P29: =IF(OFFSET(マスタ非採用削除!C$4,統合マスタ!$A29,0)="","",OFFSET(マスタ非採用削除!C$4,統合マスタ!$A29,0)) -> ＳＰトローチ０．２５ｍｇ「明治」 | Q29: =IF(OFFSET(マスタ非採用削除!D$4,統合マスタ!$A29,0)="","",OFFSET(マスタ非採用削除!D$4,統合マスタ!$A29,0)) -> SPﾄ | R29: =IF(AA29="非採用",0,IF(OFFSET(マスタ非採用削除!E$4,統合マスタ!$A29,0)="","",OFFSET(マスタ非採用削除!E$4,統合マスタ!$A29,0))) -> 1 | S29: =IF(OFFSET(マスタ非採用削除!F$4,統合マスタ!$A29,0)="","",OFFSET(マスタ非採用削除!F$4,統合マスタ!$A29,0)) | T29: =IF(OFFSET(マスタ非採用削除!G$4,統合マスタ!$A29,0)="","",OFFSET(マスタ非採用削除!G$4,統合マスタ!$A29,0)) -> 5.9 | U29: =IF(OFFSET(マスタ非採用削除!H$4,統合マスタ!$A29,0)="","",OFFSET(マスタ非採用削除!H$4,統合マスタ!$A29,0)) -> SPﾄﾛｰﾁ0.25mg｢ﾒｲｼﾞ｣ | V29: =IF(OFFSET(マスタ非採用削除!I$4,統合マスタ!$A29,0)="","",OFFSET(マスタ非採用削除!I$4,統合マスタ!$A29,0)) -> 8 | W29: =IF(OFFSET(マスタ非採用削除!J$4,統合マスタ!$A29,0)="","",OFFSET(マスタ非採用削除!J$4,統合マスタ!$A29,0)) -> トローチ | X29: =IF(OFFSET(マスタ非採用削除!K$4,統合マスタ!$A29,0)="","",OFFSET(マスタ非採用削除!K$4,統合マスタ!$A29,0)) -> 0 | Y29: =IF(OFFSET(マスタ非採用削除!L$4,統合マスタ!$A29,0)="","",OFFSET(マスタ非採用削除!L$4,統合マスタ!$A29,0)) | Z29: =IF(OFFSET(マスタ非採用削除!M$4,統合マスタ!$A29,0)="","",OFFSET(マスタ非採用削除!M$4,統合マスタ!$A29,0)) -> 3 | AB29: =IF(R29=2,"臨時", IF(COUNTIF(分類!$H$8:$H$15, 統合マスタ!V29)>0, 分類!$G$7, IF(COUNTIF(分類!$K$8:$K$15, 統合マスタ!V29)>0, 分類!$J$7, IF(COUNTIF(分類!$N$8:$N$15, 統合マスタ!V29)>0, 分類!$M$7, IF(COUNTIF(分類!$Q$8:$Q$15, 統合マスタ!V29)>0, 分類!$P$7, "無し"))))) -> 外用 | AC29: =X29 * 100000 + B29 -> 25 | AD29: {=IF(A29="非採用","非採用",OFFSET( INDIRECT("'" & AB29 & "'!A4"), MATCH(B29, INDIRECT("'" & AB29 & "'!C5:C1000"), 0), MATCH("合計", INDIRECT("'" & AB29 & "'!4:4"), 0) - 1 ))} -> 0
A30: =元データ!P27 -> 581 | B30: =B29+1 -> 26 | C30: =DBCS(元データ!A27) -> Ｔ７２ ヨクイニンエキス錠「コタロー」 | D30: =元データ!B27 -> メディセオ | E30: =DBCS(元データ!C27) -> バラ | F30: =DBCS(元データ!D27) -> １２６Ｔｘ１０ | G30: =元データ!E27 -> 小太郎漢方 | H30: =元データ!F27 -> 6.5 | I30: =元データ!G27 -> 8190 | J30: =元データ!H27 -> 1260 | K30: =元データ!I27 -> 錠 | L30: =元データ!J27 -> 7445 | M30: =元データ!K27 -> 5.9087302 | N30: =IF(OFFSET(マスタ非採用削除!A$4,統合マスタ!$A30,0)="","",OFFSET(マスタ非採用削除!A$4,統合マスタ!$A30,0)) -> ﾖｸｲ001 | O30: =IF(OFFSET(マスタ非採用削除!B$4,統合マスタ!$A30,0)="","",OFFSET(マスタ非採用削除!B$4,統合マスタ!$A30,0)) -> ﾖｸｲ001 | P30: =IF(OFFSET(マスタ非採用削除!C$4,統合マスタ!$A30,0)="","",OFFSET(マスタ非採用削除!C$4,統合マスタ!$A30,0)) -> ヨクイニンエキス錠「コタロー」 | Q30: =IF(OFFSET(マスタ非採用削除!D$4,統合マスタ!$A30,0)="","",OFFSET(マスタ非採用削除!D$4,統合マスタ!$A30,0)) | R30: =IF(AA30="非採用",0,IF(OFFSET(マスタ非採用削除!E$4,統合マスタ!$A30,0)="","",OFFSET(マスタ非採用削除!E$4,統合マスタ!$A30,0))) -> 2 | S30: =IF(OFFSET(マスタ非採用削除!F$4,統合マスタ!$A30,0)="","",OFFSET(マスタ非採用削除!F$4,統合マスタ!$A30,0)) | T30: =IF(OFFSET(マスタ非採用削除!G$4,統合マスタ!$A30,0)="","",OFFSET(マスタ非採用削除!G$4,統合マスタ!$A30,0)) -> 6.5 | U30: =IF(OFFSET(マスタ非採用削除!H$4,統合マスタ!$A30,0)="","",OFFSET(マスタ非採用削除!H$4,統合マスタ!$A30,0)) -> ﾖｸｲﾆﾝｴｷｽｼﾞﾖｳｺﾀﾛ- | V30: =IF(OFFSET(マスタ非採用削除!I$4,統合マスタ!$A30,0)="","",OFFSET(マスタ非採用削除!I$4,統合マスタ!$A30,0)) -> 1 | W30: =IF(OFFSET(マスタ非採用削除!J$4,統合マスタ!$A30,0)="","",OFFSET(マスタ非採用削除!J$4,統合マスタ!$A30,0)) -> 錠剤 | X30: =IF(OFFSET(マスタ非採用削除!K$4,統合マスタ!$A30,0)="","",OFFSET(マスタ非採用削除!K$4,統合マスタ!$A30,0)) -> 0 | Y30: =IF(OFFSET(マスタ非採用削除!L$4,統合マスタ!$A30,0)="","",OFFSET(マスタ非採用削除!L$4,統合マスタ!$A30,0)) | Z30: =IF(OFFSET(マスタ非採用削除!M$4,統合マスタ!$A30,0)="","",OFFSET(マスタ非採用削除!M$4,統合マスタ!$A30,0)) -> 15 | AB30: =IF(R30=2,"臨時", IF(COUNTIF(分類!$H$8:$H$15, 統合マスタ!V30)>0, 分類!$G$7, IF(COUNTIF(分類!$K$8:$K$15, 統合マスタ!V30)>0, 分類!$J$7, IF(COUNTIF(分類!$N$8:$N$15, 統合マスタ!V30)>0, 分類!$M$7, IF(COUNTIF(分類!$Q$8:$Q$15, 統合マスタ!V30)>0, 分類!$P$7, "無し"))))) -> 臨時 | AC30: =X30 * 100000 + B30 -> 26 | AD30: {=IF(A30="非採用","非採用",OFFSET( INDIRECT("'" & AB30 & "'!A4"), MATCH(B30, INDIRECT("'" & AB30 & "'!C5:C1000"), 0), MATCH("合計", INDIRECT("'" & AB30 & "'!4:4"), 0) - 1 ))} -> 0
A31: =元データ!P28 -> 22 | B31: =B30+1 -> 27 | C31: =DBCS(元データ!A28) -> アーチスト錠１．２５ｍｇ | D31: =元データ!B28 -> メディセオ | E31: =DBCS(元データ!C28) -> ＰＴＰ | F31: =DBCS(元データ!D28) -> １００Ｔ | G31: =元データ!E28 -> 第一三共 | H31: =元データ!F28 -> 10.4 | I31: =元データ!G28 -> 1040 | J31: =元データ!H28 -> 100 | K31: =元データ!I28 -> 錠 | L31: =元データ!J28 -> 926 | M31: =元データ!K28 -> 9.26 | N31: =IF(OFFSET(マスタ非採用削除!A$4,統合マスタ!$A31,0)="","",OFFSET(マスタ非採用削除!A$4,統合マスタ!$A31,0)) -> ｱﾁｽ001 | O31: =IF(OFFSET(マスタ非採用削除!B$4,統合マスタ!$A31,0)="","",OFFSET(マスタ非採用削除!B$4,統合マスタ!$A31,0)) -> ｱﾁｽ001 | P31: =IF(OFFSET(マスタ非採用削除!C$4,統合マスタ!$A31,0)="","",OFFSET(マスタ非採用削除!C$4,統合マスタ!$A31,0)) -> アーチスト錠１．２５ｍｇ | Q31: =IF(OFFSET(マスタ非採用削除!D$4,統合マスタ!$A31,0)="","",OFFSET(マスタ非採用削除!D$4,統合マスタ!$A31,0)) -> ｱｰﾁ | R31: =IF(AA31="非採用",0,IF(OFFSET(マスタ非採用削除!E$4,統合マスタ!$A31,0)="","",OFFSET(マスタ非採用削除!E$4,統合マスタ!$A31,0))) -> 1 | S31: =IF(OFFSET(マスタ非採用削除!F$4,統合マスタ!$A31,0)="","",OFFSET(マスタ非採用削除!F$4,統合マスタ!$A31,0)) | T31: =IF(OFFSET(マスタ非採用削除!G$4,統合マスタ!$A31,0)="","",OFFSET(マスタ非採用削除!G$4,統合マスタ!$A31,0)) -> 10.4 | U31: =IF(OFFSET(マスタ非採用削除!H$4,統合マスタ!$A31,0)="","",OFFSET(マスタ非採用削除!H$4,統合マスタ!$A31,0)) -> ｱｰﾁｽﾄｼﾞｮｳ1.25mg | V31: =IF(OFFSET(マスタ非採用削除!I$4,統合マスタ!$A31,0)="","",OFFSET(マスタ非採用削除!I$4,統合マスタ!$A31,0)) -> 1 | W31: =IF(OFFSET(マスタ非採用削除!J$4,統合マスタ!$A31,0)="","",OFFSET(マスタ非採用削除!J$4,統合マスタ!$A31,0)) -> 錠剤 | X31: =IF(OFFSET(マスタ非採用削除!K$4,統合マスタ!$A31,0)="","",OFFSET(マスタ非採用削除!K$4,統合マスタ!$A31,0)) -> 0 | Y31: =IF(OFFSET(マスタ非採用削除!L$4,統合マスタ!$A31,0)="","",OFFSET(マスタ非採用削除!L$4,統合マスタ!$A31,0)) | Z31: =IF(OFFSET(マスタ非採用削除!M$4,統合マスタ!$A31,0)="","",OFFSET(マスタ非採用削除!M$4,統合マスタ!$A31,0)) -> 5 | AB31: =IF(R31=2,"臨時", IF(COUNTIF(分類!$H$8:$H$15, 統合マスタ!V31)>0, 分類!$G$7, IF(COUNTIF(分類!$K$8:$K$15, 統合マスタ!V31)>0, 分類!$J$7, IF(COUNTIF(分類!$N$8:$N$15, 統合マスタ!V31)>0, 分類!$M$7, IF(COUNTIF(分類!$Q$8:$Q$15, 統合マスタ!V31)>0, 分類!$P$7, "無し"))))) -> 錠剤 | AC31: =X31 * 100000 + B31 -> 27 | AD31: {=IF(A31="非採用","非採用",OFFSET( INDIRECT("'" & AB31 & "'!A4"), MATCH(B31, INDIRECT("'" & AB31 & "'!C5:C1000"), 0), MATCH("合計", INDIRECT("'" & AB31 & "'!4:4"), 0) - 1 ))} -> 2
A32: =元データ!P29 -> 非採用 | B32: =B31+1 -> 28 | C32: =DBCS(元データ!A29) -> アイファガン点眼液０．１％ | D32: =元データ!B29 | E32: =DBCS(元データ!C29) | F32: =DBCS(元データ!D29) -> ５ｍｌｘ５ | G32: =元データ!E29 -> 武田薬品工業 | H32: =元データ!F29 -> 268.9 | I32: =元データ!G29 -> 6722.5 | J32: =元データ!H29 -> 25 | K32: =元データ!I29 -> ｍｌ | L32: =元データ!J29 -> 5858 | M32: =元データ!K29 -> 234.32 | N32: =IF(OFFSET(マスタ非採用削除!A$4,統合マスタ!$A32,0)="","",OFFSET(マスタ非採用削除!A$4,統合マスタ!$A32,0)) -> #VALUE! | O32: =IF(OFFSET(マスタ非採用削除!B$4,統合マスタ!$A32,0)="","",OFFSET(マスタ非採用削除!B$4,統合マスタ!$A32,0)) -> #VALUE! | P32: =IF(OFFSET(マスタ非採用削除!C$4,統合マスタ!$A32,0)="","",OFFSET(マスタ非採用削除!C$4,統合マスタ!$A32,0)) -> #VALUE! | Q32: =IF(OFFSET(マスタ非採用削除!D$4,統合マスタ!$A32,0)="","",OFFSET(マスタ非採用削除!D$4,統合マスタ!$A32,0)) -> #VALUE! | R32: =IF(AA32="非採用",0,IF(OFFSET(マスタ非採用削除!E$4,統合マスタ!$A32,0)="","",OFFSET(マスタ非採用削除!E$4,統合マスタ!$A32,0))) -> 0 | S32: =IF(OFFSET(マスタ非採用削除!F$4,統合マスタ!$A32,0)="","",OFFSET(マスタ非採用削除!F$4,統合マスタ!$A32,0)) -> #VALUE! | T32: =IF(OFFSET(マスタ非採用削除!G$4,統合マスタ!$A32,0)="","",OFFSET(マスタ非採用削除!G$4,統合マスタ!$A32,0)) -> #VALUE! | U32: =IF(OFFSET(マスタ非採用削除!H$4,統合マスタ!$A32,0)="","",OFFSET(マスタ非採用削除!H$4,統合マスタ!$A32,0)) -> #VALUE! | V32: =IF(OFFSET(マスタ非採用削除!I$4,統合マスタ!$A32,0)="","",OFFSET(マスタ非採用削除!I$4,統合マスタ!$A32,0)) -> #VALUE! | W32: =IF(OFFSET(マスタ非採用削除!J$4,統合マスタ!$A32,0)="","",OFFSET(マスタ非採用削除!J$4,統合マスタ!$A32,0)) -> #VALUE! | X32: =IF(OFFSET(マスタ非採用削除!K$4,統合マスタ!$A32,0)="","",OFFSET(マスタ非採用削除!K$4,統合マスタ!$A32,0)) -> #VALUE! | Y32: =IF(OFFSET(マスタ非採用削除!L$4,統合マスタ!$A32,0)="","",OFFSET(マスタ非採用削除!L$4,統合マスタ!$A32,0)) -> #VALUE! | Z32: =IF(OFFSET(マスタ非採用削除!M$4,統合マスタ!$A32,0)="","",OFFSET(マスタ非採用削除!M$4,統合マスタ!$A32,0)) -> #VALUE! | AA32: 非採用 | AB32: =IF(R32=2,"臨時", IF(COUNTIF(分類!$H$8:$H$15, 統合マスタ!V32)>0, 分類!$G$7, IF(COUNTIF(分類!$K$8:$K$15, 統合マスタ!V32)>0, 分類!$J$7, IF(COUNTIF(分類!$N$8:$N$15, 統合マスタ!V32)>0, 分類!$M$7, IF(COUNTIF(分類!$Q$8:$Q$15, 統合マスタ!V32)>0, 分類!$P$7, "無し"))))) -> 無し | AC32: =X32 * 100000 + B32 -> #VALUE! | AD32: {=IF(A32="非採用","非採用",OFFSET( INDIRECT("'" & AB32 & "'!A4"), MATCH(B32, INDIRECT("'" & AB32 & "'!C5:C1000"), 0), MATCH("合計", INDIRECT("'" & AB32 & "'!4:4"), 0) - 1 ))} -> 非採用
A33: =元データ!P30 -> 非採用 | B33: =B32+1 -> 29 | C33: =DBCS(元データ!A30) -> アウィクリ注 フレックスタッチ 総量３００単位 | D33: =元データ!B30 -> アルフレッサ | E33: =DBCS(元データ!C30) | F33: =DBCS(元データ!D30) -> ０．４３ｍｌｘ２ｋｉｔ | G33: =元データ!E30 -> ノボノルディスク | H33: =元データ!F30 -> 2081 | I33: =元データ!G30 -> 4162 | J33: =元データ!H30 -> 2 | K33: =元データ!I30 -> kit | L33: =元データ!J30 -> 3689 | M33: =元データ!K30 -> 1844.5 | N33: =IF(OFFSET(マスタ非採用削除!A$4,統合マスタ!$A33,0)="","",OFFSET(マスタ非採用削除!A$4,統合マスタ!$A33,0)) -> #VALUE! | O33: =IF(OFFSET(マスタ非採用削除!B$4,統合マスタ!$A33,0)="","",OFFSET(マスタ非採用削除!B$4,統合マスタ!$A33,0)) -> #VALUE! | P33: =IF(OFFSET(マスタ非採用削除!C$4,統合マスタ!$A33,0)="","",OFFSET(マスタ非採用削除!C$4,統合マスタ!$A33,0)) -> #VALUE! | Q33: =IF(OFFSET(マスタ非採用削除!D$4,統合マスタ!$A33,0)="","",OFFSET(マスタ非採用削除!D$4,統合マスタ!$A33,0)) -> #VALUE! | R33: =IF(AA33="非採用",0,IF(OFFSET(マスタ非採用削除!E$4,統合マスタ!$A33,0)="","",OFFSET(マスタ非採用削除!E$4,統合マスタ!$A33,0))) -> 0 | S33: =IF(OFFSET(マスタ非採用削除!F$4,統合マスタ!$A33,0)="","",OFFSET(マスタ非採用削除!F$4,統合マスタ!$A33,0)) -> #VALUE! | T33: =IF(OFFSET(マスタ非採用削除!G$4,統合マスタ!$A33,0)="","",OFFSET(マスタ非採用削除!G$4,統合マスタ!$A33,0)) -> #VALUE! | U33: =IF(OFFSET(マスタ非採用削除!H$4,統合マスタ!$A33,0)="","",OFFSET(マスタ非採用削除!H$4,統合マスタ!$A33,0)) -> #VALUE! | V33: =IF(OFFSET(マスタ非採用削除!I$4,統合マスタ!$A33,0)="","",OFFSET(マスタ非採用削除!I$4,統合マスタ!$A33,0)) -> #VALUE! | W33: =IF(OFFSET(マスタ非採用削除!J$4,統合マスタ!$A33,0)="","",OFFSET(マスタ非採用削除!J$4,統合マスタ!$A33,0)) -> #VALUE! | X33: =IF(OFFSET(マスタ非採用削除!K$4,統合マスタ!$A33,0)="","",OFFSET(マスタ非採用削除!K$4,統合マスタ!$A33,0)) -> #VALUE! | Y33: =IF(OFFSET(マスタ非採用削除!L$4,統合マスタ!$A33,0)="","",OFFSET(マスタ非採用削除!L$4,統合マスタ!$A33,0)) -> #VALUE! | Z33: =IF(OFFSET(マスタ非採用削除!M$4,統合マスタ!$A33,0)="","",OFFSET(マスタ非採用削除!M$4,統合マスタ!$A33,0)) -> #VALUE! | AA33: 非採用 | AB33: =IF(R33=2,"臨時", IF(COUNTIF(分類!$H$8:$H$15, 統合マスタ!V33)>0, 分類!$G$7, IF(COUNTIF(分類!$K$8:$K$15, 統合マスタ!V33)>0, 分類!$J$7, IF(COUNTIF(分類!$N$8:$N$15, 統合マスタ!V33)>0, 分類!$M$7, IF(COUNTIF(分類!$Q$8:$Q$15, 統合マスタ!V33)>0, 分類!$P$7, "無し"))))) -> 無し | AC33: =X33 * 100000 + B33 -> #VALUE! | AD33: {=IF(A33="非採用","非採用",OFFSET( INDIRECT("'" & AB33 & "'!A4"), MATCH(B33, INDIRECT("'" & AB33 & "'!C5:C1000"), 0), MATCH("合計", INDIRECT("'" & AB33 & "'!4:4"), 0) - 1 ))} -> 非採用
