Workbook

Sheet リスト
D4: ='1行'!M4 -> No | E4: ='1行'!G4 -> 発注日 | F4: ='1行'!N4 -> 発注時刻 | G4: ='1行'!H4 -> 納品指定日 | H4: ='1行'!J4 -> 品名 | I4: ='1行'!O4 -> 規格容量 | J4: ='1行'!K4 -> メーカー名 | K4: ='1行'!F4 -> 商品コード | L4: ='1行'!D4 -> 未納品数 | M4: ='1行'!L4 -> 発注数 | N4: ='1行'!E4 -> 検品数
B5: アルフレッサ | D5: ='1行'!M5 -> 1 | E5: ='1行'!G5 -> 2026/02/09 | F5: ='1行'!N5 -> 15:44:45 | G5: ='1行'!H5 -> 2026/02/09 | H5: ='1行'!J5 -> セパゾン錠1 | I5: ='1行'!O5 -> 1mg/錠 PTP 10錠×10 | J5: ='1行'!K5 -> アルフレッサファーマ | K5: ='1行'!F5 -> 4987274132872 | L5: ='1行'!D5 -> 2 | M5: ='1行'!L5 -> 2 | N5: ='1行'!E5 -> 0
D6: ='1行'!M6 -> 2 | E6: ='1行'!G6 -> 2026/03/25 | F6: ='1行'!N6 -> 08:54:48 | G6: ='1行'!H6 -> 2026/04/01 | H6: ='1行'!J6 -> マーズレンS配合顆粒 | I6: ='1行'!O6 -> バラ 500g×2袋 | J6: ='1行'!K6 -> 寿製薬 | K6: ='1行'!F6 -> 4987071129112 | L6: ='1行'!D6 -> 1 | M6: ='1行'!L6 -> 1 | N6: ='1行'!E6 -> 0
D7: ='1行'!M7 -> 3 | E7: ='1行'!G7 -> 2026/03/25 | F7: ='1行'!N7 -> 08:54:48 | G7: ='1行'!H7 -> 2026/04/01 | H7: ='1行'!J7 -> クエチアピン細粒50%「アメル」 | I7: ='1行'!O7 -> 50%1g バラ 100g×1瓶 | J7: ='1行'!K7 -> 共和薬品工業 | K7: ='1行'!F7 -> 4987058197530 | L7: ='1行'!D7 -> 1 | M7: ='1行'!L7 -> 1 | N7: ='1行'!E7 -> 0
D8: ='1行'!M8 -> 4 | E8: ='1行'!G8 -> 2026/03/25 | F8: ='1行'!N8 -> 08:54:48 | G8: ='1行'!H8 -> 2026/04/01 | H8: ='1行'!J8 -> ジプレキサザイディス錠5mg | I8: ='1行'!O8 -> 5mg/錠 7錠×50 (ブリスター) | J8: ='1行'!K8 -> チェプラファーム | K8: ='1行'!F8 -> 4987994500173 | L8: ='1行'!D8 -> 1 | M8: ='1行'!L8 -> 1 | N8: ='1行'!E8 -> 0
D9: ='1行'!M9 -> 5 | E9: ='1行'!G9 -> 2026/03/25 | F9: ='1行'!N9 -> 08:54:48 | G9: ='1行'!H9 -> 2026/04/01 | H9: ='1行'!J9 -> ハーフジゴキシンKY錠0.125 | I9: ='1行'!O9 -> 0.125mg/錠 PTP 10錠×10 | J9: ='1行'!K9 -> トーアエイヨー | K9: ='1行'!F9 -> 4987142731114 | L9: ='1行'!D9 -> 1 | M9: ='1行'!L9 -> 1 | N9: ='1行'!E9 -> 0
D10: ='1行'!M10 -> 6 | E10: ='1行'!G10 -> 2026/03/25 | F10: ='1行'!N10 -> 08:54:48 | G10: ='1行'!H10 -> 2026/04/01 | H10: ='1行'!J10 -> シクレスト舌下錠10mg | I10: ='1行'!O10 -> 10mg/錠 PTP 10錠×10 | J10: ='1行'!K10 -> Ｍｅｉｊｉ Ｓｅｉｋａ ファル | K10: ='1行'!F10 -> 4987222674232 | L10: ='1行'!D10 -> 2 | M10: ='1行'!L10 -> 2 | N10: ='1行'!E10 -> 0
D11: ='1行'!M11 -> 7 | E11: ='1行'!G11 -> 2026/03/25 | F11: ='1行'!N11 -> 08:54:48 | G11: ='1行'!H11 -> 2026/04/01 | H11: ='1行'!J11 -> シクレスト舌下錠5mg | I11: ='1行'!O11 -> 5mg/錠 PTP 10錠×10 | J11: ='1行'!K11 -> Ｍｅｉｊｉ Ｓｅｉｋａ ファル | K11: ='1行'!F11 -> 4987222673730 | L11: ='1行'!D11 -> 2 | M11: ='1行'!L11 -> 2 | N11: ='1行'!E11 -> 0
D12: ='1行'!M12 -> 8 | E12: ='1行'!G12 -> 2026/03/25 | F12: ='1行'!N12 -> 08:54:48 | G12: ='1行'!H12 -> 2026/04/01 | H12: ='1行'!J12 -> マグミット錠500mg | I12: ='1行'!O12 -> 500mg/錠 バラ 500錠×1瓶 | J12: ='1行'!K12 -> 丸石製薬 | K12: ='1行'!F12 -> 4987211127398 | L12: ='1行'!D12 -> 1 | M12: ='1行'!L12 -> 1 | N12: ='1行'!E12 -> 0
D13: ='1行'!M13 -> 9 | E13: ='1行'!G13 -> 2026/03/25 | F13: ='1行'!N13 -> 08:54:48 | G13: ='1行'!H13 -> 2026/04/01 | H13: ='1行'!J13 -> クエチアピン錠200mg「アメル」 | I13: ='1行'!O13 -> 200mg/錠 バラ 500錠×1瓶 | J13: ='1行'!K13 -> 共和薬品工業 | K13: ='1行'!F13 -> 4987058196557 | L13: ='1行'!D13 -> 1 | M13: ='1行'!L13 -> 1 | N13: ='1行'!E13 -> 0
D14: ='1行'!M14 -> 10 | E14: ='1行'!G14 -> 2026/03/25 | F14: ='1行'!N14 -> 08:54:48 | G14: ='1行'!H14 -> 2026/04/01 | H14: ='1行'!J14 -> リスパダール細粒1% | I14: ='1行'!O14 -> 10mg/g バラ 100g×1瓶 | J14: ='1行'!K14 -> ヤンセンファーマ | K14: ='1行'!F14 -> 4987672393189 | L14: ='1行'!D14 -> 1 | M14: ='1行'!L14 -> 1 | N14: ='1行'!E14 -> 0
D15: ='1行'!M15 -> 11 | E15: ='1行'!G15 -> 2026/03/25 | F15: ='1行'!N15 -> 08:54:48 | G15: ='1行'!H15 -> 2026/04/01 | H15: ='1行'!J15 -> ゼプリオン水懸筋注75mgシリンジ | I15: ='1行'!O15 -> 75mg1キット×1キット | J15: ='1行'!K15 -> 住友ファーマ | K15: ='1行'!F15 -> 4987116011143 | L15: ='1行'!D15 -> 1 | M15: ='1行'!L15 -> 1 | N15: ='1行'!E15 -> 0
D16: ='1行'!M16 -> 12 | E16: ='1行'!G16 -> 2026/03/25 | F16: ='1行'!N16 -> 08:54:48 | G16: ='1行'!H16 -> 2026/04/01 | H16: ='1行'!J16 -> クエチアピン錠100mg「アメル」 | I16: ='1行'!O16 -> 100mg/錠 バラ 1000錠×1瓶 | J16: ='1行'!K16 -> 共和薬品工業 | K16: ='1行'!F16 -> 4987058195611 | L16: ='1行'!D16 -> 1 | M16: ='1行'!L16 -> 1 | N16: ='1行'!E16 -> 0
D17: ='1行'!M17 -> 13 | E17: ='1行'!G17 -> 2026/03/25 | F17: ='1行'!N17 -> 08:54:48 | G17: ='1行'!H17 -> 2026/04/01 | H17: ='1行'!J17 -> シングレア錠10mg | I17: ='1行'!O17 -> 10mg/錠 PTP 10錠×10 | J17: ='1行'!K17 -> オルガノン | K17: ='1行'!F17 -> 4987954807175 | L17: ='1行'!D17 -> 1 | M17: ='1行'!L17 -> 1 | N17: ='1行'!E17 -> 0
... D34: ='1行'!M34 -> 30 | E34: ='1行'!G34 -> 2026/03/25 | F34: ='1行'!N34 -> 08:54:48 | G34: ='1行'!H34 -> 2026/04/01 | H34: ='1行'!J34 -> セララ錠50mg | I34: ='1行'!O34 -> 50mg/錠 PTP 10錠×10 | J34: ='1行'!K34 -> ヴィアトリス製薬 | K34: ='1行'!F34 -> 4987901006200 | L34: ='1行'!D34 -> 1 | M34: ='1行'!L34 -> 1 | N34: ='1行'!E34 -> 0
C35: 未納品一覧 | D35: ='1行'!M35 -> 31 | E35: ='1行'!G35 -> 2026/03/25 | F35: ='1行'!N35 -> 08:54:48 | G35: ='1行'!H35 -> 2026/04/01 | H35: ='1行'!J35 -> オルメテックOD錠10mg | I35: ='1行'!O35 -> 10mg/錠 PTP 10錠×10 | J35: ='1行'!K35 -> 第一三共 | K35: ='1行'!F35 -> 4987081103119 | L35: ='1行'!D35 -> 1 | M35: ='1行'!L35 -> 1 | N35: ='1行'!E35 -> 0
D36: ='1行'!M36 -> 32 | E36: ='1行'!G36 -> 2026/03/25 | F36: ='1行'!N36 -> 08:54:48 | G36: ='1行'!H36 -> 2026/04/01 | H36: ='1行'!J36 -> ビプレッソ徐放錠150mg | I36: ='1行'!O36 -> 150mg/錠 PTP 10錠×10 | J36: ='1行'!K36 -> 共和薬品工業 | K36: ='1行'!F36 -> 4987058784280 | L36: ='1行'!D36 -> 1 | M36: ='1行'!L36 -> 1 | N36: ='1行'!E36 -> 0
D37: ='1行'!M37 -> 33 | E37: ='1行'!G37 -> 2026/03/25 | F37: ='1行'!N37 -> 08:54:48 | G37: ='1行'!H37 -> 2026/04/01 | H37: ='1行'!J37 -> ビソノテープ2mg | I37: ='1行'!O37 -> 2mg1枚×70袋 (3cm×3cm) | J37: ='1行'!K37 -> トーアエイヨー | K37: ='1行'!F37 -> 4987142381203 | L37: ='1行'!D37 -> 1 | M37: ='1行'!L37 -> 1 | N37: ='1行'!E37 -> 0
D38: ='1行'!M38 -> 34 | E38: ='1行'!G38 -> 2026/03/25 | F38: ='1行'!N38 -> 08:54:48 | G38: ='1行'!H38 -> 2026/04/01 | H38: ='1行'!J38 -> ビソノテープ4mg | I38: ='1行'!O38 -> 4mg1枚×70袋 (4.25cm×4.25cm) | J38: ='1行'!K38 -> トーアエイヨー | K38: ='1行'!F38 -> 4987142381401 | L38: ='1行'!D38 -> 1 | M38: ='1行'!L38 -> 1 | N38: ='1行'!E38 -> 0
D39: ='1行'!M39 -> 35 | E39: ='1行'!G39 -> 2026/03/25 | F39: ='1行'!N39 -> 08:54:48 | G39: ='1行'!H39 -> 2026/04/01 | H39: ='1行'!J39 -> フルニトラゼパム錠1mg「アメル」 | I39: ='1行'!O39 -> 1mg/錠 PTP 10錠×100 | J39: ='1行'!K39 -> 共和薬品工業 | K39: ='1行'!F39 -> 4987058565117 | L39: ='1行'!D39 -> 1 | M39: ='1行'!L39 -> 1 | N39: ='1行'!E39 -> 0
D40: ='1行'!M40 -> 36 | E40: ='1行'!G40 -> 2026/03/25 | F40: ='1行'!N40 -> 08:54:48 | G40: ='1行'!H40 -> 2026/04/01 | H40: ='1行'!J40 -> フルニトラゼパム錠2mg「アメル」 | I40: ='1行'!O40 -> 2mg/錠 PTP 10錠×100 | J40: ='1行'!K40 -> 共和薬品工業 | K40: ='1行'!F40 -> 4987058566114 | L40: ='1行'!D40 -> 1 | M40: ='1行'!L40 -> 1 | N40: ='1行'!E40 -> 0
D41: ='1行'!M41 -> 37 | E41: ='1行'!G41 -> 2026/03/25 | F41: ='1行'!N41 -> 08:54:48 | G41: ='1行'!H41 -> 2026/04/01 | H41: ='1行'!J41 -> セレスタミン配合錠 | I41: ='1行'!O41 -> バラ 100錠×1瓶 | J41: ='1行'!K41 -> 高田製薬 | K41: ='1行'!F41 -> 4987120246012 | L41: ='1行'!D41 -> 1 | M41: ='1行'!L41 -> 1 | N41: ='1行'!E41 -> 0
D42: ='1行'!M42 -> 38 | E42: ='1行'!G42 -> 2026/03/25 | F42: ='1行'!N42 -> 08:54:48 | G42: ='1行'!H42 -> 2026/04/01 | H42: ='1行'!J42 -> フルニトラゼパム錠1mg「アメル」 | I42: ='1行'!O42 -> 1mg/錠 バラ 1000錠×1瓶 | J42: ='1行'!K42 -> 共和薬品工業 | K42: ='1行'!F42 -> 4987058565612 | L42: ='1行'!D42 -> 1 | M42: ='1行'!L42 -> 1 | N42: ='1行'!E42 -> 0
D43: ='1行'!M43 -> 39 | E43: ='1行'!G43 -> 2026/03/25 | F43: ='1行'!N43 -> 08:54:48 | G43: ='1行'!H43 -> 2026/04/01 | H43: ='1行'!J43 -> フルニトラゼパム錠2mg「アメル」 | I43: ='1行'!O43 -> 2mg/錠 バラ 1000錠×1瓶 | J43: ='1行'!K43 -> 共和薬品工業 | K43: ='1行'!F43 -> 4987058566619 | L43: ='1行'!D43 -> 1 | M43: ='1行'!L43 -> 1 | N43: ='1行'!E43 -> 0
D44: ='1行'!M44 -> 40 | E44: ='1行'!G44 -> 2026/03/25 | F44: ='1行'!N44 -> 08:54:48 | G44: ='1行'!H44 -> 2026/04/01 | H44: ='1行'!J44 -> クエチアピン錠25mg「アメル」 | I44: ='1行'!O44 -> 25mg/錠 バラ 1000錠×1瓶 | J44: ='1行'!K44 -> 共和薬品工業 | K44: ='1行'!F44 -> 4987058193617 | L44: ='1行'!D44 -> 2 | M44: ='1行'!L44 -> 2 | N44: ='1行'!E44 -> 0
D45: ='1行'!M45 -> 41 | E45: ='1行'!G45 -> 2026/03/25 | F45: ='1行'!N45 -> 08:54:48 | G45: ='1行'!H45 -> 2026/04/01 | H45: ='1行'!J45 -> デパケンR錠200mg | I45: ='1行'!O45 -> 200mg/錠 バラ 1000錠×1瓶 | J45: ='1行'!K45 -> 日医工 | K45: ='1行'!F45 -> 4987376850223 | L45: ='1行'!D45 -> 1 | M45: ='1行'!L45 -> 1 | N45: ='1行'!E45 -> 0
D46: ='1行'!M46 -> 42 | E46: ='1行'!G46 -> 2026/03/25 | F46: ='1行'!N46 -> 08:54:48 | G46: ='1行'!H46 -> 2026/04/01 | H46: ='1行'!J46 -> イベニティ皮下注105mgシリンジ | I46: ='1行'!O46 -> 105mg1.17mL1筒×2筒 | J46: ='1行'!K46 -> アステラス製薬 | K46: ='1行'!F46 -> 4987233105220 | L46: ='1行'!D46 -> 5 | M46: ='1行'!L46 -> 5 | N46: ='1行'!E46 -> 0
D47: ='1行'!M47 -> 43 | E47: ='1行'!G47 -> 2026/03/25 | F47: ='1行'!N47 -> 08:54:48 | G47: ='1行'!H47 -> 2026/04/01 | H47: ='1行'!J47 -> プレガバリンOD錠75mg「サワイ」 | I47: ='1行'!O47 -> 75mg/錠 PTP 10錠×10 | J47: ='1行'!K47 -> 沢井製薬 | K47: ='1行'!F47 -> 4987080471714 | L47: ='1行'!D47 -> 1 | M47: ='1行'!L47 -> 1 | N47: ='1行'!E47 -> 0
... D57: ='1行'!M57 -> 53 | E57: ='1行'!G57 -> 2026/03/25 | F57: ='1行'!N57 -> 08:54:48 | G57: ='1行'!H57 -> 2026/04/01 | H57: ='1行'!J57 -> ゼプリオン水懸筋注100mgシリンジ | I57: ='1行'!O57 -> 100mg1キット×1キット | J57: ='1行'!K57 -> 住友ファーマ | K57: ='1行'!F57 -> 4987116011150 | L57: ='1行'!D57 -> 1 | M57: ='1行'!L57 -> 1 | N57: ='1行'!E57 -> 0
B58: メディセオ（井筒） | D58: ='1行'!M58 -> 1 | E58: ='1行'!G58 -> 2026/03/26 | F58: ='1行'!N58 -> 15:43:55 | G58: ='1行'!H58 -> 2026/03/26 | H58: ='1行'!J58 -> モビコール配合内用剤LD | I58: ='1行'!O58 -> 分包 6.8523g1包×100包 | J58: ='1行'!K58 -> 持田製薬 | K58: ='1行'!F58 -> 4987224143521 | L58: ='1行'!D58 -> 2 | M58: ='1行'!L58 -> 2 | N58: ='1行'!E58 -> 0
D59: ='1行'!M59 -> 2 | E59: ='1行'!G59 -> 2026/03/26 | F59: ='1行'!N59 -> 15:43:55 | G59: ='1行'!H59 -> 2026/03/26 | H59: ='1行'!J59 -> ツムラ抑肝散エキス顆粒(医療用) | I59: ='1行'!O59 -> 分包 2.5g×189包 | J59: ='1行'!K59 -> ツムラ | K59: ='1行'!F59 -> 4987138805430 | L59: ='1行'!D59 -> 2 | M59: ='1行'!L59 -> 2 | N59: ='1行'!E59 -> 0
D60: ='1行'!M60 -> 3 | E60: ='1行'!G60 -> 2026/03/26 | F60: ='1行'!N60 -> 15:43:55 | G60: ='1行'!H60 -> 2026/03/26 | H60: ='1行'!J60 -> ソルデム1輸液 200ｍｌ | I60: ='1行'!O60 -> 200mL×30袋 | J60: ='1行'!K60 -> テルモ | K60: ='1行'!F60 -> 4987350088710 | L60: ='1行'!D60 -> 2 | M60: ='1行'!L60 -> 2 | N60: ='1行'!E60 -> 0
D61: ='1行'!M61 -> 4 | E61: ='1行'!G61 -> 2026/03/26 | F61: ='1行'!N61 -> 15:43:55 | G61: ='1行'!H61 -> 2026/03/26 | H61: ='1行'!J61 -> ラスビック点滴静注キット150mg | I61: ='1行'!O61 -> 150mg1キット×1キット (76mL専用希釈液(注入針入り支持筒付容器付)) | J61: ='1行'!K61 -> 杏林製薬 | K61: ='1行'!F61 -> 4987060008909 | L61: ='1行'!D61 -> 3 | M61: ='1行'!L61 -> 3 | N61: ='1行'!E61 -> 0
C62: 未納品一覧 | D62: ='1行'!M62 -> 5 | E62: ='1行'!G62 -> 2026/03/26 | F62: ='1行'!N62 -> 15:43:55 | G62: ='1行'!H62 -> 2026/03/26 | H62: ='1行'!J62 -> グリセリン浣腸液50%「ムネ」60mL | I62: ='1行'!O62 -> 50%60mL1個×10個 (ポリ) | J62: ='1行'!K62 -> 丸石製薬 | K62: ='1行'!F62 -> 4987211123710 | L62: ='1行'!D62 -> 12 | M62: ='1行'!L62 -> 12 | N62: ='1行'!E62 -> 0
D63: ='1行'!M63 -> 6 | E63: ='1行'!G63 -> 2026/03/26 | F63: ='1行'!N63 -> 15:43:55 | G63: ='1行'!H63 -> 2026/03/26 | H63: ='1行'!J63 -> リクシアナOD錠30mg | I63: ='1行'!O63 -> 30mg/錠 バラ 100錠×1瓶 | J63: ='1行'!K63 -> 第一三共 | K63: ='1行'!F63 -> 4987081107063 | L63: ='1行'!D63 -> 1 | M63: ='1行'!L63 -> 1 | N63: ='1行'!E63 -> 0
D64: ='1行'!M64 -> 7 | E64: ='1行'!G64 -> 2026/03/25 | F64: ='1行'!N64 -> 08:54:48 | G64: ='1行'!H64 -> 2026/04/01 | H64: ='1行'!J64 -> ツムラ八味地黄丸エキス顆粒(医療用) | I64: ='1行'!O64 -> 分包 2.5g×189包 | J64: ='1行'!K64 -> ツムラ | K64: ='1行'!F64 -> 4987138800732 | L64: ='1行'!D64 -> 1 | M64: ='1行'!L64 -> 1 | N64: ='1行'!E64 -> 0
D65: ='1行'!M65 -> 8 | E65: ='1行'!G65 -> 2026/03/25 | F65: ='1行'!N65 -> 08:54:48 | G65: ='1行'!H65 -> 2026/04/01 | H65: ='1行'!J65 -> シロスタゾールOD錠100mg「タカタ」 | I65: ='1行'!O65 -> 100mg/錠 PTP 10錠×10 | J65: ='1行'!K65 -> 高田製薬 | K65: ='1行'!F65 -> 4987120339905 | L65: ='1行'!D65 -> 1 | M65: ='1行'!L65 -> 1 | N65: ='1行'!E65 -> 0
D66: ='1行'!M66 -> 9 | E66: ='1行'!G66 -> 2026/03/25 | F66: ='1行'!N66 -> 08:54:48 | G66: ='1行'!H66 -> 2026/04/01 | H66: ='1行'!J66 -> セディール錠10mg | I66: ='1行'!O66 -> 10mg/錠 バラ 500錠×1瓶 | J66: ='1行'!K66 -> 住友ファーマ | K66: ='1行'!F66 -> 4987116020732 | L66: ='1行'!D66 -> 1 | M66: ='1行'!L66 -> 1 | N66: ='1行'!E66 -> 0
D67: ='1行'!M67 -> 10 | E67: ='1行'!G67 -> 2026/03/25 | F67: ='1行'!N67 -> 08:54:48 | G67: ='1行'!H67 -> 2026/04/01 | H67: ='1行'!J67 -> グラマリール細粒10% | I67: ='1行'!O67 -> 100mg/g バラ 100g×1瓶 | J67: ='1行'!K67 -> 日医工 | K67: ='1行'!F67 -> 4987376245807 | L67: ='1行'!D67 -> 1 | M67: ='1行'!L67 -> 1 | N67: ='1行'!E67 -> 0
D68: ='1行'!M68 -> 11 | E68: ='1行'!G68 -> 2026/03/25 | F68: ='1行'!N68 -> 08:54:48 | G68: ='1行'!H68 -> 2026/04/01 | H68: ='1行'!J68 -> パレプラス輸液 | I68: ='1行'!O68 -> 500mL1キット×20キット | J68: ='1行'!K68 -> 陽進堂 | K68: ='1行'!F68 -> 4987476167108 | L68: ='1行'!D68 -> 3 | M68: ='1行'!L68 -> 3 | N68: ='1行'!E68 -> 0
...

Sheet 1行
C4: 1行 | D4: 未納品数 | E4: 検品数 | F4: 商品コード | G4: 発注日 | H4: 納品指定日 | I4: 品名＋メーカー名 | J4: 品名 | K4: メーカー名 | L4: 発注数 | M4: No | N4: 発注時刻 | O4: 規格容量 | P4: メーカー名
B5: 0 | C5: =_xlfn.CONCAT(OFFSET(元!$B$10,'1行'!B5,0)," ",OFFSET(元!$B$12,'1行'!B5,0)) -> 2026/02/09 2026/02/09 セパゾン錠1 アルフレッサファーマ 2 1 15:44:45 1mg/錠 PTP 10錠×10 4987274132872 2 0 | D5: {=INDEX(_xlfn.FILTERXML("<t><s>" & SUBSTITUTE(C5," ","</s><s>") & "</s></t>","//s[number(.)=number(.)]"), COUNT(_xlfn.FILTERXML("<t><s>" & SUBSTITUTE(C5," ","</s><s>") & "</s></t>","//s[number(.)=number(.)]"))-1)} -> 2 | E5: {=INDEX(_xlfn.FILTERXML("<t><s>" & SUBSTITUTE(C5," ","</s><s>") & "</s></t>","//s[number(.)=number(.)]"), COUNT(_xlfn.FILTERXML("<t><s>" & SUBSTITUTE(C5," ","</s><s>") & "</s></t>","//s[number(.)=number(.)]")))} -> 0 | F5: =TRIM(RIGHT(SUBSTITUTE(C5," "&D5&" "&E5,""),13)) -> 4987274132872 | G5: =LEFT(C5,10) -> 2026/02/09 | H5: =MID(C5,12,10) -> 2026/02/09 | I5: =_xlfn.LET( _xlpm.s, _xlfn.TEXTAFTER(C5, " " & H5 & " "), TRIM(_xlfn.TEXTBEFORE(_xlpm.s, " " & L5 & " ")) ) -> セパゾン錠1 アルフレッサファーマ | J5: =LEFT(I5, LEN(I5) - LEN(K5)) -> セパゾン錠1 | K5: {=_xlfn.LET( _xlpm.s, SUBSTITUTE(SUBSTITUTE(I5," ","")," ",""), _xlpm.dic, SUBSTITUTE(SUBSTITUTE(メーカー!$A$1:$A$100," ","")," ",""), _xlpm.pos, MATCH(TRUE, RIGHT(_xlpm.s, LEN(_xlpm.dic)) = _xlpm.dic, 0), INDEX(メーカー!$A$1:$A$100, _xlpm.pos) )} -> アルフレッサファーマ | L5: {=INDEX(_xlfn.FILTERXML("<t><s>" & SUBSTITUTE(MID(C5,23,999)," ","</s><s>") & "</s></t>","//s[number(.)=number(.)]"),1)} -> 2 | M5: {=INDEX( _xlfn.FILTERXML("<t><s>" & SUBSTITUTE(MID(C5, 22 + LEN(I5) + 1, 999), " ", "</s><s>") & "</s></t>", "//s[number(.)=number(.)]"), 2 )} -> 1 | N5: {=_xlfn.REGEXEXTRACT(C5, "\d{2}:\d{2}:\d{2}")} -> 15:44:45 | O5: =TRIM(SUBSTITUTE(_xlfn.TEXTAFTER(C5, " " & N5 & " "), F5 & " " & D5 & " " & E5, "")) -> 1mg/錠 PTP 10錠×10 | P5: =TRIM(LEFT(_xlfn.TEXTAFTER(C5, I5 & " "), FIND(" ", _xlfn.TEXTAFTER(C5, I5 & " "))-1)) -> 2
B6: =B5+4 -> 4 | C6: =_xlfn.CONCAT(OFFSET(元!$B$10,'1行'!B6,0)," ",OFFSET(元!$B$12,'1行'!B6,0)) -> 2026/03/25 2026/04/01 マーズレンS配合顆粒寿製薬 1 2 08:54:48 バラ 500g×2袋4987071129112 1 0 | D6: {=INDEX(_xlfn.FILTERXML("<t><s>" & SUBSTITUTE(C6," ","</s><s>") & "</s></t>","//s[number(.)=number(.)]"), COUNT(_xlfn.FILTERXML("<t><s>" & SUBSTITUTE(C6," ","</s><s>") & "</s></t>","//s[number(.)=number(.)]"))-1)} -> 1 | E6: {=INDEX(_xlfn.FILTERXML("<t><s>" & SUBSTITUTE(C6," ","</s><s>") & "</s></t>","//s[number(.)=number(.)]"), COUNT(_xlfn.FILTERXML("<t><s>" & SUBSTITUTE(C6," ","</s><s>") & "</s></t>","//s[number(.)=number(.)]")))} -> 0 | F6: =TRIM(RIGHT(SUBSTITUTE(C6," "&D6&" "&E6,""),13)) -> 4987071129112 | G6: =LEFT(C6,10) -> 2026/03/25 | H6: =MID(C6,12,10) -> 2026/04/01 | I6: =_xlfn.LET( _xlpm.s, _xlfn.TEXTAFTER(C6, " " & H6 & " "), TRIM(_xlfn.TEXTBEFORE(_xlpm.s, " " & L6 & " ")) ) -> マーズレンS配合顆粒寿製薬 | J6: =LEFT(I6, LEN(I6) - LEN(K6)) -> マーズレンS配合顆粒 | K6: {=_xlfn.LET( _xlpm.s, SUBSTITUTE(SUBSTITUTE(I6," ","")," ",""), _xlpm.dic, SUBSTITUTE(SUBSTITUTE(メーカー!$A$1:$A$100," ","")," ",""), _xlpm.pos, MATCH(TRUE, RIGHT(_xlpm.s, LEN(_xlpm.dic)) = _xlpm.dic, 0), INDEX(メーカー!$A$1:$A$100, _xlpm.pos) )} -> 寿製薬 | L6: {=INDEX(_xlfn.FILTERXML("<t><s>" & SUBSTITUTE(MID(C6,23,999)," ","</s><s>") & "</s></t>","//s[number(.)=number(.)]"),1)} -> 1 | M6: {=INDEX( _xlfn.FILTERXML("<t><s>" & SUBSTITUTE(MID(C6, 22 + LEN(I6) + 1, 999), " ", "</s><s>") & "</s></t>", "//s[number(.)=number(.)]"), 2 )} -> 2 | N6: {=_xlfn.REGEXEXTRACT(C6, "\d{2}:\d{2}:\d{2}")} -> 08:54:48 | O6: =TRIM(SUBSTITUTE(_xlfn.TEXTAFTER(C6, " " & N6 & " "), F6 & " " & D6 & " " & E6, "")) -> バラ 500g×2袋 | P6: =TRIM(LEFT(_xlfn.TEXTAFTER(C6, I6 & " "), FIND(" ", _xlfn.TEXTAFTER(C6, I6 & " "))-1)) -> 1
B7: =B6+4 -> 8 | C7: =_xlfn.CONCAT(OFFSET(元!$B$10,'1行'!B7,0)," ",OFFSET(元!$B$12,'1行'!B7,0)) -> 2026/03/25 2026/04/01 クエチアピン細粒50%「アメル」共和薬品工業 1 3 08:54:48 50%1g バラ 100g×1瓶4987058197530 1 0 | D7: {=INDEX(_xlfn.FILTERXML("<t><s>" & SUBSTITUTE(C7," ","</s><s>") & "</s></t>","//s[number(.)=number(.)]"), COUNT(_xlfn.FILTERXML("<t><s>" & SUBSTITUTE(C7," ","</s><s>") & "</s></t>","//s[number(.)=number(.)]"))-1)} -> 1 | E7: {=INDEX(_xlfn.FILTERXML("<t><s>" & SUBSTITUTE(C7," ","</s><s>") & "</s></t>","//s[number(.)=number(.)]"), COUNT(_xlfn.FILTERXML("<t><s>" & SUBSTITUTE(C7," ","</s><s>") & "</s></t>","//s[number(.)=number(.)]")))} -> 0 | F7: =TRIM(RIGHT(SUBSTITUTE(C7," "&D7&" "&E7,""),13)) -> 4987058197530 | G7: =LEFT(C7,10) -> 2026/03/25 | H7: =MID(C7,12,10) -> 2026/04/01 | I7: =_xlfn.LET( _xlpm.s, _xlfn.TEXTAFTER(C7, " " & H7 & " "), TRIM(_xlfn.TEXTBEFORE(_xlpm.s, " " & L7 & " ")) ) -> クエチアピン細粒50%「アメル」共和薬品工業 | J7: =LEFT(I7, LEN(I7) - LEN(K7)) -> クエチアピン細粒50%「アメル」 | K7: {=_xlfn.LET( _xlpm.s, SUBSTITUTE(SUBSTITUTE(I7," ","")," ",""), _xlpm.dic, SUBSTITUTE(SUBSTITUTE(メーカー!$A$1:$A$100," ","")," ",""), _xlpm.pos, MATCH(TRUE, RIGHT(_xlpm.s, LEN(_xlpm.dic)) = _xlpm.dic, 0), INDEX(メーカー!$A$1:$A$100, _xlpm.pos) )} -> 共和薬品工業 | L7: {=INDEX(_xlfn.FILTERXML("<t><s>" & SUBSTITUTE(MID(C7,23,999)," ","</s><s>") & "</s></t>","//s[number(.)=number(.)]"),1)} -> 1 | M7: {=INDEX( _xlfn.FILTERXML("<t><s>" & SUBSTITUTE(MID(C7, 22 + LEN(I7) + 1, 999), " ", "</s><s>") & "</s></t>", "//s[number(.)=number(.)]"), 2 )} -> 3 | N7: {=_xlfn.REGEXEXTRACT(C7, "\d{2}:\d{2}:\d{2}")} -> 08:54:48 | O7: =TRIM(SUBSTITUTE(_xlfn.TEXTAFTER(C7, " " & N7 & " "), F7 & " " & D7 & " " & E7, "")) -> 50%1g バラ 100g×1瓶 | P7: =TRIM(LEFT(_xlfn.TEXTAFTER(C7, I7 & " "), FIND(" ", _xlfn.TEXTAFTER(C7, I7 & " "))-1)) -> 1
B8: =B7+4 -> 12 | C8: =_xlfn.CONCAT(OFFSET(元!$B$10,'1行'!B8,0)," ",OFFSET(元!$B$12,'1行'!B8,0)) -> 2026/03/25 2026/04/01 ジプレキサザイディス錠5mg チェプラファーム 1 4 08:54:48 5mg/錠 7錠×50 (ブリスター) 4987994500173 1 0 | D8: {=INDEX(_xlfn.FILTERXML("<t><s>" & SUBSTITUTE(C8," ","</s><s>") & "</s></t>","//s[number(.)=number(.)]"), COUNT(_xlfn.FILTERXML("<t><s>" & SUBSTITUTE(C8," ","</s><s>") & "</s></t>","//s[number(.)=number(.)]"))-1)} -> 1 | E8: {=INDEX(_xlfn.FILTERXML("<t><s>" & SUBSTITUTE(C8," ","</s><s>") & "</s></t>","//s[number(.)=number(.)]"), COUNT(_xlfn.FILTERXML("<t><s>" & SUBSTITUTE(C8," ","</s><s>") & "</s></t>","//s[number(.)=number(.)]")))} -> 0 | F8: =TRIM(RIGHT(SUBSTITUTE(C8," "&D8&" "&E8,""),13)) -> 4987994500173 | G8: =LEFT(C8,10) -> 2026/03/25 | H8: =MID(C8,12,10) -> 2026/04/01 | I8: =_xlfn.LET( _xlpm.s, _xlfn.TEXTAFTER(C8, " " & H8 & " "), TRIM(_xlfn.TEXTBEFORE(_xlpm.s, " " & L8 & " ")) ) -> ジプレキサザイディス錠5mg チェプラファーム | J8: =LEFT(I8, LEN(I8) - LEN(K8)) -> ジプレキサザイディス錠5mg | K8: {=_xlfn.LET( _xlpm.s, SUBSTITUTE(SUBSTITUTE(I8," ","")," ",""), _xlpm.dic, SUBSTITUTE(SUBSTITUTE(メーカー!$A$1:$A$100," ","")," ",""), _xlpm.pos, MATCH(TRUE, RIGHT(_xlpm.s, LEN(_xlpm.dic)) = _xlpm.dic, 0), INDEX(メーカー!$A$1:$A$100, _xlpm.pos) )} -> チェプラファーム | L8: {=INDEX(_xlfn.FILTERXML("<t><s>" & SUBSTITUTE(MID(C8,23,999)," ","</s><s>") & "</s></t>","//s[number(.)=number(.)]"),1)} -> 1 | M8: {=INDEX( _xlfn.FILTERXML("<t><s>" & SUBSTITUTE(MID(C8, 22 + LEN(I8) + 1, 999), " ", "</s><s>") & "</s></t>", "//s[number(.)=number(.)]"), 2 )} -> 4 | N8: {=_xlfn.REGEXEXTRACT(C8, "\d{2}:\d{2}:\d{2}")} -> 08:54:48 | O8: =TRIM(SUBSTITUTE(_xlfn.TEXTAFTER(C8, " " & N8 & " "), F8 & " " & D8 & " " & E8, "")) -> 5mg/錠 7錠×50 (ブリスター) | P8: =TRIM(LEFT(_xlfn.TEXTAFTER(C8, I8 & " "), FIND(" ", _xlfn.TEXTAFTER(C8, I8 & " "))-1)) -> 1
B9: =B8+4 -> 16 | C9: =_xlfn.CONCAT(OFFSET(元!$B$10,'1行'!B9,0)," ",OFFSET(元!$B$12,'1行'!B9,0)) -> 2026/03/25 2026/04/01 ハーフジゴキシンKY錠0.125 トーアエイヨー 1 5 08:54:48 0.125mg/錠 PTP 10錠×10 4987142731114 1 0 | D9: {=INDEX(_xlfn.FILTERXML("<t><s>" & SUBSTITUTE(C9," ","</s><s>") & "</s></t>","//s[number(.)=number(.)]"), COUNT(_xlfn.FILTERXML("<t><s>" & SUBSTITUTE(C9," ","</s><s>") & "</s></t>","//s[number(.)=number(.)]"))-1)} -> 1 | E9: {=INDEX(_xlfn.FILTERXML("<t><s>" & SUBSTITUTE(C9," ","</s><s>") & "</s></t>","//s[number(.)=number(.)]"), COUNT(_xlfn.FILTERXML("<t><s>" & SUBSTITUTE(C9," ","</s><s>") & "</s></t>","//s[number(.)=number(.)]")))} -> 0 | F9: =TRIM(RIGHT(SUBSTITUTE(C9," "&D9&" "&E9,""),13)) -> 4987142731114 | G9: =LEFT(C9,10) -> 2026/03/25 | H9: =MID(C9,12,10) -> 2026/04/01 | I9: =_xlfn.LET( _xlpm.s, _xlfn.TEXTAFTER(C9, " " & H9 & " "), TRIM(_xlfn.TEXTBEFORE(_xlpm.s, " " & L9 & " ")) ) -> ハーフジゴキシンKY錠0.125 トーアエイヨー | J9: =LEFT(I9, LEN(I9) - LEN(K9)) -> ハーフジゴキシンKY錠0.125 | K9: {=_xlfn.LET( _xlpm.s, SUBSTITUTE(SUBSTITUTE(I9," ","")," ",""), _xlpm.dic, SUBSTITUTE(SUBSTITUTE(メーカー!$A$1:$A$100," ","")," ",""), _xlpm.pos, MATCH(TRUE, RIGHT(_xlpm.s, LEN(_xlpm.dic)) = _xlpm.dic, 0), INDEX(メーカー!$A$1:$A$100, _xlpm.pos) )} -> トーアエイヨー | L9: {=INDEX(_xlfn.FILTERXML("<t><s>" & SUBSTITUTE(MID(C9,23,999)," ","</s><s>") & "</s></t>","//s[number(.)=number(.)]"),1)} -> 1 | M9: {=INDEX( _xlfn.FILTERXML("<t><s>" & SUBSTITUTE(MID(C9, 22 + LEN(I9) + 1, 999), " ", "</s><s>") & "</s></t>", "//s[number(.)=number(.)]"), 2 )} -> 5 | N9: {=_xlfn.REGEXEXTRACT(C9, "\d{2}:\d{2}:\d{2}")} -> 08:54:48 | O9: =TRIM(SUBSTITUTE(_xlfn.TEXTAFTER(C9, " " & N9 & " "), F9 & " " & D9 & " " & E9, "")) -> 0.125mg/錠 PTP 10錠×10 | P9: =TRIM(LEFT(_xlfn.TEXTAFTER(C9, I9 & " "), FIND(" ", _xlfn.TEXTAFTER(C9, I9 & " "))-1)) -> 1
B10: =B9+4 -> 20 | C10: =_xlfn.CONCAT(OFFSET(元!$B$10,'1行'!B10,0)," ",OFFSET(元!$B$12,'1行'!B10,0)) -> 2026/03/25 2026/04/01 シクレスト舌下錠10mg Ｍｅｉｊｉ Ｓｅｉｋａ ファル 2 6 08:54:48 10mg/錠 PTP 10錠×10 4987222674232 2 0 | D10: {=INDEX(_xlfn.FILTERXML("<t><s>" & SUBSTITUTE(C10," ","</s><s>") & "</s></t>","//s[number(.)=number(.)]"), COUNT(_xlfn.FILTERXML("<t><s>" & SUBSTITUTE(C10," ","</s><s>") & "</s></t>","//s[number(.)=number(.)]"))-1)} -> 2 | E10: {=INDEX(_xlfn.FILTERXML("<t><s>" & SUBSTITUTE(C10," ","</s><s>") & "</s></t>","//s[number(.)=number(.)]"), COUNT(_xlfn.FILTERXML("<t><s>" & SUBSTITUTE(C10," ","</s><s>") & "</s></t>","//s[number(.)=number(.)]")))} -> 0 | F10: =TRIM(RIGHT(SUBSTITUTE(C10," "&D10&" "&E10,""),13)) -> 4987222674232 | G10: =LEFT(C10,10) -> 2026/03/25 | H10: =MID(C10,12,10) -> 2026/04/01 | I10: =_xlfn.LET( _xlpm.s, _xlfn.TEXTAFTER(C10, " " & H10 & " "), TRIM(_xlfn.TEXTBEFORE(_xlpm.s, " " & L10 & " ")) ) -> シクレスト舌下錠10mg Ｍｅｉｊｉ Ｓｅｉｋａ ファル | J10: =LEFT(I10, LEN(I10) - LEN(K10)) -> シクレスト舌下錠10mg | K10: {=_xlfn.LET( _xlpm.s, SUBSTITUTE(SUBSTITUTE(I10," ","")," ",""), _xlpm.dic, SUBSTITUTE(SUBSTITUTE(メーカー!$A$1:$A$100," ","")," ",""), _xlpm.pos, MATCH(TRUE, RIGHT(_xlpm.s, LEN(_xlpm.dic)) = _xlpm.dic, 0), INDEX(メーカー!$A$1:$A$100, _xlpm.pos) )} -> Ｍｅｉｊｉ Ｓｅｉｋａ ファル | L10: {=INDEX(_xlfn.FILTERXML("<t><s>" & SUBSTITUTE(MID(C10,23,999)," ","</s><s>") & "</s></t>","//s[number(.)=number(.)]"),1)} -> 2 | M10: {=INDEX( _xlfn.FILTERXML("<t><s>" & SUBSTITUTE(MID(C10, 22 + LEN(I10) + 1, 999), " ", "</s><s>") & "</s></t>", "//s[number(.)=number(.)]"), 2 )} -> 6 | N10: {=_xlfn.REGEXEXTRACT(C10, "\d{2}:\d{2}:\d{2}")} -> 08:54:48 | O10: =TRIM(SUBSTITUTE(_xlfn.TEXTAFTER(C10, " " & N10 & " "), F10 & " " & D10 & " " & E10, "")) -> 10mg/錠 PTP 10錠×10 | P10: =TRIM(LEFT(_xlfn.TEXTAFTER(C10, I10 & " "), FIND(" ", _xlfn.TEXTAFTER(C10, I10 & " "))-1)) -> 2
B11: =B10+4 -> 24 | C11: =_xlfn.CONCAT(OFFSET(元!$B$10,'1行'!B11,0)," ",OFFSET(元!$B$12,'1行'!B11,0)) -> 2026/03/25 2026/04/01 シクレスト舌下錠5mg Ｍｅｉｊｉ Ｓｅｉｋａ ファル 2 7 08:54:48 5mg/錠 PTP 10錠×10 4987222673730 2 0 | D11: {=INDEX(_xlfn.FILTERXML("<t><s>" & SUBSTITUTE(C11," ","</s><s>") & "</s></t>","//s[number(.)=number(.)]"), COUNT(_xlfn.FILTERXML("<t><s>" & SUBSTITUTE(C11," ","</s><s>") & "</s></t>","//s[number(.)=number(.)]"))-1)} -> 2 | E11: {=INDEX(_xlfn.FILTERXML("<t><s>" & SUBSTITUTE(C11," ","</s><s>") & "</s></t>","//s[number(.)=number(.)]"), COUNT(_xlfn.FILTERXML("<t><s>" & SUBSTITUTE(C11," ","</s><s>") & "</s></t>","//s[number(.)=number(.)]")))} -> 0 | F11: =TRIM(RIGHT(SUBSTITUTE(C11," "&D11&" "&E11,""),13)) -> 4987222673730 | G11: =LEFT(C11,10) -> 2026/03/25 | H11: =MID(C11,12,10) -> 2026/04/01 | I11: =_xlfn.LET( _xlpm.s, _xlfn.TEXTAFTER(C11, " " & H11 & " "), TRIM(_xlfn.TEXTBEFORE(_xlpm.s, " " & L11 & " ")) ) -> シクレスト舌下錠5mg Ｍｅｉｊｉ Ｓｅｉｋａ ファル | J11: =LEFT(I11, LEN(I11) - LEN(K11)) -> シクレスト舌下錠5mg | K11: {=_xlfn.LET( _xlpm.s, SUBSTITUTE(SUBSTITUTE(I11," ","")," ",""), _xlpm.dic, SUBSTITUTE(SUBSTITUTE(メーカー!$A$1:$A$100," ","")," ",""), _xlpm.pos, MATCH(TRUE, RIGHT(_xlpm.s, LEN(_xlpm.dic)) = _xlpm.dic, 0), INDEX(メーカー!$A$1:$A$100, _xlpm.pos) )} -> Ｍｅｉｊｉ Ｓｅｉｋａ ファル | L11: {=INDEX(_xlfn.FILTERXML("<t><s>" & SUBSTITUTE(MID(C11,23,999)," ","</s><s>") & "</s></t>","//s[number(.)=number(.)]"),1)} -> 2 | M11: {=INDEX( _xlfn.FILTERXML("<t><s>" & SUBSTITUTE(MID(C11, 22 + LEN(I11) + 1, 999), " ", "</s><s>") & "</s></t>", "//s[number(.)=number(.)]"), 2 )} -> 7 | N11: {=_xlfn.REGEXEXTRACT(C11, "\d{2}:\d{2}:\d{2}")} -> 08:54:48 | O11: =TRIM(SUBSTITUTE(_xlfn.TEXTAFTER(C11, " " & N11 & " "), F11 & " " & D11 & " " & E11, "")) -> 5mg/錠 PTP 10錠×10 | P11: =TRIM(LEFT(_xlfn.TEXTAFTER(C11, I11 & " "), FIND(" ", _xlfn.TEXTAFTER(C11, I11 & " "))-1)) -> 2
B12: =B11+4 -> 28 | C12: =_xlfn.CONCAT(OFFSET(元!$B$10,'1行'!B12,0)," ",OFFSET(元!$B$12,'1行'!B12,0)) -> 2026/03/25 2026/04/01 マグミット錠500mg 丸石製薬 1 8 08:54:48 500mg/錠 バラ 500錠×1瓶4987211127398 1 0 | D12: {=INDEX(_xlfn.FILTERXML("<t><s>" & SUBSTITUTE(C12," ","</s><s>") & "</s></t>","//s[number(.)=number(.)]"), COUNT(_xlfn.FILTERXML("<t><s>" & SUBSTITUTE(C12," ","</s><s>") & "</s></t>","//s[number(.)=number(.)]"))-1)} -> 1 | E12: {=INDEX(_xlfn.FILTERXML("<t><s>" & SUBSTITUTE(C12," ","</s><s>") & "</s></t>","//s[number(.)=number(.)]"), COUNT(_xlfn.FILTERXML("<t><s>" & SUBSTITUTE(C12," ","</s><s>") & "</s></t>","//s[number(.)=number(.)]")))} -> 0 | F12: =TRIM(RIGHT(SUBSTITUTE(C12," "&D12&" "&E12,""),13)) -> 4987211127398 | G12: =LEFT(C12,10) -> 2026/03/25 | H12: =MID(C12,12,10) -> 2026/04/01 | I12: =_xlfn.LET( _xlpm.s, _xlfn.TEXTAFTER(C12, " " & H12 & " "), TRIM(_xlfn.TEXTBEFORE(_xlpm.s, " " & L12 & " ")) ) -> マグミット錠500mg 丸石製薬 | J12: =LEFT(I12, LEN(I12) - LEN(K12)) -> マグミット錠500mg | K12: {=_xlfn.LET( _xlpm.s, SUBSTITUTE(SUBSTITUTE(I12," ","")," ",""), _xlpm.dic, SUBSTITUTE(SUBSTITUTE(メーカー!$A$1:$A$100," ","")," ",""), _xlpm.pos, MATCH(TRUE, RIGHT(_xlpm.s, LEN(_xlpm.dic)) = _xlpm.dic, 0), INDEX(メーカー!$A$1:$A$100, _xlpm.pos) )} -> 丸石製薬 | L12: {=INDEX(_xlfn.FILTERXML("<t><s>" & SUBSTITUTE(MID(C12,23,999)," ","</s><s>") & "</s></t>","//s[number(.)=number(.)]"),1)} -> 1 | M12: {=INDEX( _xlfn.FILTERXML("<t><s>" & SUBSTITUTE(MID(C12, 22 + LEN(I12) + 1, 999), " ", "</s><s>") & "</s></t>", "//s[number(.)=number(.)]"), 2 )} -> 8 | N12: {=_xlfn.REGEXEXTRACT(C12, "\d{2}:\d{2}:\d{2}")} -> 08:54:48 | O12: =TRIM(SUBSTITUTE(_xlfn.TEXTAFTER(C12, " " & N12 & " "), F12 & " " & D12 & " " & E12, "")) -> 500mg/錠 バラ 500錠×1瓶 | P12: =TRIM(LEFT(_xlfn.TEXTAFTER(C12, I12 & " "), FIND(" ", _xlfn.TEXTAFTER(C12, I12 & " "))-1)) -> 1
B13: =B12+4 -> 32 | C13: =_xlfn.CONCAT(OFFSET(元!$B$10,'1行'!B13,0)," ",OFFSET(元!$B$12,'1行'!B13,0)) -> 2026/03/25 2026/04/01 クエチアピン錠200mg「アメル」共和薬品工業 1 9 08:54:48 200mg/錠 バラ 500錠×1瓶4987058196557 1 0 | D13: {=INDEX(_xlfn.FILTERXML("<t><s>" & SUBSTITUTE(C13," ","</s><s>") & "</s></t>","//s[number(.)=number(.)]"), COUNT(_xlfn.FILTERXML("<t><s>" & SUBSTITUTE(C13," ","</s><s>") & "</s></t>","//s[number(.)=number(.)]"))-1)} -> 1 | E13: {=INDEX(_xlfn.FILTERXML("<t><s>" & SUBSTITUTE(C13," ","</s><s>") & "</s></t>","//s[number(.)=number(.)]"), COUNT(_xlfn.FILTERXML("<t><s>" & SUBSTITUTE(C13," ","</s><s>") & "</s></t>","//s[number(.)=number(.)]")))} -> 0 | F13: =TRIM(RIGHT(SUBSTITUTE(C13," "&D13&" "&E13,""),13)) -> 4987058196557 | G13: =LEFT(C13,10) -> 2026/03/25 | H13: =MID(C13,12,10) -> 2026/04/01 | I13: =_xlfn.LET( _xlpm.s, _xlfn.TEXTAFTER(C13, " " & H13 & " "), TRIM(_xlfn.TEXTBEFORE(_xlpm.s, " " & L13 & " ")) ) -> クエチアピン錠200mg「アメル」共和薬品工業 | J13: =LEFT(I13, LEN(I13) - LEN(K13)) -> クエチアピン錠200mg「アメル」 | K13: {=_xlfn.LET( _xlpm.s, SUBSTITUTE(SUBSTITUTE(I13," ","")," ",""), _xlpm.dic, SUBSTITUTE(SUBSTITUTE(メーカー!$A$1:$A$100," ","")," ",""), _xlpm.pos, MATCH(TRUE, RIGHT(_xlpm.s, LEN(_xlpm.dic)) = _xlpm.dic, 0), INDEX(メーカー!$A$1:$A$100, _xlpm.pos) )} -> 共和薬品工業 | L13: {=INDEX(_xlfn.FILTERXML("<t><s>" & SUBSTITUTE(MID(C13,23,999)," ","</s><s>") & "</s></t>","//s[number(.)=number(.)]"),1)} -> 1 | M13: {=INDEX( _xlfn.FILTERXML("<t><s>" & SUBSTITUTE(MID(C13, 22 + LEN(I13) + 1, 999), " ", "</s><s>") & "</s></t>", "//s[number(.)=number(.)]"), 2 )} -> 9 | N13: {=_xlfn.REGEXEXTRACT(C13, "\d{2}:\d{2}:\d{2}")} -> 08:54:48 | O13: =TRIM(SUBSTITUTE(_xlfn.TEXTAFTER(C13, " " & N13 & " "), F13 & " " & D13 & " " & E13, "")) -> 200mg/錠 バラ 500錠×1瓶 | P13: =TRIM(LEFT(_xlfn.TEXTAFTER(C13, I13 & " "), FIND(" ", _xlfn.TEXTAFTER(C13, I13 & " "))-1)) -> 1
B14: =B13+4 -> 36 | C14: =_xlfn.CONCAT(OFFSET(元!$B$10,'1行'!B14,0)," ",OFFSET(元!$B$12,'1行'!B14,0)) -> 2026/03/25 2026/04/01 リスパダール細粒1% ヤンセンファーマ 1 10 08:54:48 10mg/g バラ 100g×1瓶4987672393189 1 0 | D14: {=INDEX(_xlfn.FILTERXML("<t><s>" & SUBSTITUTE(C14," ","</s><s>") & "</s></t>","//s[number(.)=number(.)]"), COUNT(_xlfn.FILTERXML("<t><s>" & SUBSTITUTE(C14," ","</s><s>") & "</s></t>","//s[number(.)=number(.)]"))-1)} -> 1 | E14: {=INDEX(_xlfn.FILTERXML("<t><s>" & SUBSTITUTE(C14," ","</s><s>") & "</s></t>","//s[number(.)=number(.)]"), COUNT(_xlfn.FILTERXML("<t><s>" & SUBSTITUTE(C14," ","</s><s>") & "</s></t>","//s[number(.)=number(.)]")))} -> 0 | F14: =TRIM(RIGHT(SUBSTITUTE(C14," "&D14&" "&E14,""),13)) -> 4987672393189 | G14: =LEFT(C14,10) -> 2026/03/25 | H14: =MID(C14,12,10) -> 2026/04/01 | I14: =_xlfn.LET( _xlpm.s, _xlfn.TEXTAFTER(C14, " " & H14 & " "), TRIM(_xlfn.TEXTBEFORE(_xlpm.s, " " & L14 & " ")) ) -> リスパダール細粒1% ヤンセンファーマ | J14: =LEFT(I14, LEN(I14) - LEN(K14)) -> リスパダール細粒1% | K14: {=_xlfn.LET( _xlpm.s, SUBSTITUTE(SUBSTITUTE(I14," ","")," ",""), _xlpm.dic, SUBSTITUTE(SUBSTITUTE(メーカー!$A$1:$A$100," ","")," ",""), _xlpm.pos, MATCH(TRUE, RIGHT(_xlpm.s, LEN(_xlpm.dic)) = _xlpm.dic, 0), INDEX(メーカー!$A$1:$A$100, _xlpm.pos) )} -> ヤンセンファーマ | L14: {=INDEX(_xlfn.FILTERXML("<t><s>" & SUBSTITUTE(MID(C14,23,999)," ","</s><s>") & "</s></t>","//s[number(.)=number(.)]"),1)} -> 1 | M14: {=INDEX( _xlfn.FILTERXML("<t><s>" & SUBSTITUTE(MID(C14, 22 + LEN(I14) + 1, 999), " ", "</s><s>") & "</s></t>", "//s[number(.)=number(.)]"), 2 )} -> 10 | N14: {=_xlfn.REGEXEXTRACT(C14, "\d{2}:\d{2}:\d{2}")} -> 08:54:48 | O14: =TRIM(SUBSTITUTE(_xlfn.TEXTAFTER(C14, " " & N14 & " "), F14 & " " & D14 & " " & E14, "")) -> 10mg/g バラ 100g×1瓶 | P14: =TRIM(LEFT(_xlfn.TEXTAFTER(C14, I14 & " "), FIND(" ", _xlfn.TEXTAFTER(C14, I14 & " "))-1)) -> 1
B15: =B14+4 -> 40 | C15: =_xlfn.CONCAT(OFFSET(元!$B$10,'1行'!B15,0)," ",OFFSET(元!$B$12,'1行'!B15,0)) -> 2026/03/25 2026/04/01 ゼプリオン水懸筋注75mgシリンジ住友ファーマ 1 11 08:54:48 75mg1キット×1キット4987116011143 1 0 | D15: {=INDEX(_xlfn.FILTERXML("<t><s>" & SUBSTITUTE(C15," ","</s><s>") & "</s></t>","//s[number(.)=number(.)]"), COUNT(_xlfn.FILTERXML("<t><s>" & SUBSTITUTE(C15," ","</s><s>") & "</s></t>","//s[number(.)=number(.)]"))-1)} -> 1 | E15: {=INDEX(_xlfn.FILTERXML("<t><s>" & SUBSTITUTE(C15," ","</s><s>") & "</s></t>","//s[number(.)=number(.)]"), COUNT(_xlfn.FILTERXML("<t><s>" & SUBSTITUTE(C15," ","</s><s>") & "</s></t>","//s[number(.)=number(.)]")))} -> 0 | F15: =TRIM(RIGHT(SUBSTITUTE(C15," "&D15&" "&E15,""),13)) -> 4987116011143 | G15: =LEFT(C15,10) -> 2026/03/25 | H15: =MID(C15,12,10) -> 2026/04/01 | I15: =_xlfn.LET( _xlpm.s, _xlfn.TEXTAFTER(C15, " " & H15 & " "), TRIM(_xlfn.TEXTBEFORE(_xlpm.s, " " & L15 & " ")) ) -> ゼプリオン水懸筋注75mgシリンジ住友ファーマ | J15: =LEFT(I15, LEN(I15) - LEN(K15)) -> ゼプリオン水懸筋注75mgシリンジ | K15: {=_xlfn.LET( _xlpm.s, SUBSTITUTE(SUBSTITUTE(I15," ","")," ",""), _xlpm.dic, SUBSTITUTE(SUBSTITUTE(メーカー!$A$1:$A$100," ","")," ",""), _xlpm.pos, MATCH(TRUE, RIGHT(_xlpm.s, LEN(_xlpm.dic)) = _xlpm.dic, 0), INDEX(メーカー!$A$1:$A$100, _xlpm.pos) )} -> 住友ファーマ | L15: {=INDEX(_xlfn.FILTERXML("<t><s>" & SUBSTITUTE(MID(C15,23,999)," ","</s><s>") & "</s></t>","//s[number(.)=number(.)]"),1)} -> 1 | M15: {=INDEX( _xlfn.FILTERXML("<t><s>" & SUBSTITUTE(MID(C15, 22 + LEN(I15) + 1, 999), " ", "</s><s>") & "</s></t>", "//s[number(.)=number(.)]"), 2 )} -> 11 | N15: {=_xlfn.REGEXEXTRACT(C15, "\d{2}:\d{2}:\d{2}")} -> 08:54:48 | O15: =TRIM(SUBSTITUTE(_xlfn.TEXTAFTER(C15, " " & N15 & " "), F15 & " " & D15 & " " & E15, "")) -> 75mg1キット×1キット | P15: =TRIM(LEFT(_xlfn.TEXTAFTER(C15, I15 & " "), FIND(" ", _xlfn.TEXTAFTER(C15, I15 & " "))-1)) -> 1
B16: =B15+4 -> 44 | C16: =_xlfn.CONCAT(OFFSET(元!$B$10,'1行'!B16,0)," ",OFFSET(元!$B$12,'1行'!B16,0)) -> 2026/03/25 2026/04/01 クエチアピン錠100mg「アメル」共和薬品工業 1 12 08:54:48 100mg/錠 バラ 1000錠×1瓶4987058195611 1 0 | D16: {=INDEX(_xlfn.FILTERXML("<t><s>" & SUBSTITUTE(C16," ","</s><s>") & "</s></t>","//s[number(.)=number(.)]"), COUNT(_xlfn.FILTERXML("<t><s>" & SUBSTITUTE(C16," ","</s><s>") & "</s></t>","//s[number(.)=number(.)]"))-1)} -> 1 | E16: {=INDEX(_xlfn.FILTERXML("<t><s>" & SUBSTITUTE(C16," ","</s><s>") & "</s></t>","//s[number(.)=number(.)]"), COUNT(_xlfn.FILTERXML("<t><s>" & SUBSTITUTE(C16," ","</s><s>") & "</s></t>","//s[number(.)=number(.)]")))} -> 0 | F16: =TRIM(RIGHT(SUBSTITUTE(C16," "&D16&" "&E16,""),13)) -> 4987058195611 | G16: =LEFT(C16,10) -> 2026/03/25 | H16: =MID(C16,12,10) -> 2026/04/01 | I16: =_xlfn.LET( _xlpm.s, _xlfn.TEXTAFTER(C16, " " & H16 & " "), TRIM(_xlfn.TEXTBEFORE(_xlpm.s, " " & L16 & " ")) ) -> クエチアピン錠100mg「アメル」共和薬品工業 | J16: =LEFT(I16, LEN(I16) - LEN(K16)) -> クエチアピン錠100mg「アメル」 | K16: {=_xlfn.LET( _xlpm.s, SUBSTITUTE(SUBSTITUTE(I16," ","")," ",""), _xlpm.dic, SUBSTITUTE(SUBSTITUTE(メーカー!$A$1:$A$100," ","")," ",""), _xlpm.pos, MATCH(TRUE, RIGHT(_xlpm.s, LEN(_xlpm.dic)) = _xlpm.dic, 0), INDEX(メーカー!$A$1:$A$100, _xlpm.pos) )} -> 共和薬品工業 | L16: {=INDEX(_xlfn.FILTERXML("<t><s>" & SUBSTITUTE(MID(C16,23,999)," ","</s><s>") & "</s></t>","//s[number(.)=number(.)]"),1)} -> 1 | M16: {=INDEX( _xlfn.FILTERXML("<t><s>" & SUBSTITUTE(MID(C16, 22 + LEN(I16) + 1, 999), " ", "</s><s>") & "</s></t>", "//s[number(.)=number(.)]"), 2 )} -> 12 | N16: {=_xlfn.REGEXEXTRACT(C16, "\d{2}:\d{2}:\d{2}")} -> 08:54:48 | O16: =TRIM(SUBSTITUTE(_xlfn.TEXTAFTER(C16, " " & N16 & " "), F16 & " " & D16 & " " & E16, "")) -> 100mg/錠 バラ 1000錠×1瓶 | P16: =TRIM(LEFT(_xlfn.TEXTAFTER(C16, I16 & " "), FIND(" ", _xlfn.TEXTAFTER(C16, I16 & " "))-1)) -> 1
B17: =B16+4 -> 48 | C17: =_xlfn.CONCAT(OFFSET(元!$B$10,'1行'!B17,0)," ",OFFSET(元!$B$12,'1行'!B17,0)) -> 2026/03/25 2026/04/01 シングレア錠10mg オルガノン 1 13 08:54:48 10mg/錠 PTP 10錠×10 4987954807175 1 0 | D17: {=INDEX(_xlfn.FILTERXML("<t><s>" & SUBSTITUTE(C17," ","</s><s>") & "</s></t>","//s[number(.)=number(.)]"), COUNT(_xlfn.FILTERXML("<t><s>" & SUBSTITUTE(C17," ","</s><s>") & "</s></t>","//s[number(.)=number(.)]"))-1)} -> 1 | E17: {=INDEX(_xlfn.FILTERXML("<t><s>" & SUBSTITUTE(C17," ","</s><s>") & "</s></t>","//s[number(.)=number(.)]"), COUNT(_xlfn.FILTERXML("<t><s>" & SUBSTITUTE(C17," ","</s><s>") & "</s></t>","//s[number(.)=number(.)]")))} -> 0 | F17: =TRIM(RIGHT(SUBSTITUTE(C17," "&D17&" "&E17,""),13)) -> 4987954807175 | G17: =LEFT(C17,10) -> 2026/03/25 | H17: =MID(C17,12,10) -> 2026/04/01 | I17: =_xlfn.LET( _xlpm.s, _xlfn.TEXTAFTER(C17, " " & H17 & " "), TRIM(_xlfn.TEXTBEFORE(_xlpm.s, " " & L17 & " ")) ) -> シングレア錠10mg オルガノン | J17: =LEFT(I17, LEN(I17) - LEN(K17)) -> シングレア錠10mg | K17: {=_xlfn.LET( _xlpm.s, SUBSTITUTE(SUBSTITUTE(I17," ","")," ",""), _xlpm.dic, SUBSTITUTE(SUBSTITUTE(メーカー!$A$1:$A$100," ","")," ",""), _xlpm.pos, MATCH(TRUE, RIGHT(_xlpm.s, LEN(_xlpm.dic)) = _xlpm.dic, 0), INDEX(メーカー!$A$1:$A$100, _xlpm.pos) )} -> オルガノン | L17: {=INDEX(_xlfn.FILTERXML("<t><s>" & SUBSTITUTE(MID(C17,23,999)," ","</s><s>") & "</s></t>","//s[number(.)=number(.)]"),1)} -> 1 | M17: {=INDEX( _xlfn.FILTERXML("<t><s>" & SUBSTITUTE(MID(C17, 22 + LEN(I17) + 1, 999), " ", "</s><s>") & "</s></t>", "//s[number(.)=number(.)]"), 2 )} -> 13 | N17: {=_xlfn.REGEXEXTRACT(C17, "\d{2}:\d{2}:\d{2}")} -> 08:54:48 | O17: =TRIM(SUBSTITUTE(_xlfn.TEXTAFTER(C17, " " & N17 & " "), F17 & " " & D17 & " " & E17, "")) -> 10mg/錠 PTP 10錠×10 | P17: =TRIM(LEFT(_xlfn.TEXTAFTER(C17, I17 & " "), FIND(" ", _xlfn.TEXTAFTER(C17, I17 & " "))-1)) -> 1
... B34: =B33+4 -> 116 | C34: =_xlfn.CONCAT(OFFSET(元!$B$10,'1行'!B34,0)," ",OFFSET(元!$B$12,'1行'!B34,0)) -> 2026/03/25 2026/04/01 セララ錠50mg ヴィアトリス製薬 1 30 08:54:48 50mg/錠 PTP 10錠×10 4987901006200 1 0 | D34: {=INDEX(_xlfn.FILTERXML("<t><s>" & SUBSTITUTE(C34," ","</s><s>") & "</s></t>","//s[number(.)=number(.)]"), COUNT(_xlfn.FILTERXML("<t><s>" & SUBSTITUTE(C34," ","</s><s>") & "</s></t>","//s[number(.)=number(.)]"))-1)} -> 1 | E34: {=INDEX(_xlfn.FILTERXML("<t><s>" & SUBSTITUTE(C34," ","</s><s>") & "</s></t>","//s[number(.)=number(.)]"), COUNT(_xlfn.FILTERXML("<t><s>" & SUBSTITUTE(C34," ","</s><s>") & "</s></t>","//s[number(.)=number(.)]")))} -> 0 | F34: =TRIM(RIGHT(SUBSTITUTE(C34," "&D34&" "&E34,""),13)) -> 4987901006200 | G34: =LEFT(C34,10) -> 2026/03/25 | H34: =MID(C34,12,10) -> 2026/04/01 | I34: =_xlfn.LET( _xlpm.s, _xlfn.TEXTAFTER(C34, " " & H34 & " "), TRIM(_xlfn.TEXTBEFORE(_xlpm.s, " " & L34 & " ")) ) -> セララ錠50mg ヴィアトリス製薬 | J34: =LEFT(I34, LEN(I34) - LEN(K34)) -> セララ錠50mg | K34: {=_xlfn.LET( _xlpm.s, SUBSTITUTE(SUBSTITUTE(I34," ","")," ",""), _xlpm.dic, SUBSTITUTE(SUBSTITUTE(メーカー!$A$1:$A$100," ","")," ",""), _xlpm.pos, MATCH(TRUE, RIGHT(_xlpm.s, LEN(_xlpm.dic)) = _xlpm.dic, 0), INDEX(メーカー!$A$1:$A$100, _xlpm.pos) )} -> ヴィアトリス製薬 | L34: {=INDEX(_xlfn.FILTERXML("<t><s>" & SUBSTITUTE(MID(C34,23,999)," ","</s><s>") & "</s></t>","//s[number(.)=number(.)]"),1)} -> 1 | M34: {=INDEX( _xlfn.FILTERXML("<t><s>" & SUBSTITUTE(MID(C34, 22 + LEN(I34) + 1, 999), " ", "</s><s>") & "</s></t>", "//s[number(.)=number(.)]"), 2 )} -> 30 | N34: {=_xlfn.REGEXEXTRACT(C34, "\d{2}:\d{2}:\d{2}")} -> 08:54:48 | O34: =TRIM(SUBSTITUTE(_xlfn.TEXTAFTER(C34, " " & N34 & " "), F34 & " " & D34 & " " & E34, "")) -> 50mg/錠 PTP 10錠×10 | P34: =TRIM(LEFT(_xlfn.TEXTAFTER(C34, I34 & " "), FIND(" ", _xlfn.TEXTAFTER(C34, I34 & " "))-1)) -> 1
B35: =B34+20 -> 136 | C35: =_xlfn.CONCAT(OFFSET(元!$B$10,'1行'!B35,0)," ",OFFSET(元!$B$12,'1行'!B35,0)) -> 2026/03/25 2026/04/01 オルメテックOD錠10mg 第一三共 1 31 08:54:48 10mg/錠 PTP 10錠×10 4987081103119 1 0 | D35: {=INDEX(_xlfn.FILTERXML("<t><s>" & SUBSTITUTE(C35," ","</s><s>") & "</s></t>","//s[number(.)=number(.)]"), COUNT(_xlfn.FILTERXML("<t><s>" & SUBSTITUTE(C35," ","</s><s>") & "</s></t>","//s[number(.)=number(.)]"))-1)} -> 1 | E35: {=INDEX(_xlfn.FILTERXML("<t><s>" & SUBSTITUTE(C35," ","</s><s>") & "</s></t>","//s[number(.)=number(.)]"), COUNT(_xlfn.FILTERXML("<t><s>" & SUBSTITUTE(C35," ","</s><s>") & "</s></t>","//s[number(.)=number(.)]")))} -> 0 | F35: =TRIM(RIGHT(SUBSTITUTE(C35," "&D35&" "&E35,""),13)) -> 4987081103119 | G35: =LEFT(C35,10) -> 2026/03/25 | H35: =MID(C35,12,10) -> 2026/04/01 | I35: =_xlfn.LET( _xlpm.s, _xlfn.TEXTAFTER(C35, " " & H35 & " "), TRIM(_xlfn.TEXTBEFORE(_xlpm.s, " " & L35 & " ")) ) -> オルメテックOD錠10mg 第一三共 | J35: =LEFT(I35, LEN(I35) - LEN(K35)) -> オルメテックOD錠10mg | K35: {=_xlfn.LET( _xlpm.s, SUBSTITUTE(SUBSTITUTE(I35," ","")," ",""), _xlpm.dic, SUBSTITUTE(SUBSTITUTE(メーカー!$A$1:$A$100," ","")," ",""), _xlpm.pos, MATCH(TRUE, RIGHT(_xlpm.s, LEN(_xlpm.dic)) = _xlpm.dic, 0), INDEX(メーカー!$A$1:$A$100, _xlpm.pos) )} -> 第一三共 | L35: {=INDEX(_xlfn.FILTERXML("<t><s>" & SUBSTITUTE(MID(C35,23,999)," ","</s><s>") & "</s></t>","//s[number(.)=number(.)]"),1)} -> 1 | M35: {=INDEX( _xlfn.FILTERXML("<t><s>" & SUBSTITUTE(MID(C35, 22 + LEN(I35) + 1, 999), " ", "</s><s>") & "</s></t>", "//s[number(.)=number(.)]"), 2 )} -> 31 | N35: {=_xlfn.REGEXEXTRACT(C35, "\d{2}:\d{2}:\d{2}")} -> 08:54:48 | O35: =TRIM(SUBSTITUTE(_xlfn.TEXTAFTER(C35, " " & N35 & " "), F35 & " " & D35 & " " & E35, "")) -> 10mg/錠 PTP 10錠×10 | P35: =TRIM(LEFT(_xlfn.TEXTAFTER(C35, I35 & " "), FIND(" ", _xlfn.TEXTAFTER(C35, I35 & " "))-1)) -> 1
B36: =B35+4 -> 140 | C36: =_xlfn.CONCAT(OFFSET(元!$B$10,'1行'!B36,0)," ",OFFSET(元!$B$12,'1行'!B36,0)) -> 2026/03/25 2026/04/01 ビプレッソ徐放錠150mg 共和薬品工業 1 32 08:54:48 150mg/錠 PTP 10錠×10 4987058784280 1 0 | D36: {=INDEX(_xlfn.FILTERXML("<t><s>" & SUBSTITUTE(C36," ","</s><s>") & "</s></t>","//s[number(.)=number(.)]"), COUNT(_xlfn.FILTERXML("<t><s>" & SUBSTITUTE(C36," ","</s><s>") & "</s></t>","//s[number(.)=number(.)]"))-1)} -> 1 | E36: {=INDEX(_xlfn.FILTERXML("<t><s>" & SUBSTITUTE(C36," ","</s><s>") & "</s></t>","//s[number(.)=number(.)]"), COUNT(_xlfn.FILTERXML("<t><s>" & SUBSTITUTE(C36," ","</s><s>") & "</s></t>","//s[number(.)=number(.)]")))} -> 0 | F36: =TRIM(RIGHT(SUBSTITUTE(C36," "&D36&" "&E36,""),13)) -> 4987058784280 | G36: =LEFT(C36,10) -> 2026/03/25 | H36: =MID(C36,12,10) -> 2026/04/01 | I36: =_xlfn.LET( _xlpm.s, _xlfn.TEXTAFTER(C36, " " & H36 & " "), TRIM(_xlfn.TEXTBEFORE(_xlpm.s, " " & L36 & " ")) ) -> ビプレッソ徐放錠150mg 共和薬品工業 | J36: =LEFT(I36, LEN(I36) - LEN(K36)) -> ビプレッソ徐放錠150mg | K36: {=_xlfn.LET( _xlpm.s, SUBSTITUTE(SUBSTITUTE(I36," ","")," ",""), _xlpm.dic, SUBSTITUTE(SUBSTITUTE(メーカー!$A$1:$A$100," ","")," ",""), _xlpm.pos, MATCH(TRUE, RIGHT(_xlpm.s, LEN(_xlpm.dic)) = _xlpm.dic, 0), INDEX(メーカー!$A$1:$A$100, _xlpm.pos) )} -> 共和薬品工業 | L36: {=INDEX(_xlfn.FILTERXML("<t><s>" & SUBSTITUTE(MID(C36,23,999)," ","</s><s>") & "</s></t>","//s[number(.)=number(.)]"),1)} -> 1 | M36: {=INDEX( _xlfn.FILTERXML("<t><s>" & SUBSTITUTE(MID(C36, 22 + LEN(I36) + 1, 999), " ", "</s><s>") & "</s></t>", "//s[number(.)=number(.)]"), 2 )} -> 32 | N36: {=_xlfn.REGEXEXTRACT(C36, "\d{2}:\d{2}:\d{2}")} -> 08:54:48 | O36: =TRIM(SUBSTITUTE(_xlfn.TEXTAFTER(C36, " " & N36 & " "), F36 & " " & D36 & " " & E36, "")) -> 150mg/錠 PTP 10錠×10 | P36: =TRIM(LEFT(_xlfn.TEXTAFTER(C36, I36 & " "), FIND(" ", _xlfn.TEXTAFTER(C36, I36 & " "))-1)) -> 1
B37: =B36+4 -> 144 | C37: =_xlfn.CONCAT(OFFSET(元!$B$10,'1行'!B37,0)," ",OFFSET(元!$B$12,'1行'!B37,0)) -> 2026/03/25 2026/04/01 ビソノテープ2mg トーアエイヨー 1 33 08:54:48 2mg1枚×70袋 (3cm×3cm) 4987142381203 1 0 | D37: {=INDEX(_xlfn.FILTERXML("<t><s>" & SUBSTITUTE(C37," ","</s><s>") & "</s></t>","//s[number(.)=number(.)]"), COUNT(_xlfn.FILTERXML("<t><s>" & SUBSTITUTE(C37," ","</s><s>") & "</s></t>","//s[number(.)=number(.)]"))-1)} -> 1 | E37: {=INDEX(_xlfn.FILTERXML("<t><s>" & SUBSTITUTE(C37," ","</s><s>") & "</s></t>","//s[number(.)=number(.)]"), COUNT(_xlfn.FILTERXML("<t><s>" & SUBSTITUTE(C37," ","</s><s>") & "</s></t>","//s[number(.)=number(.)]")))} -> 0 | F37: =TRIM(RIGHT(SUBSTITUTE(C37," "&D37&" "&E37,""),13)) -> 4987142381203 | G37: =LEFT(C37,10) -> 2026/03/25 | H37: =MID(C37,12,10) -> 2026/04/01 | I37: =_xlfn.LET( _xlpm.s, _xlfn.TEXTAFTER(C37, " " & H37 & " "), TRIM(_xlfn.TEXTBEFORE(_xlpm.s, " " & L37 & " ")) ) -> ビソノテープ2mg トーアエイヨー | J37: =LEFT(I37, LEN(I37) - LEN(K37)) -> ビソノテープ2mg | K37: {=_xlfn.LET( _xlpm.s, SUBSTITUTE(SUBSTITUTE(I37," ","")," ",""), _xlpm.dic, SUBSTITUTE(SUBSTITUTE(メーカー!$A$1:$A$100," ","")," ",""), _xlpm.pos, MATCH(TRUE, RIGHT(_xlpm.s, LEN(_xlpm.dic)) = _xlpm.dic, 0), INDEX(メーカー!$A$1:$A$100, _xlpm.pos) )} -> トーアエイヨー | L37: {=INDEX(_xlfn.FILTERXML("<t><s>" & SUBSTITUTE(MID(C37,23,999)," ","</s><s>") & "</s></t>","//s[number(.)=number(.)]"),1)} -> 1 | M37: {=INDEX( _xlfn.FILTERXML("<t><s>" & SUBSTITUTE(MID(C37, 22 + LEN(I37) + 1, 999), " ", "</s><s>") & "</s></t>", "//s[number(.)=number(.)]"), 2 )} -> 33 | N37: {=_xlfn.REGEXEXTRACT(C37, "\d{2}:\d{2}:\d{2}")} -> 08:54:48 | O37: =TRIM(SUBSTITUTE(_xlfn.TEXTAFTER(C37, " " & N37 & " "), F37 & " " & D37 & " " & E37, "")) -> 2mg1枚×70袋 (3cm×3cm) | P37: =TRIM(LEFT(_xlfn.TEXTAFTER(C37, I37 & " "), FIND(" ", _xlfn.TEXTAFTER(C37, I37 & " "))-1)) -> 1
B38: =B37+4 -> 148 | C38: =_xlfn.CONCAT(OFFSET(元!$B$10,'1行'!B38,0)," ",OFFSET(元!$B$12,'1行'!B38,0)) -> 2026/03/25 2026/04/01 ビソノテープ4mg トーアエイヨー 1 34 08:54:48 4mg1枚×70袋 (4.25cm×4.25cm) 4987142381401 1 0 | D38: {=INDEX(_xlfn.FILTERXML("<t><s>" & SUBSTITUTE(C38," ","</s><s>") & "</s></t>","//s[number(.)=number(.)]"), COUNT(_xlfn.FILTERXML("<t><s>" & SUBSTITUTE(C38," ","</s><s>") & "</s></t>","//s[number(.)=number(.)]"))-1)} -> 1 | E38: {=INDEX(_xlfn.FILTERXML("<t><s>" & SUBSTITUTE(C38," ","</s><s>") & "</s></t>","//s[number(.)=number(.)]"), COUNT(_xlfn.FILTERXML("<t><s>" & SUBSTITUTE(C38," ","</s><s>") & "</s></t>","//s[number(.)=number(.)]")))} -> 0 | F38: =TRIM(RIGHT(SUBSTITUTE(C38," "&D38&" "&E38,""),13)) -> 4987142381401 | G38: =LEFT(C38,10) -> 2026/03/25 | H38: =MID(C38,12,10) -> 2026/04/01 | I38: =_xlfn.LET( _xlpm.s, _xlfn.TEXTAFTER(C38, " " & H38 & " "), TRIM(_xlfn.TEXTBEFORE(_xlpm.s, " " & L38 & " ")) ) -> ビソノテープ4mg トーアエイヨー | J38: =LEFT(I38, LEN(I38) - LEN(K38)) -> ビソノテープ4mg | K38: {=_xlfn.LET( _xlpm.s, SUBSTITUTE(SUBSTITUTE(I38," ","")," ",""), _xlpm.dic, SUBSTITUTE(SUBSTITUTE(メーカー!$A$1:$A$100," ","")," ",""), _xlpm.pos, MATCH(TRUE, RIGHT(_xlpm.s, LEN(_xlpm.dic)) = _xlpm.dic, 0), INDEX(メーカー!$A$1:$A$100, _xlpm.pos) )} -> トーアエイヨー | L38: {=INDEX(_xlfn.FILTERXML("<t><s>" & SUBSTITUTE(MID(C38,23,999)," ","</s><s>") & "</s></t>","//s[number(.)=number(.)]"),1)} -> 1 | M38: {=INDEX( _xlfn.FILTERXML("<t><s>" & SUBSTITUTE(MID(C38, 22 + LEN(I38) + 1, 999), " ", "</s><s>") & "</s></t>", "//s[number(.)=number(.)]"), 2 )} -> 34 | N38: {=_xlfn.REGEXEXTRACT(C38, "\d{2}:\d{2}:\d{2}")} -> 08:54:48 | O38: =TRIM(SUBSTITUTE(_xlfn.TEXTAFTER(C38, " " & N38 & " "), F38 & " " & D38 & " " & E38, "")) -> 4mg1枚×70袋 (4.25cm×4.25cm) | P38: =TRIM(LEFT(_xlfn.TEXTAFTER(C38, I38 & " "), FIND(" ", _xlfn.TEXTAFTER(C38, I38 & " "))-1)) -> 1
B39: =B38+4 -> 152 | C39: =_xlfn.CONCAT(OFFSET(元!$B$10,'1行'!B39,0)," ",OFFSET(元!$B$12,'1行'!B39,0)) -> 2026/03/25 2026/04/01 フルニトラゼパム錠1mg「アメル」共和薬品工業 1 35 08:54:48 1mg/錠 PTP 10錠×100 4987058565117 1 0 | D39: {=INDEX(_xlfn.FILTERXML("<t><s>" & SUBSTITUTE(C39," ","</s><s>") & "</s></t>","//s[number(.)=number(.)]"), COUNT(_xlfn.FILTERXML("<t><s>" & SUBSTITUTE(C39," ","</s><s>") & "</s></t>","//s[number(.)=number(.)]"))-1)} -> 1 | E39: {=INDEX(_xlfn.FILTERXML("<t><s>" & SUBSTITUTE(C39," ","</s><s>") & "</s></t>","//s[number(.)=number(.)]"), COUNT(_xlfn.FILTERXML("<t><s>" & SUBSTITUTE(C39," ","</s><s>") & "</s></t>","//s[number(.)=number(.)]")))} -> 0 | F39: =TRIM(RIGHT(SUBSTITUTE(C39," "&D39&" "&E39,""),13)) -> 4987058565117 | G39: =LEFT(C39,10) -> 2026/03/25 | H39: =MID(C39,12,10) -> 2026/04/01 | I39: =_xlfn.LET( _xlpm.s, _xlfn.TEXTAFTER(C39, " " & H39 & " "), TRIM(_xlfn.TEXTBEFORE(_xlpm.s, " " & L39 & " ")) ) -> フルニトラゼパム錠1mg「アメル」共和薬品工業 | J39: =LEFT(I39, LEN(I39) - LEN(K39)) -> フルニトラゼパム錠1mg「アメル」 | K39: {=_xlfn.LET( _xlpm.s, SUBSTITUTE(SUBSTITUTE(I39," ","")," ",""), _xlpm.dic, SUBSTITUTE(SUBSTITUTE(メーカー!$A$1:$A$100," ","")," ",""), _xlpm.pos, MATCH(TRUE, RIGHT(_xlpm.s, LEN(_xlpm.dic)) = _xlpm.dic, 0), INDEX(メーカー!$A$1:$A$100, _xlpm.pos) )} -> 共和薬品工業 | L39: {=INDEX(_xlfn.FILTERXML("<t><s>" & SUBSTITUTE(MID(C39,23,999)," ","</s><s>") & "</s></t>","//s[number(.)=number(.)]"),1)} -> 1 | M39: {=INDEX( _xlfn.FILTERXML("<t><s>" & SUBSTITUTE(MID(C39, 22 + LEN(I39) + 1, 999), " ", "</s><s>") & "</s></t>", "//s[number(.)=number(.)]"), 2 )} -> 35 | N39: {=_xlfn.REGEXEXTRACT(C39, "\d{2}:\d{2}:\d{2}")} -> 08:54:48 | O39: =TRIM(SUBSTITUTE(_xlfn.TEXTAFTER(C39, " " & N39 & " "), F39 & " " & D39 & " " & E39, "")) -> 1mg/錠 PTP 10錠×100 | P39: =TRIM(LEFT(_xlfn.TEXTAFTER(C39, I39 & " "), FIND(" ", _xlfn.TEXTAFTER(C39, I39 & " "))-1)) -> 1
B40: =B39+4 -> 156 | C40: =_xlfn.CONCAT(OFFSET(元!$B$10,'1行'!B40,0)," ",OFFSET(元!$B$12,'1行'!B40,0)) -> 2026/03/25 2026/04/01 フルニトラゼパム錠2mg「アメル」共和薬品工業 1 36 08:54:48 2mg/錠 PTP 10錠×100 4987058566114 1 0 | D40: {=INDEX(_xlfn.FILTERXML("<t><s>" & SUBSTITUTE(C40," ","</s><s>") & "</s></t>","//s[number(.)=number(.)]"), COUNT(_xlfn.FILTERXML("<t><s>" & SUBSTITUTE(C40," ","</s><s>") & "</s></t>","//s[number(.)=number(.)]"))-1)} -> 1 | E40: {=INDEX(_xlfn.FILTERXML("<t><s>" & SUBSTITUTE(C40," ","</s><s>") & "</s></t>","//s[number(.)=number(.)]"), COUNT(_xlfn.FILTERXML("<t><s>" & SUBSTITUTE(C40," ","</s><s>") & "</s></t>","//s[number(.)=number(.)]")))} -> 0 | F40: =TRIM(RIGHT(SUBSTITUTE(C40," "&D40&" "&E40,""),13)) -> 4987058566114 | G40: =LEFT(C40,10) -> 2026/03/25 | H40: =MID(C40,12,10) -> 2026/04/01 | I40: =_xlfn.LET( _xlpm.s, _xlfn.TEXTAFTER(C40, " " & H40 & " "), TRIM(_xlfn.TEXTBEFORE(_xlpm.s, " " & L40 & " ")) ) -> フルニトラゼパム錠2mg「アメル」共和薬品工業 | J40: =LEFT(I40, LEN(I40) - LEN(K40)) -> フルニトラゼパム錠2mg「アメル」 | K40: {=_xlfn.LET( _xlpm.s, SUBSTITUTE(SUBSTITUTE(I40," ","")," ",""), _xlpm.dic, SUBSTITUTE(SUBSTITUTE(メーカー!$A$1:$A$100," ","")," ",""), _xlpm.pos, MATCH(TRUE, RIGHT(_xlpm.s, LEN(_xlpm.dic)) = _xlpm.dic, 0), INDEX(メーカー!$A$1:$A$100, _xlpm.pos) )} -> 共和薬品工業 | L40: {=INDEX(_xlfn.FILTERXML("<t><s>" & SUBSTITUTE(MID(C40,23,999)," ","</s><s>") & "</s></t>","//s[number(.)=number(.)]"),1)} -> 1 | M40: {=INDEX( _xlfn.FILTERXML("<t><s>" & SUBSTITUTE(MID(C40, 22 + LEN(I40) + 1, 999), " ", "</s><s>") & "</s></t>", "//s[number(.)=number(.)]"), 2 )} -> 36 | N40: {=_xlfn.REGEXEXTRACT(C40, "\d{2}:\d{2}:\d{2}")} -> 08:54:48 | O40: =TRIM(SUBSTITUTE(_xlfn.TEXTAFTER(C40, " " & N40 & " "), F40 & " " & D40 & " " & E40, "")) -> 2mg/錠 PTP 10錠×100 | P40: =TRIM(LEFT(_xlfn.TEXTAFTER(C40, I40 & " "), FIND(" ", _xlfn.TEXTAFTER(C40, I40 & " "))-1)) -> 1
B41: =B40+4 -> 160 | C41: =_xlfn.CONCAT(OFFSET(元!$B$10,'1行'!B41,0)," ",OFFSET(元!$B$12,'1行'!B41,0)) -> 2026/03/25 2026/04/01 セレスタミン配合錠高田製薬 1 37 08:54:48 バラ 100錠×1瓶4987120246012 1 0 | D41: {=INDEX(_xlfn.FILTERXML("<t><s>" & SUBSTITUTE(C41," ","</s><s>") & "</s></t>","//s[number(.)=number(.)]"), COUNT(_xlfn.FILTERXML("<t><s>" & SUBSTITUTE(C41," ","</s><s>") & "</s></t>","//s[number(.)=number(.)]"))-1)} -> 1 | E41: {=INDEX(_xlfn.FILTERXML("<t><s>" & SUBSTITUTE(C41," ","</s><s>") & "</s></t>","//s[number(.)=number(.)]"), COUNT(_xlfn.FILTERXML("<t><s>" & SUBSTITUTE(C41," ","</s><s>") & "</s></t>","//s[number(.)=number(.)]")))} -> 0 | F41: =TRIM(RIGHT(SUBSTITUTE(C41," "&D41&" "&E41,""),13)) -> 4987120246012 | G41: =LEFT(C41,10) -> 2026/03/25 | H41: =MID(C41,12,10) -> 2026/04/01 | I41: =_xlfn.LET( _xlpm.s, _xlfn.TEXTAFTER(C41, " " & H41 & " "), TRIM(_xlfn.TEXTBEFORE(_xlpm.s, " " & L41 & " ")) ) -> セレスタミン配合錠高田製薬 | J41: =LEFT(I41, LEN(I41) - LEN(K41)) -> セレスタミン配合錠 | K41: {=_xlfn.LET( _xlpm.s, SUBSTITUTE(SUBSTITUTE(I41," ","")," ",""), _xlpm.dic, SUBSTITUTE(SUBSTITUTE(メーカー!$A$1:$A$100," ","")," ",""), _xlpm.pos, MATCH(TRUE, RIGHT(_xlpm.s, LEN(_xlpm.dic)) = _xlpm.dic, 0), INDEX(メーカー!$A$1:$A$100, _xlpm.pos) )} -> 高田製薬 | L41: {=INDEX(_xlfn.FILTERXML("<t><s>" & SUBSTITUTE(MID(C41,23,999)," ","</s><s>") & "</s></t>","//s[number(.)=number(.)]"),1)} -> 1 | M41: {=INDEX( _xlfn.FILTERXML("<t><s>" & SUBSTITUTE(MID(C41, 22 + LEN(I41) + 1, 999), " ", "</s><s>") & "</s></t>", "//s[number(.)=number(.)]"), 2 )} -> 37 | N41: {=_xlfn.REGEXEXTRACT(C41, "\d{2}:\d{2}:\d{2}")} -> 08:54:48 | O41: =TRIM(SUBSTITUTE(_xlfn.TEXTAFTER(C41, " " & N41 & " "), F41 & " " & D41 & " " & E41, "")) -> バラ 100錠×1瓶 | P41: =TRIM(LEFT(_xlfn.TEXTAFTER(C41, I41 & " "), FIND(" ", _xlfn.TEXTAFTER(C41, I41 & " "))-1)) -> 1
B42: =B41+4 -> 164 | C42: =_xlfn.CONCAT(OFFSET(元!$B$10,'1行'!B42,0)," ",OFFSET(元!$B$12,'1行'!B42,0)) -> 2026/03/25 2026/04/01 フルニトラゼパム錠1mg「アメル」共和薬品工業 1 38 08:54:48 1mg/錠 バラ 1000錠×1瓶4987058565612 1 0 | D42: {=INDEX(_xlfn.FILTERXML("<t><s>" & SUBSTITUTE(C42," ","</s><s>") & "</s></t>","//s[number(.)=number(.)]"), COUNT(_xlfn.FILTERXML("<t><s>" & SUBSTITUTE(C42," ","</s><s>") & "</s></t>","//s[number(.)=number(.)]"))-1)} -> 1 | E42: {=INDEX(_xlfn.FILTERXML("<t><s>" & SUBSTITUTE(C42," ","</s><s>") & "</s></t>","//s[number(.)=number(.)]"), COUNT(_xlfn.FILTERXML("<t><s>" & SUBSTITUTE(C42," ","</s><s>") & "</s></t>","//s[number(.)=number(.)]")))} -> 0 | F42: =TRIM(RIGHT(SUBSTITUTE(C42," "&D42&" "&E42,""),13)) -> 4987058565612 | G42: =LEFT(C42,10) -> 2026/03/25 | H42: =MID(C42,12,10) -> 2026/04/01 | I42: =_xlfn.LET( _xlpm.s, _xlfn.TEXTAFTER(C42, " " & H42 & " "), TRIM(_xlfn.TEXTBEFORE(_xlpm.s, " " & L42 & " ")) ) -> フルニトラゼパム錠1mg「アメル」共和薬品工業 | J42: =LEFT(I42, LEN(I42) - LEN(K42)) -> フルニトラゼパム錠1mg「アメル」 | K42: {=_xlfn.LET( _xlpm.s, SUBSTITUTE(SUBSTITUTE(I42," ","")," ",""), _xlpm.dic, SUBSTITUTE(SUBSTITUTE(メーカー!$A$1:$A$100," ","")," ",""), _xlpm.pos, MATCH(TRUE, RIGHT(_xlpm.s, LEN(_xlpm.dic)) = _xlpm.dic, 0), INDEX(メーカー!$A$1:$A$100, _xlpm.pos) )} -> 共和薬品工業 | L42: {=INDEX(_xlfn.FILTERXML("<t><s>" & SUBSTITUTE(MID(C42,23,999)," ","</s><s>") & "</s></t>","//s[number(.)=number(.)]"),1)} -> 1 | M42: {=INDEX( _xlfn.FILTERXML("<t><s>" & SUBSTITUTE(MID(C42, 22 + LEN(I42) + 1, 999), " ", "</s><s>") & "</s></t>", "//s[number(.)=number(.)]"), 2 )} -> 38 | N42: {=_xlfn.REGEXEXTRACT(C42, "\d{2}:\d{2}:\d{2}")} -> 08:54:48 | O42: =TRIM(SUBSTITUTE(_xlfn.TEXTAFTER(C42, " " & N42 & " "), F42 & " " & D42 & " " & E42, "")) -> 1mg/錠 バラ 1000錠×1瓶 | P42: =TRIM(LEFT(_xlfn.TEXTAFTER(C42, I42 & " "), FIND(" ", _xlfn.TEXTAFTER(C42, I42 & " "))-1)) -> 1
B43: =B42+4 -> 168 | C43: =_xlfn.CONCAT(OFFSET(元!$B$10,'1行'!B43,0)," ",OFFSET(元!$B$12,'1行'!B43,0)) -> 2026/03/25 2026/04/01 フルニトラゼパム錠2mg「アメル」共和薬品工業 1 39 08:54:48 2mg/錠 バラ 1000錠×1瓶4987058566619 1 0 | D43: {=INDEX(_xlfn.FILTERXML("<t><s>" & SUBSTITUTE(C43," ","</s><s>") & "</s></t>","//s[number(.)=number(.)]"), COUNT(_xlfn.FILTERXML("<t><s>" & SUBSTITUTE(C43," ","</s><s>") & "</s></t>","//s[number(.)=number(.)]"))-1)} -> 1 | E43: {=INDEX(_xlfn.FILTERXML("<t><s>" & SUBSTITUTE(C43," ","</s><s>") & "</s></t>","//s[number(.)=number(.)]"), COUNT(_xlfn.FILTERXML("<t><s>" & SUBSTITUTE(C43," ","</s><s>") & "</s></t>","//s[number(.)=number(.)]")))} -> 0 | F43: =TRIM(RIGHT(SUBSTITUTE(C43," "&D43&" "&E43,""),13)) -> 4987058566619 | G43: =LEFT(C43,10) -> 2026/03/25 | H43: =MID(C43,12,10) -> 2026/04/01 | I43: =_xlfn.LET( _xlpm.s, _xlfn.TEXTAFTER(C43, " " & H43 & " "), TRIM(_xlfn.TEXTBEFORE(_xlpm.s, " " & L43 & " ")) ) -> フルニトラゼパム錠2mg「アメル」共和薬品工業 | J43: =LEFT(I43, LEN(I43) - LEN(K43)) -> フルニトラゼパム錠2mg「アメル」 | K43: {=_xlfn.LET( _xlpm.s, SUBSTITUTE(SUBSTITUTE(I43," ","")," ",""), _xlpm.dic, SUBSTITUTE(SUBSTITUTE(メーカー!$A$1:$A$100," ","")," ",""), _xlpm.pos, MATCH(TRUE, RIGHT(_xlpm.s, LEN(_xlpm.dic)) = _xlpm.dic, 0), INDEX(メーカー!$A$1:$A$100, _xlpm.pos) )} -> 共和薬品工業 | L43: {=INDEX(_xlfn.FILTERXML("<t><s>" & SUBSTITUTE(MID(C43,23,999)," ","</s><s>") & "</s></t>","//s[number(.)=number(.)]"),1)} -> 1 | M43: {=INDEX( _xlfn.FILTERXML("<t><s>" & SUBSTITUTE(MID(C43, 22 + LEN(I43) + 1, 999), " ", "</s><s>") & "</s></t>", "//s[number(.)=number(.)]"), 2 )} -> 39 | N43: {=_xlfn.REGEXEXTRACT(C43, "\d{2}:\d{2}:\d{2}")} -> 08:54:48 | O43: =TRIM(SUBSTITUTE(_xlfn.TEXTAFTER(C43, " " & N43 & " "), F43 & " " & D43 & " " & E43, "")) -> 2mg/錠 バラ 1000錠×1瓶 | P43: =TRIM(LEFT(_xlfn.TEXTAFTER(C43, I43 & " "), FIND(" ", _xlfn.TEXTAFTER(C43, I43 & " "))-1)) -> 1
B44: =B43+4 -> 172 | C44: =_xlfn.CONCAT(OFFSET(元!$B$10,'1行'!B44,0)," ",OFFSET(元!$B$12,'1行'!B44,0)) -> 2026/03/25 2026/04/01 クエチアピン錠25mg「アメル」共和薬品工業 2 40 08:54:48 25mg/錠 バラ 1000錠×1瓶4987058193617 2 0 | D44: {=INDEX(_xlfn.FILTERXML("<t><s>" & SUBSTITUTE(C44," ","</s><s>") & "</s></t>","//s[number(.)=number(.)]"), COUNT(_xlfn.FILTERXML("<t><s>" & SUBSTITUTE(C44," ","</s><s>") & "</s></t>","//s[number(.)=number(.)]"))-1)} -> 2 | E44: {=INDEX(_xlfn.FILTERXML("<t><s>" & SUBSTITUTE(C44," ","</s><s>") & "</s></t>","//s[number(.)=number(.)]"), COUNT(_xlfn.FILTERXML("<t><s>" & SUBSTITUTE(C44," ","</s><s>") & "</s></t>","//s[number(.)=number(.)]")))} -> 0 | F44: =TRIM(RIGHT(SUBSTITUTE(C44," "&D44&" "&E44,""),13)) -> 4987058193617 | G44: =LEFT(C44,10) -> 2026/03/25 | H44: =MID(C44,12,10) -> 2026/04/01 | I44: =_xlfn.LET( _xlpm.s, _xlfn.TEXTAFTER(C44, " " & H44 & " "), TRIM(_xlfn.TEXTBEFORE(_xlpm.s, " " & L44 & " ")) ) -> クエチアピン錠25mg「アメル」共和薬品工業 | J44: =LEFT(I44, LEN(I44) - LEN(K44)) -> クエチアピン錠25mg「アメル」 | K44: {=_xlfn.LET( _xlpm.s, SUBSTITUTE(SUBSTITUTE(I44," ","")," ",""), _xlpm.dic, SUBSTITUTE(SUBSTITUTE(メーカー!$A$1:$A$100," ","")," ",""), _xlpm.pos, MATCH(TRUE, RIGHT(_xlpm.s, LEN(_xlpm.dic)) = _xlpm.dic, 0), INDEX(メーカー!$A$1:$A$100, _xlpm.pos) )} -> 共和薬品工業 | L44: {=INDEX(_xlfn.FILTERXML("<t><s>" & SUBSTITUTE(MID(C44,23,999)," ","</s><s>") & "</s></t>","//s[number(.)=number(.)]"),1)} -> 2 | M44: {=INDEX( _xlfn.FILTERXML("<t><s>" & SUBSTITUTE(MID(C44, 22 + LEN(I44) + 1, 999), " ", "</s><s>") & "</s></t>", "//s[number(.)=number(.)]"), 2 )} -> 40 | N44: {=_xlfn.REGEXEXTRACT(C44, "\d{2}:\d{2}:\d{2}")} -> 08:54:48 | O44: =TRIM(SUBSTITUTE(_xlfn.TEXTAFTER(C44, " " & N44 & " "), F44 & " " & D44 & " " & E44, "")) -> 25mg/錠 バラ 1000錠×1瓶 | P44: =TRIM(LEFT(_xlfn.TEXTAFTER(C44, I44 & " "), FIND(" ", _xlfn.TEXTAFTER(C44, I44 & " "))-1)) -> 2
B45: =B44+4 -> 176 | C45: =_xlfn.CONCAT(OFFSET(元!$B$10,'1行'!B45,0)," ",OFFSET(元!$B$12,'1行'!B45,0)) -> 2026/03/25 2026/04/01 デパケンR錠200mg 日医工 1 41 08:54:48 200mg/錠 バラ 1000錠×1瓶4987376850223 1 0 | D45: {=INDEX(_xlfn.FILTERXML("<t><s>" & SUBSTITUTE(C45," ","</s><s>") & "</s></t>","//s[number(.)=number(.)]"), COUNT(_xlfn.FILTERXML("<t><s>" & SUBSTITUTE(C45," ","</s><s>") & "</s></t>","//s[number(.)=number(.)]"))-1)} -> 1 | E45: {=INDEX(_xlfn.FILTERXML("<t><s>" & SUBSTITUTE(C45," ","</s><s>") & "</s></t>","//s[number(.)=number(.)]"), COUNT(_xlfn.FILTERXML("<t><s>" & SUBSTITUTE(C45," ","</s><s>") & "</s></t>","//s[number(.)=number(.)]")))} -> 0 | F45: =TRIM(RIGHT(SUBSTITUTE(C45," "&D45&" "&E45,""),13)) -> 4987376850223 | G45: =LEFT(C45,10) -> 2026/03/25 | H45: =MID(C45,12,10) -> 2026/04/01 | I45: =_xlfn.LET( _xlpm.s, _xlfn.TEXTAFTER(C45, " " & H45 & " "), TRIM(_xlfn.TEXTBEFORE(_xlpm.s, " " & L45 & " ")) ) -> デパケンR錠200mg 日医工 | J45: =LEFT(I45, LEN(I45) - LEN(K45)) -> デパケンR錠200mg | K45: {=_xlfn.LET( _xlpm.s, SUBSTITUTE(SUBSTITUTE(I45," ","")," ",""), _xlpm.dic, SUBSTITUTE(SUBSTITUTE(メーカー!$A$1:$A$100," ","")," ",""), _xlpm.pos, MATCH(TRUE, RIGHT(_xlpm.s, LEN(_xlpm.dic)) = _xlpm.dic, 0), INDEX(メーカー!$A$1:$A$100, _xlpm.pos) )} -> 日医工 | L45: {=INDEX(_xlfn.FILTERXML("<t><s>" & SUBSTITUTE(MID(C45,23,999)," ","</s><s>") & "</s></t>","//s[number(.)=number(.)]"),1)} -> 1 | M45: {=INDEX( _xlfn.FILTERXML("<t><s>" & SUBSTITUTE(MID(C45, 22 + LEN(I45) + 1, 999), " ", "</s><s>") & "</s></t>", "//s[number(.)=number(.)]"), 2 )} -> 41 | N45: {=_xlfn.REGEXEXTRACT(C45, "\d{2}:\d{2}:\d{2}")} -> 08:54:48 | O45: =TRIM(SUBSTITUTE(_xlfn.TEXTAFTER(C45, " " & N45 & " "), F45 & " " & D45 & " " & E45, "")) -> 200mg/錠 バラ 1000錠×1瓶 | P45: =TRIM(LEFT(_xlfn.TEXTAFTER(C45, I45 & " "), FIND(" ", _xlfn.TEXTAFTER(C45, I45 & " "))-1)) -> 1
B46: =B45+4 -> 180 | C46: =_xlfn.CONCAT(OFFSET(元!$B$10,'1行'!B46,0)," ",OFFSET(元!$B$12,'1行'!B46,0)) -> 2026/03/25 2026/04/01 イベニティ皮下注105mgシリンジアステラス製薬 5 42 08:54:48 105mg1.17mL1筒×2筒4987233105220 5 0 | D46: {=INDEX(_xlfn.FILTERXML("<t><s>" & SUBSTITUTE(C46," ","</s><s>") & "</s></t>","//s[number(.)=number(.)]"), COUNT(_xlfn.FILTERXML("<t><s>" & SUBSTITUTE(C46," ","</s><s>") & "</s></t>","//s[number(.)=number(.)]"))-1)} -> 5 | E46: {=INDEX(_xlfn.FILTERXML("<t><s>" & SUBSTITUTE(C46," ","</s><s>") & "</s></t>","//s[number(.)=number(.)]"), COUNT(_xlfn.FILTERXML("<t><s>" & SUBSTITUTE(C46," ","</s><s>") & "</s></t>","//s[number(.)=number(.)]")))} -> 0 | F46: =TRIM(RIGHT(SUBSTITUTE(C46," "&D46&" "&E46,""),13)) -> 4987233105220 | G46: =LEFT(C46,10) -> 2026/03/25 | H46: =MID(C46,12,10) -> 2026/04/01 | I46: =_xlfn.LET( _xlpm.s, _xlfn.TEXTAFTER(C46, " " & H46 & " "), TRIM(_xlfn.TEXTBEFORE(_xlpm.s, " " & L46 & " ")) ) -> イベニティ皮下注105mgシリンジアステラス製薬 | J46: =LEFT(I46, LEN(I46) - LEN(K46)) -> イベニティ皮下注105mgシリンジ | K46: {=_xlfn.LET( _xlpm.s, SUBSTITUTE(SUBSTITUTE(I46," ","")," ",""), _xlpm.dic, SUBSTITUTE(SUBSTITUTE(メーカー!$A$1:$A$100," ","")," ",""), _xlpm.pos, MATCH(TRUE, RIGHT(_xlpm.s, LEN(_xlpm.dic)) = _xlpm.dic, 0), INDEX(メーカー!$A$1:$A$100, _xlpm.pos) )} -> アステラス製薬 | L46: {=INDEX(_xlfn.FILTERXML("<t><s>" & SUBSTITUTE(MID(C46,23,999)," ","</s><s>") & "</s></t>","//s[number(.)=number(.)]"),1)} -> 5 | M46: {=INDEX( _xlfn.FILTERXML("<t><s>" & SUBSTITUTE(MID(C46, 22 + LEN(I46) + 1, 999), " ", "</s><s>") & "</s></t>", "//s[number(.)=number(.)]"), 2 )} -> 42 | N46: {=_xlfn.REGEXEXTRACT(C46, "\d{2}:\d{2}:\d{2}")} -> 08:54:48 | O46: =TRIM(SUBSTITUTE(_xlfn.TEXTAFTER(C46, " " & N46 & " "), F46 & " " & D46 & " " & E46, "")) -> 105mg1.17mL1筒×2筒 | P46: =TRIM(LEFT(_xlfn.TEXTAFTER(C46, I46 & " "), FIND(" ", _xlfn.TEXTAFTER(C46, I46 & " "))-1)) -> 5
