Workbook

Sheet 合体
B4: No | C4: 名称 | D4: カナ名称 | E4: 剤形(区分値) | F4: 剤形 | G4: 名称照合 | H4: 行番号 | I4: 一致率 | J4: 目視一致チェック | K4: 納入単価 | L4: 在庫総量 | M4: 在庫金額
B5: 1 | C5: =薬品マスタリスト_20260130100542!A3 -> アイファガン点眼液０．１％ | D5: =薬品マスタリスト_20260130100542!B3 -> ｱｲﾌｧｶﾞﾝﾃﾝｶﾞﾝｴｷ0.1% | E5: =薬品マスタリスト_20260130100542!C3 -> 21 | F5: =薬品マスタリスト_20260130100542!D3 -> 点眼剤 | G5: =match_results!C2 -> アイファガン点眼０．１％ | H5: =match_results!D2 -> 93 | I5: =match_results!E2 -> 96 | K5: =IF($J5="〇",OFFSET(集計!B$3,合体!$H5,0),"") | L5: =IF($J5="〇",OFFSET(集計!C$3,合体!$H5,0),"") | M5: =IF($J5="〇",OFFSET(集計!D$3,合体!$H5,0),"")
B6: =B5+1 -> 2 | C6: =薬品マスタリスト_20260130100542!A4 -> アウィクリ注 フレックスタッチ 総量３００単位 | D6: =薬品マスタリスト_20260130100542!B4 -> ｱｳｲｸﾘﾁﾕｳﾌﾚﾂｸｽﾀﾂﾁｿｳﾘﾖｳ300ﾀﾝｲ | E6: =薬品マスタリスト_20260130100542!C4 -> 25 | F6: =薬品マスタリスト_20260130100542!D4 -> 注射剤 | G6: =match_results!C3 -> トレシーバ注フレックスタッチ | H6: =match_results!D3 -> 127 | I6: =match_results!E3 -> 48.648649 | K6: =IF($J6="〇",OFFSET(集計!B$3,合体!$H6,0),"") | L6: =IF($J6="〇",OFFSET(集計!C$3,合体!$H6,0),"") | M6: =IF($J6="〇",OFFSET(集計!D$3,合体!$H6,0),"")
B7: =B6+1 -> 3 | C7: =薬品マスタリスト_20260130100542!A5 -> 亜鉛華軟膏「ニッコー」 | D7: =薬品マスタリスト_20260130100542!B5 -> ｱｴﾝｶﾅﾝｺｳ｢ﾆｯｺｰ｣ | E7: =薬品マスタリスト_20260130100542!C5 -> 14 | F7: =薬品マスタリスト_20260130100542!D5 -> 軟膏 | G7: =match_results!C4 -> 亜鉛華軟膏 ５００ｇ | H7: =match_results!D4 -> 99 | I7: =match_results!E4 -> 47.619048 | K7: =IF($J7="〇",OFFSET(集計!B$3,合体!$H7,0),"") | L7: =IF($J7="〇",OFFSET(集計!C$3,合体!$H7,0),"") | M7: =IF($J7="〇",OFFSET(集計!D$3,合体!$H7,0),"")
B8: =B7+1 -> 4 | C8: =薬品マスタリスト_20260130100542!A6 -> アキネトン細粒１％ | D8: =薬品マスタリスト_20260130100542!B6 -> ｱｷﾈﾄﾝｻｲﾘｭｳ1% | E8: =薬品マスタリスト_20260130100542!C6 -> 3 | F8: =薬品マスタリスト_20260130100542!D6 -> 散 | G8: =match_results!C5 -> アキネトン細粒１％ | H8: =match_results!D5 -> 1 | I8: =match_results!E5 -> 100 | J8: 〇 | K8: =IF($J8="〇",OFFSET(集計!B$3,合体!$H8,0),"") -> 20.23 | L8: =IF($J8="〇",OFFSET(集計!C$3,合体!$H8,0),"") -> 0 | M8: =IF($J8="〇",OFFSET(集計!D$3,合体!$H8,0),"") -> 0
B9: =B8+1 -> 5 | C9: =薬品マスタリスト_20260130100542!A7 -> アキネトン注射液５ｍｇ | D9: =薬品マスタリスト_20260130100542!B7 -> ｱｷﾈﾄﾝﾁｭｳｼｬｴｷ5mg | E9: =薬品マスタリスト_20260130100542!C7 -> 25 | F9: =薬品マスタリスト_20260130100542!D7 -> 注射剤 | G9: =match_results!C6 -> アキネトン注射液５ｍｇ | H9: =match_results!D6 -> 208 | I9: =match_results!E6 -> 100 | J9: 〇 | K9: =IF($J9="〇",OFFSET(集計!B$3,合体!$H9,0),"") -> 52.6 | L9: =IF($J9="〇",OFFSET(集計!C$3,合体!$H9,0),"") -> 57 | M9: =IF($J9="〇",OFFSET(集計!D$3,合体!$H9,0),"") -> 2998.2
B10: =B9+1 -> 6 | C10: =薬品マスタリスト_20260130100542!A8 -> アクアチムクリーム１％ | D10: =薬品マスタリスト_20260130100542!B8 -> ｱｸｱﾁﾑｸﾘｰﾑ1% | E10: =薬品マスタリスト_20260130100542!C8 -> 15 | F10: =薬品マスタリスト_20260130100542!D8 -> クリーム | G10: =match_results!C7 -> アクアチム クリ－ム１％ １０ｇ／本 | H10: =match_results!D7 -> 204 | I10: =match_results!E7 -> 68.965517 | K10: =IF($J10="〇",OFFSET(集計!B$3,合体!$H10,0),"") | L10: =IF($J10="〇",OFFSET(集計!C$3,合体!$H10,0),"") | M10: =IF($J10="〇",OFFSET(集計!D$3,合体!$H10,0),"")
B11: =B10+1 -> 7 | C11: =薬品マスタリスト_20260130100542!A9 -> アクチット輸液 | D11: =薬品マスタリスト_20260130100542!B9 -> ｱｸﾁﾂﾄﾕｴｷ | E11: =薬品マスタリスト_20260130100542!C9 -> 25 | F11: =薬品マスタリスト_20260130100542!D9 -> 注射剤 | G11: =match_results!C8 -> アクチット輸液 | H11: =match_results!D8 -> 235 | I11: =match_results!E8 -> 100 | J11: 〇 | K11: =IF($J11="〇",OFFSET(集計!B$3,合体!$H11,0),"") -> 303.75 | L11: =IF($J11="〇",OFFSET(集計!C$3,合体!$H11,0),"") -> 11 | M11: =IF($J11="〇",OFFSET(集計!D$3,合体!$H11,0),"") -> 3341.25
B12: =B11+1 -> 8 | C12: =薬品マスタリスト_20260130100542!A10 -> アクトシン軟膏３％ | D12: =薬品マスタリスト_20260130100542!B10 -> ｱｸﾄｼﾝﾅﾝｺｳ3% | E12: =薬品マスタリスト_20260130100542!C10 -> 14 | F12: =薬品マスタリスト_20260130100542!D10 -> 軟膏 | G12: =match_results!C9 -> アクトシン軟膏（３０ｇ） | H12: =match_results!D9 -> 2 | I12: =match_results!E9 -> 76.190476 | K12: =IF($J12="〇",OFFSET(集計!B$3,合体!$H12,0),"") | L12: =IF($J12="〇",OFFSET(集計!C$3,合体!$H12,0),"") | M12: =IF($J12="〇",OFFSET(集計!D$3,合体!$H12,0),"")
B13: =B12+1 -> 9 | C13: =薬品マスタリスト_20260130100542!A11 -> アザルフィジンＥＮ錠５００ｍｇ | D13: =薬品マスタリスト_20260130100542!B11 -> ｱｻﾞﾙﾌｨｼﾞﾝENｼﾞｮｳ500mg | E13: =薬品マスタリスト_20260130100542!C11 -> 1 | F13: =薬品マスタリスト_20260130100542!D11 -> 錠剤 | G13: =match_results!C10 -> アザルフィジンＥＮ（５００） | H13: =match_results!D10 -> 230 | I13: =match_results!E10 -> 82.758621 | K13: =IF($J13="〇",OFFSET(集計!B$3,合体!$H13,0),"") | L13: =IF($J13="〇",OFFSET(集計!C$3,合体!$H13,0),"") | M13: =IF($J13="〇",OFFSET(集計!D$3,合体!$H13,0),"")
B14: =B13+1 -> 10 | C14: =薬品マスタリスト_20260130100542!A12 -> アシクロビル点滴静注用２５０ｍｇ「サワイ」 | D14: =薬品マスタリスト_20260130100542!B12 -> ｱｼｸﾛﾋﾞﾙﾃﾝﾃｷｼﾞｮｳﾁｭｳﾖｳ250mg｢ｻﾜｲ｣ | E14: =薬品マスタリスト_20260130100542!C12 -> 25 | F14: =薬品マスタリスト_20260130100542!D12 -> 注射剤 | G14: =match_results!C11 -> アシクロビル点滴２５０ｍｇ | H14: =match_results!D11 -> 579 | I14: =match_results!E11 -> 76.470588 | K14: =IF($J14="〇",OFFSET(集計!B$3,合体!$H14,0),"") | L14: =IF($J14="〇",OFFSET(集計!C$3,合体!$H14,0),"") | M14: =IF($J14="〇",OFFSET(集計!D$3,合体!$H14,0),"")
B15: =B14+1 -> 11 | C15: =薬品マスタリスト_20260130100542!A13 -> アジスロマイシン錠２５０ｍｇ「トーワ」 | D15: =薬品マスタリスト_20260130100542!B13 -> ｱｼﾞｽﾛﾏｲｼﾝｼﾞｮｳ250mg｢ﾄｰﾜ｣ | E15: =薬品マスタリスト_20260130100542!C13 -> 1 | F15: =薬品マスタリスト_20260130100542!D13 -> 錠剤 | G15: =match_results!C12 -> アジスロマイシン錠２５０ｍｇ | H15: =match_results!D12 -> 331 | I15: =match_results!E12 -> 84.848485 | K15: =IF($J15="〇",OFFSET(集計!B$3,合体!$H15,0),"") | L15: =IF($J15="〇",OFFSET(集計!C$3,合体!$H15,0),"") | M15: =IF($J15="〇",OFFSET(集計!D$3,合体!$H15,0),"")
B16: =B15+1 -> 12 | C16: =薬品マスタリスト_20260130100542!A14 -> アジルバ錠１０ｍｇ | D16: =薬品マスタリスト_20260130100542!B14 -> ｱｼﾞﾙﾊﾞｼﾞｮｳ10mg | E16: =薬品マスタリスト_20260130100542!C14 -> 1 | F16: =薬品マスタリスト_20260130100542!D14 -> 錠剤 | G16: =match_results!C13 -> アジルバ（１０） | H16: =match_results!D13 -> 231 | I16: =match_results!E13 -> 70.588235 | K16: =IF($J16="〇",OFFSET(集計!B$3,合体!$H16,0),"") | L16: =IF($J16="〇",OFFSET(集計!C$3,合体!$H16,0),"") | M16: =IF($J16="〇",OFFSET(集計!D$3,合体!$H16,0),"")
B17: =B16+1 -> 13 | C17: =薬品マスタリスト_20260130100542!A15 -> アジルバ錠２０ｍｇ | D17: =薬品マスタリスト_20260130100542!B15 -> ｱｼﾞﾙﾊﾞｼﾞｮｳ20mg | E17: =薬品マスタリスト_20260130100542!C15 -> 1 | F17: =薬品マスタリスト_20260130100542!D15 -> 錠剤 | G17: =match_results!C14 -> フラジール錠２５０ｍｇ | H17: =match_results!D14 -> 85 | I17: =match_results!E14 -> 70 | K17: =IF($J17="〇",OFFSET(集計!B$3,合体!$H17,0),"") | L17: =IF($J17="〇",OFFSET(集計!C$3,合体!$H17,0),"") | M17: =IF($J17="〇",OFFSET(集計!D$3,合体!$H17,0),"")
B18: =B17+1 -> 14 | C18: =薬品マスタリスト_20260130100542!A16 -> アジルサルタンＯＤ錠２０ｍｇ「サワイ」 | D18: =薬品マスタリスト_20260130100542!B16 -> ｱｼﾞﾙｻﾙﾀﾝODｼﾞﾖｳ20MGｻﾜｲ | E18: =薬品マスタリスト_20260130100542!C16 -> 1 | F18: =薬品マスタリスト_20260130100542!D16 -> 錠剤 | G18: =match_results!C15 -> アジルサルタンＯＤ２０ｍｇ | H18: =match_results!D15 -> 601 | I18: =match_results!E15 -> 81.25 | K18: =IF($J18="〇",OFFSET(集計!B$3,合体!$H18,0),"") | L18: =IF($J18="〇",OFFSET(集計!C$3,合体!$H18,0),"") | M18: =IF($J18="〇",OFFSET(集計!D$3,合体!$H18,0),"")
B19: =B18+1 -> 15 | C19: =薬品マスタリスト_20260130100542!A17 -> アスコルビン酸注射液５００ｍｇ「日医工」 | D19: =薬品マスタリスト_20260130100542!B17 -> ｱｽｺﾙﾋﾞﾝｻﾝﾁｭｳｼｬｴｷ500mg｢ﾆﾁｲｺｳ｣ | E19: =薬品マスタリスト_20260130100542!C17 -> 25 | F19: =薬品マスタリスト_20260130100542!D17 -> 注射剤 | G19: =match_results!C16 -> アスコルビン酸注射液５００ｍｇ「トーワ」 | H19: =match_results!D16 -> 365 | I19: =match_results!E16 -> 85 | K19: =IF($J19="〇",OFFSET(集計!B$3,合体!$H19,0),"") | L19: =IF($J19="〇",OFFSET(集計!C$3,合体!$H19,0),"") | M19: =IF($J19="〇",OFFSET(集計!D$3,合体!$H19,0),"")
B20: =B19+1 -> 16 | C20: =薬品マスタリスト_20260130100542!A18 -> アスコルビン酸注射液５００ｍｇ「トーワ」 | D20: =薬品マスタリスト_20260130100542!B18 -> ｱｽｺﾙﾋﾞﾝｻﾝﾁﾕｳｼﾔｴｷ500MGﾄ-ﾜ | E20: =薬品マスタリスト_20260130100542!C18 -> 25 | F20: =薬品マスタリスト_20260130100542!D18 -> 注射剤 | G20: =match_results!C17 -> アスコルビン酸注射液５００ｍｇ「トーワ」 | H20: =match_results!D17 -> 365 | I20: =match_results!E17 -> 100 | J20: 〇 | K20: =IF($J20="〇",OFFSET(集計!B$3,合体!$H20,0),"") -> 72.2 | L20: =IF($J20="〇",OFFSET(集計!C$3,合体!$H20,0),"") -> 93 | M20: =IF($J20="〇",OFFSET(集計!D$3,合体!$H20,0),"") -> 6714.6
B21: =B20+1 -> 17 | C21: =薬品マスタリスト_20260130100542!A19 -> アスコルビン酸注５００ｍｇ「イセイ」 | D21: =薬品マスタリスト_20260130100542!B19 -> ｱｽｺﾙﾋﾞﾝｻﾝﾁﾕｳ500MGｲｾｲ | E21: =薬品マスタリスト_20260130100542!C19 -> 25 | F21: =薬品マスタリスト_20260130100542!D19 -> 注射剤 | G21: =match_results!C18 -> アスコルビン酸注射液５００ｍｇ「トーワ」 | H21: =match_results!D18 -> 365 | I21: =match_results!E18 -> 78.947368 | K21: =IF($J21="〇",OFFSET(集計!B$3,合体!$H21,0),"") | L21: =IF($J21="〇",OFFSET(集計!C$3,合体!$H21,0),"") | M21: =IF($J21="〇",OFFSET(集計!D$3,合体!$H21,0),"")
B22: =B21+1 -> 18 | C22: =薬品マスタリスト_20260130100542!A20 -> アズノールＳＴ錠口腔用５ｍｇ | D22: =薬品マスタリスト_20260130100542!B20 -> ｱｽﾞﾉｰﾙSTｼﾞｮｳｺｳｸｳﾖｳ5mg | E22: =薬品マスタリスト_20260130100542!C20 -> 8 | F22: =薬品マスタリスト_20260130100542!D20 -> トローチ | G22: =match_results!C19 -> プロタノールＳ錠１５ｍｇ | H22: =match_results!D19 -> 301 | I22: =match_results!E19 -> 61.538462 | K22: =IF($J22="〇",OFFSET(集計!B$3,合体!$H22,0),"") | L22: =IF($J22="〇",OFFSET(集計!C$3,合体!$H22,0),"") | M22: =IF($J22="〇",OFFSET(集計!D$3,合体!$H22,0),"")
B23: =B22+1 -> 19 | C23: =薬品マスタリスト_20260130100542!A21 -> アズノール軟膏０．０３３％ | D23: =薬品マスタリスト_20260130100542!B21 -> ｱｽﾞﾉｰﾙﾅﾝｺｳ0.033% | E23: =薬品マスタリスト_20260130100542!C21 -> 14 | F23: =薬品マスタリスト_20260130100542!D21 -> 軟膏 | G23: =match_results!C20 -> アズノール軟膏 ２０ｇ／本 | H23: =match_results!D20 -> 330 | I23: =match_results!E20 -> 61.538462 | K23: =IF($J23="〇",OFFSET(集計!B$3,合体!$H23,0),"") | L23: =IF($J23="〇",OFFSET(集計!C$3,合体!$H23,0),"") | M23: =IF($J23="〇",OFFSET(集計!D$3,合体!$H23,0),"")
B24: =B23+1 -> 20 | C24: =薬品マスタリスト_20260130100542!A22 -> アズノール錠２ｍｇ | D24: =薬品マスタリスト_20260130100542!B22 -> ｱｽﾞﾉ-ﾙｼﾞﾖｳ2MG | E24: =薬品マスタリスト_20260130100542!C22 -> 1 | F24: =薬品マスタリスト_20260130100542!D22 -> 錠剤 | G24: =match_results!C21 -> アナフラニール錠２５ｍｇ | H24: =match_results!D21 -> 157 | I24: =match_results!E21 -> 66.666667 | K24: =IF($J24="〇",OFFSET(集計!B$3,合体!$H24,0),"") | L24: =IF($J24="〇",OFFSET(集計!C$3,合体!$H24,0),"") | M24: =IF($J24="〇",OFFSET(集計!D$3,合体!$H24,0),"")
B25: =B24+1 -> 21 | C25: =薬品マスタリスト_20260130100542!A23 -> アスパラ－ＣＡ錠２００ | D25: =薬品マスタリスト_20260130100542!B23 -> ｱｽﾊﾟﾗ-CAｼﾞｮｳ200 | E25: =薬品マスタリスト_20260130100542!C23 -> 1 | F25: =薬品マスタリスト_20260130100542!D23 -> 錠剤 | G25: =match_results!C22 -> アスパラＣＡ錠２００ｍｇ | H25: =match_results!D22 -> 355 | I25: =match_results!E22 -> 86.956522 | K25: =IF($J25="〇",OFFSET(集計!B$3,合体!$H25,0),"") | L25: =IF($J25="〇",OFFSET(集計!C$3,合体!$H25,0),"") | M25: =IF($J25="〇",OFFSET(集計!D$3,合体!$H25,0),"")
B26: =B25+1 -> 22 | C26: =薬品マスタリスト_20260130100542!A24 -> アスパラカリウム錠３００ｍｇ | D26: =薬品マスタリスト_20260130100542!B24 -> ｱｽﾊﾟﾗｶﾘｳﾑｼﾞｮｳ300mg | E26: =薬品マスタリスト_20260130100542!C24 -> 1 | F26: =薬品マスタリスト_20260130100542!D24 -> 錠剤 | G26: =match_results!C23 -> アスパラカリウム錠３００ｍｇ | H26: =match_results!D23 -> 309 | I26: =match_results!E23 -> 100 | J26: 〇 | K26: =IF($J26="〇",OFFSET(集計!B$3,合体!$H26,0),"") -> 5.26 | L26: =IF($J26="〇",OFFSET(集計!C$3,合体!$H26,0),"") -> 920 | M26: =IF($J26="〇",OFFSET(集計!D$3,合体!$H26,0),"") -> 4839.2
B27: =B26+1 -> 23 | C27: =薬品マスタリスト_20260130100542!A25 -> アスパラカリウム散５０％ | D27: =薬品マスタリスト_20260130100542!B25 -> ｱｽﾊﾟﾗｶﾘｳﾑｻﾝ50% | E27: =薬品マスタリスト_20260130100542!C25 -> 3 | F27: =薬品マスタリスト_20260130100542!D25 -> 散 | G27: =match_results!C24 -> アスパラカリウム散５０％ | H27: =match_results!D24 -> 227 | I27: =match_results!E24 -> 100 | J27: 〇 | K27: =IF($J27="〇",OFFSET(集計!B$3,合体!$H27,0),"") -> 5.79 | L27: =IF($J27="〇",OFFSET(集計!C$3,合体!$H27,0),"") -> 557 | M27: =IF($J27="〇",OFFSET(集計!D$3,合体!$H27,0),"") -> 3225.03
B28: =B27+1 -> 24 | C28: =薬品マスタリスト_20260130100542!A26 -> アスパラギン酸カリウム注１０ｍＥｑキット「テルモ」 | D28: =薬品マスタリスト_20260130100542!B26 -> ｱｽﾊﾟﾗｷﾞﾝｻﾝｶﾘｳﾑﾁｭｳ10mEqｷｯﾄ｢ﾃﾙﾓ｣ | E28: =薬品マスタリスト_20260130100542!C26 -> 25 | F28: =薬品マスタリスト_20260130100542!D26 -> 注射剤 | G28: =match_results!C25 -> アスパラギンサンカリウム注１０ＭＥＱキット「テル | H28: =match_results!D25 -> 219 | I28: =match_results!E25 -> 81.632653 | K28: =IF($J28="〇",OFFSET(集計!B$3,合体!$H28,0),"") | L28: =IF($J28="〇",OFFSET(集計!C$3,合体!$H28,0),"") | M28: =IF($J28="〇",OFFSET(集計!D$3,合体!$H28,0),"")
B29: =B28+1 -> 25 | C29: =薬品マスタリスト_20260130100542!A27 -> アズレン点眼液０．０２％「ニットー」 | D29: =薬品マスタリスト_20260130100542!B27 -> ｱｽﾞﾚﾝﾃﾝｶﾞﾝｴｷ0.02%｢ﾆｯﾄｰ｣ | E29: =薬品マスタリスト_20260130100542!C27 -> 21 | F29: =薬品マスタリスト_20260130100542!D27 -> 点眼剤 | G29: =match_results!C26 -> アズレン点眼液 | H29: =match_results!D26 -> 106 | I29: =match_results!E26 -> 56 | K29: =IF($J29="〇",OFFSET(集計!B$3,合体!$H29,0),"") | L29: =IF($J29="〇",OFFSET(集計!C$3,合体!$H29,0),"") | M29: =IF($J29="〇",OFFSET(集計!D$3,合体!$H29,0),"")
B30: =B29+1 -> 26 | C30: =薬品マスタリスト_20260130100542!A28 -> アズレン点眼液わかもと | D30: =薬品マスタリスト_20260130100542!B28 -> ｱｽﾞﾚﾝﾃﾝｶﾞﾝｴｷﾜｶﾓﾄ | E30: =薬品マスタリスト_20260130100542!C28 -> 21 | F30: =薬品マスタリスト_20260130100542!D28 -> 点眼剤 | G30: =match_results!C27 -> アズレン点眼液 | H30: =match_results!D27 -> 106 | I30: =match_results!E27 -> 77.777778 | K30: =IF($J30="〇",OFFSET(集計!B$3,合体!$H30,0),"") | L30: =IF($J30="〇",OFFSET(集計!C$3,合体!$H30,0),"") | M30: =IF($J30="〇",OFFSET(集計!D$3,合体!$H30,0),"")
B31: =B30+1 -> 27 | C31: =薬品マスタリスト_20260130100542!A29 -> アセリオ静注液１０００ｍｇバッグ | D31: =薬品マスタリスト_20260130100542!B29 -> ｱｾﾘｵｼﾞｮｳﾁｭｳｴｷ1000mgﾊﾞｯｸﾞ | E31: =薬品マスタリスト_20260130100542!C29 -> 25 | F31: =薬品マスタリスト_20260130100542!D29 -> 注射剤 | G31: =match_results!C28 -> アセリオ靜注液１０００ｍｇバッグ | H31: =match_results!D28 -> 322 | I31: =match_results!E28 -> 93.75 | K31: =IF($J31="〇",OFFSET(集計!B$3,合体!$H31,0),"") | L31: =IF($J31="〇",OFFSET(集計!C$3,合体!$H31,0),"") | M31: =IF($J31="〇",OFFSET(集計!D$3,合体!$H31,0),"")
B32: =B31+1 -> 28 | C32: =薬品マスタリスト_20260130100542!A30 -> アセレンド注１００μｇ | D32: =薬品マスタリスト_20260130100542!B30 -> ｱｾﾚﾝﾄﾞﾁｭｳ100μg | E32: =薬品マスタリスト_20260130100542!C30 -> 25 | F32: =薬品マスタリスト_20260130100542!D30 -> 注射剤 | G32: =match_results!C29 -> アセレンド注 | H32: =match_results!D29 -> 292 | I32: =match_results!E29 -> 70.588235 | K32: =IF($J32="〇",OFFSET(集計!B$3,合体!$H32,0),"") | L32: =IF($J32="〇",OFFSET(集計!C$3,合体!$H32,0),"") | M32: =IF($J32="〇",OFFSET(集計!D$3,合体!$H32,0),"")
B33: =B32+1 -> 29 | C33: =薬品マスタリスト_20260130100542!A31 -> アゾセミド錠３０ｍｇ「ＪＧ」 | D33: =薬品マスタリスト_20260130100542!B31 -> ｱｿﾞｾﾐﾄﾞｼﾞｮｳ30mg｢JG｣ | E33: =薬品マスタリスト_20260130100542!C31 -> 1 | F33: =薬品マスタリスト_20260130100542!D31 -> 錠剤 | G33: =match_results!C30 -> アゾセミド錠６０ｍｇ | H33: =match_results!D30 -> 81 | I33: =match_results!E30 -> 75 | K33: =IF($J33="〇",OFFSET(集計!B$3,合体!$H33,0),"") | L33: =IF($J33="〇",OFFSET(集計!C$3,合体!$H33,0),"") | M33: =IF($J33="〇",OFFSET(集計!D$3,合体!$H33,0),"")
B34: =B33+1 -> 30 | C34: =薬品マスタリスト_20260130100542!A32 -> アゾセミド錠３０ｍｇ「ＤＳＥＰ」 | D34: =薬品マスタリスト_20260130100542!B32 -> ｱｿﾞｾﾐﾄﾞｼﾞｮｳ30mg｢DSEP｣ | E34: =薬品マスタリスト_20260130100542!C32 -> 1 | F34: =薬品マスタリスト_20260130100542!D32 -> 錠剤 | G34: =match_results!C31 -> アゾセミド錠６０ｍｇ | H34: =match_results!D31 -> 81 | I34: =match_results!E31 -> 69.230769 | K34: =IF($J34="〇",OFFSET(集計!B$3,合体!$H34,0),"") | L34: =IF($J34="〇",OFFSET(集計!C$3,合体!$H34,0),"") | M34: =IF($J34="〇",OFFSET(集計!D$3,合体!$H34,0),"")
B35: =B34+1 -> 31 | C35: =薬品マスタリスト_20260130100542!A33 -> アゾセミド錠６０ｍｇ「ＤＳＥＰ」 | D35: =薬品マスタリスト_20260130100542!B33 -> ｱｿﾞｾﾐﾄﾞｼﾞｮｳ60mg｢DSEP｣ | E35: =薬品マスタリスト_20260130100542!C33 -> 1 | F35: =薬品マスタリスト_20260130100542!D33 -> 錠剤 | G35: =match_results!C32 -> アゾセミド錠６０ｍｇ | H35: =match_results!D32 -> 81 | I35: =match_results!E32 -> 76.923077 | K35: =IF($J35="〇",OFFSET(集計!B$3,合体!$H35,0),"") | L35: =IF($J35="〇",OFFSET(集計!C$3,合体!$H35,0),"") | M35: =IF($J35="〇",OFFSET(集計!D$3,合体!$H35,0),"")
B36: =B35+1 -> 32 | C36: =薬品マスタリスト_20260130100542!A34 -> アタラックス錠２５ｍｇ | D36: =薬品マスタリスト_20260130100542!B34 -> ｱﾀﾗｯｸｽｼﾞｮｳ25mg | E36: =薬品マスタリスト_20260130100542!C34 -> 1 | F36: =薬品マスタリスト_20260130100542!D34 -> 錠剤 | G36: =match_results!C33 -> アタラックス錠２５ＭＧ | H36: =match_results!D33 -> 274 | I36: =match_results!E33 -> 81.818182 | K36: =IF($J36="〇",OFFSET(集計!B$3,合体!$H36,0),"") | L36: =IF($J36="〇",OFFSET(集計!C$3,合体!$H36,0),"") | M36: =IF($J36="〇",OFFSET(集計!D$3,合体!$H36,0),"")
B37: =B36+1 -> 33 | C37: =薬品マスタリスト_20260130100542!A35 -> アダラートＣＲ錠２０ｍｇ | D37: =薬品マスタリスト_20260130100542!B35 -> ｱﾀﾞﾗｰﾄCRｼﾞｮｳ20mg | E37: =薬品マスタリスト_20260130100542!C35 -> 1 | F37: =薬品マスタリスト_20260130100542!D35 -> 錠剤 | G37: =match_results!C34 -> アダラートＣＲ錠２０ｍｇ | H37: =match_results!D34 -> 114 | I37: =match_results!E34 -> 100 | J37: 〇 | K37: =IF($J37="〇",OFFSET(集計!B$3,合体!$H37,0),"") -> 13.28 | L37: =IF($J37="〇",OFFSET(集計!C$3,合体!$H37,0),"") -> 120 | M37: =IF($J37="〇",OFFSET(集計!D$3,合体!$H37,0),"") -> 1593.6
B38: =B37+1 -> 34 | C38: =薬品マスタリスト_20260130100542!A36 -> アーチスト錠１．２５ｍｇ | D38: =薬品マスタリスト_20260130100542!B36 -> ｱｰﾁｽﾄｼﾞｮｳ1.25mg | E38: =薬品マスタリスト_20260130100542!C36 -> 1 | F38: =薬品マスタリスト_20260130100542!D36 -> 錠剤 | G38: =match_results!C35 -> ア－チスト錠１．２５ｍｇ | H38: =match_results!D35 -> 169 | I38: =match_results!E35 -> 91.666667 | K38: =IF($J38="〇",OFFSET(集計!B$3,合体!$H38,0),"") | L38: =IF($J38="〇",OFFSET(集計!C$3,合体!$H38,0),"") | M38: =IF($J38="〇",OFFSET(集計!D$3,合体!$H38,0),"")
B39: =B38+1 -> 35 | C39: =薬品マスタリスト_20260130100542!A37 -> アドエア５００ディスカス６０吸入用 | D39: =薬品マスタリスト_20260130100542!B37 -> ｱﾄﾞｴｱ500ﾃﾞｨｽｶｽ60ｷｭｳﾆｭｳﾖｳ | E39: =薬品マスタリスト_20260130100542!C37 -> 10 | F39: =薬品マスタリスト_20260130100542!D37 -> 吸入剤 | G39: =match_results!C36 -> アドエア５００ディスカス６０吸入用 ６０ブリスターＸ１ | H39: =match_results!D36 -> 390 | I39: =match_results!E36 -> 77.272727 | K39: =IF($J39="〇",OFFSET(集計!B$3,合体!$H39,0),"") | L39: =IF($J39="〇",OFFSET(集計!C$3,合体!$H39,0),"") | M39: =IF($J39="〇",OFFSET(集計!D$3,合体!$H39,0),"")
B40: =B39+1 -> 36 | C40: =薬品マスタリスト_20260130100542!A38 -> アドナ錠３０ｍｇ | D40: =薬品マスタリスト_20260130100542!B38 -> ｱﾄﾞﾅｼﾞｮｳ30mg | E40: =薬品マスタリスト_20260130100542!C38 -> 1 | F40: =薬品マスタリスト_20260130100542!D38 -> 錠剤 | G40: =match_results!C37 -> アドナ錠３０ｍｇ | H40: =match_results!D37 -> 380 | I40: =match_results!E37 -> 100 | J40: 〇 | K40: =IF($J40="〇",OFFSET(集計!B$3,合体!$H40,0),"") -> 7.28 | L40: =IF($J40="〇",OFFSET(集計!C$3,合体!$H40,0),"") -> 970 | M40: =IF($J40="〇",OFFSET(集計!D$3,合体!$H40,0),"") -> 7061.6
B41: =B40+1 -> 37 | C41: =薬品マスタリスト_20260130100542!A39 -> アドナ注（静脈用）５０ｍｇ | D41: =薬品マスタリスト_20260130100542!B39 -> ｱﾄﾞﾅﾁｭｳ(ｼﾞｮｳﾐｬｸﾖｳ)50mg | E41: =薬品マスタリスト_20260130100542!C39 -> 25 | F41: =薬品マスタリスト_20260130100542!D39 -> 注射剤 | G41: =match_results!C38 -> アドナ注（静脈用）５０ｍｇ | H41: =match_results!D38 -> 236 | I41: =match_results!E38 -> 100 | J41: 〇 | K41: =IF($J41="〇",OFFSET(集計!B$3,合体!$H41,0),"") -> 80 | L41: =IF($J41="〇",OFFSET(集計!C$3,合体!$H41,0),"") -> 42 | M41: =IF($J41="〇",OFFSET(集計!D$3,合体!$H41,0),"") -> 3360
B42: =B41+1 -> 38 | C42: =薬品マスタリスト_20260130100542!A40 -> アドナ散１０％ | D42: =薬品マスタリスト_20260130100542!B40 -> ｱﾄﾞﾅｻﾝ10% | E42: =薬品マスタリスト_20260130100542!C40 -> 3 | F42: =薬品マスタリスト_20260130100542!D40 -> 散 | G42: =match_results!C39 -> アドナ散 | H42: =match_results!D39 -> 213 | I42: =match_results!E39 -> 72.727273 | K42: =IF($J42="〇",OFFSET(集計!B$3,合体!$H42,0),"") | L42: =IF($J42="〇",OFFSET(集計!C$3,合体!$H42,0),"") | M42: =IF($J42="〇",OFFSET(集計!D$3,合体!$H42,0),"")
B43: =B42+1 -> 39 | C43: =薬品マスタリスト_20260130100542!A41 -> アドフィードパップ４０ｍｇ | D43: =薬品マスタリスト_20260130100542!B41 -> ｱﾄﾞﾌｲ-ﾄﾞﾊﾟﾂﾌﾟ40MG | E43: =薬品マスタリスト_20260130100542!C41 -> 19 | F43: =薬品マスタリスト_20260130100542!D41 -> 貼付剤 | G43: =match_results!C40 -> アドフィードパップ（７枚／袋） | H43: =match_results!D40 -> 327 | I43: =match_results!E40 -> 64.285714 | K43: =IF($J43="〇",OFFSET(集計!B$3,合体!$H43,0),"") | L43: =IF($J43="〇",OFFSET(集計!C$3,合体!$H43,0),"") | M43: =IF($J43="〇",OFFSET(集計!D$3,合体!$H43,0),"")
...

Sheet match_results
A1: A行番号 | B1: A薬品名 | C1: B候補 | D1: B行番号 | E1: 類似度(0-100)
A2: 1 | B2: アイファガン点眼液０．１％ | C2: アイファガン点眼０．１％ | D2: 93 | E2: 96
A3: 2 | B3: アウィクリ注 フレックスタッチ 総量３００単位 | C3: トレシーバ注フレックスタッチ | D3: 127 | E3: 48.648649
A4: 3 | B4: 亜鉛華軟膏「ニッコー」 | C4: 亜鉛華軟膏 ５００ｇ | D4: 99 | E4: 47.619048
A5: 4 | B5: アキネトン細粒１％ | C5: アキネトン細粒１％ | D5: 1 | E5: 100
A6: 5 | B6: アキネトン注射液５ｍｇ | C6: アキネトン注射液５ｍｇ | D6: 208 | E6: 100
A7: 6 | B7: アクアチムクリーム１％ | C7: アクアチム クリ－ム１％ １０ｇ／本 | D7: 204 | E7: 68.965517
A8: 7 | B8: アクチット輸液 | C8: アクチット輸液 | D8: 235 | E8: 100
A9: 8 | B9: アクトシン軟膏３％ | C9: アクトシン軟膏（３０ｇ） | D9: 2 | E9: 76.190476
A10: 9 | B10: アザルフィジンＥＮ錠５００ｍｇ | C10: アザルフィジンＥＮ（５００） | D10: 230 | E10: 82.758621
A11: 10 | B11: アシクロビル点滴静注用２５０ｍｇ「サワイ」 | C11: アシクロビル点滴２５０ｍｇ | D11: 579 | E11: 76.470588
A12: 11 | B12: アジスロマイシン錠２５０ｍｇ「トーワ」 | C12: アジスロマイシン錠２５０ｍｇ | D12: 331 | E12: 84.848485
A13: 12 | B13: アジルバ錠１０ｍｇ | C13: アジルバ（１０） | D13: 231 | E13: 70.588235
... A1029: 1028 | B1029: ワンパル１号輸液 | C1029: ワンパル２号輸液８００ | D1029: 625 | E1029: 73.684211

Sheet 薬品マスタリスト_20260130100542
A1: 46052
A2: 名称 | B2: カナ名称 | C2: 剤形(区分値) | D2: 剤形
A3: アイファガン点眼液０．１％ | B3: ｱｲﾌｧｶﾞﾝﾃﾝｶﾞﾝｴｷ0.1% | C3: 21 | D3: 点眼剤
A4: アウィクリ注 フレックスタッチ 総量３００単位 | B4: ｱｳｲｸﾘﾁﾕｳﾌﾚﾂｸｽﾀﾂﾁｿｳﾘﾖｳ300ﾀﾝｲ | C4: 25 | D4: 注射剤
A5: 亜鉛華軟膏「ニッコー」 | B5: ｱｴﾝｶﾅﾝｺｳ｢ﾆｯｺｰ｣ | C5: 14 | D5: 軟膏
A6: アキネトン細粒１％ | B6: ｱｷﾈﾄﾝｻｲﾘｭｳ1% | C6: 3 | D6: 散
A7: アキネトン注射液５ｍｇ | B7: ｱｷﾈﾄﾝﾁｭｳｼｬｴｷ5mg | C7: 25 | D7: 注射剤
A8: アクアチムクリーム１％ | B8: ｱｸｱﾁﾑｸﾘｰﾑ1% | C8: 15 | D8: クリーム
A9: アクチット輸液 | B9: ｱｸﾁﾂﾄﾕｴｷ | C9: 25 | D9: 注射剤
A10: アクトシン軟膏３％ | B10: ｱｸﾄｼﾝﾅﾝｺｳ3% | C10: 14 | D10: 軟膏
A11: アザルフィジンＥＮ錠５００ｍｇ | B11: ｱｻﾞﾙﾌｨｼﾞﾝENｼﾞｮｳ500mg | C11: 1 | D11: 錠剤
A12: アシクロビル点滴静注用２５０ｍｇ「サワイ」 | B12: ｱｼｸﾛﾋﾞﾙﾃﾝﾃｷｼﾞｮｳﾁｭｳﾖｳ250mg｢ｻﾜｲ｣ | C12: 25 | D12: 注射剤
A13: アジスロマイシン錠２５０ｍｇ「トーワ」 | B13: ｱｼﾞｽﾛﾏｲｼﾝｼﾞｮｳ250mg｢ﾄｰﾜ｣ | C13: 1 | D13: 錠剤
A14: アジルバ錠１０ｍｇ | B14: ｱｼﾞﾙﾊﾞｼﾞｮｳ10mg | C14: 1 | D14: 錠剤
... A1030: ワンパル１号輸液 | B1030: ﾜﾝﾊﾟﾙ1ｺﾞｳﾕｴｷ | C1030: 25 | D1030: 注射剤

Sheet 集計
A1: 2024年度 北山病院 棚卸 | F1: 10万円以上
F2: 1000錠以上
A3: 商品名 | B3: 納入単価 | C3: 在庫総量 | D3: 在庫金額
A4: アキネトン細粒1% | B4: 20.23 | C4: 0 | D4: 0 | E4: =DBCS(A4) -> アキネトン細粒１％ | F4: =LEFT(E4,5) -> アキネトン
A5: ｱｸﾄｼﾝ軟膏（30ｇ） | B5: 1362 | C5: 0 | D5: 0 | E5: =DBCS(A5) -> アクトシン軟膏（３０ｇ） | F5: =LEFT(E5,5) -> アクトシン
A6: アナフラニール錠10ｍｇ | B6: 8.5 | C6: 0 | D6: 0 | E6: =DBCS(A6) -> アナフラニール錠１０ｍｇ | F6: =LEFT(E6,5) -> アナフラニ
A7: イバンドロン酸1㎖シリンジ | B7: 1368 | C7: 0 | D7: 0 | E7: =DBCS(A7) -> イバンドロン酸１㎖シリンジ | F7: =LEFT(E7,5) -> イバンドロ
A8: イベニティ皮下注105mgシリンジ | B8: 43356 | C8: 0 | D8: 0 | E8: =DBCS(A8) -> イベニティ皮下注１０５ｍｇシリンジ | F8: =LEFT(E8,5) -> イベニティ
A9: ｲﾝﾄﾗﾘﾎﾟｽ輸液20%100ｍｌ | B9: 727 | C9: 0 | D9: 0 | E9: =DBCS(A9) -> イントラリポス輸液２０％１００ｍｌ | F9: =LEFT(E9,5) -> イントラリ
A10: ｷｼﾛｶｲﾝ ﾋﾞｽｶｽ2% | B10: 530 | C10: 0 | D10: 0 | E10: =DBCS(A10) -> キシロカイン ビスカス２％ | F10: =LEFT(E10,5) -> キシロカイ
A11: ｷｼﾛｶｲﾝ ﾎﾟﾝﾌﾟｽﾌﾟﾚ-8% | B11: 19.2 | C11: 0 | D11: 0 | E11: =DBCS(A11) -> キシロカイン ポンプスプレ－８％ | F11: =LEFT(E11,5) -> キシロカイ
A12: ｷｼﾛｶｲﾝ注ﾎﾟﾘｱﾝﾌﾟ0.5% | B12: 52.1 | C12: 0 | D12: 0 | E12: =DBCS(A12) -> キシロカイン注ポリアンプ０．５％ | F12: =LEFT(E12,5) -> キシロカイ
A13: セフタジジム静注用１ｇ １０Ｖ | B13: 405.4 | C13: 0 | D13: 0 | E13: =DBCS(A13) -> セフタジジム静注用１ｇ １０Ｖ | F13: =LEFT(E13,5) -> セフタジジ
A14: ﾃﾞﾙﾓｿﾞ-ﾙG ｸﾘ-ﾑ 5g/本 | B14: 123.38 | C14: 0 | D14: 0 | E14: =DBCS(A14) -> デルモゾ－ルＧ クリ－ム ５ｇ／本 | F14: =LEFT(E14,5) -> デルモゾ－
A15: ドグマチール細粒 | B15: 22.3 | C15: 0 | D15: 0 | E15: =DBCS(A15) -> ドグマチール細粒 | F15: =LEFT(E15,5) -> ドグマチー
... A672: ラツーダ錠40ｍｇ | B672: 265.98 | C672: 2171.4706 | D672: 577567.75 | E672: =DBCS(A672) -> ラツーダ錠４０ｍｇ | F672: =LEFT(E672,5) -> ラツーダ錠
D673: =SUM(D4:D672) -> 10421362

Sheet Sheet1
A1: 2024年度 北山病院薬剤部 棚卸し | J1: 回転台 | M1: 分包機・散薬 | O1: 在庫棚 | P1: ヒート棚
A2: 商品名 | B2: 分類 | C2: 納入単価 | J2: 測定量（ｇ） | K2: 風袋 | L2: g/10T | M2: 測定量（ｇ） | N2: 風袋 | O2: 数量(錠） | P2: ﾋｰﾄ数 | Q2: 在庫総量 | R2: 単位 | S2: 在庫金額
A3: アキネトン細粒1% | B3: 11 | C3: 21.4 | J3: 100 | M3: 52 | N3: 47 | R3: g
A4: アスパラカリウム散50％ | B4: 11 | C4: 5.8 | J4: 221 | M4: 204 | N4: 115
A5: アドナ散 | B5: 11 | C5: 32.6 | M5: 256 | N5: 149 | R5: ｇ
A6: ｱﾘﾋﾟﾌﾟﾗｿﾞｰﾙ散1％「ﾆﾌﾟﾛ」 | B6: 11 | C6: 17.9 | J6: 100 | M6: 56 | N6: 40 | R6: ｇ
A7: アレビアチン散１０％ | B7: 11 | C7: 10.8 | J7: 493 | N7: 237 | R7: ｇ
A8: ウインタミン細粒（１０％） | B8: 11 | C8: 5.8 | J8: 434 | M8: 72 | N8: 42 | R8: ｇ
A9: オランザピン細粒1％「ヨシトミ」 | B9: 11 | C9: 62.4 | J9: 200 | M9: 96 | N9: 43 | R9: ｇ
A10: カルバマゼピン細粒５０％「アメル」 | B10: 11 | C10: 17.1 | J10: 680 | M10: 257 | N10: 229 | R10: ｇ
A11: クエチアピン細粒50％ | B11: 11 | C11: 136.4 | J11: 100 | M11: 111 | N11: 50 | R11: ｇ
A12: グラマリール細粒10％ | B12: 11 | C12: 21.4 | J12: 100 | M12: 121 | N12: 64
A13: コデインリン酸塩酸1％ | B13: 11 | C13: 6.7 | M13: 106 | N13: 103
A14: スルピリド細粒５０％「アメル」 ５００ｇ | B14: 11 | C14: 12.7 | J14: 950 | N14: 76 | R14: ｇ
A15: センノサイド顆粒 ８％ | B15: 11 | C15: 9.9 | M15: 165 | N15: 70 | R15: ｇ
A16: ｾﾝﾌﾞﾘ・重曹散｢ﾖｼﾀﾞ｣ | B16: 11 | C16: 6.5 | J16: 500 | M16: 184 | N16: 97 | R16: ｇ
A17: タンニン酸アルブミン「VTRS] | B17: 11 | C17: 6.2 | J17: 500 | M17: 227 | N17: 116 | R17: ｇ
A18: デパス細粒1％ | B18: 11 | C18: 36.7 | J18: 100 | M18: 182 | N18: 175
A19: テプレノン細粒１０％ | B19: 11 | C19: 9.1 | J19: 200 | M19: 345 | N19: 285 | R19: ｇ
A20: ドグマチール細粒 | B20: 11 | C20: 22.3
A21: トロペロン細粒1％ | B21: 11 | C21: 75.2 | J21: 400 | M21: 171 | N21: 98
A22: トーワチーム配合顆粒 | B22: 11 | J22: 118 | M22: 164 | N22: 118
A23: ﾆｺﾁﾝ酸ｱﾐﾄﾞ散10％「ｿﾞﾝﾈ」 | B23: 11 | J23: 641
A24: バルプロ酸Na徐放顆粒４０％ | B24: 11 | C24: 25.9 | J24: 500 | M24: 388 | N24: 108 | R24: ｇ
A25: ハロペリドール細粒１％ ｢ﾖｼﾄﾐ｣ | B25: 11 | C25: 10.5 | J25: 300 | M25: 105 | N25: 99 | R25: ｇ
A26: パントシン散（２０％） | B26: 11 | C26: 11.4 | J26: 1000 | M26: 589 | N26: 257 | R26: ｇ
A27: ﾋﾞｵﾌｪﾙﾐﾝ配合散 | B27: 11 | C27: 5.3 | M27: 496 | N27: 284 | R27: ｇ
A28: ヒベルナ散 １０％ １００ｇ | B28: 11 | N28: 75 | R28: ｇ
A29: ファモチジン散１０％ | B29: 11 | C29: 43 | J29: 100 | M29: 129 | N29: 39 | R29: ｇ
A30: フェノバルビタール散１０％「ホエイ」 | B30: 11 | C30: 6.5 | J30: 500 | M30: 367 | N30: 58 | R30: ｇ
A31: フェロミア顆粒８．３％ | B31: 11 | C31: 10 | J31: 500 | M31: 140 | N31: 74 | R31: ｇ
A32: ブドウ糖 | B32: 11 | C32: 7.4 | J32: 2303 | M32: 219 | N32: 73 | R32: ｇ
A33: フロセミド細粒 ４％ 「ＥＭＥＣ」 | B33: 11 | C33: 8.3 | J33: 300 | M33: 162 | N33: 149 | R33: ｇ
A34: ブロナンセリン散2％「DSPB] | B34: 11 | C34: 101.4 | J34: 200 | M34: 143 | N34: 49
A35: ブロムペリドール細粒1％ | B35: 11 | J35: 26 | M35: 174 | N35: 75 | R35: ｇ
A36: ﾍﾞｻｺﾘﾝ散5％ | B36: 11 | C36: 8.9 | J36: 100 | M36: 57 | N36: 40 | R36: ｇ
A37: ベンザリン細粒 | B37: 11 | C37: 13.4 | J37: 100 | M37: 139 | N37: 60
A38: マーズレンS配合顆粒 | B38: 11 | C38: 10.2 | J38: 1000 | M38: 392 | N38: 113
A39: モサプリドクエン酸塩散1％「日医工」 | B39: 11 | C39: 9.4 | J39: 200 | M39: 154 | N39: 75
A40: リスパダール細粒１％ | B40: 11 | C40: 104.4 | M40: 150 | N40: 68 | R40: ｇ
...

Sheet 注射（集計）
A1: 2024年度 北山病院薬剤部 棚卸し | K1: ヒート棚
A2: 商品名 | B2: 分類 | D2: 納入単価 | K2: ﾋｰﾄ数 | L2: 単位 | M2: 在庫金額
A3: ベクルリー点滴静注用100mg | B3: 8 | C3: 1 | D3: 41108 | K3: 4 | L3: 本 | M3: =SUM(D3*K3) -> 164432
A4: アキネトン注射液５ｍｇ | B4: 40 | C4: 1 | D4: 52.6 | K4: 57 | L4: 本 | M4: =SUM(D4*K4) -> 2998.2
A5: アクチット輸液 | B5: 40 | C5: 1 | D5: 303.75 | K5: 11 | L5: 袋 | M5: =SUM(D5*K5) -> 3341.25
A6: アシクロビル点滴250ｍｇ | B6: 40 | C6: 1 | D6: 341.2 | K6: 80 | L6: 本 | M6: =SUM(D6*K6) -> 27296
A7: ｱｽﾊﾟﾗｷﾞﾝｻﾝｶﾘｳﾑ注10MEQｷｯﾄ｢ﾃﾙ | B7: 40 | C7: 1 | D7: 163.7 | K7: 19 | L7: 本 | M7: =SUM(D7*K7) -> 3110.3
A8: アセリオ靜注液1000mgバッグ | B8: 40 | C8: 1 | D8: 274 | K8: 19 | L8: 袋 | M8: =SUM(D8*K8) -> 5206
A9: アセレンド注 | B9: 40 | C9: 1 | D9: 1483 | K9: 3 | L9: 本 | M9: =SUM(D9*K9) -> 4449
A10: アドナ注（静脈用）５０ｍｇ | B10: 40 | C10: 1 | D10: 80 | K10: 42 | L10: 本 | M10: =SUM(D10*K10) -> 3360
A11: ｱﾄﾛﾋﾟﾝ硫酸塩注0.5ｍｇ | B11: 40 | C11: 1 | D11: 83.7 | K11: 7 | L11: 本 | M11: =SUM(D11*K11) -> 585.9
A12: アネキセート注射液0.5MG | B12: 40 | C12: 1 | D12: 1800.6 | K12: 2 | L12: 本 | M12: =SUM(D12*K12) -> 3601.2
A13: アミノレバン点滴静注 | B13: 40 | C13: 1 | D13: 637 | K13: 11 | L13: 袋 | M13: =SUM(D13*K13) -> 7007
A14: ｱﾙﾌﾞﾐﾅ- 25%静注12.5G/50ML | B14: 40 | C14: 1 | D14: 4032 | K14: 1 | L14: 本 | M14: =SUM(D14*K14) -> 4032
... A22: 塩酸メトクロプラミド注射注１０ｍｇ | B22: 40 | C22: 1 | D22: 51.8 | K22: 84 | L22: 本 | M22: =SUM(D22*K22) -> 4351.2
A23: ｷｼﾛｶｲﾝ ﾋﾞｽｶｽ2% | B23: 40 | C23: 1 | E23: 552 | F23: 100 | G23: 552 | H23: 100 | K23: 0 | L23: 本 | M23: =SUM(D23*K23) -> 0
A24: ｷｼﾛｶｲﾝ ﾎﾟﾝﾌﾟｽﾌﾟﾚ-8% | B24: 40 | C24: 1 | D24: 19.2 | E24: 1745 | F24: 80 | G24: 1745 | H24: 80 | K24: 0 | L24: 本 | M24: =SUM(D24*K24) -> 0
A25: ｷｼﾛカインｼﾘﾝｼﾞ | B25: 40 | C25: 1 | D25: 187 | K25: 9 | L25: 本 | M25: =SUM(D25*K25) -> 1683
A26: ｷｼﾛｶｲﾝ注ﾎﾟﾘｱﾝﾌﾟ0.5% | B26: 40 | C26: 1 | D26: 52.1 | E26: 552 | F26: 10 | G26: 552 | H26: 10 | K26: 0 | L26: 本 | M26: =SUM(D26*K26) -> 0
A27: グリセオール注 ２００ｍＬＸ１０袋 | B27: 40 | C27: 1 | D27: 272.6 | K27: 11 | L27: 袋 | M27: =SUM(D27*K27) -> 2998.6
A28: ｸﾘﾝﾀﾞﾏｲｼﾝﾘﾝ酸ｴｽﾃﾙ注射液300 | B28: 40 | C28: 1 | D28: 247.2 | K28: 14 | L28: 本 | M28: =SUM(D28*K28) -> 3460.8
A29: ケイツーＮ静注１０ｍｇ ２ｍＬＸ１０管 | B29: 40 | C29: 1 | D29: 55 | K29: 10 | L29: 本 | M29: =SUM(D29*K29) -> 550
A30: ジアゼパム注射液「NIG」 | B30: 40 | C30: 1 | D30: 109 | K30: 19 | M30: =SUM(D30*K30) -> 2071
A31: ｼﾞｷﾞﾗﾉｹﾞﾝ注0.4ｍｇ | B31: 40 | C31: 1 | D31: 123.8 | K31: 1 | L31: 本 | M31: =SUM(D31*K31) -> 123.8
A32: 静注用ｷｼﾛｶｲﾝ2％ | B32: 40 | C32: 1 | D32: 107.1 | K32: 4 | L32: 本 | M32: =SUM(D32*K32) -> 428.4
A33: スルバシリン注 | B33: 40 | C33: 1 | D33: 538.3 | K33: 39 | L33: 本 | M33: =SUM(D33*K33) -> 20993.7
A34: 生食10ｍｌシリンジ | B34: 40 | C34: 1 | D34: 90 | K34: 155 | L34: 本 | M34: =SUM(D34*K34) -> 13950
A35: 生食溶解ｷｯﾄH100ｍｌ | B35: 40 | C35: 1 | D35: 188.8 | K35: 130 | L35: 本 | M35: =SUM(D35*K35) -> 24544
A36: セフィピム注 | B36: 40 | C36: 1 | D36: 469.8 | K36: 46 | L36: 本 | M36: =SUM(D36*K36) -> 21610.8
A37: セフタジジム静注用１ｇ １０Ｖ | B37: 40 | C37: 1 | D37: 405.4 | K37: 0 | L37: 本 | M37: =SUM(D37*K37) -> 0
A38: セフトリアキソン静注用1G | B38: 40 | C38: 1 | D38: 383.5 | K38: 74 | L38: 本 | M38: =SUM(D38*K38) -> 28379
A39: ｾﾞﾌﾟﾘｵﾝ水懸筋注100ｍｇ | B39: 40 | C39: 1 | D39: 38961 | K39: 3 | L39: 本 | M39: =SUM(D39*K39) -> 116883
A40: ｾﾞﾌﾟﾘｵﾝ水懸筋注150ｍｇ | B40: 40 | C40: 1 | D40: 49996 | K40: 1 | L40: 本 | M40: =SUM(D40*K40) -> 49996
A41: ｾﾞﾌﾟﾘｵﾝ水懸筋注50ｍｇ | B41: 40 | C41: 1 | D41: 24411 | K41: 1 | L41: 本 | M41: =SUM(D41*K41) -> 24411
A42: ｾﾞﾌﾟﾘｵﾝ水懸筋注75ｍｇ | B42: 40 | C42: 1 | D42: 32112 | K42: 1 | L42: 本 | M42: =SUM(D42*K42) -> 32112
... A55: トランサミン注 ５％ | B55: 40 | C55: 1 | D55: 57.5 | K55: 72 | L55: 本 | M55: =SUM(D55*K55) -> 4140
A56: ﾄﾘﾌﾘ-ﾄﾞ輸液 | B56: 40 | C56: 1 | D56: 228 | E56: 3806 | F56: 20 | G56: 3806 | H56: 20 | K56: 69 | L56: 袋 | M56: =SUM(D56*K56) -> 15732
A57: ドルミカム注10ｍｇ | B57: 7 | C57: 1 | D57: 88 | K57: 6 | L57: 本 | M57: =SUM(D57*K57) -> 528
A58: トロペロン注４ｍｇ | B58: 40 | C58: 1 | D58: 171.1 | K58: 10 | L58: 本 | M58: =SUM(D58*K58) -> 1711
A59: ネオファーゲン | B59: 40 | C59: 1 | D59: 48 | K59: 14 | L59: 本 | M59: =SUM(D59*K59) -> 672
...

Sheet 錠剤(集計）
A1: 2024年度 北山病院薬剤部 棚卸し | J1: 回転台 | M1: 分包機・散薬 | O1: 在庫棚 | P1: ヒート棚
A2: 商品名 | B2: 分類 | C2: 納入単価 | J2: 測定量（ｇ） | K2: 風袋 | L2: g/10T | M2: 測定量（ｇ） | N2: 風袋 | O2: 数量(錠） | P2: ﾋｰﾄ数 | Q2: 在庫総量 | R2: 単位 | S2: 在庫金額
A3: ｱｻﾞﾙﾌｨｼﾞﾝEN（500） | B3: 6 | C3: 26.46 | O3: 24 | P3: 100 | Q3: =SUM(O3:P3) -> 124 | R3: 錠 | S3: =SUM(C:C*Q:Q) -> 3281.04
A4: アゾセミド錠60mg | B4: 6 | C4: 10.95 | O4: 49 | P4: 46 | Q4: =SUM(O4:P4) -> 95 | S4: =SUM(C:C*Q:Q) -> 1040.25
A5: アナストロゾール（1） | B5: 6 | C5: 57.33 | O5: 27 | P5: 53 | Q5: =SUM(O5:P5) -> 80 | R5: 錠 | S5: =SUM(C:C*Q:Q) -> 4586.4
A6: イリボー（5） | B6: 6 | C6: 59.77 | O6: 58 | P6: 111 | Q6: =SUM(O6:P6) -> 169 | R6: 錠 | S6: =SUM(C:C*Q:Q) -> 10101.13
A7: エゼチミブOD10mg｢ﾄｰﾜ｣ | B7: 6 | C7: 27.2 | O7: 46 | P7: 27 | Q7: =SUM(O7:P7) -> 73 | S7: =SUM(C:C*Q:Q) -> 1985.6
A8: エリキュース錠2.5ｍｇ | B8: 6 | C8: 103.5 | L8: 0.9 | M8: 256 | N8: 250 | O8: 100 | P8: 1.5 | Q8: =SUM((J8-K8))+(M8-N8)*10/L8+O8+P8 -> 168.16667 | S8: =SUM(C:C*Q:Q) -> 17405.25
A9: エリスロシン錠200mg | B9: 6 | C9: 8.73 | O9: 0 | P9: 106 | Q9: =SUM(O9:P9) -> 106 | S9: =SUM(C:C*Q:Q) -> 925.38
A10: エンレスト錠100mg | B10: 6 | C10: 85.83 | O10: 0 | P10: 103 | Q10: =SUM(O10:P10) -> 103 | S10: =SUM(C:C*Q:Q) -> 8840.49
A11: オーグメンチン配合錠250ｍｇ | B11: 6 | C11: 40.7 | O11: 0 | P11: 63 | Q11: =SUM(O11:P11) -> 63 | S11: =SUM(C:C*Q:Q) -> 2564.1
A12: オルメテックOD錠10ｍｇ | B12: 6 | C12: 17.89 | L12: 0.8 | M12: 258 | N12: 250 | O12: 70 | P12: 100 | Q12: =SUM((J12-K12))+(M12-N12)*10/L12+O12+P12 -> 270 | S12: =SUM(C:C*Q:Q) -> 4830.3
A13: ク―ビビック錠50mg | B13: 6 | C13: 80.88 | O13: 0 | P13: 89 | Q13: =SUM(O13:P13) -> 89 | S13: =SUM(C:C*Q:Q) -> 7198.32
A14: クロピトグレル錠25ｍｇ | B14: 6 | C14: 11.38 | O14: 100 | P14: 88 | Q14: =SUM(O14:P14) -> 188 | S14: =SUM(C:C*Q:Q) -> 2139.44
A15: クロフェクトン錠２５ｍｇ | B15: 6 | C15: 15.77 | O15: 130 | P15: 36 | Q15: 166 | S15: =SUM(C:C*Q:Q) -> 2617.82
A16: シロドシンOD錠4mg | B16: 6 | C16: 12.04 | O16: 83 | P16: 93 | Q16: =SUM(O16:P16) -> 176 | S16: =SUM(C:C*Q:Q) -> 2119.04
A17: ストロメクトール | B17: 6 | C17: 522 | O17: 0 | P17: 74 | Q17: =SUM(O17:P17) -> 74 | S17: =SUM(C:C*Q:Q) -> 38628
A18: ｾﾗﾗ（50） | B18: 6 | C18: 39.2 | O18: 115 | P18: 100 | Q18: =SUM(O18:P18) -> 215 | R18: 錠 | S18: =SUM(C:C*Q:Q) -> 8428
A19: ダーブロック錠2mg | B19: 6 | C19: 143.55 | O19: 27 | P19: 39 | Q19: =SUM(O19:P19) -> 66 | S19: =SUM(C:C*Q:Q) -> 9474.3
A20: ﾀﾞｲﾌｪﾝ配合錠 | B20: 6 | C20: 14.61 | O20: 36 | P20: 62.5 | Q20: =SUM(O20:P20) -> 98.5 | R20: 錠 | S20: =SUM(C:C*Q:Q) -> 1439.085
A21: タクロリムスカプセル（1） | B21: 6 | C21: 136.75 | O21: 17 | P21: 102 | Q21: =SUM(O21:P21) -> 119 | S21: =SUM(C:C*Q:Q) -> 16273.25
A22: ﾀﾁｵﾝ（50） | B22: 6 | C22: 8.29 | O22: 0 | P22: 57 | Q22: =SUM(O22:P22) -> 57 | R22: 錠 | S22: =SUM(C:C*Q:Q) -> 472.53
A23: タリージェ錠5㎎ | B23: 6 | C23: 80.57 | O23: 130 | P23: 100 | Q23: =SUM(O23:P23) -> 230 | S23: =SUM(C:C*Q:Q) -> 18531.1
A24: タンボコール錠50ｍｇ | B24: 6 | C24: 41.39 | O24: 16 | P24: 120 | Q24: =SUM(O24:P24) -> 136 | S24: =SUM(C:C*Q:Q) -> 5629.04
A25: デノタスチュアブル配合 | B25: 6 | C25: 10.83 | O25: 0 | P25: 22 | Q25: =SUM(O25:P25) -> 22 | S25: =SUM(C:C*Q:Q) -> 238.26
A26: デュタステリドカプセル（0.5） | B26: 6 | C26: 26.53 | O26: 0 | P26: 35 | Q26: =SUM(O26:P26) -> 35 | S26: =SUM(C:C*Q:Q) -> 928.55
A27: トラゼンタ錠5ｍｇ | B27: 6 | C27: 108.68 | O27: 41 | P27: 155 | Q27: =SUM(O27:P27) -> 196 | S27: =SUM(C:C*Q:Q) -> 21301.28
A28: トラマールOD錠25 | B28: 6 | C28: 16.3 | O28: 0 | P28: 184 | Q28: =SUM(O28:P28) -> 184 | S28: =SUM(C:C*Q:Q) -> 2999.2
A29: ノベルジン錠25ｍｇ | B29: 6 | C29: 182.79 | O29: 100 | P29: 33 | Q29: =SUM(O29:P29) -> 133 | S29: =SUM(C:C*Q:Q) -> 24311.07
A30: ビ・シフロール錠0.125mg | B30: 6 | C30: 16.5 | O30: 0 | P30: 184 | Q30: =SUM(O30:P30) -> 184 | S30: =SUM(C:C*Q:Q) -> 3036
A31: ピーゼットシー錠 | B31: 6 | C31: 8.27 | O31: 100 | P31: 8 | Q31: =SUM(O31:P31) -> 108 | S31: =SUM(C:C*Q:Q) -> 893.16
A32: ピオグリタゾンOD錠15mg | B32: 6 | C32: 9.8 | O32: 54 | P32: 47 | Q32: =SUM(O32:P32) -> 101 | S32: =SUM(C:C*Q:Q) -> 989.8
A33: ビカルタミド | B33: 6 | C33: 109.47 | O33: 15 | P33: 60 | Q33: =SUM(O33:P33) -> 75 | R33: 錠 | S33: =SUM(C:C*Q:Q) -> 8210.25
A34: ﾋﾞｿﾌﾟﾛﾛｰﾙﾌﾏﾙ酸（0.625）「トーワ」 | B34: 6 | C34: 8.4 | O34: 162 | P34: 73 | Q34: =SUM(O34:P34) -> 235 | S34: =SUM(C:C*Q:Q) -> 1974
A35: ﾋﾞｿﾌﾟﾛﾛｰﾙﾌﾏﾙ酸（2.5）「トーワ」 | B35: 6 | C35: 8.4 | O35: 196 | P35: 100 | Q35: =SUM(O35:P35) -> 296 | S35: =SUM(C:C*Q:Q) -> 2486.4
A36: ビプレッソ徐放150ｍｇ | B36: 6 | C36: 126.33 | O36: 120 | P36: 100 | Q36: =SUM(O36:P36) -> 220 | S36: =SUM(C:C*Q:Q) -> 27792.6
A37: ビプレッソ徐放50ｍｇ | B37: 6 | C37: 47.72 | O37: 60 | P37: 0 | Q37: =SUM(O37:P37) -> 60 | S37: =SUM(C:C*Q:Q) -> 2863.2
A38: ビムパット100ｍｇ | B38: 6 | C38: 308.93 | O38: 30 | P38: 99 | Q38: =SUM(O38:P38) -> 129 | S38: =SUM(C:C*Q:Q) -> 39851.97
A39: ビムパット錠50ｍｇ | B39: 6 | C39: 189.27 | O39: 120 | P39: 100 | Q39: =SUM(O39:P39) -> 220 | S39: =SUM(C:C*Q:Q) -> 41639.4
A40: ピモペンダン錠 | B40: 6 | C40: 31.72 | O40: 0 | P40: 161 | Q40: =SUM(O40:P40) -> 161 | S40: =SUM(C:C*Q:Q) -> 5106.92
...

Sheet 散剤（集計）
A1: 2024年度 北山病院薬剤部 棚卸し | J1: 在庫 | K1: 分包機・散薬
A2: 商品名 | B2: 分類 | C2: 納入単価 | J2: 測定量（ｇ） | K2: 測定量（ｇ） | L2: 風袋 | M2: 在庫総量 | N2: 単位 | O2: 在庫金額
A3: アキネトン細粒1% | B3: 11 | C3: 20.23 | J3: 0 | K3: 0 | L3: 0 | M3: =SUM(K:K-L:L+J:J) -> 0 | N3: g | O3: =SUM(C:C*M:M) -> 0
A4: アスパラカリウム散50％ | B4: 11 | C4: 5.79 | J4: 500 | K4: 172 | L4: 115 | M4: =SUM(K:K-L:L+J:J) -> 557 | N4: g | O4: =SUM(C:C*M:M) -> 3225.03
A5: アドナ散 | B5: 11 | C5: 30.2 | J5: 100 | K5: 0 | L5: 0 | M5: =SUM(K:K-L:L+J:J) -> 100 | N5: ｇ | O5: =SUM(C:C*M:M) -> 3020
A6: ｱﾘﾋﾟﾌﾟﾗｿﾞｰﾙ散1％「ﾆﾌﾟﾛ」 | B6: 11 | C6: 17.2 | J6: 0 | K6: 142 | L6: 40 | M6: =SUM(K:K-L:L+J:J) -> 102 | N6: ｇ | O6: =SUM(C:C*M:M) -> 1754.4
A7: アレビアチン散１０％ | B7: 11 | C7: 10.79 | J7: 300 | K7: 276 | L7: 237 | M7: =SUM(K:K-L:L+J:J) -> 339 | N7: ｇ | O7: =SUM(C:C*M:M) -> 3657.81
A8: ウインタミン細粒（１０％） | B8: 11 | C8: 8.91 | J8: 0 | K8: 66 | L8: 42 | M8: =SUM(K:K-L:L+J:J) -> 24 | N8: ｇ | O8: =SUM(C:C*M:M) -> 213.84
A9: オランザピン細粒1％「ヨシトミ」 | B9: 11 | C9: 59.7 | J9: 100 | K9: 134 | L9: 43 | M9: =SUM(K:K-L:L+J:J) -> 191 | N9: ｇ | O9: =SUM(C:C*M:M) -> 11402.7
A10: カルバマゼピン細粒50％ | B10: 11 | C10: 20.18 | J10: 600 | K10: 236 | L10: 232 | M10: =SUM(K:K-L:L+J:J) -> 604 | N10: ｇ | O10: =SUM(C:C*M:M) -> 12188.72
A11: クエチアピン細粒50％ | B11: 11 | C11: 121.5 | J11: 100 | K11: 119 | L11: 50 | M11: =SUM(K:K-L:L+J:J) -> 169 | N11: ｇ | O11: =SUM(C:C*M:M) -> 20533.5
A12: グラマリール細粒10％ | B12: 11 | C12: 18.97 | J12: 0 | K12: 101 | L12: 64 | M12: =SUM(K:K-L:L+J:J) -> 37 | N12: ｇ | O12: =SUM(C:C*M:M) -> 701.89
A13: ｾﾝﾌﾞﾘ・重曹散｢ﾖｼﾀﾞ｣ | B13: 11 | C13: 6.5 | J13: 500 | K13: 249 | L13: 97 | M13: =SUM(K:K-L:L+J:J) -> 652 | N13: ｇ | O13: =SUM(C:C*M:M) -> 4238
A14: タンニン酸アルブミン「VTRS] | B14: 11 | C14: 6.36 | J14: 500 | K14: 346 | L14: 116 | M14: =SUM(K:K-L:L+J:J) -> 730 | N14: ｇ | O14: =SUM(C:C*M:M) -> 4642.8
... A16: テプレノン細粒１０％ | B16: 11 | C16: 8.73 | J16: 300 | K16: 298 | L16: 285 | M16: =SUM(K:K-L:L+J:J) -> 313 | N16: ｇ | O16: =SUM(C:C*M:M) -> 2732.49
A17: ドグマチール細粒 | B17: 11 | C17: 22.3 | J17: 0 | K17: 0 | M17: =SUM(K:K-L:L+J:J) -> 0 | N17: ｇ | O17: =SUM(C:C*M:M) -> 0
A18: トロペロン細粒1％ | B18: 11 | C18: 68.24 | J18: 100 | K18: 151 | L18: 98 | M18: =SUM(K:K-L:L+J:J) -> 153 | N18: ｇ | O18: =SUM(C:C*M:M) -> 10440.72
A19: ﾆｺﾁﾝ酸ｱﾐﾄﾞ散10％「ｿﾞﾝﾈ」 | B19: 11 | C19: 10.7 | J19: 426 | K19: 0 | M19: =SUM(K:K-L:L+J:J) -> 426 | N19: ｇ | O19: =SUM(C:C*M:M) -> 4558.2
A20: バルプロ酸Na徐放顆粒４０％ | B20: 11 | C20: 25.38 | J20: 1000 | K20: 472 | L20: 108 | M20: =SUM(K:K-L:L+J:J) -> 1364 | N20: ｇ | O20: =SUM(C:C*M:M) -> 34618.32
A21: ハロペリドール細粒１％ ｢ﾖｼﾄﾐ｣ | B21: 11 | C21: 9.99 | J21: 200 | K21: 149 | L21: 99 | M21: =SUM(K:K-L:L+J:J) -> 250 | N21: ｇ | O21: =SUM(C:C*M:M) -> 2497.5
A22: パントシン散（２０％） | B22: 11 | C22: 10.75 | J22: 200 | K22: 1223 | L22: 257 | M22: =SUM(K:K-L:L+J:J) -> 1166 | N22: ｇ | O22: =SUM(C:C*M:M) -> 12534.5
A23: ﾋﾞｵﾌｪﾙﾐﾝ配合散 | B23: 11 | C23: 5.26 | J23: 1200 | K23: 370 | L23: 284 | M23: =SUM(K:K-L:L+J:J) -> 1286 | N23: ｇ | O23: =SUM(C:C*M:M) -> 6764.36
A24: ファモチジン散１０％ | B24: 11 | C24: 39.5 | J24: 100 | K24: 78 | L24: 39 | M24: =SUM(K:K-L:L+J:J) -> 139 | N24: ｇ | O24: =SUM(C:C*M:M) -> 5490.5
A25: フェノバルビタール散１０％「ホエイ」 | B25: 11 | C25: 6.5 | J25: 265 | K25: 193 | L25: 58 | M25: =SUM(K:K-L:L+J:J) -> 400 | N25: ｇ | O25: =SUM(C:C*M:M) -> 2600
A26: フェロミア顆粒８．３％ | B26: 11 | C26: 9.02 | J26: 500 | K26: 97 | L26: 74 | M26: =SUM(K:K-L:L+J:J) -> 523 | N26: ｇ | O26: =SUM(C:C*M:M) -> 4717.46
A27: ブドウ糖 | B27: 11 | C27: 0.72 | J27: 750 | K27: 230 | L27: 73 | M27: =SUM(K:K-L:L+J:J) -> 907 | N27: ｇ | O27: =SUM(C:C*M:M) -> 653.04
A28: フロセミド細粒 ４％ 「ＥＭＥＣ」 | B28: 11 | C28: 12.45 | J28: 0 | K28: 250 | L28: 149 | M28: =SUM(K:K-L:L+J:J) -> 101 | N28: ｇ | O28: =SUM(C:C*M:M) -> 1257.45
A29: ブロナンセリン散2％「DSPB] | B29: 11 | C29: 86.38 | J29: 200 | K29: 67 | L29: 49 | M29: =SUM(K:K-L:L+J:J) -> 218 | N29: ｇ | O29: =SUM(C:C*M:M) -> 18830.84
A30: ブロムペリドール細粒1％ | B30: 11 | C30: 25.1 | J30: 0 | K30: 174 | L30: 75 | M30: =SUM(K:K-L:L+J:J) -> 99 | N30: ｇ | O30: =SUM(C:C*M:M) -> 2484.9
A31: ﾍﾞｻｺﾘﾝ散5％ | B31: 11 | C31: 8.1 | J31: 100 | K31: 110 | L31: 40 | M31: =SUM(K:K-L:L+J:J) -> 170 | N31: ｇ | O31: =SUM(C:C*M:M) -> 1377
... A37: レボトミン顆粒 １０％ | B37: 11 | C37: 12.73 | J37: 300 | K37: 118 | L37: 99 | M37: =SUM(K:K-L:L+J:J) -> 319 | N37: ｇ | O37: =SUM(C:C*M:M) -> 4060.87
A38: レボフロキサシン細粒10%「DSEP] | B38: 11 | C38: 26.63 | D38: 10600 | E38: 100 | F38: 10600 | G38: 100 | J38: 100 | K38: 79 | L38: 40 | M38: =SUM(K:K-L:L+J:J) -> 139 | N38: ｇ | O38: =SUM(C:C*M:M) -> 3701.57
A39: ロキソニン細粒１０％ | B39: 11 | C39: 13.21 | J39: 500 | K39: 263 | L39: 244 | M39: =SUM(K:K-L:L+J:J) -> 519 | N39: ｇ | O39: =SUM(C:C*M:M) -> 6855.99
A40: ロドピン細粒５０％ | B40: 11 | C40: 173.1 | J40: 100 | K40: 179 | L40: 154 | M40: =SUM(K:K-L:L+J:J) -> 125 | N40: ｇ | O40: =SUM(C:C*M:M) -> 21637.5
A41: 塩化ｶﾘｳﾑ | B41: 11 | C41: 2.67 | D41: 380 | E41: 50 | F41: 380 | G41: 50 | J41: 325 | K41: 292 | L41: 243 | M41: =SUM(K:K-L:L+J:J) -> 374 | N41: ｇ | O41: =SUM(C:C*M:M) -> 998.58
A42: 塩化ﾅﾄﾘｳﾑ | B42: 11 | C42: 0.81 | J42: 500 | K42: 58 | L42: 68 | M42: =SUM(K:K-L:L+J:J) -> 490 | N42: ｇ | O42: =SUM(C:C*M:M) -> 396.9
A43: 重ｶﾏ｢ﾖｼﾀﾞ｣(細粒状) | B43: 11 | C43: 1.49 | D43: 5255 | E43: 500 | F43: 5255 | G43: 500 | J43: 9000 | K43: 668 | L43: 78 | M43: =SUM(K:K-L:L+J:J) -> 9590 | N43: ｇ | O43: =SUM(C:C*M:M) -> 14289.1
A44: 炭酸水素ﾅﾄﾘｳﾑ | B44: 11 | C44: 0.66 | D44: 340 | E44: 50 | F44: 340 | G44: 50 | J44: 500 | K44: 131 | L44: 100 | M44: =SUM(K:K-L:L+J:J) -> 531 | N44: ｇ | O44: =SUM(C:C*M:M) -> 350.46
A45: 乳糖水和物｢ﾖｼﾀﾞ｣ | B45: 11 | C45: 1.39 | D45: 942 | E45: 50 | F45: 942 | G45: 50 | J45: 200 | K45: 210 | L45: 98 | M45: =SUM(K:K-L:L+J:J) -> 312 | N45: ｇ | O45: =SUM(C:C*M:M) -> 433.68
O46: =SUM(O3:O45) -> 260351.06

Sheet 漢方 (集計)
A1: 2024年度 北山病院薬剤部 棚卸し | K1: 在庫棚
A2: 商品名 | B2: 分類 | D2: 納入単価 | K2: 数量(錠） | L2: 単位 | M2: 在庫金額
A3: ｱﾐﾉﾚﾊﾞﾝEN配合散 50g/包 | B3: 12 | C3: 5 | D3: 395.23 | E3: 29152 | F3: 315 | G3: 29152 | H3: 315 | K3: 28 | L3: 包 | M3: =SUM(D:D*K:K) -> 11066.44
A4: シーピー配合顆粒 １ｇＸ１００８包 | B4: 12 | C4: 1 | D4: 5.62 | K4: 767 | L4: 包 | M4: =SUM(D:D*K:K) -> 4310.54
A5: クレメジン細粒2ｇ | B5: 12 | C5: 2 | D5: 93.26 | K5: 84 | L5: 包 | M5: =SUM(D:D*K:K) -> 7833.84
A6: トーワチーム配合顆粒(分包品1ｇ） | B6: 12 | C6: 1 | D6: 5.6 | K6: 654 | L6: 包 | M6: =SUM(D:D*K:K) -> 3662.4
A7: モビコール配合内用剤LD | B7: 12 | C7: 1 | D7: 56.17 | K7: 172 | L7: 包 | M7: =SUM(D:D*K:K) -> 9661.24
A8: SPトローチ | B8: 12 | C8: 1 | D8: 5.14 | E8: 9301 | F8: 105 | G8: 9301 | H8: 105 | K8: 1056 | L8: 錠 | M8: =SUM(D:D*K:K) -> 5427.84
A9: エビリファイ内用液分包3ｍｇ | B9: 12 | C9: 1 | D9: 93.14 | K9: 62 | L9: 包 | M9: =SUM(D:D*K:K) -> 5774.68
A10: エビリファイ内用液分包6ｍｇ | B10: 12 | C10: 1 | D10: 186.25 | K10: 58 | L10: 包 | M10: =SUM(D:D*K:K) -> 10802.5
A11: ポリスチレンスルホン酸ゼリー | B11: 12 | C11: 1 | D11: 64.1 | K11: 63 | L11: 個 | M11: =SUM(D:D*K:K) -> 4038.3
A12: リスパダール内用液 １ｍｇ／ｍＬ30ｍｌ | B12: 12 | C12: 1 | D12: 980 | K12: 0 | L12: 本 | M12: =SUM(D:D*K:K) -> 0
A13: リスパダール内用液分包0.5ｍｇ/0.5ｍｌ | B13: 12 | C13: 1 | D13: 16.68 | K13: 221 | L13: 包 | M13: =SUM(D:D*K:K) -> 3686.28
A14: リスパダール内用液分包1ｍｇ/1ｍｌ | B14: 12 | C14: 1 | D14: 32.68 | K14: 259 | L14: 包 | M14: =SUM(D:D*K:K) -> 8464.12
A15: リスペリドン内用液1ｍｇ/100ｍｌ | B15: 12 | C15: 1 | D15: 1634 | K15: 0 | L15: 本 | M15: =SUM(D:D*K:K) -> 0
A16: リスペリドン内用液分包0.5ｍｇ/0.5ｍｌ | B16: 12 | C16: 1 | D16: 13.18 | K16: 271 | L16: 包 | M16: =SUM(D:D*K:K) -> 3571.78
A17: リスペリドン内用液分包1ｍｇ/1ｍｌ | B17: 12 | C17: 1 | D17: 27.04 | K17: 165 | L17: 包 | M17: =SUM(D:D*K:K) -> 4461.6
A18: 007ﾂﾑﾗﾊﾁﾐｼﾞｵｳｶﾞﾝ2.5g/包 | B18: 13 | C18: 2.5 | D18: 22.26 | K18: 69 | L18: 包 | M18: =SUM(D:D*K:K) -> 1535.94
A19: 012ﾂﾑﾗｻｲｺｶﾘｭｳｺﾂﾎﾞﾚｲﾄｳ2.5g/包 | B19: 13 | C19: 2.5 | D19: 45.2 | K19: 145 | L19: 包 | M19: =SUM(D:D*K:K) -> 6554
A20: 016ﾂﾑﾗ ﾊﾝｹﾞｺｳﾎﾞｸﾄｳ2.5ｇ/包 | B20: 13 | C20: 2.5 | D20: 32.86 | K20: 103 | L20: 包 | M20: =SUM(D:D*K:K) -> 3384.58
... A37: ｸﾗｼｴ猪苓湯EK-40 2.0g/包 | B37: 13 | C37: 2 | D37: 26.9 | K37: 120 | L37: 包 | M37: =SUM(D:D*K:K) -> 3228
M38: =SUM(M3:M37) -> 276253.41

Sheet 外用 (集計)
A1: 2024年度 北山病院薬剤部 棚卸し | M1: =SUM(D:D*K:K) -> 0
A2: 商品名 | B2: 分類 | D2: 納入単価 | K2: 在庫総量 | L2: 単位 | M2: 在庫金額
A3: ｱｸｱﾁﾑ ｸﾘ-ﾑ1% 10ｇ/本 | B3: 30 | C3: 10 | D3: 196.5 | E3: 3870 | F3: 100 | G3: 3870 | H3: 100 | K3: 15 | L3: 本 | M3: =SUM(D:D*K:K) -> 2947.5
A4: ｱｽﾞﾉｰﾙ軟膏 20ｇ/本 | B4: 30 | C4: 2 | D4: 94.4 | K4: 57 | L4: 本 | M4: =SUM(D:D*K:K) -> 5380.8
A5: アフタッチ口腔用貼付剤２５μｇ ＰＴＰ １００錠 | B5: 30 | C5: 1 | D5: 22.7 | K5: 85 | L5: 錠 | M5: =SUM(D:D*K:K) -> 1929.5
A6: ウレパールクリーム10％ | B6: 30 | D6: 73 | K6: 5 | L6: 本 | M6: =SUM(D:D*K:K) -> 365
A7: オイラックスクリーム１０％ １０ｇＸ１０ | B7: 30 | C7: 1 | D7: 73.7 | K7: 38 | L7: 本 | M7: =SUM(D:D*K:K) -> 2800.6
A8: ｵｷｻﾛｰﾙ軟膏 10g/本 | B8: 30 | C8: 10 | D8: 488.7 | K8: 2 | L8: 本 | M8: =SUM(D:D*K:K) -> 977.4
A9: クレナフィン爪液 | B9: 30 | D9: 4497.2 | K9: 3 | L9: 本 | M9: =SUM(D:D*K:K) -> 13491.6
A10: ケトチフェン点鼻液 | B10: 30 | D10: 208.8 | K10: 7 | L10: 本 | M10: =SUM(D:D*K:K) -> 1461.6
A11: ゲンタマイシン軟膏0.1% 10g/本 | B11: 30 | C11: 10 | D11: 77.5 | K11: 36 | L11: 本 | M11: =SUM(D:D*K:K) -> 2790
A12: コールタイジン点鼻液 １５ｍＬＸ１０ | B12: 30 | C12: 15 | D12: 107.7 | K12: 14 | L12: 本 | M12: =SUM(D:D*K:K) -> 1507.8
A13: スピール膏Ｍ ＳＰＭ１６ ６枚 | B13: 30 | C13: 1 | D13: 66 | K13: 7 | L13: 枚 | M13: =SUM(D:D*K:K) -> 462
A14: スミスリンローション | B14: 30 | D14: 1975 | K14: 9 | L14: 本 | M14: =SUM(D:D*K:K) -> 17775
A15: ｿﾌﾗﾁｭｰﾙ貼付剤 | B15: 30 | C15: 1 | D15: 48.6 | K15: 7 | L15: 枚 | M15: =SUM(D:D*K:K) -> 340.2
A16: ﾀﾞｲｱｯﾌﾟ坐薬4 | B16: 30 | C16: 1 | D16: 49.18 | K16: 43 | L16: 個 | M16: =SUM(D:D*K:K) -> 2114.74
A17: タリビッド眼軟膏０．３％ 3.5g/本 | B17: 30 | C17: 3.5 | D17: 345 | E17: 894 | F17: 10 | G17: 894 | H17: 10 | K17: 15 | L17: 本 | M17: =SUM(D:D*K:K) -> 5175
A18: タリビッド耳科用液０．３％ ５ｍＬＸ５ | B18: 30 | C18: 5 | D18: 495.4 | E18: 718 | F18: 100 | G18: 718 | H18: 100 | K18: 3 | L18: 本 | M18: =SUM(D:D*K:K) -> 1486.2
A19: デキサメタゾン口腔用軟膏 | B19: 30 | D19: 195 | K19: 20 | L19: 本 | M19: =SUM(D:D*K:K) -> 3900
A20: テクスメテンユニバーサルクリーム0.1％ | B20: 30 | D20: 172.8 | K20: 7 | L20: 本 | M20: =SUM(D:D*K:K) -> 1209.6
A21: ﾃﾙﾋﾞﾅﾌｨﾝｸﾘ-ﾑ1% 10g/本 | B21: 30 | C21: 10 | D21: 89.9 | K21: 34 | L21: 本 | M21: =SUM(D:D*K:K) -> 3056.6
A22: ﾃﾙﾋﾞﾅﾌｨﾝﾞ液1% 10g/本 | B22: 30 | C22: 10 | D22: 90 | E22: 1000 | F22: 100 | G22: 1000 | H22: 100 | K22: 17 | L22: 本 | M22: =SUM(D:D*K:K) -> 1530
A23: ﾃﾞﾙﾓｿﾞ-ﾙG ｸﾘ-ﾑ 5g/本 | B23: 30 | C23: 5 | D23: 123.38 | K23: 0 | L23: 本 | M23: =SUM(D:D*K:K) -> 0
A24: ﾃﾞﾙﾓｿﾞ-ﾙG軟膏 5g/本 | B24: 30 | C24: 5 | D24: 123.38 | K24: 351 | L24: 本 | M24: =SUM(D:D*K:K) -> 43306.38
A25: ﾃﾞﾙﾓﾍﾞ-ﾄ軟膏0.05% 5g/本 | B25: 30 | C25: 5 | D25: 71 | K25: 34 | L25: 本 | M25: =SUM(D:D*K:K) -> 2414
A26: ニゾラールクリーム２％ 10g/本 | B26: 30 | C26: 10 | D26: 154.55 | K26: 31 | L26: 本 | M26: =SUM(D:D*K:K) -> 4791.05
A27: ニゾラールローション２％ 10g/本 | B27: 30 | C27: 10 | D27: 200.9 | K27: 3 | L27: 本 | M27: =SUM(D:D*K:K) -> 602.7
A28: 尿素クリーム | B28: 30 | C28: 20 | D28: 58 | K28: 10 | L28: 本 | M28: =SUM(D:D*K:K) -> 580
A29: ネオメドロールEE軟膏 | B29: 30 | D29: 121.6 | K29: 9 | L29: 本 | M29: =SUM(D:D*K:K) -> 1094.4
A30: ﾋﾞﾀﾞﾗﾋﾞﾝ軟膏3%｢MEEK｣ 5g/本 | B30: 30 | C30: 5 | D30: 348 | E30: 168 | F30: 50 | G30: 168 | H30: 50 | K30: 7 | L30: 本 | M30: =SUM(D:D*K:K) -> 2436
A31: ﾋﾙﾄﾞｲﾄﾞ ｿﾌﾄ軟膏0.3% 25g/本 | B31: 30 | C31: 25 | D31: 412 | E31: 701 | F31: 100 | G31: 701 | H31: 100 | K31: 21 | L31: 本 | M31: =SUM(D:D*K:K) -> 8652
A32: プロスタンディン軟膏 30g/本 | B32: 30 | C32: 30 | D32: 1002 | E32: 1998 | F32: 250 | G32: 1998 | H32: 250 | K32: 1 | L32: 本 | M32: =SUM(D:D*K:K) -> 1002
A33: ベタメタゾン吉草酸ローション | B33: 30 | C33: 10 | D33: 77.2 | K33: 10 | L33: 本 | M33: =SUM(D:D*K:K) -> 772
A34: ﾍﾓﾚｯｸｽ軟膏 2g/本 | B34: 30 | C34: 2 | D34: 37.94 | K34: 151 | L34: 本 | M34: =SUM(D:D*K:K) -> 5728.94
A35: マイザー軟膏 | B35: 30 | C35: 5 | D35: 53.4 | K35: 44 | L35: 本 | M35: =SUM(D:D*K:K) -> 2349.6
A36: リドメックスコーワ軟膏0.3％ | B36: 30 | D36: 147 | K36: 7 | L36: 本 | M36: =SUM(D:D*K:K) -> 1029
A37: ﾘﾝﾃﾞﾛﾝ-V ｸﾘ-ﾑ0.12% 5g/本 | B37: 30 | C37: 5 | D37: 82.3 | K37: 36 | L37: 本 | M37: =SUM(D:D*K:K) -> 2962.8
A38: ロコイド軟膏0.1％ | B38: 30 | D38: 66.3 | K38: 37 | L38: 本 | M38: =SUM(D:D*K:K) -> 2453.1
A39: ５％ サリチル酸ワセリン 軟膏 ５００ｇ | B39: 31 | C39: 50 | D39: 36.6 | K39: 290 | L39: ｇ | M39: =SUM(D:D*K:K) -> 10614
A40: アドエア５００ディスカス６０吸入用 ６０ブリスターＸ１ | B40: 31 | C40: 1 | D40: 3641 | E40: 10857 | F40: 500 | G40: 10857 | H40: 500 | K40: 2 | L40: 個 | M40: =SUM(D:D*K:K) -> 7282
...

Sheet 残量上位
A1: 2024年度 北山病院 棚卸
A3: 商品名 | B3: 納入単価 | C3: 在庫総量 | D3: 在庫金額 | F3: 年間購入量 | G3: F-C
A4: 重ｶﾏ｢ﾖｼﾀﾞ｣(細粒状) | B4: 1.49 | C4: 9590 | D4: 14289.1 | F4: 20000 | G4: =C4-F4 -> -10410
A5: イルベサルタン錠50ｍｇ｢ｻﾜｲ｣ | B5: 8.7 | C5: 9549 | D5: 83076.3 | F5: 12700 | G5: =C5-F5 -> -3151
A6: メコバラミン錠５００「トーワ」 | B6: 4.96 | C6: 4336.8571 | D6: 21510.811 | F6: 15400 | G6: =C6-F6 -> -11063.143
A7: ビペリデン錠1MG | B7: 5.08 | C7: 4128 | D7: 20970.24 | F7: 43000 | G7: =C7-F7 -> -38872
A8: マグミット錠330mg | B8: 3.42 | C8: 4082.8947 | D8: 13963.5 | F8: 77000 | G8: =C8-F8 -> -72917.105
A9: ミルタザピン錠15ｍｇ｢ｻﾜｲ｣ | B9: 15.94 | C9: 3725.6667 | D9: 59387.127 | F9: 21100 | G9: =C9-F9 -> -17374.333
A10: ロキソプロフェン錠６０ｍｇ | B10: 8.7 | C10: 3468.4211 | D10: 30175.263 | F10: 37000 | G10: =C10-F10 -> -33531.579
A11: アトルバスタチンOD錠10ｍｇ | B11: 12.64 | C11: 3349.4444 | D11: 42336.978 | F11: 6600 | G11: =C11-F11 -> -3250.5556
A12: ミドドリン塩酸塩錠2ｍｇ | B12: 7.39 | C12: 3296 | D12: 24357.44 | F12: 6500 | G12: =C12-F12 -> -3204
A13: モサプリドクエン酸塩錠 | B13: 8.3 | C13: 3117 | D13: 25871.1 | F13: 52500 | G13: =C13-F13 -> -49383
A14: 炭酸リチウム錠100 | B14: 7.92 | C14: 3060 | D14: 24235.2 | F14: 3500 | G14: =C14-F14 -> -440
A15: エチゾラム錠1mg｢ｱﾒﾙ｣ | B15: 8.3 | C15: 3032.9231 | D15: 25173.262 | F15: 7000 | G15: =C15-F15 -> -3967.0769
... A43: ソラナックス０．４ｍｇ錠 | B43: 5.22 | C43: 2066.3333 | D43: 10786.26 | F43: 37500 | G43: =C43-F43 -> -35433.667
A44: オランザピンOD錠5ｍｇ | B44: 16.71 | C44: 1996 | D44: 33353.16
A45: ヒルナミン錠5mg | B45: 5.08 | C45: 1970.0909 | D45: 10008.062
A46: デエビゴ錠5ｍｇ | B46: 71.12 | C46: 1937.3333 | D46: 137783.15
A47: ベンザリン錠 | B47: 7.49 | C47: 1931.2857 | D47: 14465.33
A48: ｱﾘﾋﾟﾌﾟﾗｿﾞｰﾙOD錠12ｍｇ「ﾆﾌﾟﾛ」 | B48: 21.12 | C48: 1904 | D48: 40212.48
A49: ﾊﾛﾍﾟﾘﾄﾞｰﾙ錠 ０．７５ｍｇ | B49: 5.1 | C49: 1854.5 | D49: 9457.95
A50: トリアゾラム錠０．２５ｍｇ | B50: 5.36 | C50: 1846.1111 | D50: 9895.1556
A51: ジメチコン錠40ｍｇ | B51: 4.77 | C51: 1826.4286 | D51: 8712.0643
A52: ﾘﾎﾞﾄﾘ-ﾙ錠0.5ｍｇ | B52: 8.25 | C52: 1826 | D52: 15064.5
A53: エソメプラゾールカプセル（20） | B53: 37.24 | C53: 1818 | D53: 67702.32
A54: メマンチン塩酸塩OD２０ｍｇ | B54: 63.33 | C54: 1805 | D54: 114310.65
A55: ソラナックス０．８ｍｇ錠 | B55: 7.62 | C55: 1792.8462 | D55: 13661.488
... A672: 大塚食塩注１０％20ｍｌ | B672: 86.4 | C672: 0 | D672: 0
D673: =SUM(D4:D672) -> 10421362

Sheet sheet2
B1: 商品名 | C1: 納入単価 | D1: 在庫総量 | E1: 在庫金額 | G1: *在庫
A2: * | B2: 007ﾂﾑﾗﾊﾁﾐｼﾞｵｳｶﾞﾝ2.5g/包 | C2: 22.26 | D2: 69 | E2: 1535.94 | F2: =E2-E3 -> -19969.06
B3: 007 ﾂﾑﾗ ハチミジオウガン | C3: 935 | D3: 23 | E3: 21505 | F3: =E3-E3 -> 0
A4: * | B4: 012ﾂﾑﾗｻｲｺｶﾘｭｳｺﾂﾎﾞﾚｲﾄｳ2.5g/包 | C4: 45.2 | D4: 145 | E4: 6554 | F4: =E4-E5 -> -61798
B5: 012 ｻｲｺｶﾘｭｳｺﾂﾎﾞﾚｲﾄｳ | C5: 8544 | D5: 8 | E5: 68352 | F5: =E5-E5 -> 0
A6: * | B6: 016ﾂﾑﾗ ﾊﾝｹﾞｺｳﾎﾞｸﾄｳ2.5ｇ/包 | C6: 32.86 | D6: 103 | E6: 3384.58 | F6: =E6-E7 -> 3384.58
F7: =E7-E7 -> 0
A8: * | B8: 017 ﾂﾑﾗ ｺﾞﾚｲｻﾝ 2.5g/包 | C8: 30.3 | D8: 272 | E8: 8241.6 | F8: =E8-E9 -> -123502.4
B9: 017 ﾂﾑﾗ ｺﾞﾚｲｻﾝ | C9: 5728 | D9: 23 | E9: 131744 | F9: =E9-E9 -> 0
A10: * | B10: 020 ﾂﾑﾗ ﾎﾞｳｲｵｳｷﾞﾄｳ 2.5g/包 | C10: 21.39 | D10: 61 | E10: 1304.79 | F10: =E10-E11 -> -6781.21
B11: 020 ﾂﾑﾗ ボウイオウギトウ | C11: 4043 | D11: 2 | E11: 8086 | F11: =E11-E11 -> 0
A12: * | B12: 043ﾂﾑﾗﾘｯｸﾝｼﾄｳ 2.5g/包 | C12: 40.08 | D12: 258 | E12: 10340.64 | F12: =E12-E13 -> -35115.36
B13: 043 ツムラ リツクンシトウ | C13: 7576 | D13: 6 | E13: 45456 | F13: =E13-E13 -> 0
A14: * | B14: 048 ﾂﾑﾗ ｼﾞｭｳｾﾞﾝﾀｲﾎﾄｳ 2.5g/包 | C14: 41 | D14: 341 | E14: 13981 | F14: =E14-E15 -> 6231
B15: 048 ﾂﾑﾗ ｼﾞｭｳｾﾞﾝﾀｲﾎﾄｳ | C15: 7750 | D15: 1 | E15: 7750 | F15: =E15-E15 -> 0
A16: * | B16: 054 ﾂﾑﾗ ﾖｸｶﾝｻﾝ 2.5g/包 | C16: 36.24 | D16: 756 | E16: 27397.44 | F16: =E16-E17 -> -1158160.6
B17: 054 ﾂﾑﾗ ﾖｸｶﾝｻﾝ | C17: 8385 | D17: 253 | E17: 1185558 | F17: =E17-E17 -> 0
A18: * | B18: 062 ﾂﾑﾗ ﾎﾞｳﾌｳﾂｳｼｮｳｻﾝ 2.5g/包 | C18: 31.06 | D18: 510 | E18: 15840.6 | F18: =E18-E19 -> -72224.4
B19: 062 ﾂﾑﾗ ﾎﾞｳﾌｳﾂｳｼﾖｳｻﾝ | C19: 5871 | D19: 15 | E19: 88065 | F19: =E19-E19 -> 0
A20: * | B20: 068ﾂﾑﾗｼｬｸﾔｸｶﾝｿﾞｳﾄｳ 2.5g/包 | C20: 23.62 | D20: 64 | E20: 1511.68 | F20: =E20-E21 -> -16344.32
B21: 068 ｼｬｸﾔｸｶﾝｿﾞｳﾄｳ | C21: 992 | D21: 18 | E21: 17856 | F21: =E21-E21 -> 0
A22: * | B22: 083ﾂﾑﾗﾖｸｶﾝｻｶﾁﾝﾋﾟﾊﾝｹﾞ 2.5g/包 | C22: 32.09 | D22: 273 | E22: 8760.57 | F22: =E22-E23 -> -161059.43
B23: 083 ﾂﾑﾗ ﾖｸｶﾝｻﾝｶﾁﾝﾋﾟﾊﾝｹﾞ | C23: 6065 | D23: 28 | E23: 169820 | F23: =E23-E23 -> 0
A24: * | B24: 100 ﾂﾑﾗ ﾀﾞｲｹﾝﾁｭｳﾄｳ 2.5g/包 | C24: 30.84 | D24: 636 | E24: 19614.24 | F24: =E24-E25 -> -784649.76
B25: 100 ﾂﾑﾗ ﾀﾞｲｹﾝﾁﾕｳﾄｳ | C25: 5828 | D25: 138 | E25: 804264 | F25: =E25-E25 -> 0
A26: * | B26: 112ﾂﾑﾗﾁｮﾚｲﾄｳｺﾝｺﾞｳｼﾓﾂﾄｳ 2.5ｇ/包 | C26: 52.02 | D26: 46 | E26: 2392.92 | F26: =E26-E27 -> -36937.08
B27: 112 チョレイトウゴウシモットウ | C27: 2185 | D27: 18 | E27: 39330 | F27: =E27-E27 -> 0
A28: * | B28: 25MG ｱﾘﾅﾐﾝ F糖衣錠 | C28: 5.26 | D28: 959 | E28: 5044.34 | F28: =E28-E29 -> -60674.66
B29: 25MG ｱﾘﾅﾐﾝ F糖衣錠 | C29: 8412 | D29: 31 | E29: 65719 | F29: =E29-E29 -> 0
A30: * | B30: ５％ サリチル酸ワセリン 軟膏 ５００ｇ | C30: 36.6 | D30: 290 | E30: 10614 | F30: =E30-E31 -> 10614
F31: =E31-E31 -> 0
A32: * | B32: 葛根湯 ＥＫ－１ 2.5g/包 | C32: 22.72 | D32: 454 | E32: 10314.88 | F32: =E32-E33 -> -49796.12
B33: ＥＫ１ 葛根湯エキス細粒 | C33: 6679 | D33: 9 | E33: 60111 | F33: =E33-E33 -> 0
A34: * | F34: =E34-E35 -> -10640
B35: EK108 人参養栄湯エキス細粒 | C35: 2128 | D35: 5 | E35: 10640 | F35: =E35-E35 -> 0
A36: * | B36: 柴苓湯 ＥＫ－１１４ 2.7g/包 | C36: 111.83 | D36: 267 | E36: 29858.61 | F36: =E36-E37 -> -68775.39
B37: EK114 柴苓湯 | C37: 32878 | D37: 3 | E37: 98634 | F37: =E37-E37 -> 0
A38: * | B38: 黄連解毒湯 KB-15 3.0g/包 | C38: 24.17 | D38: 129 | E38: 3117.93 | F38: =E38-E39 -> -26317.07
B39: EK15 黄連解毒湯エキス細粒 | C39: 1015 | D39: 29 | E39: 29435 | F39: =E39-E39 -> 0
A40: * | B40: 加味逍遥散KB-24 3.0g/包 | C40: 33.26 | D40: 152 | E40: 5055.52 | F40: =E40-E41 -> -63397.48
...
