Workbook

Sheet 元データ
A1: 品名 | B1: 2025年度卸 | C1: 包装形態 | D1: 容量 | E1: メーカー | F1: 新単位薬価 | G1: 2025年度薬価 | H1: 単位数量 | I1: 薬価単位 | J1: 2025年納入価格 | K1: 単位納入価 | L1: 分類 | M1: 単位当たり利益 | N1: マスタと一致 | O1: 薬品棚
A2: 007 ﾂﾑﾗ ハチミジオウガン | B2: メディセオ | C2: 粉 | D2: 2.5ｇｘ189 | E2: ツムラ | F2: 9.8 | G2: 4630.5 | H2: =G2/F2 -> 472.5 | I2: ｇ | J2: 4093 | K2: =J2/H2 -> 8.6624339 | L2: 5.2 | M2: =F2-K2 -> 1.1375661 | N2: =IF(match_results!C2="完全一致","〇","×") -> ×
A3: 007 ﾂﾑﾗ ハチミジオウガン | C3: 粉 | D3: 2.5ｇｘ42 | E3: ツムラ | F3: 9.8 | G3: 1029 | H3: =G3/F3 -> 105 | I3: ｇ | J3: 935 | K3: =J3/H3 -> 8.9047619 | L3: 5.2 | M3: =F3-K3 -> 0.8952381 | N3: =IF(match_results!C3="完全一致","〇","×") -> ×
A4: 012 ﾂﾑﾗ ｻｲｺｶﾘｭｳｺﾂﾎﾞﾚｲﾄｳ | B4: メディセオ | C4: 粉 | D4: 2.5ｇｘ189 | E4: ツムラ | F4: 20.3 | G4: 9591.75 | H4: =G4/F4 -> 472.5 | I4: g | J4: 8544 | K4: =J4/H4 -> 18.08254 | L4: 5.2 | M4: =F4-K4 -> 2.2174603 | N4: =IF(match_results!C4="完全一致","〇","×") -> ×
A5: 016 ﾂﾑﾗ ハンゲコウボクトウ | B5: メディセオ | C5: 粉 | D5: 2.5ｇｘ189 | E5: ツムラ | F5: 14.6 | G5: 6898.5 | H5: =G5/F5 -> 472.5 | I5: ｇ | J5: 6211 | K5: =J5/H5 -> 13.144974 | L5: 5.2 | M5: =F5-K5 -> 1.4550265 | N5: =IF(match_results!C5="完全一致","〇","×") -> × | O5: 4
A6: 017 ﾂﾑﾗ ｺﾞﾚｲｻﾝ | B6: メディセオ | C6: 粉 | D6: 2.5ｇｘ189 | E6: ツムラ | F6: 13.6 | G6: 6426 | H6: =G6/F6 -> 472.5 | I6: g | J6: 5728 | K6: =J6/H6 -> 12.122751 | L6: 5.2 | M6: =F6-K6 -> 1.4772487 | N6: =IF(match_results!C6="完全一致","〇","×") -> × | O6: 4
A7: 019 ツムラ ショウセイリュウトウ | B7: メディセオ | C7: 粉 | D7: 3ｇX42 | E7: ツムラ | F7: 12.8 | G7: 1612.8 | H7: =G7/F7 -> 126 | I7: g | J7: 1465 | K7: =J7/H7 -> 11.626984 | L7: 5.2 | M7: =F7-K7 -> 1.1730159 | N7: =IF(match_results!C7="完全一致","〇","×") -> × | O7: 4
A8: 043 ツムラ リツクンシトウ | B8: メディセオ | C8: 粉 | D8: 2.5ｇｘ189 | E8: ツムラ | F8: 18 | G8: 8505 | H8: =G8/F8 -> 472.5 | I8: g | J8: 7576 | K8: =J8/H8 -> 16.033862 | L8: 5.2 | M8: =F8-K8 -> 1.9661376 | N8: =IF(match_results!C8="完全一致","〇","×") -> × | O8: 4
A9: 048 ﾂﾑﾗ ｼﾞｭｳｾﾞﾝﾀｲﾎﾄｳ | C9: 粉 | D9: 2.5ｇｘ189包 | E9: ツムラ | F9: 18.4 | G9: 8694 | H9: =G9/F9 -> 472.5 | I9: g | J9: 7750 | K9: =J9/H9 -> 16.402116 | L9: 5.2 | M9: =F9-K9 -> 1.9978836 | N9: =IF(match_results!C9="完全一致","〇","×") -> × | O9: 4
A10: 054 ﾂﾑﾗ ﾖｸｶﾝｻﾝ | B10: メディセオ | C10: 粉 | D10: 2.5ｇX189 | E10: ツムラ | F10: 16.1 | G10: 7607.25 | H10: =G10/F10 -> 472.5 | I10: g | J10: 6849 | K10: =J10/H10 -> 14.495238 | L10: 5.2 | M10: =F10-K10 -> 1.6047619 | N10: =IF(match_results!C10="完全一致","〇","×") -> × | O10: 4
A11: 062 ﾂﾑﾗ ﾎﾞｳﾌｳﾂｳｼﾖｳｻﾝ | B11: メディセオ | C11: 粉 | D11: 2.5ｇｘ189 | E11: ツムラ | F11: 13.8 | G11: 6520.5 | H11: =G11/F11 -> 472.5 | I11: g | J11: 5871 | K11: =J11/H11 -> 12.425397 | L11: 5.2 | M11: =F11-K11 -> 1.3746032 | N11: =IF(match_results!C11="完全一致","〇","×") -> × | O11: 4
A12: 068 ﾂﾑﾗ ｼｬｸﾔｸｶﾝｿﾞｳﾄｳ | B12: メディセオ | C12: 粉 | D12: 2.5ｇｘ42 | E12: ツムラ | F12: 10.4 | G12: 1092 | H12: =G12/F12 -> 105 | I12: g | J12: 992 | K12: =J12/H12 -> 9.447619 | L12: 5.2 | M12: =F12-K12 -> 0.95238095 | N12: =IF(match_results!C12="完全一致","〇","×") -> × | O12: 4
A13: 083 ﾂﾑﾗ ﾖｸｶﾝｻﾝｶﾁﾝﾋﾟﾊﾝｹﾞ | B13: メディセオ | C13: 粉 | D13: 2.5ｇｘ189 | E13: ツムラ | F13: 14.4 | G13: 6804 | H13: =G13/F13 -> 472.5 | I13: g | J13: 6065 | K13: =J13/H13 -> 12.835979 | L13: 5.2 | M13: =F13-K13 -> 1.5640212 | N13: =IF(match_results!C13="完全一致","〇","×") -> × | O13: 4
A14: 100 ﾂﾑﾗ ﾀﾞｲｹﾝﾁﾕｳﾄｳ | B14: メディセオ | C14: 粉 | D14: 2.5ｇX189 | E14: ツムラ | F14: 13.7 | G14: 6473.25 | H14: =G14/F14 -> 472.5 | I14: g | J14: 5828 | K14: =J14/H14 -> 12.334392 | L14: 5.2 | M14: =F14-K14 -> 1.3656085 | N14: =IF(match_results!C14="完全一致","〇","×") -> × | O14: 4
A15: 108 ツムラ ニンジンヨウエイトウ | B15: メディセオ | C15: 粉 | D15: 3ｇｘ42包 | E15: ツムラ | F15: 20.1 | G15: 2532.6 | H15: =G15/F15 -> 126 | I15: ｇ | J15: 2301 | K15: =J15/H15 -> 18.261905 | L15: 5.2 | M15: =F15-K15 -> 1.8380952 | N15: =IF(match_results!C15="完全一致","〇","×") -> × | O15: 4
A16: 112 ツムラ チョレイトウゴウシモットウ | C16: 粉 | D16: 2.5ｇｘ42 | E16: ツムラ | F16: 22.9 | G16: 2404.5 | H16: =G16/F16 -> 105 | I16: g | J16: 2185 | K16: =J16/H16 -> 20.809524 | L16: 5.2 | M16: =F16-K16 -> 2.0904762 | N16: =IF(match_results!C16="完全一致","〇","×") -> × | O16: 4
A17: 25ｍｇｱﾘﾅﾐﾝ F糖衣錠 | B17: メディセオ | C17: PTP | D17: 100Ｔ | E17: 武田薬品工業 | F17: 6.1 | G17: 610 | H17: =G17/F17 -> 100 | I17: 錠 | J17: 544 | K17: =J17/H17 -> 5.44 | L17: 3.1.2 | M17: =F17-K17 -> 0.66 | N17: =IF(match_results!C17="完全一致","〇","×") -> × | O17: 5
A18: ＥＫ１ 葛根湯エキス細粒 | B18: メディセオ | C18: 粉 | D18: 2.5ｇ×294 | E18: クラシエ | F18: 10.2 | G18: 7497 | H18: =G18/F18 -> 735 | I18: g | J18: 6679 | K18: =J18/H18 -> 9.0870748 | L18: 5.2 | M18: =F18-K18 -> 1.1129252 | N18: =IF(match_results!C18="完全一致","〇","×") -> × | O18: 4
A19: EK114 柴苓湯 | B19: メディセオ | C19: 粉 | D19: 2.7ｇ×２９４ | E19: クラシエ | F19: 46.8 | G19: 37149.84 | H19: =G19/F19 -> 793.8 | I19: g | J19: 33097 | K19: =J19/H19 -> 41.694381 | L19: 5.2 | M19: =F19-K19 -> 5.1056185 | N19: =IF(match_results!C19="完全一致","〇","×") -> × | O19: 4
A20: EK15 黄連解毒湯エキス細粒 | B20: メディセオ | C20: 粉 | D20: 2ｇｘ42包 | E20: クラシエ | F20: 13.3 | G20: 1117.2 | H20: =G20/F20 -> 84 | I20: g | J20: 1015 | K20: =J20/H20 -> 12.083333 | L20: 5.2 | M20: =F20-K20 -> 1.2166667 | N20: =IF(match_results!C20="完全一致","〇","×") -> × | O20: 4
A21: EK19 小青竜湯エキス細粒 | B21: アルフレッサ | D21: 2ｇｘ42包 | E21: クラシエ | F21: 24.1 | G21: 2024.4 | H21: =G21/F21 -> 84 | I21: g | J21: 1840 | K21: =J21/H21 -> 21.904762 | L21: 5.2 | M21: =F21-K21 -> 2.1952381 | N21: =IF(match_results!C21="完全一致","〇","×") -> × | O21: 4
A22: ＥＫ24 加味逍遥散料エキス細粒 | B22: メディセオ | C22: 粉 | D22: 2ｇｘ42包 | E22: クラシエ | F22: 18.3 | G22: 1537.2 | H22: =G22/F22 -> 84 | I22: g | J22: 1397 | K22: =J22/H22 -> 16.630952 | L22: 5.2 | M22: =F22-K22 -> 1.6690476 | N22: =IF(match_results!C22="完全一致","〇","×") -> × | O22: 4
A23: ＥＫ40 猪苓湯エキス細粒 | B23: メディセオ | C23: 粉 | D23: 2ｇｘ42包 | E23: クラシエ | F23: 14.8 | G23: 1243.2 | H23: =G23/F23 -> 84 | I23: g | J23: 1130 | K23: =J23/H23 -> 13.452381 | L23: 5.2 | M23: =F23-K23 -> 1.347619 | N23: =IF(match_results!C23="完全一致","〇","×") -> × | O23: 4
A24: EK41 補中益気湯エキス細粒 | B24: メディセオ | C24: 粉 | D24: 2.5ｇｘ294 | E24: クラシエ | F24: 20.4 | G24: 14994 | H24: =G24/F24 -> 735 | I24: g | J24: 13358 | K24: =J24/H24 -> 18.17415 | L24: 5.2 | M24: =F24-K24 -> 2.2258503 | N24: =IF(match_results!C24="完全一致","〇","×") -> × | O24: 4
A25: EPLカプセル250ｍｇ 販売中止 | B25: アルフレッサ | C25: ＰＴＰ | D25: ４００Ｐ | E25: アルフレッサファーマ | F25: 6.1 | G25: 2440 | H25: =G25/F25 -> 400 | I25: cap | J25: 2218 | K25: =J25/H25 -> 5.545 | L25: 2.1.8 | M25: =F25-K25 -> 0.555 | N25: =IF(match_results!C25="完全一致","〇","×") -> × | O25: 5
A26: SPトローチ0.25ｍｇ「明治」 | B26: メディセオ | C26: PTP | D26: 1200T | E26: meijiseika | F26: 5.9 | G26: 7080 | H26: =G26/F26 -> 1200 | I26: 錠 | J26: 6435 | K26: =J26/H26 -> 5.3625 | L26: 2.3.9 | M26: =F26-K26 -> 0.5375 | N26: =IF(match_results!C26="完全一致","〇","×") -> 〇 | O26: 3
A27: T72 ヨクイニンエキス錠「コタロー」 | B27: メディセオ | C27: バラ | D27: 126Tx10 | E27: 小太郎漢方 | F27: 6.5 | G27: 8190 | H27: =G27/F27 -> 1260 | I27: 錠 | J27: 7445 | K27: =J27/H27 -> 5.9087302 | L27: 5.2 | M27: =F27-K27 -> 0.59126984 | N27: =IF(match_results!C27="完全一致","〇","×") -> × | O27: 15
A28: アーチスト錠1.25ｍｇ | B28: メディセオ | C28: PTP | D28: 100T | E28: 第一三共 | F28: 10.4 | G28: 1040 | H28: =G28/F28 -> 100 | I28: 錠 | J28: 926 | K28: =J28/H28 -> 9.26 | L28: 2.1.4 | M28: =F28-K28 -> 1.14 | N28: =IF(match_results!C28="完全一致","〇","×") -> 〇 | O28: 5
A29: アイファガン点眼液0.1％ | D29: 5ｍｌｘ5 | E29: 武田薬品工業 | F29: 268.9 | G29: 6722.5 | H29: =G29/F29 -> 25 | I29: ｍｌ | J29: 5858 | K29: =J29/H29 -> 234.32 | L29: 1.3.1 | M29: =F29-K29 -> 34.58 | N29: =IF(match_results!C29="完全一致","〇","×") -> × | O29: 3
A30: アウィクリ注 フレックスタッチ 総量300単位 | B30: アルフレッサ | D30: 0.43ｍｌｘ2kit | E30: ノボノルディスク | F30: 2081 | G30: 4162 | H30: =G30/F30 -> 2 | I30: kit | J30: 3689 | K30: =J30/H30 -> 1844.5 | L30: 2.4.9 | M30: =F30-K30 -> 236.5 | N30: =IF(match_results!C30="完全一致","〇","×") -> × | O30: 15
A31: アキネトン細粒1％ | C31: 粉 | D31: 100ｇ | E31: 住友ファーマ | F31: 21.4 | G31: 2140 | H31: =G31/F31 -> 100 | I31: ｇ | J31: 1907 | K31: =J31/H31 -> 19.07 | L31: 1.1.6 | M31: =F31-K31 -> 2.33 | N31: =IF(match_results!C31="完全一致","〇","×") -> × | O31: 2
A32: アキネトン注射液５ｍｇ | D32: １ｍＬ×5０Ａ | E32: 住友ファーマ | F32: 61 | G32: 3050 | H32: =G32/F32 -> 50 | I32: A | J32: 2718 | K32: =J32/H32 -> 54.36 | L32: 1.1.6 | M32: =F32-K32 -> 6.64 | N32: =IF(match_results!C32="完全一致","〇","×") -> × | O32: 9
A33: アクアチムクリーム1% | B33: スズケン | D33: 10ｇX10 | E33: 大塚製薬 | F33: 20.7 | G33: 2070 | H33: =G33/F33 -> 100 | I33: ｇ | J33: 1841 | K33: =J33/H33 -> 18.41 | L33: 2.6.3 | M33: =F33-K33 -> 2.29 | N33: =IF(match_results!C33="完全一致","〇","×") -> 〇 | O33: 3
A34: アクチット輸液 | B34: メディセオ | D34: 500ｍｌｘ20袋 | E34: 扶桑薬品 | F34: 341 | G34: 6820 | H34: =G34/F34 -> 20 | I34: 袋 | J34: 6075 | K34: =J34/H34 -> 303.75 | L34: 3.3.1 | M34: =F34-K34 -> 37.25 | N34: =IF(match_results!C34="完全一致","〇","×") -> × | O34: 10
A35: アクトシン軟膏３％ | B35: アルフレッサ | D35: 30ｇ | E35: マルホ | F35: 50 | G35: 1500 | H35: =G35/F35 -> 30 | I35: g | J35: 1251 | K35: =J35/H35 -> 41.7 | L35: 2.6.9 | M35: =F35-K35 -> 8.3 | N35: =IF(match_results!C35="完全一致","〇","×") -> 〇 | O35: 3
A36: アザルフィジンＥＮ錠500ｍｇ | B36: KSK | C36: PTP | D36: 100Ｔ | E36: ファイザー | F36: 25.9 | G36: 2590 | H36: =G36/F36 -> 100 | I36: 錠 | J36: 2308 | K36: =J36/H36 -> 23.08 | L36: 6.2.1 | M36: =F36-K36 -> 2.82 | N36: =IF(match_results!C36="完全一致","〇","×") -> 〇 | O36: 3
A37: アシクロビル点滴静注用250ｍｇ「サワイ」 | D37: 10V | E37: 沢井製薬 | F37: 368 | G37: 3680 | H37: =G37/F37 -> 10 | I37: V | J37: 3238 | K37: =J37/H37 -> 323.8 | L37: 6.2.5 | M37: =F37-K37 -> 44.2 | N37: =IF(match_results!C37="完全一致","〇","×") -> 〇 | O37: 9
A38: アジスロマイシン錠250ｍｇ「ﾄｰﾜ」 | C38: ＰＴＰ | D38: 60T | E38: 東和薬品 | F38: 60.7 | G38: 3642 | H38: =G38/F38 -> 60 | I38: 錠 | J38: 2952 | K38: =J38/H38 -> 49.2 | L38: 6.1.4 | M38: =F38-K38 -> 11.5 | N38: =IF(match_results!C38="完全一致","〇","×") -> 〇 | O38: 1
A39: アジルサルタンOD錠20ｍｇ「サワイ」 | B39: アルフレッサ | C39: PTP | D39: 100T | E39: 沢井製薬 | F39: 27.4 | G39: 2740 | H39: =G39/F39 -> 100 | I39: 錠 | J39: 2082 | K39: =J39/H39 -> 20.82 | L39: 2.1.4 | M39: =F39-K39 -> 6.58 | N39: =IF(match_results!C39="完全一致","〇","×") -> 〇 | O39: 1
A40: アジルサルタンOD錠20ｍｇ「サワイ」 | B40: アルフレッサ | C40: バラ | D40: 200T | E40: 沢井製薬 | F40: 27.4 | G40: 5480 | H40: =G40/F40 -> 200 | I40: 錠 | J40: 4165 | K40: =J40/H40 -> 20.825 | L40: 2.1.4 | M40: =F40-K40 -> 6.575 | N40: =IF(match_results!C40="完全一致","〇","×") -> 〇 | O40: 5
...

Sheet マスタ非採用削除
A1: 薬品マスタ | B1: 46085
A2: PK | C2: TZMYAKUHINMEISHO | D2: TZMYAKUHIN | E2: TZMYAKUHINBETSUKIHONJOHOKUBUN | G2: TZMYAKUKA | H2: TZMYAKUHINMEISHO | I2: TZMYAKUHIN | K2: TZMYAKUHINBETSUKIHONJOHOKUBUN
A3: YAKUHIN_CODE | C3: YAKUHIN_NM | D3: HOST_CODE | E3: SAIYO_DIV | G3: YAKKA | H3: YAKUHIN_NM_KANA | I3: ZAIKEI_CODE | K3: DOKUGEKIYAKU_DIV
A4: コード(区分値) | B4: コード | C4: 名称 | D4: ホストコード | E4: 採用区分（区分値）(区分値) | F4: 採用区分（区分値） | G4: 薬価 | H4: カナ名称 | I4: 剤形(区分値) | J4: 剤形 | K4: 毒劇薬（区分値）(区分値) | L4: 毒劇薬（区分値） | M4: 棚
A5: ｱｴﾝ001 | B5: ｱｴﾝ001 | C5: 亜鉛華軟膏「ニッコー」 | D5: ｱｴﾝｶﾅﾝ | E5: 1 | G5: 3.3 | H5: ｱｴﾝｶﾅﾝｺｳ｢ﾆｯｺｰ｣ | I5: 14 | J5: 軟膏 | K5: 0 | M5: 7
A6: ｱｷﾈ002 | B6: ｱｷﾈ002 | C6: アキネトン注射液５ｍｇ | D6: ｱｷﾈﾄﾝﾁ | E6: 1 | G6: 61 | H6: ｱｷﾈﾄﾝﾁｭｳｼｬｴｷ5mg | I6: 25 | J6: 注射剤 | K6: 2 | M6: 9
A7: ｱｸｱ001 | B7: ｱｸｱ001 | C7: アクアチムクリーム１％ | D7: ｱｸｱﾁﾑ | E7: 1 | G7: 20.7 | H7: ｱｸｱﾁﾑｸﾘｰﾑ1% | I7: 15 | J7: クリーム | K7: 0 | M7: 3
A8: ｱｸﾁ002 | B8: ｱｸﾁ002 | C8: アクチット輸液 | E8: 1 | G8: 341 | H8: ｱｸﾁﾂﾄﾕｴｷ | I8: 25 | J8: 注射剤 | K8: 0 | M8: 10
A9: ｱｸﾄ001 | B9: ｱｸﾄ001 | C9: アクトシン軟膏３％ | D9: ｱｸﾄｼﾝ | E9: 1 | G9: 50 | H9: ｱｸﾄｼﾝﾅﾝｺｳ3% | I9: 14 | J9: 軟膏 | K9: 0 | M9: 15
A10: ｱｻﾙ001 | B10: ｱｻﾙ001 | C10: アザルフィジンＥＮ錠５００ｍｇ | D10: ｱｻﾞﾙ1 | E10: 2 | G10: 25.9 | H10: ｱｻﾞﾙﾌｨｼﾞﾝENｼﾞｮｳ500mg | I10: 1 | J10: 錠剤 | K10: 0 | M10: 3
A11: ｱｼｸ001 | B11: ｱｼｸ001 | C11: アシクロビル点滴静注用２５０ｍｇ「サワイ」 | D11: ｱｼｸﾛ | E11: 2 | G11: 368 | H11: ｱｼｸﾛﾋﾞﾙﾃﾝﾃｷｼﾞｮｳﾁｭｳﾖｳ250mg｢ｻﾜｲ｣ | I11: 25 | J11: 注射剤 | K11: 0 | M11: 9
A12: ｱｼｽ001 | B12: ｱｼｽ001 | C12: アジスロマイシン錠２５０ｍｇ「トーワ」 | D12: ｱｼﾞｽ | E12: 1 | G12: 60.7 | H12: ｱｼﾞｽﾛﾏｲｼﾝｼﾞｮｳ250mg｢ﾄｰﾜ｣ | I12: 1 | J12: 錠剤 | K12: 0 | M12: 1
A13: ｱｼﾙ003 | B13: ｱｼﾙ003 | C13: アジルサルタンＯＤ錠２０ｍｇ「サワイ」 | E13: 1 | G13: 27.4 | H13: ｱｼﾞﾙｻﾙﾀﾝODｼﾞﾖｳ20MGｻﾜｲ | I13: 1 | J13: 錠剤 | K13: 0 | M13: 5
A14: ｱｽｺ003 | B14: ｱｽｺ003 | C14: アスコルビン酸注５００ｍｇ「イセイ」 | E14: 1 | G14: 100 | H14: ｱｽｺﾙﾋﾞﾝｻﾝﾁﾕｳ500MGｲｾｲ | I14: 25 | J14: 注射剤 | K14: 0 | M14: 11
A15: ｱｽﾉ002 | B15: ｱｽﾉ002 | C15: アズノール軟膏０．０３３％ | D15: ｱｽﾞﾉ3 | E15: 1 | G15: 8.03 | H15: ｱｽﾞﾉｰﾙﾅﾝｺｳ0.033% | I15: 14 | J15: 軟膏 | K15: 0 | M15: 3
A16: ｱｽﾊ001 | B16: ｱｽﾊ001 | C16: アスパラ－ＣＡ錠２００ | D16: ｱｽﾊﾟ | E16: 1 | G16: 5.9 | H16: ｱｽﾊﾟﾗ-CAｼﾞｮｳ200 | I16: 1 | J16: 錠剤 | K16: 0 | M16: 5
A17: ｱｽﾊ002 | B17: ｱｽﾊ002 | C17: アスパラカリウム錠３００ｍｇ | D17: ｱｽﾊﾟﾗ | E17: 1 | G17: 6.1 | H17: ｱｽﾊﾟﾗｶﾘｳﾑｼﾞｮｳ300mg | I17: 1 | J17: 錠剤 | K17: 0 | M17: 1
A18: ｱｽﾊ003 | B18: ｱｽﾊ003 | C18: アスパラカリウム散５０％ | D18: ｱｽﾊﾟ1 | E18: 1 | G18: 6.7 | H18: ｱｽﾊﾟﾗｶﾘｳﾑｻﾝ50% | I18: 3 | J18: 散 | K18: 0 | M18: 2
A19: ｱｽﾊ004 | B19: ｱｽﾊ004 | C19: アスパラギン酸カリウム注１０ｍＥｑキット「テルモ」 | D19: ｱｽﾊﾟ2 | E19: 1 | G19: 181 | H19: ｱｽﾊﾟﾗｷﾞﾝｻﾝｶﾘｳﾑﾁｭｳ10mEqｷｯﾄ｢ﾃﾙﾓ｣ | I19: 25 | J19: 注射剤 | K19: 0 | M19: 9
A20: ｱｽﾚ001 | B20: ｱｽﾚ001 | C20: アズレン点眼液０．０２％「ニットー」 | D20: ｱｽﾞﾚ | E20: 1 | G20: 91.6 | H20: ｱｽﾞﾚﾝﾃﾝｶﾞﾝｴｷ0.02%｢ﾆｯﾄｰ｣ | I20: 21 | J20: 点眼剤 | K20: 0 | M20: 3
A21: ｱｾﾘ001 | B21: ｱｾﾘ001 | C21: アセリオ静注液１０００ｍｇバッグ | D21: ｱｾﾘ | E21: 2 | G21: 298 | H21: ｱｾﾘｵｼﾞｮｳﾁｭｳｴｷ1000mgﾊﾞｯｸﾞ | I21: 25 | J21: 注射剤 | K21: 2 | M21: 8
A22: ｱｾﾚ001 | B22: ｱｾﾚ001 | C22: アセレンド注１００μｇ | D22: ｱｾﾚ | E22: 2 | G22: 1646 | H22: ｱｾﾚﾝﾄﾞﾁｭｳ100μg | I22: 25 | J22: 注射剤 | K22: 2 | M22: 9
A23: ｱｿｾ002 | B23: ｱｿｾ002 | C23: アゾセミド錠３０ｍｇ「ＤＳＥＰ」 | D23: ｱｿﾞｾ2 | E23: 2 | G23: 10.4 | H23: ｱｿﾞｾﾐﾄﾞｼﾞｮｳ30mg｢DSEP｣ | I23: 1 | J23: 錠剤 | K23: 0 | M23: 3
A24: ｱﾀﾗ001 | B24: ｱﾀﾗ001 | C24: アタラックス錠２５ｍｇ | D24: ｱﾀﾗｯ2 | E24: 1 | G24: 6.1 | H24: ｱﾀﾗｯｸｽｼﾞｮｳ25mg | I24: 1 | J24: 錠剤 | K24: 0 | M24: 5
A25: ｱﾀﾗ002 | B25: ｱﾀﾗ002 | C25: アダラートＣＲ錠２０ｍｇ | D25: ｱﾀﾞﾗ | E25: 1 | G25: 13.2 | H25: ｱﾀﾞﾗｰﾄCRｼﾞｮｳ20mg | I25: 1 | J25: 錠剤 | K25: 2 | M25: 6
A26: ｱﾁｽ001 | B26: ｱﾁｽ001 | C26: アーチスト錠１．２５ｍｇ | D26: ｱｰﾁ | E26: 1 | G26: 10.4 | H26: ｱｰﾁｽﾄｼﾞｮｳ1.25mg | I26: 1 | J26: 錠剤 | K26: 0 | M26: 5
... A30: ｱﾄﾅ003 | B30: ｱﾄﾅ003 | C30: アドナ散１０％ | D30: ｱﾄﾞﾅ2* | E30: 1 | G30: 32.5 | H30: ｱﾄﾞﾅｻﾝ10% | I30: 3 | J30: 散 | K30: 0 | M30: 2
A31: ｱﾄﾌ001 | B31: ｱﾄﾌ001 | C31: アドフィードパップ４０ｍｇ | E31: 1 | G31: 17.6 | H31: ｱﾄﾞﾌｲ-ﾄﾞﾊﾟﾂﾌﾟ40MG | I31: 19 | J31: 貼付剤 | K31: 0 | M31: 12
A32: ｱﾄﾓ001 | B32: ｱﾄﾓ001 | C32: アトモキセチンカプセル１０ｍｇ「サワイ」 | D32: ｱﾄ10 | E32: 1 | G32: 50.3 | H32: ｱﾄﾓｷｾﾁﾝｶﾌﾟｾﾙ10mg｢ｻﾜｲ｣ | I32: 2 | J32: カプセル | K32: 2 | M32: 6
A33: ｱﾄﾓ005 | B33: ｱﾄﾓ005 | C33: アトモキセチンカプセル４０ｍｇ「ＶＴＲＳ」 | E33: 1 | G33: 64.7 | H33: ｱﾄﾓｷｾﾁﾝｶﾌﾟｾﾙ40MGVTRS | I33: 2 | J33: カプセル | K33: 2 | M33: 6
A34: ｱﾄﾙ002 | B34: ｱﾄﾙ002 | C34: アトルバスタチンＯＤ錠１０ｍｇ「トーワ」 | E34: 1 | G34: 13.9 | H34: ｱﾄﾙﾊﾞｽﾀﾁﾝODｼﾞﾖｳ10MGﾄ-ﾜ | I34: 1 | J34: 錠剤 | K34: 0 | M34: 5
A35: ｱﾄﾛ001 | B35: ｱﾄﾛ001 | C35: アトロピン硫酸塩注０．５ｍｇ「ニプロ」 | D35: ｱﾄﾛ | E35: 1 | G35: 100 | H35: ｱﾄﾛﾋﾟﾝﾘﾕｳｻﾝｴﾝﾁﾕｳ0.5MGﾆﾌﾟﾛ | I35: 25 | J35: 注射剤 | K35: 2 | M35: 9
A36: ｱﾅｽ002 | B36: ｱﾅｽ002 | C36: アナストロゾール錠１ｍｇ「サワイ」 | E36: 2 | G36: 58.5 | H36: ｱﾅｽﾄﾛｿﾞ-ﾙｼﾞﾖｳ1MGｻﾜｲ | I36: 1 | J36: 錠剤 | K36: 2 | M36: 3
A37: ｱﾅﾌ002 | B37: ｱﾅﾌ002 | C37: アナフラニール点滴静注液２５ｍｇ | D37: ｱﾅﾌﾗﾆｰ | E37: 2 | G37: 225 | H37: ｱﾅﾌﾗﾆｰﾙﾃﾝﾃｷｼﾞｮｳﾁｭｳｴｷ25mg | I37: 25 | J37: 注射剤 | K37: 2 | M37: 15
A38: ｱﾈｷ001 | B38: ｱﾈｷ001 | C38: アネキセート注射液０．５ｍｇ | D38: ｱﾈｷｾ | E38: 1 | G38: 2001 | H38: ｱﾈｷｾｰﾄﾁｭｳｼｬｴｷ0.5mg | I38: 25 | J38: 注射剤 | K38: 2 | M38: 9
A39: ｱﾏﾝ001 | B39: ｱﾏﾝ001 | C39: アマンタジン塩酸塩錠５０ｍｇ「杏林」 | D39: ｱﾏﾝﾀ | E39: 1 | G39: 6.1 | H39: ｱﾏﾝﾀｼﾞﾝｴﾝｻﾝｴﾝｼﾞｮｳ50mg｢ｷｮｳﾘﾝ｣ | I39: 1 | J39: 錠剤 | K39: 0 | M39: 5
A40: ｱﾐｵ001 | B40: ｱﾐｵ001 | C40: アミオダロン塩酸塩速崩錠５０ｍｇ「ＴＥ」 | D40: ｱﾐｵ | E40: 2 | G40: 44.1 | H40: ｱﾐｵﾀﾞﾛﾝｴﾝｻﾝｴﾝｿｸﾎｳｼﾞｮｳ50mg｢TE｣ | I40: 1 | J40: 錠剤 | K40: 1 | M40: 3
A41: ｱﾐﾃ001 | B41: ｱﾐﾃ001 | C41: アミティーザカプセル２４μｇ | D41: ｱﾐﾃ | E41: 1 | G41: 96.9 | H41: ｱﾐﾃｨｰｻﾞｶﾌﾟｾﾙ24μg | I41: 2 | J41: カプセル | K41: 0 | M41: 5
A42: ｱﾐﾉ001 | B42: ｱﾐﾉ001 | C42: アミノレバンＥＮ配合散 | D42: ｱﾐﾉﾚ1* | E42: 1 | G42: 8.88 | H42: ｱﾐﾉﾚﾊﾞﾝENﾊｲｺﾞｳｻﾝ | I42: 3 | J42: 散 | K42: 0 | M42: 15
A43: ｱﾐﾉ002 | B43: ｱﾐﾉ002 | C43: アミノレバン点滴静注（用時購入） | E43: 2 | G43: 715 | H43: ｱﾐﾉﾚﾊﾞﾝﾃﾝﾃｷｼﾞﾖｳﾁﾕｳ | I43: 25 | J43: 注射剤 | K43: 0 | M43: 15
...

Sheet match_results
A1: A行番号 | B1: A薬品名 | C1: 判定 | D1: 候補1_薬品名 | E1: 候補1_行番号 | F1: 候補2_薬品名 | G1: 候補2_行番号 | H1: 候補3_薬品名 | I1: 候補3_行番号 | J1: 候補4_薬品名 | K1: 候補4_行番号 | L1: 候補5_薬品名 | M1: 候補5_行番号 | N1: 候補6_薬品名 | O1: 候補6_行番号 | P1: 候補7_薬品名 | Q1: 候補7_行番号 | R1: 候補8_薬品名 | S1: 候補8_行番号 | T1: 候補9_薬品名 | U1: 候補9_行番号 | V1: 候補10_薬品名 | W1: 候補10_行番号 | X1: 候補11_薬品名 | Y1: 候補11_行番号 | Z1: 候補12_薬品名 | AA1: 候補12_行番号 | AB1: 候補13_薬品名 | AC1: 候補13_行番号 | AD1: 候補14_薬品名 | AE1: 候補14_行番号 | AF1: 候補15_薬品名 | AG1: 候補15_行番号 | AH1: 候補16_薬品名 | AI1: 候補16_行番号 | AJ1: 候補17_薬品名 | AK1: 候補17_行番号 | AL1: 候補18_薬品名 | AM1: 候補18_行番号 | AN1: 候補19_薬品名 | AO1: 候補19_行番号 | AP1: 候補20_薬品名 | AQ1: 候補20_行番号 | AR1: 候補21_薬品名 | AS1: 候補21_行番号 | AT1: 候補22_薬品名 | AU1: 候補22_行番号 | AV1: 候補23_薬品名 | AW1: 候補23_行番号 | AX1: 候補24_薬品名 | AY1: 候補24_行番号 | AZ1: 候補25_薬品名 | BA1: 候補25_行番号 | BB1: 候補26_薬品名 | BC1: 候補26_行番号 | BD1: 候補27_薬品名 | BE1: 候補27_行番号 | BF1: 候補28_薬品名 | BG1: 候補28_行番号 | BH1: 候補29_薬品名 | BI1: 候補29_行番号 | BJ1: 候補30_薬品名 | BK1: 候補30_行番号 | BL1: 候補31_薬品名 | BM1: 候補31_行番号 | BN1: 候補32_薬品名 | BO1: 候補32_行番号 | BP1: 候補33_薬品名 | BQ1: 候補33_行番号 | BR1: 候補34_薬品名 | BS1: 候補34_行番号 | BT1: 候補35_薬品名 | BU1: 候補35_行番号 | BV1: 候補36_薬品名 | BW1: 候補36_行番号 | BX1: 候補37_薬品名 | BY1: 候補37_行番号 | BZ1: 候補38_薬品名 | CA1: 候補38_行番号 | CB1: 候補39_薬品名 | CC1: 候補39_行番号 | CD1: 候補40_薬品名 | CE1: 候補40_行番号
A2: 1 | B2: ００７ ツムラ ハチミジオウガン | C2: 薬価一致候補 | D2: ツムラ八味地黄丸エキス顆粒（医療用） | E2: 295 | F2: ロペミンカプセル１ｍｇ | G2: 675
A3: 2 | B3: ００７ ツムラ ハチミジオウガン | C3: 薬価一致候補 | D3: ツムラ八味地黄丸エキス顆粒（医療用） | E3: 295 | F3: ロペミンカプセル１ｍｇ | G3: 675
A4: 3 | B4: ０１２ ツムラ サイコカリュウコツボレイトウ | C4: 薬価一致候補 | D4: ツムラ柴胡加竜骨牡蛎湯エキス顆粒（医療用） | E4: 296
A5: 4 | B5: ０１６ ツムラ ハンゲコウボクトウ | C5: 薬価一致候補 | D5: ツムラ半夏厚朴湯エキス顆粒（医療用） | E5: 297 | F5: パロキセチンＯＤ錠１０ｍｇ「トーワ」 | G5: 405
A6: 5 | B6: ０１７ ツムラ ゴレイサン | C6: 薬価一致候補 | D6: ツムラ五苓散エキス顆粒（医療用） | E6: 298
A7: 6 | B7: ０１９ ツムラ ショウセイリュウトウ | C7: 薬価一致候補 | D7: ゲーベンクリーム１％ | E7: 167 | F7: ツムラ小青竜湯エキス顆粒（医療用） | G7: 299 | H7: トレドミン錠２５ｍｇ | I7: 363
A8: 7 | B8: ０４３ ツムラ リツクンシトウ | C8: 薬価一致候補 | D8: ツムラ六君子湯エキス顆粒（医療用） | E8: 301 | F8: ブロナンセリン錠４ｍｇ「ＤＳＰＢ」 | G8: 493
A9: 8 | B9: ０４８ ツムラ ジュウゼンタイホトウ | C9: 薬価一致候補 | D9: ガランタミンＯＤ錠４ｍｇ「日医工」 | E9: 115
A10: 9 | B10: ０５４ ツムラ ヨクカンサン | C10: 薬価一致候補 | D10: グラマリール錠５０ｍｇ | E10: 146 | F10: クロフェクトン錠２５ｍｇ | G10: 159 | H10: ツムラ抑肝散エキス顆粒（医療用） | I10: 302
A11: 10 | B11: ０６２ ツムラ ボウフウツウシヨウサン | C11: 薬価一致候補 | D11: ツムラ防風通聖散エキス顆粒（医療用） | E11: 303 | F11: ロキソニン細粒１０％ | G11: 664 | H11: ロラメット錠１．０ | I11: 677
A12: 11 | B12: ０６８ ツムラ シャクヤクカンゾウトウ | C12: 薬価一致候補 | D12: アゾセミド錠３０ｍｇ「ＤＳＥＰ」 | E12: 19 | F12: アーチスト錠１．２５ｍｇ | G12: 22 | H12: アムロジピンＯＤ錠２．５ｍｇ「明治」 | I12: 40 | J12: イルベサルタン錠５０ｍｇ「サワイ」 | K12: 64 | L12: インデラル錠１０ｍｇ | M12: 69 | N12: ウルソデオキシコール酸錠１００ｍｇ「サワイ」 | O12: 72 | P12: エナラプリルマレイン酸塩錠５ｍｇ「サワイ」 | Q12: 81 | R12: オロパタジン塩酸塩ＯＤ錠５ｍｇ「トーワ」 | S12: 111 | T12: カルベジロール錠１０ｍｇ「ＤＳＥＰ」 | U12: 121 | V12: カルボシステイン錠２５０ｍｇ「トーワ」 | W12: 122 | X12: クエチアピン錠１２．５ｍｇ「アメル」 | Y12: 130 | Z12: クエチアピン錠２５ｍｇ「アメル」 | AA12: 131 | AB12: グリメピリドＯＤ錠１ｍｇ「トーワ」 | AC12: 154 | AD12: ジスチグミン臭化物錠５ｍｇ「ＮＩＧ」 | AE12: 194 | AF12: チラーヂンＳ錠２５μｇ | AG12: 291 | AH12: チラーヂンＳ錠５０μｇ | AI12: 292 | AJ12: ツムラ芍薬甘草湯エキス顆粒（医療用） | AK12: 304 | AL12: テルミサルタンＯＤ錠２０ｍｇ「トーワ」 | AM12: 332 | AN12: トランサミンカプセル２５０ｍｇ | AO12: 349 | AP12: ナトリックス錠１ | AQ12: 368 | AR12: ニルバジピン錠４ｍｇ「サワイ」 | AS12: 382 | AT12: ビソプロロールフマル酸塩錠２．５ｍｇ「トーワ」 | AU12: 427 | AV12: ビソプロロールフマル酸塩錠０．６２５ｍｇ「トーワ」 | AW12: 428 | AX12: ファモチジンＤ錠２０ｍｇ「サワイ」 | AY12: 447 | AZ12: フェノバール錠３０ｍｇ | BA12: 454 | BB12: プラバスタチンＮａ錠５ｍｇ「サワイ」 | BC12: 471 | BD12: ブロチゾラム錠０．２５ｍｇ「ヨシトミ」 | BE12: 491 | BF12: ベザフィブラートＳＲ錠２００ｍｇ「日医工」 | BG12: 508 | BH12: ボグリボースＯＤ錠０．２ｍｇ「トーワ」 | BI12: 530 | BJ12: メイラックス錠１ｍｇ | BK12: 560 | BL12: メトホルミン塩酸塩錠２５０ｍｇＭＴ「ＤＳＰＢ」 | BM12: 565 | BN12: モサプリドクエン酸塩錠５ｍｇ「日医工」 | BO12: 573 | BP12: リオレサール錠５ｍｇ | BQ12: 598 | BR12: リスペリドンＯＤ錠０．５ｍｇ「アメル」 | BS12: 614 | BT12: リスペリドンＯＤ錠１ｍｇ「アメル」 | BU12: 615 | BV12: リスペリドンＯＤ錠２ｍｇ「アメル」 | BW12: 616 | BX12: リボトリール錠１ｍｇ | BY12: 627 | BZ12: レバミピド錠１００ｍｇ「オーツカ」 | CA12: 649 | CB12: ロスバスタチン錠２．５ｍｇ「トーワ」 | CC12: 668 | CD12: ワーファリン錠１ｍｇ | CE12: 681
A13: 12 | B13: ０８３ ツムラ ヨクカンサンカチンピハンゲ | C13: 薬価一致候補 | D13: セルトラリン錠２５ｍｇ「明治」 | E13: 239 | F13: ツムラ抑肝散加陳皮半夏エキス顆粒（医療用） | G13: 305
A14: 13 | B14: １００ ツムラ ダイケンチユウトウ | C14: 薬価一致候補 | D14: ツムラ大建中湯エキス顆粒（医療用） | E14: 306
A15: 14 | B15: １０８ ツムラ ニンジンヨウエイトウ | C15: 薬価一致候補 | D15: ツムラ人参養栄湯エキス顆粒（医療用） | E15: 307
A16: 15 | B16: １１２ ツムラ チョレイトウゴウシモットウ | C16: 薬価一致候補 | D16: ツムラ猪苓湯合四物湯エキス顆粒（医療用） | E16: 308 | F16: ホーリンＶ腟用錠１ｍｇ | G16: 540
A17: 16 | B17: ２５ｍｇアリナミン Ｆ糖衣錠 | C17: 薬価一致候補 | D17: アスパラカリウム錠３００ｍｇ | E17: 13 | F17: アタラックス錠２５ｍｇ | G17: 20 | H17: アマンタジン塩酸塩錠５０ｍｇ「杏林」 | I17: 35 | J17: ２５ｍｇアリナミンＦ糖衣錠 | K17: 43 | L17: アリピプラゾール錠１ｍｇ「サワイ」 | M17: 48 | N17: アルファカルシドールカプセル０．５μｇ「フソー」 | O17: 51 | P17: ＥＰＬカプセル２５０ｍｇ | Q17: 59 | R17: 硝酸イソソルビド徐放カプセル２０ｍｇ「Ｓｔ」 | S17: 203 | T17: セレコキシブ錠１００ｍｇ「ＤＳＥＰ」 | U17: 240 | V17: ソラナックス０．４ｍｇ錠 | W17: 253 | X17: チザニジン錠１ｍｇ「トーワ」 | Y17: 286 | Z17: テオフィリン徐放Ｕ錠２００ｍｇ「トーワ」 | AA17: 313 | AB17: トラセミド錠４ｍｇ「ＫＯ」 | AC17: 346 | AD17: トラゾドン塩酸塩錠２５ｍｇ「アメル」 | AE17: 347 | AF17: トリアゾラム錠０．２５ｍｇ「日医工」 | AG17: 351 | AH17: トリメブチンマレイン酸塩錠１００ｍｇ「トーワ」 | AI17: 355 | AJ17: ドンペリドン錠１０ｍｇ「ＪＧ」 | AK17: 366 | AL17: ニコランジル錠５ｍｇ「トーワ」 | AM17: 370 | AN17: ニューレプチル錠５ｍｇ | AO17: 379 | AP17: ピコスルファートナトリウム錠２．５ｍｇ「イワキ」 | AQ17: 421 | AR17: フェブキソスタットＯＤ錠１０ｍｇ「サワイ」 | AS17: 456 | AT17: フェロミア錠５０ｍｇ | AU17: 457 | AV17: フルニトラゼパム錠２ｍｇ「アメル」 | AW17: 481 | AX17: マプロチリン塩酸塩錠１０ｍｇ「アメル」 | AY17: 549 | AZ17: レキソタン錠２ | BA17: 642
A18: 17 | B18: ＥＫ１ 葛根湯エキス細粒 | C18: 薬価一致候補 | D18: クラシエ葛根湯エキス細粒 | E18: 139 | F18: ロドピン錠２５ｍｇ | G18: 670
A19: 18 | B19: ＥＫ１１４ 柴苓湯 | C19: 薬価一致候補 | D19: クラシエ柴苓湯エキス細粒 | E19: 144
A20: 19 | B20: ＥＫ１５ 黄連解毒湯エキス細粒 | C20: 薬価一致候補 | D20: クラシエ黄連解毒湯エキス細粒 | E20: 140
A21: 20 | B21: ＥＫ１９ 小青竜湯エキス細粒 | C21: 不一致
A22: 21 | B22: ＥＫ２４ 加味逍遥散料エキス細粒 | C22: 薬価一致候補 | D22: クラシエ加味逍遙散料エキス細粒 | E22: 141 | F22: デプロメール錠２５ | G22: 326 | H22: プレガバリンＯＤ錠７５ｍｇ「サワイ」 | I22: 483
A23: 22 | B23: ＥＫ４０ 猪苓湯エキス細粒 | C23: 薬価一致候補 | D23: クラシエ猪苓湯エキス細粒 | E23: 142
A24: 23 | B24: ＥＫ４１ 補中益気湯エキス細粒 | C24: 薬価一致候補 | D24: クラシエ補中益気湯エキス細粒 | E24: 143
A25: 24 | B25: ＥＰＬカプセル２５０ｍｇ 販売中止 | C25: 薬価一致候補 | D25: アスパラカリウム錠３００ｍｇ | E25: 13 | F25: アタラックス錠２５ｍｇ | G25: 20 | H25: アマンタジン塩酸塩錠５０ｍｇ「杏林」 | I25: 35 | J25: ２５ｍｇアリナミンＦ糖衣錠 | K25: 43 | L25: アリピプラゾール錠１ｍｇ「サワイ」 | M25: 48 | N25: アルファカルシドールカプセル０．５μｇ「フソー」 | O25: 51 | P25: ＥＰＬカプセル２５０ｍｇ | Q25: 59 | R25: 硝酸イソソルビド徐放カプセル２０ｍｇ「Ｓｔ」 | S25: 203 | T25: セレコキシブ錠１００ｍｇ「ＤＳＥＰ」 | U25: 240 | V25: ソラナックス０．４ｍｇ錠 | W25: 253 | X25: チザニジン錠１ｍｇ「トーワ」 | Y25: 286 | Z25: テオフィリン徐放Ｕ錠２００ｍｇ「トーワ」 | AA25: 313 | AB25: トラセミド錠４ｍｇ「ＫＯ」 | AC25: 346 | AD25: トラゾドン塩酸塩錠２５ｍｇ「アメル」 | AE25: 347 | AF25: トリアゾラム錠０．２５ｍｇ「日医工」 | AG25: 351 | AH25: トリメブチンマレイン酸塩錠１００ｍｇ「トーワ」 | AI25: 355 | AJ25: ドンペリドン錠１０ｍｇ「ＪＧ」 | AK25: 366 | AL25: ニコランジル錠５ｍｇ「トーワ」 | AM25: 370 | AN25: ニューレプチル錠５ｍｇ | AO25: 379 | AP25: ピコスルファートナトリウム錠２．５ｍｇ「イワキ」 | AQ25: 421 | AR25: フェブキソスタットＯＤ錠１０ｍｇ「サワイ」 | AS25: 456 | AT25: フェロミア錠５０ｍｇ | AU25: 457 | AV25: フルニトラゼパム錠２ｍｇ「アメル」 | AW25: 481 | AX25: マプロチリン塩酸塩錠１０ｍｇ「アメル」 | AY25: 549 | AZ25: レキソタン錠２ | BA25: 642
A26: 25 | B26: ＳＰトローチ０．２５ｍｇ「明治」 | C26: 完全一致 | D26: ＳＰトローチ０．２５ｍｇ「明治」 | E26: 76
A27: 26 | B27: Ｔ７２ ヨクイニンエキス錠「コタロー」 | C27: 薬価一致候補 | D27: シーピー配合顆粒 | E27: 195 | F27: テプレノンカプセル５０ｍｇ「ＹＤ」 | G27: 325 | H27: トーワチーム配合顆粒 | I27: 365 | J27: ビオフェルミン配合散 | K27: 418 | L27: ヨクイニンエキス錠「コタロー」 | M27: 581
A28: 27 | B28: アーチスト錠１．２５ｍｇ | C28: 完全一致 | D28: アーチスト錠１．２５ｍｇ | E28: 22
A29: 28 | B29: アイファガン点眼液０．１％ | C29: 不一致
A30: 29 | B30: アウィクリ注 フレックスタッチ 総量３００単位 | C30: 不一致
A31: 30 | B31: アキネトン細粒１％ | C31: 不一致
A32: 31 | B32: アキネトン注射液５ｍｇ | C32: 薬価一致候補 | D32: アキネトン注射液５ｍｇ | E32: 2 | F32: イリボー錠５μｇ | G32: 63 | H32: エホチール注１０ｍｇ | I32: 92 | J32: ケイツーＮ静注１０ｍｇ | K32: 163 | L32: ダイビタミックス注 | M32: 260 | N32: ネオファーゲン静注２０ｍＬ | O32: 386 | P32: パントール注射液５００ｍｇ | Q32: 416 | R32: ブスコパン注２０ｍｇ | S32: 462 | T32: プリンペラン注射液１０ｍｇ | U32: 475
A33: 32 | B33: アクアチムクリーム１％ | C33: 完全一致 | D33: アクアチムクリーム１％ | E33: 3
A34: 33 | B34: アクチット輸液 | C34: 薬価一致候補 | D34: アクチット輸液 | E34: 4
A35: 34 | B35: アクトシン軟膏３％ | C35: 完全一致 | D35: アクトシン軟膏３％ | E35: 5
A36: 35 | B36: アザルフィジンＥＮ錠５００ｍｇ | C36: 完全一致 | D36: アザルフィジンＥＮ錠５００ｍｇ | E36: 6
A37: 36 | B37: アシクロビル点滴静注用２５０ｍｇ「サワイ」 | C37: 完全一致 | D37: アシクロビル点滴静注用２５０ｍｇ「サワイ」 | E37: 7
A38: 37 | B38: アジスロマイシン錠２５０ｍｇ「トーワ」 | C38: 完全一致 | D38: アジスロマイシン錠２５０ｍｇ「トーワ」 | E38: 8
A39: 38 | B39: アジルサルタンＯＤ錠２０ｍｇ「サワイ」 | C39: 完全一致 | D39: アジルサルタンＯＤ錠２０ｍｇ「サワイ」 | E39: 9
A40: 39 | B40: アジルサルタンＯＤ錠２０ｍｇ「サワイ」 | C40: 完全一致 | D40: アジルサルタンＯＤ錠２０ｍｇ「サワイ」 | E40: 9
...

Sheet Sheet2

Sheet A_1
A1: 007 ﾂﾑﾗ ハチミジオウガン | B1: 9.8 | C1: =DBCS(A1) -> ００７ ツムラ ハチミジオウガン | D1: =B1 -> 9.8
A2: 007 ﾂﾑﾗ ハチミジオウガン | B2: 9.8 | C2: =DBCS(A2) -> ００７ ツムラ ハチミジオウガン | D2: =B2 -> 9.8
A3: 012 ﾂﾑﾗ ｻｲｺｶﾘｭｳｺﾂﾎﾞﾚｲﾄｳ | B3: 20.3 | C3: =DBCS(A3) -> ０１２ ツムラ サイコカリュウコツボレイトウ | D3: =B3 -> 20.3
A4: 016 ﾂﾑﾗ ハンゲコウボクトウ | B4: 14.6 | C4: =DBCS(A4) -> ０１６ ツムラ ハンゲコウボクトウ | D4: =B4 -> 14.6
A5: 017 ﾂﾑﾗ ｺﾞﾚｲｻﾝ | B5: 13.6 | C5: =DBCS(A5) -> ０１７ ツムラ ゴレイサン | D5: =B5 -> 13.6
A6: 019 ツムラ ショウセイリュウトウ | B6: 12.8 | C6: =DBCS(A6) -> ０１９ ツムラ ショウセイリュウトウ | D6: =B6 -> 12.8
A7: 043 ツムラ リツクンシトウ | B7: 18 | C7: =DBCS(A7) -> ０４３ ツムラ リツクンシトウ | D7: =B7 -> 18
A8: 048 ﾂﾑﾗ ｼﾞｭｳｾﾞﾝﾀｲﾎﾄｳ | B8: 18.4 | C8: =DBCS(A8) -> ０４８ ツムラ ジュウゼンタイホトウ | D8: =B8 -> 18.4
A9: 054 ﾂﾑﾗ ﾖｸｶﾝｻﾝ | B9: 16.1 | C9: =DBCS(A9) -> ０５４ ツムラ ヨクカンサン | D9: =B9 -> 16.1
A10: 062 ﾂﾑﾗ ﾎﾞｳﾌｳﾂｳｼﾖｳｻﾝ | B10: 13.8 | C10: =DBCS(A10) -> ０６２ ツムラ ボウフウツウシヨウサン | D10: =B10 -> 13.8
A11: 068 ﾂﾑﾗ ｼｬｸﾔｸｶﾝｿﾞｳﾄｳ | B11: 10.4 | C11: =DBCS(A11) -> ０６８ ツムラ シャクヤクカンゾウトウ | D11: =B11 -> 10.4
A12: 083 ﾂﾑﾗ ﾖｸｶﾝｻﾝｶﾁﾝﾋﾟﾊﾝｹﾞ | B12: 14.4 | C12: =DBCS(A12) -> ０８３ ツムラ ヨクカンサンカチンピハンゲ | D12: =B12 -> 14.4
... A49: アズレン点眼液0.02％「ﾆｯﾄｰ」 | B49: 91.6 | C49: =DBCS(A49) -> アズレン点眼液０．０２％「ニットー」 | D49: =B49 -> 91.6
A50: アセサイド消毒液6％ 800ｍｌｘ2 | C50: =DBCS(A50) -> アセサイド消毒液６％ ８００ｍｌｘ２ | D50: =B50 -> 0
A51: アセリオ静注液1000ｍｇバッグ | B51: 298 | C51: =DBCS(A51) -> アセリオ静注液１０００ｍｇバッグ | D51: =B51 -> 298
A52: アセレンド注100μｇ | B52: 1646 | C52: =DBCS(A52) -> アセレンド注１００μｇ | D52: =B52 -> 1646
A53: アゾセミド錠30ｍｇ「ＤＳＥＰ」 | B53: 10.4 | C53: =DBCS(A53) -> アゾセミド錠３０ｍｇ「ＤＳＥＰ」 | D53: =B53 -> 10.4
A54: アゾセミド錠60ｍｇ「ＤＳＥＰ」 | B54: 11.3 | C54: =DBCS(A54) -> アゾセミド錠６０ｍｇ「ＤＳＥＰ」 | D54: =B54 -> 11.3
A55: アダラートCR錠20ｍｇ | B55: 13.2 | C55: =DBCS(A55) -> アダラートＣＲ錠２０ｍｇ | D55: =B55 -> 13.2
A56: アタラックス錠25ｍｇ | B56: 6.1 | C56: =DBCS(A56) -> アタラックス錠２５ｍｇ | D56: =B56 -> 6.1
A57: アドエア500ディスカス 60吸入用 | B57: 3952.1 | C57: =DBCS(A57) -> アドエア５００ディスカス ６０吸入用 | D57: =B57 -> 3952.1
A58: アドナ散10％ | B58: 32.5 | C58: =DBCS(A58) -> アドナ散１０％ | D58: =B58 -> 32.5
A59: アドナ錠30ｍｇ | B59: 7.7 | C59: =DBCS(A59) -> アドナ錠３０ｍｇ | D59: =B59 -> 7.7
A60: アドナ注（静脈用）５０ｍｇ | B60: 89 | C60: =DBCS(A60) -> アドナ注（静脈用）５０ｍｇ | D60: =B60 -> 89
A61: アドナ注（静脈用）５０ｍｇ | B61: 89 | C61: =DBCS(A61) -> アドナ注（静脈用）５０ｍｇ | D61: =B61 -> 89
A62: アドフィードパップ40ｍｇ | B62: 17.6 | C62: =DBCS(A62) -> アドフィードパップ４０ｍｇ | D62: =B62 -> 17.6
... A232: コデインリン酸塩散1％「ホエイ」 | B232: 8.5 | C232: =DBCS(A232) -> コデインリン酸塩散１％「ホエイ」 | D232: =B232 -> 8.5
A233: コミナティ筋注シリンジ | C233: =DBCS(A233) -> コミナティ筋注シリンジ | D233: =B233 -> 0
A234: コンサータ錠18ｍｇ | B234: 235.8 | C234: =DBCS(A234) -> コンサータ錠１８ｍｇ | D234: =B234 -> 235.8
A235: コントミン糖衣錠１００ｍｇ | B235: 9.7 | C235: =DBCS(A235) -> コントミン糖衣錠１００ｍｇ | D235: =B235 -> 9.7
A236: コントミン糖衣錠２５ｍｇ | B236: 9.7 | C236: =DBCS(A236) -> コントミン糖衣錠２５ｍｇ | D236: =B236 -> 9.7
A237: コントミン糖衣錠２５ｍｇ | B237: 9.7 | C237: =DBCS(A237) -> コントミン糖衣錠２５ｍｇ | D237: =B237 -> 9.7
A238: コントミン糖衣錠２５ｍｇ | B238: 9.7 | C238: =DBCS(A238) -> コントミン糖衣錠２５ｍｇ | D238: =B238 -> 9.7
A239: コントミン糖衣錠５０ｍｇ | B239: 9.7 | C239: =DBCS(A239) -> コントミン糖衣錠５０ｍｇ | D239: =B239 -> 9.7
A240: コントミン糖衣錠５０ｍｇ | B240: 9.7 | C240: =DBCS(A240) -> コントミン糖衣錠５０ｍｇ | D240: =B240 -> 9.7
A241: サリベートエアゾール | B241: 369.1 | C241: =DBCS(A241) -> サリベートエアゾール | D241: =B241 -> 369.1
A242: サワシリン錠２５０ | B242: 15.3 | C242: =DBCS(A242) -> サワシリン錠２５０ | D242: =B242 -> 15.3
A243: サンリズムカプセル25ｍｇ | B243: 21.2 | C243: =DBCS(A243) -> サンリズムカプセル２５ｍｇ | D243: =B243 -> 21.2
A244: ジアゼパム錠２ｍｇ「アメル」 | B244: 5.9 | C244: =DBCS(A244) -> ジアゼパム錠２ｍｇ「アメル」 | D244: =B244 -> 5.9
A245: ジアゼパム錠５ｍｇ「アメル」 | B245: 6 | C245: =DBCS(A245) -> ジアゼパム錠５ｍｇ「アメル」 | D245: =B245 -> 6
...

Sheet B_1
A1: 亜鉛華軟膏「ニッコー」 | B1: 3.3 | C1: =DBCS(A1) -> 亜鉛華軟膏「ニッコー」 | D1: =B1 -> 3.3
A2: アキネトン注射液５ｍｇ | B2: 61 | C2: =DBCS(A2) -> アキネトン注射液５ｍｇ | D2: =B2 -> 61
A3: アクアチムクリーム１％ | B3: 20.7 | C3: =DBCS(A3) -> アクアチムクリーム１％ | D3: =B3 -> 20.7
A4: アクチット輸液 | B4: 341 | C4: =DBCS(A4) -> アクチット輸液 | D4: =B4 -> 341
A5: アクトシン軟膏３％ | B5: 50 | C5: =DBCS(A5) -> アクトシン軟膏３％ | D5: =B5 -> 50
A6: アザルフィジンＥＮ錠５００ｍｇ | B6: 25.9 | C6: =DBCS(A6) -> アザルフィジンＥＮ錠５００ｍｇ | D6: =B6 -> 25.9
A7: アシクロビル点滴静注用２５０ｍｇ「サワイ」 | B7: 368 | C7: =DBCS(A7) -> アシクロビル点滴静注用２５０ｍｇ「サワイ」 | D7: =B7 -> 368
A8: アジスロマイシン錠２５０ｍｇ「トーワ」 | B8: 60.7 | C8: =DBCS(A8) -> アジスロマイシン錠２５０ｍｇ「トーワ」 | D8: =B8 -> 60.7
A9: アジルサルタンＯＤ錠２０ｍｇ「サワイ」 | B9: 27.4 | C9: =DBCS(A9) -> アジルサルタンＯＤ錠２０ｍｇ「サワイ」 | D9: =B9 -> 27.4
A10: アスコルビン酸注５００ｍｇ「イセイ」 | B10: 100 | C10: =DBCS(A10) -> アスコルビン酸注５００ｍｇ「イセイ」 | D10: =B10 -> 100
A11: アズノール軟膏０．０３３％ | B11: 8.03 | C11: =DBCS(A11) -> アズノール軟膏０．０３３％ | D11: =B11 -> 8.03
A12: アスパラ－ＣＡ錠２００ | B12: 5.9 | C12: =DBCS(A12) -> アスパラ－ＣＡ錠２００ | D12: =B12 -> 5.9
... A683: ワンパル２号輸液 | B683: 1399 | C683: =DBCS(A683) -> ワンパル２号輸液 | D683: =B683 -> 1399

Sheet match_results_不採用
A1: A行番号 | B1: A薬品名 | C1: 判定 | D1: 候補1_薬品名 | E1: 候補1_行番号
A2: 8 | B2: アルメタ軟膏 | C2: 完全一致 | D2: アルメタ軟膏 | E2: 32
A3: 18 | B3: サリベートエアゾール | C3: 完全一致 | D3: サリベートエアゾール | E3: 122
A4: 38 | B4: 静注用キシロカイン２％ | C4: 完全一致 | D4: 静注用キシロカイン２％ | E4: 94
A5: 5 | B5: アズノール軟膏0.033% | C5: 不一致
A6: 7 | B6: アミノレバンEN配合散 コーヒー味 | C6: 不一致
A7: 10 | B7: アレビアチン錠100ｍｇ | C7: 不一致
A8: 12 | B8: エピペン注射液0.3ｍｇ | C8: 不一致
A9: 14 | B9: オイラックスクリーム10% | C9: 不一致
A10: 15 | B10: オリブ油 | C10: 不一致
A11: 19 | B11: ジクアス点眼液3％ | C11: 不一致
A12: 22 | B12: デカドロン注射液6.6ｍｇ | C12: 不一致
A13: 24 | B13: ネオメドロールEE軟膏 | C13: 不一致
A14: 26 | B14: ヒアルロン酸Na点眼液0.1％「ニットー」 | C14: 不一致
A15: 35 | B15: ロイコボリン注3ｍｇ | C15: 不一致
A16: 36 | B16: 重カマ「ヨシダ」（細粒状） | C16: 不一致
... A18: 39 | B18: 白色ワセリン「ケンエー」 | C18: 不一致
A19: 1 | B19: EK19 小青竜湯エキス細粒 | C19: 薬価一致候補 | D19: クラシエ小青竜湯エキス細粒 | E19: 98
A20: 2 | B20: アイファガン点眼液0.1％ | C20: 薬価一致候補 | D20: アイファガン点眼液０．１％ | E20: 1
A21: 3 | B21: アウィクリ注 フレックスタッチ 総量300単位 | C21: 薬価一致候補 | D21: アウィクリ注 フレックスタッチ 総量３００単位 | E21: 2
A22: 4 | B22: アキネトン細粒1％ | C22: 薬価一致候補 | D22: アキネトン細粒１％ | E22: 3
A23: 6 | B23: アノーロエリプタ30吸入用 | C23: 薬価一致候補 | D23: アノーロエリプタ３０吸入用 | E23: 19
A24: 9 | B24: アレギサール点眼液0.1％ 販売中止 | C24: 薬価一致候補 | D24: アレギサール点眼液０．１％ | E24: 33
A25: 11 | B25: イノラス配合経腸用液（コーヒー） | C25: 薬価一致候補 | D25: ルボックス錠２５ | E25: 335
A26: 13 | B26: エンテカビルOD錠0.5ｍｇ「サワイ」 | C26: 薬価一致候補 | D26: エンテカビルＯＤ錠０．５ｍｇ「サワイ」 | E26: 68
A27: 16 | B27: グラナテック点眼液0.4％ | C27: 薬価一致候補 | D27: グラナテック点眼液０．４％ | E27: 101
A28: 17 | B28: クレナフィン爪外用液10％3.56ｇ | C28: 薬価一致候補 | D28: クレナフィン爪外用液１０％ | E28: 106
A29: 20 | B29: ジスバルカプセル40ｍｇ | C29: 薬価一致候補 | D29: ジスバルカプセル４０ｍｇ | E29: 124
A30: 21 | B30: スピリーバ2.5μｇレスピマット60吸入 | C30: 薬価一致候補 | D30: スピリーバ２．５μｇレスピマット６０吸入 | E30: 131
... A40: 34 | B40: リフキシマ錠200ｍｇ | C40: 薬価一致候補 | D40: リフキシマ錠２００ｍｇ | E40: 329
A41: 40
A42: 41
A43: 42
A44: 43
A45: 44
A46: 45
A47: 46
A48: 47
A49: 48
A50: 49
...
