Workbook

Sheet Sheet3
A1: 剤形 | B1: 場所
A2: 3 | B2: 4
A3: 5 | B3: 4
A4: 1 | B4: 15
A5: 1 | B5: 3
A6: 25 | B6: 9
A7: 25 | B7: 8
A8: 10 | B8: 3
A9: 25 | B9: 15
A10: 24 | B10: 7
A11: 21 | B11: 15
A12: 17 | B12: 3
A13: 3 | B13: 15
... A20: 1 | B20: 8
A21: 1
A22: 3 | B22: 2
A23: 19 | B23: 3
A24: 11 | B24: 15
A25: 1 | B25: 1
A26: 5 | B26: 1
A27: 11 | B27: 3
A28: 1 | B28: 2
A29: 7 | B29: 15
A30: 25 | B30: 6
A31: 14 | B31: 3
A32: 3 | B32: 3

Sheet 表
C3: 採用薬 | E3: 1 | F3: =E3+1 -> 2 | G3: =F3+1 -> 3 | H3: =G3+1 -> 4 | I3: =H3+1 -> 5 | J3: =I3+1 -> 6 | K3: =J3+1 -> 7 | L3: =K3+1 -> 8 | M3: =L3+1 -> 9 | ... V3: =U3+1 -> 18
E4: =OFFSET(分類!$A$30,E3-1,0) -> 1 | F4: =OFFSET(分類!$A$30,F3-1,0) -> 2 | G4: =OFFSET(分類!$A$30,G3-1,0) -> 3 | H4: =OFFSET(分類!$A$30,H3-1,0) -> 4 | I4: =OFFSET(分類!$A$30,I3-1,0) -> 5 | J4: =OFFSET(分類!$A$30,J3-1,0) -> 6 | K4: =OFFSET(分類!$A$30,K3-1,0) -> 7 | L4: =OFFSET(分類!$A$30,L3-1,0) -> 8 | ... V4: =OFFSET(分類!$A$30,V3-1,0) -> 27
E5: =OFFSET(分類!$B$30,E3-1,0) -> 調剤棚 | F5: =OFFSET(分類!$B$30,F3-1,0) -> 散薬調剤台 | G5: =OFFSET(分類!$B$30,G3-1,0) -> 外用.臨時.散薬ヒート | H5: =OFFSET(分類!$B$30,H3-1,0) -> 漢方薬 | I5: =OFFSET(分類!$B$30,I3-1,0) -> 普通薬バラ | J5: =OFFSET(分類!$B$30,J3-1,0) -> 劇薬バラ | K5: =OFFSET(分類!$B$30,K3-1,0) -> 軟膏 | L5: =OFFSET(分類!$B$30,L3-1,0) -> 抗生剤.小輸液 | ... V5: =OFFSET(分類!$B$30,V3-1,0) -> 分包機
B6: 1 | C6: =OFFSET(分類!$A$3,$B6-1,0) -> 1 | D6: =OFFSET(分類!B$3,$B6-1,0) -> 錠剤
B7: =B6+1 -> 2 | C7: =OFFSET(分類!$A$3,$B7-1,0) -> 2 | D7: =OFFSET(分類!B$3,$B7-1,0) -> カプセル
B8: =B7+1 -> 3 | C8: =OFFSET(分類!$A$3,$B8-1,0) -> 3 | D8: =OFFSET(分類!B$3,$B8-1,0) -> 散
B9: =B8+1 -> 4 | C9: =OFFSET(分類!$A$3,$B9-1,0) -> 4 | D9: =OFFSET(分類!B$3,$B9-1,0) -> 細粒
B10: =B9+1 -> 5 | C10: =OFFSET(分類!$A$3,$B10-1,0) -> 5 | D10: =OFFSET(分類!B$3,$B10-1,0) -> 顆粒
B11: =B10+1 -> 6 | C11: =OFFSET(分類!$A$3,$B11-1,0) -> 6 | D11: =OFFSET(分類!B$3,$B11-1,0) -> シロップ
B12: =B11+1 -> 7 | C12: =OFFSET(分類!$A$3,$B12-1,0) -> 7 | D12: =OFFSET(分類!B$3,$B12-1,0) -> 液（内用）
B13: =B12+1 -> 8 | C13: =OFFSET(分類!$A$3,$B13-1,0) -> 8 | D13: =OFFSET(分類!B$3,$B13-1,0) -> トローチ
B14: =B13+1 -> 9 | C14: =OFFSET(分類!$A$3,$B14-1,0) -> 9 | D14: =OFFSET(分類!B$3,$B14-1,0) -> 含漱剤
B15: =B14+1 -> 10 | C15: =OFFSET(分類!$A$3,$B15-1,0) -> 10 | D15: =OFFSET(分類!B$3,$B15-1,0) -> 吸入剤
B16: =B15+1 -> 11 | C16: =OFFSET(分類!$A$3,$B16-1,0) -> 11 | D16: =OFFSET(分類!B$3,$B16-1,0) -> 膣錠
B17: =B16+1 -> 12 | C17: =OFFSET(分類!$A$3,$B17-1,0) -> 12 | D17: =OFFSET(分類!B$3,$B17-1,0) -> 坐剤
B18: =B17+1 -> 13 | C18: =OFFSET(分類!$A$3,$B18-1,0) -> 13 | D18: =OFFSET(分類!B$3,$B18-1,0) -> 浣腸
... B29: =B28+1 -> 24 | C29: =OFFSET(分類!$A$3,$B29-1,0) -> 25 | D29: =OFFSET(分類!B$3,$B29-1,0) -> 注射剤
C33: 臨時 | E33: 1 | F33: =E33+1 -> 2 | G33: =F33+1 -> 3 | H33: =G33+1 -> 4 | I33: =H33+1 -> 5 | J33: =I33+1 -> 6 | K33: =J33+1 -> 7 | L33: =K33+1 -> 8 | M33: =L33+1 -> 9 | ... V33: =U33+1 -> 18
E34: =OFFSET(分類!$A$30,E33-1,0) -> 1 | F34: =OFFSET(分類!$A$30,F33-1,0) -> 2 | G34: =OFFSET(分類!$A$30,G33-1,0) -> 3 | H34: =OFFSET(分類!$A$30,H33-1,0) -> 4 | I34: =OFFSET(分類!$A$30,I33-1,0) -> 5 | J34: =OFFSET(分類!$A$30,J33-1,0) -> 6 | K34: =OFFSET(分類!$A$30,K33-1,0) -> 7 | L34: =OFFSET(分類!$A$30,L33-1,0) -> 8 | ... V34: =OFFSET(分類!$A$30,V33-1,0) -> 27
E35: =OFFSET(分類!$B$30,E33-1,0) -> 調剤棚 | F35: =OFFSET(分類!$B$30,F33-1,0) -> 散薬調剤台 | G35: =OFFSET(分類!$B$30,G33-1,0) -> 外用.臨時.散薬ヒート | H35: =OFFSET(分類!$B$30,H33-1,0) -> 漢方薬 | I35: =OFFSET(分類!$B$30,I33-1,0) -> 普通薬バラ | J35: =OFFSET(分類!$B$30,J33-1,0) -> 劇薬バラ | K35: =OFFSET(分類!$B$30,K33-1,0) -> 軟膏 | L35: =OFFSET(分類!$B$30,L33-1,0) -> 抗生剤.小輸液 | ... V35: =OFFSET(分類!$B$30,V33-1,0) -> 分包機
B36: 1 | C36: =OFFSET(分類!$A$3,$B36-1,0) -> 1 | D36: =OFFSET(分類!B$3,$B36-1,0) -> 錠剤
B37: =B36+1 -> 2 | C37: =OFFSET(分類!$A$3,$B37-1,0) -> 2 | D37: =OFFSET(分類!B$3,$B37-1,0) -> カプセル
B38: =B37+1 -> 3 | C38: =OFFSET(分類!$A$3,$B38-1,0) -> 3 | D38: =OFFSET(分類!B$3,$B38-1,0) -> 散
B39: =B38+1 -> 4 | C39: =OFFSET(分類!$A$3,$B39-1,0) -> 4 | D39: =OFFSET(分類!B$3,$B39-1,0) -> 細粒
B40: =B39+1 -> 5 | C40: =OFFSET(分類!$A$3,$B40-1,0) -> 5 | D40: =OFFSET(分類!B$3,$B40-1,0) -> 顆粒
B41: =B40+1 -> 6 | C41: =OFFSET(分類!$A$3,$B41-1,0) -> 6 | D41: =OFFSET(分類!B$3,$B41-1,0) -> シロップ
B42: =B41+1 -> 7 | C42: =OFFSET(分類!$A$3,$B42-1,0) -> 7 | D42: =OFFSET(分類!B$3,$B42-1,0) -> 液（内用）
B43: =B42+1 -> 8 | C43: =OFFSET(分類!$A$3,$B43-1,0) -> 8 | D43: =OFFSET(分類!B$3,$B43-1,0) -> トローチ
B44: =B43+1 -> 9 | C44: =OFFSET(分類!$A$3,$B44-1,0) -> 9 | D44: =OFFSET(分類!B$3,$B44-1,0) -> 含漱剤
B45: =B44+1 -> 10 | C45: =OFFSET(分類!$A$3,$B45-1,0) -> 10 | D45: =OFFSET(分類!B$3,$B45-1,0) -> 吸入剤
B46: =B45+1 -> 11 | C46: =OFFSET(分類!$A$3,$B46-1,0) -> 11 | D46: =OFFSET(分類!B$3,$B46-1,0) -> 膣錠
B47: =B46+1 -> 12 | C47: =OFFSET(分類!$A$3,$B47-1,0) -> 12 | D47: =OFFSET(分類!B$3,$B47-1,0) -> 坐剤
B48: =B47+1 -> 13 | C48: =OFFSET(分類!$A$3,$B48-1,0) -> 13 | D48: =OFFSET(分類!B$3,$B48-1,0) -> 浣腸
... B59: =B58+1 -> 24 | C59: =OFFSET(分類!$A$3,$B59-1,0) -> 25 | D59: =OFFSET(分類!B$3,$B59-1,0) -> 注射剤

Sheet 分類
A2: No | B2: 分類
A3: 1 | B3: 錠剤 | F3: 採用０（非採用）はいらない
A4: 2 | B4: カプセル | F4: 採用２（臨時採用薬）で1グループ
A5: 3 | B5: 散 | F5: 採用１（採用薬） | AD5: 1 | AE5: =AD5+1 -> 2 | AF5: =AE5+1 -> 3 | AG5: =AF5+1 -> 4 | AH5: =AG5+1 -> 5 | AI5: =AH5+1 -> 6 | AJ5: =AI5+1 -> 7 | AK5: =AJ5+1 -> 8 | AL5: =AK5+1 -> 9 | ... AU5: =AT5+1 -> 18
A6: 4 | B6: 細粒 | AD6: =OFFSET($A$30,AD5-1,0) -> 1 | AE6: =OFFSET($A$30,AE5-1,0) -> 2 | AF6: =OFFSET($A$30,AF5-1,0) -> 3 | AG6: =OFFSET($A$30,AG5-1,0) -> 4 | AH6: =OFFSET($A$30,AH5-1,0) -> 5 | AI6: =OFFSET($A$30,AI5-1,0) -> 6 | AJ6: =OFFSET($A$30,AJ5-1,0) -> 7 | AK6: =OFFSET($A$30,AK5-1,0) -> 8 | ... AU6: =OFFSET($A$30,AU5-1,0) -> 27
A7: 5 | B7: 顆粒 | G7: 外用 | J7: 散剤 | M7: 錠剤 | P7: 注射 | S7: その他 | AD7: =OFFSET($B$30,AD5-1,0) -> 調剤棚 | AE7: =OFFSET($B$30,AE5-1,0) -> 散薬調剤台 | AF7: =OFFSET($B$30,AF5-1,0) -> 外用.臨時.散薬ヒート | AG7: =OFFSET($B$30,AG5-1,0) -> 漢方薬 | AH7: =OFFSET($B$30,AH5-1,0) -> 普通薬バラ | AI7: =OFFSET($B$30,AI5-1,0) -> 劇薬バラ | AJ7: =OFFSET($B$30,AJ5-1,0) -> 軟膏 | AK7: =OFFSET($B$30,AK5-1,0) -> 抗生剤.小輸液 | ... AU7: =OFFSET($B$30,AU5-1,0) -> 分包機
A8: 6 | B8: シロップ | G8: クリーム | H8: 15 | J8: 散剤 | K8: 3 | M8: 錠剤 | N8: 1 | P8: 注射 | Q8: 25 | S8: シロップ | T8: 6 | AC8: 非採用
A9: 7 | B9: 液（内用） | G9: 軟膏 | H9: 14 | J9: 細粒 | K9: 4 | M9: カプセル | N9: 2 | S9: 液（内用） | T9: 7 | AC9: 臨時
A10: 8 | B10: トローチ | G10: トローチ | H10: 8 | J10: 顆粒 | K10: 5 | S10: 坐剤 | T10: 12 | AA10: 1 | AB10: =OFFSET(A$3,$AA10-1,0) -> 1 | AC10: =OFFSET(B$3,$AA10-1,0) -> 錠剤
A11: 9 | B11: 含漱剤 | G11: 点眼 | H11: 21 | S11: 点耳薬 | T11: 22 | AA11: =AA10+1 -> 2 | AB11: =OFFSET(A$3,$AA11-1,0) -> 2 | AC11: =OFFSET(B$3,$AA11-1,0) -> カプセル
A12: 10 | B12: 吸入剤 | G12: 点鼻 | H12: 23 | S12: その他 | T12: 24 | AA12: =AA11+1 -> 3 | AB12: =OFFSET(A$3,$AA12-1,0) -> 3 | AC12: =OFFSET(B$3,$AA12-1,0) -> 散
A13: 11 | B13: 膣錠 | G13: 外用剤 | H13: 17 | AA13: =AA12+1 -> 4 | AB13: =OFFSET(A$3,$AA13-1,0) -> 4 | AC13: =OFFSET(B$3,$AA13-1,0) -> 細粒
A14: 12 | B14: 坐剤 | G14: 吸入 | H14: 10 | AA14: =AA13+1 -> 5 | AB14: =OFFSET(A$3,$AA14-1,0) -> 5 | AC14: =OFFSET(B$3,$AA14-1,0) -> 顆粒
A15: 13 | B15: 浣腸 | G15: 貼付薬 | H15: 19 | AA15: =AA14+1 -> 6 | AB15: =OFFSET(A$3,$AA15-1,0) -> 6 | AC15: =OFFSET(B$3,$AA15-1,0) -> シロップ
A16: 14 | B16: 軟膏 | G16: 浣腸 | H16: 13 | AA16: =AA15+1 -> 7 | AB16: =OFFSET(A$3,$AA16-1,0) -> 7 | AC16: =OFFSET(B$3,$AA16-1,0) -> 液（内用）
A17: 15 | B17: クリーム | G17: 噴霧剤 | H17: 18 | AA17: =AA16+1 -> 8 | AB17: =OFFSET(A$3,$AA17-1,0) -> 8 | AC17: =OFFSET(B$3,$AA17-1,0) -> トローチ
A18: 16 | B18: ゼリー（ゲル） | G18: 膣錠 | H18: 11 | AA18: =AA17+1 -> 9 | AB18: =OFFSET(A$3,$AA18-1,0) -> 9 | AC18: =OFFSET(B$3,$AA18-1,0) -> 含漱剤
A19: 17 | B19: 外用液剤 | G19: 含漱剤 | H19: 9 | AA19: =AA18+1 -> 10 | AB19: =OFFSET(A$3,$AA19-1,0) -> 10 | AC19: =OFFSET(B$3,$AA19-1,0) -> 吸入剤
A20: 18 | B20: 噴霧剤 | G20: ゼリー（ゲル） | H20: 16 | AA20: =AA19+1 -> 11 | AB20: =OFFSET(A$3,$AA20-1,0) -> 11 | AC20: =OFFSET(B$3,$AA20-1,0) -> 膣錠
A21: 19 | B21: 貼付剤 | AA21: =AA20+1 -> 12 | AB21: =OFFSET(A$3,$AA21-1,0) -> 12 | AC21: =OFFSET(B$3,$AA21-1,0) -> 坐剤
A22: 21 | B22: 点眼剤 | AA22: =AA21+1 -> 13 | AB22: =OFFSET(A$3,$AA22-1,0) -> 13 | AC22: =OFFSET(B$3,$AA22-1,0) -> 浣腸
A23: 22 | B23: 点耳薬 | AA23: =AA22+1 -> 14 | AB23: =OFFSET(A$3,$AA23-1,0) -> 14 | AC23: =OFFSET(B$3,$AA23-1,0) -> 軟膏
A24: 23 | B24: 点鼻薬 | AA24: =AA23+1 -> 15 | AB24: =OFFSET(A$3,$AA24-1,0) -> 15 | AC24: =OFFSET(B$3,$AA24-1,0) -> クリーム
A25: 24 | B25: その他 | AA25: =AA24+1 -> 16 | AB25: =OFFSET(A$3,$AA25-1,0) -> 16 | AC25: =OFFSET(B$3,$AA25-1,0) -> ゼリー（ゲル）
A26: 25 | B26: 注射剤 | AA26: =AA25+1 -> 17 | AB26: =OFFSET(A$3,$AA26-1,0) -> 17 | AC26: =OFFSET(B$3,$AA26-1,0) -> 外用液剤
AA27: =AA26+1 -> 18 | AB27: =OFFSET(A$3,$AA27-1,0) -> 18 | AC27: =OFFSET(B$3,$AA27-1,0) -> 噴霧剤
AA28: =AA27+1 -> 19 | AB28: =OFFSET(A$3,$AA28-1,0) -> 19 | AC28: =OFFSET(B$3,$AA28-1,0) -> 貼付剤
A29: 棚 | AA29: =AA28+1 -> 20 | AB29: =OFFSET(A$3,$AA29-1,0) -> 21 | AC29: =OFFSET(B$3,$AA29-1,0) -> 点眼剤
A30: 1 | B30: 調剤棚 | AA30: =AA29+1 -> 21 | AB30: =OFFSET(A$3,$AA30-1,0) -> 22 | AC30: =OFFSET(B$3,$AA30-1,0) -> 点耳薬
A31: =A30+1 -> 2 | B31: 散薬調剤台 | AA31: =AA30+1 -> 22 | AB31: =OFFSET(A$3,$AA31-1,0) -> 23 | AC31: =OFFSET(B$3,$AA31-1,0) -> 点鼻薬
A32: =A31+1 -> 3 | B32: 外用.臨時.散薬ヒート | AA32: =AA31+1 -> 23 | AB32: =OFFSET(A$3,$AA32-1,0) -> 24 | AC32: =OFFSET(B$3,$AA32-1,0) -> その他
A33: =A32+1 -> 4 | B33: 漢方薬 | AA33: =AA32+1 -> 24 | AB33: =OFFSET(A$3,$AA33-1,0) -> 25 | AC33: =OFFSET(B$3,$AA33-1,0) -> 注射剤
A34: =A33+1 -> 5 | B34: 普通薬バラ
A35: =A34+1 -> 6 | B35: 劇薬バラ
A36: =A35+1 -> 7 | B36: 軟膏
A37: =A36+1 -> 8 | B37: 抗生剤.小輸液
A38: =A37+1 -> 9 | B38: 注射
A39: =A38+1 -> 10 | B39: 輸液
A40: =A39+1 -> 11 | B40: 冷蔵庫
A41: =A40+1 -> 12 | B41: 湿布
...

Sheet Sheet2
A1: 剤形 | B1: 場所
A2: 3 | B2: 4
A3: 1 | B3: 25
A4: 2 | B4: 5
A5: 8 | B5: 3
A6: 1 | B6: 5
A7: 25 | B7: 9
A8: 15 | B8: 3
A9: 25 | B9: 10
A10: 14 | B10: 15
A11: 1 | B11: 1
A12: 25 | B12: 11
A13: 3 | B13: 2
... A58: 3 | B58: 9
